
# Created by Ruins mod version 17.0 Ingame Parser
# authoring Player: ST753M

weight=1
embed_into_distance=4
acceptable_target_blocks=
unacceptable_target_blocks=flowing_water,water,flowing_lava,lava,ice,bedrock,netherrack,nether_brick,nether_brick_fence,soul_sand,quartz_ore,end_stone,obsidian,iron_bars,Natura:Cloud,slime_grass,slime_congealed,slime_dirt,clouds,natura:clouds
dimensions=22,12,8
allowable_overhang=4
max_leveling=0
leveling_buffer=-1
preserve_water=1
preserve_lava=1
random_height_offset=-2,2

biomesToSpawnIn=stone_beach,gravel_beach,ocean,kelp_forest,deep_ocean,coral_reef,coralium_infested_ocean,swampland,mutated_swampland,wetland,quagmire,lush_swamp,mangrove,marsh,bayou,bog,bamboo_forest,dead_swamp,moor,dead_swamp,coralium_infested_swamp,jungle,jungle_edge,jungle_hills,tropical_island,tropical_rainforest,rainforest,mutated_jungle,mutated_jungle_edge,bamboo_forest,overgrown_cliffs,eucalyptus_forest,mini_jungle,forest,maple_woods,boreal_forest,forest_hills,woodland,seasonal_forest,temperate_rainforest,fen,grove,sacred_springs,land_of_lakes,forested_hills,lush_hills,thicket,birch_forest,birch_forest_hills,mutated_birch_forest,mutated_birch_forest_hills,birch_forested_hills,cherry_blossom_grove,mutated_forest,roofed_forest,mutated_roofed_forest,taiga,taiga_hills,mutated_redwood_taiga,mutated_redwood_taiga_hills,redwood_taiga,mutated_taiga,redwood_taiga_hills,redwood_forest,coniferous_forest,shield,dead_forest,autumnal_wooded_hills,autumnal_woods,snowy_forest,mutated_taiga_cold,snowy_coniferous_forest,taiga_cold,taiga_cold_hills,extreme_hills,smaller_extreme_hills,mutated_extreme_hills,mutated_extreme_hills_with_trees,extreme_hills_with_trees,highland,alps,alps_foothills,mountain,mountain_foothills,crag,cliffs,rocky_plateau,savanna_rock,mutated_savanna_rock,steppe,wasteland,tundra,mushroom_island,mushroom_island_shore,mushroomisland,mushroomislandshore

rule1=0,100,preserveBlock

#  Main Body 
rule2=0,100,botania:biomestonea-5
^0,100,botania:biomestonea-4
^0,100,botania:livingrock-0
^0,100,botania:biomestonea-6
^0,100,botania:biomestonea-7
^0,100,botania:biomestonea-1
^0,100,botania:biomestonea-3
^0,100,botania:biomestonea-0
^0,100,botania:biomestonea-2
^0,100,botania:biomestonea-12
^0,100,botania:biomestonea-11
^0,100,botania:biomestonea-13
^0,100,botania:biomestonea-8
^0,100,botania:biomestonea-9
^0,100,botania:biomestonea-14
^0,100,botania:biomestonea-10
^0,100,botania:biomestonea-15
^0,100,botania:biomestonea-5
^0,100,botania:biomestonea-4
^0,100,botania:livingrock-0
^0,100,botania:biomestonea-6
^0,100,botania:biomestonea-7
^0,100,botania:biomestonea-1
^0,100,botania:biomestonea-3
^0,100,botania:biomestonea-0
^0,100,botania:biomestonea-2
^0,100,botania:biomestonea-12
^0,100,botania:biomestonea-11
^0,100,botania:biomestonea-13
^0,100,botania:biomestonea-8
^0,100,botania:biomestonea-9
^0,100,botania:biomestonea-14
^0,100,botania:biomestonea-10
^0,100,botania:biomestonea-15

#  Eyes (has 4 blocks)
rule3=0,100,botania:storage-3
^0,100,botania:shimmerrock-0
^0,100,botania:dreamwood-0
^0,100,botania:storage-0
^0,100,botania:storage-0
^0,100,botania:storage-0
^0,100,botania:livingrock-4
^0,100,botania:dreamwood-5
^0,100,botania:shimmerwoodplanks-0
^0,100,botania:blazeblock-0
^0,100,botania:quartztypelavender-0
^0,100,botania:quartztypemana-0
^0,100,botania:quartztypeelf-0
^0,100,botania:quartztypedark-0
^0,100,botania:quartztypesunny-0
^0,100,botania:quartztypered-0
^0,100,botania:quartztypeblaze-0
^0,100,botania:quartztypelavender-0
^0,100,botania:quartztypemana-0
^0,100,botania:quartztypeelf-0
^0,100,botania:quartztypedark-0
^0,100,botania:quartztypesunny-0
^0,100,botania:quartztypered-0
^0,100,botania:quartztypeblaze-0

layer
1,1,1,1,1,1,1,1
1,1,1,1,1,1,1,1
1,1,2,2,2,2,1,1
1,1,2,2,2,2,1,1
1,1,2,2,2,2,1,1
1,1,2,2,2,2,1,1
1,1,2,2,2,2,1,1
1,1,2,2,2,2,1,1
1,1,2,2,2,2,1,1
1,1,1,1,1,1,1,1
1,1,1,1,1,1,1,1
1,1,1,1,1,1,1,1
endlayer

layer
1,1,1,1,1,1,1,1
1,1,2,2,2,2,1,1
1,2,2,2,2,2,2,1
1,2,2,2,2,2,2,1
1,2,2,2,2,2,2,1
1,2,2,2,2,2,2,1
1,2,2,2,2,2,2,1
1,2,2,2,2,2,2,1
1,2,2,2,2,2,2,1
1,1,2,2,2,2,1,1
1,1,1,1,1,1,1,1
1,1,1,1,1,1,1,1
endlayer

layer
1,1,1,1,1,1,1,1
1,1,2,2,2,2,1,1
1,2,2,2,2,2,2,1
1,2,2,2,2,2,2,1
1,2,2,2,2,2,2,1
1,2,2,2,2,2,2,1
1,2,2,2,2,2,2,1
1,2,2,2,2,2,2,1
1,2,2,2,2,2,2,1
1,1,2,2,2,2,1,1
1,1,1,1,1,1,1,1
1,1,1,1,1,1,1,1
endlayer

layer
1,1,1,1,1,1,1,1
1,1,2,2,2,2,1,1
1,2,2,2,2,2,2,1
1,2,2,2,2,2,2,1
1,2,2,2,2,2,2,1
1,2,2,2,2,2,2,1
1,2,2,2,2,2,2,1
1,2,2,2,2,2,2,1
1,2,2,2,2,2,2,1
1,1,2,2,2,2,1,1
1,1,1,1,1,1,1,1
1,1,1,1,1,1,1,1
endlayer

layer
1,1,1,1,1,1,1,1
1,1,2,2,2,2,1,1
1,2,2,2,2,2,2,1
1,2,2,2,2,2,2,1
1,2,2,2,2,2,2,1
1,2,2,2,2,2,2,1
1,2,2,2,2,2,2,1
1,2,2,2,2,2,2,1
1,2,2,2,2,2,2,1
1,1,1,2,2,1,1,1
1,1,1,1,1,1,1,1
1,1,1,1,1,1,1,1
endlayer

layer
1,1,1,1,1,1,1,1
1,1,2,2,2,2,1,1
1,1,2,2,2,2,1,1
1,2,2,2,2,2,2,1
1,2,2,2,2,2,2,1
1,2,2,2,2,2,2,1
1,2,2,2,2,2,2,1
1,2,2,2,2,2,2,1
1,1,2,2,2,2,1,1
1,1,1,1,1,1,1,1
1,1,1,1,1,1,1,1
1,1,1,1,1,1,1,1
endlayer

layer
1,1,1,1,1,1,1,1
1,1,2,2,2,2,1,1
1,1,2,2,2,2,1,1
1,1,2,2,2,2,1,1
1,2,2,2,2,2,2,1
1,2,2,2,2,2,2,1
1,2,2,2,2,2,2,1
1,1,2,2,2,2,1,1
1,1,2,2,2,2,1,1
1,1,1,1,1,1,1,1
1,1,1,1,1,1,1,1
1,1,1,1,1,1,1,1
endlayer

layer
1,1,1,1,1,1,1,1
1,1,1,2,2,1,1,1
1,1,2,2,2,2,1,1
1,1,2,2,2,2,1,1
1,1,2,2,2,2,1,1
1,1,2,2,2,2,1,1
1,1,2,2,2,2,1,1
1,1,2,2,2,2,1,1
1,1,1,2,2,1,1,1
1,1,1,1,1,1,1,1
1,1,1,1,1,1,1,1
1,1,1,1,1,1,1,1
endlayer

layer
1,1,1,1,1,1,1,1
1,1,1,1,1,1,1,1
1,1,2,2,2,2,1,1
1,1,2,2,2,2,1,1
1,1,2,2,2,2,1,1
1,1,2,2,2,2,1,1
1,1,2,2,2,2,1,1
1,1,2,2,2,2,1,1
1,1,1,2,2,1,1,1
1,1,1,1,1,1,1,1
1,1,1,1,1,1,1,1
1,1,1,1,1,1,1,1
endlayer

layer
1,1,1,1,1,1,1,1
1,1,1,1,1,1,1,1
1,1,1,2,2,1,1,1
1,1,2,2,2,2,1,1
1,1,2,2,2,2,1,1
1,1,2,2,2,2,1,1
1,1,2,2,2,2,1,1
1,1,2,2,2,2,1,1
1,1,2,2,2,2,1,1
1,1,1,2,2,1,1,1
1,1,1,1,1,1,1,1
1,1,1,1,1,1,1,1
endlayer

layer
1,1,1,1,1,1,1,1
1,1,1,1,1,1,1,1
1,1,1,1,1,1,1,1
1,1,1,2,2,1,1,1
1,1,2,2,2,2,1,1
1,1,2,2,2,2,1,1
1,1,2,2,2,2,1,1
1,1,2,2,2,2,1,1
1,1,2,2,2,2,1,1
1,1,1,2,2,1,1,1
1,1,1,1,1,1,1,1
1,1,1,1,1,1,1,1
endlayer

layer
1,1,1,1,1,1,1,1
1,1,1,1,1,1,1,1
1,1,1,1,1,1,1,1
1,1,1,1,1,1,1,1
1,1,1,1,1,1,1,1
1,1,1,1,1,1,1,1
1,1,1,2,2,1,1,1
1,1,2,2,2,2,1,1
1,1,2,2,2,2,1,1
1,1,1,2,2,1,1,1
1,1,1,2,2,1,1,1
1,1,1,1,1,1,1,1
endlayer

layer
1,1,1,1,1,1,1,1
1,1,1,1,1,1,1,1
1,1,1,1,1,1,1,1
1,1,1,1,1,1,1,1
1,1,1,1,1,1,1,1
1,1,1,1,1,1,1,1
1,1,1,1,1,1,1,1
1,1,1,2,2,1,1,1
1,1,2,2,2,2,1,1
1,1,2,2,2,2,1,1
1,1,1,2,2,1,1,1
1,1,1,1,1,1,1,1
endlayer

layer
1,1,1,1,1,1,1,1
1,1,1,1,1,1,1,1
1,1,1,1,1,1,1,1
1,1,1,1,1,1,1,1
1,1,1,1,1,1,1,1
1,1,1,1,1,1,1,1
1,1,1,1,1,1,1,1
1,1,1,2,2,1,1,1
1,1,2,2,2,2,1,1
1,1,2,2,2,2,1,1
1,1,1,2,2,1,1,1
1,1,1,1,1,1,1,1
endlayer

layer
1,1,1,1,1,1,1,1
1,1,1,1,1,1,1,1
1,1,1,1,1,1,1,1
1,1,1,1,1,1,1,1
1,1,1,1,1,1,1,1
1,1,1,1,1,1,1,1
1,1,1,1,1,1,1,1
1,1,1,2,2,1,1,1
1,1,2,2,2,2,1,1
1,1,1,2,2,1,1,1
1,1,1,2,2,1,1,1
1,1,1,1,1,1,1,1
endlayer

layer
1,1,1,1,1,1,1,1
1,1,1,1,1,1,1,1
1,1,1,1,1,1,1,1
1,1,1,1,1,1,1,1
1,1,1,1,1,1,1,1
1,1,1,1,1,1,1,1
1,1,1,2,2,1,1,1
1,1,1,2,2,1,1,1
1,1,1,2,2,1,1,1
1,1,1,2,2,1,1,1
1,1,1,2,2,1,1,1
1,1,1,1,1,1,1,1
endlayer

layer
1,1,1,1,1,1,1,1
1,1,1,1,1,1,1,1
1,1,1,1,1,1,1,1
1,1,1,1,1,1,1,1
1,1,1,1,1,1,1,1
1,1,1,1,1,1,1,1
1,1,1,2,2,1,1,1
1,1,1,2,2,1,1,1
1,1,1,2,2,1,1,1
1,1,1,2,2,1,1,1
1,1,1,1,1,1,1,1
1,1,1,1,1,1,1,1
endlayer

layer
1,1,1,2,2,1,1,1
1,1,1,2,2,1,1,1
1,1,2,2,2,2,1,1
1,1,2,2,2,2,1,1
1,1,2,2,2,2,1,1
1,1,2,2,2,2,1,1
1,1,2,2,2,2,1,1
1,1,2,2,2,2,1,1
1,1,1,2,2,1,1,1
1,1,1,2,2,1,1,1
1,1,1,1,1,1,1,1
1,1,1,1,1,1,1,1
endlayer

layer
1,1,2,2,2,2,1,1
1,1,2,2,2,2,1,1
1,1,2,2,2,2,1,1
1,1,2,2,2,2,1,1
1,1,2,2,2,2,1,1
1,1,2,2,2,2,1,1
1,1,2,2,2,2,1,1
1,1,2,2,2,2,1,1
1,1,1,2,2,1,1,1
1,1,1,1,1,1,1,1
1,1,1,1,1,1,1,1
1,1,1,1,1,1,1,1
endlayer

layer
1,1,2,1,1,2,1,1
1,1,1,1,1,1,1,1
1,1,1,2,2,1,1,1
1,1,2,2,2,2,1,1
1,1,0,3,3,0,1,1
1,1,0,3,3,0,1,1
1,1,2,2,2,2,1,1
1,2,2,2,2,2,2,1
1,1,1,1,1,1,1,1
1,1,1,1,1,1,1,1
1,1,1,1,1,1,1,1
1,1,1,1,1,1,1,1
endlayer

layer
1,1,1,1,1,1,1,1
1,1,1,1,1,1,1,1
1,1,1,1,1,1,1,1
1,1,2,2,2,2,1,1
1,1,2,2,2,2,1,1
1,1,2,2,2,2,1,1
1,2,2,2,2,2,2,1
2,2,2,2,2,2,2,2
2,2,2,1,1,2,2,2
1,2,1,1,1,1,2,1
1,1,1,1,1,1,1,1
1,1,1,1,1,1,1,1
endlayer

layer
1,1,1,1,1,1,1,1
1,1,1,1,1,1,1,1
1,1,1,1,1,1,1,1
1,1,1,1,1,1,1,1
1,1,1,1,1,1,1,1
1,1,1,2,2,1,1,1
1,1,2,2,2,2,1,1
1,2,1,1,1,1,2,1
2,1,1,1,1,1,1,2
2,1,1,1,1,1,1,2
2,1,1,1,1,1,1,2
2,1,1,1,1,1,1,2
endlayer

