
# Created by Ruins mod version 17.0 Ingame Parser
# authoring Player: ST753M

weight=1
embed_into_distance=5
uniqueMinDistance=1000
spawnMinDistance=500
acceptable_target_blocks=grass,mycelium,podzol,dirt
unacceptable_target_blocks=flowing_water,water,flowing_lava,lava
dimensions=16,15,15
allowable_overhang=5
max_leveling=0
leveling_buffer=-1
preserve_water=0
preserve_lava=0
preventRotation=1

biomesToSpawnIn=mushroom_island,mushroom_island_shore,mushroomisland,mutated_swampland

=0,100,air
rule1=0,100,preserveBlock
rule2=0,100,minecraft:dirt-0
rule3=0,100,minecraft:planks-5
rule4=0,100,minecraft:brown_mushroom_block-15
rule5=0,100,minecraft:web-0
rule6=0,100,minecraft:red_mushroom_block-14
rule7=0,100,minecraft:ladder-2
rule8=0,80,IInventory;minecraft:chest;minecraft:mushroom_stew#2#0#0+harvestcraft:whitemushroomitem#5#0#2+minecraft:mushroom_stew#3#0#5+harvestcraft:grilledmushroomitem#6#0#7+harvestcraft:mushroomsteakitem#1#0#10+minecraft:brown_mushroom_block#16#0#11+harvestcraft:mushroomlasagnaitem#1#0#14+minecraft:red_mushroom#2#0#17+minecraft:red_mushroom#2#0#18+minecraft:air#0#0#19+minecraft:air#0#0#20+minecraft:mushroom_stew#1#0#21+minecraft:red_mushroom#6#0#22+minecraft:air#0#0#23+minecraft:rotten_flesh#5#0#24+minecraft:mushroom_stew#2#0#26-2
rule9=0,100,MobSpawner:spider,MobSpawner:cave_spider
rule10=0,80,IInventory;minecraft:chest;minecraft:air#0#0#0+minecraft:rotten_flesh#2#0#2+minecraft:air#0#0#3+harvestcraft:whitemushroomitem#6#0#5+minecraft:poisonous_potato#2#0#7+harvestcraft:stuffedmushroomitem#4#0#8+minecraft:spider_eye#3#0#9+minecraft:air#0#0#11+harvestcraft:baconmushroomburgeritem#2#0#12+minecraft:red_mushroom_block#17#0#13+minecraft:mushroom_stew#3#0#15+minecraft:air#0#0#16+minecraft:dirt#1#0#17+minecraft:rotten_flesh#3#0#19+minecraft:brown_mushroom#4#0#20+minecraft:air#0#0#21+harvestcraft:mushroomrisottoitem#2#0#23+minecraft:mushroom_stew#1#0#25+minecraft:air#0#0#26-2
rule11=0,100,minecraft:hardened_clay-0
rule12=0,100,minecraft:mycelium-0
rule13=0,100,cookingforblockheads:kitchen_floor-0
rule14=0,100,minecraft:oak_stairs-3
rule15=0,100,minecraft:fence-0
rule16=0,100,minecraft:oak_stairs-2
rule17=0,100,minecraft:carpet-14
rule18=0,100,minecraft:bookshelf-0
rule19=0,100,minecraft:spruce_door-1
rule20=0,100,minecraft:spruce_door-2
rule21=0,100,cookingforblockheads:cooking_table-4
rule22=0,100,cookingforblockheads:oven-4
rule23=0,100,cookingforblockheads:counter-9
rule24=0,100,cookingforblockheads:fridge-9
rule25=0,100,minecraft:trapdoor-2
rule26=0,100,minecraft:crafting_table-0
rule27=0,100,minecraft:stained_glass-0
rule28=1,100,minecraft:torch-5
rule29=0,100,minecraft:spruce_door-9
rule30=0,100,minecraft:spruce_door-8
rule31=0,100,cookingforblockheads:cow_jar-4
rule32=0,100,minecraft:dark_oak_stairs-0
rule33=0,100,minecraft:dark_oak_stairs-3
rule34=0,100,minecraft:dark_oak_stairs-2
rule35=0,100,cookingforblockheads:spice_rack-3
rule36=0,100,cookingforblockheads:tool_rack-4
rule37=0,100,minecraft:dark_oak_stairs-1
rule38=0,100,minecraft:bed-3
rule39=0,100,minecraft:bed-11

layer
1,1,1,1,1,2,2,2,2,2,1,1,1,1,1
1,1,1,2,2,2,2,2,2,2,2,2,1,1,1
1,1,2,2,2,2,2,2,2,2,2,2,2,1,1
1,2,2,2,2,2,2,2,2,2,2,2,2,2,1
1,2,2,2,2,2,2,3,3,3,2,2,2,2,1
2,2,2,2,2,2,3,3,3,3,3,2,2,2,2
2,2,2,2,2,2,3,3,3,3,3,2,2,2,2
2,2,2,2,2,2,3,3,3,3,3,2,2,2,2
2,2,2,2,2,2,2,3,3,3,3,3,2,2,2
2,2,2,2,2,2,2,2,3,3,3,3,2,2,2
1,2,2,2,2,2,2,2,2,3,3,3,2,2,1
1,2,2,2,2,2,2,2,2,2,2,2,2,2,1
1,1,2,2,2,2,2,2,2,2,2,2,2,1,1
1,1,1,2,2,2,2,2,2,2,2,2,1,1,1
1,1,1,1,1,2,2,2,2,2,1,1,1,1,1
endlayer

layer
1,1,1,1,1,2,2,2,2,2,1,1,1,1,1
1,1,1,2,2,2,2,2,2,2,2,2,1,1,1
1,1,2,2,2,2,2,2,2,2,2,2,2,1,1
1,2,2,2,2,2,2,4,4,4,2,2,2,2,1
1,2,2,2,2,2,4,5,0,0,4,2,2,2,1
2,2,2,2,2,4,6,0,0,0,5,4,2,2,2
2,2,2,2,2,4,6,0,0,4,0,4,2,2,2
2,2,2,2,2,4,4,0,0,0,5,4,2,2,2
2,2,2,2,2,2,4,0,0,0,0,0,4,2,2
2,2,2,2,2,2,2,4,7,0,0,0,4,2,2
1,2,2,2,2,2,2,2,4,0,0,0,4,2,1
1,2,2,2,2,2,2,2,2,4,4,4,2,2,1
1,1,2,2,2,2,2,2,2,2,2,2,2,1,1
1,1,1,2,2,2,2,2,2,2,2,2,1,1,1
1,1,1,1,1,2,2,2,2,2,1,1,1,1,1
endlayer

layer
1,1,1,1,1,2,2,2,2,2,1,1,1,1,1
1,1,1,2,2,2,2,2,2,2,2,2,1,1,1
1,1,4,2,2,2,2,2,2,2,2,2,2,4,1
1,2,2,2,2,2,2,4,4,4,2,2,2,2,1
1,2,2,2,2,2,4,0,0,0,4,2,2,2,1
2,2,2,2,2,4,8,0,0,0,0,4,2,2,2
2,2,2,2,2,4,10,5,0,9,0,4,2,2,2
2,2,2,2,2,4,4,0,0,5,0,4,2,2,2
2,2,2,2,2,2,4,0,0,0,0,0,4,2,2
2,2,2,2,2,2,2,4,7,0,0,0,4,2,2
1,2,2,2,2,2,2,2,4,0,0,5,4,2,1
1,2,2,2,2,2,2,2,2,4,4,4,2,2,1
1,1,2,2,2,2,2,2,2,2,2,2,2,1,1
1,1,1,2,2,2,2,2,2,2,2,2,1,1,1
1,1,1,1,1,2,2,2,2,2,1,1,1,1,1
endlayer

layer
1,1,1,1,1,2,2,2,2,2,1,1,1,1,1
1,1,1,2,2,2,2,2,2,2,2,2,1,1,1
1,1,4,2,2,2,2,2,2,2,2,2,11,4,1
1,2,2,2,2,2,2,4,4,4,2,2,2,11,1
1,2,2,2,2,2,4,5,0,0,4,2,2,4,1
2,2,2,2,2,4,5,0,0,0,0,4,2,2,2
2,2,2,2,2,4,0,0,0,4,5,4,2,2,2
2,2,2,2,2,4,4,5,0,0,5,4,2,2,2
2,2,2,2,2,2,4,0,0,0,0,5,4,2,2
2,2,2,2,2,2,2,4,7,0,0,0,4,2,2
1,2,2,2,2,2,2,2,4,0,0,0,4,2,1
1,2,2,2,2,2,2,2,2,4,4,4,2,2,1
1,1,2,2,2,2,2,2,2,2,2,2,2,1,1
1,1,1,2,2,2,2,2,2,2,2,2,1,1,1
1,1,1,1,1,2,2,2,2,2,1,1,1,1,1
endlayer

layer
1,1,1,1,1,12,12,12,12,12,1,1,1,1,1
1,1,1,12,12,12,12,12,12,12,12,12,1,1,1
1,1,4,2,2,2,2,2,2,2,2,2,11,4,1
1,12,2,3,3,3,3,3,3,3,3,3,3,11,1
1,12,2,3,3,3,3,3,3,3,3,3,3,4,1
12,12,12,3,3,3,3,3,3,3,3,3,3,2,12
12,12,12,3,3,3,3,3,3,3,3,3,3,2,12
12,12,2,13,13,13,13,3,3,3,3,3,3,4,12
12,12,2,13,13,13,13,3,3,3,3,3,3,2,12
12,12,2,2,2,2,2,4,7,3,3,3,2,2,12
1,12,12,12,12,12,12,2,3,3,3,3,12,12,1
1,12,12,12,12,12,12,12,2,2,2,12,12,12,1
1,1,12,12,12,12,12,12,12,12,12,12,12,1,1
1,1,1,12,12,12,12,12,12,12,12,12,1,1,1
1,1,1,1,1,12,12,12,12,12,1,1,1,1,1
endlayer

layer
1,1,1,1,1,1,1,1,1,1,1,1,1,1,1
1,1,1,0,0,0,0,0,0,0,0,0,1,1,1
1,1,4,11,11,11,11,11,11,11,11,11,11,4,1
1,0,11,0,16,15,14,0,0,0,0,0,0,11,1
1,15,4,0,0,0,0,0,17,17,17,0,0,4,1
1,0,19,0,0,0,0,0,17,17,17,0,18,11,0
1,0,19,0,0,0,0,0,0,0,0,0,18,11,0
1,15,4,0,0,0,0,0,4,20,4,0,0,4,0
1,0,11,24,23,22,21,4,7,0,0,4,0,11,0
1,0,4,11,11,11,11,4,25,0,0,4,11,4,0
1,0,0,0,0,0,0,4,0,0,26,4,0,0,1
1,1,1,1,1,1,1,1,4,4,4,1,1,1,1
1,1,1,1,1,1,1,1,1,1,1,1,1,1,1
1,1,1,1,1,1,1,1,1,1,1,1,1,1,1
1,1,1,1,1,1,1,1,1,1,1,1,1,1,1
endlayer

layer
1,1,1,1,1,1,1,1,1,1,1,1,1,1,1
1,1,1,0,0,0,0,0,0,0,0,0,1,1,1
1,1,4,11,27,27,11,27,27,11,27,27,11,4,1
1,0,11,0,0,25,0,0,0,0,0,0,0,11,1
1,0,4,0,0,0,0,0,0,0,0,0,0,4,1
1,0,29,0,0,0,0,0,0,0,0,0,28,27,0
1,0,30,0,0,0,0,0,0,0,0,0,0,27,0
1,0,4,0,0,0,0,0,4,30,4,0,0,4,0
1,0,11,24,31,0,0,4,7,0,0,4,0,11,0
1,0,4,11,27,27,11,4,0,0,0,4,11,4,0
1,0,0,0,0,0,0,4,0,0,0,4,0,0,1
1,1,1,1,1,1,1,1,4,27,4,1,1,1,1
1,1,1,1,1,1,1,1,1,1,1,1,1,1,1
1,1,1,1,1,1,1,1,1,1,1,1,1,1,1
1,1,1,1,1,1,1,1,1,1,1,1,1,1,1
endlayer

layer
1,1,1,1,1,1,1,1,1,1,1,1,1,1,1
1,33,32,32,32,32,32,32,32,32,32,32,32,32,32
1,33,4,11,11,11,11,11,11,11,11,11,11,4,34
1,33,11,0,0,0,0,0,0,0,0,0,0,11,34
1,33,4,0,0,0,0,0,0,0,0,0,0,4,34
1,33,11,0,0,0,0,0,0,0,0,0,35,11,34
1,33,11,0,0,0,0,0,0,0,0,0,35,11,34
1,33,4,0,0,0,0,0,4,4,4,0,0,4,34
1,33,11,36,36,36,36,4,7,0,0,4,0,11,34
1,33,4,11,11,11,11,4,0,0,0,4,11,4,34
1,37,37,37,37,37,37,4,0,0,0,4,37,37,34
1,1,1,1,1,1,1,1,4,27,4,1,1,1,1
1,1,1,1,1,1,1,1,1,1,1,1,1,1,1
1,1,1,1,1,1,1,1,1,1,1,1,1,1,1
1,1,1,1,1,1,1,1,1,1,1,1,1,1,1
endlayer

layer
1,1,1,1,1,1,1,1,1,1,1,1,1,1,1
1,1,1,1,1,1,1,1,1,1,1,1,1,1,1
1,1,32,32,32,32,32,32,32,32,32,32,32,32,1
1,1,33,3,3,3,3,3,3,3,3,3,3,34,1
1,1,33,3,3,3,3,3,3,3,3,3,3,34,1
1,1,33,3,3,3,3,3,3,3,3,3,3,34,1
1,1,33,3,3,3,3,3,3,3,3,3,3,34,1
1,1,33,3,3,3,3,3,4,3,4,3,3,34,1
1,1,33,3,3,3,3,4,7,3,3,4,3,34,1
1,1,37,37,37,37,37,4,3,3,3,4,37,37,1
1,1,1,1,1,1,1,4,3,3,3,4,1,1,1
1,1,1,1,1,1,1,1,4,4,4,1,1,1,1
1,1,1,1,1,1,1,1,1,1,1,1,1,1,1
1,1,1,1,1,1,1,1,1,1,1,1,1,1,1
1,1,1,1,1,1,1,1,1,1,1,1,1,1,1
endlayer

layer
1,1,1,1,1,1,1,1,1,1,1,1,1,1,1
1,1,1,1,1,1,1,1,1,1,1,1,1,1,1
1,1,1,1,1,1,1,1,1,1,1,1,1,1,1
1,1,1,15,15,15,15,15,15,15,15,15,15,1,1
1,1,1,15,0,0,0,0,0,0,0,0,15,1,1
1,1,1,15,0,0,0,0,0,0,0,0,15,1,1
1,1,1,15,0,0,0,0,0,0,0,0,15,1,1
1,1,1,15,0,0,0,0,4,20,4,0,15,1,1
1,1,1,15,15,15,15,4,7,0,0,4,15,1,1
1,1,1,1,1,1,1,4,0,0,38,4,1,1,1
1,1,1,1,1,1,1,4,0,0,39,4,1,1,1
1,1,1,1,1,1,1,1,4,4,4,1,1,1,1
1,1,1,1,1,1,1,1,1,1,1,1,1,1,1
1,1,1,1,1,1,1,1,1,1,1,1,1,1,1
1,1,1,1,1,1,1,1,1,1,1,1,1,1,1
endlayer

layer
1,1,1,1,1,1,1,1,1,1,1,1,1,1,1
1,1,1,1,1,1,1,1,1,1,1,1,1,1,1
1,1,1,1,1,1,1,1,1,1,1,1,1,1,1
1,1,1,1,1,1,1,1,1,1,1,1,1,1,1
1,1,1,1,1,1,1,1,1,1,1,1,1,1,1
1,1,1,1,1,1,1,1,1,1,1,1,1,1,1
1,1,1,1,1,1,1,1,1,1,1,1,1,1,1
1,1,1,1,1,1,1,1,4,30,4,1,1,1,1
1,1,1,1,1,1,1,4,0,0,0,4,1,1,1
1,1,1,1,1,1,1,27,0,0,0,27,1,1,1
1,1,1,1,1,1,1,4,0,0,0,4,1,1,1
1,1,1,1,1,1,1,1,4,27,4,1,1,1,1
1,1,1,1,1,1,1,1,1,1,1,1,1,1,1
1,1,1,1,1,1,1,1,1,1,1,1,1,1,1
1,1,1,1,1,1,1,1,1,1,1,1,1,1,1
endlayer

layer
1,1,1,1,1,1,1,1,1,1,1,1,1,1,1
1,1,1,1,1,1,1,1,1,1,1,1,1,1,1
1,1,1,1,1,1,1,1,1,1,1,1,1,1,1
1,1,1,1,1,1,1,1,1,1,1,1,1,1,1
1,1,1,1,1,1,1,1,1,1,1,1,1,1,1
1,1,1,1,1,1,1,1,1,1,1,1,1,1,1
1,1,1,1,1,1,1,1,1,1,1,1,1,1,1
1,1,1,1,1,1,1,1,4,4,4,1,1,1,1
1,1,1,1,1,1,1,4,0,0,0,4,1,1,1
1,1,1,1,1,1,1,27,0,0,0,27,1,1,1
1,1,1,1,1,1,1,4,0,0,0,4,1,1,1
1,1,1,1,1,1,1,1,4,27,4,1,1,1,1
1,1,1,1,1,1,1,1,1,1,1,1,1,1,1
1,1,1,1,1,1,1,1,1,1,1,1,1,1,1
1,1,1,1,1,1,1,1,1,1,1,1,1,1,1
endlayer

layer
1,1,1,1,1,1,1,1,1,1,1,1,1,1,1
1,1,1,1,1,1,1,1,1,1,1,1,1,1,1
1,1,1,1,1,1,1,1,1,1,1,1,1,1,1
1,1,1,1,1,1,1,1,1,1,1,1,1,1,1
1,1,1,1,1,1,1,6,6,6,6,6,1,1,1
1,1,1,1,1,6,6,1,1,1,1,1,6,6,1
1,1,1,1,1,6,1,1,1,1,1,1,1,6,1
1,1,1,1,6,1,1,1,4,4,4,1,1,0,6
1,1,1,1,6,1,1,4,0,0,0,4,1,1,6
1,1,1,1,6,1,1,4,0,0,0,4,1,1,6
1,1,1,1,6,1,1,4,0,0,0,4,1,1,6
1,1,1,1,6,1,1,1,4,4,4,1,1,1,6
1,1,1,1,1,6,1,1,1,1,1,1,1,6,1
1,1,1,1,1,6,6,1,1,1,1,1,6,6,1
1,1,1,1,1,1,1,6,6,6,6,6,1,1,1
endlayer

layer
1,1,1,1,1,1,1,1,1,1,1,1,1,1,1
1,1,1,1,1,1,1,1,1,1,1,1,1,1,1
1,1,1,1,1,1,1,1,1,1,1,1,1,1,1
1,1,1,1,1,1,1,1,1,1,1,1,1,1,1
1,1,1,1,1,1,1,6,6,6,6,6,1,1,1
1,1,1,1,1,1,6,6,6,6,6,6,6,1,1
1,1,1,1,1,6,6,0,0,0,0,0,6,6,1
1,1,1,1,6,6,0,0,4,4,4,0,0,6,6
1,1,1,1,6,6,0,4,0,0,0,4,0,6,6
1,1,1,1,6,6,0,4,0,0,0,4,0,6,6
1,1,1,1,6,6,0,4,0,0,0,4,0,6,6
1,1,1,1,6,6,0,0,4,4,4,0,0,6,6
1,1,1,1,1,6,6,0,0,0,0,0,6,6,1
1,1,1,1,1,1,6,6,6,6,6,6,6,1,1
1,1,1,1,1,1,1,6,6,6,6,6,1,1,1
endlayer

layer
1,1,1,1,1,1,1,1,1,1,1,1,1,1,1
1,1,1,1,1,1,1,1,1,1,1,1,1,1,1
1,1,1,1,1,1,1,1,1,1,1,1,1,1,1
1,1,1,1,1,1,1,1,1,1,1,1,1,1,1
1,1,1,1,1,1,1,1,1,1,1,1,1,1,1
1,1,1,1,1,1,1,6,6,6,6,6,1,1,1
1,1,1,1,1,1,6,6,6,6,6,6,6,1,1
1,1,1,1,1,6,6,6,6,6,6,6,6,6,1
1,1,1,1,1,6,6,6,0,0,0,6,6,6,1
1,1,1,1,1,6,6,6,0,0,0,6,6,6,1
1,1,1,1,1,6,6,6,0,0,0,6,6,6,1
1,1,1,1,1,6,6,6,6,6,6,6,6,6,1
1,1,1,1,1,1,6,6,6,6,6,6,6,1,1
1,1,1,1,1,1,1,6,6,6,6,6,1,1,1
1,1,1,1,1,1,1,1,1,1,1,1,1,1,1
endlayer

layer
1,1,1,1,1,1,1,1,1,1,1,1,1,1,1
1,1,1,1,1,1,1,1,1,1,1,1,1,1,1
1,1,1,1,1,1,1,1,1,1,1,1,1,1,1
1,1,1,1,1,1,1,1,1,1,1,1,1,1,1
1,1,1,1,1,1,1,1,1,1,1,1,1,1,1
1,1,1,1,1,1,1,1,1,1,1,1,1,1,1
1,1,1,1,1,1,1,1,1,1,1,1,1,1,1
1,1,1,1,1,1,1,1,6,6,6,1,1,1,1
1,1,1,1,1,1,1,6,6,6,6,6,1,1,1
1,1,1,1,1,1,1,6,6,6,6,6,1,1,1
1,1,1,1,1,1,1,6,6,6,6,6,1,1,1
1,1,1,1,1,1,1,1,6,6,6,1,1,1,1
1,1,1,1,1,1,1,1,1,1,1,1,1,1,1
1,1,1,1,1,1,1,1,1,1,1,1,1,1,1
1,1,1,1,1,1,1,1,1,1,1,1,1,1,1
endlayer

