
# Created by Ruins mod version 17.1 Ingame Parser
# authoring Player: ST753M

weight=1
embed_into_distance=250
acceptable_target_blocks=grass,dirt,podzol,mycelium,stone,biomesoplenty:grass,biomesoplenty:dirt,sand,sandstone,gravel,terracotta,stained_terracotta,hardened_clay,hardened_sand,mud,coarse_dirt,clay,red_sand,water,ice,snow,packed_ice
unacceptable_target_blocks=
dimensions=9,21,21
allowable_overhang=0
max_leveling=0
leveling_buffer=-1
preserve_water=0
preserve_lava=0

rule1=0,100,preserveBlock
rule2=0,100,botania:biomestonea-3
rule3=0,100,botania:altgrass-5
rule4=0,100,botania:flower-10
rule5=0,100,botania:altar-4
rule6=0,100,IInventory;minecraft:chest;botania:cosmetic#1#14#7+botania:manaresource#2#1#12+botania:lexicon#{}#0#14+botania:brewvial#{brewKey:"nightVision"}#0#19-5
rule7=0,100,botania:biomestonea-11

layer
1,1,1,1,1,1,1,1,2,2,2,2,2,1,1,1,1,1,1,1,1
1,1,1,1,1,1,2,2,3,3,3,3,3,2,2,1,1,1,1,1,1
1,1,1,1,2,2,3,3,3,3,3,3,3,3,3,2,2,1,1,1,1
1,1,1,2,3,3,3,3,3,3,3,3,3,3,3,3,3,2,1,1,1
1,1,2,3,3,3,3,3,3,3,3,3,3,3,3,3,3,3,2,1,1
1,1,2,3,3,3,3,3,3,3,3,3,3,3,3,3,3,3,2,1,1
1,2,3,3,3,3,3,3,3,3,3,3,3,3,3,3,3,3,3,2,1
1,2,3,3,3,3,3,3,3,3,3,3,3,3,3,3,3,3,3,2,1
2,3,3,3,3,3,3,3,3,3,3,3,3,3,3,3,3,3,3,3,2
2,3,3,3,3,3,3,3,3,3,3,3,3,3,3,3,3,3,3,3,2
2,3,3,3,3,3,3,3,3,3,3,3,3,3,3,3,3,3,3,3,2
2,3,3,3,3,3,3,3,3,3,3,3,3,3,3,3,3,3,3,3,2
2,3,3,3,3,3,3,3,3,3,3,3,3,3,3,3,3,3,3,3,2
1,2,3,3,3,3,3,3,3,3,3,3,3,3,3,3,3,3,3,2,1
1,2,3,3,3,3,3,3,3,3,3,3,3,3,3,3,3,3,3,2,1
1,1,2,3,3,3,3,3,3,3,3,3,3,3,3,3,3,3,2,1,1
1,1,2,3,3,3,3,3,3,3,3,3,3,3,3,3,3,3,2,1,1
1,1,1,2,3,3,3,3,3,3,3,3,3,3,3,3,3,2,1,1,1
1,1,1,1,2,2,3,3,3,3,3,3,3,3,3,2,2,1,1,1,1
1,1,1,1,1,1,2,2,3,3,3,3,3,2,2,1,1,1,1,1,1
1,1,1,1,1,1,1,1,2,2,2,2,2,1,1,1,1,1,1,1,1
endlayer

layer
1,1,1,1,1,1,1,1,2,2,2,2,2,1,1,1,1,1,1,1,1
1,1,1,1,1,1,2,2,0,4,0,4,0,2,2,1,1,1,1,1,1
1,1,1,1,2,2,0,4,0,2,2,2,0,4,0,2,2,1,1,1,1
1,1,1,2,0,0,0,2,2,0,4,0,2,0,0,2,0,2,1,1,1
1,1,2,4,4,4,2,4,0,0,2,0,0,2,4,0,4,0,2,1,1
1,1,2,4,0,2,0,2,0,2,0,2,4,0,2,2,4,0,2,1,1
1,2,0,0,2,0,4,0,2,0,4,0,2,0,0,4,2,0,4,2,1
1,2,4,2,0,4,0,2,0,0,2,0,0,2,2,0,0,2,4,2,1
2,0,0,2,0,0,2,4,0,2,0,2,4,2,4,0,2,2,0,0,2
2,4,2,4,0,2,0,0,2,0,0,0,2,0,2,0,0,0,2,4,2
2,4,2,0,2,0,0,0,2,0,5,4,2,4,0,2,2,4,2,0,2
2,4,2,0,2,0,2,0,2,0,0,0,2,4,0,2,0,0,2,4,2
2,0,2,4,0,4,2,4,0,2,4,2,0,0,2,0,0,2,0,0,2
1,2,4,2,0,0,0,2,0,2,4,0,0,2,4,0,2,0,4,2,1
1,2,0,4,2,0,0,2,0,0,0,2,2,0,0,0,2,4,0,2,1
1,1,2,4,0,2,0,4,2,2,2,0,0,0,2,0,2,0,2,1,1
1,1,2,0,4,0,2,0,0,4,0,0,4,2,4,4,4,0,2,1,1
1,1,1,2,4,0,0,2,2,2,2,2,2,0,0,2,0,2,1,1,1
1,1,1,1,2,2,0,0,4,2,4,0,4,0,0,2,2,1,1,1,1
1,1,1,1,1,1,2,2,4,0,0,2,0,2,2,1,1,1,1,1,1
1,1,1,1,1,1,1,1,2,2,2,2,2,1,1,1,1,1,1,1,1
endlayer

layer
1,1,1,1,1,1,1,1,2,2,2,2,2,1,1,1,1,1,1,1,1
1,1,1,1,1,1,2,2,0,0,0,0,0,2,2,1,1,1,1,1,1
1,1,1,1,2,2,0,0,0,2,2,2,0,0,0,2,2,1,1,1,1
1,1,1,2,0,0,0,2,2,0,0,0,2,0,0,2,0,2,1,1,1
1,1,2,0,0,0,2,0,0,0,2,0,0,2,0,0,0,0,2,1,1
1,1,2,0,0,2,0,2,0,2,0,2,0,0,2,2,0,0,2,1,1
1,2,0,0,2,0,0,0,2,0,0,0,2,0,0,0,2,0,0,2,1
1,2,0,2,0,0,0,2,0,0,2,0,0,2,2,0,0,2,0,2,1
2,0,0,2,0,0,2,0,0,2,0,2,0,2,0,0,2,2,0,0,2
2,0,2,0,0,2,0,0,2,0,0,0,2,0,2,0,0,0,2,0,2
2,0,2,0,2,0,0,0,2,0,6,0,2,0,0,2,2,0,2,0,2
2,0,2,0,2,0,2,0,2,0,0,0,2,0,0,2,0,0,2,0,2
2,0,2,0,0,0,2,0,0,2,0,2,0,0,2,0,0,2,0,0,2
1,2,0,2,0,0,0,2,0,2,0,0,0,2,0,0,2,0,0,2,1
1,2,0,0,2,0,0,2,0,0,0,2,2,0,0,0,2,0,0,2,1
1,1,2,0,0,2,0,0,2,2,2,0,0,0,2,0,2,0,2,1,1
1,1,2,0,0,0,2,0,0,0,0,0,0,2,0,0,0,0,2,1,1
1,1,1,2,0,0,0,2,2,2,2,2,2,0,0,2,0,2,1,1,1
1,1,1,1,2,2,0,0,0,2,0,0,0,0,0,2,2,1,1,1,1
1,1,1,1,1,1,2,2,0,0,0,2,0,2,2,1,1,1,1,1,1
1,1,1,1,1,1,1,1,2,2,2,2,2,1,1,1,1,1,1,1,1
endlayer

layer
1,1,1,1,1,1,1,1,2,2,2,2,2,1,1,1,1,1,1,1,1
1,1,1,1,1,1,2,2,0,0,0,0,0,2,2,1,1,1,1,1,1
1,1,1,1,2,2,0,0,0,2,2,2,0,0,0,2,2,1,1,1,1
1,1,1,2,0,0,0,2,2,0,0,0,2,0,0,2,0,2,1,1,1
1,1,2,0,0,0,2,0,0,0,2,0,0,2,0,0,0,0,2,1,1
1,1,2,0,0,2,0,2,0,2,0,2,0,0,2,2,0,0,2,1,1
1,2,0,0,2,0,0,0,2,0,0,0,2,0,0,0,2,0,0,2,1
1,2,0,2,0,0,0,2,0,0,2,0,0,2,2,0,0,2,0,2,1
2,0,0,2,0,0,2,0,0,2,0,2,0,2,0,0,2,2,0,0,2
2,0,2,0,0,2,0,0,2,0,0,0,2,0,2,0,0,0,2,0,2
2,0,2,0,2,0,0,0,2,0,0,0,2,0,0,2,2,0,2,0,2
2,0,2,0,2,0,2,0,2,0,0,0,2,0,0,2,0,0,2,0,2
2,0,2,0,0,0,2,0,0,2,0,2,0,0,2,0,0,2,0,0,2
1,2,0,2,0,0,0,2,0,2,0,0,0,2,0,0,2,0,0,2,1
1,2,0,0,2,0,0,2,0,0,0,2,2,0,0,0,2,0,0,2,1
1,1,2,0,0,2,0,0,2,2,2,0,0,0,2,0,2,0,2,1,1
1,1,2,0,0,0,2,0,0,0,0,0,0,2,0,0,0,0,2,1,1
1,1,1,2,0,0,0,2,2,2,2,2,2,0,0,2,0,2,1,1,1
1,1,1,1,2,2,0,0,0,2,0,0,0,0,0,2,2,1,1,1,1
1,1,1,1,1,1,2,2,0,0,0,2,0,2,2,1,1,1,1,1,1
1,1,1,1,1,1,1,1,2,2,2,2,2,1,1,1,1,1,1,1,1
endlayer

layer
1,1,1,1,1,1,1,1,1,1,1,1,1,1,1,1,1,1,1,1,1
1,1,1,1,1,1,1,1,7,7,7,7,7,1,1,1,1,1,1,1,1
1,1,1,1,1,1,7,7,7,7,7,7,7,7,7,1,1,1,1,1,1
1,1,1,1,7,7,7,7,7,7,7,7,7,7,7,7,7,1,1,1,1
1,1,1,7,7,7,7,7,7,7,7,7,7,7,7,7,7,7,1,1,1
1,1,1,7,7,7,7,7,7,7,7,7,7,7,7,7,7,7,1,1,1
1,1,7,7,7,7,7,7,7,7,7,7,7,7,7,7,7,7,7,1,1
1,1,7,7,7,7,7,7,7,7,7,7,7,7,7,7,7,7,7,1,1
1,7,7,7,7,7,7,7,7,7,7,7,7,7,7,7,7,7,7,7,1
1,7,7,7,7,7,7,7,7,7,7,7,7,7,7,7,7,7,7,7,1
1,7,7,7,7,7,7,7,7,7,7,7,7,7,7,7,7,7,7,7,1
1,7,7,7,7,7,7,7,7,7,7,7,7,7,7,7,7,7,7,7,1
1,7,7,7,7,7,7,7,7,7,7,7,7,7,7,7,7,7,7,7,1
1,1,7,7,7,7,7,7,7,7,7,7,7,7,7,7,7,7,7,1,1
1,1,7,7,7,7,7,7,7,7,7,7,7,7,7,7,7,7,7,1,1
1,1,1,7,7,7,7,7,7,7,7,7,7,7,7,7,7,7,1,1,1
1,1,1,7,7,7,7,7,7,7,7,7,7,7,7,7,7,7,1,1,1
1,1,1,1,7,7,7,7,7,7,7,7,7,7,7,7,7,1,1,1,1
1,1,1,1,1,1,7,7,7,7,7,7,7,7,7,1,1,1,1,1,1
1,1,1,1,1,1,1,1,7,7,7,7,7,1,1,1,1,1,1,1,1
1,1,1,1,1,1,1,1,1,1,1,1,1,1,1,1,1,1,1,1,1
endlayer

layer
1,1,1,1,1,1,1,1,1,1,1,1,1,1,1,1,1,1,1,1,1
1,1,1,1,1,1,1,1,1,1,1,1,1,1,1,1,1,1,1,1,1
1,1,1,1,1,1,1,1,1,3,3,3,1,1,1,1,1,1,1,1,1
1,1,1,1,1,1,1,3,3,3,3,3,3,3,1,1,1,1,1,1,1
1,1,1,1,1,3,3,3,3,3,3,3,3,3,3,3,1,1,1,1,1
1,1,1,1,3,3,3,3,3,3,3,3,3,3,3,3,3,1,1,1,1
1,1,1,1,3,3,3,3,3,3,3,3,3,3,3,3,3,1,1,1,1
1,1,1,3,3,3,3,3,3,3,3,3,3,3,3,3,3,3,1,1,1
1,1,1,3,3,3,3,3,3,3,3,3,3,3,3,3,3,3,1,1,1
1,1,3,3,3,3,3,3,3,3,3,3,3,3,3,3,3,3,3,1,1
1,1,3,3,3,3,3,3,3,3,3,3,3,3,3,3,3,3,3,1,1
1,1,3,3,3,3,3,3,3,3,3,3,3,3,3,3,3,3,3,1,1
1,1,1,3,3,3,3,3,3,3,3,3,3,3,3,3,3,3,1,1,1
1,1,1,3,3,3,3,3,3,3,3,3,3,3,3,3,3,3,1,1,1
1,1,1,1,3,3,3,3,3,3,3,3,3,3,3,3,3,1,1,1,1
1,1,1,1,3,3,3,3,3,3,3,3,3,3,3,3,3,1,1,1,1
1,1,1,1,1,3,3,3,3,3,3,3,3,3,3,3,1,1,1,1,1
1,1,1,1,1,1,1,3,3,3,3,3,3,3,1,1,1,1,1,1,1
1,1,1,1,1,1,1,1,1,3,3,3,1,1,1,1,1,1,1,1,1
1,1,1,1,1,1,1,1,1,1,1,1,1,1,1,1,1,1,1,1,1
1,1,1,1,1,1,1,1,1,1,1,1,1,1,1,1,1,1,1,1,1
endlayer

layer
1,1,1,1,1,1,1,1,1,1,1,1,1,1,1,1,1,1,1,1,1
1,1,1,1,1,1,1,1,1,1,1,1,1,1,1,1,1,1,1,1,1
1,1,1,1,1,1,1,1,1,1,4,1,1,1,1,1,1,1,1,1,1
1,1,1,1,1,1,1,1,0,0,0,0,0,4,1,1,1,1,1,1,1
1,1,1,1,1,0,0,4,0,0,0,0,0,0,0,0,1,1,1,1,1
1,1,1,1,0,0,0,0,0,0,0,0,4,0,0,0,4,1,1,1,1
1,1,1,1,4,0,0,0,0,4,0,0,0,0,0,0,0,1,1,1,1
1,1,1,1,0,0,0,0,0,0,0,0,0,0,0,0,0,1,1,1,1
1,1,1,1,0,0,0,0,4,0,0,0,0,0,4,0,0,4,1,1,1
1,1,4,0,0,4,0,0,0,4,4,0,0,0,0,0,0,0,4,1,1
1,1,0,0,0,0,0,0,0,4,0,4,0,0,0,0,0,0,1,1,1
1,1,1,0,0,0,0,0,4,0,0,0,0,0,0,4,0,0,1,1,1
1,1,1,0,0,4,0,0,4,0,0,0,0,0,0,0,0,1,1,1,1
1,1,1,1,0,0,0,0,0,0,4,0,4,0,0,0,1,1,1,1,1
1,1,1,1,0,0,0,4,0,0,0,0,0,0,0,4,1,1,1,1,1
1,1,1,1,0,0,0,0,0,0,4,0,0,0,0,0,1,1,1,1,1
1,1,1,1,1,1,0,0,0,0,0,0,0,0,1,1,1,1,1,1,1
1,1,1,1,1,1,1,1,4,0,4,1,1,1,1,1,1,1,1,1,1
1,1,1,1,1,1,1,1,1,1,1,1,1,1,1,1,1,1,1,1,1
1,1,1,1,1,1,1,1,1,1,1,1,1,1,1,1,1,1,1,1,1
1,1,1,1,1,1,1,1,1,1,1,1,1,1,1,1,1,1,1,1,1
endlayer

layer
1,1,1,1,1,1,1,1,1,1,1,1,1,1,1,1,1,1,1,1,1
1,1,1,1,1,1,1,1,1,1,1,1,1,1,1,1,1,1,1,1,1
1,1,1,1,1,1,1,1,1,1,1,1,1,1,1,1,1,1,1,1,1
1,1,1,1,1,1,1,1,1,1,1,1,1,1,1,1,1,1,1,1,1
1,1,1,1,1,1,1,1,1,0,0,0,0,1,1,1,1,1,1,1,1
1,1,1,1,1,1,1,0,0,0,0,0,0,0,0,0,1,1,1,1,1
1,1,1,1,1,1,0,0,0,0,0,0,0,0,0,0,1,1,1,1,1
1,1,1,1,1,0,0,0,0,0,0,0,0,0,0,0,0,1,1,1,1
1,1,1,1,1,0,0,0,0,0,0,0,0,0,0,0,0,0,1,1,1
1,1,1,1,0,0,0,0,0,0,0,0,0,0,0,0,0,0,1,1,1
1,1,1,1,0,0,0,0,0,0,0,0,0,0,0,0,0,1,1,1,1
1,1,1,1,0,0,0,0,0,0,0,0,0,0,0,0,0,1,1,1,1
1,1,1,1,1,0,0,0,0,0,0,0,0,0,0,0,1,1,1,1,1
1,1,1,1,1,1,0,0,0,0,0,0,0,0,0,1,1,1,1,1,1
1,1,1,1,1,1,0,0,0,0,0,0,0,0,0,1,1,1,1,1,1
1,1,1,1,1,1,1,0,0,0,0,0,0,1,1,1,1,1,1,1,1
1,1,1,1,1,1,1,1,0,0,1,1,1,1,1,1,1,1,1,1,1
1,1,1,1,1,1,1,1,1,1,1,1,1,1,1,1,1,1,1,1,1
1,1,1,1,1,1,1,1,1,1,1,1,1,1,1,1,1,1,1,1,1
1,1,1,1,1,1,1,1,1,1,1,1,1,1,1,1,1,1,1,1,1
1,1,1,1,1,1,1,1,1,1,1,1,1,1,1,1,1,1,1,1,1
endlayer

layer
1,1,1,1,1,1,1,1,1,1,1,1,1,1,1,1,1,1,1,1,1
1,1,1,1,1,1,1,1,1,1,1,1,1,1,1,1,1,1,1,1,1
1,1,1,1,1,1,1,1,1,1,1,1,1,1,1,1,1,1,1,1,1
1,1,1,1,1,1,1,1,1,1,1,1,1,1,1,1,1,1,1,1,1
1,1,1,1,1,1,1,1,1,1,1,1,1,1,1,1,1,1,1,1,1
1,1,1,1,1,1,1,1,1,1,1,1,1,1,1,1,1,1,1,1,1
1,1,1,1,1,1,1,1,1,1,1,1,1,1,1,1,1,1,1,1,1
1,1,1,1,1,1,1,1,1,0,0,0,1,1,1,1,1,1,1,1,1
1,1,1,1,1,1,1,0,0,0,0,0,0,0,1,1,1,1,1,1,1
1,1,1,1,1,1,1,0,0,0,0,0,0,0,0,1,1,1,1,1,1
1,1,1,1,1,1,0,0,0,0,0,0,0,0,1,1,1,1,1,1,1
1,1,1,1,1,1,1,0,0,0,0,0,0,0,1,1,1,1,1,1,1
1,1,1,1,1,1,1,1,0,0,0,0,1,1,1,1,1,1,1,1,1
1,1,1,1,1,1,1,1,1,0,1,1,1,1,1,1,1,1,1,1,1
1,1,1,1,1,1,1,1,1,1,1,1,1,1,1,1,1,1,1,1,1
1,1,1,1,1,1,1,1,1,1,1,1,1,1,1,1,1,1,1,1,1
1,1,1,1,1,1,1,1,1,1,1,1,1,1,1,1,1,1,1,1,1
1,1,1,1,1,1,1,1,1,1,1,1,1,1,1,1,1,1,1,1,1
1,1,1,1,1,1,1,1,1,1,1,1,1,1,1,1,1,1,1,1,1
1,1,1,1,1,1,1,1,1,1,1,1,1,1,1,1,1,1,1,1,1
1,1,1,1,1,1,1,1,1,1,1,1,1,1,1,1,1,1,1,1,1
endlayer

