
# Created by Ruins mod version 16.5 Ingame Parser
# authoring Player: ST753M

# Hot air balloon (white with 2 random color vertical stripes) with a treasure
# (botania stuff: a random tool, decorative bauble, potion, and flower)

weight=1
embed_into_distance=-40
random_height_offset=-20,20
acceptable_target_blocks=
unacceptable_target_blocks=lava
dimensions=20,13,13
allowable_overhang=9999
max_cut_in=0
cut_in_buffer=0
max_leveling=0
leveling_buffer=-1
preserve_water=0
preserve_lava=0
uniqueMinDistance=1500
spawnMinDistance=500

biomesToSpawnIn=beaches,white_beach,stone_beach,gravel_beach,beach,sky,void

rule1=0,100,minecraft:oak_stairs-3
^0,100,minecraft:spruce_stairs-3
^0,100,minecraft:birch_stairs-3
^0,100,minecraft:jungle_stairs-3
rule2^0,100,minecraft:oak_stairs-1
^0,100,minecraft:spruce_stairs-1
^0,100,minecraft:birch_stairs-1
^0,100,minecraft:jungle_stairs-1
rule3^0,100,minecraft:wooden_slab-0
^0,100,minecraft:wooden_slab-1
^0,100,minecraft:wooden_slab-2
^0,100,minecraft:wooden_slab-3
rule4^0,100,minecraft:oak_stairs-2
^0,100,minecraft:spruce_stairs-2
^0,100,minecraft:birch_stairs-2
^0,100,minecraft:jungle_stairs-2
rule5^0,100,minecraft:oak_stairs-0
^0,100,minecraft:spruce_stairs-0
^0,100,minecraft:birch_stairs-0
^0,100,minecraft:jungle_stairs-0
rule6^0,100,minecraft:fence-0
^0,100,minecraft:spruce_fence-0
^0,100,minecraft:birch_fence-0
^0,100,minecraft:jungle_fence-0

rule7=0,100,IInventory;minecraft:chest;botania:miniisland#1#7#11+botania:auraring#1#0#14+botania:cosmetic#1#16#15+botania:brewvial#{brewKey:"resistance"}#0#24-4,IInventory;minecraft:chest;botania:cosmetic#1#22#6+botania:brewvial#{brewKey:"strength"}#0#12+botania:starfield#1#0#15+botania:floatingspecialflower#{type:"puredaisy"}#0#19-4,IInventory;minecraft:chest;botania:cosmetic#1#26#4+botania:brewvial#{brewKey:"absorption"}#0#15+botania:miniisland#1#1#17+botania:dirtrod#1#0#20-4,IInventory;minecraft:chest;botania:miniisland#1#0#7+botania:cosmetic#1#27#11+botania:brewvial#{brewKey:"emptiness"}#0#13+botania:lavapendant#1#0#23-4,IInventory;minecraft:chest;botania:miniisland#1#11#2+botania:cosmetic#1#18#7+botania:skydirtrod#1#0#13+botania:brewvial#{brewKey:"jumpBoost"}#0#24-4,IInventory;minecraft:chest;botania:magnetring#{}#0#12+botania:brewvial#{brewKey:"bloodthirst"}#0#14+botania:miniisland#1#3#16+botania:cosmetic#1#13#19-4,IInventory;minecraft:chest;botania:miniisland#1#12#10+botania:brewvial#{brewKey:"nightVision"}#0#14+botania:cosmetic#1#19#16+botania:miningring#1#0#21-4,IInventory;minecraft:chest;botania:miniisland#1#10#10+botania:brewvial#{brewKey:"fireResistance"}#0#11+botania:cosmetic#1#5#15+botania:tornadorod#{}#0#22-4,IInventory;minecraft:chest;botania:brewvial#{brewKey:"soulCross"}#0#6+botania:miniisland#1#2#12+botania:swapring#1#0#18+botania:cosmetic#1#15#23-4,IInventory;minecraft:chest;botania:cosmetic#1#31#2+botania:grasshorn#1#2#13+botania:miniisland#1#8#15+botania:brewvial#{brewKey:"allure"}#0#20-4,IInventory;minecraft:chest;botania:miniisland#1#6#10+botania:brewvial#{brewKey:"warpWard"}#0#13+botania:cosmetic#1#4#16+botania:recordgaia1#1#0#23-4,IInventory;minecraft:chest;botania:cosmetic#1#2#5+botania:miniisland#1#9#10+botania:brewvial#{brewKey:"speed"}#0#11+botania:cobblerod#1#0#23-4,IInventory;minecraft:chest;botania:floatingspecialflower#{type:"puredaisy"}#0#4+botania:cosmetic#1#11#10+botania:waterrod#1#0#15+botania:brewvial#{brewKey:"regen"}#0#21-4,IInventory;minecraft:chest;botania:miniisland#1#13#4+botania:brewvial#{brewKey:"waterBreathing"}#0#11+botania:grasshorn#1#0#21+botania:cosmetic#1#24#24-4,IInventory;minecraft:chest;botania:miniisland#1#14#10+botania:brewvial#{brewKey:"invisibility"}#0#13+botania:cosmetic#1#25#21+botania:firerod#1#0#25-4,IInventory;minecraft:chest;botania:cosmetic#1#17#6+botania:waterring#1#0#12+botania:miniisland#1#5#22+botania:brewvial#{brewKey:"haste"}#0#24-4,IInventory;minecraft:chest;botania:cosmetic#1#10#5+botania:recordgaia2#1#0#10+botania:miniisland#1#15#16+botania:brewvial#{brewKey:"featherFeet"}#0#22-4,IInventory;minecraft:chest;botania:cosmetic#1#23#4+botania:grasshorn#1#1#15+botania:brewvial#{brewKey:"clear"}#0#20+botania:miniisland#1#4#22-4

rule8=0,100,minecraft:wool-1
^0,100,minecraft:wool-2
^0,100,minecraft:wool-3
^0,100,minecraft:wool-4
^0,100,minecraft:wool-5
^0,100,minecraft:wool-6
^0,100,minecraft:wool-8
^0,100,minecraft:wool-9
^0,100,minecraft:wool-10
^0,100,minecraft:wool-11
^0,100,minecraft:wool-13
^0,100,minecraft:wool-14
rule9=0,100,minecraft:wool-0
rule10=0,100,minecraft:wool-1
^0,100,minecraft:wool-2
^0,100,minecraft:wool-3
^0,100,minecraft:wool-4
^0,100,minecraft:wool-5
^0,100,minecraft:wool-6
^0,100,minecraft:wool-8
^0,100,minecraft:wool-9
^0,100,minecraft:wool-10
^0,100,minecraft:wool-11
^0,100,minecraft:wool-13
^0,100,minecraft:wool-14

layer
0,0,0,0,0,0,0,0,0,0,0,0,0
0,0,0,0,0,0,0,0,0,0,0,0,0
0,0,0,0,0,0,0,0,0,0,0,0,0
0,0,0,0,0,0,0,0,0,0,0,0,0
0,0,0,0,0,0,0,0,0,0,0,0,0
0,0,0,0,0,2,2,1,0,0,0,0,0
0,0,0,0,0,4,3,1,0,0,0,0,0
0,0,0,0,0,4,5,5,0,0,0,0,0
0,0,0,0,0,0,0,0,0,0,0,0,0
0,0,0,0,0,0,0,0,0,0,0,0,0
0,0,0,0,0,0,0,0,0,0,0,0,0
0,0,0,0,0,0,0,0,0,0,0,0,0
0,0,0,0,0,0,0,0,0,0,0,0,0
endlayer

layer
0,0,0,0,0,0,0,0,0,0,0,0,0
0,0,0,0,0,0,0,0,0,0,0,0,0
0,0,0,0,0,0,0,0,0,0,0,0,0
0,0,0,0,0,0,0,0,0,0,0,0,0
0,0,0,0,0,0,0,0,0,0,0,0,0
0,0,0,0,0,6,6,6,0,0,0,0,0
0,0,0,0,0,6,7,6,0,0,0,0,0
0,0,0,0,0,6,6,6,0,0,0,0,0
0,0,0,0,0,0,0,0,0,0,0,0,0
0,0,0,0,0,0,0,0,0,0,0,0,0
0,0,0,0,0,0,0,0,0,0,0,0,0
0,0,0,0,0,0,0,0,0,0,0,0,0
0,0,0,0,0,0,0,0,0,0,0,0,0
endlayer

layer
0,0,0,0,0,0,0,0,0,0,0,0,0
0,0,0,0,0,0,0,0,0,0,0,0,0
0,0,0,0,0,0,0,0,0,0,0,0,0
0,0,0,0,0,0,0,0,0,0,0,0,0
0,0,0,0,0,0,0,0,0,0,0,0,0
0,0,0,0,0,6,0,6,0,0,0,0,0
0,0,0,0,0,0,0,0,0,0,0,0,0
0,0,0,0,0,6,0,6,0,0,0,0,0
0,0,0,0,0,0,0,0,0,0,0,0,0
0,0,0,0,0,0,0,0,0,0,0,0,0
0,0,0,0,0,0,0,0,0,0,0,0,0
0,0,0,0,0,0,0,0,0,0,0,0,0
0,0,0,0,0,0,0,0,0,0,0,0,0
endlayer

layer
0,0,0,0,0,0,0,0,0,0,0,0,0
0,0,0,0,0,0,0,0,0,0,0,0,0
0,0,0,0,0,0,0,0,0,0,0,0,0
0,0,0,0,0,0,0,0,0,0,0,0,0
0,0,0,0,0,0,0,0,0,0,0,0,0
0,0,0,0,0,6,0,6,0,0,0,0,0
0,0,0,0,0,0,0,0,0,0,0,0,0
0,0,0,0,0,6,0,6,0,0,0,0,0
0,0,0,0,0,0,0,0,0,0,0,0,0
0,0,0,0,0,0,0,0,0,0,0,0,0
0,0,0,0,0,0,0,0,0,0,0,0,0
0,0,0,0,0,0,0,0,0,0,0,0,0
0,0,0,0,0,0,0,0,0,0,0,0,0
endlayer

layer
0,0,0,0,0,0,0,0,0,0,0,0,0
0,0,0,0,0,0,0,0,0,0,0,0,0
0,0,0,0,0,0,0,0,0,0,0,0,0
0,0,0,0,0,0,0,0,0,0,0,0,0
0,0,0,0,0,0,0,0,0,0,0,0,0
0,0,0,0,0,10,9,8,0,0,0,0,0
0,0,0,0,0,9,0,9,0,0,0,0,0
0,0,0,0,0,8,9,10,0,0,0,0,0
0,0,0,0,0,0,0,0,0,0,0,0,0
0,0,0,0,0,0,0,0,0,0,0,0,0
0,0,0,0,0,0,0,0,0,0,0,0,0
0,0,0,0,0,0,0,0,0,0,0,0,0
0,0,0,0,0,0,0,0,0,0,0,0,0
endlayer

layer
0,0,0,0,0,0,0,0,0,0,0,0,0
0,0,0,0,0,0,0,0,0,0,0,0,0
0,0,0,0,0,0,0,0,0,0,0,0,0
0,0,0,0,0,0,0,0,0,0,0,0,0
0,0,0,0,0,10,9,9,0,0,0,0,0
0,0,0,0,9,0,0,0,8,0,0,0,0
0,0,0,0,9,0,0,0,9,0,0,0,0
0,0,0,0,8,0,0,0,9,0,0,0,0
0,0,0,0,0,9,9,10,0,0,0,0,0
0,0,0,0,0,0,0,0,0,0,0,0,0
0,0,0,0,0,0,0,0,0,0,0,0,0
0,0,0,0,0,0,0,0,0,0,0,0,0
0,0,0,0,0,0,0,0,0,0,0,0,0
endlayer

layer
0,0,0,0,0,0,0,0,0,0,0,0,0
0,0,0,0,0,0,0,0,0,0,0,0,0
0,0,0,0,0,0,0,0,0,0,0,0,0
0,0,0,0,0,10,9,9,0,0,0,0,0
0,0,0,0,10,0,0,0,8,0,0,0,0
0,0,0,9,0,0,0,0,0,8,0,0,0
0,0,0,9,0,0,0,0,0,9,0,0,0
0,0,0,8,0,0,0,0,0,9,0,0,0
0,0,0,0,8,0,0,0,10,0,0,0,0
0,0,0,0,0,9,9,10,0,0,0,0,0
0,0,0,0,0,0,0,0,0,0,0,0,0
0,0,0,0,0,0,0,0,0,0,0,0,0
0,0,0,0,0,0,0,0,0,0,0,0,0
endlayer

layer
0,0,0,0,0,0,0,0,0,0,0,0,0
0,0,0,0,0,0,0,0,0,0,0,0,0
0,0,0,0,0,10,9,9,0,0,0,0,0
0,0,0,0,10,0,0,0,8,0,0,0,0
0,0,0,10,0,0,0,0,0,8,0,0,0
0,0,9,0,0,0,0,0,0,0,8,0,0
0,0,9,0,0,0,0,0,0,0,9,0,0
0,0,8,0,0,0,0,0,0,0,9,0,0
0,0,0,8,0,0,0,0,0,9,0,0,0
0,0,0,0,9,0,0,0,10,0,0,0,0
0,0,0,0,0,9,9,10,0,0,0,0,0
0,0,0,0,0,0,0,0,0,0,0,0,0
0,0,0,0,0,0,0,0,0,0,0,0,0
endlayer

layer
0,0,0,0,0,0,0,0,0,0,0,0,0
0,0,0,0,0,0,9,0,0,0,0,0,0
0,0,0,0,10,10,0,9,9,0,0,0,0
0,0,0,10,0,0,0,0,0,8,0,0,0
0,0,9,0,0,0,0,0,0,0,8,0,0
0,0,9,0,0,0,0,0,0,0,8,0,0
0,9,0,0,0,0,0,0,0,0,0,9,0
0,0,8,0,0,0,0,0,0,0,9,0,0
0,0,8,0,0,0,0,0,0,0,9,0,0
0,0,0,8,0,0,0,0,0,10,0,0,0
0,0,0,0,9,9,0,10,10,0,0,0,0
0,0,0,0,0,0,9,0,0,0,0,0,0
0,0,0,0,0,0,0,0,0,0,0,0,0
endlayer

layer
0,0,0,0,0,0,0,0,0,0,0,0,0
0,0,0,0,0,10,9,9,0,0,0,0,0
0,0,0,10,10,0,0,0,9,8,0,0,0
0,0,10,0,0,0,0,0,0,0,8,0,0
0,0,9,0,0,0,0,0,0,0,8,0,0
0,9,0,0,0,0,0,0,0,0,0,8,0
0,9,0,0,0,0,0,0,0,0,0,9,0
0,8,0,0,0,0,0,0,0,0,0,9,0
0,0,8,0,0,0,0,0,0,0,9,0,0
0,0,8,0,0,0,0,0,0,0,10,0,0
0,0,0,8,9,0,0,0,10,10,0,0,0
0,0,0,0,0,9,9,10,0,0,0,0,0
0,0,0,0,0,0,0,0,0,0,0,0,0
endlayer

layer
0,0,0,0,0,0,9,0,0,0,0,0,0
0,0,0,0,10,9,0,9,9,0,0,0,0
0,0,10,10,0,0,0,0,0,8,8,0,0
0,0,10,0,0,0,0,0,0,0,8,0,0
0,9,0,0,0,0,0,0,0,0,0,8,0
0,9,0,0,0,0,0,0,0,0,0,9,0
9,0,0,0,0,0,0,0,0,0,0,0,9
0,9,0,0,0,0,0,0,0,0,0,9,0
0,8,0,0,0,0,0,0,0,0,0,9,0
0,0,8,0,0,0,0,0,0,0,10,0,0
0,0,8,8,0,0,0,0,0,10,10,0,0
0,0,0,0,9,9,0,9,10,0,0,0,0
0,0,0,0,0,0,9,0,0,0,0,0,0
endlayer

layer
0,0,0,0,0,9,9,9,0,0,0,0,0
0,0,0,10,10,0,0,0,9,9,0,0,0
0,0,10,0,0,0,0,0,0,0,8,0,0
0,9,0,0,0,0,0,0,0,0,0,8,0
0,9,0,0,0,0,0,0,0,0,0,8,0
9,0,0,0,0,0,0,0,0,0,0,0,9
9,0,0,0,0,0,0,0,0,0,0,0,9
9,0,0,0,0,0,0,0,0,0,0,0,9
0,8,0,0,0,0,0,0,0,0,0,9,0
0,8,0,0,0,0,0,0,0,0,0,9,0
0,0,8,0,0,0,0,0,0,0,10,0,0
0,0,0,9,9,0,0,0,10,10,0,0,0
0,0,0,0,0,9,9,9,0,0,0,0,0
endlayer

layer
0,0,0,0,10,9,9,9,9,0,0,0,0
0,0,10,10,0,0,0,0,0,9,8,0,0
0,10,0,0,0,0,0,0,0,0,0,8,0
0,9,0,0,0,0,0,0,0,0,0,8,0
9,9,0,0,0,0,0,0,0,0,0,0,8
9,0,0,0,0,0,0,0,0,0,0,0,9
9,0,0,0,0,0,0,0,0,0,0,0,9
9,0,0,0,0,0,0,0,0,0,0,0,9
8,0,0,0,0,0,0,0,0,0,0,0,9
0,8,0,0,0,0,0,0,0,0,0,9,0
0,8,0,0,0,0,0,0,0,0,0,10,0
0,0,8,9,0,0,0,0,0,10,10,0,0
0,0,0,0,9,9,9,9,10,0,0,0,0
endlayer

layer
0,0,0,0,10,9,9,9,9,0,0,0,0
0,0,10,10,0,0,0,0,0,9,8,0,0
0,10,0,0,0,0,0,0,0,0,0,8,0
0,9,0,0,0,0,0,0,0,0,0,8,0
9,0,0,0,0,0,0,0,0,0,0,0,8
9,0,0,0,0,0,0,0,0,0,0,0,9
9,0,0,0,0,0,0,0,0,0,0,0,9
9,0,0,0,0,0,0,0,0,0,0,0,9
8,0,0,0,0,0,0,0,0,0,0,0,9
0,8,0,0,0,0,0,0,0,0,0,9,0
0,8,0,0,0,0,0,0,0,0,0,10,0
0,0,8,9,0,0,0,0,0,10,10,0,0
0,0,0,0,9,9,9,9,10,0,0,0,0
endlayer

layer
0,0,0,0,10,9,9,9,9,0,0,0,0
0,0,10,10,0,0,0,0,0,9,8,0,0
0,10,0,0,0,0,0,0,0,0,0,8,0
0,9,0,0,0,0,0,0,0,0,0,8,0
9,0,0,0,0,0,0,0,0,0,0,0,8
9,0,0,0,0,0,0,0,0,0,0,0,9
9,0,0,0,0,0,0,0,0,0,0,0,9
9,0,0,0,0,0,0,0,0,0,0,0,9
8,0,0,0,0,0,0,0,0,0,0,0,9
0,8,0,0,0,0,0,0,0,0,0,9,0
0,8,0,0,0,0,0,0,0,0,0,10,0
0,0,8,9,0,0,0,0,0,10,10,0,0
0,0,0,0,9,9,9,9,10,0,0,0,0
endlayer

layer
0,0,0,0,0,9,9,9,0,0,0,0,0
0,0,0,10,10,0,0,0,9,9,0,0,0
0,0,10,0,0,0,0,0,0,0,8,0,0
0,9,0,0,0,0,0,0,0,0,0,8,0
0,9,0,0,0,0,0,0,0,0,0,8,0
9,0,0,0,0,0,0,0,0,0,0,0,9
9,0,0,0,0,0,0,0,0,0,0,0,9
9,0,0,0,0,0,0,0,0,0,0,0,9
0,8,0,0,0,0,0,0,0,0,0,9,0
0,8,0,0,0,0,0,0,0,0,0,9,0
0,0,8,0,0,0,0,0,0,0,10,0,0
0,0,0,9,9,0,0,0,10,10,0,0,0
0,0,0,0,0,9,9,9,0,0,0,0,0
endlayer

layer
0,0,0,0,0,0,0,0,0,0,0,0,0
0,0,0,0,10,9,9,9,9,0,0,0,0
0,0,10,10,0,0,0,0,0,8,8,0,0
0,0,10,0,0,0,0,0,0,0,8,0,0
0,9,0,0,0,0,0,0,0,0,0,8,0
0,9,0,0,0,0,0,0,0,0,0,9,0
0,9,0,0,0,0,0,0,0,0,0,9,0
0,9,0,0,0,0,0,0,0,0,0,9,0
0,8,0,0,0,0,0,0,0,0,0,9,0
0,0,8,0,0,0,0,0,0,0,10,0,0
0,0,8,8,0,0,0,0,0,10,10,0,0
0,0,0,0,9,9,9,9,10,0,0,0,0
0,0,0,0,0,0,0,0,0,0,0,0,0
endlayer

layer
0,0,0,0,0,0,0,0,0,0,0,0,0
0,0,0,0,0,10,9,9,0,0,0,0,0
0,0,0,10,10,0,0,0,9,8,0,0,0
0,0,10,10,0,0,0,0,0,8,8,0,0
0,0,9,0,0,0,0,0,0,0,8,0,0
0,9,0,0,0,0,0,0,0,0,0,8,0
0,9,0,0,0,0,0,0,0,0,0,9,0
0,8,0,0,0,0,0,0,0,0,0,9,0
0,0,8,0,0,0,0,0,0,0,9,0,0
0,0,8,8,0,0,0,0,0,10,10,0,0
0,0,0,8,9,0,0,0,10,10,0,0,0
0,0,0,0,0,9,9,10,0,0,0,0,0
0,0,0,0,0,0,0,0,0,0,0,0,0
endlayer

layer
0,0,0,0,0,0,0,0,0,0,0,0,0
0,0,0,0,0,0,0,0,0,0,0,0,0
0,0,0,0,0,10,9,9,0,0,0,0,0
0,0,0,0,10,10,9,9,9,0,0,0,0
0,0,0,9,10,0,0,0,8,8,0,0,0
0,0,9,9,0,0,0,0,0,8,8,0,0
0,0,9,9,0,0,0,0,0,9,9,0,0
0,0,8,8,0,0,0,0,0,9,9,0,0
0,0,0,8,8,0,0,0,10,9,0,0,0
0,0,0,0,9,9,9,10,10,0,0,0,0
0,0,0,0,0,9,9,10,0,0,0,0,0
0,0,0,0,0,0,0,0,0,0,0,0,0
0,0,0,0,0,0,0,0,0,0,0,0,0
endlayer

layer
0,0,0,0,0,0,0,0,0,0,0,0,0
0,0,0,0,0,0,0,0,0,0,0,0,0
0,0,0,0,0,0,0,0,0,0,0,0,0
0,0,0,0,0,0,0,0,0,0,0,0,0
0,0,0,0,0,10,9,9,0,0,0,0,0
0,0,0,0,9,10,9,8,8,0,0,0,0
0,0,0,0,9,9,9,9,9,0,0,0,0
0,0,0,0,8,8,9,10,9,0,0,0,0
0,0,0,0,0,9,9,10,0,0,0,0,0
0,0,0,0,0,0,0,0,0,0,0,0,0
0,0,0,0,0,0,0,0,0,0,0,0,0
0,0,0,0,0,0,0,0,0,0,0,0,0
0,0,0,0,0,0,0,0,0,0,0,0,0
endlayer

