# Desert Mini Village Dungeon (NO CB)
# MC 1.7.10; 26 Oct 2014
# Created by Ruins mod version 15.1 Ingame Parser
# authoring Player: Jordan_Greywolf
# 6 Jan 2016 -- "Sewer Dungeon" level added.
# Updated for MC 1.8: 24 Mar 2016
# Updated for MC 1.9: 26 Apr 2016
# Updated for MC 1.11: 11 Jan 2017
# Updated for MC 1.12: 23 Jun 2017
# Updated to MC 1.12.1: 12 Sep 2017

biomesToSpawnIn=desert,desert m,desert oil field,deserthills,dunes,lush desert,oasis,mountainous desert,rwg_hotdesert,rwg_oasis,mutated_desert,desert_hills

uniqueMinDistance=5000

weight=1
embed_into_distance=8
acceptable_target_blocks=

unacceptable_target_blocks=cloud,Natura:Cloud,slime_congealed,slime_dirt,slime_grass,command_block

dimensions=20,36,36
allowable_overhang=0
max_leveling=5
leveling_buffer=-1
preserve_water=0
preserve_lava=0
preserve_plants=1

# Smooth Sandstone
rule1=0,100,minecraft:sandstone-2

# Plain Sandstone
rule2=0,100,minecraft:sandstone-0

# placeholder
rule3=0,100,minecraft:sandstone

# Flowing Water (pool, fountain, troughs)
rule4=0,100,minecraft:flowing_water

# Clay - Magenta
rule5=0,100,minecraft:stained_hardened_clay-2

# Wooden Fence
rule6=0,100,minecraft:fence-0

# Chiseled Sandstone
rule7=0,100,minecraft:sandstone-1

# Treasure!
rule8=0,100,ChestGenHook:chests/simple_dungeon:2-5,ChestGenHook:chests/spawn_bonus_chest:6-5,ChestGenHook:chests/desert_pyramid:3-5,ChestGenHook:chests/village_blacksmith:3-5

# Placeholder
rule9=0,100,minecraft:sandstone

# Placeholder
rule10=0,100,minecraft:sandstone

# Monster Spawner (Sand Spirit)
rule11=0,100,MobSpawner:Skeleton


# Standing Torch
rule12=1,100,minecraft:torch-5

rule13=0,100,minecraft:sandstone_stairs-3
rule14=0,100,minecraft:sandstone_stairs-0
rule15=0,100,minecraft:sandstone_stairs-2
rule16=0,100,minecraft:sandstone_stairs-1
rule17=0,100,minecraft:sandstone_stairs-7
rule18=0,100,minecraft:sandstone_stairs-4
rule19=0,100,minecraft:sandstone_stairs-6

# Stained Clay (Cyan)
rule20=0,100,minecraft:stained_hardened_clay-9

# Stained Clay (Light Blue)
rule21=0,100,minecraft:stained_hardened_clay-3

# Stained Clay (Light Gray)
rule22=0,100,minecraft:stained_hardened_clay-8

rule23=0,100,minecraft:sandstone_stairs-5

# Stained Clay (Blue)
rule24=0,100,minecraft:stained_hardened_clay-11

# Stained Clay (Green)
rule25=0,100,minecraft:stained_hardened_clay-13

# Stained Clay (White)
rule26=0,100,minecraft:stained_hardened_clay-0

# Chiseled Quartz Block
rule27=0,100,minecraft:quartz_block-1

# Placeholder
rule28=0,100,minecraft:sandstone

# Placeholder
rule29=0,100,minecraft:sandstone

# Placeholder
rule30=0,100,minecraft:sandstone

# Placeholder
rule31=0,100,minecraft:sandstone

# Placeholder
rule32=0,100,minecraft:sandstone

# Placeholder
rule33=0,100,minecraft:sandstone

# Placeholder
rule34=0,100,minecraft:sandstone

# Stone Slab (lower)
rule35=0,100,minecraft:stone_slab-1

# Double Stone Slab
rule36=0,100,minecraft:double_stone_slab-0

# Grass
rule37=0,100,minecraft:grass-0

# Wool (randomized color)
rule38=0,100,minecraft:wool-2,minecraft:wool-3,minecraft:wool-5,minecraft:wool-6,minecraft:wool-9,minecraft:wool-10,minecraft:wool-11,minecraft:wool-13,minecraft:wool-15


rule39=0,100,minecraft:fence_gate-3
rule40=0,100,minecraft:cauldron-0
rule41=0,100,minecraft:birch_stairs-1
rule42=0,100,minecraft:noteblock-0

# White Carpet (table top, canopy)
rule43=0,100,minecraft:carpet-0

rule44=0,100,minecraft:trapped_chest-2

# Randomized Garden Flowers
rule45=0,100,minecraft:red_flower-0,minecraft:red_flower-1,minecraft:red_flower-2

rule46=0,100,minecraft:fence_gate-2
rule47=0,100,minecraft:crafting_table-0
rule48=0,100,IInventory;minecraft:lit_furnace;minecraft:coal#2#1#1-4
rule49=0,100,minecraft:jungle_door-2

# Randomized Fruit (melon, pumpkin)
rule50=0,100,minecraft:melon_block-0,minecraft:pumpkin-4,minecraft:lit_pumpkin

rule51=0,100,minecraft:trapdoor-11
rule52=0,100,minecraft:dropper-3
rule53=0,100,minecraft:dispenser-3

# Iron Block (body of iron golem that is made upon
# structure spawn)
rule54=0,100,minecraft:iron_block-0


rule55=0,100,minecraft:stone_slab-7

# Barn: hay blocks with randomized positions
rule56=0,100,minecraft:hay_block-0,minecraft:hay_block-4,minecraft:hay_block-8

rule57=0,100,minecraft:fence_gate-0
rule58=0,100,minecraft:jungle_door-0
rule59=0,100,minecraft:birch_stairs-0
rule60=0,100,minecraft:jungle_door-3
rule61=0,100,minecraft:birch_stairs-5
rule62=0,100,minecraft:trapdoor-8
rule63=0,100,minecraft:birch_stairs-7
rule64=0,100,minecraft:birch_stairs-6

# Stone Slab (sandstone, upper)
rule65=0,100,minecraft:stone_slab-9

rule66=0,100,minecraft:jungle_door-1

rule67=0,100,minecraft:ladder-2

# Carpet (red) - canopies & table top
rule68=0,100,minecraft:carpet-14

rule69=0,100,minecraft:jungle_door-8

# Carpet (blue) - table top
rule70=0,100,minecraft:carpet-11

# Wool (yellow, white, red, blue) - canopies
rule71=0,100,minecraft:wool-4
rule72=0,100,minecraft:wool-0
rule73=0,100,minecraft:wool-14
rule74=0,100,minecraft:wool-11

rule75=0,100,minecraft:wooden_slab-2

# Iron Golem Head
rule76=0,100,minecraft:pumpkin-0

# Wool (white) - canopies & table tops
rule77=0,100,minecraft:wool-1

# Wool (brown) - canopies
rule78=0,100,minecraft:wool-12

rule79=0,100,minecraft:wooden_slab-10

# Carpet (yellow) - canopies
rule80=0,100,minecraft:carpet-4

rule81=0,100,minecraft:lit_redstone_lamp-0

# Carpet (orange) - canopies
rule82=0,100,minecraft:carpet-1

# Jungle Leaves (no decay)
rule83=0,100,minecraft:leaves-7

# Fountain Center (light blue stained glass)
rule84=0,100,minecraft:stained_glass-3

# Carpet (brown) - canopies
rule85=0,100,minecraft:carpet-12

rule86=0,100,minecraft:spruce_stairs-1
rule87=0,100,minecraft:spruce_stairs-2
rule88=0,100,minecraft:birch_stairs-4

# Stained Hardened Clay (brown) - antiquities shop rooftop
rule89=0,100,minecraft:stained_hardened_clay-12

rule90=0,100,minecraft:redstone_block-0
rule91=0,100,minecraft:birch_stairs-2
rule92=0,100,minecraft:planks-2
rule93=0,100,minecraft:birch_stairs-3
rule94=0,100,minecraft:ladder-3

# Rooftop garden farmland
rule95=0,100,minecraft:farmland-7,minecraft:farmland-4,minecraft:farmland-2

rule96=0,100,minecraft:trapdoor-2

# Rooftop garden wheat
rule97=0,100,minecraft:wheat-7,minecraft:wheat-4,minecraft:wheat-1

rule98=0,100,minecraft:trapdoor-3
rule99=0,100,minecraft:quartz_stairs-2
rule100=0,100,minecraft:quartz_stairs-0

# Quartz Slab (upper)
rule101=0,100,minecraft:stone_slab-15

rule102=0,100,minecraft:quartz_stairs-3
rule103=0,100,minecraft:quartz_stairs-1


layer
1,2,2,2,2,2,2,2,2,2,2,2,2,2,2,2,2,2,2,2,2,2,2,2,2,2,2,2,2,2,2,2,2,2,2,1
2,2,2,2,2,2,2,2,2,2,2,2,2,2,2,2,2,2,2,2,2,2,2,2,2,2,2,2,2,2,2,2,2,2,2,2
2,2,2,2,2,2,2,2,2,2,2,2,2,2,2,2,2,2,2,2,2,2,2,2,2,2,2,2,2,2,2,2,2,2,2,2
2,2,2,2,2,2,2,2,2,2,2,2,2,2,2,2,2,2,2,2,2,2,2,2,2,2,2,2,2,2,2,2,2,2,2,2
2,2,2,2,2,2,2,2,2,2,2,2,2,2,2,2,2,2,2,2,2,2,2,2,2,2,2,2,2,2,2,2,2,2,2,2
2,2,2,2,2,2,2,3,2,2,2,2,2,2,2,2,2,2,2,2,2,2,2,2,2,2,2,2,2,2,2,2,2,2,2,2
2,2,2,2,2,2,2,2,2,2,2,2,2,2,2,2,2,2,2,2,2,2,2,2,2,2,2,2,2,2,2,2,2,2,2,2
2,2,2,2,2,2,2,2,2,2,2,2,2,2,2,2,2,2,2,2,2,2,2,2,2,2,2,2,2,2,2,2,2,2,2,2
2,2,2,2,2,2,2,2,2,2,2,2,2,2,2,2,2,2,2,2,2,2,2,2,2,2,2,2,2,2,2,2,2,2,2,2
2,2,2,2,2,2,2,2,2,2,2,2,2,2,2,2,2,2,2,2,2,2,2,2,2,2,2,2,2,2,2,2,2,2,2,2
2,2,2,2,2,2,2,2,2,2,2,2,2,2,2,2,2,2,2,2,2,2,2,2,2,2,2,2,2,2,2,2,2,2,2,2
2,2,2,2,2,2,2,2,2,2,2,2,2,2,2,2,2,2,2,2,2,2,2,2,2,2,2,2,2,2,2,2,2,2,2,2
2,2,2,2,2,2,2,2,2,2,2,2,2,2,2,2,2,2,2,2,2,2,2,2,2,2,2,2,2,2,2,2,2,2,2,2
2,2,2,2,2,2,2,2,2,2,2,2,2,2,2,2,2,2,2,2,2,2,2,2,2,2,2,2,2,2,2,2,2,2,2,2
2,2,2,2,2,2,2,2,2,2,2,2,2,2,2,2,2,2,2,2,2,2,2,2,2,2,2,2,2,2,2,2,2,2,2,2
2,2,2,2,2,2,2,2,2,2,2,2,2,2,2,2,2,2,2,2,2,2,2,2,2,2,2,2,2,2,2,2,2,2,2,2
2,2,2,2,2,2,2,2,2,2,2,2,2,2,2,2,2,2,2,2,2,2,2,2,2,2,2,2,2,2,2,2,2,2,2,2
2,2,2,2,2,2,2,2,2,2,2,2,2,2,2,2,2,2,2,2,2,2,2,2,2,2,2,2,2,2,2,2,2,2,2,2
2,2,2,2,2,2,2,2,2,2,2,2,2,2,2,2,2,2,2,2,2,2,2,2,2,2,2,2,2,2,2,2,2,2,2,2
2,2,2,2,2,2,2,2,2,2,2,2,2,2,2,2,2,2,2,2,2,2,2,2,2,2,2,2,2,2,2,2,2,2,2,2
2,2,2,2,2,2,2,2,2,2,2,2,2,2,2,2,2,2,2,2,2,2,2,2,2,2,2,2,2,2,2,2,2,2,2,2
2,2,2,2,2,2,2,2,2,2,2,2,2,2,2,2,2,2,2,2,2,2,2,2,2,2,2,2,2,2,2,2,2,2,2,2
2,2,2,2,2,2,2,2,2,2,2,2,2,2,2,2,2,2,2,2,2,2,2,2,2,2,2,2,2,2,2,2,2,2,2,2
2,2,2,2,2,2,2,2,2,2,2,2,2,2,2,2,2,2,2,2,2,2,2,2,2,2,2,2,2,2,2,2,2,2,2,2
2,2,2,2,2,2,2,2,2,2,2,2,2,2,2,2,2,2,2,2,2,2,2,2,2,2,2,2,2,2,2,2,2,2,2,2
2,2,2,2,2,2,2,2,2,2,2,2,2,2,2,2,2,2,2,2,2,2,2,2,2,2,2,2,2,2,2,2,2,2,2,2
2,2,2,2,2,2,2,2,2,2,2,2,2,2,2,2,2,2,2,2,2,2,2,2,2,2,2,2,2,2,2,2,2,2,2,2
2,2,2,2,2,2,2,2,2,2,2,2,2,2,2,2,2,2,2,2,2,2,2,2,2,2,2,2,2,2,2,2,2,2,2,2
2,2,2,2,2,2,2,2,2,2,2,2,2,2,2,2,2,2,2,2,2,2,2,2,2,2,2,2,2,2,2,2,2,2,2,2
2,2,2,2,2,2,2,2,2,2,2,2,2,2,2,2,2,2,2,2,2,2,2,2,2,2,2,2,2,2,2,2,2,2,2,2
2,2,2,2,2,2,2,2,2,2,2,2,2,2,2,2,2,2,2,2,2,2,2,2,2,2,2,2,2,2,2,2,2,2,2,2
2,2,2,2,2,2,2,2,2,2,2,2,2,2,2,2,2,2,2,2,2,2,2,2,2,2,2,2,2,2,2,2,2,2,2,2
2,2,2,2,2,2,2,2,2,2,2,2,2,2,2,2,2,2,2,2,2,2,2,2,2,2,2,2,2,2,2,2,2,2,2,2
2,2,2,2,2,2,2,2,2,2,2,2,2,2,2,2,2,2,2,2,2,2,2,2,2,2,2,2,2,2,2,2,2,2,2,2
2,2,2,2,2,2,2,2,2,2,2,2,2,2,2,2,2,2,2,2,2,2,2,2,2,2,2,2,2,2,2,2,2,2,2,2
1,2,2,2,2,2,2,2,2,2,2,2,2,2,2,2,2,2,2,2,2,2,2,2,2,2,2,2,2,2,2,2,2,2,2,1
endlayer

layer
1,2,2,2,2,2,2,2,2,2,2,2,2,2,2,2,2,2,2,2,2,2,2,2,2,2,2,2,4,1,4,2,2,2,2,1
2,1,2,5,2,4,4,4,2,5,2,1,1,1,2,5,2,5,2,5,2,5,1,1,1,1,1,5,4,1,4,5,1,1,1,2
2,2,5,2,5,4,4,4,5,2,5,2,1,2,5,2,5,2,5,2,5,2,5,1,4,1,1,2,4,4,4,2,1,4,1,2
2,5,2,5,2,4,4,4,2,5,2,5,1,5,2,5,2,5,2,5,2,5,2,1,1,1,1,5,4,4,4,5,1,1,1,2
2,2,5,2,5,4,4,4,5,2,5,2,1,2,5,2,5,2,5,2,5,2,5,1,4,2,1,1,1,4,1,1,5,2,5,2
2,4,4,4,4,4,4,4,4,4,4,4,4,4,4,4,4,4,4,4,4,4,4,4,4,4,4,4,4,4,4,4,4,4,4,2
2,4,4,4,4,4,4,4,4,4,4,4,4,4,4,4,4,4,4,4,4,4,4,4,4,4,4,4,4,4,4,4,4,4,4,2
2,5,2,5,2,4,4,4,2,5,2,5,1,5,2,5,2,5,2,5,2,5,2,1,4,5,1,1,1,4,1,1,2,5,2,2
2,2,5,2,5,4,4,4,5,2,5,2,1,2,5,2,5,2,5,2,5,2,5,1,1,1,1,2,4,1,4,2,1,1,1,2
2,5,2,5,2,4,4,4,2,5,2,5,1,5,2,5,2,5,2,5,2,5,2,1,4,1,1,5,4,4,4,5,1,4,1,2
2,1,5,2,5,4,4,4,5,2,5,1,1,1,5,2,5,2,5,2,5,2,1,1,1,1,1,2,4,4,4,2,1,1,1,2
2,1,1,1,1,4,4,4,1,1,1,1,1,1,1,1,1,5,2,1,1,1,1,1,1,1,1,1,4,4,4,1,1,1,1,2
2,1,5,2,5,4,4,4,5,2,5,1,1,1,5,2,5,2,5,2,5,2,1,1,1,2,5,2,4,4,4,2,5,2,1,2
2,5,2,5,2,4,4,4,2,5,2,5,1,5,2,5,2,5,2,5,2,5,2,1,2,5,2,5,4,4,4,5,2,5,2,2
2,2,5,2,5,4,4,4,5,2,5,2,1,2,5,2,5,2,5,2,5,2,5,1,5,2,5,2,4,4,4,2,5,2,5,2
2,5,2,5,2,4,4,4,2,5,2,5,1,5,2,5,2,5,2,5,2,5,2,1,2,5,2,5,4,4,4,5,2,5,2,2
2,2,5,2,5,4,4,4,5,2,5,2,1,2,5,2,5,2,5,2,5,2,5,1,5,2,5,2,4,4,4,2,5,2,5,2
2,4,4,4,4,4,4,4,4,4,4,4,4,4,4,4,4,4,4,4,4,4,4,4,4,4,4,4,4,4,4,4,4,4,4,2
2,4,4,4,4,4,4,4,4,4,4,4,4,4,4,4,4,4,4,4,4,4,4,4,4,4,4,4,4,4,4,4,4,4,4,2
2,5,2,5,2,4,4,4,2,5,2,5,1,5,2,5,2,5,2,5,2,5,2,1,2,5,2,5,4,4,4,5,2,5,2,2
2,2,5,2,5,4,4,4,5,2,5,2,1,2,5,2,5,2,5,2,5,2,5,1,5,2,5,2,4,4,4,2,5,2,5,2
2,5,2,5,2,4,4,4,2,5,2,5,1,5,2,5,2,5,2,5,2,5,2,1,2,5,2,5,4,4,4,5,2,5,2,2
2,2,5,2,5,4,4,4,5,2,5,2,1,2,5,2,5,2,5,2,5,2,5,1,5,2,5,2,4,4,4,2,5,2,5,2
2,1,2,5,2,4,4,4,2,5,2,1,1,1,2,5,2,5,2,5,2,5,1,1,1,5,2,5,4,4,4,5,2,5,1,2
2,1,1,1,1,4,4,4,1,1,1,1,4,1,1,1,1,2,5,1,1,1,1,1,1,1,1,1,4,4,4,1,1,1,1,2
2,1,2,5,2,4,4,4,2,5,2,1,1,1,2,5,2,5,2,5,2,5,1,1,1,5,2,5,4,4,4,5,2,5,1,2
2,2,5,2,5,4,4,4,5,2,5,2,1,2,5,2,5,2,5,2,5,2,5,1,5,2,5,2,4,4,4,2,5,2,5,2
2,5,2,5,2,4,4,4,2,5,2,5,1,5,2,5,2,5,2,5,2,5,2,1,2,5,2,5,4,4,4,5,2,5,2,2
2,2,5,2,5,4,4,4,5,2,5,2,1,2,5,2,5,2,5,2,5,2,5,1,5,2,5,2,4,4,4,2,5,2,5,2
2,4,4,4,4,4,4,4,4,4,4,4,4,4,4,4,4,4,4,4,4,4,4,4,4,4,4,4,4,4,4,4,4,4,4,2
2,4,4,4,4,4,4,4,4,4,4,4,4,4,4,4,4,4,4,4,4,4,4,4,4,4,4,4,4,4,4,4,4,4,4,2
2,5,2,5,2,4,4,4,2,5,2,5,1,5,2,5,2,5,2,5,2,5,2,1,2,5,2,5,4,4,4,5,2,5,2,2
2,2,5,2,5,4,4,4,5,2,5,2,1,2,5,2,5,2,5,2,5,2,5,1,5,2,5,2,4,4,4,2,5,2,5,2
2,5,2,5,2,4,4,4,2,5,2,5,1,5,2,5,2,5,2,5,2,5,2,1,2,5,2,5,4,4,4,5,2,5,2,2
2,1,5,2,5,4,4,4,5,2,5,1,1,1,5,2,5,2,5,2,5,2,1,1,1,2,5,2,4,4,4,2,5,2,1,2
1,2,2,2,2,2,2,2,2,2,2,2,2,2,2,2,2,2,2,2,2,2,2,2,2,2,2,2,2,2,2,2,2,2,2,1
endlayer

layer
1,2,2,2,2,2,2,2,2,2,2,2,2,2,2,2,1,1,1,1,2,2,2,2,2,2,2,1,1,1,1,1,2,2,2,1
2,1,10,9,8,0,0,0,8,0,0,1,1,1,0,0,0,0,0,0,0,0,1,1,1,1,1,6,0,7,0,6,1,1,1,2
2,0,0,0,0,0,0,0,0,0,0,0,1,0,0,0,0,0,0,0,0,0,0,1,4,1,1,0,0,0,0,0,1,4,1,2
2,0,0,0,0,0,0,0,0,0,0,0,1,0,0,0,0,0,0,0,0,0,0,1,1,1,1,6,0,0,0,6,1,1,1,2
2,0,0,0,0,0,0,0,0,0,0,0,1,0,0,0,0,0,0,0,0,0,0,1,0,0,1,1,1,1,1,1,1,0,0,2
2,0,0,0,0,0,11,0,0,0,0,0,6,0,0,0,0,0,0,0,0,0,0,6,0,0,1,4,4,4,4,1,0,0,0,2
2,0,0,0,0,0,11,0,0,0,0,0,6,0,0,0,0,0,0,0,0,0,0,6,0,0,1,4,4,4,4,1,0,0,0,2
2,0,0,0,0,0,0,0,0,0,0,0,1,0,0,0,0,8,8,0,0,0,0,1,0,0,1,1,1,1,1,1,1,0,0,2
2,0,0,0,0,0,0,0,0,0,0,0,1,0,0,0,0,0,0,0,0,0,0,1,1,1,1,8,0,7,0,8,1,1,1,2
2,0,0,0,0,0,0,0,0,0,0,0,1,0,0,0,0,0,0,0,0,0,0,1,4,1,1,0,0,0,0,0,1,4,1,2
2,1,0,0,0,0,0,0,0,0,0,1,1,1,0,0,0,0,0,0,0,0,1,1,1,1,1,0,0,0,0,0,1,1,1,2
2,1,1,1,1,6,6,6,1,1,1,1,1,1,1,1,1,6,6,1,1,1,1,1,1,1,1,1,6,6,6,1,1,1,1,2
2,1,0,0,0,0,0,0,0,0,0,1,1,1,0,0,0,0,0,0,0,0,1,1,1,8,0,0,0,0,0,0,0,8,1,2
2,0,0,0,0,0,0,0,0,0,0,0,1,0,0,0,0,0,0,0,0,0,0,1,0,0,0,0,0,0,0,0,0,0,0,2
2,0,0,0,0,0,0,0,0,0,0,0,1,0,0,0,0,0,0,0,0,0,0,1,0,0,0,0,0,0,0,0,0,0,0,2
2,0,0,0,0,0,0,0,0,0,0,0,1,0,0,0,0,0,0,0,0,0,0,1,0,0,0,0,0,0,0,0,0,0,0,2
1,0,0,0,8,0,0,0,8,0,0,0,1,0,0,0,0,8,8,0,0,0,0,1,0,0,0,0,0,0,0,0,0,0,0,1
1,0,0,0,0,0,0,0,0,0,0,0,6,0,0,0,0,0,0,0,0,0,0,6,0,0,0,0,0,0,0,0,0,0,0,1
1,0,0,0,0,0,0,0,0,0,0,0,6,0,0,0,0,0,0,0,0,0,0,6,0,0,0,0,0,0,0,0,0,0,0,1
1,0,0,0,0,0,0,0,0,0,0,0,1,0,0,0,0,0,0,0,0,0,0,1,0,0,0,0,0,0,0,0,0,0,0,1
2,0,0,0,0,0,0,0,0,0,0,0,1,0,0,0,0,0,0,0,0,0,0,1,0,0,0,0,0,0,0,0,0,0,0,2
2,0,0,0,0,0,0,0,0,0,0,0,1,0,0,0,0,0,0,0,0,0,0,1,0,0,0,0,0,0,0,0,0,0,0,2
2,0,0,0,0,0,0,0,0,0,0,0,1,0,0,0,0,0,0,0,0,0,0,1,0,0,0,0,0,0,0,0,0,0,0,2
2,1,0,0,0,0,0,0,0,0,0,1,1,1,0,0,0,0,0,0,0,0,1,1,1,0,0,0,0,0,0,0,0,0,1,2
2,1,1,1,1,6,6,6,1,1,1,1,4,1,1,1,1,6,6,1,1,1,1,1,1,1,1,1,6,6,6,1,1,1,1,2
2,1,0,0,0,0,0,0,0,0,0,1,1,1,0,0,0,0,0,0,0,0,1,1,1,0,0,0,0,0,0,0,0,0,1,2
2,0,0,0,0,0,0,0,0,0,0,0,1,0,0,0,0,0,0,0,0,0,0,1,8,0,0,0,0,0,0,0,0,0,8,2
2,0,0,0,0,0,0,0,0,0,0,0,1,0,0,0,0,0,0,0,0,0,0,1,0,0,0,0,0,0,0,0,0,0,0,2
2,0,0,0,8,0,0,0,8,0,0,0,1,0,0,0,0,0,0,0,0,0,0,1,0,0,0,0,0,0,0,0,0,0,0,2
2,0,0,0,0,0,0,0,0,0,0,0,6,0,0,0,0,0,0,0,0,0,0,6,0,0,0,0,0,0,0,0,0,0,0,2
2,0,0,0,0,0,0,0,0,0,0,0,6,0,0,0,0,0,0,0,0,0,0,6,0,0,0,0,0,0,0,0,0,0,0,2
2,0,0,0,0,0,0,0,0,0,0,0,1,0,0,0,0,8,8,0,0,0,0,1,0,0,0,0,0,0,0,0,0,0,0,2
2,0,0,0,0,0,0,0,0,0,0,0,1,0,0,0,0,0,0,0,0,0,0,1,0,0,0,0,0,0,0,0,0,0,0,2
2,0,0,0,0,0,0,0,0,0,0,0,1,0,0,0,0,0,0,0,0,0,0,1,0,0,0,0,0,0,0,0,0,0,0,2
2,1,0,0,0,0,0,0,0,0,0,1,1,1,0,0,0,0,0,0,0,0,1,1,1,0,0,0,0,0,0,0,0,0,1,2
1,2,2,2,2,2,2,2,2,2,2,2,2,2,2,2,1,1,1,1,2,2,2,2,2,2,2,2,2,2,2,2,2,2,2,1
endlayer

layer
1,2,2,2,2,2,2,2,2,2,2,2,2,2,2,2,7,2,2,7,2,2,2,2,2,2,2,7,2,7,2,7,2,2,2,1
2,7,0,0,0,0,0,0,0,0,0,7,1,7,0,0,0,0,0,0,0,0,7,1,1,1,7,12,0,8,0,12,7,1,1,2
2,0,0,0,0,0,0,0,0,0,0,0,2,0,0,0,0,0,0,0,0,0,0,2,4,1,2,0,0,0,0,0,2,4,1,2
2,0,0,0,0,0,0,0,0,0,0,0,2,0,0,0,0,0,0,0,0,0,0,2,0,1,7,12,0,0,0,12,7,1,1,2
2,0,0,0,0,0,0,0,0,0,0,0,7,0,0,0,0,0,0,0,0,0,0,7,0,0,1,7,2,7,2,7,1,0,0,2
2,0,0,0,0,0,0,0,0,0,0,0,6,0,0,0,0,0,0,0,0,0,0,6,0,0,0,4,4,4,4,1,0,0,0,2
2,0,0,0,0,0,0,0,0,0,0,0,6,0,0,0,0,0,0,0,0,0,0,6,0,0,0,4,4,4,4,1,0,0,0,2
2,0,0,0,0,0,0,0,0,0,0,0,7,0,0,0,0,11,11,0,0,0,0,7,0,0,1,7,2,2,2,7,1,0,0,2
2,0,0,0,0,0,0,0,0,0,0,0,2,0,0,0,0,0,0,0,0,0,0,2,0,1,2,0,0,8,0,0,2,1,1,2
2,0,0,0,0,0,0,0,0,0,0,0,2,0,0,0,0,0,0,0,0,0,0,2,4,1,2,0,0,0,0,0,2,4,1,2
2,7,0,0,0,0,0,0,0,0,0,7,1,7,0,0,0,0,0,0,0,0,7,1,1,1,2,0,0,0,0,0,2,1,1,2
2,1,2,2,7,6,6,6,7,2,2,1,1,1,2,2,7,6,6,7,2,2,1,1,1,2,2,7,6,6,6,7,2,2,1,2
2,7,0,0,0,0,0,0,0,0,0,7,1,7,0,0,0,0,0,0,0,0,7,1,7,11,0,0,0,0,0,0,0,11,7,2
2,0,0,0,0,0,0,0,0,0,0,0,2,0,0,0,0,0,0,0,0,0,0,2,0,0,0,0,0,0,0,0,0,0,0,2
2,0,0,0,0,0,0,0,0,0,0,0,2,0,0,0,0,0,0,0,0,0,0,2,0,0,0,0,0,0,0,0,0,0,0,2
2,0,0,0,0,0,0,0,0,0,0,0,2,0,0,0,0,0,0,0,0,0,0,2,0,0,0,0,0,0,0,0,0,0,0,2
7,0,0,0,11,0,0,0,11,0,0,0,7,0,0,0,0,11,11,0,0,0,0,7,0,0,0,0,0,0,0,0,0,0,0,7
2,0,0,0,0,0,0,0,0,0,0,0,6,0,0,0,0,0,0,0,0,0,0,6,0,0,0,0,0,0,0,0,0,0,0,2
2,0,0,0,0,0,0,0,0,0,0,0,6,0,0,0,0,0,0,0,0,0,0,6,0,0,0,0,0,0,0,0,0,0,0,2
7,0,0,0,0,0,0,0,0,0,0,0,7,0,0,0,0,0,0,0,0,0,0,7,0,0,0,0,0,0,0,0,0,0,0,7
2,0,0,0,0,0,0,0,0,0,0,0,2,0,0,0,0,0,0,0,0,0,0,2,0,0,0,0,0,0,0,0,0,0,0,2
2,0,0,0,0,0,0,0,0,0,0,0,2,0,0,0,0,0,0,0,0,0,0,2,0,0,0,0,0,0,0,0,0,0,0,2
2,0,0,0,0,0,0,0,0,0,0,0,2,0,0,0,0,0,0,0,0,0,0,2,0,0,0,0,0,0,0,0,0,0,0,2
2,7,0,0,0,0,0,0,0,0,0,7,1,7,0,0,0,0,0,0,0,0,7,1,7,0,0,0,0,0,0,0,0,0,7,2
2,1,2,2,7,6,6,6,7,2,2,1,4,1,2,2,7,6,6,7,2,2,1,1,1,2,2,7,6,6,6,7,2,2,1,2
2,7,0,0,0,0,0,0,0,0,0,7,1,7,0,0,0,0,0,0,0,0,7,1,7,0,0,0,0,0,0,0,0,0,7,2
2,0,0,0,0,0,0,0,0,0,0,0,2,0,0,0,0,0,0,0,0,0,0,2,11,0,0,0,0,0,0,0,0,0,11,2
2,0,0,0,0,0,0,0,0,0,0,0,2,0,0,0,0,0,0,0,0,0,0,2,0,0,0,0,0,0,0,0,0,0,0,2
2,0,0,0,11,0,0,0,11,0,0,0,7,0,0,0,0,0,0,0,0,0,0,7,0,0,0,0,0,0,0,0,0,0,0,2
2,0,0,0,0,0,0,0,0,0,0,0,6,0,0,0,0,0,0,0,0,0,0,6,0,0,0,0,0,0,0,0,0,0,0,2
2,0,0,0,0,0,0,0,0,0,0,0,6,0,0,0,0,0,0,0,0,0,0,6,0,0,0,0,0,0,0,0,0,0,0,2
2,0,0,0,0,0,0,0,0,0,0,0,7,0,0,0,0,11,11,0,0,0,0,7,0,0,0,0,0,0,0,0,0,0,0,2
2,0,0,0,0,0,0,0,0,0,0,0,2,0,0,0,0,0,0,0,0,0,0,2,0,0,0,0,0,0,0,0,0,0,0,2
2,0,0,0,0,0,0,0,0,0,0,0,2,0,0,0,0,0,0,0,0,0,0,2,0,0,0,0,0,0,0,0,0,0,0,2
2,7,0,0,0,0,0,0,0,0,0,7,1,7,0,0,0,0,0,0,0,0,7,1,7,0,0,0,0,0,0,0,0,0,7,2
1,2,2,2,2,2,2,2,2,2,2,2,2,2,2,2,7,2,2,7,2,2,2,2,2,2,2,2,2,2,2,2,2,2,2,1
endlayer

layer
1,2,2,2,2,2,2,2,2,2,2,2,2,2,2,2,7,2,2,7,2,2,2,2,2,2,2,7,2,7,2,7,2,2,2,1
2,7,0,0,0,0,0,0,0,0,0,7,1,7,0,0,0,0,0,0,0,0,7,1,1,1,7,0,0,0,0,0,7,1,1,2
2,0,0,0,0,0,0,0,0,0,0,0,2,0,0,0,0,0,0,0,0,0,0,2,4,1,2,0,0,0,0,0,2,4,1,2
2,0,0,0,0,0,0,0,0,0,0,0,2,0,0,0,0,0,0,0,0,0,0,2,0,1,7,0,0,0,0,0,7,0,2,2
2,0,0,0,0,0,0,0,0,0,0,0,7,0,0,0,0,0,0,0,0,0,0,7,0,0,1,7,2,7,2,7,6,0,0,2
2,0,0,0,0,0,0,0,0,0,0,0,6,0,0,0,0,0,0,0,0,0,0,6,0,0,0,4,4,4,4,0,0,0,0,2
2,0,0,0,0,0,0,0,0,0,0,0,6,0,0,0,0,0,0,0,0,0,0,6,0,0,0,4,4,4,4,0,0,0,0,2
2,0,0,0,0,0,0,0,0,0,0,0,7,0,0,0,0,0,0,0,0,0,0,7,0,0,1,7,2,2,2,7,6,0,0,2
2,0,0,0,0,0,0,0,0,0,0,0,2,0,0,0,0,0,0,0,0,0,0,2,0,1,2,0,0,11,0,0,2,0,2,2
2,0,0,0,0,0,0,0,0,0,0,0,2,0,0,0,0,0,0,0,0,0,0,2,4,1,2,0,0,0,0,0,2,4,1,2
2,7,0,0,0,0,0,0,0,0,0,7,1,7,0,0,0,0,0,0,0,0,7,1,1,1,2,0,0,0,0,0,2,1,1,2
2,1,2,2,7,6,6,6,7,2,2,1,1,1,2,2,7,6,6,7,2,2,1,1,1,2,2,7,6,6,6,7,2,2,1,2
2,7,0,0,0,0,0,0,0,0,0,7,1,7,0,0,0,0,0,0,0,0,7,1,7,0,0,0,0,0,0,0,0,0,7,2
2,0,0,0,0,0,0,0,0,0,0,0,2,0,0,0,0,0,0,0,0,0,0,2,0,0,0,0,0,0,0,0,0,0,0,2
2,0,0,0,0,0,0,0,0,0,0,0,2,0,0,0,0,0,0,0,0,0,0,2,0,0,0,0,0,0,0,0,0,0,0,2
2,0,0,0,0,0,0,0,0,0,0,0,2,0,0,0,0,0,0,0,0,0,0,2,0,0,0,0,0,0,0,0,0,0,0,2
7,0,0,0,0,0,0,0,0,0,0,0,7,0,0,0,0,0,0,0,0,0,0,7,0,0,0,0,0,0,0,0,0,0,0,7
2,0,0,0,0,0,0,0,0,0,0,0,6,0,0,0,0,0,0,0,0,0,0,6,0,0,0,0,0,0,0,0,0,0,0,2
2,0,0,0,0,0,0,0,0,0,0,0,6,0,0,0,0,0,0,0,0,0,0,6,0,0,0,0,0,0,0,0,0,0,0,2
7,0,0,0,0,0,0,0,0,0,0,0,7,0,0,0,0,0,0,0,0,0,0,7,0,0,0,0,0,0,0,0,0,0,0,7
2,0,0,0,0,0,0,0,0,0,0,0,2,0,0,0,0,0,0,0,0,0,0,2,0,0,0,0,0,0,0,0,0,0,0,2
2,0,0,0,0,0,0,0,0,0,0,0,2,0,0,0,0,0,0,0,0,0,0,2,0,0,0,0,0,0,0,0,0,0,0,2
2,0,0,0,0,0,0,0,0,0,0,0,2,0,0,0,0,0,0,0,0,0,0,2,0,0,0,0,0,0,0,0,0,0,0,2
2,7,0,0,0,0,0,0,0,0,0,7,1,7,0,0,0,0,0,0,0,0,7,1,7,0,0,0,0,0,0,0,0,0,7,2
2,1,2,2,7,6,6,6,7,2,2,1,4,1,2,2,7,6,6,7,2,2,1,1,1,2,2,7,6,6,6,7,2,2,1,2
2,7,0,0,0,0,0,0,0,0,0,7,1,7,0,0,0,0,0,0,0,0,7,1,7,0,0,0,0,0,0,0,0,0,7,2
2,0,0,0,0,0,0,0,0,0,0,0,2,0,0,0,0,0,0,0,0,0,0,2,0,0,0,0,0,0,0,0,0,0,0,2
2,0,0,0,0,0,0,0,0,0,0,0,2,0,0,0,0,0,0,0,0,0,0,2,0,0,0,0,0,0,0,0,0,0,0,2
2,0,0,0,0,0,0,0,0,0,0,0,7,0,0,0,0,0,0,0,0,0,0,7,0,0,0,0,0,0,0,0,0,0,0,2
2,0,0,0,0,0,0,0,0,0,0,0,6,0,0,0,0,0,0,0,0,0,0,6,0,0,0,0,0,0,0,0,0,0,0,2
2,0,0,0,0,0,0,0,0,0,0,0,6,0,0,0,0,0,0,0,0,0,0,6,0,0,0,0,0,0,0,0,0,0,0,2
2,0,0,0,0,0,0,0,0,0,0,0,7,0,0,0,0,0,0,0,0,0,0,7,0,0,0,0,0,0,0,0,0,0,0,2
2,0,0,0,0,0,0,0,0,0,0,0,2,0,0,0,0,0,0,0,0,0,0,2,0,0,0,0,0,0,0,0,0,0,0,2
2,0,0,0,0,0,0,0,0,0,0,0,2,0,0,0,0,0,0,0,0,0,0,2,0,0,0,0,0,0,0,0,0,0,0,2
2,7,0,0,0,0,0,0,0,0,0,7,1,7,0,0,0,0,0,0,0,0,7,1,7,0,0,0,0,0,0,0,0,0,7,2
1,2,2,2,2,2,2,2,2,2,2,2,2,2,2,2,7,2,2,7,2,2,2,2,2,2,2,2,2,2,2,2,2,2,2,1
endlayer

layer
1,2,15,14,14,14,14,14,14,14,14,14,14,14,13,2,7,2,2,7,2,15,14,14,14,14,14,14,14,14,14,14,14,13,2,1
2,1,0,0,0,0,0,0,0,0,0,1,1,1,0,0,0,0,0,0,0,0,1,1,1,1,1,0,0,0,0,0,1,1,1,2
16,0,0,0,0,0,0,0,0,0,0,0,2,0,0,0,0,0,0,0,0,0,0,2,4,1,1,0,0,0,0,0,1,4,1,16
13,0,0,0,0,0,0,0,0,0,0,0,2,0,0,0,0,0,0,0,0,0,0,2,0,1,1,0,0,0,0,0,1,0,2,15
13,0,0,0,0,0,0,0,0,0,0,0,1,0,0,0,0,0,0,0,0,0,0,1,0,6,1,1,1,1,1,1,12,0,0,15
13,0,0,0,0,0,0,0,0,0,0,0,6,0,0,0,0,0,0,0,0,0,0,6,0,0,0,4,4,4,4,0,0,0,0,15
13,0,0,0,0,0,0,0,0,0,0,0,6,0,0,0,0,0,0,0,0,0,0,6,0,0,0,4,4,4,4,0,0,0,0,15
13,0,0,0,0,0,0,0,0,0,0,0,1,0,0,0,0,0,0,0,0,0,0,1,0,6,1,1,2,2,2,1,12,0,0,15
13,0,0,0,0,0,0,0,0,0,0,0,2,0,0,0,0,0,0,0,0,0,0,2,0,1,2,0,0,0,0,0,2,0,2,15
13,0,0,0,0,0,0,0,0,0,0,0,2,0,0,0,0,0,0,0,0,0,0,2,4,1,2,0,0,0,0,0,2,4,1,15
13,1,0,0,0,0,0,0,0,0,0,1,1,1,0,0,0,0,0,0,0,0,1,1,1,1,2,0,0,0,0,0,2,1,1,15
13,1,2,2,1,6,6,6,1,2,2,1,1,1,2,2,1,6,6,1,2,2,1,1,1,2,2,1,6,6,6,1,2,2,1,15
13,1,0,0,0,0,0,0,0,0,0,1,1,1,0,0,0,0,0,0,0,0,1,1,1,0,0,0,0,0,0,0,0,0,1,15
13,0,0,0,0,0,0,0,0,0,0,0,2,0,0,0,0,0,0,0,0,0,0,2,0,0,0,0,0,0,0,0,0,0,0,15
14,0,0,0,0,0,0,0,0,0,0,0,2,0,0,0,0,0,0,0,0,0,0,2,0,0,0,0,0,0,0,0,0,0,0,14
2,0,0,0,0,0,0,0,0,0,0,0,2,0,0,0,0,0,0,0,0,0,0,2,0,0,0,0,0,0,0,0,0,0,0,2
7,0,0,0,0,0,0,0,0,0,0,0,1,0,0,0,0,0,0,0,0,0,0,1,0,0,0,0,0,0,0,0,0,0,0,7
2,0,0,0,0,0,0,0,0,0,0,0,6,0,0,0,0,0,0,0,0,0,0,6,0,0,0,0,0,0,0,0,0,0,0,2
2,0,0,0,0,0,0,0,0,0,0,0,6,0,0,0,0,0,0,0,0,0,0,6,0,0,0,0,0,0,0,0,0,0,0,2
7,0,0,0,0,0,0,0,0,0,0,0,1,0,0,0,0,0,0,0,0,0,0,1,0,0,0,0,0,0,0,0,0,0,0,7
2,0,0,0,0,0,0,0,0,0,0,0,2,0,0,0,0,0,0,0,0,0,0,2,0,0,0,0,0,0,0,0,0,0,0,2
16,0,0,0,0,0,0,0,0,0,0,0,2,0,0,0,0,0,0,0,0,0,0,2,0,0,0,0,0,0,0,0,0,0,0,16
13,0,0,0,0,0,0,0,0,0,0,0,2,0,0,0,0,0,0,0,0,0,0,2,0,0,0,0,0,0,0,0,0,0,0,15
13,1,0,0,0,0,0,0,0,0,0,1,1,1,0,0,0,0,0,0,0,0,1,1,1,0,0,0,0,0,0,0,0,0,1,15
13,1,2,2,1,6,6,6,1,2,2,1,4,1,2,2,1,6,6,1,2,2,1,1,1,2,2,1,6,6,6,1,2,2,1,15
13,1,0,0,0,0,0,0,0,0,0,1,1,1,0,0,0,0,0,0,0,0,1,1,1,0,0,0,0,0,0,0,0,0,1,15
13,0,0,0,0,0,0,0,0,0,0,0,2,0,0,0,0,0,0,0,0,0,0,2,0,0,0,0,0,0,0,0,0,0,0,15
13,0,0,0,0,0,0,0,0,0,0,0,2,0,0,0,0,0,0,0,0,0,0,2,0,0,0,0,0,0,0,0,0,0,0,15
13,0,0,0,0,0,0,0,0,0,0,0,1,0,0,0,0,0,0,0,0,0,0,1,0,0,0,0,0,0,0,0,0,0,0,15
13,0,0,0,0,0,0,0,0,0,0,0,6,0,0,0,0,0,0,0,0,0,0,6,0,0,0,0,0,0,0,0,0,0,0,15
13,0,0,0,0,0,0,0,0,0,0,0,6,0,0,0,0,0,0,0,0,0,0,6,0,0,0,0,0,0,0,0,0,0,0,15
13,0,0,0,0,0,0,0,0,0,0,0,1,0,0,0,0,0,0,0,0,0,0,1,0,0,0,0,0,0,0,0,0,0,0,15
13,0,0,0,0,0,0,0,0,0,0,0,2,0,0,0,0,0,0,0,0,0,0,2,0,0,0,0,0,0,0,0,0,0,0,15
14,0,0,0,0,0,0,0,0,0,0,0,2,0,0,0,0,0,0,0,0,0,0,2,0,0,0,0,0,0,0,0,0,0,0,14
2,1,0,0,0,0,0,0,0,0,0,1,1,1,0,0,0,0,0,0,0,0,1,1,1,0,0,0,0,0,0,0,0,0,1,2
1,2,15,16,16,16,16,16,16,16,16,16,16,16,13,2,7,2,2,7,2,15,16,16,16,16,16,16,16,16,16,16,16,13,2,1
endlayer

layer
1,2,19,18,18,18,18,18,18,18,18,18,18,18,17,2,1,1,1,1,2,19,18,18,18,18,18,18,18,18,18,18,18,17,2,1
2,1,22,22,22,22,22,22,22,22,22,1,1,1,5,5,20,21,21,20,5,5,1,1,1,1,1,0,0,0,0,0,1,1,1,2
23,22,22,22,22,22,22,22,22,22,22,22,1,5,5,21,20,20,20,20,21,5,5,1,4,1,1,0,0,0,0,0,1,4,1,23
17,22,22,22,21,21,21,21,21,22,22,22,1,5,21,21,21,20,20,21,21,21,5,1,1,1,1,0,0,0,0,0,1,1,1,19
17,22,22,21,25,21,20,21,25,21,22,22,1,20,20,21,20,24,24,20,21,20,20,1,0,12,1,1,1,1,1,1,0,0,0,19
17,22,22,21,21,20,5,20,21,21,22,22,1,21,20,20,24,5,5,24,20,20,21,1,0,0,0,4,4,4,4,1,0,0,0,19
17,22,22,21,21,20,5,20,21,21,22,22,1,21,20,20,24,5,5,24,20,20,21,1,0,0,0,4,4,4,4,1,0,0,0,19
17,22,22,21,25,21,20,21,25,21,22,22,1,20,20,21,20,24,24,20,21,20,20,1,0,12,1,1,1,1,1,1,0,0,0,19
17,22,22,22,21,21,21,21,21,22,22,22,1,5,21,21,21,20,20,21,21,21,5,1,1,1,1,0,0,0,0,0,1,1,1,19
17,22,22,22,22,22,22,22,22,22,22,22,1,5,5,21,20,20,20,20,21,5,5,1,4,1,1,0,0,0,0,0,1,4,1,19
17,1,22,22,22,22,22,22,22,22,22,1,1,1,5,5,20,21,21,20,5,5,1,1,1,1,1,0,0,0,0,0,1,1,1,19
17,1,1,1,1,1,1,1,1,1,1,1,1,1,1,1,1,1,1,1,1,1,1,1,1,1,1,1,1,1,1,1,1,1,1,19
17,1,20,20,20,21,21,21,20,20,20,1,1,1,24,24,24,26,26,24,24,24,1,1,1,5,21,21,20,20,20,21,21,5,1,19
17,20,20,21,21,21,21,21,21,21,20,20,1,24,24,5,21,26,26,21,5,24,24,1,5,5,21,21,21,20,21,21,21,5,5,19
18,20,21,20,21,21,21,21,21,20,21,20,1,24,5,21,20,21,21,20,21,5,24,1,21,21,5,21,21,20,21,21,5,21,21,18
2,20,21,21,21,21,24,21,21,21,21,20,1,24,21,20,21,5,5,21,20,21,24,1,21,21,21,5,21,24,21,5,21,21,21,2
1,21,21,21,21,24,20,24,21,21,21,21,1,26,26,21,5,21,21,5,21,26,26,1,21,20,21,21,20,24,20,21,21,20,21,1
1,24,21,21,24,20,5,20,24,21,21,24,1,26,21,5,21,26,26,21,5,21,26,1,20,5,20,24,5,5,5,24,20,5,20,1
1,24,21,21,24,20,5,20,24,21,21,24,1,26,21,5,21,26,26,21,5,21,26,1,20,5,20,24,5,5,5,24,20,5,20,1
1,21,21,21,21,24,20,24,21,21,21,21,1,26,26,21,5,21,21,5,21,26,26,1,21,20,21,21,20,24,20,21,21,20,21,1
2,20,21,21,21,21,24,21,21,21,21,20,1,24,21,20,21,5,5,21,20,21,24,1,21,21,21,5,21,24,21,5,21,21,21,2
23,20,21,20,21,21,21,21,21,20,21,20,1,24,5,21,20,21,21,20,21,5,24,1,21,21,5,21,21,20,21,21,5,21,21,23
17,20,20,21,21,21,21,21,21,21,20,20,1,24,24,5,21,26,26,21,5,24,24,1,5,5,21,21,21,20,21,21,21,5,5,19
17,1,20,20,20,21,21,21,20,20,20,1,1,1,24,24,24,26,26,24,24,24,1,1,1,5,21,21,20,20,20,21,21,5,1,19
17,1,1,1,1,1,1,1,1,1,1,1,4,1,1,1,1,1,1,1,1,1,1,1,1,1,1,1,1,1,1,1,1,1,1,19
17,1,24,26,26,26,24,26,26,26,24,1,1,1,5,5,21,21,21,21,5,5,1,1,1,24,20,20,5,5,5,20,20,24,1,19
17,24,21,24,24,26,24,26,24,24,21,24,1,5,5,5,24,21,21,24,5,5,5,1,24,24,20,20,20,5,20,20,20,24,24,19
17,26,24,26,26,24,26,24,26,26,24,26,1,5,5,24,24,20,20,24,24,5,5,1,20,20,24,20,26,5,26,20,24,20,20,19
17,26,24,26,26,26,21,26,26,26,24,26,1,21,24,24,5,24,24,5,24,24,21,1,5,20,20,26,26,21,26,26,20,20,5,19
17,26,26,24,26,21,5,21,26,24,26,26,1,21,21,20,24,26,26,24,20,21,21,1,5,5,21,26,24,5,24,26,21,5,5,19
17,26,26,24,26,21,5,21,26,24,26,26,1,21,21,20,24,26,26,24,20,21,21,1,5,5,21,26,24,5,24,26,21,5,5,19
17,26,24,26,26,26,21,26,26,26,24,26,1,21,24,24,5,24,24,5,24,24,21,1,5,20,20,26,26,21,26,26,20,20,5,19
17,26,24,26,26,24,26,24,26,26,24,26,1,5,5,24,24,20,20,24,24,5,5,1,20,20,24,20,26,5,26,20,24,20,20,19
18,24,21,24,24,26,24,26,24,24,21,24,1,5,5,5,24,21,21,24,5,5,5,1,24,24,20,20,20,5,20,20,20,24,24,18
2,1,24,26,26,26,24,26,26,26,24,1,1,1,5,5,21,21,21,21,5,5,1,1,1,24,20,20,5,5,5,20,20,24,1,2
1,2,19,23,23,23,23,23,23,23,23,23,23,23,17,2,1,1,1,1,2,19,23,23,23,23,23,23,23,23,23,23,23,17,2,1
endlayer

layer
1,2,2,2,2,2,2,2,2,2,2,2,2,2,2,2,2,2,2,2,2,2,2,2,2,2,2,2,2,2,2,2,2,2,2,1
2,2,2,2,2,2,2,2,2,2,2,2,2,2,2,2,2,2,2,2,2,2,2,2,2,2,2,2,2,2,2,2,2,2,2,2
2,2,2,2,2,2,2,2,2,2,2,2,2,2,3,2,2,2,2,2,2,2,2,2,2,2,2,2,2,2,2,2,2,2,2,2
2,2,2,2,2,2,2,2,2,2,2,2,2,2,2,2,2,2,2,2,2,2,2,2,2,2,2,2,2,2,2,2,2,2,2,2
2,2,2,2,2,2,2,2,2,2,2,2,2,2,2,2,2,2,2,2,2,2,2,2,2,2,2,2,2,2,2,2,2,2,2,2
2,2,2,2,2,2,2,3,2,2,2,2,2,2,2,2,2,2,2,2,2,2,2,2,2,2,2,27,4,4,27,2,2,2,2,2
2,2,2,2,2,2,2,2,2,2,2,2,2,2,2,2,2,2,2,2,2,2,2,2,2,2,2,27,4,4,27,2,2,2,2,2
2,2,2,2,2,2,2,2,2,2,2,2,2,2,2,2,2,2,2,2,2,2,2,2,2,2,2,2,2,2,2,2,2,2,2,2
2,2,2,2,2,2,2,2,2,2,2,2,2,2,2,2,2,2,2,2,2,2,2,2,2,2,2,2,2,2,2,2,2,2,2,2
2,2,2,2,2,2,2,2,2,2,2,2,2,2,2,2,2,2,2,2,2,2,2,2,2,2,2,2,2,2,2,2,2,2,2,2
2,2,2,2,2,2,2,2,2,2,2,2,2,2,2,2,2,2,2,2,2,2,2,2,2,2,2,2,2,2,2,2,2,2,2,2
2,2,2,2,2,2,2,2,2,2,2,2,2,2,2,2,2,2,2,2,2,2,2,2,2,2,2,2,2,2,2,2,2,2,2,2
2,2,2,2,2,2,2,2,2,2,2,2,2,28,2,2,2,2,2,2,2,2,2,2,2,2,2,2,2,2,2,2,2,2,2,2
2,2,2,2,2,2,2,2,2,2,2,2,2,2,2,2,2,2,2,2,2,2,2,2,2,2,2,2,2,2,2,2,2,2,2,2
2,2,2,2,2,2,2,29,2,2,2,2,2,2,2,2,2,2,2,2,2,2,2,2,2,2,2,2,2,2,2,2,2,2,2,2
2,2,2,2,2,2,2,2,2,2,2,2,2,2,2,2,2,2,2,2,2,2,2,2,2,2,2,2,2,2,2,2,2,2,2,2
2,2,2,2,2,2,2,2,2,2,2,2,2,2,2,2,2,2,2,2,2,2,2,2,2,2,2,2,2,2,2,2,2,2,2,2
2,2,2,2,2,2,2,2,2,2,2,2,2,2,2,2,2,2,2,2,2,2,2,2,2,2,2,2,2,2,2,2,2,2,2,2
2,2,2,2,2,2,2,2,2,2,2,2,2,2,2,2,2,2,2,2,2,2,2,2,2,2,2,2,2,2,2,2,2,2,2,2
2,2,2,2,2,2,2,2,2,2,2,2,2,2,2,2,2,2,2,2,2,2,2,2,2,2,2,2,2,2,2,2,2,2,2,2
2,2,2,2,2,2,2,2,2,2,2,2,2,2,2,2,2,2,2,2,2,2,2,2,2,2,2,2,2,2,2,2,2,2,2,2
2,2,2,2,2,2,2,2,2,2,2,2,2,2,2,2,2,2,2,2,2,2,2,2,2,2,2,2,2,2,2,2,2,2,2,2
2,2,2,2,2,2,2,2,2,2,2,2,2,2,2,2,2,2,2,2,2,2,2,2,2,2,2,2,2,2,2,2,2,2,2,2
2,2,2,2,2,2,2,2,2,2,2,2,2,2,2,2,2,2,2,2,2,2,2,2,2,2,2,2,2,2,2,2,2,2,2,2
2,2,2,2,2,2,2,2,2,2,2,2,4,2,2,2,2,2,2,2,2,2,2,2,2,2,2,2,2,2,2,2,30,2,2,2
2,2,2,2,2,2,2,2,2,2,2,2,2,2,2,2,2,2,2,2,2,2,2,2,2,2,2,2,2,31,2,2,2,2,2,2
2,3,2,2,2,2,2,2,2,2,2,2,2,2,2,2,2,2,2,2,2,2,2,2,2,2,2,2,2,2,2,2,2,2,2,2
2,2,2,2,2,2,2,2,2,2,2,2,2,2,2,2,2,2,2,2,2,2,2,2,2,2,2,2,2,2,2,2,2,2,2,2
2,2,2,2,2,2,2,2,2,2,2,2,2,2,2,2,2,2,2,2,2,2,2,2,2,2,2,2,2,2,2,2,2,2,2,2
2,2,2,2,2,2,2,2,2,2,2,2,2,2,2,2,2,2,2,2,2,2,2,2,2,2,2,2,2,2,2,2,2,2,2,2
2,2,2,2,2,2,2,2,2,2,2,2,2,2,2,2,2,2,2,2,2,2,2,2,2,2,2,2,2,2,2,2,2,2,2,2
2,2,2,2,2,2,2,2,2,2,2,2,2,2,2,2,2,2,2,2,2,2,2,2,2,2,2,2,2,2,2,2,2,2,2,2
2,34,2,2,2,33,2,2,2,2,2,2,2,2,2,2,2,2,2,2,2,2,2,2,2,2,2,2,2,32,2,2,2,2,2,2
2,2,2,2,2,2,2,2,2,2,2,2,2,2,2,2,2,2,2,2,2,2,2,2,2,2,2,2,2,2,2,2,2,2,2,2
2,2,2,2,2,2,2,2,2,2,2,3,2,2,2,2,2,2,2,2,2,2,2,2,2,2,2,2,2,2,2,2,2,2,2,2
1,2,2,2,2,2,2,2,2,2,2,2,2,2,2,2,2,2,2,2,2,2,2,2,2,2,2,2,2,2,2,2,2,2,2,1
endlayer

layer
1,2,2,2,2,2,2,2,2,2,2,2,2,2,2,2,2,35,35,2,2,2,2,2,2,2,2,2,2,2,2,2,2,2,2,1
2,2,2,2,2,2,2,2,2,2,2,2,2,2,2,2,2,35,35,2,2,36,2,2,2,2,2,2,2,2,2,2,2,2,2,2
2,2,2,2,2,2,2,2,2,2,2,2,2,2,2,2,2,35,35,2,2,36,2,2,4,2,2,2,2,2,2,2,2,4,2,2
2,2,2,2,2,2,2,2,2,2,2,2,2,2,2,2,2,35,35,2,2,36,2,2,2,2,2,2,2,2,2,2,2,2,2,2
2,38,2,2,2,2,2,2,2,2,2,2,2,2,2,2,2,35,35,2,2,36,2,2,2,2,37,37,37,37,37,37,2,2,2,2
2,2,2,2,2,2,2,2,2,2,2,2,2,2,2,2,2,35,35,2,2,36,2,2,2,2,37,4,4,4,4,37,2,2,2,2
2,2,2,2,2,2,2,2,2,2,2,2,2,2,2,2,2,35,35,2,2,36,2,2,2,2,37,4,4,4,4,37,2,2,2,2
2,2,2,2,2,2,38,2,2,2,2,2,2,2,2,2,2,35,35,2,2,36,2,2,2,2,37,37,37,37,37,37,2,2,2,2
2,2,2,2,2,2,2,2,2,2,2,2,2,2,2,2,2,35,35,2,2,36,2,2,2,2,2,2,2,2,2,2,2,2,2,2
2,2,2,2,2,2,2,2,2,2,2,2,2,2,2,2,2,35,35,2,2,36,2,2,4,2,2,2,2,2,2,2,2,4,2,2
2,38,2,2,2,2,2,2,2,2,2,2,2,2,2,2,2,35,35,2,2,36,2,2,2,2,2,2,2,2,2,2,2,2,2,2
2,2,2,2,2,2,2,2,2,2,2,2,2,2,2,2,2,35,35,2,2,36,2,2,2,2,2,2,2,2,2,2,2,2,2,2
2,2,2,2,2,2,2,2,2,2,2,2,2,2,2,2,2,35,35,2,2,36,36,36,36,36,36,36,36,36,36,36,36,36,36,2
2,2,2,2,2,2,2,2,2,2,2,2,2,2,2,2,2,35,35,2,2,2,2,2,2,2,2,2,2,2,2,2,2,2,2,2
2,2,2,2,2,2,2,2,2,2,2,2,2,2,2,2,2,35,35,2,2,2,2,2,2,2,2,2,2,2,2,2,2,2,2,2
2,2,2,2,2,2,2,2,2,2,2,2,2,2,2,2,2,35,35,2,2,2,2,2,2,2,2,2,2,2,2,2,2,2,2,2
2,2,2,2,2,2,2,2,2,2,2,2,2,2,2,2,2,35,35,2,2,2,2,2,2,2,2,2,2,2,2,2,2,2,2,2
35,35,35,35,35,35,35,35,35,35,35,35,35,35,35,35,35,35,35,35,35,35,35,35,35,35,35,35,35,35,35,35,35,35,35,35
35,35,35,35,35,35,35,35,35,35,35,35,35,35,35,35,35,35,35,35,35,35,35,35,35,35,35,35,35,35,35,35,35,35,35,35
2,2,2,2,2,2,2,2,2,2,2,2,2,2,2,2,2,2,35,35,2,2,2,2,2,2,2,2,2,2,2,2,2,2,2,2
2,2,2,2,2,2,2,2,2,2,4,4,4,4,4,2,2,2,35,35,2,37,2,37,37,2,37,2,2,2,2,2,2,2,2,2
2,2,2,2,2,2,2,2,2,4,4,2,2,2,4,4,2,2,35,35,2,2,2,37,37,2,2,2,2,2,2,2,2,2,2,2
2,2,2,2,2,2,2,2,4,4,2,2,2,2,2,4,4,2,35,35,2,37,37,37,37,37,37,2,2,2,2,2,2,2,2,2
2,2,2,2,2,2,2,2,4,2,2,2,2,2,2,2,4,2,35,35,2,37,37,37,37,37,37,2,2,2,2,2,2,2,2,2
2,2,2,2,2,2,2,2,4,2,2,2,2,2,2,2,4,2,35,35,2,2,2,37,37,2,2,2,2,2,2,2,2,2,2,2
2,2,2,2,2,2,2,2,4,2,2,2,2,2,2,2,4,2,35,35,2,37,2,37,37,2,37,2,2,2,2,2,2,2,2,2
2,2,2,2,2,2,2,2,4,4,2,2,2,2,2,4,4,2,35,35,2,2,2,2,2,2,2,2,2,2,2,2,2,2,2,2
2,2,2,2,2,2,2,2,2,4,4,2,2,2,4,4,2,2,35,35,2,2,2,2,2,2,2,2,2,2,2,2,2,2,2,2
2,2,2,2,2,2,2,2,2,2,4,4,4,4,4,2,2,2,35,35,2,2,2,2,2,2,2,2,2,2,2,2,2,2,2,2
2,2,2,2,2,2,2,2,2,2,2,2,2,2,2,2,2,35,35,35,2,2,2,2,2,2,2,2,2,2,2,2,2,2,2,2
2,2,2,2,2,2,2,2,2,2,2,2,2,2,2,2,2,35,35,2,2,2,2,2,2,2,2,2,2,2,2,2,2,2,2,2
2,2,2,2,2,2,2,2,2,2,2,2,2,2,2,2,2,35,35,2,2,2,2,2,2,2,2,2,2,2,2,2,2,2,2,2
2,2,2,2,2,2,2,2,2,2,2,2,2,2,2,2,2,35,35,2,2,2,2,2,2,2,2,2,2,2,2,2,2,2,2,2
2,2,2,2,2,2,2,2,2,2,2,2,2,2,2,2,2,35,35,2,2,2,2,2,2,2,2,2,2,2,2,2,2,2,2,2
2,2,2,2,2,2,2,2,2,2,2,2,2,2,2,2,2,35,35,2,2,2,2,2,2,2,2,2,2,2,2,2,2,2,2,2
1,2,2,2,2,2,2,2,2,2,2,2,2,2,2,2,2,35,35,2,2,2,2,2,2,2,2,2,2,2,2,2,2,2,2,1
endlayer

layer
1,2,2,2,2,2,2,2,2,2,2,2,2,2,2,2,1,39,39,1,2,2,2,2,2,2,2,2,2,2,2,2,2,2,2,1
2,38,42,38,0,0,0,0,2,0,41,41,6,2,40,6,0,0,0,0,0,0,6,35,35,35,35,35,35,35,35,35,35,35,35,2
2,42,0,0,0,0,0,14,2,0,6,6,0,2,0,6,0,0,0,0,0,0,0,35,1,1,35,35,1,1,35,35,1,1,35,2
2,44,0,0,0,0,40,23,2,0,43,43,0,2,0,6,0,0,0,0,0,0,0,35,1,6,0,0,6,6,0,0,6,1,35,2
2,42,0,0,0,0,6,0,2,0,0,0,0,46,0,6,0,0,0,0,0,0,0,35,35,0,45,45,45,45,45,45,0,35,35,2
2,38,0,0,0,0,6,0,2,0,0,0,40,2,0,6,0,0,0,0,0,0,6,35,1,6,45,0,0,0,0,45,6,1,35,2
2,42,0,0,0,0,6,0,2,6,0,48,47,2,0,6,0,0,0,0,0,0,6,35,1,6,45,0,0,0,0,45,6,1,35,2
2,44,0,0,0,0,42,0,2,2,49,2,2,2,6,6,0,0,0,0,0,0,0,35,35,0,45,45,45,45,45,45,0,35,35,2
2,42,0,0,0,0,44,0,2,0,0,0,0,0,0,0,0,0,0,0,0,0,0,35,1,6,0,0,6,6,0,0,6,1,35,2
2,38,0,0,0,0,44,0,2,0,0,0,0,0,0,0,0,0,0,0,0,0,0,35,1,1,35,35,1,1,35,35,1,1,35,2
2,42,0,0,0,0,38,0,2,0,0,6,50,50,6,6,0,0,0,0,0,0,6,35,35,35,35,35,35,35,35,35,35,35,35,2
2,44,0,0,0,0,51,0,2,0,0,6,0,47,6,0,0,0,0,0,0,0,1,6,6,0,0,0,6,6,0,0,0,6,6,2
2,0,0,0,0,0,52,0,2,0,0,46,0,0,6,0,0,0,0,0,0,0,0,0,0,0,0,0,0,0,0,0,0,0,0,2
2,42,0,0,0,0,53,0,2,0,0,6,0,0,6,0,0,0,0,0,0,0,0,0,0,0,0,0,0,0,0,0,0,0,0,2
2,38,42,0,0,0,47,0,2,0,0,6,0,42,6,0,0,0,0,0,0,0,0,0,0,0,0,0,0,0,0,0,0,0,0,2
2,2,2,2,49,2,2,2,1,0,0,6,50,50,6,6,0,0,0,0,0,0,0,0,0,0,0,0,0,0,0,0,0,0,0,2
1,0,0,0,0,0,0,0,0,0,0,0,0,0,0,0,0,0,0,54,0,0,0,0,0,0,0,0,0,0,0,0,0,0,0,1
46,0,0,0,0,0,0,0,0,0,0,0,0,0,0,0,0,0,0,0,0,0,0,0,0,0,0,0,0,0,0,0,0,0,0,46
46,0,0,0,0,0,0,0,0,0,0,0,0,0,0,0,0,0,0,0,0,0,0,0,0,0,0,0,0,0,0,0,0,0,0,46
1,0,0,0,0,0,0,0,0,0,55,55,55,55,55,0,0,0,0,0,35,35,35,0,0,35,35,35,0,0,0,0,0,0,0,1
2,0,0,0,0,0,0,0,0,55,0,0,0,0,0,55,0,0,0,0,35,6,35,0,0,35,6,35,0,0,0,0,0,0,0,2
2,39,6,0,0,0,0,0,55,0,0,1,24,1,0,0,55,0,0,0,35,35,35,0,0,35,35,35,0,0,0,0,0,0,0,2
2,0,6,0,0,0,0,55,0,0,1,1,1,1,1,0,0,55,0,0,0,0,0,0,0,0,0,0,0,0,1,6,39,6,1,2
2,0,6,0,0,0,0,55,0,1,1,1,1,1,1,1,0,55,0,0,0,0,0,0,0,0,0,0,6,6,2,0,0,0,56,2
2,0,6,0,0,0,0,55,0,24,1,1,1,1,1,24,0,55,0,0,35,35,35,0,0,35,35,35,6,0,57,0,0,0,56,2
2,0,6,0,0,0,0,55,0,1,1,1,1,1,1,1,0,55,0,0,35,6,35,0,0,35,6,35,6,0,47,0,0,0,56,2
2,0,6,0,0,0,0,55,0,0,1,1,1,1,1,0,0,55,0,0,35,35,35,0,0,35,35,35,6,6,2,0,0,56,56,2
2,6,6,0,0,0,0,0,55,0,0,1,24,1,0,0,55,0,0,0,0,0,6,0,0,0,6,0,0,0,1,2,49,2,1,2
2,0,0,0,0,0,0,0,0,55,0,0,0,0,0,55,0,0,0,0,0,0,6,0,0,0,6,0,0,0,0,0,0,0,0,2
2,0,0,0,0,6,0,0,0,0,55,55,55,55,55,0,0,0,0,0,0,1,2,2,58,2,2,2,1,0,0,0,0,0,6,2
2,38,38,38,38,0,0,0,0,0,0,0,0,0,0,0,0,0,0,0,0,2,0,0,0,0,0,6,2,1,2,58,2,1,1,2
2,2,2,2,2,2,1,0,0,0,0,0,0,0,0,0,0,0,0,0,0,2,0,0,0,0,0,0,2,40,2,0,6,6,6,2
2,0,0,0,0,0,2,0,6,0,0,0,0,0,0,0,0,0,0,0,0,60,0,0,0,0,0,59,2,0,6,0,0,0,0,2
2,64,40,63,62,47,1,0,0,0,6,6,6,6,6,0,0,0,0,0,0,2,0,0,0,0,0,61,2,0,46,0,0,0,0,2
2,0,0,0,0,0,66,0,0,0,6,0,0,0,46,0,0,0,0,0,0,2,6,47,65,48,40,0,2,47,2,1,48,1,6,2
1,2,2,2,2,2,2,2,2,2,2,2,2,2,2,2,1,39,39,1,2,2,2,2,2,2,2,2,2,2,2,2,2,2,2,1
endlayer

layer
1,2,2,2,2,2,2,2,2,2,2,2,2,2,2,2,7,0,0,7,2,2,2,2,2,2,2,2,2,2,2,2,2,2,2,1
2,42,0,0,6,0,0,0,2,0,0,0,12,2,0,43,6,0,0,6,0,0,6,0,0,0,0,0,0,0,0,0,0,0,0,2
2,44,0,0,0,0,0,0,2,0,43,43,0,6,0,43,0,0,0,0,0,0,0,0,1,1,0,0,1,1,0,0,1,1,0,2
2,0,0,0,0,0,0,14,2,67,0,0,0,2,0,43,0,0,0,0,0,0,0,0,1,12,0,0,43,43,0,0,12,1,0,2
2,0,0,0,0,0,68,23,2,0,0,0,0,0,0,43,0,0,0,0,0,0,0,0,0,0,0,0,0,0,0,0,0,0,0,2
2,0,0,0,0,0,43,0,2,0,0,0,0,2,0,43,0,0,0,0,0,0,6,0,1,43,0,0,0,0,0,0,43,1,0,2
2,0,0,0,0,0,68,0,2,12,0,0,0,6,0,43,0,0,0,0,0,0,6,0,1,43,0,0,0,0,0,0,43,1,0,2
2,6,0,0,0,0,0,0,2,2,69,2,6,2,43,6,0,0,0,0,0,0,0,0,0,0,0,0,0,0,0,0,0,0,0,2
2,44,0,0,0,0,0,0,2,0,0,0,0,0,0,0,0,0,0,0,0,0,0,0,1,12,0,0,43,43,0,0,12,1,0,2
2,42,0,0,0,0,0,0,6,0,0,0,0,0,0,0,0,0,0,0,0,0,0,0,1,1,0,0,1,1,0,0,1,1,0,2
2,0,0,0,0,0,0,0,2,6,0,6,0,0,6,12,0,0,0,0,0,0,6,0,0,0,0,0,0,0,0,0,0,0,0,2
2,0,0,0,0,0,0,0,6,0,0,43,0,0,43,0,0,0,0,0,0,0,1,6,12,0,0,0,6,6,0,0,0,12,6,2
2,0,0,0,0,0,0,0,2,6,0,0,0,0,43,0,0,0,0,0,0,0,0,0,0,0,0,0,0,0,0,0,0,0,0,2
2,0,0,0,0,0,0,0,6,0,0,43,0,0,43,0,0,0,0,0,0,0,0,0,0,0,0,0,0,0,0,0,0,0,0,2
2,42,0,6,0,6,0,0,2,0,0,43,0,0,43,0,0,0,0,0,0,0,0,0,0,0,0,0,0,0,0,0,0,0,0,2
2,2,6,2,69,2,6,2,1,0,0,6,0,0,6,12,0,0,0,54,0,0,0,0,0,0,0,0,0,0,0,0,0,0,0,2
7,6,0,6,0,6,0,0,0,0,0,0,0,0,0,0,0,0,0,54,0,0,0,0,0,0,0,0,0,0,0,0,0,0,6,7
0,0,0,0,0,0,0,0,0,0,0,0,0,0,0,0,0,0,0,54,0,0,0,0,0,0,0,0,0,0,0,0,0,0,0,0
0,0,0,0,0,0,0,0,0,0,0,0,0,0,0,0,0,0,0,0,0,0,0,0,0,0,0,0,0,0,0,0,0,0,0,0
7,6,0,0,0,0,0,0,0,0,0,0,0,0,0,0,0,0,0,0,0,0,0,0,0,0,0,0,0,0,0,0,0,0,6,7
2,0,0,0,0,0,0,0,0,0,0,0,0,0,0,0,0,0,0,0,0,6,0,0,0,0,6,0,0,0,0,0,0,0,0,2
2,0,6,0,0,0,0,0,0,0,0,0,0,0,0,0,0,0,0,0,0,0,0,0,0,0,0,0,0,0,0,0,0,0,0,2
2,0,43,0,0,0,0,0,0,0,12,7,1,7,12,0,0,0,0,0,0,0,0,0,0,0,0,0,0,0,1,0,0,0,1,2
2,0,43,0,0,0,0,0,0,0,7,24,24,24,7,0,0,0,0,0,0,0,0,0,0,0,0,0,6,43,2,0,0,0,56,2
2,0,43,0,0,0,0,0,0,0,1,24,1,24,1,0,0,0,0,0,0,0,0,0,0,0,0,0,43,0,0,0,0,0,56,2
2,0,43,0,0,0,0,0,0,0,7,24,24,24,7,0,0,0,0,0,0,6,0,0,0,0,6,0,43,0,0,0,0,0,0,2
2,0,43,0,0,0,0,0,0,0,12,7,1,7,12,0,0,0,0,0,0,0,0,0,0,0,0,0,6,43,2,67,0,0,56,2
2,12,6,0,0,0,0,0,0,0,0,0,0,0,0,0,0,0,0,0,0,0,6,0,0,0,6,0,0,0,1,2,69,2,1,2
2,0,0,0,0,0,0,0,0,0,0,0,0,0,0,0,0,0,0,0,0,0,12,0,0,0,12,0,0,0,0,0,0,0,0,2
2,0,0,0,0,6,0,0,0,0,0,0,0,0,0,0,0,0,0,0,0,1,6,2,69,2,6,2,1,0,0,0,0,0,12,2
2,0,0,0,0,0,0,0,0,0,0,0,0,0,0,0,0,0,0,0,0,6,0,0,0,0,0,12,2,1,2,69,2,1,1,2
2,2,6,2,6,2,1,0,0,0,0,0,0,0,0,0,0,0,0,0,0,2,0,0,0,0,0,0,2,0,2,0,43,43,43,2
2,0,0,0,0,0,6,0,6,0,0,0,0,0,0,0,0,0,0,0,0,69,0,0,0,0,0,0,2,0,0,0,0,0,0,2
2,68,0,70,0,0,1,0,0,0,6,43,43,43,6,0,0,0,0,0,0,2,0,0,0,0,0,59,2,0,0,0,0,0,0,2
2,67,0,0,0,0,69,0,0,0,12,0,0,0,0,0,6,0,0,6,0,6,12,0,43,0,0,61,2,12,2,1,48,1,12,2
1,2,2,2,2,2,2,2,2,2,2,2,2,2,2,2,7,0,0,7,2,2,2,2,2,2,2,2,2,2,2,2,2,2,2,1
endlayer

layer
1,2,2,2,2,2,2,2,2,2,2,2,2,2,2,2,7,6,6,7,2,2,2,2,2,2,2,2,2,2,2,2,2,2,2,1
2,0,0,0,12,0,0,0,2,65,65,65,65,2,6,71,12,0,0,12,0,0,6,0,0,0,0,0,0,0,0,0,0,0,0,2
2,0,0,0,0,0,73,0,2,65,65,65,65,2,6,72,0,0,0,0,0,0,0,0,1,1,0,0,1,1,0,0,1,1,0,2
2,0,0,0,0,0,74,0,2,67,65,65,65,2,6,71,0,0,0,0,0,0,0,0,1,0,0,0,0,0,0,0,0,1,0,2
2,0,0,0,0,0,73,14,2,65,65,65,65,2,6,72,0,0,0,0,0,0,0,0,0,0,0,0,0,0,0,0,0,0,0,2
2,0,0,0,0,0,74,23,2,65,65,65,65,2,6,71,0,0,0,0,0,0,6,0,1,0,0,0,0,0,0,0,0,1,0,2
2,0,0,0,0,0,73,0,2,65,65,65,65,2,6,72,0,0,0,0,0,0,6,0,1,0,0,0,0,0,0,0,0,1,0,2
2,12,0,0,0,0,74,0,2,2,2,2,2,2,6,71,0,0,0,0,0,0,0,0,0,0,0,0,0,0,0,0,0,0,0,2
2,0,0,0,0,0,73,0,2,0,75,0,75,0,0,0,0,0,0,0,0,0,0,0,1,0,0,0,0,0,0,0,0,1,0,2
2,0,0,0,0,0,74,0,73,0,0,0,0,0,0,0,0,0,0,0,0,0,0,0,1,1,0,0,1,1,0,0,1,1,0,2
2,0,0,0,0,0,73,0,2,12,0,6,6,6,6,0,0,0,0,0,0,0,6,0,0,0,0,0,0,0,0,0,0,0,0,2
2,0,0,0,0,0,74,0,73,0,0,6,0,0,6,0,0,0,0,0,0,0,1,6,0,0,0,0,6,6,0,0,0,0,6,2
2,0,0,0,0,0,73,0,2,12,0,6,0,0,6,0,0,0,0,0,0,0,0,0,0,0,0,0,0,0,0,0,0,0,0,2
2,0,0,0,0,0,74,0,73,0,0,6,0,0,6,0,0,0,0,0,0,0,0,0,0,0,0,0,0,0,0,0,0,0,0,2
2,0,0,12,0,12,73,0,2,0,0,6,0,0,6,0,0,0,0,0,0,0,0,0,0,0,0,0,0,0,0,0,0,0,0,2
2,2,73,2,7,2,73,2,1,0,0,6,6,6,6,0,0,0,0,0,0,0,0,0,0,0,0,0,0,0,0,0,0,0,0,2
7,12,0,12,0,12,0,0,0,0,0,0,0,0,0,0,0,0,0,76,0,0,0,0,0,0,0,0,0,0,0,0,0,0,12,7
6,0,0,0,0,0,0,0,0,0,0,0,0,0,0,0,0,0,0,0,0,0,0,0,0,0,0,0,0,0,0,0,0,0,0,6
6,0,0,0,0,0,0,0,0,0,0,0,0,0,0,0,0,0,0,0,0,0,0,0,0,0,0,0,0,0,0,0,0,0,0,6
7,12,0,0,0,0,0,0,0,0,0,0,0,0,0,0,0,0,0,0,0,0,0,0,0,0,0,0,0,0,0,0,0,0,12,7
2,0,0,0,0,0,0,0,0,0,0,0,0,0,0,0,0,0,0,0,0,6,0,0,0,0,6,0,0,0,0,0,0,0,0,2
2,6,72,0,0,0,0,0,0,0,0,0,0,0,0,0,0,0,0,0,0,0,0,0,0,0,0,0,0,0,0,0,0,0,0,2
2,6,77,0,0,0,0,0,0,0,0,1,0,1,0,0,0,0,0,0,0,0,0,0,0,0,0,0,0,72,1,0,0,0,1,2
2,6,72,0,0,0,0,0,0,0,1,55,0,55,1,0,0,0,0,0,0,0,0,0,0,0,0,0,72,6,2,0,0,0,56,2
2,6,77,0,0,0,0,0,0,0,0,0,1,0,0,0,0,0,0,0,0,0,0,0,0,0,0,0,72,6,1,0,0,0,0,2
2,6,72,0,0,0,0,0,0,0,1,55,0,55,1,0,0,0,0,0,0,6,0,0,0,0,6,0,72,6,1,0,0,0,6,2
2,6,77,0,0,0,0,0,0,0,0,1,0,1,0,0,0,0,0,0,0,0,0,0,0,0,0,0,72,6,2,67,0,0,0,2
2,6,72,0,0,0,0,0,0,0,0,0,0,0,0,0,0,0,0,0,0,0,78,72,78,72,78,0,0,72,1,2,1,2,1,2
2,0,0,0,0,0,0,0,0,0,0,0,0,0,0,0,0,0,0,0,0,0,6,6,6,6,6,0,0,0,0,0,0,0,0,2
2,72,73,72,73,72,0,0,0,0,0,0,0,0,0,0,0,0,0,0,0,1,1,1,1,1,1,1,1,0,0,0,0,0,0,2
2,6,6,6,6,6,0,0,0,0,0,0,0,0,0,0,0,0,0,0,75,1,79,79,79,79,79,79,2,1,2,0,2,1,1,2
2,1,1,1,1,1,1,0,0,0,0,0,0,0,0,0,0,0,0,0,0,1,79,79,79,79,79,0,2,0,2,0,0,0,0,2
2,0,0,6,0,0,1,6,72,0,0,0,0,0,0,0,0,0,0,0,0,1,79,79,79,79,79,0,2,0,6,0,0,0,0,2
2,6,6,6,6,6,1,6,73,0,72,78,72,78,72,0,0,0,0,0,0,1,79,79,79,79,79,0,2,0,6,0,0,0,0,2
2,67,0,6,0,0,1,6,72,0,6,6,6,6,6,0,12,0,0,12,75,1,79,79,79,79,79,59,2,0,2,1,48,1,6,2
1,2,2,2,2,2,2,2,2,2,2,2,2,2,2,2,7,6,6,7,2,2,2,2,2,2,2,2,2,2,2,2,2,2,2,1
endlayer

layer
1,2,15,14,14,14,14,14,14,14,14,14,14,14,13,2,7,43,43,7,2,15,14,14,14,14,14,14,14,14,14,14,14,13,2,1
2,0,0,0,0,0,0,0,2,0,0,0,0,1,80,61,0,0,0,0,61,0,6,0,0,0,0,0,0,0,0,0,0,0,79,2
16,0,0,0,0,0,73,0,2,0,0,0,41,1,43,0,0,0,0,0,72,6,6,0,1,1,19,17,1,1,19,17,1,1,0,16
13,0,0,0,0,0,74,0,2,0,0,0,0,1,80,0,0,0,0,0,72,6,6,0,1,6,0,0,6,6,0,0,6,1,0,15
13,0,0,0,0,0,73,0,2,0,0,0,0,1,43,0,0,0,0,0,72,6,6,0,65,0,0,0,0,0,0,0,0,65,0,15
13,0,0,0,0,0,74,14,2,0,0,0,0,1,80,0,0,0,0,0,72,6,6,0,1,6,0,0,0,0,0,0,6,1,0,15
13,0,0,0,0,0,73,23,2,0,0,0,0,1,43,0,0,0,0,0,72,6,6,0,1,6,0,0,0,0,0,0,6,1,0,15
13,0,0,0,0,0,74,0,2,1,1,1,1,1,80,0,0,0,0,0,72,6,6,0,65,0,0,0,0,0,0,0,0,65,0,15
13,0,0,0,81,0,73,0,2,0,0,0,0,0,0,0,0,0,0,0,72,6,6,0,1,6,0,0,6,6,0,0,6,1,0,15
13,0,0,0,0,0,74,0,2,75,0,0,0,0,0,0,0,0,0,0,72,6,6,0,1,1,19,17,1,1,19,17,1,1,0,15
13,0,0,0,0,0,73,0,2,0,0,43,72,72,43,0,0,0,0,0,72,6,6,0,0,0,0,0,0,0,0,0,0,0,0,15
13,0,0,0,0,0,74,0,2,75,0,82,77,77,82,0,0,0,0,0,0,0,1,6,6,6,6,6,6,6,6,6,6,6,6,15
13,0,0,0,0,0,73,0,2,0,0,43,72,72,43,0,0,0,0,0,0,0,0,6,6,6,6,6,6,6,6,6,6,6,0,15
13,0,0,0,0,0,74,0,2,75,0,82,77,77,82,0,0,0,0,0,0,0,0,72,72,72,72,72,72,72,72,72,72,72,0,15
14,0,0,0,0,0,73,0,2,0,0,43,72,72,43,0,0,0,0,0,0,0,0,0,0,0,0,0,0,0,0,0,0,0,0,14
2,2,2,2,2,2,2,2,1,0,0,82,77,77,82,0,0,0,0,0,0,0,0,0,0,0,0,0,0,0,0,0,0,0,63,2
7,0,75,0,75,0,75,0,0,0,0,0,0,0,0,0,0,0,0,0,0,0,0,0,0,0,0,0,0,0,0,0,0,0,0,7
43,0,0,0,0,0,0,0,0,0,0,0,0,0,0,0,0,0,0,0,0,0,0,0,0,0,0,0,0,0,0,0,0,0,0,43
43,0,0,0,0,0,0,0,0,0,0,0,0,0,0,0,0,0,0,0,0,0,0,0,0,0,0,0,0,0,0,0,0,0,0,43
7,0,0,0,0,0,0,0,0,0,0,0,0,0,0,0,0,0,0,0,0,0,0,0,0,0,0,0,0,0,0,0,0,0,0,7
2,64,0,0,0,0,0,0,0,0,0,0,0,0,0,0,0,0,0,0,0,6,0,0,0,0,6,0,0,0,0,0,0,0,63,2
16,43,0,0,0,0,0,0,0,0,0,0,0,0,0,0,0,0,0,0,0,0,0,0,0,0,0,0,0,0,0,0,0,0,0,16
13,82,0,0,0,0,0,0,0,0,0,0,0,0,0,0,0,0,0,0,0,83,0,0,0,0,0,0,0,0,1,0,0,0,1,15
13,43,0,0,0,0,0,0,0,0,0,0,0,0,0,0,0,0,0,0,0,83,0,0,0,0,0,0,0,43,2,0,0,0,0,15
13,82,0,0,0,0,0,0,0,0,0,0,84,0,0,0,0,0,0,0,0,0,0,0,0,0,0,0,0,43,6,0,0,0,0,15
13,43,0,0,0,0,0,0,0,0,0,0,0,0,0,0,0,0,83,83,0,6,0,83,83,0,6,0,0,43,6,0,0,0,12,15
13,82,0,0,0,0,0,0,0,0,0,0,0,0,0,0,0,0,0,0,0,0,0,0,0,0,0,0,0,43,2,67,0,0,0,15
13,43,0,0,0,0,0,0,0,0,0,0,0,0,0,0,0,0,0,0,0,83,0,0,0,0,0,0,0,0,1,2,6,2,1,15
13,0,0,0,0,0,0,0,0,0,0,0,0,0,0,0,0,0,0,0,0,83,85,43,85,43,85,0,0,0,0,0,0,0,0,15
13,0,0,0,0,0,0,0,0,0,0,0,0,0,0,0,0,0,0,0,0,1,6,2,6,2,6,2,1,0,0,0,0,0,0,15
13,43,68,43,68,43,6,0,0,0,0,0,0,0,0,0,0,0,0,0,0,2,0,0,0,0,0,0,2,1,2,2,2,1,1,15
13,2,2,2,2,2,1,6,0,0,0,0,0,0,0,0,0,0,0,0,0,6,0,0,86,0,6,6,2,79,2,0,0,0,79,15
13,38,38,0,38,38,2,43,0,0,0,0,0,0,0,0,0,0,0,0,0,2,0,87,6,0,6,0,2,0,6,0,0,0,0,15
14,0,0,12,0,0,2,68,0,0,0,0,0,0,0,0,0,0,0,0,0,6,0,0,0,0,6,0,2,0,6,0,0,0,0,14
2,67,0,38,38,38,2,43,0,0,43,85,43,85,43,88,0,0,0,0,88,2,0,0,0,0,0,0,2,79,2,1,1,1,79,2
1,2,15,16,16,16,16,16,16,16,16,16,16,16,13,2,7,43,43,7,2,15,16,16,16,16,16,16,16,16,16,16,16,13,2,1
endlayer

layer
1,2,19,18,18,18,18,18,18,18,18,18,18,18,17,2,1,1,1,1,2,19,18,18,18,18,18,18,18,18,18,18,18,17,2,1
2,89,89,89,89,89,89,89,1,75,75,75,75,75,75,75,75,75,75,75,75,75,75,75,75,75,75,75,75,75,75,75,75,75,75,2
23,89,89,89,89,89,89,89,1,0,0,0,0,6,0,0,0,0,0,0,0,43,2,75,2,2,2,2,2,2,2,2,2,2,75,23
17,89,89,89,89,89,89,0,1,0,0,0,0,2,0,0,0,0,0,0,0,43,2,75,2,75,75,75,75,75,75,75,75,2,75,19
17,89,89,89,89,89,89,0,1,0,0,0,0,6,0,0,0,0,0,0,0,43,2,75,2,75,0,0,0,0,0,0,75,2,75,19
17,89,89,89,89,89,89,0,1,0,0,0,0,2,0,0,0,0,0,0,0,43,2,75,2,75,0,0,0,0,0,0,75,2,75,19
17,89,89,89,89,89,89,14,1,0,0,0,0,6,0,0,0,0,0,0,0,43,2,75,2,75,0,0,0,0,0,0,75,2,75,19
17,89,89,89,89,89,89,89,1,2,6,2,6,2,0,0,0,0,0,0,0,43,2,75,2,75,0,0,0,0,0,0,75,2,75,19
17,89,89,89,90,89,89,89,1,0,0,0,0,0,0,0,0,0,0,0,0,43,2,75,2,75,75,75,75,75,75,75,75,2,75,19
17,89,89,89,89,89,89,89,1,0,0,0,0,0,0,0,0,0,0,0,0,43,2,75,2,2,2,2,2,2,2,2,2,2,75,19
17,89,89,89,89,89,89,89,1,0,0,0,0,0,0,0,0,0,0,0,0,43,2,75,75,75,75,75,75,75,75,75,75,75,75,19
17,89,89,89,89,89,89,89,1,0,0,0,0,0,0,0,0,0,0,0,0,0,1,2,2,2,2,2,2,2,2,2,2,2,75,19
17,89,89,89,89,89,89,89,1,0,0,0,0,0,0,0,0,0,0,0,0,0,0,43,43,43,43,43,43,43,43,43,43,43,75,19
17,89,89,89,89,89,89,89,1,0,0,0,0,0,0,0,0,0,0,0,0,0,0,0,0,0,0,0,0,0,0,0,0,0,75,19
18,89,89,89,89,89,89,89,1,0,0,0,0,0,0,0,0,0,0,0,0,0,0,0,0,0,0,0,0,0,0,0,0,0,75,18
2,1,1,1,1,1,1,1,1,0,0,0,0,0,0,0,0,0,0,0,0,0,0,0,0,0,0,0,0,0,0,0,0,0,75,2
1,75,0,0,0,0,0,0,0,0,0,0,0,0,0,0,0,0,0,0,0,0,0,0,0,0,0,0,0,0,0,0,0,0,75,1
1,75,0,0,0,0,0,0,0,0,0,0,0,0,0,0,0,0,0,0,0,0,0,0,0,0,0,0,0,0,0,0,0,0,75,1
1,75,0,0,0,0,0,0,0,0,0,0,0,0,0,0,0,0,0,0,0,0,0,0,0,0,0,0,0,0,0,0,0,0,75,1
1,75,0,0,0,0,0,0,0,0,0,0,0,0,0,0,0,0,0,0,0,0,0,0,0,0,0,0,0,0,0,0,0,0,75,1
2,75,0,0,0,0,0,0,0,0,0,0,0,0,0,0,0,0,0,0,0,6,0,0,0,0,6,0,0,0,0,0,0,0,75,2
23,75,0,0,0,0,0,0,0,0,0,0,0,0,0,0,0,0,0,0,0,0,0,0,0,0,0,0,0,0,0,0,0,0,75,23
17,75,0,0,0,0,0,0,0,0,0,0,0,0,0,0,0,0,0,0,0,0,0,0,0,0,0,0,0,0,1,1,1,1,1,19
17,75,0,0,0,0,0,0,0,0,0,0,0,0,0,0,0,0,0,0,0,83,0,0,0,0,0,0,0,0,1,75,75,75,75,19
17,75,0,0,0,0,0,0,0,0,0,0,84,0,0,0,0,0,0,0,0,83,0,0,0,0,0,0,0,0,1,75,75,75,75,19
17,75,0,0,0,0,0,0,0,0,0,0,0,0,0,0,0,0,0,83,83,83,83,83,0,0,6,0,0,0,1,75,75,75,75,19
17,75,0,0,0,0,0,0,0,0,0,0,0,0,0,0,0,0,0,0,0,83,0,0,0,0,0,0,0,0,1,67,75,75,75,19
17,75,0,0,0,0,0,0,0,0,0,0,0,0,0,0,0,0,0,0,0,83,0,0,0,0,0,0,0,0,1,1,1,1,1,19
17,75,0,0,0,0,0,0,0,0,0,0,0,0,0,0,0,0,0,0,0,0,0,0,0,0,0,0,0,0,0,0,0,0,75,19
17,75,0,0,0,0,0,0,0,0,0,0,0,0,0,0,0,0,0,0,0,1,0,2,0,2,0,2,1,0,0,0,0,0,75,19
17,75,0,0,0,0,12,0,0,0,0,0,0,0,0,0,0,0,0,0,0,2,0,0,0,0,0,94,2,93,92,92,92,91,75,19
17,2,2,2,2,2,1,12,0,0,0,0,0,0,0,0,0,0,0,0,0,0,0,0,0,0,0,0,2,75,75,75,75,75,75,19
17,79,79,79,79,79,2,0,0,0,0,0,0,0,0,0,0,0,0,0,0,2,0,0,43,0,0,0,2,75,75,75,75,75,75,19
18,79,79,79,79,79,2,0,0,0,0,0,0,0,0,0,0,0,0,0,0,0,0,0,0,0,12,0,2,75,75,75,75,75,75,18
2,67,79,79,79,79,2,75,75,75,75,75,75,75,75,75,75,75,75,93,92,2,0,0,0,0,0,0,2,92,91,1,1,1,75,2
1,2,19,23,23,23,23,23,23,23,23,23,23,23,17,2,1,1,1,1,2,19,23,23,23,23,23,23,23,23,23,23,23,17,2,1
endlayer

layer
1,15,13,15,13,15,13,15,13,15,13,15,13,15,13,15,13,15,13,15,13,15,13,15,13,15,13,15,13,15,13,15,13,15,13,1
16,0,0,0,0,0,0,0,0,0,0,0,0,0,0,0,0,0,0,0,0,0,0,0,0,0,0,0,0,0,0,0,0,0,0,16
14,0,0,0,0,0,6,6,13,0,0,0,0,6,0,0,0,0,0,0,0,0,14,0,1,15,0,0,13,15,0,0,13,1,0,14
16,0,0,0,0,0,6,0,6,0,0,0,0,6,0,0,0,0,0,0,0,0,16,0,16,0,0,0,0,0,0,0,0,16,0,16
14,0,0,0,0,0,6,0,13,0,0,0,0,6,0,0,0,0,0,0,0,0,14,0,0,0,0,0,0,0,0,0,0,0,0,14
16,0,0,0,0,0,6,39,6,0,0,0,0,6,0,0,0,0,0,0,0,0,16,0,14,0,0,0,0,0,0,0,0,14,0,16
14,0,0,0,0,0,0,0,13,0,0,0,0,6,0,0,0,0,0,0,0,0,14,0,16,0,0,0,0,0,0,0,0,16,0,14
16,0,0,13,14,15,0,0,6,6,6,6,6,6,0,0,0,0,0,0,0,0,16,0,0,0,0,0,0,0,0,0,0,0,0,16
14,0,1,1,4,1,1,0,13,0,0,0,0,0,0,0,0,0,0,0,0,0,14,0,14,0,0,0,0,0,0,0,0,14,0,14
16,0,35,95,95,95,35,0,6,0,0,0,0,0,0,0,0,0,0,0,0,0,16,0,1,15,0,0,13,15,0,0,13,1,0,16
14,0,35,95,95,95,35,0,13,0,0,0,0,0,0,0,0,0,0,0,0,0,14,0,0,0,0,0,0,0,0,0,0,0,0,14
16,0,35,95,95,95,35,0,6,0,0,0,0,0,0,0,0,0,0,0,0,0,1,15,13,15,13,15,13,15,13,15,13,15,0,16
14,0,35,95,95,95,35,0,13,0,0,0,0,0,0,0,0,0,0,0,0,0,0,0,0,0,0,0,0,0,0,0,0,0,0,14
16,0,1,35,35,35,1,0,6,0,0,0,0,0,0,0,0,0,0,0,0,0,0,0,0,0,0,0,0,0,0,0,0,0,0,16
14,0,0,0,0,0,0,0,13,0,0,0,0,0,0,0,0,0,0,0,0,0,0,0,0,0,0,0,0,0,0,0,0,0,0,14
16,0,15,13,15,13,15,13,1,0,0,0,0,0,0,0,0,0,0,0,0,0,0,0,0,0,0,0,0,0,0,0,0,0,0,16
14,0,0,0,0,0,0,0,0,0,0,0,0,0,0,0,0,0,0,0,0,83,0,0,0,0,0,0,0,0,0,0,0,0,0,14
16,0,0,0,0,0,0,0,0,0,0,0,0,0,0,0,0,0,0,0,0,0,0,0,0,0,0,0,0,0,0,0,0,0,0,16
14,0,0,0,0,0,0,0,0,0,0,0,0,0,0,0,0,0,0,0,0,0,0,0,0,0,0,0,0,0,0,0,0,0,0,14
16,0,0,0,0,0,0,0,0,0,0,0,0,0,0,0,0,0,0,0,0,0,0,0,0,0,0,0,0,0,0,0,0,0,0,16
14,0,0,0,0,0,0,0,0,0,0,0,0,0,0,0,0,83,0,0,0,6,0,0,0,83,6,0,0,0,0,0,0,0,0,14
16,0,0,0,0,0,0,0,0,0,0,0,0,0,0,0,0,0,0,0,0,0,0,0,0,0,0,0,0,0,0,0,0,0,0,16
14,0,0,0,0,0,0,0,0,0,0,0,0,0,0,0,0,0,0,0,0,0,0,0,0,0,0,0,0,0,6,6,6,6,0,14
16,0,0,0,0,0,0,0,0,0,0,0,0,0,0,0,0,0,0,0,0,0,0,0,0,0,83,0,0,0,6,0,0,0,0,16
14,0,0,0,0,0,0,0,0,0,0,0,84,0,0,0,0,0,0,0,0,83,0,0,0,0,83,0,0,0,6,0,0,0,0,14
16,0,0,0,0,0,0,0,0,0,0,0,0,0,0,0,0,0,0,0,0,0,0,0,83,83,6,83,83,0,6,0,0,0,0,16
14,0,0,0,0,0,0,0,0,0,0,0,0,0,0,0,0,0,0,0,0,0,0,0,0,0,83,0,0,0,6,0,0,0,0,14
16,0,0,0,0,0,0,0,0,0,0,0,0,0,0,0,0,0,0,0,0,0,0,0,0,0,83,0,0,0,6,6,6,6,0,16
14,0,0,0,0,0,0,0,0,0,0,0,0,0,0,0,0,0,0,0,0,0,75,0,75,0,75,0,0,0,0,0,0,0,0,14
16,0,0,0,0,0,0,0,0,0,0,0,0,0,0,0,0,0,0,0,0,1,1,1,1,1,1,1,1,0,0,0,0,0,0,16
14,0,0,0,0,0,0,0,0,0,0,0,0,0,0,0,0,0,0,0,0,1,79,79,79,79,79,94,1,0,75,75,75,0,0,14
16,0,15,13,15,13,1,0,0,0,0,0,0,0,0,0,0,0,0,0,75,1,79,79,79,79,79,79,1,0,0,0,0,0,0,16
14,0,0,0,0,0,16,0,0,0,0,0,0,0,0,0,0,0,0,0,0,1,79,79,79,79,79,79,1,0,0,0,0,0,0,14
16,0,0,0,0,0,14,0,0,0,0,0,0,0,0,0,0,0,0,0,75,1,79,79,79,79,79,79,1,0,0,0,0,0,0,16
14,96,0,0,0,0,0,0,0,0,0,0,0,0,0,0,0,0,0,0,93,1,79,79,79,79,79,79,1,91,0,1,1,1,0,14
1,15,13,15,13,15,13,15,13,15,13,15,13,15,13,15,13,15,13,15,13,1,1,1,1,1,1,1,1,15,13,15,13,15,13,1
endlayer

layer
6,0,0,0,0,0,0,0,6,6,6,6,6,6,0,0,0,0,0,0,0,0,0,0,0,0,0,0,0,0,0,0,0,0,0,6
0,0,0,0,0,0,0,0,0,0,0,0,0,0,0,0,0,0,0,0,0,0,0,0,0,0,0,0,0,0,0,0,0,0,0,0
0,0,0,0,0,0,6,6,6,0,0,0,0,6,0,0,0,0,0,0,0,0,0,0,1,6,0,0,6,6,0,0,6,1,0,0
0,0,0,0,0,0,6,0,6,0,0,0,0,6,0,0,0,0,0,0,0,0,0,0,6,0,0,0,0,0,0,0,0,6,0,0
0,0,0,0,0,0,12,0,6,0,0,0,0,6,0,0,0,0,0,0,0,0,0,0,0,0,0,0,0,0,0,0,0,0,0,0
0,0,0,0,0,0,6,0,6,0,0,0,0,6,0,0,0,0,0,0,0,0,0,0,6,0,0,0,0,0,0,0,0,6,0,0
0,0,0,0,0,0,0,0,6,0,0,0,0,6,0,0,0,0,0,0,0,0,0,0,6,0,0,0,0,0,0,0,0,6,0,0
0,0,0,0,0,0,0,0,6,6,6,6,6,6,0,0,0,0,0,0,0,0,0,0,0,0,0,0,0,0,0,0,0,0,0,0
0,0,6,0,0,0,6,0,0,0,0,0,0,0,0,0,0,0,0,0,0,0,0,0,6,0,0,0,0,0,0,0,0,6,0,0
0,0,0,97,97,97,0,0,0,0,0,0,0,0,0,0,0,0,0,0,0,0,0,0,1,6,0,0,6,6,0,0,6,1,0,0
0,0,0,97,97,97,0,0,0,0,0,0,0,0,0,0,0,0,0,0,0,0,0,0,0,0,0,0,0,0,0,0,0,0,0,0
0,0,0,97,97,97,0,0,0,0,0,0,0,0,0,0,0,0,0,0,0,0,12,0,0,0,0,0,0,0,0,0,0,0,0,0
0,0,0,97,97,97,0,0,0,0,0,0,0,0,0,0,0,0,0,0,0,0,0,0,0,0,0,0,0,0,0,0,0,0,0,0
0,0,6,0,0,0,6,0,0,0,0,0,0,0,0,0,0,0,0,0,0,0,0,0,0,0,0,0,0,0,0,0,0,0,0,0
0,0,0,0,0,0,0,0,0,0,0,0,0,0,0,0,0,0,0,0,0,0,0,0,0,0,0,0,0,0,0,0,0,0,0,0
0,0,0,0,0,0,0,0,0,0,0,0,0,0,0,0,0,0,0,0,0,0,0,0,0,0,0,0,0,0,0,0,0,0,0,0
0,0,0,0,0,0,0,0,0,0,0,0,0,0,0,0,0,0,0,0,0,0,0,0,0,0,0,0,0,0,0,0,0,0,0,0
0,0,0,0,0,0,0,0,0,0,0,0,0,0,0,0,0,0,0,0,0,83,0,0,0,0,0,0,0,0,0,0,0,0,0,0
0,0,0,0,0,0,0,0,0,0,0,0,0,0,0,0,0,0,0,0,0,83,0,0,0,0,0,0,0,0,0,0,0,0,0,0
0,0,0,0,0,0,0,0,0,0,0,0,0,0,0,0,0,0,0,0,0,83,0,0,0,0,0,0,0,0,0,0,0,0,0,0
0,0,0,0,0,0,0,0,0,0,0,0,0,0,0,0,0,0,83,83,83,6,83,83,83,0,6,0,0,0,0,0,0,0,0,0
0,0,0,0,0,0,0,0,0,0,0,0,0,0,0,0,0,0,0,0,0,83,0,0,0,0,0,0,0,0,0,0,0,0,0,0
0,0,0,0,0,0,0,0,0,0,0,0,0,0,0,0,0,0,0,0,0,83,0,0,0,0,0,0,0,0,6,0,0,6,0,0
0,0,0,0,0,0,0,0,0,0,0,0,0,0,0,0,0,0,0,0,0,83,0,0,0,0,0,0,0,0,0,0,0,0,0,0
0,0,0,0,0,0,0,0,0,0,0,0,4,0,0,0,0,0,0,0,0,0,0,0,0,0,83,0,0,0,0,0,0,0,0,0
0,0,0,0,0,0,0,0,0,0,0,0,0,0,0,0,0,0,0,0,0,0,0,0,0,83,83,83,0,0,0,0,0,0,0,0
0,0,0,0,0,0,0,0,0,0,0,0,0,0,0,0,0,0,0,0,0,0,0,0,0,0,83,0,0,0,0,0,0,0,0,0
0,0,0,0,0,0,0,0,0,0,0,0,0,0,0,0,0,0,0,0,0,0,0,0,0,0,0,0,0,0,6,0,0,6,0,0
0,0,0,0,0,0,0,0,0,0,0,0,0,0,0,0,0,0,0,0,0,0,0,0,0,0,0,0,0,0,0,0,0,0,0,0
0,0,0,0,0,0,0,0,0,0,0,0,0,0,0,0,0,0,0,0,0,1,15,13,15,13,15,13,1,0,0,0,0,0,0,0
0,0,0,0,0,0,0,0,0,0,0,0,0,0,0,0,0,0,0,0,0,16,0,0,0,0,0,98,16,0,0,0,0,0,0,0
0,0,0,0,0,0,6,0,0,0,0,0,0,0,0,0,0,0,0,0,0,14,0,0,0,0,0,0,14,0,0,0,0,0,0,0
0,0,0,0,0,0,0,0,0,0,0,0,0,0,0,0,0,0,0,0,0,16,0,0,0,0,0,0,16,0,0,0,0,0,0,0
0,0,0,0,0,0,0,0,0,0,0,0,0,0,0,0,0,0,0,0,0,14,0,0,0,0,0,0,14,0,0,0,0,0,0,0
0,0,0,0,0,0,0,0,0,0,0,0,0,0,0,0,0,0,0,0,0,0,0,0,0,0,0,0,0,0,0,13,1,15,0,0
6,0,0,0,0,0,0,0,0,0,0,0,0,0,0,0,0,0,0,0,0,15,13,15,13,15,13,15,13,0,0,0,0,0,0,6
endlayer

layer
12,0,0,0,0,0,0,0,6,6,6,6,6,6,0,0,0,0,0,0,0,0,0,0,0,0,0,0,0,0,0,0,0,0,0,12
0,0,0,0,0,0,0,0,6,0,0,0,0,6,0,0,0,0,0,0,0,0,0,0,0,0,0,0,6,6,0,0,0,0,0,0
0,0,0,0,0,72,6,6,6,0,0,0,0,6,0,0,0,0,0,0,0,0,0,0,1,6,0,0,6,6,0,0,6,1,0,0
0,0,0,0,0,72,6,6,6,0,0,0,0,6,0,0,0,0,0,0,0,0,0,0,6,6,0,0,0,0,0,0,6,6,0,0
0,0,0,0,0,72,6,6,6,0,0,0,0,6,0,0,0,0,0,0,0,0,0,0,0,0,0,0,0,0,0,0,0,0,0,0
0,0,0,0,0,72,6,6,6,0,0,0,0,6,0,0,0,0,0,0,0,0,0,6,6,0,0,0,0,0,0,0,0,6,6,0
0,0,0,0,0,0,0,0,6,0,0,0,0,6,0,0,0,0,0,0,0,0,0,6,6,0,0,0,0,0,0,0,0,6,6,0
0,0,0,0,0,0,0,0,6,6,6,6,6,6,0,0,0,0,0,0,0,0,0,0,0,0,0,0,0,0,0,0,0,0,0,0
0,0,12,0,0,0,12,0,0,0,0,0,0,0,0,0,0,0,0,0,0,0,0,0,6,6,0,0,0,0,0,0,6,6,0,0
0,0,0,0,0,0,0,0,0,0,0,0,0,0,0,0,0,0,0,0,0,0,0,0,1,6,0,0,6,6,0,0,6,1,0,0
0,0,0,0,0,0,0,0,0,0,0,0,0,0,0,0,0,0,0,0,0,0,0,0,0,0,0,0,6,6,0,0,0,0,0,0
0,0,0,0,0,0,0,0,0,0,0,0,0,0,0,0,0,0,0,0,0,0,0,0,0,0,0,0,0,0,0,0,0,0,0,0
0,0,0,0,0,0,0,0,0,0,0,0,0,0,0,0,0,0,0,0,0,0,0,0,0,0,0,0,0,0,0,0,0,0,0,0
0,0,12,0,0,0,12,0,0,0,0,0,0,0,0,0,0,0,0,0,0,0,0,0,0,0,0,0,0,0,0,0,0,0,0,0
0,0,0,0,0,0,0,0,0,0,0,0,0,0,0,0,0,0,0,0,0,0,0,0,0,0,0,0,0,0,0,0,0,0,0,0
0,0,0,0,0,0,0,0,0,0,0,0,0,0,0,0,0,0,0,0,0,0,0,0,0,0,0,0,0,0,0,0,0,0,0,0
0,0,0,0,0,0,0,0,0,0,0,0,0,0,0,0,0,0,0,0,0,0,0,0,0,0,0,0,0,0,0,0,0,0,0,0
0,0,0,0,0,0,0,0,0,0,0,0,0,0,0,0,0,0,0,0,0,0,0,0,0,0,0,0,0,0,0,0,0,0,0,0
0,0,0,0,0,0,0,0,0,0,0,0,0,0,0,0,0,0,0,0,0,0,0,0,0,0,0,0,0,0,0,0,0,0,0,0
0,0,0,0,0,0,0,0,0,0,0,0,0,0,0,0,0,0,0,0,0,83,0,0,0,0,0,0,0,0,0,0,0,0,0,0
0,0,0,0,0,0,0,0,0,0,0,0,0,0,0,0,0,0,0,0,83,83,83,0,0,0,6,0,0,0,0,0,0,0,0,0
0,0,0,0,0,0,0,0,0,0,0,0,0,0,0,0,0,0,0,0,0,83,0,0,0,0,0,0,0,6,72,72,72,72,6,0
0,0,0,0,0,0,0,0,0,0,0,0,0,0,0,0,0,0,0,0,0,0,0,0,0,0,0,0,0,72,6,6,6,6,72,0
0,0,0,0,0,0,0,0,0,0,0,0,0,0,0,0,0,0,0,0,0,0,0,0,0,0,0,0,0,72,6,6,6,6,72,0
0,0,0,0,0,0,0,0,0,0,0,0,0,0,0,0,0,0,0,0,0,0,0,0,0,0,0,0,0,72,6,6,6,6,72,0
0,0,0,0,0,0,0,0,0,0,0,0,0,0,0,0,0,0,0,0,0,0,0,0,0,0,0,0,0,72,6,6,6,6,72,0
0,0,0,0,0,0,0,0,0,0,0,0,0,0,0,0,0,0,0,0,0,0,0,0,0,0,0,0,0,72,6,6,6,6,72,0
0,0,0,0,0,0,0,0,0,0,0,0,0,0,0,0,0,0,0,0,0,0,0,0,0,0,0,0,0,72,6,6,6,6,72,0
0,0,0,0,0,0,0,0,0,0,0,0,0,0,0,0,0,0,0,0,0,0,0,0,0,0,0,0,0,6,72,72,72,72,6,0
0,0,0,0,0,0,0,0,0,0,0,0,0,0,0,0,0,0,0,0,0,6,0,0,0,0,0,0,6,0,0,0,0,0,0,0
0,0,0,0,0,0,0,0,0,0,0,0,0,0,0,0,0,0,0,0,0,0,0,0,0,0,0,0,0,0,0,0,0,0,0,0
0,0,0,0,0,0,12,0,0,0,0,0,0,0,0,0,0,0,0,0,0,0,0,0,0,0,0,0,0,0,0,0,0,0,0,0
0,0,0,0,0,0,0,0,0,0,0,0,0,0,0,0,0,0,0,0,0,0,0,0,0,0,0,0,0,0,0,0,0,0,0,0
0,0,0,0,0,0,0,0,0,0,0,0,0,0,0,0,0,0,0,0,0,0,0,0,0,0,0,0,0,0,0,0,0,0,0,0
0,0,0,0,0,0,0,0,0,0,0,0,0,0,0,0,0,0,0,0,0,0,0,0,0,0,0,0,0,0,0,0,1,0,0,0
12,0,0,0,0,0,0,0,0,0,0,0,0,0,0,0,0,0,0,0,0,0,0,0,0,0,0,0,0,0,0,0,0,0,0,12
endlayer

layer
0,0,0,0,0,0,0,0,72,72,72,72,72,72,0,0,0,0,0,0,0,0,0,0,0,0,0,0,0,0,0,0,0,0,0,0
0,0,0,0,0,0,0,0,72,6,6,6,6,72,0,0,0,0,0,0,0,0,0,0,0,0,0,0,12,12,0,0,0,0,0,0
0,0,0,0,0,0,43,43,72,6,6,6,6,72,0,0,0,0,0,0,0,0,0,0,1,19,0,0,17,19,0,0,17,1,0,0
0,0,0,0,0,0,43,43,72,6,0,0,6,72,0,0,0,0,0,0,0,0,0,0,23,12,0,0,0,0,0,0,12,23,0,0
0,0,0,0,0,0,43,43,72,6,0,0,6,72,0,0,0,0,0,0,0,0,0,0,0,0,0,0,0,0,0,0,0,0,0,0
0,0,0,0,0,0,43,43,72,6,6,6,6,72,0,0,0,0,0,0,0,0,0,12,18,0,0,0,0,0,0,0,0,18,12,0
0,0,0,0,0,0,0,0,72,6,6,6,6,72,0,0,0,0,0,0,0,0,0,12,23,0,0,0,0,0,0,0,0,23,12,0
0,0,0,0,0,0,0,0,72,72,72,72,72,72,0,0,0,0,0,0,0,0,0,0,0,0,0,0,0,0,0,0,0,0,0,0
0,0,0,0,0,0,0,0,0,0,0,0,0,0,0,0,0,0,0,0,0,0,0,0,18,12,0,0,0,0,0,0,12,18,0,0
0,0,0,0,0,0,0,0,0,0,0,0,0,0,0,0,0,0,0,0,0,0,0,0,1,19,0,0,17,19,0,0,17,1,0,0
0,0,0,0,0,0,0,0,0,0,0,0,0,0,0,0,0,0,0,0,0,0,0,0,0,0,0,0,12,12,0,0,0,0,0,0
0,0,0,0,0,0,0,0,0,0,0,0,0,0,0,0,0,0,0,0,0,0,0,0,0,0,0,0,0,0,0,0,0,0,0,0
0,0,0,0,0,0,0,0,0,0,0,0,0,0,0,0,0,0,0,0,0,0,0,0,0,0,0,0,0,0,0,0,0,0,0,0
0,0,0,0,0,0,0,0,0,0,0,0,0,0,0,0,0,0,0,0,0,0,0,0,0,0,0,0,0,0,0,0,0,0,0,0
0,0,0,0,0,0,0,0,0,0,0,0,0,0,0,0,0,0,0,0,0,0,0,0,0,0,0,0,0,0,0,0,0,0,0,0
0,0,0,0,0,0,0,0,0,0,0,0,0,0,0,0,0,0,0,0,0,0,0,0,0,0,83,0,0,0,0,0,0,0,0,0
0,0,0,0,0,0,0,0,0,0,0,0,0,0,0,0,0,0,0,0,0,0,0,0,0,0,83,0,0,0,0,0,0,0,0,0
0,0,0,0,0,0,0,0,0,0,0,0,0,0,0,0,0,0,0,0,0,0,0,0,0,0,83,0,0,0,0,0,0,0,0,0
0,0,0,0,0,0,0,0,0,0,0,0,0,0,0,0,0,0,0,0,0,0,0,0,0,0,0,0,0,0,0,0,0,0,0,0
0,0,0,0,0,0,0,0,0,0,0,0,0,0,0,0,0,0,0,0,0,0,0,0,0,0,0,0,0,0,0,0,0,0,0,0
0,0,0,0,0,0,0,0,0,0,0,0,0,0,0,0,0,0,0,0,0,83,83,83,0,0,6,0,0,83,83,83,0,0,0,0
0,0,0,0,0,0,0,0,0,0,0,0,0,0,0,0,0,0,0,0,0,0,0,0,0,0,0,0,0,12,0,0,0,0,12,0
0,0,0,0,0,0,0,0,0,0,0,0,0,0,0,0,0,0,0,0,0,0,0,0,0,0,0,0,0,0,43,43,43,43,0,0
0,0,0,0,0,0,0,0,0,0,0,0,0,0,0,0,0,0,0,0,0,0,0,0,0,0,83,0,0,0,43,43,43,43,0,0
0,0,0,0,0,0,0,0,0,0,0,0,0,0,0,0,0,0,0,0,0,0,0,0,0,0,83,0,0,0,43,43,43,43,0,0
0,0,0,0,0,0,0,0,0,0,0,0,0,0,0,0,0,0,0,0,0,0,0,0,0,0,83,0,0,0,43,43,43,43,0,0
0,0,0,0,0,0,0,0,0,0,0,0,0,0,0,0,0,0,0,0,0,0,0,0,0,0,0,0,0,0,43,43,43,43,0,0
0,0,0,0,0,0,0,0,0,0,0,0,0,0,0,0,0,0,0,0,0,0,0,0,0,0,0,0,0,0,43,43,43,43,0,0
0,0,0,0,0,0,0,0,0,0,0,0,0,0,0,0,0,0,0,0,0,0,0,0,0,0,0,0,0,12,0,0,0,0,12,0
0,0,0,0,0,0,0,0,0,0,0,0,0,0,0,0,0,0,0,0,0,12,0,0,0,0,0,0,12,0,0,0,0,0,0,0
0,0,0,0,0,0,0,0,0,0,0,0,0,0,0,0,0,0,0,0,0,0,0,0,0,0,0,0,0,0,0,0,0,0,0,0
0,0,0,0,0,0,0,0,0,0,0,0,0,0,0,0,0,0,0,0,0,0,0,0,0,0,0,0,0,0,0,0,0,0,0,0
0,0,0,0,0,0,0,0,0,0,0,0,0,0,0,0,0,0,0,0,0,0,0,0,0,0,0,0,0,0,0,0,0,0,0,0
0,0,0,0,0,0,0,0,0,0,0,0,0,0,0,0,0,0,0,0,0,0,0,0,0,0,0,0,0,0,0,0,0,0,0,0
0,0,0,0,0,0,0,0,0,0,0,0,0,0,0,0,0,0,0,0,0,0,0,0,0,0,0,0,0,0,0,0,40,0,0,0
0,0,0,0,0,0,0,0,0,0,0,0,0,0,0,0,0,0,0,0,0,0,0,0,0,0,0,0,0,0,0,0,0,0,0,0
endlayer

layer
0,0,0,0,0,0,0,0,0,0,0,0,0,0,0,0,0,0,0,0,0,0,0,0,0,0,0,0,0,0,0,0,0,0,0,0
0,0,0,0,0,0,0,0,0,43,43,43,43,0,0,0,0,0,0,0,0,0,0,55,55,55,55,55,55,55,55,55,55,55,55,0
0,0,0,0,0,0,0,0,0,43,12,12,43,0,0,0,0,0,0,0,0,0,0,55,100,100,100,100,100,100,100,100,100,99,55,0
0,0,0,0,0,0,0,0,0,43,0,0,43,0,0,0,0,0,0,0,0,0,0,55,102,101,101,101,101,101,101,101,101,99,55,0
0,0,0,0,0,0,0,0,0,43,0,0,43,0,0,0,0,0,0,0,0,0,0,55,102,101,0,0,0,0,0,0,101,99,55,0
0,0,0,0,0,0,0,0,0,43,12,12,43,0,0,0,0,0,0,0,0,0,0,55,102,101,0,0,0,0,0,0,101,99,55,0
0,0,0,0,0,0,0,0,0,43,43,43,43,0,0,0,0,0,0,0,0,0,0,55,102,101,0,0,0,0,0,0,101,99,55,0
0,0,0,0,0,0,0,0,0,0,0,0,0,0,0,0,0,0,0,0,0,0,0,55,102,101,0,0,0,0,0,0,101,99,55,0
0,0,0,0,0,0,0,0,0,0,0,0,0,0,0,0,0,0,0,0,0,0,0,55,102,101,101,101,101,101,101,101,101,99,55,0
0,0,0,0,0,0,0,0,0,0,0,0,0,0,0,0,0,0,0,0,0,0,0,55,102,103,103,103,103,103,103,103,103,103,55,0
0,0,0,0,0,0,0,0,0,0,0,0,0,0,0,0,0,0,0,0,0,0,0,55,55,55,55,55,55,55,55,55,55,55,55,0
0,0,0,0,0,0,0,0,0,0,0,0,0,0,0,0,0,0,0,0,0,0,0,0,0,0,0,0,0,0,0,0,0,0,0,0
0,0,0,0,0,0,0,0,0,0,0,0,0,0,0,0,0,0,0,0,0,0,0,0,0,0,0,0,0,0,0,0,0,0,0,0
0,0,0,0,0,0,0,0,0,0,0,0,0,0,0,0,0,0,0,0,0,0,0,0,0,0,0,0,0,0,0,0,0,0,0,0
0,0,0,0,0,0,0,0,0,0,0,0,0,0,0,0,0,0,0,0,0,0,0,0,0,0,0,0,0,0,0,0,0,0,0,0
0,0,0,0,0,0,0,0,0,0,0,0,0,0,0,0,0,0,0,0,0,0,0,0,0,0,0,0,0,0,0,0,0,0,0,0
0,0,0,0,0,0,0,0,0,0,0,0,0,0,0,0,0,0,0,0,0,0,0,0,0,0,0,0,0,0,0,0,0,0,0,0
0,0,0,0,0,0,0,0,0,0,0,0,0,0,0,0,0,0,0,0,0,0,0,0,0,0,83,0,0,0,0,0,0,0,0,0
0,0,0,0,0,0,0,0,0,0,0,0,0,0,0,0,0,0,0,0,0,0,0,0,0,0,83,0,0,0,0,0,0,0,0,0
0,0,0,0,0,0,0,0,0,0,0,0,0,0,0,0,0,0,0,0,0,0,0,0,0,0,83,0,0,0,0,0,0,0,0,0
0,0,0,0,0,0,0,0,0,0,0,0,0,0,0,0,0,0,0,0,0,0,0,83,83,83,83,83,83,83,0,0,0,0,0,0
0,0,0,0,0,0,0,0,0,0,0,0,0,0,0,0,0,0,0,0,0,0,0,0,0,0,83,0,0,0,0,0,0,0,0,0
0,0,0,0,0,0,0,0,0,0,0,0,0,0,0,0,0,0,0,0,0,0,0,0,0,0,83,0,0,0,0,0,0,0,0,0
0,0,0,0,0,0,0,0,0,0,0,0,0,0,0,0,0,0,0,0,0,0,0,0,0,0,83,0,0,0,0,0,0,0,0,0
0,0,0,0,0,0,0,0,0,0,0,0,0,0,0,0,0,0,0,0,0,0,0,0,0,0,0,0,0,0,0,0,0,0,0,0
0,0,0,0,0,0,0,0,0,0,0,0,0,0,0,0,0,0,0,0,0,0,0,0,0,0,0,0,0,0,0,0,0,0,0,0
0,0,0,0,0,0,0,0,0,0,0,0,0,0,0,0,0,0,0,0,0,0,0,0,0,0,0,0,0,0,0,0,0,0,0,0
0,0,0,0,0,0,0,0,0,0,0,0,0,0,0,0,0,0,0,0,0,0,0,0,0,0,0,0,0,0,0,0,0,0,0,0
0,0,0,0,0,0,0,0,0,0,0,0,0,0,0,0,0,0,0,0,0,0,0,0,0,0,0,0,0,0,0,0,0,0,0,0
0,0,0,0,0,0,0,0,0,0,0,0,0,0,0,0,0,0,0,0,0,0,0,0,0,0,0,0,0,0,0,0,0,0,0,0
0,0,0,0,0,0,0,0,0,0,0,0,0,0,0,0,0,0,0,0,0,0,0,0,0,0,0,0,0,0,0,0,0,0,0,0
0,0,0,0,0,0,0,0,0,0,0,0,0,0,0,0,0,0,0,0,0,0,0,0,0,0,0,0,0,0,0,0,0,0,0,0
0,0,0,0,0,0,0,0,0,0,0,0,0,0,0,0,0,0,0,0,0,0,0,0,0,0,0,0,0,0,0,0,0,0,0,0
0,0,0,0,0,0,0,0,0,0,0,0,0,0,0,0,0,0,0,0,0,0,0,0,0,0,0,0,0,0,0,0,0,0,0,0
0,0,0,0,0,0,0,0,0,0,0,0,0,0,0,0,0,0,0,0,0,0,0,0,0,0,0,0,0,0,0,0,0,0,0,0
0,0,0,0,0,0,0,0,0,0,0,0,0,0,0,0,0,0,0,0,0,0,0,0,0,0,0,0,0,0,0,0,0,0,0,0
endlayer

layer
0,0,0,0,0,0,0,0,0,0,0,0,0,0,0,0,0,0,0,0,0,0,0,0,0,0,0,0,0,0,0,0,0,0,0,0
0,0,0,0,0,0,0,0,0,0,0,0,0,0,0,0,0,0,0,0,0,0,0,0,0,0,0,0,0,0,0,0,0,0,0,0
0,0,0,0,0,0,0,0,0,0,0,0,0,0,0,0,0,0,0,0,0,0,0,0,0,0,0,0,0,0,0,0,0,0,0,0
0,0,0,0,0,0,0,0,0,0,0,0,0,0,0,0,0,0,0,0,0,0,0,0,0,55,55,55,55,55,55,55,55,0,0,0
0,0,0,0,0,0,0,0,0,0,0,0,0,0,0,0,0,0,0,0,0,0,0,0,0,55,55,55,55,55,55,55,55,0,0,0
0,0,0,0,0,0,0,0,0,0,0,0,0,0,0,0,0,0,0,0,0,0,0,0,0,55,55,35,35,35,35,55,55,0,0,0
0,0,0,0,0,0,0,0,0,0,0,0,0,0,0,0,0,0,0,0,0,0,0,0,0,55,55,35,35,35,35,55,55,0,0,0
0,0,0,0,0,0,0,0,0,0,0,0,0,0,0,0,0,0,0,0,0,0,0,0,0,55,55,55,55,55,55,55,55,0,0,0
0,0,0,0,0,0,0,0,0,0,0,0,0,0,0,0,0,0,0,0,0,0,0,0,0,55,55,55,55,55,55,55,55,0,0,0
0,0,0,0,0,0,0,0,0,0,0,0,0,0,0,0,0,0,0,0,0,0,0,0,0,0,0,0,0,0,0,0,0,0,0,0
0,0,0,0,0,0,0,0,0,0,0,0,0,0,0,0,0,0,0,0,0,0,0,0,0,0,0,0,0,0,0,0,0,0,0,0
0,0,0,0,0,0,0,0,0,0,0,0,0,0,0,0,0,0,0,0,0,0,0,0,0,0,0,0,0,0,0,0,0,0,0,0
0,0,0,0,0,0,0,0,0,0,0,0,0,0,0,0,0,0,0,0,0,0,0,0,0,0,0,0,0,0,0,0,0,0,0,0
0,0,0,0,0,0,0,0,0,0,0,0,0,0,0,0,0,0,0,0,0,0,0,0,0,0,0,0,0,0,0,0,0,0,0,0
0,0,0,0,0,0,0,0,0,0,0,0,0,0,0,0,0,0,0,0,0,0,0,0,0,0,0,0,0,0,0,0,0,0,0,0
0,0,0,0,0,0,0,0,0,0,0,0,0,0,0,0,0,0,0,0,0,0,0,0,0,0,0,0,0,0,0,0,0,0,0,0
0,0,0,0,0,0,0,0,0,0,0,0,0,0,0,0,0,0,0,0,0,0,0,0,0,0,0,0,0,0,0,0,0,0,0,0
0,0,0,0,0,0,0,0,0,0,0,0,0,0,0,0,0,0,0,0,0,0,0,0,0,0,0,0,0,0,0,0,0,0,0,0
0,0,0,0,0,0,0,0,0,0,0,0,0,0,0,0,0,0,0,0,0,0,0,0,0,0,0,0,0,0,0,0,0,0,0,0
0,0,0,0,0,0,0,0,0,0,0,0,0,0,0,0,0,0,0,0,0,0,0,0,0,0,0,0,0,0,0,0,0,0,0,0
0,0,0,0,0,0,0,0,0,0,0,0,0,0,0,0,0,0,0,0,0,0,0,0,0,0,0,0,0,0,0,0,0,0,0,0
0,0,0,0,0,0,0,0,0,0,0,0,0,0,0,0,0,0,0,0,0,0,0,0,0,0,0,0,0,0,0,0,0,0,0,0
0,0,0,0,0,0,0,0,0,0,0,0,0,0,0,0,0,0,0,0,0,0,0,0,0,0,0,0,0,0,0,0,0,0,0,0
0,0,0,0,0,0,0,0,0,0,0,0,0,0,0,0,0,0,0,0,0,0,0,0,0,0,0,0,0,0,0,0,0,0,0,0
0,0,0,0,0,0,0,0,0,0,0,0,0,0,0,0,0,0,0,0,0,0,0,0,0,0,0,0,0,0,0,0,0,0,0,0
0,0,0,0,0,0,0,0,0,0,0,0,0,0,0,0,0,0,0,0,0,0,0,0,0,0,0,0,0,0,0,0,0,0,0,0
0,0,0,0,0,0,0,0,0,0,0,0,0,0,0,0,0,0,0,0,0,0,0,0,0,0,0,0,0,0,0,0,0,0,0,0
0,0,0,0,0,0,0,0,0,0,0,0,0,0,0,0,0,0,0,0,0,0,0,0,0,0,0,0,0,0,0,0,0,0,0,0
0,0,0,0,0,0,0,0,0,0,0,0,0,0,0,0,0,0,0,0,0,0,0,0,0,0,0,0,0,0,0,0,0,0,0,0
0,0,0,0,0,0,0,0,0,0,0,0,0,0,0,0,0,0,0,0,0,0,0,0,0,0,0,0,0,0,0,0,0,0,0,0
0,0,0,0,0,0,0,0,0,0,0,0,0,0,0,0,0,0,0,0,0,0,0,0,0,0,0,0,0,0,0,0,0,0,0,0
0,0,0,0,0,0,0,0,0,0,0,0,0,0,0,0,0,0,0,0,0,0,0,0,0,0,0,0,0,0,0,0,0,0,0,0
0,0,0,0,0,0,0,0,0,0,0,0,0,0,0,0,0,0,0,0,0,0,0,0,0,0,0,0,0,0,0,0,0,0,0,0
0,0,0,0,0,0,0,0,0,0,0,0,0,0,0,0,0,0,0,0,0,0,0,0,0,0,0,0,0,0,0,0,0,0,0,0
0,0,0,0,0,0,0,0,0,0,0,0,0,0,0,0,0,0,0,0,0,0,0,0,0,0,0,0,0,0,0,0,0,0,0,0
0,0,0,0,0,0,0,0,0,0,0,0,0,0,0,0,0,0,0,0,0,0,0,0,0,0,0,0,0,0,0,0,0,0,0,0
endlayer

