
# Created by Ruins mod version 17.0 Ingame Parser
# authoring Player: ST753M

weight=1
embed_into_distance=3
acceptable_target_blocks=water
unacceptable_target_blocks=
dimensions=23,15,25
allowable_overhang=0
max_leveling=0
leveling_buffer=0
preserve_water=0
preserve_lava=0
uniqueMinDistance=1000
spawnMinDistance=1000

=0,100,air
rule1=0,100,preserveBlock
rule2=0,100,minecraft:planks-0
rule3=0,100,minecraft:log-8
rule4=0,100,minecraft:birch_door-3
rule5=0,100,harvestcraft:watertrap-5
rule6=0,100,minecraft:log-0
rule7=0,100,minecraft:bed-10
rule8=0,100,minecraft:bed-2
rule9=0,100,minecraft:birch_stairs-0
rule10=0,100,minecraft:birch_door-7
rule11=0,100,IInventory;minecraft:chest;harvestcraft:freshwateritem#4#0#0+harvestcraft:fishtrapbaititem#3#0#8+harvestcraft:snapperrawitem#3#0#12+harvestcraft:jellyfishrawitem#1#0#15+harvestcraft:tunarawitem#4#0#19+harvestcraft:shrimprawitem#2#0#23+minecraft:fishing_rod#1#0#26-5,air
rule12=0,100,harvestcraft:watertrap-2
rule13=0,100,minecraft:birch_door-8
rule14=0,100,minecraft:oak_stairs-6
rule15=0,100,minecraft:stained_glass-0
rule16=0,100,minecraft:ladder-3
rule17=0,100,minecraft:birch_stairs-4
rule18=0,100,minecraft:birch_stairs-5
rule19=0,100,minecraft:birch_stairs-6
rule20=0,100,minecraft:planks-2
rule21=0,100,minecraft:birch_stairs-7
rule22=0,100,minecraft:double_wooden_slab-2
rule23=0,100,minecraft:wooden_slab-10
rule24=0,100,minecraft:trapdoor-11
rule25=0,100,minecraft:trapdoor-10
rule26=0,100,minecraft:birch_stairs-3
rule27=0,100,minecraft:birch_door-0
rule28=0,100,minecraft:birch_stairs-1
rule29=0,100,minecraft:spruce_stairs-1
rule30=0,100,minecraft:oak_stairs-0
rule31=0,100,minecraft:fence-0
rule32=0,100,minecraft:spruce_stairs-0
rule33=0,100,minecraft:oak_stairs-1
rule34=0,100,minecraft:birch_stairs-2
rule35=0,100,minecraft:double_wooden_slab-0
rule36=0,100,minecraft:wooden_slab-0
rule37=0,100,minecraft:birch_door-9
rule38=0,100,minecraft:trapdoor-3
rule39=0,100,minecraft:wooden_slab-8
rule40=0,100,minecraft:oak_stairs-3
rule41=0,100,minecraft:spruce_stairs-4
rule42=0,100,minecraft:spruce_stairs-5
rule43=0,100,minecraft:wool-8
^0,100,minecraft:wool-0
^0,100,minecraft:wool-0
rule44=0,100,minecraft:log-4
rule45=0,100,minecraft:oak_stairs-4
rule46=0,100,minecraft:oak_stairs-5
rule47=0,50,minecraft:glowstone-0
rule48=0,100,minecraft:wool-14
^0,100,minecraft:wool-0
^0,100,minecraft:wool-1
^0,100,minecraft:wool-2
^0,100,minecraft:wool-3
^0,100,minecraft:wool-4
^0,100,minecraft:wool-5
^0,100,minecraft:wool-6
^0,100,minecraft:wool-7
^0,100,minecraft:wool-8
^0,100,minecraft:wool-9
^0,100,minecraft:wool-10
^0,100,minecraft:wool-11
^0,100,minecraft:wool-12
^0,100,minecraft:wool-13
^0,100,minecraft:wool-14
^0,100,minecraft:wool-15

layer
1,1,1,1,1,1,1,1,1,1,1,1,1,1,1,1,1,1,1,1,1,1,1,1,1
1,1,1,1,1,1,1,1,1,1,1,1,1,1,1,1,1,1,1,1,1,1,1,1,1
1,1,1,1,1,1,1,1,1,1,1,1,1,1,1,1,1,1,1,1,1,1,1,1,1
1,1,1,1,1,1,1,1,1,1,1,1,1,1,1,1,1,1,1,1,1,1,1,1,1
1,1,1,1,1,1,1,1,1,1,1,1,1,1,1,1,1,1,1,1,1,1,1,1,1
1,1,1,2,2,2,2,2,2,2,2,2,2,2,2,1,1,1,1,1,1,1,1,1,1
1,1,2,2,2,2,2,2,2,2,2,2,2,2,2,2,1,1,1,1,1,1,1,1,1
1,1,2,2,2,2,2,2,2,2,2,2,2,2,2,2,1,1,1,1,1,1,1,1,1
1,1,2,2,2,2,2,2,2,2,2,2,2,2,2,2,1,1,1,1,1,1,1,1,1
1,1,1,2,2,2,2,2,2,2,2,2,2,2,2,1,1,1,1,1,1,1,1,1,1
1,1,1,1,1,1,1,1,1,1,1,1,1,1,1,1,1,1,1,1,1,1,1,1,1
1,1,1,1,1,1,1,1,1,1,1,1,1,1,1,1,1,1,1,1,1,1,1,1,1
1,1,1,1,1,1,1,1,1,1,1,1,1,1,1,1,1,1,1,1,1,1,1,1,1
1,1,1,1,1,1,1,1,1,1,1,1,1,1,1,1,1,1,1,1,1,1,1,1,1
1,1,1,1,1,1,1,1,1,1,1,1,1,1,1,1,1,1,1,1,1,1,1,1,1
endlayer

layer
1,1,1,1,1,1,1,1,1,1,1,1,1,1,1,1,1,1,1,1,1,1,1,1,1
1,1,1,1,1,1,1,1,1,1,1,1,1,1,1,1,1,1,1,1,1,1,1,1,1
1,1,1,1,1,1,1,1,1,1,1,1,1,1,1,1,1,1,1,1,1,1,1,1,1
1,1,1,1,1,1,1,1,1,1,1,1,1,1,1,1,1,1,1,1,1,1,1,1,1
3,3,3,3,3,3,3,3,3,3,3,3,3,3,3,3,3,3,3,3,1,1,1,1,1
1,1,2,0,5,0,5,0,0,4,0,0,0,0,0,2,1,1,1,1,1,1,1,1,1
1,2,0,0,0,0,5,0,0,2,0,0,0,8,7,6,2,1,1,1,1,1,1,1,1
1,2,9,0,0,0,0,0,0,6,2,2,2,2,2,2,2,1,1,1,1,1,1,1,1
1,2,2,0,0,0,0,0,0,2,0,0,0,8,7,6,2,1,1,1,1,1,1,1,1
1,1,2,0,0,0,0,0,0,10,0,0,0,0,0,2,1,1,1,1,1,1,1,1,1
3,3,3,3,3,3,3,3,3,3,3,3,3,3,3,3,3,3,3,3,1,1,1,1,1
1,1,1,1,1,1,1,1,1,1,1,1,1,1,1,1,1,1,1,1,1,1,1,1,1
1,1,1,1,1,1,1,1,1,1,1,1,1,1,1,1,1,1,1,1,1,1,1,1,1
1,1,1,1,1,1,1,1,1,1,1,1,1,1,1,1,1,1,1,1,1,1,1,1,1
1,1,1,1,1,1,1,1,1,1,1,1,1,1,1,1,1,1,1,1,1,1,1,1,1
endlayer

layer
1,1,1,1,1,1,1,1,1,1,1,1,1,1,1,1,1,1,1,1,1,1,1,1,1
1,1,1,1,1,1,1,1,1,1,1,1,1,1,1,1,1,1,1,1,1,1,1,1,1
1,1,1,1,1,1,1,1,1,1,1,1,1,1,1,1,1,1,1,1,1,1,1,1,1
1,1,6,2,2,2,2,2,2,2,2,2,2,2,1,1,1,1,1,1,1,1,1,1,1
1,1,2,12,0,5,5,11,0,2,0,0,0,0,2,2,1,1,1,1,1,1,1,1,1
1,2,0,0,0,0,5,0,0,13,0,0,0,0,0,2,2,2,1,1,1,1,1,1,1
1,2,0,0,0,0,0,0,0,2,0,0,0,0,0,6,2,2,1,1,1,1,1,1,1
1,2,0,0,0,0,0,0,0,6,2,2,2,2,2,2,2,2,2,1,1,1,1,1,1
1,2,9,0,0,0,0,0,0,2,0,0,0,0,0,6,2,2,1,1,1,1,1,1,1
1,2,2,0,0,0,0,0,0,13,0,0,0,0,0,2,2,2,1,1,1,1,1,1,1
1,1,2,0,0,0,0,0,0,2,0,0,0,0,2,2,1,1,1,1,1,1,1,1,1
1,1,6,2,2,2,2,2,2,2,2,2,2,2,1,1,1,1,1,1,1,1,1,1,1
1,1,1,1,1,1,1,1,1,1,1,1,1,1,1,1,1,1,1,1,1,1,1,1,1
1,1,1,1,1,1,1,1,1,1,1,1,1,1,1,1,1,1,1,1,1,1,1,1,1
1,1,1,1,1,1,1,1,1,1,1,1,1,1,1,1,1,1,1,1,1,1,1,1,1
endlayer

layer
1,1,1,1,1,1,1,1,1,1,1,1,1,1,1,1,1,1,1,1,1,1,1,1,1
1,1,1,1,1,1,1,1,1,1,1,1,1,1,1,1,1,1,1,1,1,1,1,1,1
1,1,1,1,1,1,1,1,1,1,1,1,1,1,1,1,1,1,1,1,1,1,1,1,1
1,16,6,2,2,15,2,15,2,2,2,15,2,2,14,1,1,1,1,1,1,1,1,1,1
1,2,2,0,0,0,5,0,0,2,0,0,0,0,2,2,14,1,1,1,1,1,1,1,1
1,2,0,0,0,0,0,0,0,2,0,0,0,0,0,2,2,2,1,1,1,1,1,1,1
1,15,0,0,0,0,0,0,0,2,0,0,0,0,0,6,2,2,14,1,1,1,1,1,1
1,2,0,0,0,0,0,0,0,6,2,2,2,2,2,2,2,2,2,14,1,1,1,1,1
1,15,0,0,0,0,0,0,0,2,0,0,0,0,0,6,2,2,14,1,1,1,1,1,1
1,2,9,0,0,0,0,0,0,2,0,0,0,0,0,2,2,2,1,1,1,1,1,1,1
1,2,2,0,0,0,0,0,0,2,0,0,0,0,2,2,14,1,1,1,1,1,1,1,1
1,1,6,2,2,15,2,15,2,2,2,15,2,2,14,1,1,1,1,1,1,1,1,1,1
1,1,1,1,1,1,1,1,1,1,1,1,1,1,1,1,1,1,1,1,1,1,1,1,1
1,1,1,1,1,1,1,1,1,1,1,1,1,1,1,1,1,1,1,1,1,1,1,1,1
1,1,1,1,1,1,1,1,1,1,1,1,1,1,1,1,1,1,1,1,1,1,1,1,1
endlayer

layer
1,1,1,1,1,1,1,1,1,1,1,1,1,1,1,1,1,1,1,1,1,1,1,1,1
1,1,1,1,1,1,1,1,1,1,1,1,1,1,1,1,1,1,1,1,1,1,1,1,1
1,1,17,1,17,1,17,1,17,1,17,1,17,1,1,1,1,1,1,1,1,1,1,1,1
1,16,6,2,2,2,2,2,2,2,2,2,2,2,2,1,1,1,1,1,1,1,1,1,1
21,2,22,19,18,18,18,18,21,20,19,18,18,18,2,2,2,0,0,0,1,1,1,1,1
1,2,22,19,23,23,23,23,21,20,19,24,24,23,21,22,2,2,1,1,1,1,1,1,1
21,2,18,19,23,23,23,23,21,20,19,17,17,17,21,22,22,2,2,1,1,1,1,1,1
1,2,0,23,23,23,23,23,21,6,20,20,20,20,20,20,20,2,2,2,1,1,1,1,1
21,2,0,23,23,23,23,23,21,20,18,18,18,18,21,22,22,2,2,1,1,1,1,1,1
1,2,0,23,23,23,23,23,21,20,19,25,25,23,21,22,22,2,1,1,1,1,1,1,1
21,2,9,17,17,17,17,17,21,20,19,17,17,17,2,2,2,0,0,0,1,1,1,1,1
1,21,2,2,2,2,2,2,2,2,2,2,2,2,2,1,1,1,1,1,1,1,1,1,1
1,1,18,1,18,1,18,1,18,1,18,1,18,1,1,1,1,1,1,1,1,1,1,1,1
1,1,1,1,1,1,1,1,1,1,1,1,1,1,1,1,1,1,1,1,1,1,1,1,1
1,1,1,1,1,1,1,1,1,1,1,1,1,1,1,1,1,1,1,1,1,1,1,1,1
endlayer

layer
1,1,1,1,1,1,1,1,1,1,1,1,1,1,1,1,1,1,1,1,1,1,1,1,1
1,1,1,1,1,1,1,1,1,1,1,1,1,1,1,1,1,1,1,1,1,1,1,1,1
1,1,26,26,26,26,26,26,26,26,26,26,26,1,17,1,1,1,1,1,1,1,1,1,1
1,0,0,2,2,2,2,0,0,0,0,0,0,2,2,1,17,1,1,1,1,1,1,1,1
28,2,27,0,0,0,0,2,0,0,0,0,0,0,2,2,2,17,0,0,1,1,1,1,1
28,2,0,0,0,0,29,2,0,0,0,0,0,0,0,2,2,2,1,1,1,1,1,1,1
28,2,31,31,0,0,31,2,0,30,0,0,0,0,0,0,2,2,2,1,1,1,1,1,1
20,2,0,31,0,0,32,2,16,6,0,0,0,0,0,0,0,2,2,2,14,1,1,1,1
9,2,0,31,0,0,0,2,0,33,0,0,0,0,0,0,2,2,2,1,1,1,1,1,1
9,2,0,31,0,0,0,4,0,0,0,0,0,0,0,2,2,2,1,1,1,1,1,1,1
9,2,0,0,0,0,0,2,0,0,0,0,0,0,2,2,2,18,0,0,1,1,1,1,1
1,26,2,2,2,2,2,0,0,0,0,0,0,2,2,1,18,1,1,1,1,1,1,1,1
1,1,26,26,26,26,26,26,26,26,26,26,26,1,18,1,1,1,1,1,1,1,1,1,1
1,1,1,1,1,1,1,1,1,1,1,1,1,1,1,1,1,1,1,1,1,1,1,1,1
1,1,1,1,1,1,1,1,1,1,1,1,1,1,1,1,1,1,1,1,1,1,1,1,1
endlayer

layer
1,1,1,1,1,1,1,1,1,1,1,1,1,1,1,1,1,1,1,1,1,1,1,1,1
1,1,1,1,1,1,1,1,1,1,1,1,1,1,1,1,1,1,1,1,1,1,1,1,1
1,1,36,36,36,36,36,36,36,36,36,36,35,34,26,1,1,1,1,1,1,1,1,1,1
1,0,0,2,2,36,2,0,0,0,0,0,0,0,0,34,26,1,1,1,1,1,1,1,1
36,2,37,0,0,0,0,2,0,0,0,0,0,0,0,0,0,26,17,0,1,1,1,1,1
36,36,0,0,0,0,0,36,0,0,0,0,0,0,0,0,0,0,2,1,1,1,1,1,1
36,2,0,0,0,0,38,2,0,0,0,0,0,0,0,0,0,0,2,2,1,1,1,1,1
36,36,0,0,0,0,0,36,16,6,0,0,0,0,0,0,0,0,0,2,2,2,39,1,1
36,2,0,0,0,0,0,2,0,0,0,0,0,0,0,0,0,0,2,2,1,1,1,1,1
36,36,0,0,0,0,0,13,0,0,0,0,0,0,0,0,0,0,2,1,1,1,1,1,1
36,2,0,0,0,0,0,2,0,0,0,0,0,0,0,0,0,26,18,0,1,1,1,1,1
1,36,2,36,2,36,2,0,0,0,0,0,0,0,0,34,26,1,1,1,1,1,1,1,1
1,1,36,36,36,36,36,36,36,36,36,36,35,34,26,1,1,1,1,1,1,1,1,1,1
1,1,1,1,1,1,1,1,1,1,1,1,1,1,1,1,1,1,1,1,1,1,1,1,1
1,1,1,1,1,1,1,1,1,1,1,1,1,1,1,1,1,1,1,1,1,1,1,1,1
endlayer

layer
1,1,1,1,1,1,1,1,1,1,1,1,1,1,1,1,1,1,1,1,1,1,1,1,1
1,1,1,1,1,1,1,1,1,1,1,1,1,1,1,1,1,1,1,1,1,1,1,1,1
1,1,17,0,17,0,17,0,0,0,0,0,0,36,36,1,1,1,1,1,1,1,1,1,1
1,21,2,2,2,2,2,19,0,0,0,0,0,0,0,36,36,1,1,1,1,1,1,1,1
21,2,23,23,23,23,23,2,19,0,0,0,0,0,0,0,0,40,26,0,1,1,1,1,1
0,2,23,24,24,24,23,2,0,0,0,0,0,0,0,0,0,0,0,17,1,1,1,1,1
21,2,23,25,25,25,23,2,19,0,0,0,0,0,0,0,0,0,0,2,41,1,1,1,1
0,2,23,23,23,23,23,2,16,6,0,0,0,0,0,0,0,0,0,0,2,3,3,3,3
21,2,23,24,24,24,23,2,19,0,0,0,0,0,0,0,0,0,0,2,42,1,1,1,1
0,2,23,25,25,25,23,2,0,0,0,0,0,0,0,0,0,0,0,18,1,1,1,1,1
21,2,23,23,23,23,23,2,19,0,0,0,0,0,0,0,0,40,26,0,1,1,1,1,1
1,21,2,2,2,2,2,19,0,0,0,0,0,0,0,36,36,1,1,1,1,1,1,1,1
1,1,18,0,18,0,18,0,0,0,0,0,0,36,36,1,1,1,1,1,1,1,1,1,1
1,1,1,1,1,1,1,1,1,1,1,1,1,1,1,1,1,1,1,1,1,1,1,1,1
1,1,1,1,1,1,1,1,1,1,1,1,1,1,1,1,1,1,1,1,1,1,1,1,1
endlayer

layer
1,1,1,1,1,1,1,1,1,1,1,1,1,1,1,1,1,1,1,1,1,1,1,1,1
1,1,1,1,1,1,1,1,1,1,1,1,1,1,1,1,1,1,1,1,1,1,1,1,1
1,1,26,26,26,26,26,0,0,0,0,0,0,0,0,1,1,1,1,1,1,1,1,1,1
1,26,0,0,0,0,0,20,0,0,0,0,0,0,0,0,0,1,1,1,1,1,1,1,1
28,0,0,0,0,0,0,0,28,0,0,0,0,0,0,0,0,0,30,0,1,1,1,1,1
28,0,0,0,0,0,0,0,28,0,0,0,0,0,0,0,0,0,0,26,1,1,1,1,1
28,0,0,0,0,0,0,0,28,0,0,0,0,0,0,0,0,0,0,0,26,1,1,1,1
20,0,0,0,0,0,0,0,16,6,0,0,0,0,0,0,0,0,0,0,26,19,0,0,31
9,0,0,0,0,0,0,0,9,0,0,0,0,0,0,0,0,0,0,0,26,1,1,1,1
9,0,0,0,0,0,0,0,9,0,0,0,0,0,0,0,0,0,0,26,1,1,1,1,1
9,0,0,0,0,0,0,0,9,0,0,0,0,0,0,0,0,0,33,0,1,1,1,1,1
1,26,0,0,0,0,0,20,0,0,0,0,0,0,0,0,0,1,1,1,1,1,1,1,1
1,1,26,26,26,26,26,0,0,0,0,0,0,0,0,1,1,1,1,1,1,1,1,1,1
1,1,1,1,1,1,1,1,1,1,1,1,1,1,1,1,1,1,1,1,1,1,1,1,1
1,1,1,1,1,1,1,1,1,1,1,1,1,1,1,1,1,1,1,1,1,1,1,1,1
endlayer

layer
1,1,1,1,1,1,1,1,1,1,1,1,1,1,1,1,1,1,1,1,1,1,1,1,1
1,1,1,1,1,1,1,1,1,1,1,1,1,1,1,1,1,1,1,1,1,1,1,1,1
1,1,36,36,36,36,36,0,0,0,0,0,0,0,0,1,1,1,1,1,1,1,1,1,1
1,36,0,0,0,0,0,36,0,0,0,0,0,0,0,0,0,1,1,1,1,1,1,1,1
36,0,0,0,0,0,0,0,36,0,0,0,0,0,0,0,0,0,0,0,1,1,1,1,1
36,0,0,0,0,0,0,0,36,0,0,0,0,0,0,0,0,0,36,36,1,1,1,1,1
36,0,0,0,0,0,0,0,36,36,36,0,0,0,0,0,0,0,0,36,40,14,1,1,1
36,0,0,0,0,0,0,0,16,6,36,0,0,0,0,0,0,0,0,0,0,26,19,0,31
36,0,0,0,0,0,0,0,36,36,36,0,0,0,0,0,0,0,0,36,40,14,1,1,1
36,0,0,0,0,0,0,0,36,0,0,0,0,0,0,0,0,0,36,36,1,1,1,1,1
36,0,0,0,0,0,0,0,36,0,0,0,0,0,0,0,0,0,0,0,1,1,1,1,1
1,36,0,0,0,0,0,36,0,0,0,0,0,0,0,0,0,1,1,1,1,1,1,1,1
1,1,36,36,36,36,36,0,0,0,0,0,0,0,0,1,1,1,1,1,1,1,1,1,1
1,1,1,1,1,1,1,1,1,1,1,1,1,1,1,1,1,1,1,1,1,1,1,1,1
1,1,1,1,1,1,1,1,1,1,1,1,1,1,1,1,1,1,1,1,1,1,1,1,1
endlayer

layer
1,1,1,1,1,1,1,1,1,44,43,1,1,1,1,1,1,1,1,1,1,1,1,1,1
1,1,1,1,1,1,1,1,1,44,43,1,1,1,1,1,1,1,1,1,1,1,1,1,1
1,1,0,0,0,0,0,0,0,44,43,0,0,0,0,1,1,1,1,1,1,1,1,1,1
1,0,0,0,0,0,0,0,0,44,43,0,0,0,0,0,0,1,1,1,1,1,1,1,1
0,0,0,0,0,0,0,0,0,44,43,0,0,0,0,0,0,0,0,0,1,1,1,1,1
0,0,0,0,0,0,0,0,0,44,43,0,0,0,0,0,0,0,0,0,1,1,1,1,1
0,0,0,0,0,0,0,0,0,44,43,0,0,0,0,0,0,0,0,0,0,0,36,45,1
0,0,0,0,0,0,0,0,16,6,0,0,0,0,0,0,0,0,0,0,0,0,6,19,31
0,0,0,0,0,0,0,0,0,44,43,0,0,0,0,0,0,0,0,0,0,0,36,46,1
0,0,0,0,0,0,0,0,0,44,43,0,0,0,0,0,0,0,0,0,1,1,1,1,1
0,0,0,0,0,0,0,0,0,44,43,0,0,0,0,0,0,0,0,0,1,1,1,1,1
1,0,0,0,0,0,0,0,0,44,43,0,0,0,0,0,0,1,1,1,1,1,1,1,1
1,1,0,0,0,0,0,0,0,44,43,0,0,0,0,1,1,1,1,1,1,1,1,1,1
1,1,1,1,1,1,1,1,1,44,43,1,1,1,1,1,1,1,1,1,1,1,1,1,1
1,1,1,1,1,1,1,1,1,44,43,1,1,1,1,1,1,1,1,1,1,1,1,1,1
endlayer

layer
1,1,1,1,1,1,1,1,1,0,0,43,1,1,1,1,1,1,1,1,1,1,1,1,1
1,1,1,1,1,1,1,1,1,0,0,43,1,1,1,1,1,1,1,1,1,1,1,1,1
1,1,0,0,0,0,0,0,0,0,0,43,0,0,0,1,1,1,1,1,1,1,1,1,1
1,0,0,0,0,0,0,0,0,0,0,43,0,0,0,0,0,1,1,1,1,1,1,1,1
0,0,0,0,0,0,0,0,0,0,0,43,0,0,0,0,0,0,0,0,1,1,1,1,1
0,0,0,0,0,0,0,0,0,0,0,43,0,0,0,0,0,0,0,0,1,1,1,1,1
0,0,0,0,0,0,0,0,0,0,0,43,0,0,0,0,0,0,0,0,0,0,0,0,1
0,0,0,0,0,0,0,0,16,6,0,0,0,0,0,0,0,0,0,0,0,0,31,36,40
0,0,0,0,0,0,0,0,0,0,0,43,0,0,0,0,0,0,0,0,0,0,0,0,1
0,0,0,0,0,0,0,0,0,0,0,43,0,0,0,0,0,0,0,0,1,1,1,1,1
0,0,0,0,0,0,0,0,0,0,0,43,0,0,0,0,0,0,0,0,1,1,1,1,1
1,0,0,0,0,0,0,0,0,0,0,43,0,0,0,0,0,1,1,1,1,1,1,1,1
1,1,0,0,0,0,0,0,0,0,0,43,0,0,0,1,1,1,1,1,1,1,1,1,1
1,1,1,1,1,1,1,1,1,0,0,43,1,1,1,1,1,1,1,1,1,1,1,1,1
1,1,1,1,1,1,1,1,1,0,0,43,1,1,1,1,1,1,1,1,1,1,1,1,1
endlayer

layer
1,1,1,1,1,1,1,1,1,0,0,43,1,1,1,1,1,1,1,1,1,1,1,1,1
1,1,1,1,1,1,1,1,1,0,0,0,43,1,1,1,1,1,1,1,1,1,1,1,1
1,1,0,0,0,0,0,0,0,0,0,0,43,0,0,1,1,1,1,1,1,1,1,1,1
1,0,0,0,0,0,0,0,0,0,0,0,43,0,0,0,0,1,1,1,1,1,1,1,1
0,0,0,0,0,0,0,0,0,0,0,0,43,0,0,0,0,0,0,0,1,1,1,1,1
0,0,0,0,0,0,0,0,0,0,0,0,43,0,0,0,0,0,0,0,1,1,1,1,1
0,0,0,0,0,0,0,0,0,0,0,43,0,0,0,0,0,0,0,0,0,0,0,0,1
0,0,0,0,0,0,0,0,16,6,0,0,0,0,0,0,0,0,0,0,0,0,31,0,0
0,0,0,0,0,0,0,0,0,0,0,43,0,0,0,0,0,0,0,0,0,0,0,0,1
0,0,0,0,0,0,0,0,0,0,0,0,43,0,0,0,0,0,0,0,1,1,1,1,1
0,0,0,0,0,0,0,0,0,0,0,0,43,0,0,0,0,0,0,0,1,1,1,1,1
1,0,0,0,0,0,0,0,0,0,0,0,43,0,0,0,0,1,1,1,1,1,1,1,1
1,1,0,0,0,0,0,0,0,0,0,0,43,0,0,1,1,1,1,1,1,1,1,1,1
1,1,1,1,1,1,1,1,1,0,0,0,43,1,1,1,1,1,1,1,1,1,1,1,1
1,1,1,1,1,1,1,1,1,0,0,43,1,1,1,1,1,1,1,1,1,1,1,1,1
endlayer

layer
1,1,1,1,1,1,1,1,1,0,0,0,43,1,1,1,1,1,1,1,1,1,1,1,1
1,1,1,1,1,1,1,1,1,0,0,0,43,1,1,1,1,1,1,1,1,1,1,1,1
1,1,0,0,0,0,0,0,0,0,0,0,43,0,0,1,1,1,1,1,1,1,1,1,1
1,0,0,0,0,0,0,0,0,0,0,0,43,0,0,0,0,1,1,1,1,1,1,1,1
0,0,0,0,0,0,0,0,0,0,0,0,43,0,0,0,0,0,0,0,1,1,1,1,1
0,0,0,0,0,0,0,0,0,0,0,0,43,0,0,0,0,0,0,0,1,1,1,1,1
0,0,0,0,0,0,0,0,0,0,0,0,43,0,0,0,0,0,0,0,0,0,0,0,1
0,0,0,0,0,0,0,0,16,6,0,0,0,0,0,0,0,0,0,0,0,0,31,0,0
0,0,0,0,0,0,0,0,0,0,0,0,43,0,0,0,0,0,0,0,0,0,0,0,1
0,0,0,0,0,0,0,0,0,0,0,0,43,0,0,0,0,0,0,0,1,1,1,1,1
0,0,0,0,0,0,0,0,0,0,0,0,43,0,0,0,0,0,0,0,1,1,1,1,1
1,0,0,0,0,0,0,0,0,0,0,0,43,0,0,0,0,1,1,1,1,1,1,1,1
1,1,0,0,0,0,0,0,0,0,0,0,43,0,0,1,1,1,1,1,1,1,1,1,1
1,1,1,1,1,1,1,1,1,0,0,0,43,1,1,1,1,1,1,1,1,1,1,1,1
1,1,1,1,1,1,1,1,1,0,0,0,43,1,1,1,1,1,1,1,1,1,1,1,1
endlayer

layer
1,1,1,1,1,1,1,1,1,0,0,0,43,1,1,1,1,1,1,1,1,1,1,1,1
1,1,1,1,1,1,1,1,1,0,0,0,43,1,1,1,1,1,1,1,1,1,1,1,1
1,1,0,0,0,0,0,0,0,0,0,0,43,0,0,1,1,1,1,1,1,1,1,1,1
1,0,0,0,0,0,0,0,0,0,0,0,43,0,0,0,0,1,1,1,1,1,1,1,1
0,0,0,0,0,0,0,0,0,0,0,0,43,0,0,0,0,0,0,0,1,1,1,1,1
0,0,0,0,0,0,0,0,0,0,0,0,43,0,0,0,0,0,0,0,1,1,1,1,1
0,0,0,0,0,0,0,0,0,0,0,0,43,0,0,0,0,0,0,0,0,0,0,0,1
0,0,0,0,0,0,0,0,16,6,0,0,0,0,0,0,0,0,0,0,0,0,47,0,0
0,0,0,0,0,0,0,0,0,0,0,0,43,0,0,0,0,0,0,0,0,0,0,0,1
0,0,0,0,0,0,0,0,0,0,0,0,43,0,0,0,0,0,0,0,1,1,1,1,1
0,0,0,0,0,0,0,0,0,0,0,0,43,0,0,0,0,0,0,0,1,1,1,1,1
1,0,0,0,0,0,0,0,0,0,0,0,43,0,0,0,0,1,1,1,1,1,1,1,1
1,1,0,0,0,0,0,0,0,0,0,0,43,0,0,1,1,1,1,1,1,1,1,1,1
1,1,1,1,1,1,1,1,1,0,0,0,43,1,1,1,1,1,1,1,1,1,1,1,1
1,1,1,1,1,1,1,1,1,0,0,0,43,1,1,1,1,1,1,1,1,1,1,1,1
endlayer

layer
1,1,1,1,1,1,1,1,1,0,0,43,0,1,1,1,1,1,1,1,1,1,1,1,1
1,1,1,1,1,1,1,1,1,0,0,0,43,1,1,1,1,1,1,1,1,1,1,1,1
1,1,0,0,0,0,0,0,0,0,0,0,43,0,0,1,1,1,1,1,1,1,1,1,1
1,0,0,0,0,0,0,0,0,0,0,0,43,0,0,0,0,1,1,1,1,1,1,1,1
0,0,0,0,0,0,0,0,0,0,0,0,43,0,0,0,0,0,0,0,1,1,1,1,1
0,0,0,0,0,0,0,0,0,0,0,0,43,0,0,0,0,0,0,0,1,1,1,1,1
0,0,0,0,0,0,0,0,0,0,0,43,0,0,0,0,0,0,0,0,0,0,0,0,1
0,0,0,0,0,0,0,0,16,6,0,0,0,0,0,0,0,0,0,0,0,0,0,0,0
0,0,0,0,0,0,0,0,0,0,0,43,0,0,0,0,0,0,0,0,0,0,0,0,1
0,0,0,0,0,0,0,0,0,0,0,0,43,0,0,0,0,0,0,0,1,1,1,1,1
0,0,0,0,0,0,0,0,0,0,0,0,43,0,0,0,0,0,0,0,1,1,1,1,1
1,0,0,0,0,0,0,0,0,0,0,0,43,0,0,0,0,1,1,1,1,1,1,1,1
1,1,0,0,0,0,0,0,0,0,0,0,43,0,0,1,1,1,1,1,1,1,1,1,1
1,1,1,1,1,1,1,1,1,0,0,0,43,1,1,1,1,1,1,1,1,1,1,1,1
1,1,1,1,1,1,1,1,1,0,0,43,0,1,1,1,1,1,1,1,1,1,1,1,1
endlayer

layer
1,1,1,1,1,1,1,1,1,0,43,0,0,1,1,1,1,1,1,1,1,1,1,1,1
1,1,1,1,1,1,1,1,1,0,0,43,0,1,1,1,1,1,1,1,1,1,1,1,1
1,1,0,0,0,0,0,0,0,0,0,43,0,0,0,1,1,1,1,1,1,1,1,1,1
1,0,0,0,0,0,0,0,0,0,0,43,0,0,0,0,0,1,1,1,1,1,1,1,1
0,0,0,0,0,0,0,0,0,0,0,43,0,0,0,0,0,0,0,0,1,1,1,1,1
0,0,0,0,0,0,0,0,0,0,0,43,0,0,0,0,0,0,0,0,1,1,1,1,1
0,0,0,0,0,0,0,0,0,0,43,0,0,0,0,0,0,0,0,0,0,0,0,0,1
0,0,0,0,0,0,0,0,16,6,0,0,0,0,0,0,0,0,0,0,0,0,0,0,0
0,0,0,0,0,0,0,0,0,0,43,0,0,0,0,0,0,0,0,0,0,0,0,0,1
0,0,0,0,0,0,0,0,0,0,0,43,0,0,0,0,0,0,0,0,1,1,1,1,1
0,0,0,0,0,0,0,0,0,0,0,43,0,0,0,0,0,0,0,0,1,1,1,1,1
1,0,0,0,0,0,0,0,0,0,0,43,0,0,0,0,0,1,1,1,1,1,1,1,1
1,1,0,0,0,0,0,0,0,0,0,43,0,0,0,1,1,1,1,1,1,1,1,1,1
1,1,1,1,1,1,1,1,1,0,0,43,0,1,1,1,1,1,1,1,1,1,1,1,1
1,1,1,1,1,1,1,1,1,0,43,0,0,1,1,1,1,1,1,1,1,1,1,1,1
endlayer

layer
1,1,1,1,1,1,1,1,1,44,43,0,0,1,1,1,1,1,1,1,1,1,1,1,1
1,1,1,1,1,1,1,1,1,44,43,0,0,1,1,1,1,1,1,1,1,1,1,1,1
1,1,0,0,0,0,0,0,0,44,43,0,0,0,0,1,1,1,1,1,1,1,1,1,1
1,0,0,0,0,0,0,0,0,44,43,0,0,0,0,0,0,1,1,1,1,1,1,1,1
0,0,0,0,0,0,0,0,0,44,43,0,0,0,0,0,0,0,0,0,1,1,1,1,1
0,0,0,0,0,0,0,0,0,44,43,0,0,0,0,0,0,0,0,0,1,1,1,1,1
0,0,0,0,0,0,0,0,0,44,43,0,0,0,0,0,0,0,0,0,0,0,0,0,1
0,0,0,0,0,0,0,0,16,6,0,0,0,0,0,0,0,0,0,0,0,0,0,0,0
0,0,0,0,0,0,0,0,0,44,43,0,0,0,0,0,0,0,0,0,0,0,0,0,1
0,0,0,0,0,0,0,0,0,44,43,0,0,0,0,0,0,0,0,0,1,1,1,1,1
0,0,0,0,0,0,0,0,0,44,43,0,0,0,0,0,0,0,0,0,1,1,1,1,1
1,0,0,0,0,0,0,0,0,44,43,0,0,0,0,0,0,1,1,1,1,1,1,1,1
1,1,0,0,0,0,0,0,0,44,43,0,0,0,0,1,1,1,1,1,1,1,1,1,1
1,1,1,1,1,1,1,1,1,44,43,0,0,1,1,1,1,1,1,1,1,1,1,1,1
1,1,1,1,1,1,1,1,1,44,43,0,0,1,1,1,1,1,1,1,1,1,1,1,1
endlayer

layer
1,1,1,1,1,1,1,1,1,0,0,0,0,1,1,1,1,1,1,1,1,1,1,1,1
1,1,1,1,1,1,1,1,1,0,0,0,0,1,1,1,1,1,1,1,1,1,1,1,1
1,1,0,0,0,0,0,0,0,0,0,0,0,0,0,1,1,1,1,1,1,1,1,1,1
1,0,0,0,0,0,0,0,0,0,0,0,0,0,0,0,0,1,1,1,1,1,1,1,1
0,0,0,0,0,0,0,0,0,0,0,0,0,0,0,0,0,0,0,0,1,1,1,1,1
0,0,0,0,0,0,0,0,0,0,0,0,0,0,0,0,0,0,0,0,1,1,1,1,1
0,0,0,0,0,0,0,0,39,39,39,0,0,0,0,0,0,0,0,0,0,0,0,0,1
0,0,0,0,0,0,0,0,16,6,39,0,0,0,0,0,0,0,0,0,0,0,0,0,0
0,0,0,0,0,0,0,0,39,39,39,0,0,0,0,0,0,0,0,0,0,0,0,0,1
0,0,0,0,0,0,0,0,0,0,0,0,0,0,0,0,0,0,0,0,1,1,1,1,1
0,0,0,0,0,0,0,0,0,0,0,0,0,0,0,0,0,0,0,0,1,1,1,1,1
1,0,0,0,0,0,0,0,0,0,0,0,0,0,0,0,0,1,1,1,1,1,1,1,1
1,1,0,0,0,0,0,0,0,0,0,0,0,0,0,1,1,1,1,1,1,1,1,1,1
1,1,1,1,1,1,1,1,1,0,0,0,0,1,1,1,1,1,1,1,1,1,1,1,1
1,1,1,1,1,1,1,1,1,0,0,0,0,1,1,1,1,1,1,1,1,1,1,1,1
endlayer

layer
1,1,1,1,1,1,1,1,1,0,0,0,0,1,1,1,1,1,1,1,1,1,1,1,1
1,1,1,1,1,1,1,1,1,0,0,0,0,1,1,1,1,1,1,1,1,1,1,1,1
1,1,0,0,0,0,0,0,0,0,0,0,0,0,0,1,1,1,1,1,1,1,1,1,1
1,0,0,0,0,0,0,0,0,0,0,0,0,0,0,0,0,1,1,1,1,1,1,1,1
0,0,0,0,0,0,0,0,0,0,0,0,0,0,0,0,0,0,0,0,1,1,1,1,1
0,0,0,0,0,0,0,17,17,17,17,19,0,0,0,0,0,0,0,0,1,1,1,1,1
0,0,0,0,0,0,0,21,0,0,0,19,0,0,0,0,0,0,0,0,0,0,0,0,1
0,0,0,0,0,0,0,21,16,6,0,19,0,0,0,0,0,0,0,0,0,0,0,0,0
0,0,0,0,0,0,0,21,0,0,0,19,0,0,0,0,0,0,0,0,0,0,0,0,1
0,0,0,0,0,0,0,21,18,18,18,19,0,0,0,0,0,0,0,0,1,1,1,1,1
0,0,0,0,0,0,0,0,0,0,0,0,0,0,0,0,0,0,0,0,1,1,1,1,1
1,0,0,0,0,0,0,0,0,0,0,0,0,0,0,0,0,1,1,1,1,1,1,1,1
1,1,0,0,0,0,0,0,0,0,0,0,0,0,0,1,1,1,1,1,1,1,1,1,1
1,1,1,1,1,1,1,1,1,0,0,0,0,1,1,1,1,1,1,1,1,1,1,1,1
1,1,1,1,1,1,1,1,1,0,0,0,0,1,1,1,1,1,1,1,1,1,1,1,1
endlayer

layer
1,1,1,1,1,1,1,1,1,0,0,0,0,1,1,1,1,1,1,1,1,1,1,1,1
1,1,1,1,1,1,1,1,1,0,0,0,0,1,1,1,1,1,1,1,1,1,1,1,1
1,1,0,0,0,0,0,0,0,0,0,0,0,0,0,1,1,1,1,1,1,1,1,1,1
1,0,0,0,0,0,0,0,0,0,0,0,0,0,0,0,0,1,1,1,1,1,1,1,1
0,0,0,0,0,0,0,0,0,0,0,0,0,0,0,0,0,0,0,0,1,1,1,1,1
0,0,0,0,0,0,0,31,31,31,31,31,0,0,0,0,0,0,0,0,1,1,1,1,1
0,0,0,0,0,0,0,31,0,0,0,31,0,0,0,0,0,0,0,0,0,0,0,0,1
0,0,0,0,0,0,0,31,0,31,0,31,0,0,0,0,0,0,0,0,0,0,0,0,0
0,0,0,0,0,0,0,31,0,0,0,31,0,0,0,0,0,0,0,0,0,0,0,0,1
0,0,0,0,0,0,0,31,31,31,31,31,0,0,0,0,0,0,0,0,1,1,1,1,1
0,0,0,0,0,0,0,0,0,0,0,0,0,0,0,0,0,0,0,0,1,1,1,1,1
1,0,0,0,0,0,0,0,0,0,0,0,0,0,0,0,0,1,1,1,1,1,1,1,1
1,1,0,0,0,0,0,0,0,0,0,0,0,0,0,1,1,1,1,1,1,1,1,1,1
1,1,1,1,1,1,1,1,1,0,0,0,0,1,1,1,1,1,1,1,1,1,1,1,1
1,1,1,1,1,1,1,1,1,0,0,0,0,1,1,1,1,1,1,1,1,1,1,1,1
endlayer

layer
1,1,1,1,1,1,1,1,1,0,0,0,0,1,1,1,1,1,1,1,1,1,1,1,1
1,1,1,1,1,1,1,1,1,0,0,0,0,1,1,1,1,1,1,1,1,1,1,1,1
1,1,0,0,0,0,0,0,0,0,0,0,0,0,0,1,1,1,1,1,1,1,1,1,1
1,0,0,0,0,0,0,0,0,0,0,0,0,0,0,0,0,1,1,1,1,1,1,1,1
0,0,0,0,0,0,0,0,0,0,0,0,0,0,48,0,0,0,0,0,1,1,1,1,1
0,0,0,0,0,0,0,0,0,0,0,0,48,48,0,0,0,0,0,0,1,1,1,1,1
0,0,0,0,0,0,0,0,0,0,0,0,0,0,0,0,0,0,0,0,0,0,0,0,1
0,0,0,0,0,0,0,0,0,31,0,0,0,0,0,0,0,0,0,0,0,0,0,0,0
0,0,0,0,0,0,0,0,0,0,0,0,0,0,0,0,0,0,0,0,0,0,0,0,1
0,0,0,0,0,0,0,0,0,0,0,0,0,0,0,0,0,0,0,0,1,1,1,1,1
0,0,0,0,0,0,0,0,0,0,0,0,0,0,0,0,0,0,0,0,1,1,1,1,1
1,0,0,0,0,0,0,0,0,0,0,0,0,0,0,0,0,1,1,1,1,1,1,1,1
1,1,0,0,0,0,0,0,0,0,0,0,0,0,0,1,1,1,1,1,1,1,1,1,1
1,1,1,1,1,1,1,1,1,0,0,0,0,1,1,1,1,1,1,1,1,1,1,1,1
1,1,1,1,1,1,1,1,1,0,0,0,0,1,1,1,1,1,1,1,1,1,1,1,1
endlayer

layer
1,1,1,1,1,1,1,1,1,0,0,0,0,1,1,1,1,1,1,1,1,1,1,1,1
1,1,1,1,1,1,1,1,1,0,0,0,0,1,1,1,1,1,1,1,1,1,1,1,1
1,1,0,0,0,0,0,0,0,0,0,0,0,0,0,1,1,1,1,1,1,1,1,1,1
1,0,0,0,0,0,0,0,0,0,0,0,0,0,0,0,0,1,1,1,1,1,1,1,1
0,0,0,0,0,0,0,0,0,0,0,0,0,0,0,0,0,0,0,0,1,1,1,1,1
0,0,0,0,0,0,0,0,0,0,0,0,0,0,0,0,0,0,0,0,1,1,1,1,1
0,0,0,0,0,0,0,0,0,0,48,48,48,0,0,0,0,0,0,0,0,0,0,0,1
0,0,0,0,0,0,0,0,0,48,48,0,0,0,0,0,0,0,0,0,0,0,0,0,0
0,0,0,0,0,0,0,0,0,0,0,0,0,0,0,0,0,0,0,0,0,0,0,0,1
0,0,0,0,0,0,0,0,0,0,0,0,0,0,0,0,0,0,0,0,1,1,1,1,1
0,0,0,0,0,0,0,0,0,0,0,0,0,0,0,0,0,0,0,0,1,1,1,1,1
1,0,0,0,0,0,0,0,0,0,0,0,0,0,0,0,0,1,1,1,1,1,1,1,1
1,1,0,0,0,0,0,0,0,0,0,0,0,0,0,1,1,1,1,1,1,1,1,1,1
1,1,1,1,1,1,1,1,1,0,0,0,0,1,1,1,1,1,1,1,1,1,1,1,1
1,1,1,1,1,1,1,1,1,0,0,0,0,1,1,1,1,1,1,1,1,1,1,1,1
endlayer

