
# Created by Ruins mod version 16.7 Ingame Parser
# authoring Player: ST753M

weight=1
uniqueMinDistance=3000
spawnMinDistance=3000
embed_into_distance=4
acceptable_target_blocks=water
unacceptable_target_blocks=
dimensions=20,15,16
allowable_overhang=0
max_leveling=0
leveling_buffer=0
preserve_water=0
preserve_lava=0

biomesToSpawnIn=ocean

rule1=0,100,preserveBlock
rule2=0,100,minecraft:grass-0
rule3=0,100,minecraft:dirt-0
rule4=0,100,minecraft:log-0
rule5=0,100,minecraft:log-4
rule6=0,100,minecraft:log-8
rule7=0,100,harvestcraft:tropicalgarden-0
rule8=0,100,harvestcraft:soggygarden-0
rule9=0,70,harvestcraft:pamdragonfruit-1,harvestcraft:pamolive-0,harvestcraft:pampistachio-0,harvestcraft:pamavocado-1,harvestcraft:pamstarfruit-0,harvestcraft:pampomegranate-1,harvestcraft:pamfig-0,harvestcraft:pampapaya-0,harvestcraft:pamcherry-1,harvestcraft:pampear-0,harvestcraft:pamlemon-1,harvestcraft:pamdurian-1,harvestcraft:pamvanillabean-0,harvestcraft:pamgrapefruit-1,harvestcraft:pampecan-2,harvestcraft:pambanana-0,harvestcraft:pamcashew-1,harvestcraft:pamplum-2,harvestcraft:pamorange-0,harvestcraft:pampersimmon-1,harvestcraft:pamcoconut-0,harvestcraft:pamapricot-0,harvestcraft:pamnutmeg-1,harvestcraft:pamdate-2,harvestcraft:pamwalnut-0,harvestcraft:pammango-1,harvestcraft:pamchestnut-2,harvestcraft:pamalmond-0,harvestcraft:pampeach-1,harvestcraft:pampeppercorn-2,harvestcraft:pamgooseberry-0,harvestcraft:pamlime-1
rule10=0,100,minecraft:leaves-4
rule11=0,100,minecraft:leaves-12
rule12=0,100,minecraft:leaves-0

layer
1,1,1,2,3,3,3,3,3,3,3,2,1,1,1,1
1,1,3,3,3,3,3,3,3,3,3,3,3,1,1,1
1,3,3,3,3,3,3,3,3,3,3,3,3,3,1,1
2,3,3,3,3,3,3,3,3,3,3,3,3,3,2,1
3,3,3,3,3,3,3,3,3,3,3,3,3,3,3,1
3,3,3,3,3,3,3,3,3,3,3,3,3,3,3,1
3,3,3,3,3,3,3,3,3,3,3,3,3,3,3,1
3,3,3,3,3,3,3,3,3,3,3,3,3,3,3,1
3,3,3,3,3,3,3,3,3,3,3,3,3,3,3,1
3,3,3,3,3,3,3,3,3,3,3,3,3,3,3,1
3,3,3,3,3,3,3,3,3,3,3,3,3,3,3,1
2,3,3,3,3,3,3,3,3,3,3,3,3,3,2,1
1,3,3,3,3,3,3,3,3,3,3,3,3,3,1,1
1,1,3,3,3,3,3,3,3,3,3,3,3,1,1,1
1,1,1,2,3,3,3,3,3,3,3,2,1,1,1,1
endlayer

layer
1,1,1,1,2,3,3,3,3,3,2,1,1,1,1,1
1,1,2,3,3,3,3,3,3,3,3,3,2,1,1,1
1,2,3,3,3,3,3,3,3,3,3,3,3,2,1,1
1,3,3,3,3,3,3,3,3,3,3,3,3,3,1,1
2,3,3,3,3,3,3,3,3,3,3,3,3,3,2,1
3,3,3,3,3,3,3,3,3,3,3,3,3,3,3,1
3,3,3,3,3,3,3,3,3,3,3,3,3,3,3,1
3,3,3,3,3,3,3,3,3,3,3,3,3,3,3,1
3,3,3,3,3,3,3,3,3,3,3,3,3,3,3,1
3,3,3,3,3,3,3,3,3,3,3,3,3,3,3,1
2,3,3,3,3,3,3,3,3,3,3,3,3,3,2,1
1,3,3,3,3,3,3,3,3,3,3,3,3,3,1,1
1,2,3,3,3,3,3,3,3,3,3,3,3,2,1,1
1,1,2,3,3,3,3,3,3,3,3,3,2,1,1,1
1,1,1,1,2,3,3,3,3,3,2,1,1,1,1,1
endlayer

layer
1,1,1,1,1,2,2,2,2,2,1,1,1,1,1,1
1,1,1,2,3,3,3,3,3,3,3,2,1,1,1,1
1,1,2,3,3,3,3,3,3,3,3,3,2,1,1,1
1,2,3,3,3,3,3,3,3,3,3,3,3,2,1,1
1,3,3,3,3,3,3,3,3,3,3,3,3,3,1,1
2,3,3,3,3,3,3,3,3,3,3,3,3,3,2,1
2,3,3,3,3,3,3,3,3,3,3,3,3,3,2,1
2,3,3,3,3,3,3,3,3,3,3,3,3,3,2,1
2,3,3,3,3,3,3,3,3,3,3,3,3,3,2,1
2,3,3,3,3,3,3,3,3,3,3,3,3,3,2,1
1,3,3,3,3,3,3,3,3,3,3,3,3,3,1,1
1,2,3,3,3,3,3,3,3,3,3,3,3,2,1,1
1,1,2,3,3,3,3,3,3,3,3,3,2,1,1,1
1,1,1,2,3,3,3,3,3,3,3,2,1,1,1,1
1,1,1,1,1,2,2,2,2,2,1,1,1,1,1,1
endlayer

layer
1,1,1,1,1,1,1,1,1,1,1,1,1,1,1,1
1,1,1,1,2,2,2,2,2,2,2,1,1,1,1,1
1,1,1,2,3,3,3,3,3,3,3,2,1,1,1,1
1,1,2,3,3,3,3,3,3,3,3,3,2,1,1,1
1,2,3,3,3,3,3,3,3,3,3,3,3,2,1,1
1,2,3,3,3,3,3,3,3,3,3,3,3,2,1,1
1,2,3,3,3,3,3,3,3,3,3,3,3,2,1,1
1,2,3,3,3,3,3,3,4,3,3,3,3,2,1,1
1,2,3,3,3,3,3,3,3,3,3,3,3,2,1,1
1,2,3,3,3,3,3,3,3,3,3,3,3,2,1,1
1,2,3,3,3,3,3,3,3,3,3,3,3,2,1,1
1,1,2,3,3,3,3,3,3,3,3,3,2,1,1,1
1,1,1,2,3,3,3,3,3,3,3,2,1,1,1,1
1,1,1,1,2,2,2,2,2,2,2,1,1,1,1,1
1,1,1,1,1,1,1,1,1,1,1,1,1,1,1,1
endlayer

layer
1,1,1,1,1,1,1,1,1,1,1,1,1,1,1,1
1,1,1,1,1,1,1,1,1,1,1,1,1,1,1,1
1,1,1,1,2,2,2,2,2,2,2,1,1,1,1,1
1,1,1,2,2,3,3,3,3,3,2,2,1,1,1,1
1,1,2,2,3,3,3,3,3,3,3,2,2,1,1,1
1,1,2,3,3,3,3,3,3,3,3,3,2,1,1,1
1,1,2,3,3,3,3,3,3,3,3,3,2,1,1,1
1,1,2,3,3,4,3,3,4,3,3,3,2,1,1,1
1,1,2,3,3,3,3,3,3,3,3,3,2,1,1,1
1,1,2,3,3,3,3,4,3,3,3,3,2,1,1,1
1,1,2,2,3,3,3,4,3,3,3,2,2,1,1,1
1,1,1,2,2,3,3,3,3,3,2,2,1,1,1,1
1,1,1,1,2,2,2,2,2,2,2,1,1,1,1,1
1,1,1,1,1,1,1,1,1,1,1,1,1,1,1,1
1,1,1,1,1,1,1,1,1,1,1,1,1,1,1,1
endlayer

layer
1,1,1,1,1,1,1,1,1,1,1,1,1,1,1,1
1,1,1,1,1,1,1,1,1,1,1,1,1,1,1,1
1,1,1,1,1,1,1,1,1,1,1,1,1,1,1,1
1,1,1,1,1,2,2,2,2,2,1,1,1,1,1,1
1,1,1,1,2,2,2,2,2,2,2,1,1,1,1,1
1,1,1,2,2,2,2,2,5,2,2,2,1,1,1,1
1,1,1,2,2,2,2,3,6,6,2,2,1,1,1,1
1,1,1,2,2,6,6,3,4,2,2,2,1,1,1,1
1,1,1,2,2,2,2,5,2,2,2,2,1,1,1,1
1,1,1,2,2,2,2,5,2,2,2,2,1,1,1,1
1,1,1,1,2,2,2,5,2,2,2,1,1,1,1,1
1,1,1,1,1,2,2,2,2,2,1,1,1,1,1,1
1,1,1,1,1,1,1,1,1,1,1,1,1,1,1,1
1,1,1,1,1,1,1,1,1,1,1,1,1,1,1,1
1,1,1,1,1,1,1,1,1,1,1,1,1,1,1,1
endlayer

layer
0,0,0,0,0,0,0,0,0,0,0,0,0,0,0,0
0,0,0,0,0,0,0,0,0,0,0,0,0,0,0,0
0,0,0,0,0,0,0,0,0,0,0,0,0,0,0,0
0,0,0,0,0,0,0,0,0,0,0,0,0,0,0,0
0,0,0,0,0,0,0,0,0,7,0,0,0,0,0,0
0,0,0,0,0,0,0,0,5,0,0,0,0,0,0,0
0,0,0,0,0,0,0,4,4,0,0,0,0,0,0,0
0,0,0,8,0,0,0,4,4,0,0,0,0,0,0,0
0,0,0,0,0,0,0,5,0,0,0,0,0,0,0,0
0,0,0,0,0,7,0,0,0,0,8,0,0,0,0,0
0,0,0,0,0,0,0,0,0,0,0,0,0,0,0,0
0,0,0,0,0,0,0,0,7,0,0,0,0,0,0,0
0,0,0,0,0,0,0,0,0,0,0,0,0,0,0,0
0,0,0,0,0,0,0,0,0,0,0,0,0,0,0,0
0,0,0,0,0,0,0,0,0,0,0,0,0,0,0,0
endlayer

layer
0,0,0,0,0,0,0,0,0,0,0,0,0,0,0,0
0,0,0,0,0,0,0,0,0,0,0,0,0,0,0,0
0,0,0,0,0,0,0,0,0,0,0,0,0,0,0,0
0,0,0,0,0,0,0,0,0,0,0,0,0,0,0,0
0,0,0,0,0,0,0,0,0,0,0,0,0,0,0,0
0,0,0,0,0,0,0,0,0,0,0,0,0,0,0,0
0,0,0,0,0,0,0,4,4,0,0,0,0,0,0,0
0,0,0,0,0,0,0,4,4,0,0,0,0,0,0,0
0,0,0,0,0,0,0,0,0,0,0,0,0,0,0,0
0,0,0,0,0,0,0,0,0,0,0,0,0,0,0,0
0,0,0,0,0,0,0,0,0,0,0,0,0,0,0,0
0,0,0,0,0,0,0,0,0,0,0,0,0,0,0,0
0,0,0,0,0,0,0,0,0,0,0,0,0,0,0,0
0,0,0,0,0,0,0,0,0,0,0,0,0,0,0,0
0,0,0,0,0,0,0,0,0,0,0,0,0,0,0,0
endlayer

layer
0,0,0,0,0,0,0,0,0,0,0,0,0,0,0,0
0,0,0,0,0,0,0,0,0,0,0,0,0,0,0,0
0,0,0,0,0,0,0,0,0,0,0,0,0,0,0,0
0,0,0,0,0,0,0,0,0,0,0,0,0,0,0,0
0,0,0,0,0,0,0,0,0,0,0,0,0,0,0,0
0,0,0,0,0,0,0,0,0,0,0,0,0,0,0,0
0,0,0,0,0,0,0,0,4,0,0,0,0,0,0,0
0,0,0,0,0,0,0,4,4,0,0,0,0,0,0,0
0,0,0,0,0,0,0,0,4,0,0,0,0,0,0,0
0,0,0,0,0,0,0,0,0,0,0,0,0,0,0,0
0,0,0,0,0,0,0,0,0,0,0,0,0,0,0,0
0,0,0,0,0,0,0,0,0,0,0,0,0,0,0,0
0,0,0,0,0,0,0,0,0,0,0,0,0,0,0,0
0,0,0,0,0,0,0,0,0,0,0,0,0,0,0,0
0,0,0,0,0,0,0,0,0,0,0,0,0,0,0,0
endlayer

layer
0,0,0,0,0,0,0,0,0,0,0,0,0,0,0,0
0,0,0,0,0,0,0,0,0,0,0,0,0,0,0,0
0,0,0,0,0,0,0,0,0,0,0,0,0,0,0,0
0,0,0,0,0,0,0,0,0,0,0,0,0,0,0,0
0,0,0,0,0,0,0,0,0,0,0,0,0,0,0,0
0,0,0,0,0,0,0,0,0,0,0,0,0,0,0,0
0,0,0,0,9,0,0,0,4,9,0,0,0,0,0,0
0,0,0,0,0,0,9,4,4,0,0,0,0,0,0,0
0,0,0,0,9,0,0,4,4,0,9,0,0,0,0,0
0,0,0,0,0,0,0,9,0,0,0,0,0,0,0,0
0,0,0,0,0,0,0,0,0,0,0,0,0,0,0,0
0,0,0,0,0,0,0,0,0,0,0,0,0,0,0,0
0,0,0,0,0,0,0,0,0,0,0,0,0,0,0,0
0,0,0,0,0,0,0,0,0,0,0,0,0,0,0,0
0,0,0,0,0,0,0,0,0,0,0,0,0,0,0,0
endlayer

layer
0,0,0,0,0,0,0,0,0,0,0,0,0,0,0,0
0,0,0,0,0,0,0,0,0,0,0,0,0,0,0,0
0,0,0,0,0,0,0,0,0,0,0,0,0,0,0,0
0,0,0,0,0,0,0,0,0,0,0,0,0,0,0,0
0,0,0,0,0,0,0,0,0,0,0,0,0,0,0,0
0,0,0,9,0,0,0,0,0,0,9,0,0,0,0,0
0,0,0,0,11,11,0,0,0,10,10,10,0,0,0,0
0,0,9,10,10,11,11,4,4,10,11,11,9,0,0,0
0,0,0,0,10,10,10,4,4,10,11,0,0,0,0,0
0,0,0,9,0,10,10,10,0,9,0,0,0,0,0,0
0,0,0,0,0,9,0,0,0,0,0,0,0,0,0,0
0,0,0,0,0,0,0,0,0,0,0,0,0,0,0,0
0,0,0,0,0,0,0,0,0,0,0,0,0,0,0,0
0,0,0,0,0,0,0,0,0,0,0,0,0,0,0,0
0,0,0,0,0,0,0,0,0,0,0,0,0,0,0,0
endlayer

layer
0,0,0,0,0,0,0,0,0,0,0,0,0,0,0,0
0,0,0,0,0,0,0,0,0,0,0,0,0,0,0,0
0,0,0,0,0,0,0,0,0,0,0,0,0,0,0,0
0,0,0,0,0,0,0,0,0,0,0,0,0,0,0,0
0,0,0,0,0,0,0,0,0,0,0,0,0,0,0,0
0,0,0,10,11,9,0,0,9,0,10,0,0,9,0,0
0,0,10,10,11,11,11,9,0,10,11,11,10,0,0,0
0,0,10,10,10,11,6,6,4,4,11,11,11,10,0,9
0,0,10,10,10,10,10,11,4,11,11,11,11,10,9,0
0,0,0,10,10,10,0,11,11,11,0,0,9,0,0,0
0,0,0,0,9,10,0,0,0,0,0,0,0,0,0,0
0,0,0,0,0,0,0,0,0,0,0,0,0,0,0,0
0,0,0,0,0,0,0,0,0,0,0,0,0,0,0,0
0,0,0,0,0,0,0,0,0,0,0,0,0,0,0,0
0,0,0,0,0,0,0,0,0,0,0,0,0,0,0,0
endlayer

layer
0,0,0,0,0,0,0,0,0,0,0,0,0,0,0,0
0,0,0,0,0,0,0,0,0,0,0,0,0,0,0,0
0,0,0,0,0,0,0,0,9,0,0,0,0,0,0,0
0,0,0,0,0,0,0,9,0,0,0,0,0,0,0,0
0,0,0,0,0,0,9,10,11,10,9,0,0,0,0,0
0,0,0,10,11,10,0,10,10,10,10,0,11,11,10,0
0,0,10,10,11,11,11,10,11,10,11,11,11,11,11,11
0,0,10,10,6,6,10,10,4,4,6,6,10,10,10,10
0,0,10,10,10,10,10,11,4,4,11,10,10,10,10,10
0,0,0,10,10,10,0,0,0,11,10,10,10,10,10,0
0,0,0,0,10,10,0,0,0,0,0,0,0,9,0,0
0,0,0,0,0,0,0,0,0,0,0,0,0,0,0,0
0,0,0,0,0,0,0,0,0,0,0,0,0,0,0,0
0,0,0,0,0,0,0,0,0,0,0,0,0,0,0,0
0,0,0,0,0,0,0,0,0,0,0,0,0,0,0,0
endlayer

layer
0,0,0,0,0,0,0,0,0,0,0,0,0,0,0,0
0,0,0,0,0,0,0,0,0,0,0,0,0,0,0,0
0,0,0,0,0,0,0,9,11,10,0,0,0,0,0,0
0,0,0,0,0,0,11,11,11,10,0,0,0,0,0,0
0,0,0,0,0,0,11,10,11,11,10,0,0,0,0,0
0,0,0,10,11,11,0,10,5,11,0,0,11,11,11,0
0,0,11,11,11,11,11,10,5,11,11,11,11,11,11,11
0,0,11,11,10,10,10,0,4,4,11,11,6,6,10,10
0,0,10,10,10,10,10,0,4,4,11,11,11,10,10,10
0,0,0,10,10,10,0,0,9,0,0,10,10,10,10,0
0,0,0,0,0,0,0,0,0,0,0,0,10,10,0,0
0,0,0,0,0,0,0,9,0,0,0,0,0,0,0,0
0,0,0,0,0,0,0,0,0,0,0,0,0,0,0,0
0,0,0,0,0,0,0,0,0,0,0,0,0,0,0,0
0,0,0,0,0,0,0,0,0,0,0,0,0,0,0,0
endlayer

layer
0,0,0,0,0,0,0,0,0,0,0,0,0,0,0,0
0,0,0,0,0,0,0,0,0,0,0,0,0,0,0,0
0,0,0,0,0,0,0,11,11,11,0,0,0,0,0,0
0,0,0,0,0,0,11,11,11,11,10,0,0,0,0,0
0,0,0,0,0,0,10,10,5,11,10,0,0,0,0,0
0,0,0,0,0,0,0,10,11,11,10,0,11,10,10,0
0,0,0,10,10,10,0,10,11,11,11,11,11,11,11,10
0,0,0,10,10,10,0,0,4,4,10,10,11,10,10,10
0,0,0,10,10,10,0,0,4,4,10,10,10,10,10,10
0,0,0,0,0,0,0,10,10,10,0,0,10,10,10,0
0,0,0,0,0,9,0,12,12,12,9,0,0,0,0,0
0,0,0,0,0,0,9,12,12,12,0,0,0,0,0,0
0,0,0,0,0,0,0,0,9,0,9,0,0,0,0,0
0,0,0,0,0,0,0,9,0,0,0,0,0,0,0,0
0,0,0,0,0,0,0,0,0,0,0,0,0,0,0,0
endlayer

layer
0,0,0,0,0,0,0,0,0,0,0,0,0,0,0,0
0,0,0,0,0,0,0,0,0,0,0,0,0,0,0,0
0,0,0,0,0,0,0,10,11,0,0,0,0,0,0,0
0,0,0,0,0,0,10,10,11,11,0,0,0,0,0,0
0,0,0,0,0,0,10,10,10,11,10,0,0,0,0,0
0,0,0,0,0,0,0,10,11,11,10,0,0,0,0,0
0,0,0,0,0,0,0,10,10,11,11,0,10,10,10,0
0,0,0,0,0,0,10,11,4,4,10,9,10,10,10,0
0,0,0,0,0,10,10,10,4,4,10,0,10,10,10,0
0,0,0,0,0,10,10,10,5,10,10,0,0,0,0,0
0,0,0,0,0,10,10,12,5,12,10,0,0,0,0,0
0,0,0,0,0,0,10,12,12,12,10,0,0,0,0,0
0,0,0,0,0,0,10,10,11,11,11,0,0,0,0,0
0,0,0,0,0,0,0,10,11,9,0,0,0,0,0,0
0,0,0,0,0,0,0,0,0,0,0,0,0,0,0,0
endlayer

layer
0,0,0,0,0,0,0,0,0,0,0,0,0,0,0,0
0,0,0,0,0,0,0,0,0,0,0,0,0,0,0,0
0,0,0,0,0,0,0,0,0,0,0,0,0,0,0,0
0,0,0,0,0,0,0,0,0,0,0,0,0,0,0,0
0,0,0,0,0,0,0,0,10,0,0,0,0,0,0,0
0,0,0,0,0,0,0,10,11,11,0,0,0,0,0,0
0,0,0,0,0,0,10,10,10,10,10,0,0,0,0,0
0,0,0,0,0,10,10,10,10,4,10,10,0,0,0,0
0,0,0,0,0,10,10,10,4,4,10,10,0,0,0,0
0,0,0,0,0,10,10,10,10,10,10,0,0,0,0,0
0,0,0,0,0,10,10,12,12,12,10,0,0,0,0,0
0,0,0,0,0,0,10,12,5,12,10,0,0,0,0,0
0,0,0,0,0,0,11,11,11,11,11,0,0,0,0,0
0,0,0,0,0,0,0,11,11,11,0,0,0,0,0,0
0,0,0,0,0,0,0,0,0,0,0,0,0,0,0,0
endlayer

layer
0,0,0,0,0,0,0,0,0,0,0,0,0,0,0,0
0,0,0,0,0,0,0,0,0,0,0,0,0,0,0,0
0,0,0,0,0,0,0,0,0,0,0,0,0,0,0,0
0,0,0,0,0,0,0,0,0,0,0,0,0,0,0,0
0,0,0,0,0,0,0,0,0,0,0,0,0,0,0,0
0,0,0,0,0,0,0,11,11,11,0,0,0,0,0,0
0,0,0,0,0,0,11,11,11,11,11,0,0,0,0,0
0,0,0,0,0,10,11,11,11,11,11,11,0,0,0,0
0,0,0,0,0,10,10,10,10,4,11,11,0,0,0,0
0,0,0,0,0,10,10,10,10,11,11,0,0,0,0,0
0,0,0,0,0,0,10,10,10,11,10,0,0,0,0,0
0,0,0,0,0,0,10,10,10,10,10,0,0,0,0,0
0,0,0,0,0,0,11,11,11,10,10,0,0,0,0,0
0,0,0,0,0,0,0,0,11,10,0,0,0,0,0,0
0,0,0,0,0,0,0,0,0,0,0,0,0,0,0,0
endlayer

layer
0,0,0,0,0,0,0,0,0,0,0,0,0,0,0,0
0,0,0,0,0,0,0,0,0,0,0,0,0,0,0,0
0,0,0,0,0,0,0,0,0,0,0,0,0,0,0,0
0,0,0,0,0,0,0,0,0,0,0,0,0,0,0,0
0,0,0,0,0,0,0,0,0,0,0,0,0,0,0,0
0,0,0,0,0,0,0,0,0,0,0,0,0,0,0,0
0,0,0,0,0,0,0,0,11,11,0,0,0,0,0,0
0,0,0,0,0,0,10,11,11,11,11,0,0,0,0,0
0,0,0,0,0,0,10,10,11,11,11,0,0,0,0,0
0,0,0,0,0,0,0,10,10,11,11,0,0,0,0,0
0,0,0,0,0,0,0,10,10,11,0,0,0,0,0,0
0,0,0,0,0,0,0,10,10,10,0,0,0,0,0,0
0,0,0,0,0,0,0,11,11,10,0,0,0,0,0,0
0,0,0,0,0,0,0,0,0,0,0,0,0,0,0,0
0,0,0,0,0,0,0,0,0,0,0,0,0,0,0,0
endlayer

layer
0,0,0,0,0,0,0,0,0,0,0,0,0,0,0,0
0,0,0,0,0,0,0,0,0,0,0,0,0,0,0,0
0,0,0,0,0,0,0,0,0,0,0,0,0,0,0,0
0,0,0,0,0,0,0,0,0,0,0,0,0,0,0,0
0,0,0,0,0,0,0,0,0,0,0,0,0,0,0,0
0,0,0,0,0,0,0,0,0,0,0,0,0,0,0,0
0,0,0,0,0,0,0,0,0,0,0,0,0,0,0,0
0,0,0,0,0,0,0,0,0,10,10,0,0,0,0,0
0,0,0,0,0,0,0,0,10,11,11,0,0,0,0,0
0,0,0,0,0,0,0,0,10,11,0,0,0,0,0,0
0,0,0,0,0,0,0,0,0,0,0,0,0,0,0,0
0,0,0,0,0,0,0,0,0,0,0,0,0,0,0,0
0,0,0,0,0,0,0,0,0,0,0,0,0,0,0,0
0,0,0,0,0,0,0,0,0,0,0,0,0,0,0,0
0,0,0,0,0,0,0,0,0,0,0,0,0,0,0,0
endlayer

