
# Created by Ruins mod version 16.7 Ingame Parser
# authoring Player: lafuller

weight=1
embed_into_distance=3
acceptable_target_blocks=
unacceptable_target_blocks=flowing_water,water,flowing_lava,lava,ice,bedrock,netherrack,nether_brick,nether_brick_fence,soul_sand,quartz_ore,end_stone,obsidian,iron_bars,cloud,flesh,ash_block,slime_grass,slime_congealed,slime_dirt
biomesToSpawnIn=plains,prarie,meadow,tundra,brushland,shrubland,woodland,woodlands,lavender_fields,flower_field,sunflower_plains,ice_flats,ice_plains
dimensions=12,13,13
allowable_overhang=0
max_leveling=3
leveling_buffer=-1
preserve_water=0
preserve_lava=0

rule1=0,100,preserveBlock
rule2=0,100,minecraft:stone_brick_stairs-2
rule3=0,100,minecraft:stone_brick_stairs-0
rule4=0,100,minecraft:stone_brick_stairs-3
rule5=0,100,stonebrick-0,stonebrick-0,stonebrick-0,stonebrick-0,stonebrick-1,stonebrick-2,stonebrick-2,stone-5,stone-6,cobblestone
rule6=0,100,minecraft:stone_brick_stairs-1
rule7=0,100,minecraft:stone-6
rule8=0,100,stonebrick-0,stonebrick-0,stonebrick-0,stonebrick-0,stonebrick-1,stonebrick-2,stonebrick-2,stone-5,stone-6,cobblestone,gravel
rule9=0,100,minecraft:cobblestone_wall-0
rule10=0,100,minecraft:spruce_fence-0
rule11=0,100,minecraft:dark_oak_stairs-0
rule12=0,100,minecraft:wooden_slab-13
rule13=0,100,minecraft:spruce_fence_gate-1
rule14=0,100,minecraft:dark_oak_stairs-2
rule15=0,100,minecraft:dark_oak_stairs-3
rule16=0,100,minecraft:spruce_fence_gate-0
rule17=0,100,minecraft:spruce_fence_gate-2
rule18=0,100,minecraft:dark_oak_stairs-1
rule19=0,100,minecraft:wooden_slab-5
rule20=0,100,minecraft:spruce_fence_gate-3

layer
1,1,1,1,4,3,3,3,2,1,1,1,1
1,1,1,1,5,5,5,5,5,1,1,1,1
1,1,5,5,5,5,5,5,5,5,5,1,1
1,1,5,5,5,5,5,5,5,5,5,1,1
3,5,5,5,5,5,5,5,5,5,5,5,3
4,5,5,5,5,5,5,5,5,5,5,5,2
4,5,5,5,5,5,5,5,5,5,5,5,2
4,5,5,5,5,5,5,5,5,5,5,5,2
6,5,5,5,5,5,5,5,5,5,5,5,6
1,1,5,5,5,5,5,5,5,5,5,1,1
1,1,5,5,5,5,5,5,5,5,5,1,1
1,1,1,1,5,5,5,5,5,1,1,1,1
1,1,1,1,4,6,6,6,2,1,1,1,1
endlayer

layer
1,1,1,1,1,1,1,1,1,1,1,1,1
1,1,1,1,7,4,3,2,7,1,1,1,1
1,1,7,7,8,8,8,8,8,7,7,1,1
1,1,7,8,8,8,8,8,8,8,7,1,1
1,7,8,8,8,8,8,8,8,8,8,7,1
1,3,8,8,8,8,8,8,8,8,8,3,1
1,4,8,8,8,8,8,8,8,8,8,2,1
1,6,8,8,8,8,8,8,8,8,8,6,1
1,7,8,8,8,8,8,8,8,8,8,7,1
1,1,7,8,8,8,8,8,8,8,7,1,1
1,1,7,7,8,8,8,8,8,7,7,1,1
1,1,1,1,7,4,6,2,7,1,1,1,1
1,1,1,1,1,1,1,1,1,1,1,1,1
endlayer

layer
1,1,1,1,1,1,1,1,1,1,1,1,1
1,1,1,1,7,1,1,1,7,1,1,1,1
1,1,1,3,7,3,3,3,7,3,1,1,1
1,1,4,7,8,8,8,8,8,7,2,1,1
1,7,7,8,8,8,8,8,8,8,7,7,1
1,1,4,8,8,8,8,8,8,8,2,1,1
1,1,4,8,8,8,8,8,8,8,2,1,1
1,1,4,8,8,8,8,8,8,8,2,1,1
1,7,7,8,8,8,8,8,8,8,7,7,1
1,1,4,7,8,8,8,8,8,7,2,1,1
1,1,1,6,7,6,6,6,7,6,1,1,1
1,1,1,1,7,1,1,1,7,1,1,1,1
1,1,1,1,1,1,1,1,1,1,1,1,1
endlayer

layer
1,1,1,1,1,1,1,1,1,1,1,1,1
1,1,1,1,9,1,1,1,9,1,1,1,1
1,1,1,1,7,1,1,1,7,1,1,1,1
1,1,1,7,6,3,3,3,6,7,1,1,1
1,9,7,2,7,3,6,3,7,4,7,9,1
1,1,1,4,4,8,6,8,2,2,1,1,1
1,1,1,4,2,2,7,4,4,2,1,1,1
1,1,1,4,4,8,3,8,2,2,1,1,1
1,9,7,2,7,6,3,6,7,4,7,9,1
1,1,1,7,3,6,6,6,3,7,1,1,1
1,1,1,1,7,1,1,1,7,1,1,1,1
1,1,1,1,9,1,1,1,9,1,1,1,1
1,1,1,1,1,1,1,1,1,1,1,1,1
endlayer

layer
1,1,1,1,1,1,1,1,1,1,1,1,1
1,1,1,1,9,1,1,1,9,1,1,1,1
1,1,1,1,9,0,0,0,9,1,1,1,1
1,1,1,0,0,0,0,0,0,0,1,1,1
1,9,9,0,0,0,0,0,0,0,9,9,1
1,1,0,0,0,0,0,0,0,0,0,1,1
1,1,0,0,0,0,0,0,0,0,0,1,1
1,1,0,0,0,0,0,0,0,0,0,1,1
1,9,9,0,0,0,0,0,0,0,9,9,1
1,1,1,0,0,0,0,0,0,0,1,1,1
1,1,1,1,9,0,0,0,9,1,1,1,1
1,1,1,1,9,1,1,1,9,1,1,1,1
1,1,1,1,1,1,1,1,1,1,1,1,1
endlayer

layer
1,1,1,1,1,1,1,1,1,1,1,1,1
1,1,1,1,10,1,1,1,10,1,1,1,1
1,1,1,1,10,0,0,0,10,1,1,1,1
1,1,1,0,0,0,0,0,0,0,1,1,1
1,10,10,0,0,0,0,0,0,0,10,10,1
1,1,0,0,0,0,0,0,0,0,0,1,1
1,1,0,0,0,0,0,0,0,0,0,1,1
1,1,0,0,0,0,0,0,0,0,0,1,1
1,10,10,0,0,0,0,0,0,0,10,10,1
1,1,1,0,0,0,0,0,0,0,1,1,1
1,1,1,1,10,0,0,0,10,1,1,1,1
1,1,1,1,10,1,1,1,10,1,1,1,1
1,1,1,1,1,1,1,1,1,1,1,1,1
endlayer

layer
1,1,1,1,1,1,1,1,1,1,1,1,1
1,1,1,1,10,1,1,1,10,1,1,1,1
1,1,1,1,10,0,0,0,10,1,1,1,1
1,1,1,0,0,0,0,0,0,0,1,1,1
1,10,10,0,0,0,0,0,0,0,10,10,1
1,1,0,0,0,0,0,0,0,0,0,1,1
1,1,0,0,0,0,0,0,0,0,0,1,1
1,1,0,0,0,0,0,0,0,0,0,1,1
1,10,10,0,0,0,0,0,0,0,10,10,1
1,1,1,0,0,0,0,0,0,0,1,1,1
1,1,1,1,10,0,0,0,10,1,1,1,1
1,1,1,1,10,1,1,1,10,1,1,1,1
1,1,1,1,1,1,1,1,1,1,1,1,1
endlayer

layer
1,1,1,1,1,1,1,1,1,1,1,1,1
1,1,1,1,10,1,1,1,10,1,1,1,1
1,1,1,1,10,0,0,0,10,1,1,1,1
1,1,1,0,0,0,0,0,0,0,1,1,1
1,10,10,0,0,0,0,0,0,0,10,10,1
1,1,0,0,0,0,0,0,0,0,0,1,1
1,1,0,0,0,0,0,0,0,0,0,1,1
1,1,0,0,0,0,0,0,0,0,0,1,1
1,10,10,0,0,0,0,0,0,0,10,10,1
1,1,1,0,0,0,0,0,0,0,1,1,1
1,1,1,1,10,0,0,0,10,1,1,1,1
1,1,1,1,10,1,1,1,10,1,1,1,1
1,1,1,1,1,1,1,1,1,1,1,1,1
endlayer

layer
1,1,1,1,1,1,1,1,1,1,1,1,1
1,1,1,1,11,12,12,12,11,1,1,1,1
1,1,1,12,10,13,13,13,10,12,1,1,1
1,1,12,10,10,0,0,0,10,10,12,1,1
1,15,10,10,10,0,0,0,10,10,10,14,1
1,12,17,0,0,0,0,0,0,16,0,12,1
1,12,17,0,0,0,0,0,0,16,0,12,1
1,12,17,0,0,0,0,0,0,16,0,12,1
1,15,10,10,10,0,0,0,10,10,10,14,1
1,1,12,10,10,13,13,13,10,10,12,1,1
1,1,1,12,10,0,0,0,10,12,1,1,1
1,1,1,1,18,12,12,12,18,1,1,1,1
1,1,1,1,1,1,1,1,1,1,1,1,1
endlayer

layer
1,1,1,1,1,1,1,1,1,1,1,1,1
1,1,1,1,1,1,1,1,1,1,1,1,1
1,1,1,1,19,15,11,14,19,1,1,1,1
1,1,1,19,11,12,13,12,11,19,1,1,1
1,1,19,15,10,10,13,10,10,14,19,1,1
1,1,11,12,10,10,0,10,10,12,11,1,1
1,1,15,16,17,0,0,0,17,0,14,1,1
1,1,18,12,10,10,0,10,10,12,18,1,1
1,1,19,15,10,10,20,10,10,14,19,1,1
1,1,1,19,18,12,0,12,18,19,1,1,1
1,1,1,1,19,15,18,14,19,1,1,1,1
1,1,1,1,1,1,1,1,1,1,1,1,1
1,1,1,1,1,1,1,1,1,1,1,1,1
endlayer

layer
1,1,1,1,1,1,1,1,1,1,1,1,1
1,1,1,1,1,1,1,1,1,1,1,1,1
1,1,1,1,1,1,1,1,1,1,1,1,1
1,1,1,1,1,1,1,1,1,1,1,1,1
1,1,1,1,1,19,19,19,1,1,1,1,1
1,1,1,1,19,10,13,10,19,1,1,1,1
1,1,1,1,19,16,1,17,19,1,1,1,1
1,1,1,1,19,10,20,10,19,1,1,1,1
1,1,1,1,1,19,19,19,1,1,1,1,1
1,1,1,1,1,1,1,1,1,1,1,1,1
1,1,1,1,1,1,1,1,1,1,1,1,1
1,1,1,1,1,1,1,1,1,1,1,1,1
1,1,1,1,1,1,1,1,1,1,1,1,1
endlayer

layer
1,1,1,1,1,1,1,1,1,1,1,1,1
1,1,1,1,1,1,1,1,1,1,1,1,1
1,1,1,1,1,1,1,1,1,1,1,1,1
1,1,1,1,1,1,1,1,1,1,1,1,1
1,1,1,1,1,1,1,1,1,1,1,1,1
1,1,1,1,1,19,11,19,1,1,1,1,1
1,1,1,1,1,15,1,14,1,1,1,1,1
1,1,1,1,1,19,18,19,1,1,1,1,1
1,1,1,1,1,1,1,1,1,1,1,1,1
1,1,1,1,1,1,1,1,1,1,1,1,1
1,1,1,1,1,1,1,1,1,1,1,1,1
1,1,1,1,1,1,1,1,1,1,1,1,1
1,1,1,1,1,1,1,1,1,1,1,1,1
endlayer

