
# Created by Ruins mod version 17.0 Ingame Parser
# authoring Player: ST753M

weight=1
uniqueMinDistance=1200
spawnMinDistance=500
embed_into_distance=13
acceptable_target_blocks=water,sand,sandstone
unacceptable_target_blocks=
dimensions=40,31,31
allowable_overhang=2
max_leveling=0
leveling_buffer=-1
preserve_water=0
preserve_lava=0

biomesToSpawnIn=ocean,kelp_forest,coral_reef,beaches

rule1=0,100,preserveBlock
rule2=0,100,minecraft:sandstone-0

rule3=0,100,botania:biomestonea1stairs-7
^0,100,botania:biomestonea0stairs-7
^0,100,botania:biomestonea7stairs-7
^0,100,botania:biomestonea6stairs-7
^0,100,botania:biomestonea5stairs-7
^0,100,botania:biomestonea4stairs-7
^0,100,botania:biomestonea3stairs-7
^0,100,botania:biomestonea2stairs-7
^0,100,botania:biomestonea1stairs-7
rule4^0,100,botania:biomestonea1stairs-5
^0,100,botania:biomestonea0stairs-5
^0,100,botania:biomestonea7stairs-5
^0,100,botania:biomestonea6stairs-5
^0,100,botania:biomestonea5stairs-5
^0,100,botania:biomestonea4stairs-5
^0,100,botania:biomestonea3stairs-5
^0,100,botania:biomestonea2stairs-5
^0,100,botania:biomestonea1stairs-5
rule5^0,100,botania:biomestonea1stairs-4
^0,100,botania:biomestonea0stairs-4
^0,100,botania:biomestonea7stairs-4
^0,100,botania:biomestonea6stairs-4
^0,100,botania:biomestonea5stairs-4
^0,100,botania:biomestonea4stairs-4
^0,100,botania:biomestonea3stairs-4
^0,100,botania:biomestonea2stairs-4
^0,100,botania:biomestonea1stairs-4
rule6^0,100,botania:biomestonea1stairs-6
^0,100,botania:biomestonea0stairs-6
^0,100,botania:biomestonea7stairs-6
^0,100,botania:biomestonea6stairs-6
^0,100,botania:biomestonea5stairs-6
^0,100,botania:biomestonea4stairs-6
^0,100,botania:biomestonea3stairs-6
^0,100,botania:biomestonea2stairs-6
^0,100,botania:biomestonea1stairs-6
rule7^0,100,botania:biomestonea1stairs-2
^0,100,botania:biomestonea0stairs-2
^0,100,botania:biomestonea7stairs-2
^0,100,botania:biomestonea6stairs-2
^0,100,botania:biomestonea5stairs-2
^0,100,botania:biomestonea4stairs-2
^0,100,botania:biomestonea3stairs-2
^0,100,botania:biomestonea2stairs-2
^0,100,botania:biomestonea1stairs-2
rule8^0,100,botania:biomestonea1stairs-0
^0,100,botania:biomestonea0stairs-0
^0,100,botania:biomestonea7stairs-0
^0,100,botania:biomestonea6stairs-0
^0,100,botania:biomestonea5stairs-0
^0,100,botania:biomestonea4stairs-0
^0,100,botania:biomestonea3stairs-0
^0,100,botania:biomestonea2stairs-0
^0,100,botania:biomestonea1stairs-0
rule9^0,100,botania:biomestonea1stairs-1
^0,100,botania:biomestonea0stairs-1
^0,100,botania:biomestonea7stairs-1
^0,100,botania:biomestonea6stairs-1
^0,100,botania:biomestonea5stairs-1
^0,100,botania:biomestonea4stairs-1
^0,100,botania:biomestonea3stairs-1
^0,100,botania:biomestonea2stairs-1
^0,100,botania:biomestonea1stairs-1
rule10^0,100,botania:biomestonea1stairs-3
^0,100,botania:biomestonea0stairs-3
^0,100,botania:biomestonea7stairs-3
^0,100,botania:biomestonea6stairs-3
^0,100,botania:biomestonea5stairs-3
^0,100,botania:biomestonea4stairs-3
^0,100,botania:biomestonea3stairs-3
^0,100,botania:biomestonea2stairs-3
^0,100,botania:biomestonea1stairs-3
rule11^0,100,botania:biomestonea-1
^0,100,botania:biomestonea-0
^0,100,botania:biomestonea-7
^0,100,botania:biomestonea-6
^0,100,botania:biomestonea-5
^0,100,botania:biomestonea-4
^0,100,botania:biomestonea-3
^0,100,botania:biomestonea-2
^0,100,botania:biomestonea-1

rule12=0,100,minecraft:dirt-0

rule13=0,100,botania:altgrass-4
^0,100,botania:altgrass-5
^0,100,botania:altgrass-3
^0,100,botania:altgrass-2
^0,100,botania:altgrass-1
^0,100,botania:altgrass-0

rule14^0,70,botania:flower-8,botania:flower-6,botania:flower-5,botania:flower-0,botania:flower-11,botania:flower-9,botania:flower-7,botania:flower-3,botania:flower-2,botania:flower-13,botania:flower-10,botania:flower-8,botania:flower-6,botania:flower-5,botania:flower-0,botania:flower-11,botania:flower-9,botania:flower-7,botania:flower-3,botania:flower-2,botania:flower-13,botania:flower-10,teBlock;botania:specialflower;{x:5878,subTileCmp:{passiveDecayTicks:1905,mana:0,ticksExisted:1,burnTime:0,collectorZ:0,cooldown:0,collectorY:-1,collectorX:0},y:103,subTileName:"hydroangeas",z:1383,id:"botania:specialflower"}-0
^0,70,botania:flower-10,botania:flower-6,botania:flower-0,botania:flower-15,botania:flower-9,botania:flower-7,botania:flower-3,botania:flower-2,botania:flower-11,botania:flower-10,botania:flower-6,botania:flower-0,botania:flower-15,botania:flower-9,botania:flower-7,botania:flower-3,botania:flower-2,botania:flower-11,teBlock;botania:specialflower;{x:5875,subTileCmp:{ticksExisted:2168,ticksRemaining2:-1,ticksRemaining3:-1,ticksRemaining0:-1,position:0,ticksRemaining1:-1,ticksRemaining6:-1,ticksRemaining7:-1,ticksRemaining4:-1,ticksRemaining5:-1},y:103,subTileName:"puredaisy",z:1383,id:"botania:specialflower"}-0
^0,70,botania:flower-15,botania:flower-8,botania:flower-7,botania:flower-4,botania:flower-14,botania:flower-12,botania:flower-1,botania:flower-15,botania:flower-8,botania:flower-7,botania:flower-4,botania:flower-14,botania:flower-12,botania:flower-1,botania:flower-15,botania:flower-8,botania:flower-7,botania:flower-4,botania:flower-14,botania:flower-12,botania:flower-1,teBlock;botania:specialflower;{x:5881,subTileCmp:{poolZ:0,poolX:0,poolY:-1,mana:0,ticksExisted:1926},y:103,subTileName:"exoflame",z:1383,id:"botania:specialflower"}-0
^0,70,botania:flower-9,botania:flower-4,botania:flower-0,botania:flower-6,botania:flower-14,botania:flower-5,botania:flower-2,botania:flower-13,botania:flower-9,botania:flower-4,botania:flower-0,botania:flower-6,botania:flower-14,botania:flower-5,botania:flower-2,botania:flower-13,botania:flower-9,botania:flower-4,botania:flower-0,botania:flower-6,botania:flower-14,botania:flower-5,botania:flower-2,botania:flower-13,teBlock;botania:specialflower;{x:5885,subTileCmp:{poolZ:0,windTicks:0,poolX:0,orientation:1,poolY:-1,mana:0,ticksExisted:1853},y:103,subTileName:"daffomill",z:1383,id:"botania:specialflower"}-0
^0,70,botania:flower-8,botania:flower-1,botania:flower-14,botania:flower-12,botania:flower-7,botania:flower-4,botania:flower-8,botania:flower-1,botania:flower-14,botania:flower-12,botania:flower-7,botania:flower-4,botania:flower-8,botania:flower-1,botania:flower-14,botania:flower-12,botania:flower-7,botania:flower-4,botania:flower-8,botania:flower-1,botania:flower-14,botania:flower-12,botania:flower-7,botania:flower-4,teBlock;botania:specialflower;{x:5887,subTileCmp:{passiveDecayTicks:0,mana:0,ticksExisted:2250,burnTime:0,collectorZ:0,cooldown:0,collectorY:-1,collectorX:0},y:103,subTileName:"thermalily",z:1383,id:"botania:specialflower"}-0
^0,70,botania:flower-8,botania:flower-7,botania:flower-0,botania:flower-1,botania:flower-12,botania:flower-4,botania:flower-6,botania:flower-8,botania:flower-7,botania:flower-0,botania:flower-1,botania:flower-12,botania:flower-4,botania:flower-6,botania:flower-8,botania:flower-7,botania:flower-0,botania:flower-1,botania:flower-12,botania:flower-4,botania:flower-6,botania:flower-8,botania:flower-7,botania:flower-0,botania:flower-1,botania:flower-12,botania:flower-4,botania:flower-6,teBlock;botania:specialflower;{x:5891,subTileCmp:{poolZ:0,poolX:0,poolY:-1,mana:0,ticksExisted:1356},y:103,subTileName:"solegnolia",z:1383,id:"botania:specialflower"}-0


rule15=0,100,ChestGenHook:chests/simple_dungeon:5-4
rule16=0,100,MobSpawner:skeleton,MobSpawner:zombie,MobSpawner:silverfish
rule17=0,100,botania:livingrock-1
rule18=0,100,minecraft:glowstone-0
rule19=0,100,minecraft:water-0
rule20=0,100,minecraft:sand-0
rule21=0,100,botania:altar-0
rule22=0,100,botania:livingrock0slab-0
rule23=0,100,botania:livingrock-0
rule24=0,100,botania:livingrock0slab-8
rule25=0,100,botania:pool-0
rule26=0,100,minecraft:stone-0
rule27=0,100,minecraft:leaves-7
rule28=0,100,minecraft:log-3
rule29=0,100,minecraft:leaves-15
rule30=0,100,minecraft:furnace-5
rule31=0,100,minecraft:oak_stairs-1
rule32=0,100,minecraft:trapdoor-8
rule33=0,100,minecraft:jungle_door-3
rule34=0,100,minecraft:oak_stairs-0
rule35=0,100,minecraft:jungle_door-0
rule36=0,100,minecraft:bed-3
rule37=0,100,minecraft:bed-11
rule38=0,100,minecraft:bookshelf-0
rule39=0,100,botania:managlass-0
rule40=0,100,minecraft:cobblestone_wall-0
rule41=0,100,minecraft:flower_pot-0
rule42=0,100,minecraft:jungle_door-8
#          Diagonal stripes on the lighthouse
rule43=0,100,botania:petalblock-0

layer
1,1,1,1,1,1,1,1,1,1,1,1,1,1,1,1,1,1,1,1,1,1,1,1,1,1,1,1,1,1,1
1,1,1,1,1,1,1,1,1,1,1,1,1,1,1,1,1,1,1,1,1,1,1,1,1,1,1,1,1,1,1
1,1,1,1,1,1,1,1,1,1,1,2,2,2,2,2,2,2,2,2,1,1,1,1,1,1,1,1,1,1,1
1,1,1,1,1,1,1,1,1,2,2,2,2,2,2,2,2,2,2,2,2,2,1,1,1,1,1,1,1,1,1
1,1,1,1,1,1,1,2,2,2,2,2,2,2,2,2,2,2,2,2,2,2,2,2,1,1,1,1,1,1,1
1,1,1,1,1,1,2,2,2,2,2,2,2,2,2,2,2,2,2,2,2,2,2,2,2,1,1,1,1,1,1
1,1,1,1,1,2,2,2,2,2,2,2,2,2,2,2,2,2,2,2,2,2,2,2,2,2,1,1,1,1,1
1,1,1,1,2,2,2,2,2,2,2,2,2,2,2,2,2,2,2,2,2,2,2,2,2,2,2,1,1,1,1
1,1,1,1,2,2,2,2,2,2,2,2,2,2,2,2,2,2,2,2,2,2,2,2,2,2,2,1,1,1,1
1,1,1,2,2,2,2,2,2,2,2,2,2,2,2,2,2,2,2,2,2,2,2,2,2,2,2,2,1,1,1
1,1,1,2,2,2,2,2,2,2,2,2,2,2,2,2,2,2,2,2,2,2,2,2,2,2,2,2,1,1,1
1,1,2,2,2,2,2,2,2,2,2,2,2,2,2,2,2,2,2,2,2,2,2,2,2,2,2,2,2,1,1
1,1,2,2,2,2,2,2,2,2,2,2,2,2,2,2,2,2,2,2,2,2,2,2,2,2,2,2,2,1,1
1,1,2,2,2,2,2,2,2,2,2,2,2,2,2,2,2,2,2,2,2,2,2,2,2,2,2,2,2,1,1
1,1,2,2,2,2,2,2,2,2,2,2,2,2,2,2,2,2,2,2,2,2,2,2,2,2,2,2,2,1,1
1,1,2,2,2,2,2,2,2,2,2,2,2,2,2,2,2,2,2,2,2,2,2,2,2,2,2,2,2,1,1
1,1,2,2,2,2,2,2,2,2,2,2,2,2,2,2,2,2,2,2,2,2,2,2,2,2,2,2,2,1,1
1,1,2,2,2,2,2,2,2,2,2,2,2,2,2,2,2,2,2,2,2,2,2,2,2,2,2,2,2,1,1
1,1,2,2,2,2,2,2,2,2,2,2,2,2,2,2,2,4,3,2,2,2,2,2,2,2,2,2,2,1,1
1,1,2,2,2,2,2,2,2,2,2,2,2,2,2,2,2,6,5,2,2,2,2,2,2,2,2,2,2,1,1
1,1,1,2,2,2,2,2,2,2,2,2,2,2,2,2,2,2,2,2,2,2,2,2,2,2,2,2,1,1,1
1,1,1,2,2,2,2,2,2,2,2,2,2,2,2,2,2,8,7,2,2,2,2,2,2,2,2,2,1,1,1
1,1,1,1,2,2,2,2,2,2,2,2,2,2,2,2,2,10,9,2,2,2,2,2,2,2,2,1,1,1,1
1,1,1,1,2,2,2,2,2,2,2,2,2,2,2,2,2,2,11,2,2,2,2,2,2,2,2,1,1,1,1
1,1,1,1,1,2,2,2,2,2,2,2,2,2,2,2,2,2,2,2,2,2,2,2,2,2,1,1,1,1,1
1,1,1,1,1,1,2,2,2,2,2,2,2,2,2,2,2,2,2,2,2,2,2,2,2,1,1,1,1,1,1
1,1,1,1,1,1,1,2,2,2,2,2,2,2,2,2,2,2,2,2,2,2,2,2,1,1,1,1,1,1,1
1,1,1,1,1,1,1,1,1,2,2,2,2,2,2,2,2,2,2,2,2,2,1,1,1,1,1,1,1,1,1
1,1,1,1,1,1,1,1,1,1,1,2,2,2,2,2,2,2,2,2,1,1,1,1,1,1,1,1,1,1,1
1,1,1,1,1,1,1,1,1,1,1,1,1,1,1,1,1,1,1,1,1,1,1,1,1,1,1,1,1,1,1
1,1,1,1,1,1,1,1,1,1,1,1,1,1,1,1,1,1,1,1,1,1,1,1,1,1,1,1,1,1,1
endlayer

layer
1,1,1,1,1,1,1,1,1,1,1,1,1,1,1,1,1,1,1,1,1,1,1,1,1,1,1,1,1,1,1
1,1,1,1,1,1,1,1,1,1,1,2,2,2,2,2,2,2,2,2,1,1,1,1,1,1,1,1,1,1,1
1,1,1,1,1,1,1,1,1,2,2,2,2,2,2,2,2,2,2,2,2,2,1,1,1,1,1,1,1,1,1
1,1,1,1,1,1,1,2,2,2,2,2,2,2,2,2,2,2,2,2,2,2,2,2,1,1,1,1,1,1,1
1,1,1,1,1,1,2,2,2,2,2,2,2,2,2,2,2,2,2,2,2,2,2,2,2,1,1,1,1,1,1
1,1,1,1,1,2,2,2,2,2,2,2,2,2,2,2,2,2,2,2,2,2,2,2,2,2,1,1,1,1,1
1,1,1,1,2,2,2,2,2,2,2,2,2,2,2,2,2,2,2,2,2,2,2,2,2,2,2,1,1,1,1
1,1,1,2,2,2,2,2,2,2,2,2,2,2,2,2,2,2,2,2,2,2,2,2,2,2,2,2,1,1,1
1,1,1,2,2,2,2,2,2,2,2,2,2,2,2,2,2,2,2,2,2,2,2,2,2,2,2,2,1,1,1
1,1,2,2,2,2,2,2,2,2,2,2,2,2,2,2,2,2,2,2,2,2,2,2,2,2,2,2,2,1,1
1,1,2,2,2,2,2,2,2,2,2,2,2,2,2,2,2,2,2,2,2,2,2,2,2,2,2,2,2,1,1
1,2,2,2,2,2,2,2,2,2,2,2,2,2,2,2,2,2,2,2,2,2,2,2,2,2,2,2,2,2,1
1,2,2,2,2,2,2,2,2,2,2,2,2,2,2,2,2,2,2,2,2,2,2,2,2,2,2,2,2,2,1
1,2,2,2,2,2,2,2,2,2,2,2,2,2,2,2,2,2,2,2,2,2,2,2,2,2,2,2,2,2,1
1,2,2,2,2,2,2,2,2,2,2,2,2,2,2,2,2,2,2,2,2,2,2,2,2,2,2,2,2,2,1
1,2,2,2,2,2,2,2,2,2,2,2,2,2,2,2,2,2,2,2,2,2,2,2,2,2,2,2,2,2,1
1,2,2,2,2,2,2,2,2,2,2,2,2,2,2,2,2,2,2,2,2,2,2,2,2,2,2,2,2,2,1
1,2,2,2,2,2,2,2,2,2,2,2,2,2,2,2,2,2,2,2,2,2,2,2,2,2,2,2,2,2,1
1,2,2,2,2,2,2,2,2,2,2,2,2,2,2,2,2,13,12,2,2,2,2,2,2,2,2,2,2,2,1
1,2,2,2,2,2,2,2,2,2,2,2,2,2,2,2,2,2,2,2,2,2,2,2,2,2,2,2,2,2,1
1,1,2,2,2,2,2,2,2,2,2,2,2,2,2,2,2,2,2,2,2,2,2,2,2,2,2,2,2,1,1
1,1,2,2,2,2,2,2,2,2,2,2,2,2,2,2,2,2,2,2,2,2,2,2,2,2,2,2,2,1,1
1,1,1,2,2,2,2,2,2,2,2,2,2,2,2,2,2,2,2,2,2,2,2,2,2,2,2,2,1,1,1
1,1,1,2,2,2,2,2,2,2,2,2,2,2,2,2,2,2,2,2,2,2,2,2,2,2,2,2,1,1,1
1,1,1,1,2,2,2,2,2,2,2,2,2,2,2,2,2,2,2,2,2,2,2,2,2,2,2,1,1,1,1
1,1,1,1,1,2,2,2,2,2,2,2,2,2,2,2,2,2,2,2,2,2,2,2,2,2,1,1,1,1,1
1,1,1,1,1,1,2,2,2,2,2,2,2,2,2,2,2,2,2,2,2,2,2,2,2,1,1,1,1,1,1
1,1,1,1,1,1,1,2,2,2,2,2,2,2,2,2,2,2,2,2,2,2,2,2,1,1,1,1,1,1,1
1,1,1,1,1,1,1,1,1,2,2,2,2,2,2,2,2,2,2,2,2,2,1,1,1,1,1,1,1,1,1
1,1,1,1,1,1,1,1,1,1,1,2,2,2,2,2,2,2,2,2,1,1,1,1,1,1,1,1,1,1,1
1,1,1,1,1,1,1,1,1,1,1,1,1,1,1,1,1,1,1,1,1,1,1,1,1,1,1,1,1,1,1
endlayer

layer
1,1,1,1,1,1,1,1,1,1,1,1,1,1,1,1,1,1,1,1,1,1,1,1,1,1,1,1,1,1,1
1,1,1,1,1,1,1,1,1,1,2,2,2,2,2,2,2,2,2,2,2,1,1,1,1,1,1,1,1,1,1
1,1,1,1,1,1,1,1,2,2,2,2,2,2,2,2,2,2,2,2,2,2,2,1,1,1,1,1,1,1,1
1,1,1,1,1,1,1,2,2,2,2,2,2,2,2,2,2,2,2,2,2,2,2,2,1,1,1,1,1,1,1
1,1,1,1,1,2,2,2,2,2,2,2,2,2,2,2,2,2,2,2,2,2,2,2,2,2,1,1,1,1,1
1,1,1,1,2,2,2,2,2,2,2,2,2,2,2,2,2,2,2,2,2,2,2,2,2,2,2,1,1,1,1
1,1,1,1,2,2,2,2,2,2,2,2,2,2,2,2,2,2,2,2,2,2,2,2,2,2,2,1,1,1,1
1,1,1,2,2,2,2,2,2,2,2,2,2,2,2,2,2,2,2,2,2,2,2,2,2,2,2,2,1,1,1
1,1,2,2,2,2,2,2,2,2,2,2,2,2,2,2,2,2,2,2,2,2,2,2,2,2,2,2,2,1,1
1,1,2,2,2,2,2,2,2,2,2,2,2,2,2,2,2,2,2,2,2,2,2,2,2,2,2,2,2,1,1
1,2,2,2,2,2,2,2,2,2,2,2,2,2,2,2,2,2,2,2,2,2,2,2,2,2,2,2,2,2,1
1,2,2,2,2,2,2,2,2,2,2,2,2,2,2,2,2,2,2,2,2,2,2,2,2,2,2,2,2,2,1
1,2,2,2,2,2,2,2,2,2,2,2,2,2,2,2,2,2,2,2,2,2,2,2,2,2,2,2,2,2,1
1,2,2,2,2,11,2,2,2,2,2,2,2,2,2,2,2,2,2,2,2,2,2,2,2,2,2,2,2,2,1
1,2,2,2,2,11,11,11,11,2,2,2,2,2,2,2,2,2,2,2,2,2,2,2,2,2,2,2,2,2,1
1,2,2,2,2,2,2,2,11,2,2,2,2,2,2,2,2,2,2,2,2,2,2,2,2,2,2,2,2,2,1
1,2,2,2,2,2,2,2,11,2,2,2,2,2,2,2,2,2,2,2,2,2,2,2,2,2,2,2,2,2,1
1,2,2,2,2,2,2,2,11,2,2,2,2,2,2,2,2,2,2,2,2,2,2,2,2,2,2,2,2,2,1
1,2,2,2,2,2,2,2,11,2,2,2,2,2,2,2,2,14,2,2,2,2,2,2,2,2,2,2,2,2,1
1,2,2,2,2,2,11,11,11,11,11,2,2,2,2,2,2,2,2,2,2,2,2,2,2,2,2,2,2,2,1
1,2,2,2,2,2,11,11,11,11,11,2,2,2,2,2,2,2,2,2,2,2,2,2,2,2,2,2,2,2,1
1,1,2,2,2,2,11,11,11,11,11,2,2,2,2,2,2,2,2,2,2,2,2,2,2,2,2,2,2,1,1
1,1,2,2,2,2,11,11,11,11,11,2,2,2,2,2,2,2,2,2,2,2,2,2,2,2,2,2,2,1,1
1,1,1,2,2,2,11,11,11,11,11,2,2,2,2,2,2,2,2,2,2,2,2,2,2,2,2,2,1,1,1
1,1,1,1,2,2,11,11,11,11,11,2,2,2,2,2,2,2,2,2,2,2,2,2,2,2,2,1,1,1,1
1,1,1,1,2,2,11,11,11,11,11,2,2,2,2,2,2,2,2,2,2,2,2,2,2,2,2,1,1,1,1
1,1,1,1,1,2,2,2,2,2,2,2,2,2,2,2,2,2,2,2,2,2,2,2,2,2,1,1,1,1,1
1,1,1,1,1,1,1,2,2,2,2,2,2,2,2,2,2,2,2,2,2,2,2,2,1,1,1,1,1,1,1
1,1,1,1,1,1,1,1,2,2,2,2,2,2,2,2,2,2,2,2,2,2,2,1,1,1,1,1,1,1,1
1,1,1,1,1,1,1,1,1,1,2,2,2,2,2,2,2,2,2,2,2,1,1,1,1,1,1,1,1,1,1
1,1,1,1,1,1,1,1,1,1,1,1,1,1,1,1,1,1,1,1,1,1,1,1,1,1,1,1,1,1,1
endlayer

layer
1,1,1,1,1,1,1,1,1,1,1,1,1,2,2,2,2,2,1,1,1,1,1,1,1,1,1,1,1,1,1
1,1,1,1,1,1,1,1,1,1,2,2,2,2,2,2,2,2,2,2,2,1,1,1,1,1,1,1,1,1,1
1,1,1,1,1,1,1,1,2,2,2,2,2,2,2,2,2,2,2,2,2,2,2,1,1,1,1,1,1,1,1
1,1,1,1,1,1,2,2,2,2,2,2,2,2,2,2,2,2,2,2,2,2,2,2,2,1,1,1,1,1,1
1,1,1,1,1,2,2,2,2,11,11,11,11,11,11,11,11,11,2,2,2,2,2,2,2,2,1,1,1,1,1
1,1,1,1,2,2,2,2,2,11,11,11,11,11,11,11,11,11,2,2,2,2,2,2,2,2,2,1,1,1,1
1,1,1,2,2,2,2,2,2,11,11,11,11,11,11,11,11,11,2,2,2,2,2,2,2,2,2,2,1,1,1
1,1,1,2,2,11,11,11,11,11,11,11,11,11,11,11,11,11,11,11,11,11,11,11,2,2,2,2,1,1,1
1,1,2,2,2,11,2,2,2,11,11,11,11,11,11,11,11,11,2,2,2,2,2,11,2,2,2,2,2,1,1
1,1,2,2,2,11,2,2,2,11,11,11,11,11,11,11,11,11,2,2,2,2,2,2,2,2,2,2,2,1,1
1,2,2,2,2,11,2,2,2,11,11,11,11,11,11,11,11,11,2,2,2,2,2,2,2,2,2,2,2,2,1
1,2,2,2,2,11,2,2,2,2,2,2,2,2,2,2,2,2,2,2,2,2,2,2,2,2,2,2,2,2,1
1,2,2,2,2,11,2,2,2,2,2,2,2,2,2,2,2,2,2,2,2,2,2,2,2,2,2,2,2,2,1
2,2,2,2,11,9,11,11,11,2,2,2,2,2,2,2,2,2,2,2,2,2,2,2,2,2,2,2,2,2,2
2,2,2,2,11,0,0,0,0,11,2,2,2,2,2,2,2,2,2,2,2,2,2,2,2,2,2,2,2,2,2
2,2,2,2,2,11,11,11,0,11,2,2,2,2,2,2,2,2,2,2,2,2,2,2,2,2,2,2,2,2,2
2,2,2,2,2,2,2,11,0,11,2,2,2,2,2,2,2,2,2,2,2,2,2,2,2,2,2,2,2,2,2
2,2,2,2,2,2,2,11,0,11,2,2,2,2,2,2,2,2,2,2,2,2,2,2,2,2,2,2,2,2,2
1,2,2,2,2,2,11,11,0,11,11,2,2,2,2,2,2,2,2,2,2,2,2,2,2,2,2,2,2,2,1
1,2,2,2,2,11,0,0,0,0,0,11,2,2,2,2,2,2,2,2,2,2,2,2,2,2,2,2,2,2,1
1,2,2,2,2,11,0,0,0,0,0,11,2,2,2,2,2,2,2,2,2,2,2,2,2,2,2,2,2,2,1
1,1,2,2,2,11,0,0,0,0,0,11,2,2,2,2,2,2,2,2,2,2,2,2,2,2,2,2,2,1,1
1,1,2,2,2,11,0,0,0,0,0,11,2,2,2,2,2,2,2,2,2,2,2,2,2,2,2,2,2,1,1
1,1,1,2,2,11,0,0,11,0,0,11,2,2,2,2,2,2,2,2,2,2,2,2,2,2,2,2,1,1,1
1,1,1,2,2,11,0,0,0,0,0,11,2,2,2,2,2,2,2,2,2,2,2,2,2,2,2,2,1,1,1
1,1,1,1,2,11,0,0,0,0,0,11,2,2,2,2,2,2,2,2,2,2,2,2,2,2,2,1,1,1,1
1,1,1,1,1,2,11,11,11,11,11,2,2,2,2,2,2,2,2,2,2,2,2,2,2,2,1,1,1,1,1
1,1,1,1,1,1,2,2,2,2,2,2,2,2,2,2,2,2,2,2,2,2,2,2,2,1,1,1,1,1,1
1,1,1,1,1,1,1,1,2,2,2,2,2,2,2,2,2,2,2,2,2,2,2,1,1,1,1,1,1,1,1
1,1,1,1,1,1,1,1,1,1,2,2,2,2,2,2,2,2,2,2,2,1,1,1,1,1,1,1,1,1,1
1,1,1,1,1,1,1,1,1,1,1,1,1,2,2,2,2,2,1,1,1,1,1,1,1,1,1,1,1,1,1
endlayer

layer
1,1,1,1,1,1,1,1,1,1,1,1,2,2,2,2,2,2,2,1,1,1,1,1,1,1,1,1,1,1,1
1,1,1,1,1,1,1,1,1,2,2,2,2,2,2,2,2,2,2,2,2,2,1,1,1,1,1,1,1,1,1
1,1,1,1,1,1,1,2,2,2,2,2,2,2,2,2,2,2,2,2,2,2,2,2,1,1,1,1,1,1,1
1,1,1,1,1,1,2,2,2,11,11,11,11,11,11,11,11,11,2,2,2,2,2,2,2,1,1,1,1,1,1
1,1,1,1,1,2,2,2,11,0,0,0,0,0,0,0,0,0,11,2,2,2,2,2,2,2,1,1,1,1,1
1,1,1,1,2,2,2,2,11,0,0,0,0,0,0,0,0,0,11,2,2,2,2,2,2,2,2,1,1,1,1
1,1,1,2,11,11,11,11,11,0,0,0,0,0,0,0,0,0,11,11,11,11,11,11,2,2,2,2,1,1,1
1,1,2,2,11,0,0,0,7,0,0,0,0,11,0,0,0,0,0,0,0,0,0,0,11,2,2,2,2,1,1
1,1,2,2,11,0,11,11,11,0,0,0,0,0,0,0,0,0,11,11,11,11,11,8,11,2,2,2,2,1,1
1,2,2,2,11,0,11,2,11,0,0,0,0,0,0,0,0,0,11,2,2,2,2,11,2,2,2,2,2,2,1
1,2,2,2,11,0,11,2,11,0,0,0,0,0,0,0,0,0,11,2,2,2,2,11,2,2,2,2,2,2,1
1,2,2,2,11,0,11,2,2,11,11,11,11,11,11,11,11,11,2,2,2,2,2,11,2,2,2,2,2,2,1
2,2,2,2,11,0,11,2,2,2,2,2,2,2,2,2,2,2,2,2,2,2,2,11,2,2,2,2,2,2,2
2,2,2,2,11,0,11,11,11,2,2,2,2,2,2,2,2,2,2,2,2,2,2,11,2,2,2,2,2,2,2
2,2,2,2,11,0,0,0,0,11,2,2,2,2,2,2,2,2,2,2,2,2,2,2,2,2,2,2,2,2,2
2,2,2,2,2,11,11,11,0,11,2,2,2,2,2,2,2,2,2,2,2,2,2,2,2,2,2,2,2,2,2
2,2,2,2,2,2,2,11,0,11,2,2,2,2,2,2,2,2,2,2,2,2,2,2,2,2,2,2,2,2,2
2,2,2,2,2,2,2,11,0,11,2,2,2,2,2,2,2,2,2,2,2,2,2,2,2,2,2,2,2,2,2
2,2,2,2,2,2,11,11,0,11,11,2,2,2,2,2,2,2,2,2,2,2,2,2,2,2,2,2,2,2,2
1,2,2,2,2,11,0,0,0,0,0,11,2,2,2,2,2,2,2,2,2,2,2,2,2,2,2,2,2,2,1
1,2,2,2,2,11,0,0,0,0,0,11,2,2,2,2,2,2,2,2,2,2,2,2,2,2,2,2,2,2,1
1,2,2,2,2,11,0,0,0,0,0,11,2,2,2,2,2,2,2,2,2,2,2,2,2,2,2,2,2,2,1
1,1,2,2,2,11,0,0,0,0,0,11,2,2,2,2,2,2,2,2,2,2,2,2,2,2,2,2,2,1,1
1,1,2,2,2,11,0,0,15,0,0,11,2,2,2,2,2,2,2,2,2,2,2,2,2,2,2,2,2,1,1
1,1,1,2,2,11,0,0,0,0,0,11,2,2,2,2,2,2,2,2,2,2,2,2,2,2,2,2,1,1,1
1,1,1,1,2,11,0,0,0,0,0,11,2,2,2,2,2,2,2,2,2,2,2,2,2,2,2,1,1,1,1
1,1,1,1,1,2,11,11,11,11,11,2,2,2,2,2,2,2,2,2,2,2,2,2,2,2,1,1,1,1,1
1,1,1,1,1,1,2,2,2,2,2,2,2,2,2,2,2,2,2,2,2,2,2,2,2,1,1,1,1,1,1
1,1,1,1,1,1,1,2,2,2,2,2,2,2,2,2,2,2,2,2,2,2,2,2,1,1,1,1,1,1,1
1,1,1,1,1,1,1,1,1,2,2,2,2,2,2,2,2,2,2,2,2,2,1,1,1,1,1,1,1,1,1
1,1,1,1,1,1,1,1,1,1,1,1,2,2,2,2,2,2,2,1,1,1,1,1,1,1,1,1,1,1,1
endlayer

layer
1,1,1,1,1,1,1,1,1,1,1,1,2,2,2,2,2,2,2,1,1,1,1,1,1,1,1,1,1,1,1
1,1,1,1,1,1,1,1,1,2,2,2,2,2,2,2,2,2,2,2,2,2,1,1,1,1,1,1,1,1,1
1,1,1,1,1,1,1,2,2,2,2,2,2,2,2,2,2,2,2,2,2,2,2,2,1,1,1,1,1,1,1
1,1,1,1,1,1,2,2,2,11,11,11,11,11,11,11,11,11,2,2,2,2,2,2,2,1,1,1,1,1,1
1,1,1,1,1,2,2,2,11,0,0,0,0,0,0,0,0,0,11,2,2,2,2,2,2,2,1,1,1,1,1
1,1,1,1,2,2,2,2,11,0,0,0,0,0,0,0,0,0,11,2,2,2,2,2,2,2,2,1,1,1,1
1,1,1,2,11,11,11,11,11,0,0,0,0,0,0,0,0,0,11,11,11,11,11,11,2,2,2,2,1,1,1
1,1,2,2,11,0,0,0,6,0,0,0,0,11,0,0,0,0,0,0,0,0,0,0,11,2,2,2,2,1,1
1,1,2,2,11,0,11,11,11,0,0,0,0,0,0,0,0,0,11,11,11,11,11,0,11,2,2,2,2,1,1
1,2,2,2,11,0,11,2,11,0,0,0,0,0,0,0,0,0,11,2,2,2,11,0,11,2,2,2,2,2,1
1,2,2,2,11,0,11,2,11,0,0,0,0,0,0,0,0,0,11,2,2,2,11,0,11,2,2,2,2,2,1
1,2,2,2,11,0,11,2,2,11,11,11,11,11,11,11,11,11,2,2,2,2,11,0,11,2,2,2,2,2,1
2,2,2,2,11,0,11,2,2,2,2,2,2,2,2,2,2,2,2,2,2,2,11,0,11,2,2,2,2,2,2
2,2,2,2,11,0,11,11,11,2,2,2,2,2,2,2,2,2,2,2,2,2,11,8,11,2,2,2,2,2,2
2,2,2,2,11,0,0,0,0,11,2,2,2,2,2,2,2,2,2,2,2,2,11,11,11,2,2,2,2,2,2
2,2,2,2,2,11,11,11,0,11,2,2,2,2,2,2,2,2,2,2,2,2,2,11,2,2,2,2,2,2,2
2,2,2,2,2,2,2,11,0,11,2,2,2,2,2,2,2,2,2,2,2,2,2,11,2,2,2,2,2,2,2
2,2,2,2,2,2,2,11,0,11,2,2,2,2,2,2,2,2,2,2,2,2,2,11,2,2,2,2,2,2,2
2,2,2,2,2,2,11,11,11,11,11,2,2,2,2,2,2,2,2,2,2,2,2,11,2,2,2,2,2,2,2
1,2,2,2,2,11,0,0,0,0,0,11,2,2,2,2,2,2,2,2,2,2,2,2,2,2,2,2,2,2,1
1,2,2,2,2,11,0,0,0,0,0,11,2,2,2,2,2,2,2,2,2,2,2,2,2,2,2,2,2,2,1
1,2,2,2,2,11,0,0,0,0,0,11,2,2,2,2,2,2,2,2,2,2,2,2,2,2,2,2,2,2,1
1,1,2,2,2,11,0,0,0,0,0,11,2,2,2,2,2,2,2,2,2,2,2,2,2,2,2,2,2,1,1
1,1,2,2,2,11,0,0,0,0,0,11,2,2,2,2,2,2,2,2,2,2,2,2,2,2,2,2,2,1,1
1,1,1,2,2,11,0,0,0,0,0,11,2,2,2,2,2,2,2,2,2,2,2,2,2,2,2,2,1,1,1
1,1,1,1,2,11,0,0,0,0,0,11,2,2,2,2,2,2,2,2,2,2,2,2,2,2,2,1,1,1,1
1,1,1,1,1,2,11,11,11,11,11,2,2,2,2,2,2,2,2,2,2,2,2,2,2,2,1,1,1,1,1
1,1,1,1,1,1,2,2,2,2,2,2,2,2,2,2,2,2,2,2,2,2,2,2,2,1,1,1,1,1,1
1,1,1,1,1,1,1,2,2,2,2,2,2,2,2,2,2,2,2,2,2,2,2,2,1,1,1,1,1,1,1
1,1,1,1,1,1,1,1,1,2,2,2,2,2,2,2,2,2,2,2,2,2,1,1,1,1,1,1,1,1,1
1,1,1,1,1,1,1,1,1,1,1,1,2,2,2,2,2,2,2,1,1,1,1,1,1,1,1,1,1,1,1
endlayer

layer
1,1,1,1,1,1,1,1,1,1,1,1,2,2,2,2,2,2,2,1,1,1,1,1,1,1,1,1,1,1,1
1,1,1,1,1,1,1,1,1,2,2,2,2,2,2,2,2,2,2,2,2,2,1,1,1,1,1,1,1,1,1
1,1,1,1,1,1,1,2,2,2,2,2,2,2,2,2,2,2,2,2,2,2,2,2,1,1,1,1,1,1,1
1,1,1,1,1,1,2,2,2,11,11,11,11,11,11,11,11,11,2,2,2,2,2,2,2,1,1,1,1,1,1
1,1,1,1,1,2,2,2,11,0,0,0,0,0,0,0,0,0,11,2,2,2,2,2,2,2,1,1,1,1,1
1,1,1,1,2,2,2,2,11,0,0,0,0,0,0,0,0,0,11,2,2,2,2,2,2,2,2,1,1,1,1
1,1,1,2,11,11,11,11,11,0,0,0,0,0,0,0,0,0,11,11,11,11,11,11,2,2,2,2,1,1,1
1,1,2,2,11,0,0,0,11,0,0,0,0,16,0,0,0,0,11,0,0,0,0,0,11,2,2,2,2,1,1
1,1,2,2,11,0,11,11,11,0,0,0,0,0,0,0,0,0,11,11,11,11,11,0,11,2,2,2,2,1,1
1,2,2,2,11,0,11,2,11,0,0,0,0,0,0,0,0,0,11,2,2,2,11,0,11,2,2,2,2,2,1
1,2,2,2,11,0,11,2,11,0,0,0,0,0,0,0,0,0,11,2,2,2,11,0,11,2,2,2,2,2,1
1,2,2,2,9,0,9,2,2,11,11,11,11,11,11,11,11,11,2,2,2,2,11,0,11,2,2,2,2,2,1
2,2,2,2,17,0,17,2,2,2,2,2,2,2,2,2,2,2,2,2,2,2,11,0,11,2,2,2,2,2,2
2,2,2,2,17,0,17,17,17,2,2,2,2,11,11,11,2,2,2,2,2,2,11,0,11,2,2,2,2,2,2
2,2,2,2,17,0,0,0,0,17,2,2,2,11,18,11,2,2,2,2,2,2,11,0,11,2,2,2,2,2,2
2,2,2,2,2,17,17,17,0,17,2,2,2,11,11,11,2,2,2,2,2,2,11,0,11,2,2,2,2,2,2
2,2,2,2,2,2,2,17,0,17,2,2,2,2,2,2,2,2,2,2,2,2,11,0,11,2,2,2,2,2,2
2,2,2,2,2,2,2,17,0,17,2,2,2,2,2,2,2,2,2,2,2,2,11,0,11,2,2,2,2,2,2
2,2,2,2,2,2,17,17,17,17,17,2,2,2,2,2,11,11,2,2,2,2,11,8,11,2,2,2,2,2,2
1,2,2,2,2,17,0,0,0,0,0,17,2,2,2,2,2,11,2,2,2,11,11,11,11,11,2,2,2,2,1
1,2,2,2,2,17,0,0,0,0,0,17,2,2,2,2,2,11,2,2,2,11,11,11,11,11,2,2,2,2,1
1,2,2,2,2,17,0,0,0,0,0,17,2,2,2,2,2,11,2,11,11,11,11,11,11,11,2,2,2,2,1
1,1,2,2,2,17,0,0,0,0,0,17,2,2,2,2,2,11,11,11,2,11,11,11,11,11,2,2,2,1,1
1,1,2,2,2,17,0,0,0,0,0,17,2,2,2,2,2,2,2,2,2,11,11,11,11,11,2,2,2,1,1
1,1,1,2,2,17,0,0,0,0,0,17,2,2,2,2,2,2,2,2,2,2,2,2,2,2,2,2,1,1,1
1,1,1,1,2,17,0,0,0,0,0,17,2,2,2,2,2,2,2,2,2,2,2,2,2,2,2,1,1,1,1
1,1,1,1,1,2,17,17,17,17,17,2,2,2,2,2,2,2,2,2,2,2,2,2,2,2,1,1,1,1,1
1,1,1,1,1,1,2,2,2,2,2,2,2,2,2,2,2,2,2,2,2,2,2,2,2,1,1,1,1,1,1
1,1,1,1,1,1,1,2,2,2,2,2,2,2,2,2,2,2,2,2,2,2,2,2,1,1,1,1,1,1,1
1,1,1,1,1,1,1,1,1,2,2,2,2,2,2,2,2,2,2,2,2,2,1,1,1,1,1,1,1,1,1
1,1,1,1,1,1,1,1,1,1,1,1,2,2,2,2,2,2,2,1,1,1,1,1,1,1,1,1,1,1,1
endlayer

layer
1,1,1,1,1,1,1,1,1,1,1,1,2,2,2,2,2,2,2,1,1,1,1,1,1,1,1,1,1,1,1
1,1,1,1,1,1,1,1,1,2,2,2,2,2,2,2,2,2,2,2,2,2,1,1,1,1,1,1,1,1,1
1,1,1,1,1,1,1,2,2,2,2,2,2,2,2,2,2,2,2,2,2,2,2,2,1,1,1,1,1,1,1
1,1,1,1,1,1,2,2,2,17,17,17,17,17,17,17,17,17,2,2,2,2,2,2,2,1,1,1,1,1,1
1,1,1,1,1,2,2,2,17,0,0,0,0,0,0,0,0,0,17,2,2,2,2,2,2,2,1,1,1,1,1
1,1,1,1,2,2,2,2,17,0,0,0,0,0,0,0,0,0,17,2,2,2,2,2,2,2,2,1,1,1,1
1,1,1,2,17,17,17,17,17,0,0,0,0,0,0,0,0,0,17,17,17,17,17,17,2,2,2,2,1,1,1
1,1,2,2,17,0,0,0,17,0,0,0,0,17,0,0,0,0,17,0,0,0,0,0,17,2,2,2,2,1,1
1,1,2,2,17,0,17,17,17,0,0,0,0,0,0,0,0,0,17,17,17,17,17,0,17,2,2,2,2,1,1
1,2,2,2,17,0,17,2,17,0,0,0,0,0,0,0,0,0,17,2,2,2,11,0,11,2,2,2,2,2,1
1,2,2,2,17,0,17,2,17,0,0,0,0,0,0,0,0,0,17,2,2,2,11,0,11,2,2,2,2,2,1
1,2,2,2,17,0,17,2,2,17,17,17,17,17,17,17,17,17,2,2,2,2,11,0,11,2,2,2,2,2,1
2,2,2,2,17,0,17,2,2,2,2,2,2,17,17,17,2,2,2,2,2,2,11,0,11,2,2,2,2,2,2
2,2,2,2,17,5,17,2,2,2,2,2,17,19,19,19,17,2,2,2,2,2,11,0,11,2,2,2,2,2,2
2,2,2,2,2,11,11,11,11,0,2,2,17,19,19,19,11,2,2,2,2,2,11,0,11,2,2,2,2,2,2
2,2,2,2,2,2,2,2,11,2,2,2,17,19,19,19,11,2,2,11,2,2,11,0,11,2,2,2,2,2,2
2,2,2,2,2,2,2,2,11,2,2,2,11,17,11,11,2,2,2,11,2,2,11,0,11,2,2,2,2,2,2
2,2,2,2,2,2,2,2,11,2,2,2,2,2,2,2,2,11,11,11,2,2,11,0,11,2,2,2,2,2,2
2,2,2,2,2,2,2,2,11,2,2,2,2,2,2,2,2,11,11,11,2,11,11,9,11,11,2,2,2,2,2
1,2,2,2,2,2,11,11,11,11,11,2,2,2,2,2,11,11,11,11,11,0,0,0,0,0,11,2,2,2,1
1,2,2,2,2,2,11,11,11,11,11,2,2,2,2,2,11,9,11,11,11,0,0,0,0,0,11,2,2,2,1
1,2,2,2,2,2,11,11,11,11,11,2,2,2,2,2,11,0,11,0,0,0,0,0,0,0,11,2,2,2,1
1,1,2,2,2,2,11,11,11,11,11,2,2,2,2,2,11,0,0,0,11,0,0,0,0,0,11,2,2,1,1
1,1,2,2,2,2,11,11,11,11,11,2,2,2,2,2,2,11,11,11,11,0,0,0,0,0,11,2,2,1,1
1,1,1,2,2,2,11,11,11,11,11,2,2,2,2,2,2,2,2,2,2,11,11,11,11,11,2,2,1,1,1
1,1,1,1,2,2,11,11,11,11,11,2,2,2,2,2,2,2,2,2,2,2,2,2,2,2,2,1,1,1,1
1,1,1,1,1,2,2,2,2,2,2,2,2,2,2,2,2,2,2,2,2,2,2,2,2,2,1,1,1,1,1
1,1,1,1,1,1,2,2,2,2,2,2,2,2,2,2,2,2,2,2,2,2,2,2,2,1,1,1,1,1,1
1,1,1,1,1,1,1,2,2,2,2,2,2,2,2,2,2,2,2,2,2,2,2,2,1,1,1,1,1,1,1
1,1,1,1,1,1,1,1,1,2,2,2,2,2,2,2,2,2,2,2,2,2,1,1,1,1,1,1,1,1,1
1,1,1,1,1,1,1,1,1,1,1,1,2,2,2,2,2,2,2,1,1,1,1,1,1,1,1,1,1,1,1
endlayer

layer
1,1,1,1,1,1,1,1,1,1,1,1,2,2,2,2,2,2,2,1,1,1,1,1,1,1,1,1,1,1,1
1,1,1,1,1,1,1,1,1,2,2,2,2,2,2,2,2,2,2,2,2,2,1,1,1,1,1,1,1,1,1
1,1,1,1,1,1,1,2,2,2,2,2,2,2,2,2,2,2,2,2,2,2,2,2,1,1,1,1,1,1,1
1,1,1,1,1,1,2,2,2,2,2,2,2,2,2,2,2,2,2,2,2,2,2,2,2,1,1,1,1,1,1
1,1,1,1,1,2,2,2,2,11,11,11,11,11,11,11,11,11,2,2,2,2,2,2,2,2,1,1,1,1,1
1,1,1,1,2,2,2,2,2,11,11,11,11,11,11,11,11,11,2,2,2,2,2,2,2,2,2,1,1,1,1
1,1,1,2,2,2,2,2,2,11,11,11,11,11,11,11,11,11,2,2,2,2,2,2,2,2,2,2,1,1,1
1,1,2,2,2,11,11,11,11,11,11,11,11,11,11,11,11,11,11,11,11,11,11,4,17,2,2,2,2,1,1
1,1,2,2,2,11,2,2,2,11,11,11,11,11,11,11,11,11,2,2,2,2,17,0,17,2,2,2,2,1,1
1,2,2,2,2,11,2,2,2,11,11,11,11,11,11,11,11,11,2,2,2,2,17,0,17,2,2,2,2,2,1
1,2,2,2,2,11,2,2,2,11,11,11,11,11,11,11,11,11,2,2,2,2,17,0,17,2,2,2,2,2,1
1,2,2,2,2,11,2,2,2,11,11,11,11,11,11,11,11,11,11,11,2,2,17,0,17,2,2,2,2,2,1
2,2,2,2,2,11,2,2,2,11,11,11,11,11,11,11,2,2,2,11,2,2,17,0,17,2,2,2,2,2,2
2,2,2,2,2,2,2,2,2,11,11,11,11,19,19,19,17,2,2,11,2,2,11,0,11,2,2,2,2,2,2
2,2,2,2,2,2,2,2,2,11,11,11,11,19,19,19,17,2,2,11,2,2,11,0,11,2,2,2,2,2,2
2,2,2,2,2,2,2,2,2,11,11,11,11,19,19,19,17,2,11,9,11,2,11,0,11,2,2,2,2,2,2
2,2,2,2,2,2,2,2,2,2,2,2,11,17,17,17,2,2,11,0,11,2,11,0,11,2,2,2,2,2,2
2,2,2,2,2,2,2,2,2,2,2,2,11,2,2,2,2,11,11,0,11,2,11,0,11,2,2,2,2,2,2
2,2,2,2,2,2,2,2,2,2,2,2,2,2,2,2,11,0,0,0,11,11,11,4,11,11,2,2,2,2,2
1,2,2,2,2,2,2,2,2,2,2,2,2,2,2,2,11,0,11,11,11,0,0,0,0,0,11,2,2,2,1
1,2,2,2,2,2,2,2,2,2,2,2,2,2,2,2,11,0,11,11,11,0,0,0,0,0,11,2,2,2,1
1,2,2,2,2,2,2,2,2,2,2,2,2,2,2,2,11,0,11,0,0,0,0,0,0,0,11,2,2,2,1
1,1,2,2,2,2,2,2,2,2,2,2,2,2,2,2,11,0,0,0,11,0,0,0,0,0,11,2,2,1,1
1,1,2,2,2,2,2,2,2,2,2,2,2,2,2,2,2,11,11,11,11,0,0,0,0,0,11,2,2,1,1
1,1,1,2,2,2,2,2,2,2,2,2,2,2,2,2,2,2,2,2,2,11,11,11,11,11,2,2,1,1,1
1,1,1,1,2,2,2,2,2,2,2,2,2,2,2,2,2,2,2,2,2,2,2,2,2,2,2,1,1,1,1
1,1,1,1,1,2,2,2,2,2,2,2,2,2,2,2,2,2,2,2,2,2,2,2,2,2,1,1,1,1,1
1,1,1,1,1,1,2,2,2,2,2,2,2,2,2,2,2,2,2,2,2,2,2,2,2,1,1,1,1,1,1
1,1,1,1,1,1,1,2,2,2,2,2,2,2,2,2,2,2,2,2,2,2,2,2,1,1,1,1,1,1,1
1,1,1,1,1,1,1,1,1,2,2,2,2,2,2,2,2,2,2,2,2,2,1,1,1,1,1,1,1,1,1
1,1,1,1,1,1,1,1,1,1,1,1,2,2,2,2,2,2,2,1,1,1,1,1,1,1,1,1,1,1,1
endlayer

layer
1,1,1,1,1,1,1,1,1,1,1,1,20,2,2,2,2,2,20,1,1,1,1,1,1,1,1,1,1,1,1
1,1,1,1,1,1,1,1,1,20,2,2,2,2,2,2,2,2,2,2,2,20,1,1,1,1,1,1,1,1,1
1,1,1,1,1,1,1,20,2,2,2,2,2,2,2,2,2,2,2,2,2,2,2,20,1,1,1,1,1,1,1
1,1,1,1,1,1,2,2,2,2,2,2,2,2,2,2,2,2,2,2,2,2,2,2,2,1,1,1,1,1,1
1,1,1,1,1,2,2,2,2,2,2,2,2,2,2,2,2,2,2,2,2,2,2,2,2,2,1,1,1,1,1
1,1,1,1,2,2,2,2,2,2,2,2,2,2,2,2,2,2,2,2,2,2,2,2,2,2,2,1,1,1,1
1,1,1,2,2,2,2,2,2,2,2,2,2,2,2,2,2,2,2,2,2,2,2,2,2,2,2,2,1,1,1
1,1,20,2,2,2,2,2,2,11,11,11,11,11,11,11,2,2,2,2,2,2,2,2,2,2,2,2,20,1,1
1,1,2,2,2,2,2,2,11,0,0,0,0,0,0,0,11,2,2,2,2,2,2,11,2,2,2,2,2,1,1
1,20,2,2,2,2,2,2,11,0,0,0,21,0,0,0,17,2,2,2,2,2,2,11,2,2,2,2,2,20,1
1,2,2,2,2,2,2,2,11,0,22,0,0,0,21,0,11,11,11,11,2,2,2,11,2,2,2,2,2,2,1
1,2,2,2,2,2,2,2,11,0,23,0,0,0,0,0,10,0,0,0,11,2,17,4,17,2,2,2,2,2,1
20,2,2,2,2,2,2,2,11,0,24,0,0,0,0,0,11,11,11,0,11,2,17,0,17,2,2,2,2,2,20
2,2,2,2,2,2,2,2,11,0,23,0,0,0,0,0,17,2,11,0,11,2,17,0,17,2,2,2,2,2,2
2,2,2,2,2,2,2,2,11,0,22,0,0,0,0,0,11,2,11,0,11,2,17,0,17,2,2,2,2,2,2
2,2,2,2,2,2,2,2,11,0,0,0,0,0,0,0,11,2,11,0,11,2,17,0,17,2,2,2,2,2,2
2,2,2,2,2,2,2,2,2,11,11,17,0,17,11,11,2,2,11,0,11,2,17,0,17,2,2,2,2,2,2
2,2,2,2,2,2,2,2,2,2,2,11,8,11,2,2,2,11,11,0,11,2,17,0,17,2,2,2,2,2,2
20,2,2,2,2,2,2,2,2,2,2,2,11,2,2,2,11,0,0,0,11,11,11,11,11,11,2,2,2,2,20
1,2,2,2,2,2,2,2,2,2,2,2,2,2,2,2,11,0,11,11,11,0,0,0,0,0,11,2,2,2,1
1,2,2,2,2,2,2,2,2,2,2,2,2,2,2,2,11,0,11,11,11,0,0,0,0,0,11,2,2,2,1
1,20,2,2,2,2,2,2,2,2,2,2,2,2,2,2,11,0,11,0,0,0,0,0,0,0,11,2,2,20,1
1,1,2,2,2,2,2,2,2,2,2,2,2,2,2,2,11,0,0,0,11,0,0,0,0,0,11,2,2,1,1
1,1,20,2,2,2,2,2,2,2,2,2,2,2,2,2,2,11,11,11,11,0,0,0,0,0,11,2,20,1,1
1,1,1,2,2,2,2,2,2,2,2,2,2,2,2,2,2,2,2,2,2,11,11,11,11,11,2,2,1,1,1
1,1,1,1,2,2,2,2,2,2,2,2,2,2,2,2,2,2,2,2,2,2,2,2,2,2,2,1,1,1,1
1,1,1,1,1,2,2,2,2,2,2,2,2,2,2,2,2,2,2,2,2,2,2,2,2,2,1,1,1,1,1
1,1,1,1,1,1,2,2,2,2,2,2,2,2,2,2,2,2,2,2,2,2,2,2,2,1,1,1,1,1,1
1,1,1,1,1,1,1,20,2,2,2,2,2,2,2,2,2,2,2,2,2,2,2,20,1,1,1,1,1,1,1
1,1,1,1,1,1,1,1,1,20,2,2,2,2,2,2,2,2,2,2,2,20,1,1,1,1,1,1,1,1,1
1,1,1,1,1,1,1,1,1,1,1,1,20,2,2,2,2,2,20,1,1,1,1,1,1,1,1,1,1,1,1
endlayer

layer
1,1,1,1,1,1,1,1,1,1,1,1,1,20,20,20,20,20,1,1,1,1,1,1,1,1,1,1,1,1,1
1,1,1,1,1,1,1,1,1,1,2,2,2,2,2,2,2,2,2,2,2,1,1,1,1,1,1,1,1,1,1
1,1,1,1,1,1,1,1,2,2,2,2,2,2,2,2,2,2,2,2,2,2,2,1,1,1,1,1,1,1,1
1,1,1,1,1,1,20,2,2,2,2,2,2,2,2,2,2,2,2,2,2,2,2,2,20,1,1,1,1,1,1
1,1,1,1,1,2,2,2,2,2,2,2,2,2,2,2,2,2,2,2,2,2,2,2,2,2,1,1,1,1,1
1,1,1,1,2,2,2,2,2,2,2,2,2,2,2,2,2,2,2,2,2,2,2,2,2,2,2,1,1,1,1
1,1,1,20,2,2,2,2,2,2,2,2,2,2,2,2,2,2,2,2,2,2,2,2,2,2,2,20,1,1,1
1,1,1,2,2,2,2,2,2,11,11,11,11,11,11,11,2,2,2,2,2,2,2,2,2,2,2,2,1,1,1
1,1,2,2,2,2,2,2,11,0,0,0,0,0,0,0,11,2,2,2,2,2,2,2,2,2,2,2,2,1,1
1,1,2,2,2,2,2,2,11,0,0,0,0,0,0,0,17,2,2,2,2,2,2,2,2,2,2,2,2,1,1
1,2,2,2,2,2,2,2,11,0,0,0,0,0,0,0,11,11,11,11,2,2,2,2,2,2,2,2,2,2,1
1,2,2,2,2,2,2,2,11,0,0,0,0,0,0,0,3,0,0,0,11,2,2,2,2,2,2,2,2,2,1
1,2,2,2,2,2,2,2,11,0,25,0,0,0,0,0,11,11,11,0,11,2,2,11,2,2,2,2,2,2,1
20,2,2,2,2,2,2,2,11,0,0,0,0,0,0,0,17,2,11,0,11,2,2,11,2,2,2,2,2,2,20
20,2,2,2,2,2,2,2,11,0,0,0,0,0,0,0,11,2,11,0,11,2,2,11,2,2,2,2,2,2,20
20,2,2,2,2,2,2,2,11,0,0,0,0,0,0,0,11,2,11,0,11,2,2,11,2,2,2,2,2,2,20
20,2,2,2,2,2,2,2,2,11,11,17,0,17,11,11,2,2,11,0,11,2,17,4,17,2,2,2,2,2,20
20,2,2,2,2,2,2,2,2,2,2,11,0,11,2,2,2,17,11,0,11,2,17,0,17,2,2,2,2,2,20
1,2,2,2,2,2,2,2,2,2,2,11,8,11,2,2,17,0,0,0,11,17,17,17,17,17,2,2,2,2,1
1,2,2,2,2,2,2,2,2,2,2,2,11,2,2,2,17,0,17,11,17,0,0,0,0,0,17,2,2,2,1
1,2,2,2,2,2,2,2,2,2,2,2,2,2,2,2,17,0,17,17,17,0,0,0,0,0,17,2,2,2,1
1,1,2,2,2,2,2,2,2,2,2,2,2,2,2,2,17,0,17,0,0,0,0,0,0,0,17,2,2,1,1
1,1,2,2,2,2,2,2,2,2,2,2,2,2,2,2,17,0,0,0,17,0,0,0,0,0,17,2,2,1,1
1,1,1,2,2,2,2,2,2,2,2,2,2,2,2,2,2,17,17,17,17,0,0,0,0,0,17,2,1,1,1
1,1,1,20,2,2,2,2,2,2,2,2,2,2,2,2,2,2,2,2,2,17,17,17,17,17,2,20,1,1,1
1,1,1,1,2,2,2,2,2,2,2,2,2,2,2,2,2,2,2,2,2,2,2,2,2,2,2,1,1,1,1
1,1,1,1,1,2,2,2,2,2,2,2,2,2,2,2,2,2,2,2,2,2,2,2,2,2,1,1,1,1,1
1,1,1,1,1,1,20,2,2,2,2,2,2,2,2,2,2,2,2,2,2,2,2,2,20,1,1,1,1,1,1
1,1,1,1,1,1,1,1,2,2,2,2,2,2,2,2,2,2,2,2,2,2,2,1,1,1,1,1,1,1,1
1,1,1,1,1,1,1,1,1,1,2,2,2,2,2,2,2,2,2,2,2,1,1,1,1,1,1,1,1,1,1
1,1,1,1,1,1,1,1,1,1,1,1,1,20,20,20,20,20,1,1,1,1,1,1,1,1,1,1,1,1,1
endlayer

layer
1,1,1,1,1,1,1,1,1,1,1,1,1,1,1,1,1,1,1,1,1,1,1,1,1,1,1,1,1,1,1
1,1,1,1,1,1,1,1,1,1,20,2,2,2,2,2,2,2,2,2,20,1,1,1,1,1,1,1,1,1,1
1,1,1,1,1,1,1,1,20,2,2,2,2,2,2,2,2,2,2,2,2,2,20,1,1,1,1,1,1,1,1
1,1,1,1,1,1,1,2,2,2,2,2,2,2,2,2,2,2,2,2,2,2,2,2,1,1,1,1,1,1,1
1,1,1,1,1,20,2,2,2,2,2,2,2,2,2,2,2,2,2,2,2,2,2,2,2,20,1,1,1,1,1
1,1,1,1,20,2,2,2,2,2,2,2,2,2,2,2,2,2,2,2,2,2,2,2,2,2,20,1,1,1,1
1,1,1,1,2,2,2,2,2,2,2,2,2,2,2,2,2,2,2,2,2,2,2,2,2,2,2,1,1,1,1
1,1,1,2,2,2,2,2,2,11,11,11,11,11,11,11,2,2,2,2,2,2,2,2,2,2,2,2,1,1,1
1,1,20,2,2,2,2,2,11,0,0,0,0,0,0,0,11,2,2,2,2,2,2,2,2,2,2,2,20,1,1
1,1,2,2,2,2,2,2,11,0,0,0,0,0,0,0,17,2,2,2,2,2,2,2,2,2,2,2,2,1,1
1,20,2,2,2,2,2,2,11,0,0,0,0,0,0,0,11,11,11,11,2,2,2,2,2,2,2,2,2,20,1
1,2,2,2,2,2,2,2,11,0,0,0,0,0,0,0,11,0,0,0,11,2,2,2,2,2,2,2,2,2,1
1,2,2,2,2,2,2,2,11,0,0,0,0,0,0,0,11,11,11,0,11,2,2,2,2,2,2,2,2,2,1
1,2,2,2,2,2,2,2,11,0,0,0,0,0,0,0,17,2,11,0,11,2,2,2,2,2,2,2,2,2,1
1,2,2,2,2,2,2,2,11,0,0,0,0,0,0,0,11,2,17,0,17,2,2,2,2,2,2,2,2,2,1
1,2,2,2,2,2,2,2,11,0,0,0,0,0,0,0,11,2,17,0,17,2,2,2,2,2,2,2,2,2,1
1,2,2,2,2,2,2,2,2,11,11,17,0,17,11,11,2,2,17,0,17,2,2,2,2,2,2,2,2,2,1
1,2,2,2,2,2,2,2,2,2,2,11,0,11,2,2,2,17,17,0,17,2,2,11,2,2,2,2,2,2,1
1,2,2,2,2,2,2,2,2,2,2,11,0,11,2,2,17,6,0,0,17,2,2,11,2,2,2,2,2,2,1
1,2,2,2,2,2,2,2,2,2,2,11,8,11,2,2,2,11,17,17,2,11,11,11,11,11,2,2,2,2,1
1,20,2,2,2,2,2,2,2,2,2,2,11,2,2,2,2,11,2,2,2,11,11,11,11,11,2,2,2,20,1
1,1,2,2,2,2,2,2,2,2,2,2,2,2,2,2,2,11,2,11,11,11,11,18,11,11,2,2,2,1,1
1,1,20,2,2,2,2,2,2,2,2,2,2,2,2,2,2,11,11,11,2,11,11,11,11,11,2,2,20,1,1
1,1,1,2,2,2,2,2,2,2,2,2,2,2,2,2,2,2,2,2,2,11,11,11,11,11,2,2,1,1,1
1,1,1,1,2,2,2,2,2,2,2,2,2,2,2,2,2,2,2,2,2,2,2,2,2,2,2,1,1,1,1
1,1,1,1,20,2,2,2,2,2,2,2,2,2,2,2,2,2,2,2,2,2,2,2,2,2,20,1,1,1,1
1,1,1,1,1,20,2,2,2,2,2,2,2,2,2,2,2,2,2,2,2,2,2,2,2,20,1,1,1,1,1
1,1,1,1,1,1,1,2,2,2,2,2,2,2,2,2,2,2,2,2,2,2,2,2,1,1,1,1,1,1,1
1,1,1,1,1,1,1,1,20,2,2,2,2,2,2,2,2,2,2,2,2,2,20,1,1,1,1,1,1,1,1
1,1,1,1,1,1,1,1,1,1,20,2,2,2,2,2,2,2,2,2,20,1,1,1,1,1,1,1,1,1,1
1,1,1,1,1,1,1,1,1,1,1,1,1,1,1,1,1,1,1,1,1,1,1,1,1,1,1,1,1,1,1
endlayer

layer
1,1,1,1,1,1,1,1,1,1,1,1,1,1,1,1,1,1,1,1,1,1,1,1,1,1,1,1,1,1,1
1,1,1,1,1,1,1,1,1,1,1,20,20,20,20,20,20,20,20,20,1,1,1,1,1,1,1,1,1,1,1
1,1,1,1,1,1,1,1,1,20,2,2,2,2,2,2,2,2,2,2,2,20,1,1,1,1,1,1,1,1,1
1,1,1,1,1,1,1,20,2,2,2,2,2,2,2,2,2,2,2,2,2,2,2,20,1,1,1,1,1,1,1
1,1,1,1,1,1,2,2,2,2,2,2,2,2,2,2,2,2,2,2,2,2,2,2,2,1,1,1,1,1,1
1,1,1,1,1,2,2,2,2,2,2,2,2,2,2,2,2,2,2,2,2,2,2,2,2,2,1,1,1,1,1
1,1,1,1,2,2,2,2,2,2,2,2,2,2,2,2,2,2,2,2,2,2,2,2,2,2,2,1,1,1,1
1,1,1,20,2,2,2,2,2,17,17,17,17,17,17,17,2,2,2,2,2,2,2,2,2,2,2,20,1,1,1
1,1,1,2,2,2,2,2,17,0,0,0,0,0,0,0,17,2,2,2,2,2,2,2,2,2,2,2,1,1,1
1,1,20,2,2,2,2,2,17,0,0,0,0,0,0,0,17,2,2,2,2,2,2,2,2,2,2,2,20,1,1
1,1,2,2,2,2,2,2,17,0,0,0,0,0,0,0,17,17,17,17,2,2,2,2,2,2,2,2,2,1,1
1,20,2,2,2,2,2,2,17,0,0,0,0,0,0,0,17,0,0,0,17,2,2,2,2,2,2,2,2,20,1
1,20,2,2,2,2,2,2,17,0,0,0,0,0,0,0,17,17,17,0,17,2,2,2,2,2,2,2,2,20,1
1,20,2,2,2,2,2,2,17,0,0,0,0,0,0,0,17,2,17,0,17,2,2,2,2,2,2,2,2,20,1
1,20,2,2,2,2,2,2,17,0,0,0,0,0,0,0,17,2,17,0,17,2,2,2,2,2,2,2,2,20,1
1,20,2,2,2,2,2,2,17,0,0,0,0,0,0,0,17,2,17,5,17,2,2,2,2,2,2,2,2,20,1
1,20,2,2,2,2,2,2,2,17,17,17,0,17,17,17,2,2,2,11,2,2,2,2,2,2,2,2,2,20,1
1,20,2,2,2,2,2,2,2,2,2,11,0,11,2,2,2,2,2,11,2,2,2,2,2,2,2,2,2,20,1
1,20,2,2,2,2,2,2,2,2,2,11,0,11,2,2,2,2,11,11,2,2,2,2,2,2,2,2,2,20,1
1,20,2,2,2,2,2,2,2,2,2,11,0,11,2,2,2,2,2,2,2,2,2,2,2,2,2,2,2,20,1
1,1,2,2,2,2,2,2,2,2,2,11,8,11,2,2,2,2,2,2,2,2,2,2,2,2,2,2,2,1,1
1,1,20,2,2,2,2,2,2,2,2,2,11,2,2,2,2,2,2,2,2,2,2,2,2,2,2,2,20,1,1
1,1,1,2,2,2,2,2,2,2,2,2,2,2,2,2,2,2,2,2,2,2,2,2,2,2,2,2,1,1,1
1,1,1,20,2,2,2,2,2,2,2,2,2,2,2,2,2,2,2,2,2,2,2,2,2,2,2,20,1,1,1
1,1,1,1,2,2,2,2,2,2,2,2,2,2,2,2,2,2,2,2,2,2,2,2,2,2,2,1,1,1,1
1,1,1,1,1,20,2,2,2,2,2,2,2,2,2,2,2,2,2,2,2,2,2,2,2,2,1,1,1,1,1
1,1,1,1,1,1,2,2,2,2,2,2,2,2,2,2,2,2,2,2,2,2,2,2,2,1,1,1,1,1,1
1,1,1,1,1,1,1,20,2,2,2,2,2,2,2,2,2,2,2,2,2,2,2,20,1,1,1,1,1,1,1
1,1,1,1,1,1,1,1,1,20,2,2,2,2,2,2,2,2,2,2,2,20,1,1,1,1,1,1,1,1,1
1,1,1,1,1,1,1,1,1,1,1,20,20,20,20,20,20,20,20,20,1,1,1,1,1,1,1,1,1,1,1
1,1,1,1,1,1,1,1,1,1,1,1,1,1,1,1,1,1,1,1,1,1,1,1,1,1,1,1,1,1,1
endlayer

layer
1,1,1,1,1,1,1,1,1,1,1,1,1,1,1,1,1,1,1,1,1,1,1,1,1,1,1,1,1,1,1
1,1,1,1,1,1,1,1,1,1,1,1,1,1,1,1,1,1,1,1,1,1,1,1,1,1,1,1,1,1,1
1,1,1,1,1,1,1,1,1,1,20,20,20,20,20,20,20,20,13,13,13,1,1,1,1,1,1,1,1,1,1
1,1,1,1,1,1,1,1,20,20,20,26,26,26,26,26,26,26,26,26,13,13,13,1,1,1,1,1,1,1,1
1,1,1,1,1,1,20,20,20,26,26,26,26,26,26,26,26,26,26,26,26,26,13,13,20,1,1,1,1,1,1
1,1,1,1,1,20,20,26,26,26,26,26,2,2,2,2,2,2,2,26,26,26,26,26,20,20,1,1,1,1,1
1,1,1,1,20,20,26,26,26,2,2,2,2,2,2,2,2,2,2,2,2,26,26,26,26,20,20,1,1,1,1
1,1,1,1,20,26,26,26,2,2,2,2,2,2,2,2,2,2,2,2,2,2,2,26,26,26,20,1,1,1,1
1,1,1,13,13,26,26,2,2,11,11,11,11,11,11,11,2,2,2,2,2,2,2,2,26,26,20,20,1,1,1
1,1,1,13,26,26,26,2,2,11,11,11,11,11,11,11,2,2,2,2,2,2,2,2,26,26,26,20,1,1,1
1,1,13,13,26,26,2,2,2,11,11,11,11,11,11,11,2,2,2,2,2,2,2,2,2,26,26,20,20,1,1
1,1,13,26,26,26,2,2,2,11,11,11,11,11,11,11,2,11,11,11,2,2,2,2,2,26,26,26,20,1,1
1,1,13,26,26,2,2,2,2,11,11,11,11,11,11,11,2,2,2,11,2,2,2,2,2,2,26,26,20,1,1
1,1,20,26,26,2,2,2,2,11,11,11,11,11,11,11,2,2,2,11,2,2,2,2,2,2,26,26,20,1,1
1,1,20,26,26,2,2,2,2,11,11,11,11,11,11,11,2,2,2,11,2,2,2,2,2,2,26,26,20,1,1
1,1,20,26,26,2,2,2,2,11,11,11,11,11,11,11,2,2,2,2,2,2,2,2,2,2,26,26,20,1,1
1,1,20,26,26,2,2,2,2,2,2,2,11,2,2,2,2,2,2,2,2,2,2,2,2,2,26,26,20,1,1
1,1,20,26,26,2,2,2,2,2,2,11,4,11,2,2,2,2,2,2,2,2,2,2,2,2,26,26,20,1,1
1,1,20,26,26,2,2,2,2,2,2,11,0,11,2,2,2,2,2,2,2,2,2,2,2,2,26,26,20,1,1
1,1,20,26,26,26,2,2,2,2,2,11,0,11,2,2,2,2,2,2,2,2,2,2,2,26,26,26,20,1,1
1,1,20,20,26,26,2,2,2,2,2,11,0,11,2,2,2,2,2,2,2,2,2,2,2,26,26,20,20,1,1
1,1,1,20,26,26,26,2,2,2,2,11,8,11,2,2,2,2,2,2,2,2,2,2,26,26,26,20,1,1,1
1,1,1,20,20,26,26,2,2,2,2,2,2,2,2,2,2,2,2,2,2,2,2,2,26,26,20,20,1,1,1
1,1,1,1,20,26,26,26,2,2,2,2,2,2,2,2,2,2,2,2,2,2,2,26,26,26,20,1,1,1,1
1,1,1,1,20,20,26,26,26,26,2,2,2,2,2,2,2,2,2,2,2,26,26,26,26,20,20,1,1,1,1
1,1,1,1,1,1,20,26,26,26,26,26,2,2,2,2,2,2,2,26,26,26,26,26,20,20,1,1,1,1,1
1,1,1,1,1,1,20,20,20,26,26,26,26,26,26,26,26,26,26,26,26,26,20,20,20,1,1,1,1,1,1
1,1,1,1,1,1,1,1,20,20,20,26,26,26,26,26,26,26,26,26,20,20,20,1,1,1,1,1,1,1,1
1,1,1,1,1,1,1,1,1,1,20,20,20,20,20,20,20,20,20,20,20,1,1,1,1,1,1,1,1,1,1
1,1,1,1,1,1,1,1,1,1,1,1,1,1,1,1,1,1,1,1,1,1,1,1,1,1,1,1,1,1,1
1,1,1,1,1,1,1,1,1,1,1,1,1,1,1,1,1,1,1,1,1,1,1,1,1,1,1,1,1,1,1
endlayer

layer
1,1,1,1,1,1,1,1,1,1,1,1,1,1,1,1,1,1,1,1,1,1,1,1,1,1,1,1,1,1,1
1,1,1,1,1,1,1,1,1,1,1,1,1,1,1,1,1,1,1,1,1,1,1,1,1,1,1,1,1,1,1
1,1,1,1,1,1,1,1,1,1,1,1,1,1,1,1,1,1,1,14,0,1,1,1,1,1,1,1,1,1,1
1,1,1,1,1,1,1,1,1,1,1,20,20,20,20,20,13,13,13,13,14,0,1,1,1,1,1,1,1,1,1
1,1,1,1,1,1,1,1,1,20,20,20,20,20,13,13,13,13,13,13,13,13,14,0,1,1,1,1,1,1,1
1,1,1,1,1,1,1,20,20,20,13,13,2,2,2,2,2,2,2,13,13,13,13,13,1,1,1,1,1,1,1
1,1,1,1,1,1,20,13,13,2,2,2,2,2,2,2,2,2,2,2,2,13,13,13,13,1,1,1,1,1,1
1,1,1,1,1,13,13,13,2,2,2,2,2,2,2,2,2,2,2,2,2,2,2,13,20,20,1,1,1,1,1
1,1,27,27,27,13,13,2,2,2,2,2,2,2,2,2,2,2,2,2,2,2,2,2,20,20,1,1,1,1,1
1,27,27,27,28,13,13,2,2,2,2,2,2,2,2,2,2,2,2,2,2,2,2,2,20,20,20,1,1,1,1
1,27,27,27,13,13,2,2,2,2,2,2,2,2,2,2,2,2,2,2,2,2,2,2,2,20,20,1,1,1,1
1,1,27,13,13,13,2,2,2,2,2,2,2,2,2,2,2,2,2,2,2,2,2,2,2,20,20,20,1,1,1
1,1,1,13,13,2,2,2,2,2,2,2,2,2,2,2,2,2,2,2,2,2,2,2,2,2,20,20,1,1,1
1,1,1,13,13,2,2,2,2,2,2,2,2,2,2,2,2,2,2,2,2,2,2,2,2,2,20,20,1,1,1
1,1,1,13,13,2,2,2,2,2,2,2,2,2,2,2,2,2,2,2,2,2,2,2,2,2,20,20,1,1,1
1,1,1,13,13,2,2,2,2,2,2,2,2,2,2,2,2,2,2,2,2,2,2,2,2,2,20,20,1,1,1
1,1,1,20,13,2,2,2,2,2,2,2,2,2,2,2,2,2,2,2,2,2,2,2,2,2,20,20,1,1,1
1,1,1,20,13,2,2,2,2,2,2,2,2,2,2,2,2,2,2,2,2,2,2,2,2,2,20,20,1,1,1
1,1,1,20,13,2,2,2,2,2,2,11,4,11,2,2,2,2,2,2,2,2,2,2,2,2,20,20,1,1,1
1,1,1,20,20,13,2,2,2,2,2,11,0,11,2,2,2,2,2,2,2,2,2,2,2,20,20,20,1,1,1
1,27,27,27,20,20,2,2,2,2,2,11,0,11,2,2,2,2,2,2,2,2,2,2,2,20,20,1,1,1,1
27,27,27,27,20,20,13,2,2,2,2,11,0,11,2,2,2,2,2,2,2,2,2,2,20,20,20,1,1,1,1
27,27,27,28,27,20,13,2,2,2,2,11,8,11,2,2,2,2,2,2,2,2,2,2,20,20,1,1,1,1,1
27,29,29,29,27,20,20,13,2,2,2,2,2,2,2,2,2,2,2,2,2,2,2,20,20,20,1,1,1,1,1
1,29,29,29,29,29,20,13,12,20,2,2,2,2,2,2,2,2,2,2,2,20,20,20,20,1,1,1,1,1,1
1,1,29,29,29,1,1,20,13,13,20,20,2,2,2,2,2,2,2,20,20,20,20,20,1,1,1,1,1,1,1
1,1,1,1,1,1,1,1,1,13,13,13,20,20,20,20,20,20,20,20,20,20,1,1,1,1,1,1,1,1,1
1,1,1,1,1,1,1,1,1,1,1,13,13,13,13,20,20,20,20,20,1,1,1,1,1,1,1,1,1,1,1
1,1,1,1,1,1,1,1,1,1,1,1,1,29,29,29,29,27,27,1,1,1,1,1,1,1,1,1,1,1,1
1,1,1,1,1,1,1,1,1,1,1,1,1,29,29,29,27,27,27,1,1,1,1,1,1,1,1,1,1,1,1
1,1,1,1,1,1,1,1,1,1,1,1,1,1,29,29,27,27,1,1,1,1,1,1,1,1,1,1,1,1,1
endlayer

layer
1,1,1,1,1,1,1,1,1,1,1,1,1,1,1,1,1,1,1,1,1,1,1,1,1,1,1,1,1,1,1
1,1,1,1,1,1,1,1,1,1,1,1,1,1,1,1,1,1,1,1,1,1,1,1,1,1,1,1,1,1,1
1,1,1,1,1,1,1,1,1,1,0,0,0,0,0,0,0,0,0,0,0,1,1,1,1,1,1,1,1,1,1
1,1,1,1,1,1,1,1,0,0,0,0,0,0,0,0,0,0,14,0,0,0,0,1,1,1,1,1,1,1,1
1,1,1,1,1,1,0,0,0,0,0,0,0,0,0,0,14,0,0,0,0,0,0,0,0,1,1,1,1,1,1
1,1,1,1,1,0,0,0,0,0,0,0,13,13,13,13,13,13,13,0,0,14,0,0,0,0,1,1,1,1,1
1,1,1,1,0,0,0,0,0,13,13,13,13,13,13,13,13,13,13,13,13,0,0,0,0,0,1,1,1,1,1
1,1,1,1,0,0,0,0,13,13,13,13,13,12,12,12,13,13,13,13,13,13,28,0,0,0,1,1,1,1,1
1,1,0,0,0,0,0,13,13,13,13,12,12,12,12,2,2,2,12,13,13,13,13,13,0,0,1,1,1,1,1
1,0,27,27,28,0,0,13,13,13,12,12,2,2,2,2,2,2,2,2,13,13,13,13,0,0,1,1,1,1,1
1,0,27,27,0,0,13,13,13,13,2,2,2,2,2,2,2,2,2,2,2,13,13,13,13,0,1,1,1,1,1
1,1,0,0,0,14,13,13,13,13,2,2,2,2,2,2,2,2,2,2,2,2,13,13,13,0,1,1,1,1,1
1,1,0,0,0,13,13,13,13,2,2,2,2,2,2,2,2,2,2,2,2,2,2,13,13,13,1,1,1,1,1
1,1,0,0,0,13,13,13,13,2,2,2,2,2,2,2,2,2,2,2,2,2,2,13,13,13,1,1,1,1,1
1,1,0,0,14,13,13,13,2,2,2,2,2,2,2,2,2,2,2,2,2,2,2,2,13,13,1,1,1,1,1
1,1,0,0,0,13,13,13,2,2,2,2,2,2,2,2,2,2,2,2,2,2,2,2,13,13,1,1,1,1,1
1,1,0,0,0,13,13,13,2,2,2,2,2,2,2,2,2,2,2,2,2,2,2,13,13,13,1,1,1,1,1
1,1,0,0,0,13,13,13,12,2,2,2,2,2,2,2,2,2,2,2,2,2,2,13,13,12,1,1,1,1,1
1,1,0,0,0,13,13,12,12,2,2,2,2,2,2,2,2,2,2,2,2,2,13,13,13,13,1,1,1,1,1
1,1,0,0,27,27,13,12,12,12,2,11,4,11,2,2,2,2,2,2,2,2,13,13,13,1,1,1,1,1,1
1,1,0,27,29,29,13,12,12,12,12,11,0,11,2,2,2,2,2,2,2,13,13,13,13,1,1,1,1,1,1
1,1,27,27,29,29,29,17,12,12,12,11,0,11,2,2,2,2,2,12,12,13,13,13,1,1,1,1,1,1,1
1,27,27,27,29,29,29,13,17,12,12,11,0,11,2,2,12,12,17,13,13,13,13,13,1,1,1,1,1,1,1
1,29,29,29,27,27,1,29,17,12,12,11,8,11,12,12,12,12,17,13,13,13,13,1,1,1,1,1,1,1,1
1,1,0,29,27,0,1,27,28,17,12,12,12,12,12,12,12,17,13,13,13,1,1,1,1,1,1,1,1,1,1
1,1,0,0,0,1,1,1,27,27,17,17,12,12,12,17,17,13,13,1,1,1,1,1,1,1,1,1,1,1,1
1,1,1,1,1,1,1,1,0,27,27,14,17,17,17,28,29,27,27,1,1,1,1,1,1,1,1,1,1,1,1
1,1,1,1,1,1,1,1,1,1,1,0,27,14,29,29,29,27,1,1,1,1,1,1,1,1,1,1,1,1,1
1,1,1,1,1,1,1,1,1,1,1,1,1,0,29,29,29,27,1,1,1,1,1,1,1,1,1,1,1,1,1
1,1,1,1,1,1,1,1,1,1,1,1,1,1,1,29,27,1,1,1,1,1,1,1,1,1,1,1,1,1,1
1,1,1,1,1,1,1,1,1,1,1,1,1,1,1,1,1,1,1,1,1,1,1,1,1,1,1,1,1,1,1
endlayer

layer
0,0,0,0,0,0,0,0,0,0,0,0,0,0,0,0,0,0,0,0,0,0,0,0,0,0,0,0,0,0,0
0,0,0,0,0,0,0,0,0,0,0,0,0,0,0,0,0,0,0,0,0,0,0,0,0,0,0,0,0,0,0
0,0,0,0,0,0,0,0,0,0,0,0,0,0,0,0,0,0,0,0,0,0,0,0,0,0,0,0,0,0,0
0,0,0,0,0,0,0,0,0,0,0,0,0,0,0,0,0,0,0,0,0,0,0,0,0,0,0,0,0,0,0
0,0,0,0,0,0,0,0,0,0,0,0,0,0,0,0,0,0,0,0,0,0,0,0,0,0,0,0,0,0,0
0,0,0,0,0,0,0,0,0,0,0,0,0,0,14,0,0,14,0,0,0,0,0,0,0,0,0,0,0,0,0
0,0,0,0,0,0,0,0,0,0,0,14,0,0,14,0,0,0,14,0,0,0,0,0,0,0,0,0,0,0,0
0,0,0,0,0,0,0,0,0,0,0,0,14,13,13,13,14,0,14,14,0,14,28,0,0,0,0,0,0,0,0
0,0,0,0,0,0,0,0,14,0,0,13,13,13,13,13,13,13,13,0,0,0,0,0,0,0,0,0,0,0,0
0,0,0,0,28,0,0,0,0,0,13,13,13,13,13,13,13,13,13,13,14,0,14,0,0,0,0,0,0,0,0
0,0,0,0,0,0,0,0,0,14,17,17,17,11,17,17,17,13,13,13,13,14,0,0,14,0,0,0,0,0,0
0,0,0,0,0,0,0,14,14,27,17,11,11,11,11,11,17,13,13,13,13,13,0,0,0,0,0,0,0,0,0
0,0,0,0,0,0,0,0,29,28,17,11,11,11,11,11,17,13,13,13,13,13,13,0,14,0,0,0,0,0,0
0,0,0,0,0,0,0,0,27,13,17,11,11,11,11,11,17,13,13,13,13,13,13,14,0,14,0,0,0,0,0
0,0,0,0,0,0,14,0,13,13,17,11,11,11,11,11,17,13,13,13,13,13,13,13,0,14,0,0,0,0,0
0,0,0,0,0,0,14,0,13,13,17,11,11,11,11,11,17,13,13,13,13,13,13,13,14,0,0,0,0,0,0
0,0,0,0,0,0,14,14,13,17,11,11,11,11,11,11,11,17,13,13,13,13,13,0,14,0,0,0,0,0,0
0,0,0,0,0,0,0,29,17,11,11,11,11,11,11,11,11,11,17,13,13,13,13,0,0,28,0,0,0,0,0
0,0,0,0,0,0,27,28,17,11,11,11,11,11,11,11,11,11,17,13,13,13,0,0,14,0,0,0,0,0,0
0,0,0,0,0,0,29,17,11,11,11,11,11,11,11,11,11,11,11,17,13,13,14,0,0,0,0,0,0,0,0
0,0,0,0,0,0,29,17,11,11,11,11,4,11,11,11,11,11,11,17,13,0,14,0,0,0,0,0,0,0,0
0,0,0,27,29,0,0,17,11,11,11,11,0,11,11,11,11,11,11,17,28,27,27,0,0,0,0,0,0,0,0
0,0,0,27,29,0,0,14,17,11,11,11,0,11,11,11,11,11,17,29,27,0,0,14,0,0,0,0,0,0,0
0,0,0,0,0,0,0,29,17,11,11,11,0,11,11,11,11,11,17,29,27,14,0,0,0,0,0,0,0,0,0
0,0,0,0,0,0,0,0,29,17,11,11,11,11,11,11,11,17,14,0,27,0,0,0,0,0,0,0,0,0,0
0,0,0,0,0,0,0,0,27,27,17,17,11,11,11,17,17,27,0,0,0,0,0,0,0,0,0,0,0,0,0
0,0,0,0,0,0,0,0,0,0,27,0,17,17,17,29,29,27,0,0,0,0,0,0,0,0,0,0,0,0,0
0,0,0,0,0,0,0,0,0,0,0,0,0,0,0,29,0,0,0,0,0,0,0,0,0,0,0,0,0,0,0
0,0,0,0,0,0,0,0,0,0,0,0,0,0,0,0,0,0,0,0,0,0,0,0,0,0,0,0,0,0,0
0,0,0,0,0,0,0,0,0,0,0,0,0,0,0,0,0,0,0,0,0,0,0,0,0,0,0,0,0,0,0
0,0,0,0,0,0,0,0,0,0,0,0,0,0,0,0,0,0,0,0,0,0,0,0,0,0,0,0,0,0,0
endlayer

layer
0,0,0,0,0,0,0,0,0,0,0,0,0,0,0,0,0,0,0,0,0,0,0,0,0,0,0,0,0,0,0
0,0,0,0,0,0,0,0,0,0,0,0,0,0,0,0,0,0,0,0,0,0,0,0,0,0,0,0,0,0,0
0,0,0,0,0,0,0,0,0,0,0,0,0,0,0,0,0,0,0,0,0,0,0,0,0,0,0,0,0,0,0
0,0,0,0,0,0,0,0,0,0,0,0,0,0,0,0,0,0,0,0,0,0,0,0,0,0,0,0,0,0,0
0,0,0,0,0,0,0,0,0,0,0,0,0,0,0,0,0,0,0,0,0,0,0,0,0,0,0,0,0,0,0
0,0,0,0,0,0,0,0,0,0,0,0,0,0,0,0,0,0,0,0,0,0,0,0,0,0,0,0,0,0,0
0,0,0,0,0,0,0,0,0,0,0,0,0,0,0,0,0,0,0,0,0,0,0,0,0,0,0,0,0,0,0
0,0,0,0,0,0,0,0,0,0,0,0,0,0,0,0,0,0,0,0,0,0,28,0,0,0,0,0,0,0,0
0,0,0,0,0,0,0,0,0,0,0,0,0,14,0,0,0,0,0,0,0,0,0,0,0,0,0,0,0,0,0
0,0,0,0,28,0,0,0,0,0,14,0,14,0,0,0,0,14,14,0,0,0,0,0,0,0,0,0,0,0,0
0,0,0,0,0,0,0,0,0,0,17,17,17,17,17,17,17,0,0,0,0,0,0,0,0,0,0,0,0,0,0
0,0,0,0,0,0,0,0,0,0,17,0,0,30,0,0,17,14,0,0,0,0,0,0,0,0,0,0,0,0,0
0,0,0,0,0,0,0,0,0,29,17,31,0,0,0,21,17,0,14,14,0,0,0,0,0,0,0,0,0,0,0
0,0,0,0,0,0,0,0,0,27,17,32,0,0,0,0,17,0,0,0,0,0,0,0,0,0,0,0,0,0,0
0,0,0,0,0,0,0,0,0,27,17,34,0,0,0,0,33,0,0,0,0,0,14,0,0,0,0,0,0,0,0
0,0,0,0,0,0,0,0,0,14,17,0,0,0,21,0,17,0,0,14,0,0,14,0,0,0,0,0,0,0,0
0,0,0,0,0,0,0,0,29,17,17,17,35,17,17,17,17,17,0,0,0,0,14,0,0,0,0,0,0,0,0
0,0,0,0,0,0,0,0,17,17,11,0,0,0,0,0,11,17,17,0,14,0,0,0,0,28,0,0,0,0,0
0,0,0,0,0,0,0,29,17,17,0,0,0,0,0,0,0,17,17,0,0,0,0,0,0,0,0,0,0,0,0
0,0,0,0,0,0,0,17,17,17,0,0,0,0,0,0,0,17,17,17,27,0,0,0,0,0,0,0,0,0,0
0,0,0,0,0,0,29,17,17,17,0,0,8,17,0,0,0,17,17,17,29,0,0,0,0,0,0,0,0,0,0
0,0,0,0,0,0,0,17,17,17,0,0,4,17,0,0,36,17,17,17,29,27,0,0,0,0,0,0,0,0,0
0,0,0,0,0,0,0,0,17,17,0,0,0,17,0,0,37,17,17,29,27,0,0,0,0,0,0,0,0,0,0
0,0,0,0,0,0,0,0,17,17,11,0,0,17,38,38,11,17,17,29,0,0,0,0,0,0,0,0,0,0,0
0,0,0,0,0,0,0,0,27,17,17,17,17,17,17,17,17,17,0,0,0,0,0,0,0,0,0,0,0,0,0
0,0,0,0,0,0,0,0,0,27,17,17,17,17,17,17,17,0,0,0,0,0,0,0,0,0,0,0,0,0,0
0,0,0,0,0,0,0,0,0,0,0,0,17,17,17,0,29,0,0,0,0,0,0,0,0,0,0,0,0,0,0
0,0,0,0,0,0,0,0,0,0,0,0,0,0,0,0,0,0,0,0,0,0,0,0,0,0,0,0,0,0,0
0,0,0,0,0,0,0,0,0,0,0,0,0,0,0,0,0,0,0,0,0,0,0,0,0,0,0,0,0,0,0
0,0,0,0,0,0,0,0,0,0,0,0,0,0,0,0,0,0,0,0,0,0,0,0,0,0,0,0,0,0,0
0,0,0,0,0,0,0,0,0,0,0,0,0,0,0,0,0,0,0,0,0,0,0,0,0,0,0,0,0,0,0
endlayer

layer
0,0,0,0,0,0,0,0,0,0,0,0,0,0,0,0,0,0,0,0,0,0,0,0,0,0,0,0,0,0,0
0,0,0,0,0,0,0,0,0,0,0,0,0,0,0,0,0,0,0,0,0,0,0,0,0,0,0,0,0,0,0
0,0,0,0,0,0,0,0,0,0,0,0,0,0,0,0,0,0,0,0,0,0,0,0,0,0,0,0,0,0,0
0,0,0,0,0,0,0,0,0,0,0,0,0,0,0,0,0,0,0,0,0,0,0,0,0,0,0,0,0,0,0
0,0,0,0,0,0,0,0,0,0,0,0,0,0,0,0,0,0,0,0,0,0,0,0,0,0,0,0,0,0,0
0,0,0,0,0,0,0,0,0,0,0,0,0,0,0,0,0,0,0,0,0,0,0,0,0,0,0,0,0,0,0
0,0,0,0,0,0,0,0,0,0,0,0,0,0,0,0,0,0,0,0,0,0,0,0,0,0,0,0,0,0,0
0,0,0,0,0,0,0,0,0,0,0,0,0,0,0,0,0,0,0,0,0,0,28,0,0,0,0,0,0,0,0
0,0,0,0,0,0,0,0,0,0,0,0,0,0,0,0,0,0,0,0,0,0,0,0,0,0,0,0,0,0,0
0,0,0,0,28,0,0,0,0,0,0,0,0,0,0,0,0,0,0,0,0,0,0,0,0,0,0,0,0,0,0
0,0,0,0,0,0,0,0,0,0,17,17,39,17,39,17,17,0,0,0,0,0,0,0,0,0,0,0,0,0,0
0,0,0,0,0,0,0,0,0,0,17,0,0,40,0,0,17,0,0,0,0,0,0,0,0,0,0,0,0,0,0
0,0,0,0,0,0,0,0,0,0,39,0,0,0,0,0,39,0,0,0,0,0,0,0,0,0,0,0,0,0,0
0,0,0,0,0,0,0,0,0,27,17,41,0,0,0,0,17,0,0,0,0,0,0,0,0,0,0,0,0,0,0
0,0,0,0,0,0,0,0,0,0,39,0,0,0,0,0,42,0,0,0,0,0,0,0,0,0,0,0,0,0,0
0,0,0,0,0,0,0,0,0,0,17,0,0,0,0,0,17,0,0,0,0,0,0,0,0,0,0,0,0,0,0
0,0,0,0,0,0,0,0,0,43,17,17,42,17,17,17,17,43,0,0,0,0,0,0,0,0,0,0,0,0,0
0,0,0,0,0,0,0,0,43,17,11,0,0,0,0,0,11,17,43,0,0,0,0,0,0,28,0,0,0,0,0
0,0,0,0,0,0,0,0,43,17,0,0,0,0,0,0,0,17,43,0,0,0,0,0,0,0,0,0,0,0,0
0,0,0,0,0,0,0,43,17,17,0,0,0,0,0,0,0,17,17,43,0,0,0,0,0,0,0,0,0,0,0
0,0,0,0,0,0,0,43,17,17,0,0,0,17,0,0,0,17,17,43,27,0,0,0,0,0,0,0,0,0,0
0,0,0,0,0,0,0,43,17,17,0,0,8,17,0,0,0,17,17,43,0,0,0,0,0,0,0,0,0,0,0
0,0,0,0,0,0,0,0,43,17,0,0,0,17,0,0,0,17,43,27,27,0,0,0,0,0,0,0,0,0,0
0,0,0,0,0,0,0,0,43,17,11,0,0,17,0,0,11,17,43,0,0,0,0,0,0,0,0,0,0,0,0
0,0,0,0,0,0,0,0,0,43,17,17,17,17,17,17,17,43,0,0,0,0,0,0,0,0,0,0,0,0,0
0,0,0,0,0,0,0,0,0,0,43,43,17,17,17,43,43,0,0,0,0,0,0,0,0,0,0,0,0,0,0
0,0,0,0,0,0,0,0,0,0,0,0,43,43,43,0,0,0,0,0,0,0,0,0,0,0,0,0,0,0,0
0,0,0,0,0,0,0,0,0,0,0,0,0,0,0,0,0,0,0,0,0,0,0,0,0,0,0,0,0,0,0
0,0,0,0,0,0,0,0,0,0,0,0,0,0,0,0,0,0,0,0,0,0,0,0,0,0,0,0,0,0,0
0,0,0,0,0,0,0,0,0,0,0,0,0,0,0,0,0,0,0,0,0,0,0,0,0,0,0,0,0,0,0
0,0,0,0,0,0,0,0,0,0,0,0,0,0,0,0,0,0,0,0,0,0,0,0,0,0,0,0,0,0,0
endlayer

layer
0,0,0,0,0,0,0,0,0,0,0,0,0,0,0,0,0,0,0,0,0,0,0,0,0,0,0,0,0,0,0
0,0,0,0,0,0,0,0,0,0,0,0,0,0,0,0,0,0,0,0,0,0,0,0,0,0,0,0,0,0,0
0,0,0,0,0,0,0,0,0,0,0,0,0,0,0,0,0,0,0,0,0,0,0,0,0,0,0,0,0,0,0
0,0,0,0,0,0,0,0,0,0,0,0,0,0,0,0,0,0,0,0,0,0,0,0,0,0,0,0,0,0,0
0,0,0,0,0,0,0,0,0,0,0,0,0,0,0,0,0,0,0,0,0,0,0,0,0,0,0,0,0,0,0
0,0,0,0,0,0,0,0,0,0,0,0,0,0,0,0,0,0,0,0,0,0,0,0,0,0,0,0,0,0,0
0,0,0,0,0,0,0,0,0,0,0,0,0,0,0,0,0,0,0,0,0,0,0,0,0,0,0,0,0,0,0
0,0,0,0,0,0,0,0,0,0,0,0,0,0,0,0,0,0,0,0,0,0,28,0,0,0,0,0,0,0,0
0,0,0,0,0,0,0,0,0,0,0,0,0,0,0,0,0,0,0,0,0,0,0,0,0,0,0,0,0,0,0
0,0,0,0,28,0,0,0,0,0,0,0,0,0,0,0,0,0,0,0,0,0,0,0,0,0,0,0,0,0,0
0,0,0,0,0,0,0,0,0,0,17,17,17,17,17,17,17,0,0,0,0,0,0,0,0,0,0,0,0,0,0
0,0,0,0,0,0,0,0,0,0,17,0,0,40,0,0,17,0,0,0,0,0,0,0,0,0,0,0,0,0,0
0,0,0,0,0,0,0,0,0,0,17,0,0,0,0,0,17,0,0,0,0,0,0,0,0,0,0,0,0,0,0
0,0,0,0,0,0,0,0,0,0,17,0,0,0,0,0,17,0,0,0,0,0,0,0,0,0,0,0,0,0,0
0,0,0,0,0,0,0,0,0,0,17,0,0,0,0,0,17,0,0,0,0,0,0,0,0,0,0,0,0,0,0
0,0,0,0,0,0,0,0,0,0,17,0,0,0,0,0,17,0,0,0,0,0,0,0,0,0,0,0,0,0,0
0,0,0,0,0,0,0,0,0,17,17,17,17,17,17,17,17,17,0,0,0,0,0,0,0,0,0,0,0,0,0
0,0,0,0,0,0,0,0,17,17,11,0,0,0,0,0,11,17,17,0,0,0,0,0,0,28,0,0,0,0,0
0,0,0,0,0,0,0,0,17,17,0,0,0,0,0,0,0,17,17,0,0,0,0,0,0,0,0,0,0,0,0
0,0,0,0,0,0,0,17,17,17,0,0,0,0,0,0,0,17,17,17,0,0,0,0,0,0,0,0,0,0,0
0,0,0,0,0,0,0,17,17,17,0,0,0,17,0,0,0,17,17,17,0,0,0,0,0,0,0,0,0,0,0
0,0,0,0,0,0,0,17,17,17,0,0,0,10,6,0,0,17,17,17,0,0,0,0,0,0,0,0,0,0,0
0,0,0,0,0,0,0,0,17,17,0,0,0,0,0,0,0,17,17,27,0,0,0,0,0,0,0,0,0,0,0
0,0,0,0,0,0,0,0,17,17,11,0,0,0,0,0,11,17,17,0,0,0,0,0,0,0,0,0,0,0,0
0,0,0,0,0,0,0,0,0,17,17,17,17,17,17,17,17,17,0,0,0,0,0,0,0,0,0,0,0,0,0
0,0,0,0,0,0,0,0,0,0,17,17,17,17,17,17,17,0,0,0,0,0,0,0,0,0,0,0,0,0,0
0,0,0,0,0,0,0,0,0,0,0,0,17,17,17,0,0,0,0,0,0,0,0,0,0,0,0,0,0,0,0
0,0,0,0,0,0,0,0,0,0,0,0,0,0,0,0,0,0,0,0,0,0,0,0,0,0,0,0,0,0,0
0,0,0,0,0,0,0,0,0,0,0,0,0,0,0,0,0,0,0,0,0,0,0,0,0,0,0,0,0,0,0
0,0,0,0,0,0,0,0,0,0,0,0,0,0,0,0,0,0,0,0,0,0,0,0,0,0,0,0,0,0,0
0,0,0,0,0,0,0,0,0,0,0,0,0,0,0,0,0,0,0,0,0,0,0,0,0,0,0,0,0,0,0
endlayer

layer
0,0,0,0,0,0,0,0,0,0,0,0,0,0,0,0,0,0,0,0,0,0,0,0,0,0,0,0,0,0,0
0,0,0,0,0,0,0,0,0,0,0,0,0,0,0,0,0,0,0,0,0,0,0,0,0,0,0,0,0,0,0
0,0,0,0,0,0,0,0,0,0,0,0,0,0,0,0,0,0,0,0,0,0,0,0,0,0,0,0,0,0,0
0,0,0,0,0,0,0,0,0,0,0,0,0,0,0,0,0,0,0,0,0,0,0,0,0,0,0,0,0,0,0
0,0,0,0,0,0,0,0,0,0,0,0,0,0,0,0,0,0,0,0,0,0,0,0,0,0,0,0,0,0,0
0,0,0,0,27,0,0,0,0,0,0,0,0,0,0,0,0,0,0,0,0,0,0,0,0,0,0,0,0,0,0
0,0,0,0,0,0,0,0,0,0,0,0,0,0,0,0,0,0,0,0,0,0,28,0,0,0,0,0,0,0,0
0,0,0,0,0,0,0,0,0,0,0,0,0,0,0,0,0,0,0,0,0,0,0,0,0,0,0,0,0,0,0
0,0,0,0,27,0,0,0,0,0,0,0,0,0,0,0,0,0,0,0,0,0,0,0,0,0,0,0,0,0,0
27,0,0,27,28,27,0,0,27,8,8,8,8,8,8,8,8,8,0,0,0,0,0,0,0,0,0,0,0,0,0
0,0,0,0,27,0,0,0,0,10,17,43,43,43,43,43,17,7,0,0,0,0,0,0,0,0,0,0,0,0,0
0,0,0,0,0,0,0,0,0,10,43,0,0,40,0,0,43,7,0,0,0,0,0,0,0,0,0,0,0,0,0
0,0,0,0,0,0,0,0,0,10,43,0,0,0,0,0,43,7,0,0,0,0,0,0,0,0,0,0,0,0,0
0,0,0,0,27,0,0,0,0,10,43,0,0,0,0,0,43,7,0,0,0,0,0,0,0,0,0,0,0,0,0
0,0,0,0,0,0,0,0,0,10,43,0,0,0,0,0,43,7,0,0,0,0,0,0,0,0,0,0,0,0,0
0,0,0,0,0,0,0,0,8,10,43,0,0,0,0,0,43,7,8,0,0,0,0,0,0,0,0,0,0,0,0
0,0,0,0,0,0,0,8,10,17,17,43,43,43,43,43,17,17,7,8,0,0,0,0,0,0,0,0,0,0,0
0,0,0,0,0,0,0,10,17,17,11,0,0,0,0,0,11,17,17,7,0,0,0,0,0,28,0,0,0,0,0
0,0,0,0,0,0,8,10,17,43,0,0,0,0,0,0,0,43,17,7,8,0,0,0,0,0,0,0,0,0,0
0,0,0,0,0,0,10,17,17,43,0,0,0,0,0,0,0,43,17,17,7,0,0,0,0,0,0,0,0,0,0
0,0,0,0,0,0,10,17,17,43,0,0,0,17,5,0,0,43,17,17,7,0,0,0,0,0,0,0,0,0,0
0,0,0,0,0,0,10,17,17,43,0,0,0,0,10,0,0,43,17,17,7,0,0,0,0,0,0,0,0,0,0
0,0,0,0,0,0,10,9,17,43,0,0,0,0,0,0,0,43,17,7,9,0,0,0,0,0,0,0,0,0,0
0,0,0,0,0,0,0,10,17,17,11,0,0,0,0,0,11,17,17,7,0,0,0,0,0,0,0,0,0,0,0
0,0,0,0,0,0,0,10,9,17,17,43,43,43,43,43,17,17,7,9,0,0,0,0,0,0,0,0,0,0,0
0,0,0,0,0,0,0,0,10,9,17,17,17,17,17,17,17,7,9,0,0,0,0,0,0,0,0,0,0,0,0
0,0,0,0,0,0,0,0,0,10,9,9,17,17,17,7,9,9,0,0,0,0,0,0,0,0,0,0,0,0,0
0,0,0,0,0,0,0,0,0,0,0,10,9,9,9,9,0,0,0,0,0,0,0,0,0,0,0,0,0,0,0
0,0,0,0,0,0,0,0,0,0,0,0,0,0,0,0,0,0,0,0,0,0,0,0,0,0,0,0,0,0,0
0,0,0,0,0,0,0,0,0,0,0,0,0,0,0,0,0,0,0,0,0,0,0,0,0,0,0,0,0,0,0
0,0,0,0,0,0,0,0,0,0,0,0,0,0,0,0,0,0,0,0,0,0,0,0,0,0,0,0,0,0,0
endlayer

layer
0,0,0,0,0,0,0,0,0,0,0,0,0,0,0,0,0,0,0,0,0,0,0,0,0,0,0,0,0,0,0
0,0,0,0,0,0,0,0,0,0,0,0,0,0,0,0,0,0,0,0,0,0,0,0,0,0,0,0,0,0,0
0,0,0,0,0,0,0,0,0,0,0,0,0,0,0,0,0,0,0,0,0,0,0,0,0,0,0,0,0,0,0
0,0,0,0,0,0,0,0,0,0,0,0,0,0,0,0,0,0,0,0,0,0,0,0,0,0,0,0,0,0,0
0,0,0,0,0,0,0,0,0,0,0,0,0,0,0,0,0,0,0,0,0,0,0,0,0,0,0,0,0,0,0
0,0,0,0,27,0,0,0,0,0,0,0,0,0,0,0,0,0,0,0,0,0,0,0,0,0,0,0,0,0,0
0,0,0,0,29,0,0,0,0,0,0,0,0,0,0,0,0,0,0,0,0,0,28,0,0,0,0,0,0,0,0
0,0,0,0,29,0,0,0,0,0,0,0,0,0,0,0,0,0,0,0,0,0,0,0,0,0,0,0,0,0,0
0,0,0,29,29,29,0,0,0,0,0,0,0,0,0,0,0,0,0,0,0,0,0,0,0,0,0,0,0,0,0
27,27,27,27,28,27,27,27,27,0,0,0,0,0,0,0,0,0,0,0,0,0,0,0,0,0,0,0,0,0,0
0,0,0,27,27,27,0,0,0,0,8,8,8,8,8,8,7,0,0,0,0,0,0,0,0,0,0,0,0,0,0
0,0,0,0,27,0,0,0,0,0,10,11,11,11,11,11,7,0,0,0,0,0,0,0,0,0,0,0,0,0,0
0,0,0,0,27,0,0,0,0,0,10,11,11,11,11,11,7,0,0,0,0,0,0,0,0,0,0,0,0,0,0
0,0,0,0,27,0,0,0,0,0,10,11,11,18,11,11,7,0,0,0,0,0,0,0,0,0,0,0,0,0,0
0,0,0,0,0,0,0,0,0,0,10,11,11,11,11,11,7,0,0,0,0,0,0,0,0,0,0,0,0,0,0
0,0,0,0,0,0,0,0,0,0,17,11,11,11,11,11,17,0,0,0,0,0,0,0,0,0,0,0,0,0,0
0,0,0,0,0,0,0,0,0,17,11,11,11,11,11,11,11,17,0,0,0,0,0,0,0,0,0,0,0,0,0
0,0,0,0,0,0,0,0,43,17,11,11,11,11,11,11,11,17,17,0,0,0,0,0,0,28,0,0,0,0,0
0,0,0,0,0,0,0,0,43,17,11,0,0,0,0,0,11,17,17,0,0,0,0,0,0,0,0,0,0,0,0
0,0,0,0,0,0,0,17,17,17,11,0,0,0,5,0,11,17,17,17,0,0,0,0,0,0,0,0,0,0,0
0,0,0,0,0,0,0,17,17,17,11,0,0,17,9,0,11,17,17,17,0,0,0,0,0,0,0,0,0,0,0
0,0,0,0,0,0,0,17,17,17,11,0,0,0,0,0,11,17,17,17,0,0,0,0,0,0,0,0,0,0,0
0,0,0,0,0,0,0,0,17,17,11,0,0,0,0,0,11,17,43,0,0,0,0,0,0,0,0,0,0,0,0
0,0,0,0,0,0,0,0,17,17,11,11,11,11,11,11,11,17,43,0,0,0,0,0,0,0,0,0,0,0,0
0,0,0,0,0,0,0,0,0,17,17,17,17,17,17,17,17,17,0,0,0,0,0,0,0,0,0,0,0,0,0
0,0,0,0,0,0,0,0,0,0,43,43,17,17,17,17,17,0,0,0,0,0,0,0,0,0,0,0,0,0,0
0,0,0,0,0,0,0,0,0,0,0,0,17,17,17,0,0,0,0,0,0,0,0,0,0,0,0,0,0,0,0
0,0,0,0,0,0,0,0,0,0,0,0,0,0,0,0,0,0,0,0,0,0,0,0,0,0,0,0,0,0,0
0,0,0,0,0,0,0,0,0,0,0,0,0,0,0,0,0,0,0,0,0,0,0,0,0,0,0,0,0,0,0
0,0,0,0,0,0,0,0,0,0,0,0,0,0,0,0,0,0,0,0,0,0,0,0,0,0,0,0,0,0,0
0,0,0,0,0,0,0,0,0,0,0,0,0,0,0,0,0,0,0,0,0,0,0,0,0,0,0,0,0,0,0
endlayer

layer
0,0,0,0,0,0,0,0,0,0,0,0,0,0,0,0,0,0,0,0,0,0,0,0,0,0,0,0,0,0,0
0,0,0,0,0,0,0,0,0,0,0,0,0,0,0,0,0,0,0,0,0,0,0,0,0,0,0,0,0,0,0
0,0,0,0,0,0,0,0,0,0,0,0,0,0,0,0,0,0,0,0,0,0,27,0,0,0,0,0,0,0,0
0,0,0,0,0,0,0,0,0,0,0,0,0,0,0,0,0,0,0,0,0,0,0,0,0,0,0,0,0,0,0
0,0,0,0,0,0,0,0,0,0,0,0,0,0,0,0,0,0,0,0,0,0,0,0,0,0,0,0,0,0,0
0,0,0,0,0,0,0,0,0,0,0,0,0,0,0,0,0,0,0,0,0,0,27,0,0,0,0,0,0,0,0
0,27,0,0,0,0,27,27,0,0,0,0,0,0,0,0,0,0,27,0,0,27,28,27,0,0,27,0,0,0,0
0,27,27,0,0,27,27,0,0,0,0,0,0,0,0,0,0,0,0,0,0,0,27,0,0,0,0,0,0,0,0
0,0,27,29,29,29,0,0,0,0,0,0,0,0,0,0,0,0,0,0,0,0,0,0,0,0,0,0,0,0,0
0,0,0,27,27,27,0,0,0,0,0,0,0,0,0,0,0,0,0,0,0,0,0,0,0,0,0,0,0,0,0
0,0,0,27,27,27,27,0,0,0,0,0,0,0,0,0,0,0,0,0,0,0,27,0,0,0,0,0,0,0,0
0,0,27,27,0,0,27,27,0,0,0,8,8,40,8,7,0,0,0,0,0,0,0,0,0,0,0,0,0,0,0
0,27,27,0,0,0,0,27,0,0,0,10,11,11,11,7,0,0,0,0,0,0,0,0,0,0,0,0,0,0,0
0,0,0,0,0,0,0,0,0,0,0,10,11,11,11,7,0,0,0,0,0,0,0,0,0,0,0,0,0,0,0
0,0,0,0,0,0,0,0,0,0,0,10,17,17,17,7,0,0,0,0,0,0,0,0,0,0,0,0,0,0,0
0,0,0,0,0,0,0,0,0,0,17,17,17,17,17,17,17,0,0,0,0,0,0,0,0,0,0,0,0,0,0
0,0,0,0,0,0,0,0,0,17,17,17,17,17,17,17,17,17,0,0,0,0,0,0,0,0,0,0,0,0,0
0,0,0,0,0,0,0,0,17,17,17,17,17,17,17,17,17,17,17,0,0,0,0,0,0,0,28,0,0,0,0
0,0,0,0,0,0,0,0,43,17,17,17,17,17,17,17,17,17,17,0,0,0,0,0,0,0,0,0,0,0,0
0,0,0,0,0,0,0,43,17,17,17,17,0,3,9,17,17,17,17,17,0,0,0,0,0,0,0,0,0,0,0
0,0,0,0,0,0,0,17,17,17,17,17,0,17,0,17,17,17,17,17,0,0,0,0,0,0,0,0,0,0,0
0,0,0,0,0,0,0,17,17,17,17,17,0,0,0,17,17,17,17,43,0,0,0,0,0,0,0,0,0,0,0
0,0,0,0,0,0,0,0,17,17,17,17,17,17,17,17,17,17,43,0,0,0,0,0,0,0,0,0,0,0,0
0,0,0,0,0,0,0,0,17,17,17,17,17,17,17,17,17,17,17,0,0,0,0,0,0,0,0,0,0,0,0
0,0,0,0,0,0,0,0,0,17,17,17,17,17,17,17,17,17,0,0,0,0,0,0,0,0,0,0,0,0,0
0,0,0,0,0,0,0,0,0,0,17,43,17,17,17,17,17,0,0,0,0,0,0,0,0,0,0,0,0,0,0
0,0,0,0,0,0,0,0,0,0,0,0,43,17,17,0,0,0,0,0,0,0,0,0,0,0,0,0,0,0,0
0,0,0,0,0,0,0,0,0,0,0,0,0,0,0,0,0,0,0,0,0,0,0,0,0,0,0,0,0,0,0
0,0,0,0,0,0,0,0,0,0,0,0,0,0,0,0,0,0,0,0,0,0,0,0,0,0,0,0,0,0,0
0,0,0,0,0,0,0,0,0,0,0,0,0,0,0,0,0,0,0,0,0,0,0,0,0,0,0,0,0,0,0
0,0,0,0,0,0,0,0,0,0,0,0,0,0,0,0,0,0,0,0,0,0,0,0,0,0,0,0,0,0,0
endlayer

layer
0,0,0,0,0,0,0,0,0,0,0,0,0,0,0,0,0,0,0,0,0,0,0,0,0,0,0,0,0,0,0
0,0,0,0,0,0,0,0,0,0,0,0,0,0,0,0,0,0,0,0,0,0,0,0,0,0,0,0,0,0,0
0,0,0,0,0,0,0,0,0,0,0,0,0,0,0,0,0,0,0,0,0,0,27,0,0,0,0,0,0,0,0
0,0,0,0,0,0,0,0,0,0,0,0,0,0,0,0,0,0,0,0,0,0,27,0,0,0,0,0,0,0,0
0,0,0,0,0,0,0,0,0,0,0,0,0,0,0,0,0,0,0,0,0,0,27,0,0,0,0,0,0,0,0
0,0,0,0,0,0,0,0,0,0,0,0,0,0,0,0,0,0,0,0,0,27,27,27,0,0,0,0,0,0,0
0,0,0,0,27,0,0,0,0,0,0,0,0,0,0,0,0,0,27,27,27,27,28,27,27,27,27,0,0,0,0
0,0,0,0,27,0,0,0,0,0,0,0,0,0,0,0,0,0,0,0,0,27,27,27,0,0,0,0,0,0,0
0,0,0,27,27,27,0,0,0,0,0,0,0,0,0,0,0,0,0,0,0,0,27,0,0,0,0,0,0,0,0
0,27,27,27,27,27,27,27,0,0,0,0,0,0,0,0,0,0,0,0,0,0,27,0,0,0,0,0,0,0,0
0,0,0,27,27,27,0,0,0,0,0,0,0,40,0,0,0,0,0,0,0,0,27,0,0,0,0,0,0,0,0
0,0,0,0,27,0,0,0,0,0,0,0,0,40,0,0,0,0,0,0,0,0,0,0,0,0,0,0,0,0,0
0,0,0,0,27,0,0,0,0,0,0,0,10,8,7,0,0,0,0,0,0,0,0,0,0,0,0,0,0,0,0
0,0,0,0,0,0,0,0,0,0,0,0,10,11,7,0,0,0,0,0,0,0,0,0,0,0,0,0,0,0,0
0,0,0,0,0,0,0,0,0,0,0,40,17,43,43,0,0,0,0,0,0,0,0,0,0,0,0,0,0,0,0
0,0,0,0,0,0,0,0,0,0,17,17,17,17,17,17,17,0,0,0,0,0,0,0,0,0,0,0,0,0,0
0,0,0,0,0,0,0,0,0,17,17,17,17,17,17,17,17,17,0,0,0,0,0,0,0,0,0,0,0,0,0
0,0,0,0,0,0,0,0,17,17,17,17,17,17,17,17,17,17,17,0,0,0,0,0,0,0,28,0,0,0,0
0,0,0,0,0,0,0,0,17,17,17,17,17,17,17,17,17,17,17,0,0,0,0,0,0,0,0,0,0,0,0
0,0,0,0,0,0,0,43,17,17,17,17,3,7,0,17,17,17,17,17,0,0,0,0,0,0,0,0,0,0,0
0,0,0,0,0,0,0,43,17,17,17,17,0,17,0,17,17,17,17,43,0,0,0,0,0,0,0,0,0,0,0
0,0,0,0,0,0,0,17,17,17,17,17,0,0,0,17,17,17,17,43,0,0,0,0,0,0,0,0,0,0,0
0,0,0,0,0,0,0,0,17,17,17,17,17,17,17,17,17,17,17,0,0,0,0,0,0,0,0,0,0,0,0
0,0,0,0,0,0,0,0,17,17,17,17,17,17,17,17,17,17,17,0,0,0,0,0,0,0,0,0,0,0,0
0,0,0,0,0,0,0,0,0,17,17,17,17,17,17,17,17,17,0,0,0,0,0,0,0,0,0,0,0,0,0
0,0,0,0,0,0,0,0,0,0,17,17,17,17,17,17,17,0,0,0,0,0,0,0,0,0,0,0,0,0,0
0,0,0,0,0,0,0,0,0,0,0,0,43,43,17,0,0,0,0,0,0,0,0,0,0,0,0,0,0,0,0
0,0,0,0,0,0,0,0,0,0,0,0,0,0,0,0,0,0,0,0,0,0,0,0,0,0,0,0,0,0,0
0,0,0,0,0,0,0,0,0,0,0,0,0,0,0,0,0,0,0,0,0,0,0,0,0,0,0,0,0,0,0
0,0,0,0,0,0,0,0,0,0,0,0,0,0,0,0,0,0,0,0,0,0,0,0,0,0,0,0,0,0,0
0,0,0,0,0,0,0,0,0,0,0,0,0,0,0,0,0,0,0,0,0,0,0,0,0,0,0,0,0,0,0
endlayer

layer
0,0,0,0,0,0,0,0,0,0,0,0,0,0,0,0,0,0,0,0,0,0,0,0,0,0,0,0,0,0,0
0,0,0,0,0,0,0,0,0,0,0,0,0,0,0,0,0,0,0,0,0,0,0,0,0,0,0,0,0,0,0
0,0,0,0,0,0,0,0,0,0,0,0,0,0,0,0,0,0,0,0,0,0,0,0,0,0,0,0,0,0,0
0,0,0,0,0,0,0,0,0,0,0,0,0,0,0,0,0,0,0,27,0,0,0,0,27,27,0,0,0,0,0
0,0,0,0,0,0,0,0,0,0,0,0,0,0,0,0,0,0,0,27,27,0,0,27,27,0,0,0,0,0,0
0,0,0,0,0,0,0,0,0,0,0,0,0,0,0,0,0,0,0,0,27,27,27,27,0,0,0,0,0,0,0
0,0,0,0,0,0,0,0,0,0,0,0,0,0,0,0,0,0,0,0,0,27,27,27,0,0,0,0,0,0,0
0,0,0,0,0,0,0,0,0,0,0,0,0,0,0,0,0,0,0,0,0,27,27,27,27,0,0,0,0,0,0
0,0,0,27,0,27,0,0,0,0,0,0,0,0,0,0,0,0,0,0,27,27,0,0,27,27,0,0,0,0,0
0,0,0,0,0,0,0,0,0,0,0,0,0,0,0,0,0,0,0,27,27,0,0,0,0,27,0,0,0,0,0
0,0,0,27,0,27,0,0,0,0,0,0,0,40,0,0,0,0,0,0,0,0,0,0,0,0,0,0,0,0,0
0,0,0,0,0,0,0,0,0,0,0,0,0,0,0,0,0,0,0,0,0,0,0,0,0,0,0,0,0,0,0
0,0,0,0,0,0,0,0,0,0,0,0,0,0,0,0,0,0,0,0,0,0,0,0,0,0,0,0,0,0,0
0,0,0,0,0,0,0,0,0,0,0,0,0,0,0,0,0,0,0,0,0,0,0,0,0,0,27,0,0,0,0
0,0,0,0,0,0,0,0,0,0,0,0,0,0,0,0,0,0,0,0,0,0,0,0,0,0,0,0,0,0,0
0,0,0,0,0,0,0,0,0,0,0,0,43,43,17,0,0,0,0,0,0,0,0,0,0,0,0,0,0,0,0
0,0,0,0,0,0,0,0,0,0,17,17,17,17,17,17,17,0,0,0,0,0,0,0,0,0,29,0,0,0,0
0,0,0,0,0,0,0,0,0,17,17,17,17,17,17,17,17,17,0,0,0,0,27,0,0,27,28,27,0,0,27
0,0,0,0,0,0,0,0,0,17,17,17,17,17,17,17,17,17,0,0,0,0,0,0,0,0,27,0,0,0,0
0,0,0,0,0,0,0,0,17,17,17,17,7,0,0,17,17,17,43,0,0,0,0,0,0,0,0,0,0,0,0
0,0,0,0,0,0,0,0,43,17,17,17,4,17,0,17,17,17,43,0,0,0,0,0,0,0,0,0,0,0,0
0,0,0,0,0,0,0,0,43,17,17,17,0,0,0,17,17,17,17,0,0,0,0,0,0,0,27,0,0,0,0
0,0,0,0,0,0,0,0,0,17,17,17,17,17,17,17,17,17,0,0,0,0,0,0,0,0,0,0,0,0,0
0,0,0,0,0,0,0,0,0,17,17,17,17,17,17,17,17,17,0,0,0,0,0,0,0,0,0,0,0,0,0
0,0,0,0,0,0,0,0,0,0,17,17,17,17,17,17,17,0,0,0,0,0,0,0,0,0,0,0,0,0,0
0,0,0,0,0,0,0,0,0,0,0,0,17,43,43,0,0,0,0,0,0,0,0,0,0,0,0,0,0,0,0
0,0,0,0,0,0,0,0,0,0,0,0,0,0,0,0,0,0,0,0,0,0,0,0,0,0,0,0,0,0,0
0,0,0,0,0,0,0,0,0,0,0,0,0,0,0,0,0,0,0,0,0,0,0,0,0,0,0,0,0,0,0
0,0,0,0,0,0,0,0,0,0,0,0,0,0,0,0,0,0,0,0,0,0,0,0,0,0,0,0,0,0,0
0,0,0,0,0,0,0,0,0,0,0,0,0,0,0,0,0,0,0,0,0,0,0,0,0,0,0,0,0,0,0
0,0,0,0,0,0,0,0,0,0,0,0,0,0,0,0,0,0,0,0,0,0,0,0,0,0,0,0,0,0,0
endlayer

layer
0,0,0,0,0,0,0,0,0,0,0,0,0,0,0,0,0,0,0,0,0,0,0,0,0,0,0,0,0,0,0
0,0,0,0,0,0,0,0,0,0,0,0,0,0,0,0,0,0,0,0,0,0,0,0,0,0,0,0,0,0,0
0,0,0,0,0,0,0,0,0,0,0,0,0,0,0,0,0,0,0,0,0,0,0,0,0,0,0,0,0,0,0
0,0,0,0,0,0,0,0,0,0,0,0,0,0,0,0,0,0,0,0,0,0,27,0,0,0,0,0,0,0,0
0,0,0,0,0,0,0,0,0,0,0,0,0,0,0,0,0,0,0,0,0,0,27,0,0,0,0,0,0,0,0
0,0,0,0,0,0,0,0,0,0,0,0,0,0,0,0,0,0,0,0,0,29,29,27,0,0,0,0,0,0,0
0,0,0,0,0,0,0,0,0,0,0,0,0,0,0,0,0,0,0,27,29,29,29,29,29,29,0,0,0,0,0
0,0,0,0,0,0,0,0,0,0,0,0,0,0,0,0,0,0,0,0,0,29,29,29,0,0,0,0,0,0,0
0,0,0,0,0,0,0,0,0,0,0,0,0,0,0,0,0,0,0,0,0,0,27,0,0,0,0,0,0,0,0
0,0,0,0,0,0,0,0,0,0,0,0,0,0,0,0,0,0,0,0,0,0,27,0,0,0,0,0,0,0,0
0,0,0,0,0,0,0,0,0,0,0,0,0,40,0,0,0,0,0,0,0,0,0,0,0,0,0,0,0,0,0
0,0,0,0,0,0,0,0,0,0,0,0,0,0,0,0,0,0,0,0,0,0,0,0,0,0,0,0,0,0,0
0,0,0,0,0,0,0,0,0,0,0,0,0,0,0,0,0,0,0,0,0,0,0,0,0,0,0,0,0,0,0
0,0,0,0,0,0,0,0,0,0,0,0,0,0,0,0,0,0,0,0,0,0,0,0,0,0,27,0,0,0,0
0,0,0,0,0,0,0,0,0,0,0,0,0,0,0,0,0,0,0,0,0,0,0,0,0,0,27,0,0,0,0
0,0,0,0,0,0,0,0,0,0,0,0,43,17,17,0,0,0,0,0,0,0,0,0,0,0,29,0,0,0,0
0,0,0,0,0,0,0,0,0,0,17,43,17,17,17,17,17,0,0,0,0,0,0,0,0,29,29,27,0,0,0
0,0,0,0,0,0,0,0,0,17,17,17,17,17,17,17,17,17,0,0,0,0,27,27,29,29,28,27,27,27,27
0,0,0,0,0,0,0,0,0,17,17,17,17,17,17,17,17,43,0,0,0,0,0,0,0,29,29,29,0,0,0
0,0,0,0,0,0,0,0,17,17,17,17,0,0,0,17,17,17,43,0,0,0,0,0,0,0,29,0,0,0,0
0,0,0,0,0,0,0,0,17,17,17,17,8,17,0,17,17,17,17,0,0,0,0,0,0,0,29,0,0,0,0
0,0,0,0,0,0,0,0,43,17,17,17,4,0,0,17,17,17,17,0,0,0,0,0,0,0,27,0,0,0,0
0,0,0,0,0,0,0,0,0,43,17,17,17,17,17,17,17,17,0,0,0,0,0,0,0,0,0,0,0,0,0
0,0,0,0,0,0,0,0,0,17,17,17,17,17,17,17,17,17,0,0,0,0,0,0,0,0,0,0,0,0,0
0,0,0,0,0,0,0,0,0,0,17,17,17,17,17,43,17,0,0,0,0,0,0,0,0,0,0,0,0,0,0
0,0,0,0,0,0,0,0,0,0,0,0,17,17,43,0,0,0,0,0,0,0,0,0,0,0,0,0,0,0,0
0,0,0,0,0,0,0,0,0,0,0,0,0,0,0,0,0,0,0,0,0,0,0,0,0,0,0,0,0,0,0
0,0,0,0,0,0,0,0,0,0,0,0,0,0,0,0,0,0,0,0,0,0,0,0,0,0,0,0,0,0,0
0,0,0,0,0,0,0,0,0,0,0,0,0,0,0,0,0,0,0,0,0,0,0,0,0,0,0,0,0,0,0
0,0,0,0,0,0,0,0,0,0,0,0,0,0,0,0,0,0,0,0,0,0,0,0,0,0,0,0,0,0,0
0,0,0,0,0,0,0,0,0,0,0,0,0,0,0,0,0,0,0,0,0,0,0,0,0,0,0,0,0,0,0
endlayer

layer
0,0,0,0,0,0,0,0,0,0,0,0,0,0,0,0,0,0,0,0,0,0,0,0,0,0,0,0,0,0,0
0,0,0,0,0,0,0,0,0,0,0,0,0,0,0,0,0,0,0,0,0,0,0,0,0,0,0,0,0,0,0
0,0,0,0,0,0,0,0,0,0,0,0,0,0,0,0,0,0,0,0,0,0,0,0,0,0,0,0,0,0,0
0,0,0,0,0,0,0,0,0,0,0,0,0,0,0,0,0,0,0,0,0,0,0,0,0,0,0,0,0,0,0
0,0,0,0,0,0,0,0,0,0,0,0,0,0,0,0,0,0,0,0,0,0,0,0,0,0,0,0,0,0,0
0,0,0,0,0,0,0,0,0,0,0,0,0,0,0,0,0,0,0,0,0,27,0,27,0,0,0,0,0,0,0
0,0,0,0,0,0,0,0,0,0,0,0,0,0,0,0,0,0,0,0,0,0,0,0,0,0,0,0,0,0,0
0,0,0,0,0,0,0,0,0,0,0,0,0,0,0,0,0,0,0,0,0,27,0,27,0,0,0,0,0,0,0
0,0,0,0,0,0,0,0,0,0,0,0,0,0,0,0,0,0,0,0,0,0,0,0,0,0,0,0,0,0,0
0,0,0,0,0,0,0,0,0,0,0,0,0,0,0,0,0,0,0,0,0,0,0,0,0,0,0,0,0,0,0
0,0,0,0,0,0,0,0,0,0,0,0,0,0,0,0,0,0,0,0,0,0,0,0,0,0,0,0,0,0,0
0,0,0,0,0,0,0,0,0,0,0,0,0,0,0,0,0,0,0,0,0,0,0,0,0,0,0,0,0,0,0
0,0,0,0,0,0,0,0,0,0,0,0,0,0,0,0,0,0,0,0,0,0,0,0,0,0,0,0,0,0,0
0,0,0,0,0,0,0,0,0,0,0,0,0,0,0,0,0,0,0,0,0,0,0,0,0,0,0,0,0,0,0
0,0,0,0,0,0,0,0,0,0,0,0,0,0,0,0,0,0,0,0,0,0,0,27,27,0,0,0,0,27,0
0,0,0,0,0,0,0,0,0,0,0,0,17,17,17,0,0,0,0,0,0,0,0,0,27,27,0,0,27,27,0
0,0,0,0,0,0,0,0,0,0,43,43,17,17,17,17,17,0,0,0,0,0,0,0,0,27,27,27,27,0,0
0,0,0,0,0,0,0,0,0,17,17,17,17,17,17,17,17,43,0,0,0,0,0,0,0,27,27,27,0,0,0
0,0,0,0,0,0,0,0,0,17,17,17,17,17,17,17,17,43,0,0,0,0,0,0,27,29,29,29,0,0,0
0,0,0,0,0,0,0,0,17,17,17,17,0,0,0,17,17,17,17,0,0,0,0,29,29,0,0,27,29,0,0
0,0,0,0,0,0,0,0,17,17,17,17,0,17,0,17,17,17,17,0,0,0,0,29,0,0,0,0,27,27,0
0,0,0,0,0,0,0,0,17,17,17,17,8,6,0,17,17,17,17,0,0,0,0,0,0,0,0,0,0,0,0
0,0,0,0,0,0,0,0,0,43,17,17,17,17,17,17,17,17,0,0,0,0,0,0,0,0,0,0,0,0,0
0,0,0,0,0,0,0,0,0,43,17,17,17,17,17,17,17,17,0,0,0,0,0,0,0,0,0,0,0,0,0
0,0,0,0,0,0,0,0,0,0,17,17,17,17,17,43,43,0,0,0,0,0,0,0,0,0,0,0,0,0,0
0,0,0,0,0,0,0,0,0,0,0,0,17,17,17,0,0,0,0,0,0,0,0,0,0,0,0,0,0,0,0
0,0,0,0,0,0,0,0,0,0,0,0,0,0,0,0,0,0,0,0,0,0,0,0,0,0,0,0,0,0,0
0,0,0,0,0,0,0,0,0,0,0,0,0,0,0,0,0,0,0,0,0,0,0,0,0,0,0,0,0,0,0
0,0,0,0,0,0,0,0,0,0,0,0,0,0,0,0,0,0,0,0,0,0,0,0,0,0,0,0,0,0,0
0,0,0,0,0,0,0,0,0,0,0,0,0,0,0,0,0,0,0,0,0,0,0,0,0,0,0,0,0,0,0
0,0,0,0,0,0,0,0,0,0,0,0,0,0,0,0,0,0,0,0,0,0,0,0,0,0,0,0,0,0,0
endlayer

layer
0,0,0,0,0,0,0,0,0,0,0,0,0,0,0,0,0,0,0,0,0,0,0,0,0,0,0,0,0,0,0
0,0,0,0,0,0,0,0,0,0,0,0,0,0,0,0,0,0,0,0,0,0,0,0,0,0,0,0,0,0,0
0,0,0,0,0,0,0,0,0,0,0,0,0,0,0,0,0,0,0,0,0,0,0,0,0,0,0,0,0,0,0
0,0,0,0,0,0,0,0,0,0,0,0,0,0,0,0,0,0,0,0,0,0,0,0,0,0,0,0,0,0,0
0,0,0,0,0,0,0,0,0,0,0,0,0,0,0,0,0,0,0,0,0,0,0,0,0,0,0,0,0,0,0
0,0,0,0,0,0,0,0,0,0,0,0,0,0,0,0,0,0,0,0,0,0,0,0,0,0,0,0,0,0,0
0,0,0,0,0,0,0,0,0,0,0,0,0,0,0,0,0,0,0,0,0,0,0,0,0,0,0,0,0,0,0
0,0,0,0,0,0,0,0,0,0,0,0,0,0,0,0,0,0,0,0,0,0,0,0,0,0,0,0,0,0,0
0,0,0,0,0,0,0,0,0,0,0,0,0,0,0,0,0,0,0,0,0,0,0,0,0,0,0,0,0,0,0
0,0,0,0,0,0,0,0,0,0,0,0,0,0,0,0,0,0,0,0,0,0,0,0,0,0,0,0,0,0,0
0,0,0,0,0,0,0,0,0,0,0,0,0,0,0,0,0,0,0,0,0,0,0,0,0,0,0,0,0,0,0
0,0,0,0,0,0,0,0,0,0,0,0,0,0,0,0,0,0,0,0,0,0,0,0,0,0,0,0,0,0,0
0,0,0,0,0,0,0,0,0,0,0,0,0,0,0,0,0,0,0,0,0,0,0,0,0,0,0,0,0,0,0
0,0,0,0,0,0,0,0,0,0,0,0,0,0,0,0,0,0,0,0,0,0,0,0,0,0,0,0,0,0,0
0,0,0,0,0,0,0,0,0,0,0,0,0,0,0,0,0,0,0,0,0,0,0,0,0,0,27,0,0,0,0
0,0,0,0,0,0,0,0,0,0,0,0,0,0,0,0,0,0,0,0,0,0,0,0,0,0,27,0,0,0,0
0,0,0,0,0,0,0,0,0,0,0,0,17,17,17,0,0,0,0,0,0,0,0,0,0,27,27,27,0,0,0
0,0,0,0,0,0,0,0,0,0,43,17,17,17,17,43,43,0,0,0,0,0,0,27,27,27,27,27,27,27,0
0,0,0,0,0,0,0,0,0,0,43,17,17,17,17,17,17,0,0,0,0,0,0,0,0,27,27,27,0,0,0
0,0,0,0,0,0,0,0,0,17,17,17,0,0,0,17,17,17,0,0,0,0,0,0,0,0,27,0,0,0,0
0,0,0,0,0,0,0,0,0,17,17,17,0,17,0,17,17,17,0,0,0,0,0,0,0,0,27,0,0,0,0
0,0,0,0,0,0,0,0,0,17,17,17,0,10,6,17,17,17,0,0,0,0,0,0,0,0,0,0,0,0,0
0,0,0,0,0,0,0,0,0,0,17,17,17,17,17,17,43,0,0,0,0,0,0,0,0,0,0,0,0,0,0
0,0,0,0,0,0,0,0,0,0,43,43,17,17,17,17,43,0,0,0,0,0,0,0,0,0,0,0,0,0,0
0,0,0,0,0,0,0,0,0,0,0,0,17,17,17,0,0,0,0,0,0,0,0,0,0,0,0,0,0,0,0
0,0,0,0,0,0,0,0,0,0,0,0,0,0,0,0,0,0,0,0,0,0,0,0,0,0,0,0,0,0,0
0,0,0,0,0,0,0,0,0,0,0,0,0,0,0,0,0,0,0,0,0,0,0,0,0,0,0,0,0,0,0
0,0,0,0,0,0,0,0,0,0,0,0,0,0,0,0,0,0,0,0,0,0,0,0,0,0,0,0,0,0,0
0,0,0,0,0,0,0,0,0,0,0,0,0,0,0,0,0,0,0,0,0,0,0,0,0,0,0,0,0,0,0
0,0,0,0,0,0,0,0,0,0,0,0,0,0,0,0,0,0,0,0,0,0,0,0,0,0,0,0,0,0,0
0,0,0,0,0,0,0,0,0,0,0,0,0,0,0,0,0,0,0,0,0,0,0,0,0,0,0,0,0,0,0
endlayer

layer
0,0,0,0,0,0,0,0,0,0,0,0,0,0,0,0,0,0,0,0,0,0,0,0,0,0,0,0,0,0,0
0,0,0,0,0,0,0,0,0,0,0,0,0,0,0,0,0,0,0,0,0,0,0,0,0,0,0,0,0,0,0
0,0,0,0,0,0,0,0,0,0,0,0,0,0,0,0,0,0,0,0,0,0,0,0,0,0,0,0,0,0,0
0,0,0,0,0,0,0,0,0,0,0,0,0,0,0,0,0,0,0,0,0,0,0,0,0,0,0,0,0,0,0
0,0,0,0,0,0,0,0,0,0,0,0,0,0,0,0,0,0,0,0,0,0,0,0,0,0,0,0,0,0,0
0,0,0,0,0,0,0,0,0,0,0,0,0,0,0,0,0,0,0,0,0,0,0,0,0,0,0,0,0,0,0
0,0,0,0,0,0,0,0,0,0,0,0,0,0,0,0,0,0,0,0,0,0,0,0,0,0,0,0,0,0,0
0,0,0,0,0,0,0,0,0,0,0,0,0,0,0,0,0,0,0,0,0,0,0,0,0,0,0,0,0,0,0
0,0,0,0,0,0,0,0,0,0,0,0,0,0,0,0,0,0,0,0,0,0,0,0,0,0,0,0,0,0,0
0,0,0,0,0,0,0,0,0,0,0,0,0,0,0,0,0,0,0,0,0,0,0,0,0,0,0,0,0,0,0
0,0,0,0,0,0,0,0,0,0,0,0,0,0,0,0,0,0,0,0,0,0,0,0,0,0,0,0,0,0,0
0,0,0,0,0,0,0,0,0,0,0,0,0,0,0,0,0,0,0,0,0,0,0,0,0,0,0,0,0,0,0
0,0,0,0,0,0,0,0,0,0,0,0,0,0,0,0,0,0,0,0,0,0,0,0,0,0,0,0,0,0,0
0,0,0,0,0,0,0,0,0,0,0,0,0,0,0,0,0,0,0,0,0,0,0,0,0,0,0,0,0,0,0
0,0,0,0,0,0,0,0,0,0,0,0,0,0,0,0,0,0,0,0,0,0,0,0,0,0,0,0,0,0,0
0,0,0,0,0,0,0,0,0,0,0,0,0,0,0,0,0,0,0,0,0,0,0,0,0,0,0,0,0,0,0
0,0,0,0,0,0,0,0,0,0,0,0,17,17,43,0,0,0,0,0,0,0,0,0,0,27,0,27,0,0,0
0,0,0,0,0,0,0,0,0,0,17,17,17,17,17,43,17,0,0,0,0,0,0,0,0,0,0,0,0,0,0
0,0,0,0,0,0,0,0,0,0,43,17,17,17,17,17,17,0,0,0,0,0,0,0,0,27,0,27,0,0,0
0,0,0,0,0,0,0,0,0,43,17,17,0,0,0,17,17,17,0,0,0,0,0,0,0,0,0,0,0,0,0
0,0,0,0,0,0,0,0,0,17,17,17,0,17,5,17,17,17,0,0,0,0,0,0,0,0,0,0,0,0,0
0,0,0,0,0,0,0,0,0,17,17,17,0,0,10,17,17,43,0,0,0,0,0,0,0,0,0,0,0,0,0
0,0,0,0,0,0,0,0,0,0,17,17,17,17,17,17,43,0,0,0,0,0,0,0,0,0,0,0,0,0,0
0,0,0,0,0,0,0,0,0,0,17,43,17,17,17,17,17,0,0,0,0,0,0,0,0,0,0,0,0,0,0
0,0,0,0,0,0,0,0,0,0,0,0,43,17,17,0,0,0,0,0,0,0,0,0,0,0,0,0,0,0,0
0,0,0,0,0,0,0,0,0,0,0,0,0,0,0,0,0,0,0,0,0,0,0,0,0,0,0,0,0,0,0
0,0,0,0,0,0,0,0,0,0,0,0,0,0,0,0,0,0,0,0,0,0,0,0,0,0,0,0,0,0,0
0,0,0,0,0,0,0,0,0,0,0,0,0,0,0,0,0,0,0,0,0,0,0,0,0,0,0,0,0,0,0
0,0,0,0,0,0,0,0,0,0,0,0,0,0,0,0,0,0,0,0,0,0,0,0,0,0,0,0,0,0,0
0,0,0,0,0,0,0,0,0,0,0,0,0,0,0,0,0,0,0,0,0,0,0,0,0,0,0,0,0,0,0
0,0,0,0,0,0,0,0,0,0,0,0,0,0,0,0,0,0,0,0,0,0,0,0,0,0,0,0,0,0,0
endlayer

layer
0,0,0,0,0,0,0,0,0,0,0,0,0,0,0,0,0,0,0,0,0,0,0,0,0,0,0,0,0,0,0
0,0,0,0,0,0,0,0,0,0,0,0,0,0,0,0,0,0,0,0,0,0,0,0,0,0,0,0,0,0,0
0,0,0,0,0,0,0,0,0,0,0,0,0,0,0,0,0,0,0,0,0,0,0,0,0,0,0,0,0,0,0
0,0,0,0,0,0,0,0,0,0,0,0,0,0,0,0,0,0,0,0,0,0,0,0,0,0,0,0,0,0,0
0,0,0,0,0,0,0,0,0,0,0,0,0,0,0,0,0,0,0,0,0,0,0,0,0,0,0,0,0,0,0
0,0,0,0,0,0,0,0,0,0,0,0,0,0,0,0,0,0,0,0,0,0,0,0,0,0,0,0,0,0,0
0,0,0,0,0,0,0,0,0,0,0,0,0,0,0,0,0,0,0,0,0,0,0,0,0,0,0,0,0,0,0
0,0,0,0,0,0,0,0,0,0,0,0,0,0,0,0,0,0,0,0,0,0,0,0,0,0,0,0,0,0,0
0,0,0,0,0,0,0,0,0,0,0,0,0,0,0,0,0,0,0,0,0,0,0,0,0,0,0,0,0,0,0
0,0,0,0,0,0,0,0,0,0,0,0,0,0,0,0,0,0,0,0,0,0,0,0,0,0,0,0,0,0,0
0,0,0,0,0,0,0,0,0,0,0,0,0,0,0,0,0,0,0,0,0,0,0,0,0,0,0,0,0,0,0
0,0,0,0,0,0,0,0,0,0,0,0,0,0,0,0,0,0,0,0,0,0,0,0,0,0,0,0,0,0,0
0,0,0,0,0,0,0,0,0,0,0,0,0,0,0,0,0,0,0,0,0,0,0,0,0,0,0,0,0,0,0
0,0,0,0,0,0,0,0,0,0,0,0,0,0,0,0,0,0,0,0,0,0,0,0,0,0,0,0,0,0,0
0,0,0,0,0,0,0,0,0,0,0,0,0,0,0,0,0,0,0,0,0,0,0,0,0,0,0,0,0,0,0
0,0,0,0,0,0,0,0,0,0,0,0,0,0,0,0,0,0,0,0,0,0,0,0,0,0,0,0,0,0,0
0,0,0,0,0,0,0,0,0,0,0,0,17,43,43,0,0,0,0,0,0,0,0,0,0,0,0,0,0,0,0
0,0,0,0,0,0,0,0,0,0,17,17,17,17,17,17,17,0,0,0,0,0,0,0,0,0,0,0,0,0,0
0,0,0,0,0,0,0,0,0,0,17,17,17,17,17,17,17,0,0,0,0,0,0,0,0,0,0,0,0,0,0
0,0,0,0,0,0,0,0,0,43,17,17,0,0,5,17,17,17,0,0,0,0,0,0,0,0,0,0,0,0,0
0,0,0,0,0,0,0,0,0,43,17,17,0,17,9,17,17,43,0,0,0,0,0,0,0,0,0,0,0,0,0
0,0,0,0,0,0,0,0,0,17,17,17,0,0,0,17,17,43,0,0,0,0,0,0,0,0,0,0,0,0,0
0,0,0,0,0,0,0,0,0,0,17,17,17,17,17,17,17,0,0,0,0,0,0,0,0,0,0,0,0,0,0
0,0,0,0,0,0,0,0,0,0,17,17,17,17,17,17,17,0,0,0,0,0,0,0,0,0,0,0,0,0,0
0,0,0,0,0,0,0,0,0,0,0,0,43,43,17,0,0,0,0,0,0,0,0,0,0,0,0,0,0,0,0
0,0,0,0,0,0,0,0,0,0,0,0,0,0,0,0,0,0,0,0,0,0,0,0,0,0,0,0,0,0,0
0,0,0,0,0,0,0,0,0,0,0,0,0,0,0,0,0,0,0,0,0,0,0,0,0,0,0,0,0,0,0
0,0,0,0,0,0,0,0,0,0,0,0,0,0,0,0,0,0,0,0,0,0,0,0,0,0,0,0,0,0,0
0,0,0,0,0,0,0,0,0,0,0,0,0,0,0,0,0,0,0,0,0,0,0,0,0,0,0,0,0,0,0
0,0,0,0,0,0,0,0,0,0,0,0,0,0,0,0,0,0,0,0,0,0,0,0,0,0,0,0,0,0,0
0,0,0,0,0,0,0,0,0,0,0,0,0,0,0,0,0,0,0,0,0,0,0,0,0,0,0,0,0,0,0
endlayer

layer
0,0,0,0,0,0,0,0,0,0,0,0,0,0,0,0,0,0,0,0,0,0,0,0,0,0,0,0,0,0,0
0,0,0,0,0,0,0,0,0,0,0,0,0,0,0,0,0,0,0,0,0,0,0,0,0,0,0,0,0,0,0
0,0,0,0,0,0,0,0,0,0,0,0,0,0,0,0,0,0,0,0,0,0,0,0,0,0,0,0,0,0,0
0,0,0,0,0,0,0,0,0,0,0,0,0,0,0,0,0,0,0,0,0,0,0,0,0,0,0,0,0,0,0
0,0,0,0,0,0,0,0,0,0,0,0,0,0,0,0,0,0,0,0,0,0,0,0,0,0,0,0,0,0,0
0,0,0,0,0,0,0,0,0,0,0,0,0,0,0,0,0,0,0,0,0,0,0,0,0,0,0,0,0,0,0
0,0,0,0,0,0,0,0,0,0,0,0,0,0,0,0,0,0,0,0,0,0,0,0,0,0,0,0,0,0,0
0,0,0,0,0,0,0,0,0,0,0,0,0,0,0,0,0,0,0,0,0,0,0,0,0,0,0,0,0,0,0
0,0,0,0,0,0,0,0,0,0,0,0,0,0,0,0,0,0,0,0,0,0,0,0,0,0,0,0,0,0,0
0,0,0,0,0,0,0,0,0,0,0,0,0,0,0,0,0,0,0,0,0,0,0,0,0,0,0,0,0,0,0
0,0,0,0,0,0,0,0,0,0,0,0,0,0,0,0,0,0,0,0,0,0,0,0,0,0,0,0,0,0,0
0,0,0,0,0,0,0,0,0,0,0,0,0,0,0,0,0,0,0,0,0,0,0,0,0,0,0,0,0,0,0
0,0,0,0,0,0,0,0,0,0,0,0,0,0,0,0,0,0,0,0,0,0,0,0,0,0,0,0,0,0,0
0,0,0,0,0,0,0,0,0,0,0,0,0,0,0,0,0,0,0,0,0,0,0,0,0,0,0,0,0,0,0
0,0,0,0,0,0,0,0,0,0,0,0,0,0,0,0,0,0,0,0,0,0,0,0,0,0,0,0,0,0,0
0,0,0,0,0,0,0,0,0,0,0,0,0,0,0,0,0,0,0,0,0,0,0,0,0,0,0,0,0,0,0
0,0,0,0,0,0,0,0,0,0,0,0,0,43,0,0,0,0,0,0,0,0,0,0,0,0,0,0,0,0,0
0,0,0,0,0,0,0,0,0,0,0,17,43,17,17,17,0,0,0,0,0,0,0,0,0,0,0,0,0,0,0
0,0,0,0,0,0,0,0,0,0,17,17,17,17,17,17,17,0,0,0,0,0,0,0,0,0,0,0,0,0,0
0,0,0,0,0,0,0,0,0,0,17,17,0,3,9,17,43,0,0,0,0,0,0,0,0,0,0,0,0,0,0
0,0,0,0,0,0,0,0,0,43,17,17,0,17,0,17,17,43,0,0,0,0,0,0,0,0,0,0,0,0,0
0,0,0,0,0,0,0,0,0,0,43,17,0,0,0,17,17,0,0,0,0,0,0,0,0,0,0,0,0,0,0
0,0,0,0,0,0,0,0,0,0,17,17,17,17,17,17,17,0,0,0,0,0,0,0,0,0,0,0,0,0,0
0,0,0,0,0,0,0,0,0,0,0,17,17,17,43,17,0,0,0,0,0,0,0,0,0,0,0,0,0,0,0
0,0,0,0,0,0,0,0,0,0,0,0,0,43,0,0,0,0,0,0,0,0,0,0,0,0,0,0,0,0,0
0,0,0,0,0,0,0,0,0,0,0,0,0,0,0,0,0,0,0,0,0,0,0,0,0,0,0,0,0,0,0
0,0,0,0,0,0,0,0,0,0,0,0,0,0,0,0,0,0,0,0,0,0,0,0,0,0,0,0,0,0,0
0,0,0,0,0,0,0,0,0,0,0,0,0,0,0,0,0,0,0,0,0,0,0,0,0,0,0,0,0,0,0
0,0,0,0,0,0,0,0,0,0,0,0,0,0,0,0,0,0,0,0,0,0,0,0,0,0,0,0,0,0,0
0,0,0,0,0,0,0,0,0,0,0,0,0,0,0,0,0,0,0,0,0,0,0,0,0,0,0,0,0,0,0
0,0,0,0,0,0,0,0,0,0,0,0,0,0,0,0,0,0,0,0,0,0,0,0,0,0,0,0,0,0,0
endlayer

layer
0,0,0,0,0,0,0,0,0,0,0,0,0,0,0,0,0,0,0,0,0,0,0,0,0,0,0,0,0,0,0
0,0,0,0,0,0,0,0,0,0,0,0,0,0,0,0,0,0,0,0,0,0,0,0,0,0,0,0,0,0,0
0,0,0,0,0,0,0,0,0,0,0,0,0,0,0,0,0,0,0,0,0,0,0,0,0,0,0,0,0,0,0
0,0,0,0,0,0,0,0,0,0,0,0,0,0,0,0,0,0,0,0,0,0,0,0,0,0,0,0,0,0,0
0,0,0,0,0,0,0,0,0,0,0,0,0,0,0,0,0,0,0,0,0,0,0,0,0,0,0,0,0,0,0
0,0,0,0,0,0,0,0,0,0,0,0,0,0,0,0,0,0,0,0,0,0,0,0,0,0,0,0,0,0,0
0,0,0,0,0,0,0,0,0,0,0,0,0,0,0,0,0,0,0,0,0,0,0,0,0,0,0,0,0,0,0
0,0,0,0,0,0,0,0,0,0,0,0,0,0,0,0,0,0,0,0,0,0,0,0,0,0,0,0,0,0,0
0,0,0,0,0,0,0,0,0,0,0,0,0,0,0,0,0,0,0,0,0,0,0,0,0,0,0,0,0,0,0
0,0,0,0,0,0,0,0,0,0,0,0,0,0,0,0,0,0,0,0,0,0,0,0,0,0,0,0,0,0,0
0,0,0,0,0,0,0,0,0,0,0,0,0,0,0,0,0,0,0,0,0,0,0,0,0,0,0,0,0,0,0
0,0,0,0,0,0,0,0,0,0,0,0,0,0,0,0,0,0,0,0,0,0,0,0,0,0,0,0,0,0,0
0,0,0,0,0,0,0,0,0,0,0,0,0,0,0,0,0,0,0,0,0,0,0,0,0,0,0,0,0,0,0
0,0,0,0,0,0,0,0,0,0,0,0,0,0,0,0,0,0,0,0,0,0,0,0,0,0,0,0,0,0,0
0,0,0,0,0,0,0,0,0,0,0,0,0,0,0,0,0,0,0,0,0,0,0,0,0,0,0,0,0,0,0
0,0,0,0,0,0,0,0,0,0,0,0,0,0,0,0,0,0,0,0,0,0,0,0,0,0,0,0,0,0,0
0,0,0,0,0,0,0,0,0,0,0,0,0,17,0,0,0,0,0,0,0,0,0,0,0,0,0,0,0,0,0
0,0,0,0,0,0,0,0,0,0,0,43,43,17,17,17,0,0,0,0,0,0,0,0,0,0,0,0,0,0,0
0,0,0,0,0,0,0,0,0,0,17,17,17,17,17,17,43,0,0,0,0,0,0,0,0,0,0,0,0,0,0
0,0,0,0,0,0,0,0,0,0,17,17,3,7,0,17,43,0,0,0,0,0,0,0,0,0,0,0,0,0,0
0,0,0,0,0,0,0,0,0,17,17,17,0,17,0,17,17,17,0,0,0,0,0,0,0,0,0,0,0,0,0
0,0,0,0,0,0,0,0,0,0,43,17,0,0,0,17,17,0,0,0,0,0,0,0,0,0,0,0,0,0,0
0,0,0,0,0,0,0,0,0,0,43,17,17,17,17,17,17,0,0,0,0,0,0,0,0,0,0,0,0,0,0
0,0,0,0,0,0,0,0,0,0,0,17,17,17,43,43,0,0,0,0,0,0,0,0,0,0,0,0,0,0,0
0,0,0,0,0,0,0,0,0,0,0,0,0,17,0,0,0,0,0,0,0,0,0,0,0,0,0,0,0,0,0
0,0,0,0,0,0,0,0,0,0,0,0,0,0,0,0,0,0,0,0,0,0,0,0,0,0,0,0,0,0,0
0,0,0,0,0,0,0,0,0,0,0,0,0,0,0,0,0,0,0,0,0,0,0,0,0,0,0,0,0,0,0
0,0,0,0,0,0,0,0,0,0,0,0,0,0,0,0,0,0,0,0,0,0,0,0,0,0,0,0,0,0,0
0,0,0,0,0,0,0,0,0,0,0,0,0,0,0,0,0,0,0,0,0,0,0,0,0,0,0,0,0,0,0
0,0,0,0,0,0,0,0,0,0,0,0,0,0,0,0,0,0,0,0,0,0,0,0,0,0,0,0,0,0,0
0,0,0,0,0,0,0,0,0,0,0,0,0,0,0,0,0,0,0,0,0,0,0,0,0,0,0,0,0,0,0
endlayer

layer
0,0,0,0,0,0,0,0,0,0,0,0,0,0,0,0,0,0,0,0,0,0,0,0,0,0,0,0,0,0,0
0,0,0,0,0,0,0,0,0,0,0,0,0,0,0,0,0,0,0,0,0,0,0,0,0,0,0,0,0,0,0
0,0,0,0,0,0,0,0,0,0,0,0,0,0,0,0,0,0,0,0,0,0,0,0,0,0,0,0,0,0,0
0,0,0,0,0,0,0,0,0,0,0,0,0,0,0,0,0,0,0,0,0,0,0,0,0,0,0,0,0,0,0
0,0,0,0,0,0,0,0,0,0,0,0,0,0,0,0,0,0,0,0,0,0,0,0,0,0,0,0,0,0,0
0,0,0,0,0,0,0,0,0,0,0,0,0,0,0,0,0,0,0,0,0,0,0,0,0,0,0,0,0,0,0
0,0,0,0,0,0,0,0,0,0,0,0,0,0,0,0,0,0,0,0,0,0,0,0,0,0,0,0,0,0,0
0,0,0,0,0,0,0,0,0,0,0,0,0,0,0,0,0,0,0,0,0,0,0,0,0,0,0,0,0,0,0
0,0,0,0,0,0,0,0,0,0,0,0,0,0,0,0,0,0,0,0,0,0,0,0,0,0,0,0,0,0,0
0,0,0,0,0,0,0,0,0,0,0,0,0,0,0,0,0,0,0,0,0,0,0,0,0,0,0,0,0,0,0
0,0,0,0,0,0,0,0,0,0,0,0,0,0,0,0,0,0,0,0,0,0,0,0,0,0,0,0,0,0,0
0,0,0,0,0,0,0,0,0,0,0,0,0,0,0,0,0,0,0,0,0,0,0,0,0,0,0,0,0,0,0
0,0,0,0,0,0,0,0,0,0,0,0,0,0,0,0,0,0,0,0,0,0,0,0,0,0,0,0,0,0,0
0,0,0,0,0,0,0,0,0,0,0,0,0,0,0,0,0,0,0,0,0,0,0,0,0,0,0,0,0,0,0
0,0,0,0,0,0,0,0,0,0,0,0,0,0,0,0,0,0,0,0,0,0,0,0,0,0,0,0,0,0,0
0,0,0,0,0,0,0,0,0,0,0,0,0,0,0,0,0,0,0,0,0,0,0,0,0,0,0,0,0,0,0
0,0,0,0,0,0,0,0,0,0,0,0,0,17,0,0,0,0,0,0,0,0,0,0,0,0,0,0,0,0,0
0,0,0,0,0,0,0,0,0,0,0,43,17,17,17,43,0,0,0,0,0,0,0,0,0,0,0,0,0,0,0
0,0,0,0,0,0,0,0,0,0,43,17,17,17,17,17,43,0,0,0,0,0,0,0,0,0,0,0,0,0,0
0,0,0,0,0,0,0,0,0,0,17,17,7,0,0,17,17,0,0,0,0,0,0,0,0,0,0,0,0,0,0
0,0,0,0,0,0,0,0,0,17,17,17,4,17,0,17,17,17,0,0,0,0,0,0,0,0,0,0,0,0,0
0,0,0,0,0,0,0,0,0,0,17,17,0,0,0,17,17,0,0,0,0,0,0,0,0,0,0,0,0,0,0
0,0,0,0,0,0,0,0,0,0,43,17,17,17,17,17,43,0,0,0,0,0,0,0,0,0,0,0,0,0,0
0,0,0,0,0,0,0,0,0,0,0,43,17,17,17,43,0,0,0,0,0,0,0,0,0,0,0,0,0,0,0
0,0,0,0,0,0,0,0,0,0,0,0,0,17,0,0,0,0,0,0,0,0,0,0,0,0,0,0,0,0,0
0,0,0,0,0,0,0,0,0,0,0,0,0,0,0,0,0,0,0,0,0,0,0,0,0,0,0,0,0,0,0
0,0,0,0,0,0,0,0,0,0,0,0,0,0,0,0,0,0,0,0,0,0,0,0,0,0,0,0,0,0,0
0,0,0,0,0,0,0,0,0,0,0,0,0,0,0,0,0,0,0,0,0,0,0,0,0,0,0,0,0,0,0
0,0,0,0,0,0,0,0,0,0,0,0,0,0,0,0,0,0,0,0,0,0,0,0,0,0,0,0,0,0,0
0,0,0,0,0,0,0,0,0,0,0,0,0,0,0,0,0,0,0,0,0,0,0,0,0,0,0,0,0,0,0
0,0,0,0,0,0,0,0,0,0,0,0,0,0,0,0,0,0,0,0,0,0,0,0,0,0,0,0,0,0,0
endlayer

layer
0,0,0,0,0,0,0,0,0,0,0,0,0,0,0,0,0,0,0,0,0,0,0,0,0,0,0,0,0,0,0
0,0,0,0,0,0,0,0,0,0,0,0,0,0,0,0,0,0,0,0,0,0,0,0,0,0,0,0,0,0,0
0,0,0,0,0,0,0,0,0,0,0,0,0,0,0,0,0,0,0,0,0,0,0,0,0,0,0,0,0,0,0
0,0,0,0,0,0,0,0,0,0,0,0,0,0,0,0,0,0,0,0,0,0,0,0,0,0,0,0,0,0,0
0,0,0,0,0,0,0,0,0,0,0,0,0,0,0,0,0,0,0,0,0,0,0,0,0,0,0,0,0,0,0
0,0,0,0,0,0,0,0,0,0,0,0,0,0,0,0,0,0,0,0,0,0,0,0,0,0,0,0,0,0,0
0,0,0,0,0,0,0,0,0,0,0,0,0,0,0,0,0,0,0,0,0,0,0,0,0,0,0,0,0,0,0
0,0,0,0,0,0,0,0,0,0,0,0,0,0,0,0,0,0,0,0,0,0,0,0,0,0,0,0,0,0,0
0,0,0,0,0,0,0,0,0,0,0,0,0,0,0,0,0,0,0,0,0,0,0,0,0,0,0,0,0,0,0
0,0,0,0,0,0,0,0,0,0,0,0,0,0,0,0,0,0,0,0,0,0,0,0,0,0,0,0,0,0,0
0,0,0,0,0,0,0,0,0,0,0,0,0,0,0,0,0,0,0,0,0,0,0,0,0,0,0,0,0,0,0
0,0,0,0,0,0,0,0,0,0,0,0,0,0,0,0,0,0,0,0,0,0,0,0,0,0,0,0,0,0,0
0,0,0,0,0,0,0,0,0,0,0,0,0,0,0,0,0,0,0,0,0,0,0,0,0,0,0,0,0,0,0
0,0,0,0,0,0,0,0,0,0,0,0,0,0,0,0,0,0,0,0,0,0,0,0,0,0,0,0,0,0,0
0,0,0,0,0,0,0,0,0,0,0,3,5,5,5,6,0,0,0,0,0,0,0,0,0,0,0,0,0,0,0
0,0,0,0,0,0,0,0,0,3,5,5,11,11,11,5,5,6,0,0,0,0,0,0,0,0,0,0,0,0,0
0,0,0,0,0,0,0,0,3,5,11,11,11,11,11,11,11,5,6,0,0,0,0,0,0,0,0,0,0,0,0
0,0,0,0,0,0,0,0,3,11,11,11,11,11,11,11,11,11,6,0,0,0,0,0,0,0,0,0,0,0,0
0,0,0,0,0,0,0,3,5,11,11,11,11,11,11,11,11,11,5,6,0,0,0,0,0,0,0,0,0,0,0
0,0,0,0,0,0,0,3,11,11,11,11,0,0,0,11,11,11,11,6,0,0,0,0,0,0,0,0,0,0,0
0,0,0,0,0,0,0,3,11,11,11,11,8,17,5,11,11,11,11,6,0,0,0,0,0,0,0,0,0,0,0
0,0,0,0,0,0,0,3,11,11,11,11,11,11,11,11,11,11,11,6,0,0,0,0,0,0,0,0,0,0,0
0,0,0,0,0,0,0,3,4,11,11,11,11,11,11,11,11,11,6,4,0,0,0,0,0,0,0,0,0,0,0
0,0,0,0,0,0,0,0,3,11,11,11,11,11,11,11,11,11,6,0,0,0,0,0,0,0,0,0,0,0,0
0,0,0,0,0,0,0,0,3,4,11,11,11,11,11,11,11,6,4,0,0,0,0,0,0,0,0,0,0,0,0
0,0,0,0,0,0,0,0,0,3,4,4,11,11,11,6,4,4,0,0,0,0,0,0,0,0,0,0,0,0,0
0,0,0,0,0,0,0,0,0,0,0,3,4,4,4,4,0,0,0,0,0,0,0,0,0,0,0,0,0,0,0
0,0,0,0,0,0,0,0,0,0,0,0,0,0,0,0,0,0,0,0,0,0,0,0,0,0,0,0,0,0,0
0,0,0,0,0,0,0,0,0,0,0,0,0,0,0,0,0,0,0,0,0,0,0,0,0,0,0,0,0,0,0
0,0,0,0,0,0,0,0,0,0,0,0,0,0,0,0,0,0,0,0,0,0,0,0,0,0,0,0,0,0,0
0,0,0,0,0,0,0,0,0,0,0,0,0,0,0,0,0,0,0,0,0,0,0,0,0,0,0,0,0,0,0
endlayer

layer
0,0,0,0,0,0,0,0,0,0,0,0,0,0,0,0,0,0,0,0,0,0,0,0,0,0,0,0,0,0,0
0,0,0,0,0,0,0,0,0,0,0,0,0,0,0,0,0,0,0,0,0,0,0,0,0,0,0,0,0,0,0
0,0,0,0,0,0,0,0,0,0,0,0,0,0,0,0,0,0,0,0,0,0,0,0,0,0,0,0,0,0,0
0,0,0,0,0,0,0,0,0,0,0,0,0,0,0,0,0,0,0,0,0,0,0,0,0,0,0,0,0,0,0
0,0,0,0,0,0,0,0,0,0,0,0,0,0,0,0,0,0,0,0,0,0,0,0,0,0,0,0,0,0,0
0,0,0,0,0,0,0,0,0,0,0,0,0,0,0,0,0,0,0,0,0,0,0,0,0,0,0,0,0,0,0
0,0,0,0,0,0,0,0,0,0,0,0,0,0,0,0,0,0,0,0,0,0,0,0,0,0,0,0,0,0,0
0,0,0,0,0,0,0,0,0,0,0,0,0,0,0,0,0,0,0,0,0,0,0,0,0,0,0,0,0,0,0
0,0,0,0,0,0,0,0,0,0,0,0,0,0,0,0,0,0,0,0,0,0,0,0,0,0,0,0,0,0,0
0,0,0,0,0,0,0,0,0,0,0,0,0,0,0,0,0,0,0,0,0,0,0,0,0,0,0,0,0,0,0
0,0,0,0,0,0,0,0,0,0,0,0,0,0,0,0,0,0,0,0,0,0,0,0,0,0,0,0,0,0,0
0,0,0,0,0,0,0,0,0,0,0,0,0,0,0,0,0,0,0,0,0,0,0,0,0,0,0,0,0,0,0
0,0,0,0,0,0,0,0,0,0,0,0,0,0,0,0,0,0,0,0,0,0,0,0,0,0,0,0,0,0,0
0,0,0,0,0,0,0,0,0,0,0,0,0,0,0,0,0,0,0,0,0,0,0,0,0,0,0,0,0,0,0
0,0,0,0,0,0,0,0,0,0,0,0,0,0,0,0,0,0,0,0,0,0,0,0,0,0,0,0,0,0,0
0,0,0,0,0,0,0,0,0,0,0,0,0,0,0,0,0,0,0,0,0,0,0,0,0,0,0,0,0,0,0
0,0,0,0,0,0,0,0,0,0,0,17,39,39,39,17,0,0,0,0,0,0,0,0,0,0,0,0,0,0,0
0,0,0,0,0,0,0,0,0,0,39,0,0,0,0,0,39,0,0,0,0,0,0,0,0,0,0,0,0,0,0
0,0,0,0,0,0,0,0,0,17,0,0,0,0,0,0,0,17,0,0,0,0,0,0,0,0,0,0,0,0,0
0,0,0,0,0,0,0,0,0,39,0,0,0,0,0,0,0,39,0,0,0,0,0,0,0,0,0,0,0,0,0
0,0,0,0,0,0,0,0,0,39,0,0,0,17,0,0,0,39,0,0,0,0,0,0,0,0,0,0,0,0,0
0,0,0,0,0,0,0,0,0,39,0,0,0,0,0,0,0,39,0,0,0,0,0,0,0,0,0,0,0,0,0
0,0,0,0,0,0,0,0,0,17,0,0,0,0,0,0,0,17,0,0,0,0,0,0,0,0,0,0,0,0,0
0,0,0,0,0,0,0,0,0,0,39,0,0,0,0,0,39,0,0,0,0,0,0,0,0,0,0,0,0,0,0
0,0,0,0,0,0,0,0,0,0,0,17,39,39,39,17,0,0,0,0,0,0,0,0,0,0,0,0,0,0,0
0,0,0,0,0,0,0,0,0,0,0,0,0,0,0,0,0,0,0,0,0,0,0,0,0,0,0,0,0,0,0
0,0,0,0,0,0,0,0,0,0,0,0,0,0,0,0,0,0,0,0,0,0,0,0,0,0,0,0,0,0,0
0,0,0,0,0,0,0,0,0,0,0,0,0,0,0,0,0,0,0,0,0,0,0,0,0,0,0,0,0,0,0
0,0,0,0,0,0,0,0,0,0,0,0,0,0,0,0,0,0,0,0,0,0,0,0,0,0,0,0,0,0,0
0,0,0,0,0,0,0,0,0,0,0,0,0,0,0,0,0,0,0,0,0,0,0,0,0,0,0,0,0,0,0
0,0,0,0,0,0,0,0,0,0,0,0,0,0,0,0,0,0,0,0,0,0,0,0,0,0,0,0,0,0,0
endlayer

layer
0,0,0,0,0,0,0,0,0,0,0,0,0,0,0,0,0,0,0,0,0,0,0,0,0,0,0,0,0,0,0
0,0,0,0,0,0,0,0,0,0,0,0,0,0,0,0,0,0,0,0,0,0,0,0,0,0,0,0,0,0,0
0,0,0,0,0,0,0,0,0,0,0,0,0,0,0,0,0,0,0,0,0,0,0,0,0,0,0,0,0,0,0
0,0,0,0,0,0,0,0,0,0,0,0,0,0,0,0,0,0,0,0,0,0,0,0,0,0,0,0,0,0,0
0,0,0,0,0,0,0,0,0,0,0,0,0,0,0,0,0,0,0,0,0,0,0,0,0,0,0,0,0,0,0
0,0,0,0,0,0,0,0,0,0,0,0,0,0,0,0,0,0,0,0,0,0,0,0,0,0,0,0,0,0,0
0,0,0,0,0,0,0,0,0,0,0,0,0,0,0,0,0,0,0,0,0,0,0,0,0,0,0,0,0,0,0
0,0,0,0,0,0,0,0,0,0,0,0,0,0,0,0,0,0,0,0,0,0,0,0,0,0,0,0,0,0,0
0,0,0,0,0,0,0,0,0,0,0,0,0,0,0,0,0,0,0,0,0,0,0,0,0,0,0,0,0,0,0
0,0,0,0,0,0,0,0,0,0,0,0,0,0,0,0,0,0,0,0,0,0,0,0,0,0,0,0,0,0,0
0,0,0,0,0,0,0,0,0,0,0,0,0,0,0,0,0,0,0,0,0,0,0,0,0,0,0,0,0,0,0
0,0,0,0,0,0,0,0,0,0,0,0,0,0,0,0,0,0,0,0,0,0,0,0,0,0,0,0,0,0,0
0,0,0,0,0,0,0,0,0,0,0,0,0,0,0,0,0,0,0,0,0,0,0,0,0,0,0,0,0,0,0
0,0,0,0,0,0,0,0,0,0,0,0,0,0,0,0,0,0,0,0,0,0,0,0,0,0,0,0,0,0,0
0,0,0,0,0,0,0,0,0,0,0,0,0,0,0,0,0,0,0,0,0,0,0,0,0,0,0,0,0,0,0
0,0,0,0,0,0,0,0,0,0,0,0,0,0,0,0,0,0,0,0,0,0,0,0,0,0,0,0,0,0,0
0,0,0,0,0,0,0,0,0,0,0,17,39,39,39,17,0,0,0,0,0,0,0,0,0,0,0,0,0,0,0
0,0,0,0,0,0,0,0,0,0,39,0,0,0,0,0,39,0,0,0,0,0,0,0,0,0,0,0,0,0,0
0,0,0,0,0,0,0,0,0,17,0,0,0,0,0,0,0,17,0,0,0,0,0,0,0,0,0,0,0,0,0
0,0,0,0,0,0,0,0,0,39,0,0,0,0,0,0,0,39,0,0,0,0,0,0,0,0,0,0,0,0,0
0,0,0,0,0,0,0,0,0,39,0,0,0,18,0,0,0,39,0,0,0,0,0,0,0,0,0,0,0,0,0
0,0,0,0,0,0,0,0,0,39,0,0,0,0,0,0,0,39,0,0,0,0,0,0,0,0,0,0,0,0,0
0,0,0,0,0,0,0,0,0,17,0,0,0,0,0,0,0,17,0,0,0,0,0,0,0,0,0,0,0,0,0
0,0,0,0,0,0,0,0,0,0,39,0,0,0,0,0,39,0,0,0,0,0,0,0,0,0,0,0,0,0,0
0,0,0,0,0,0,0,0,0,0,0,17,39,39,39,17,0,0,0,0,0,0,0,0,0,0,0,0,0,0,0
0,0,0,0,0,0,0,0,0,0,0,0,0,0,0,0,0,0,0,0,0,0,0,0,0,0,0,0,0,0,0
0,0,0,0,0,0,0,0,0,0,0,0,0,0,0,0,0,0,0,0,0,0,0,0,0,0,0,0,0,0,0
0,0,0,0,0,0,0,0,0,0,0,0,0,0,0,0,0,0,0,0,0,0,0,0,0,0,0,0,0,0,0
0,0,0,0,0,0,0,0,0,0,0,0,0,0,0,0,0,0,0,0,0,0,0,0,0,0,0,0,0,0,0
0,0,0,0,0,0,0,0,0,0,0,0,0,0,0,0,0,0,0,0,0,0,0,0,0,0,0,0,0,0,0
0,0,0,0,0,0,0,0,0,0,0,0,0,0,0,0,0,0,0,0,0,0,0,0,0,0,0,0,0,0,0
endlayer

layer
0,0,0,0,0,0,0,0,0,0,0,0,0,0,0,0,0,0,0,0,0,0,0,0,0,0,0,0,0,0,0
0,0,0,0,0,0,0,0,0,0,0,0,0,0,0,0,0,0,0,0,0,0,0,0,0,0,0,0,0,0,0
0,0,0,0,0,0,0,0,0,0,0,0,0,0,0,0,0,0,0,0,0,0,0,0,0,0,0,0,0,0,0
0,0,0,0,0,0,0,0,0,0,0,0,0,0,0,0,0,0,0,0,0,0,0,0,0,0,0,0,0,0,0
0,0,0,0,0,0,0,0,0,0,0,0,0,0,0,0,0,0,0,0,0,0,0,0,0,0,0,0,0,0,0
0,0,0,0,0,0,0,0,0,0,0,0,0,0,0,0,0,0,0,0,0,0,0,0,0,0,0,0,0,0,0
0,0,0,0,0,0,0,0,0,0,0,0,0,0,0,0,0,0,0,0,0,0,0,0,0,0,0,0,0,0,0
0,0,0,0,0,0,0,0,0,0,0,0,0,0,0,0,0,0,0,0,0,0,0,0,0,0,0,0,0,0,0
0,0,0,0,0,0,0,0,0,0,0,0,0,0,0,0,0,0,0,0,0,0,0,0,0,0,0,0,0,0,0
0,0,0,0,0,0,0,0,0,0,0,0,0,0,0,0,0,0,0,0,0,0,0,0,0,0,0,0,0,0,0
0,0,0,0,0,0,0,0,0,0,0,0,0,0,0,0,0,0,0,0,0,0,0,0,0,0,0,0,0,0,0
0,0,0,0,0,0,0,0,0,0,0,0,0,0,0,0,0,0,0,0,0,0,0,0,0,0,0,0,0,0,0
0,0,0,0,0,0,0,0,0,0,0,0,0,0,0,0,0,0,0,0,0,0,0,0,0,0,0,0,0,0,0
0,0,0,0,0,0,0,0,0,0,0,0,0,0,0,0,0,0,0,0,0,0,0,0,0,0,0,0,0,0,0
0,0,0,0,0,0,0,0,0,0,0,0,0,0,0,0,0,0,0,0,0,0,0,0,0,0,0,0,0,0,0
0,0,0,0,0,0,0,0,0,0,0,0,0,0,0,0,0,0,0,0,0,0,0,0,0,0,0,0,0,0,0
0,0,0,0,0,0,0,0,0,0,0,17,39,39,39,17,0,0,0,0,0,0,0,0,0,0,0,0,0,0,0
0,0,0,0,0,0,0,0,0,0,39,0,0,0,0,0,39,0,0,0,0,0,0,0,0,0,0,0,0,0,0
0,0,0,0,0,0,0,0,0,17,0,0,0,0,0,0,0,17,0,0,0,0,0,0,0,0,0,0,0,0,0
0,0,0,0,0,0,0,0,0,39,0,0,0,18,0,0,0,39,0,0,0,0,0,0,0,0,0,0,0,0,0
0,0,0,0,0,0,0,0,0,39,0,0,18,18,18,0,0,39,0,0,0,0,0,0,0,0,0,0,0,0,0
0,0,0,0,0,0,0,0,0,39,0,0,0,18,0,0,0,39,0,0,0,0,0,0,0,0,0,0,0,0,0
0,0,0,0,0,0,0,0,0,17,0,0,0,0,0,0,0,17,0,0,0,0,0,0,0,0,0,0,0,0,0
0,0,0,0,0,0,0,0,0,0,39,0,0,0,0,0,39,0,0,0,0,0,0,0,0,0,0,0,0,0,0
0,0,0,0,0,0,0,0,0,0,0,17,39,39,39,17,0,0,0,0,0,0,0,0,0,0,0,0,0,0,0
0,0,0,0,0,0,0,0,0,0,0,0,0,0,0,0,0,0,0,0,0,0,0,0,0,0,0,0,0,0,0
0,0,0,0,0,0,0,0,0,0,0,0,0,0,0,0,0,0,0,0,0,0,0,0,0,0,0,0,0,0,0
0,0,0,0,0,0,0,0,0,0,0,0,0,0,0,0,0,0,0,0,0,0,0,0,0,0,0,0,0,0,0
0,0,0,0,0,0,0,0,0,0,0,0,0,0,0,0,0,0,0,0,0,0,0,0,0,0,0,0,0,0,0
0,0,0,0,0,0,0,0,0,0,0,0,0,0,0,0,0,0,0,0,0,0,0,0,0,0,0,0,0,0,0
0,0,0,0,0,0,0,0,0,0,0,0,0,0,0,0,0,0,0,0,0,0,0,0,0,0,0,0,0,0,0
endlayer

layer
0,0,0,0,0,0,0,0,0,0,0,0,0,0,0,0,0,0,0,0,0,0,0,0,0,0,0,0,0,0,0
0,0,0,0,0,0,0,0,0,0,0,0,0,0,0,0,0,0,0,0,0,0,0,0,0,0,0,0,0,0,0
0,0,0,0,0,0,0,0,0,0,0,0,0,0,0,0,0,0,0,0,0,0,0,0,0,0,0,0,0,0,0
0,0,0,0,0,0,0,0,0,0,0,0,0,0,0,0,0,0,0,0,0,0,0,0,0,0,0,0,0,0,0
0,0,0,0,0,0,0,0,0,0,0,0,0,0,0,0,0,0,0,0,0,0,0,0,0,0,0,0,0,0,0
0,0,0,0,0,0,0,0,0,0,0,0,0,0,0,0,0,0,0,0,0,0,0,0,0,0,0,0,0,0,0
0,0,0,0,0,0,0,0,0,0,0,0,0,0,0,0,0,0,0,0,0,0,0,0,0,0,0,0,0,0,0
0,0,0,0,0,0,0,0,0,0,0,0,0,0,0,0,0,0,0,0,0,0,0,0,0,0,0,0,0,0,0
0,0,0,0,0,0,0,0,0,0,0,0,0,0,0,0,0,0,0,0,0,0,0,0,0,0,0,0,0,0,0
0,0,0,0,0,0,0,0,0,0,0,0,0,0,0,0,0,0,0,0,0,0,0,0,0,0,0,0,0,0,0
0,0,0,0,0,0,0,0,0,0,0,0,0,0,0,0,0,0,0,0,0,0,0,0,0,0,0,0,0,0,0
0,0,0,0,0,0,0,0,0,0,0,0,0,0,0,0,0,0,0,0,0,0,0,0,0,0,0,0,0,0,0
0,0,0,0,0,0,0,0,0,0,0,0,0,0,0,0,0,0,0,0,0,0,0,0,0,0,0,0,0,0,0
0,0,0,0,0,0,0,0,0,0,0,0,0,0,0,0,0,0,0,0,0,0,0,0,0,0,0,0,0,0,0
0,0,0,0,0,0,0,0,0,0,0,10,8,8,8,7,0,0,0,0,0,0,0,0,0,0,0,0,0,0,0
0,0,0,0,0,0,0,0,0,10,8,8,11,11,11,8,8,7,0,0,0,0,0,0,0,0,0,0,0,0,0
0,0,0,0,0,0,0,0,10,8,11,11,11,11,11,11,11,8,7,0,0,0,0,0,0,0,0,0,0,0,0
0,0,0,0,0,0,0,0,10,11,11,4,4,4,4,4,11,11,7,0,0,0,0,0,0,0,0,0,0,0,0
0,0,0,0,0,0,0,10,8,11,6,0,0,0,0,0,3,11,8,7,0,0,0,0,0,0,0,0,0,0,0
0,0,0,0,0,0,0,10,11,11,6,0,0,0,0,0,3,11,11,7,0,0,0,0,0,0,0,0,0,0,0
0,0,0,0,0,0,0,10,11,11,6,0,0,18,0,0,3,11,11,7,0,0,0,0,0,0,0,0,0,0,0
0,0,0,0,0,0,0,10,11,11,6,0,0,0,0,0,3,11,11,7,0,0,0,0,0,0,0,0,0,0,0
0,0,0,0,0,0,0,10,9,11,6,0,0,0,0,0,3,11,7,9,0,0,0,0,0,0,0,0,0,0,0
0,0,0,0,0,0,0,0,10,11,11,5,5,5,5,5,11,11,7,0,0,0,0,0,0,0,0,0,0,0,0
0,0,0,0,0,0,0,0,10,9,11,11,11,11,11,11,11,7,9,0,0,0,0,0,0,0,0,0,0,0,0
0,0,0,0,0,0,0,0,0,10,9,9,11,11,11,7,9,9,0,0,0,0,0,0,0,0,0,0,0,0,0
0,0,0,0,0,0,0,0,0,0,0,10,9,9,9,9,0,0,0,0,0,0,0,0,0,0,0,0,0,0,0
0,0,0,0,0,0,0,0,0,0,0,0,0,0,0,0,0,0,0,0,0,0,0,0,0,0,0,0,0,0,0
0,0,0,0,0,0,0,0,0,0,0,0,0,0,0,0,0,0,0,0,0,0,0,0,0,0,0,0,0,0,0
0,0,0,0,0,0,0,0,0,0,0,0,0,0,0,0,0,0,0,0,0,0,0,0,0,0,0,0,0,0,0
0,0,0,0,0,0,0,0,0,0,0,0,0,0,0,0,0,0,0,0,0,0,0,0,0,0,0,0,0,0,0
endlayer

layer
0,0,0,0,0,0,0,0,0,0,0,0,0,0,0,0,0,0,0,0,0,0,0,0,0,0,0,0,0,0,0
0,0,0,0,0,0,0,0,0,0,0,0,0,0,0,0,0,0,0,0,0,0,0,0,0,0,0,0,0,0,0
0,0,0,0,0,0,0,0,0,0,0,0,0,0,0,0,0,0,0,0,0,0,0,0,0,0,0,0,0,0,0
0,0,0,0,0,0,0,0,0,0,0,0,0,0,0,0,0,0,0,0,0,0,0,0,0,0,0,0,0,0,0
0,0,0,0,0,0,0,0,0,0,0,0,0,0,0,0,0,0,0,0,0,0,0,0,0,0,0,0,0,0,0
0,0,0,0,0,0,0,0,0,0,0,0,0,0,0,0,0,0,0,0,0,0,0,0,0,0,0,0,0,0,0
0,0,0,0,0,0,0,0,0,0,0,0,0,0,0,0,0,0,0,0,0,0,0,0,0,0,0,0,0,0,0
0,0,0,0,0,0,0,0,0,0,0,0,0,0,0,0,0,0,0,0,0,0,0,0,0,0,0,0,0,0,0
0,0,0,0,0,0,0,0,0,0,0,0,0,0,0,0,0,0,0,0,0,0,0,0,0,0,0,0,0,0,0
0,0,0,0,0,0,0,0,0,0,0,0,0,0,0,0,0,0,0,0,0,0,0,0,0,0,0,0,0,0,0
0,0,0,0,0,0,0,0,0,0,0,0,0,0,0,0,0,0,0,0,0,0,0,0,0,0,0,0,0,0,0
0,0,0,0,0,0,0,0,0,0,0,0,0,0,0,0,0,0,0,0,0,0,0,0,0,0,0,0,0,0,0
0,0,0,0,0,0,0,0,0,0,0,0,0,0,0,0,0,0,0,0,0,0,0,0,0,0,0,0,0,0,0
0,0,0,0,0,0,0,0,0,0,0,0,0,0,0,0,0,0,0,0,0,0,0,0,0,0,0,0,0,0,0
0,0,0,0,0,0,0,0,0,0,0,0,0,0,0,0,0,0,0,0,0,0,0,0,0,0,0,0,0,0,0
0,0,0,0,0,0,0,0,0,0,0,0,0,0,0,0,0,0,0,0,0,0,0,0,0,0,0,0,0,0,0
0,0,0,0,0,0,0,0,0,0,0,8,8,8,8,8,0,0,0,0,0,0,0,0,0,0,0,0,0,0,0
0,0,0,0,0,0,0,0,0,0,8,10,11,11,11,7,8,0,0,0,0,0,0,0,0,0,0,0,0,0,0
0,0,0,0,0,0,0,0,0,8,10,11,11,11,11,11,7,8,0,0,0,0,0,0,0,0,0,0,0,0,0
0,0,0,0,0,0,0,0,0,10,11,11,11,11,11,11,11,7,0,0,0,0,0,0,0,0,0,0,0,0,0
0,0,0,0,0,0,0,0,0,10,11,11,11,11,11,11,11,7,0,0,0,0,0,0,0,0,0,0,0,0,0
0,0,0,0,0,0,0,0,0,10,11,11,11,11,11,11,11,7,0,0,0,0,0,0,0,0,0,0,0,0,0
0,0,0,0,0,0,0,0,0,10,9,11,11,11,11,11,7,9,0,0,0,0,0,0,0,0,0,0,0,0,0
0,0,0,0,0,0,0,0,0,0,10,9,11,11,11,7,9,0,0,0,0,0,0,0,0,0,0,0,0,0,0
0,0,0,0,0,0,0,0,0,0,0,10,9,9,9,9,0,0,0,0,0,0,0,0,0,0,0,0,0,0,0
0,0,0,0,0,0,0,0,0,0,0,0,0,0,0,0,0,0,0,0,0,0,0,0,0,0,0,0,0,0,0
0,0,0,0,0,0,0,0,0,0,0,0,0,0,0,0,0,0,0,0,0,0,0,0,0,0,0,0,0,0,0
0,0,0,0,0,0,0,0,0,0,0,0,0,0,0,0,0,0,0,0,0,0,0,0,0,0,0,0,0,0,0
0,0,0,0,0,0,0,0,0,0,0,0,0,0,0,0,0,0,0,0,0,0,0,0,0,0,0,0,0,0,0
0,0,0,0,0,0,0,0,0,0,0,0,0,0,0,0,0,0,0,0,0,0,0,0,0,0,0,0,0,0,0
0,0,0,0,0,0,0,0,0,0,0,0,0,0,0,0,0,0,0,0,0,0,0,0,0,0,0,0,0,0,0
endlayer

layer
0,0,0,0,0,0,0,0,0,0,0,0,0,0,0,0,0,0,0,0,0,0,0,0,0,0,0,0,0,0,0
0,0,0,0,0,0,0,0,0,0,0,0,0,0,0,0,0,0,0,0,0,0,0,0,0,0,0,0,0,0,0
0,0,0,0,0,0,0,0,0,0,0,0,0,0,0,0,0,0,0,0,0,0,0,0,0,0,0,0,0,0,0
0,0,0,0,0,0,0,0,0,0,0,0,0,0,0,0,0,0,0,0,0,0,0,0,0,0,0,0,0,0,0
0,0,0,0,0,0,0,0,0,0,0,0,0,0,0,0,0,0,0,0,0,0,0,0,0,0,0,0,0,0,0
0,0,0,0,0,0,0,0,0,0,0,0,0,0,0,0,0,0,0,0,0,0,0,0,0,0,0,0,0,0,0
0,0,0,0,0,0,0,0,0,0,0,0,0,0,0,0,0,0,0,0,0,0,0,0,0,0,0,0,0,0,0
0,0,0,0,0,0,0,0,0,0,0,0,0,0,0,0,0,0,0,0,0,0,0,0,0,0,0,0,0,0,0
0,0,0,0,0,0,0,0,0,0,0,0,0,0,0,0,0,0,0,0,0,0,0,0,0,0,0,0,0,0,0
0,0,0,0,0,0,0,0,0,0,0,0,0,0,0,0,0,0,0,0,0,0,0,0,0,0,0,0,0,0,0
0,0,0,0,0,0,0,0,0,0,0,0,0,0,0,0,0,0,0,0,0,0,0,0,0,0,0,0,0,0,0
0,0,0,0,0,0,0,0,0,0,0,0,0,0,0,0,0,0,0,0,0,0,0,0,0,0,0,0,0,0,0
0,0,0,0,0,0,0,0,0,0,0,0,0,0,0,0,0,0,0,0,0,0,0,0,0,0,0,0,0,0,0
0,0,0,0,0,0,0,0,0,0,0,0,0,0,0,0,0,0,0,0,0,0,0,0,0,0,0,0,0,0,0
0,0,0,0,0,0,0,0,0,0,0,0,0,0,0,0,0,0,0,0,0,0,0,0,0,0,0,0,0,0,0
0,0,0,0,0,0,0,0,0,0,0,0,0,0,0,0,0,0,0,0,0,0,0,0,0,0,0,0,0,0,0
0,0,0,0,0,0,0,0,0,0,0,0,0,0,0,0,0,0,0,0,0,0,0,0,0,0,0,0,0,0,0
0,0,0,0,0,0,0,0,0,0,0,0,0,0,0,0,0,0,0,0,0,0,0,0,0,0,0,0,0,0,0
0,0,0,0,0,0,0,0,0,0,0,0,8,8,8,0,0,0,0,0,0,0,0,0,0,0,0,0,0,0,0
0,0,0,0,0,0,0,0,0,0,0,10,11,11,11,7,0,0,0,0,0,0,0,0,0,0,0,0,0,0,0
0,0,0,0,0,0,0,0,0,0,0,10,11,11,11,7,0,0,0,0,0,0,0,0,0,0,0,0,0,0,0
0,0,0,0,0,0,0,0,0,0,0,10,11,11,11,7,0,0,0,0,0,0,0,0,0,0,0,0,0,0,0
0,0,0,0,0,0,0,0,0,0,0,0,9,9,9,0,0,0,0,0,0,0,0,0,0,0,0,0,0,0,0
0,0,0,0,0,0,0,0,0,0,0,0,0,0,0,0,0,0,0,0,0,0,0,0,0,0,0,0,0,0,0
0,0,0,0,0,0,0,0,0,0,0,0,0,0,0,0,0,0,0,0,0,0,0,0,0,0,0,0,0,0,0
0,0,0,0,0,0,0,0,0,0,0,0,0,0,0,0,0,0,0,0,0,0,0,0,0,0,0,0,0,0,0
0,0,0,0,0,0,0,0,0,0,0,0,0,0,0,0,0,0,0,0,0,0,0,0,0,0,0,0,0,0,0
0,0,0,0,0,0,0,0,0,0,0,0,0,0,0,0,0,0,0,0,0,0,0,0,0,0,0,0,0,0,0
0,0,0,0,0,0,0,0,0,0,0,0,0,0,0,0,0,0,0,0,0,0,0,0,0,0,0,0,0,0,0
0,0,0,0,0,0,0,0,0,0,0,0,0,0,0,0,0,0,0,0,0,0,0,0,0,0,0,0,0,0,0
0,0,0,0,0,0,0,0,0,0,0,0,0,0,0,0,0,0,0,0,0,0,0,0,0,0,0,0,0,0,0
endlayer

