
# Created by Ruins mod version 17.0 Ingame Parser
# authoring Player: ST753M

weight=1
embed_into_distance=10
uniqueMinDistance=256
acceptable_target_blocks=
unacceptable_target_blocks=flowing_water,water,flowing_lava,lava,ice,bedrock,netherrack,nether_brick,nether_brick_fence,soul_sand,quartz_ore,end_stone,obsidian,iron_bars,Natura:Cloud,slime_grass,slime_congealed,slime_dirt,clouds,natura:clouds
dimensions=11,11,11
allowable_overhang=16
max_leveling=0
leveling_buffer=-1
preserve_water=0
preserve_lava=0

biomesToSpawnIn=plains,prairie,shrubland,chaparral,grassland,meadow,orchard,rocky_plains,rocky_plateau,crystal_forest,origin_island,enchanted_forest,mystic_grove,magical_forest,savanna,savanna_rock,mutated_savanna,mutated_savanna_rock,brushland,steppe,wasteland,tundra,outback,badlands,desert_shrubland,arid_highland,dark_forest,dark_forest_center,deep_mushroom_forest,dense_twilight_forest,enchanted_forest,fire_swamp,firefly_forest,highlands_center,mushroom_forest,oak_savannah,thornlands,twilight_clearing,twilight_forest,twilight_glacier,twilight_highlands,twilight_lake,twilight_stream,twilight_swamp

=0,100,air
rule1=0,100,preserveBlock
rule2=0,100,minecraft:dirt-0

rule3=0,100,botania:altgrass-0
^0,100,botania:altgrass-1
^0,100,botania:altgrass-2
^0,100,botania:altgrass-3
^0,100,botania:altgrass-4
^0,100,botania:altgrass-5

rule4^0,100,minecraft:water-0
^0,100,minecraft:water-0
^0,100,minecraft:water-0
^0,100,minecraft:lava-0
^0,100,minecraft:water-0
^0,100,minecraft:water-0

rule5^0,100,air,minecraft:red_flower-1,botania:mushroom-5,botania:flower-14,botania:shinyflower-7,botania:flower-13,botania:flower-10,botania:flower-6
^0,100,air,minecraft:yellow_flower-0,minecraft:red_flower-0,botania:mushroom-0,botania:shinyflower-4,botania:shinyflower-1,botania:flower-7,botania:flower-12
^0,100,air,botania:mushroom-5,minecraft:red_flower-3,botania:shinyflower-13,botania:mushroom-13,botania:shinyflower-4,botania:shinyflower-5,botania:flower-5
^0,100,air,botania:mushroom-14,botania:shinyflower-14,botania:flower-15,botania:shinyflower-12,botania:flower-1,botania:flower-4
^0,100,air,botania:mushroom-9,botania:shinyflower-11,botania:shinyflower-9,botania:shinyflower-8,botania:shinyflower-0,botania:shinyflower-3,botania:flower-11
^0,100,air,botania:mushroom-10,botania:shinyflower-10,botania:shinyflower-6,botania:shinyflower-3,botania:shinyflower-0,botania:flower-2,botania:flower-9

rule6=0,100,minecraft:vine-2
rule7=0,100,minecraft:vine-1
rule8=0,100,minecraft:vine-4
rule9=0,100,minecraft:vine-8

layer
1,1,1,1,1,1,1,1,1,1,1
1,1,1,1,1,1,1,1,1,1,1
1,1,1,1,2,2,2,1,1,1,1
1,1,1,2,2,2,2,1,1,1,1
1,1,2,2,2,2,2,2,1,1,1
1,1,2,2,2,2,2,2,1,1,1
1,1,1,2,2,2,2,2,1,1,1
1,1,1,1,2,2,2,1,1,1,1
1,1,1,1,1,1,1,1,1,1,1
1,1,1,1,1,1,1,1,1,1,1
1,1,1,1,1,1,1,1,1,1,1
endlayer

layer
1,1,1,1,1,1,1,1,1,1,1
1,1,1,1,2,3,1,1,1,1,1
1,1,2,3,3,3,2,2,1,1,1
1,1,3,3,4,4,3,2,2,1,1
1,2,3,4,4,4,4,2,2,2,1
1,3,3,4,4,4,4,3,2,2,1
1,1,2,3,4,4,3,3,3,1,1
1,1,2,2,3,3,3,3,3,1,1
1,1,1,1,2,2,3,1,1,1,1
1,1,1,1,1,1,1,1,1,1,1
1,1,1,1,1,1,1,1,1,1,1
endlayer

layer
1,1,1,2,2,2,1,1,1,1,1
1,1,2,3,3,5,3,2,1,1,1
1,2,2,5,0,0,3,3,2,1,1
1,2,5,0,0,0,5,3,2,2,1
2,3,0,0,0,0,0,3,3,2,1
2,5,0,0,0,0,0,0,3,2,1
2,3,3,5,0,0,0,5,0,3,1
1,2,3,3,5,5,0,5,0,2,1
1,2,3,3,3,3,5,2,2,1,1
1,1,1,2,2,3,3,2,1,1,1
1,1,1,1,1,1,1,1,1,1,1
endlayer

layer
1,1,1,2,2,2,2,2,1,1,1
1,1,2,5,5,6,5,3,2,1,1
1,2,3,0,0,0,0,5,3,2,1
1,2,0,0,0,0,0,5,3,2,2
2,5,0,0,0,0,0,0,0,2,2
2,0,0,0,0,0,0,0,5,3,2
2,0,5,0,0,0,0,0,0,5,2
2,3,5,0,0,0,0,0,0,2,2
1,2,5,0,5,0,0,3,2,2,1
1,2,2,2,3,5,5,2,2,2,1
1,1,1,2,2,2,2,1,1,1,1
endlayer

layer
1,1,1,2,2,2,2,2,1,1,1
1,1,2,0,0,6,0,5,2,2,1
1,2,5,0,0,0,0,0,5,2,1
1,2,0,0,0,0,0,0,5,2,2
2,0,0,0,0,0,0,0,0,3,2
2,0,0,0,0,0,0,0,0,5,2
2,0,0,0,0,0,0,0,0,0,2
2,5,0,0,0,0,0,0,0,2,2
1,2,0,0,0,0,0,5,3,2,1
1,2,2,3,5,0,0,2,2,2,1
1,1,1,2,2,2,2,1,1,1,1
endlayer

layer
1,1,1,2,2,2,2,2,1,1,1
1,1,2,7,6,0,6,6,2,2,1
1,2,6,0,0,0,0,0,8,2,1
1,2,0,0,0,0,0,0,0,2,2
2,6,0,0,0,0,0,0,0,5,3
2,0,0,0,0,0,0,0,0,0,2
2,0,0,0,0,0,0,0,0,9,2
2,7,0,0,0,0,0,0,0,2,2
1,2,0,0,0,0,0,0,5,2,1
1,2,2,5,0,0,9,2,2,2,1
1,1,1,2,2,2,2,1,1,1,1
endlayer

layer
1,1,1,1,2,2,2,1,1,1,1
1,1,2,2,0,6,6,2,1,1,1
1,2,0,0,0,0,0,6,2,1,1
1,2,0,0,0,0,0,0,0,2,1
2,6,0,0,0,0,0,0,0,2,1
2,7,0,0,0,0,0,0,0,8,2
2,0,0,0,0,0,0,0,0,2,2
1,2,0,0,0,0,0,0,8,2,1
1,2,0,0,0,0,9,9,2,1,1
1,1,2,0,0,9,2,2,1,1,1
1,1,1,2,2,2,1,1,1,1,1
endlayer

layer
1,1,1,1,1,2,1,1,1,1,1
1,1,1,2,2,0,2,2,1,1,1
1,1,2,6,0,0,0,0,2,1,1
1,2,7,0,0,0,0,8,2,1,1
1,2,7,0,0,0,0,0,0,2,1
2,7,0,0,0,0,0,0,0,2,1
1,2,0,0,0,0,0,0,8,2,1
1,2,7,0,0,0,0,0,0,2,1
1,1,2,9,0,9,9,2,2,1,1
1,1,2,2,0,2,2,1,1,1,1
1,1,1,1,2,1,1,1,1,1,1
endlayer

layer
1,1,1,1,1,1,1,1,1,1,1
1,1,1,1,2,2,2,1,1,1,1
1,1,1,2,2,2,2,2,1,1,1
1,1,2,2,0,6,8,2,2,1,1
1,2,2,6,0,0,0,6,2,1,1
1,2,0,0,0,0,0,0,2,2,1
1,2,2,7,0,0,0,0,2,1,1
1,1,2,2,0,9,8,2,2,1,1
1,1,2,2,2,2,2,2,1,1,1
1,1,1,1,2,2,1,1,1,1,1
1,1,1,1,1,1,1,1,1,1,1
endlayer

layer
1,1,1,1,1,1,1,1,1,1,1
1,1,1,1,1,1,1,1,1,1,1
1,1,1,1,1,1,1,1,1,1,1
1,1,1,1,2,2,2,1,1,1,1
1,1,1,2,0,0,8,2,1,1,1
1,1,2,2,0,0,0,2,1,1,1
1,1,1,2,0,9,0,2,1,1,1
1,1,1,1,2,2,2,1,1,1,1
1,1,1,1,1,1,1,1,1,1,1
1,1,1,1,1,1,1,1,1,1,1
1,1,1,1,1,1,1,1,1,1,1
endlayer

layer
1,1,1,1,1,1,1,1,1,1,1
1,1,1,1,1,1,1,1,1,1,1
1,1,1,1,1,1,1,1,1,1,1
1,1,1,1,1,1,1,1,1,1,1
1,1,1,1,0,0,0,1,1,1,1
1,1,1,1,0,0,0,1,1,1,1
1,1,1,1,0,0,0,1,1,1,1
1,1,1,1,1,1,1,1,1,1,1
1,1,1,1,1,1,1,1,1,1,1
1,1,1,1,1,1,1,1,1,1,1
1,1,1,1,1,1,1,1,1,1,1
endlayer

