
# Created by Ruins mod version 17.0 Ingame Parser
# authoring Player: ST753M

weight=1
embed_into_distance=4
acceptable_target_blocks=
unacceptable_target_blocks=flowing_water,water,flowing_lava,lava,ice,bedrock,netherrack,nether_brick,nether_brick_fence,soul_sand,quartz_ore,end_stone,obsidian,iron_bars,Natura:Cloud,slime_grass,slime_congealed,slime_dirt,clouds,natura:clouds
dimensions=11,21,21
allowable_overhang=4
max_leveling=2
leveling_buffer=-1
preserve_water=1
preserve_lava=1

biomesToSpawnIn=beaches,white_beach,kelp_forest,ocean,coral_reef,coralium_infested_ocean,jungle,jungle_hills,tropical_island,birch_forest,birch_forest_hills,mutated_birch_forest,mutated_birch_forest_hills,birch_forested_hills,cherry_blossom_grove,mutated_forest,mutated_plains,flower_field,lavender_fields,flower_island,orchard,crystal_forest,origin_island,enchanted_forest,mystic_grove,magical_forest

=0,100,preserveBlock
rule1=1,80,botania:livingrock-3,botania:livingrock-1,botania:livingrock-2
rule2=2,60,botania:livingrock-3,botania:livingrock-1,botania:livingrock-2
rule3=1,20,ChestGenHook:chests/jungle_temple:2-2,ChestGenHook:chests/simple_dungeon:2-2

layer
0,0,0,0,0,0,0,0,0,0,0,0,0,0,0,0,0,0,0,0,0
0,0,0,0,0,0,0,0,1,1,1,1,1,0,0,0,0,0,0,0,0
0,0,0,0,0,0,1,1,0,0,0,0,0,1,1,0,0,0,0,0,0
0,0,0,0,1,1,0,0,0,0,0,0,0,0,0,1,1,0,0,0,0
0,0,0,1,0,0,0,0,0,0,0,0,0,0,0,0,0,1,0,0,0
0,0,0,1,0,0,0,0,0,0,0,0,0,0,0,0,0,1,0,0,0
0,0,1,0,0,0,0,0,0,0,0,0,0,0,0,0,0,0,1,0,0
0,0,1,0,0,0,0,0,0,0,0,0,0,0,0,0,0,0,1,0,0
0,1,0,0,0,0,0,0,0,0,0,0,0,0,0,0,0,0,0,1,0
0,1,0,0,0,0,0,0,0,0,0,0,0,0,0,0,0,0,0,1,0
0,1,0,0,0,0,0,0,0,0,0,0,0,0,0,0,0,0,0,1,0
0,1,0,0,0,0,0,0,0,0,0,0,0,0,0,0,0,0,0,1,0
0,1,0,0,0,0,0,0,0,0,0,0,0,0,0,0,0,0,0,1,0
0,0,1,0,0,0,0,0,0,0,0,0,0,0,0,0,0,0,1,0,0
0,0,1,0,0,0,0,0,0,0,0,0,0,0,0,0,0,0,1,0,0
0,0,0,1,0,0,0,0,0,0,0,0,0,0,0,0,0,1,0,0,0
0,0,0,1,0,0,0,0,0,0,0,0,0,0,0,0,0,1,0,0,0
0,0,0,0,1,1,0,0,0,0,0,0,0,0,0,1,1,0,0,0,0
0,0,0,0,0,0,1,1,0,0,0,0,0,1,1,0,0,0,0,0,0
0,0,0,0,0,0,0,0,1,1,1,1,1,0,0,0,0,0,0,0,0
0,0,0,0,0,0,0,0,0,0,0,0,0,0,0,0,0,0,0,0,0
endlayer

layer
0,0,0,0,0,0,0,0,0,0,0,0,0,0,0,0,0,0,0,0,0
0,0,0,0,0,0,0,0,1,1,1,1,1,0,0,0,0,0,0,0,0
0,0,0,0,0,0,1,1,0,0,0,0,0,1,1,0,0,0,0,0,0
0,0,0,0,1,1,0,0,0,0,0,0,0,0,0,1,1,0,0,0,0
0,0,0,1,0,0,0,0,0,0,0,0,0,0,0,0,0,1,0,0,0
0,0,0,1,0,0,0,0,0,0,0,0,0,0,0,0,0,1,0,0,0
0,0,1,0,0,0,0,0,0,0,0,0,0,0,0,0,0,0,1,0,0
0,0,1,0,0,0,0,0,0,0,0,0,0,0,0,0,0,0,1,0,0
0,1,0,0,0,0,0,0,0,0,0,0,0,0,0,0,0,0,0,1,0
0,1,0,0,0,0,0,0,0,0,0,0,0,0,0,0,0,0,0,1,0
0,1,0,0,0,0,0,0,0,0,0,0,0,0,0,0,0,0,0,1,0
0,1,0,0,0,0,0,0,0,0,0,0,0,0,0,0,0,0,0,1,0
0,1,0,0,0,0,0,0,0,0,0,0,0,0,0,0,0,0,0,1,0
0,0,1,0,0,0,0,0,0,0,0,0,0,0,0,0,0,0,1,0,0
0,0,1,0,0,0,0,0,0,0,0,0,0,0,0,0,0,0,1,0,0
0,0,0,1,0,0,0,0,0,0,0,0,0,0,0,0,0,1,0,0,0
0,0,0,1,0,0,0,0,0,0,0,0,0,0,0,0,0,1,0,0,0
0,0,0,0,1,1,0,0,0,0,0,0,0,0,0,1,1,0,0,0,0
0,0,0,0,0,0,1,1,0,0,0,0,0,1,1,0,0,0,0,0,0
0,0,0,0,0,0,0,0,1,1,1,1,1,0,0,0,0,0,0,0,0
0,0,0,0,0,0,0,0,0,0,0,0,0,0,0,0,0,0,0,0,0
endlayer

layer
0,0,0,0,0,0,0,0,0,0,0,0,0,0,0,0,0,0,0,0,0
0,0,0,0,0,0,0,0,1,1,1,1,1,0,0,0,0,0,0,0,0
0,0,0,0,0,0,1,1,0,0,0,0,0,1,1,0,0,0,0,0,0
0,0,0,0,1,1,0,0,0,0,0,0,0,0,0,1,1,0,0,0,0
0,0,0,1,0,0,0,0,0,0,0,0,0,0,0,0,0,1,0,0,0
0,0,0,1,0,0,0,0,0,0,0,0,0,0,0,0,0,1,0,0,0
0,0,1,0,0,0,0,0,0,0,0,0,0,0,0,0,0,0,1,0,0
0,0,1,0,0,0,0,0,0,0,0,0,0,0,0,0,0,0,1,0,0
0,1,0,0,0,0,0,0,0,0,0,0,0,0,0,0,0,0,0,1,0
0,1,0,0,0,0,0,0,0,0,0,0,0,0,0,0,0,0,0,1,0
0,1,0,0,0,0,0,0,0,0,0,0,0,0,0,0,0,0,0,1,0
0,1,0,0,0,0,0,0,0,0,0,0,0,0,0,0,0,0,0,1,0
0,1,0,0,0,0,0,0,0,0,0,0,0,0,0,0,0,0,0,1,0
0,0,1,0,0,0,0,0,0,0,0,0,0,0,0,0,0,0,1,0,0
0,0,1,0,0,0,0,0,0,0,0,0,0,0,0,0,0,0,1,0,0
0,0,0,1,0,0,0,0,0,0,0,0,0,0,0,0,0,1,0,0,0
0,0,0,1,0,0,0,0,0,0,0,0,0,0,0,0,0,1,0,0,0
0,0,0,0,1,1,0,0,0,0,0,0,0,0,0,1,1,0,0,0,0
0,0,0,0,0,0,1,1,0,0,0,0,0,1,1,0,0,0,0,0,0
0,0,0,0,0,0,0,0,1,1,1,1,1,0,0,0,0,0,0,0,0
0,0,0,0,0,0,0,0,0,0,0,0,0,0,0,0,0,0,0,0,0
endlayer

layer
0,0,0,0,0,0,0,0,0,0,0,0,0,0,0,0,0,0,0,0,0
0,0,0,0,0,0,0,0,1,1,1,1,1,0,0,0,0,0,0,0,0
0,0,0,0,0,0,1,1,0,0,0,0,0,1,1,0,0,0,0,0,0
0,0,0,0,1,1,0,0,0,0,0,0,0,0,0,1,1,0,0,0,0
0,0,0,1,0,0,0,0,0,0,0,0,0,0,0,0,0,1,0,0,0
0,0,0,1,0,0,0,0,0,0,0,0,0,0,0,0,0,1,0,0,0
0,0,1,0,0,0,0,0,0,0,0,0,0,0,0,0,0,0,1,0,0
0,0,1,0,0,0,0,0,0,0,0,0,0,0,0,0,0,0,1,0,0
0,1,0,0,0,0,0,0,0,0,0,0,0,0,0,0,0,0,0,1,0
0,1,0,0,0,0,0,0,0,0,0,0,0,0,0,0,0,0,0,1,0
0,1,0,0,0,0,0,0,0,0,0,0,0,0,0,0,0,0,0,1,0
0,1,0,0,0,0,0,0,0,0,0,0,0,0,0,0,0,0,0,1,0
0,1,0,0,0,0,0,0,0,0,0,0,0,0,0,0,0,0,0,1,0
0,0,1,0,0,0,0,0,0,0,0,0,0,0,0,0,0,0,1,0,0
0,0,1,0,0,0,0,0,0,0,0,0,0,0,0,0,0,0,1,0,0
0,0,0,1,0,0,0,0,0,0,0,0,0,0,0,0,0,1,0,0,0
0,0,0,1,0,0,0,0,0,0,0,0,0,0,0,0,0,1,0,0,0
0,0,0,0,1,1,0,0,0,0,0,0,0,0,0,1,1,0,0,0,0
0,0,0,0,0,0,1,1,0,0,0,0,0,1,1,0,0,0,0,0,0
0,0,0,0,0,0,0,0,1,1,1,1,1,0,0,0,0,0,0,0,0
0,0,0,0,0,0,0,0,0,0,0,0,0,0,0,0,0,0,0,0,0
endlayer

layer
0,0,0,0,0,0,0,0,0,0,0,0,0,0,0,0,0,0,0,0,0
0,0,0,0,0,0,0,0,1,1,1,1,1,0,0,0,0,0,0,0,0
0,0,0,0,0,0,1,1,0,0,0,0,0,1,1,0,0,0,0,0,0
0,0,0,0,1,1,0,0,0,0,0,0,0,0,0,1,1,0,0,0,0
0,0,0,1,0,0,0,0,0,0,0,0,0,0,0,0,0,1,0,0,0
0,0,0,1,0,0,0,0,0,0,0,0,0,0,0,0,0,1,0,0,0
0,0,1,0,0,0,0,0,0,0,0,0,0,0,0,0,0,0,1,0,0
0,0,1,0,0,0,0,0,0,0,0,0,0,0,0,0,0,0,1,0,0
0,1,0,0,0,0,0,0,0,0,0,0,0,0,0,0,0,0,0,1,0
0,1,0,0,0,0,0,0,0,0,0,0,0,0,0,0,0,0,0,1,0
0,1,0,0,0,0,0,0,0,0,0,0,0,0,0,0,0,0,0,1,0
0,1,0,0,0,0,0,0,0,0,0,0,0,0,0,0,0,0,0,1,0
0,1,0,0,0,0,0,0,0,0,0,0,0,0,0,0,0,0,0,1,0
0,0,1,0,0,0,0,0,0,0,0,0,0,0,0,0,0,0,1,0,0
0,0,1,0,0,0,0,0,0,0,0,0,0,0,0,0,0,0,1,0,0
0,0,0,1,0,0,0,0,0,0,0,0,0,0,0,0,0,1,0,0,0
0,0,0,1,0,0,0,0,0,0,0,0,0,0,0,0,0,1,0,0,0
0,0,0,0,1,1,0,0,0,0,0,0,0,0,0,1,1,0,0,0,0
0,0,0,0,0,0,1,1,0,0,0,0,0,1,1,0,0,0,0,0,0
0,0,0,0,0,0,0,0,1,1,1,1,1,0,0,0,0,0,0,0,0
0,0,0,0,0,0,0,0,0,0,0,0,0,0,0,0,0,0,0,0,0
endlayer

layer
0,0,0,0,0,0,0,0,2,2,2,2,2,0,0,0,0,0,0,0,0
0,0,0,0,0,0,2,2,1,1,1,1,1,2,2,0,0,0,0,0,0
0,0,0,0,2,2,1,1,2,2,2,2,2,1,1,2,2,0,0,0,0
0,0,0,2,1,1,2,2,0,0,0,0,0,2,2,1,1,2,0,0,0
0,0,2,1,2,2,0,0,0,0,0,0,0,0,0,2,2,1,2,0,0
0,0,2,1,2,0,0,0,0,0,0,0,0,0,0,0,2,1,2,0,0
0,2,1,2,0,0,0,0,0,0,0,0,0,0,0,0,0,2,1,2,0
0,2,1,2,0,0,0,0,0,0,0,0,0,0,0,0,0,2,1,2,0
2,1,2,0,0,0,0,0,0,0,0,0,0,0,0,0,0,0,2,1,2
2,1,2,0,0,0,0,0,0,0,0,0,0,0,0,0,0,0,2,1,2
2,1,2,0,0,0,0,0,0,0,0,0,0,0,0,0,0,0,2,1,2
2,1,2,0,0,0,0,0,0,0,0,0,0,0,0,0,0,0,2,1,2
2,1,2,0,0,0,0,0,0,0,0,0,0,0,0,0,0,0,2,1,2
0,2,1,2,0,0,0,0,0,0,0,0,0,0,0,0,0,2,1,2,0
0,2,1,2,0,0,0,0,0,0,0,0,0,0,0,0,0,2,1,2,0
0,0,2,1,2,0,0,0,0,0,0,0,0,0,0,0,2,1,2,0,0
0,0,2,1,2,2,0,0,0,0,0,0,0,0,0,2,2,1,2,0,0
0,0,0,2,1,1,2,2,0,0,0,0,0,2,2,1,1,2,0,0,0
0,0,0,0,2,2,1,1,2,2,2,2,2,1,1,2,2,0,0,0,0
0,0,0,0,0,0,2,2,1,1,1,1,1,2,2,0,0,0,0,0,0
0,0,0,0,0,0,0,0,2,2,2,2,2,0,0,0,0,0,0,0,0
endlayer

layer
0,0,0,0,0,0,0,0,0,0,0,0,0,0,0,0,0,0,0,0,0
0,0,0,0,0,0,0,0,1,1,1,1,1,0,0,0,0,0,0,0,0
0,0,0,0,0,0,1,1,0,0,3,0,0,1,1,0,0,0,0,0,0
0,0,0,0,1,1,0,0,0,0,0,0,0,0,0,1,1,0,0,0,0
0,0,0,1,0,0,0,0,0,0,0,0,0,0,0,0,0,1,0,0,0
0,0,0,1,0,0,0,0,0,0,0,0,0,0,0,0,0,1,0,0,0
0,0,1,0,0,0,0,0,0,0,0,0,0,0,0,0,0,0,1,0,0
0,0,1,0,0,0,0,0,0,0,0,0,0,0,0,0,0,0,1,0,0
0,1,0,0,0,0,0,0,0,0,0,0,0,0,0,0,0,0,0,1,0
0,1,0,0,0,0,0,0,0,0,0,0,0,0,0,0,0,0,0,1,0
0,1,0,0,0,0,0,0,0,0,0,0,0,0,0,0,0,0,0,1,0
0,1,0,0,0,0,0,0,0,0,0,0,0,0,0,0,0,0,0,1,0
0,1,0,0,0,0,0,0,0,0,0,0,0,0,0,0,0,0,0,1,0
0,0,1,0,0,0,0,0,0,0,0,0,0,0,0,0,0,0,1,0,0
0,0,1,0,0,0,0,0,0,0,0,0,0,0,0,0,0,0,1,0,0
0,0,0,1,0,0,0,0,0,0,0,0,0,0,0,0,0,1,0,0,0
0,0,0,1,0,0,0,0,0,0,0,0,0,0,0,0,0,1,0,0,0
0,0,0,0,1,1,0,0,0,0,0,0,0,0,0,1,1,0,0,0,0
0,0,0,0,0,0,1,1,0,0,3,0,0,1,1,0,0,0,0,0,0
0,0,0,0,0,0,0,0,1,1,1,1,1,0,0,0,0,0,0,0,0
0,0,0,0,0,0,0,0,0,0,0,0,0,0,0,0,0,0,0,0,0
endlayer

layer
0,0,0,0,0,0,0,0,0,0,0,0,0,0,0,0,0,0,0,0,0
0,0,0,0,0,0,0,0,1,1,1,1,1,0,0,0,0,0,0,0,0
0,0,0,0,0,0,1,1,0,0,0,0,0,1,1,0,0,0,0,0,0
0,0,0,0,1,1,0,0,0,0,0,0,0,0,0,1,1,0,0,0,0
0,0,0,1,0,0,0,0,0,0,0,0,0,0,0,0,0,1,0,0,0
0,0,0,1,0,0,0,0,0,0,0,0,0,0,0,0,0,1,0,0,0
0,0,1,0,0,0,0,0,0,0,0,0,0,0,0,0,0,0,1,0,0
0,0,1,0,0,0,0,0,0,0,0,0,0,0,0,0,0,0,1,0,0
0,1,0,0,0,0,0,0,0,0,0,0,0,0,0,0,0,0,0,1,0
0,1,0,0,0,0,0,0,0,0,0,0,0,0,0,0,0,0,0,1,0
0,1,0,0,0,0,0,0,0,0,0,0,0,0,0,0,0,0,0,1,0
0,1,0,0,0,0,0,0,0,0,0,0,0,0,0,0,0,0,0,1,0
0,1,0,0,0,0,0,0,0,0,0,0,0,0,0,0,0,0,0,1,0
0,0,1,0,0,0,0,0,0,0,0,0,0,0,0,0,0,0,1,0,0
0,0,1,0,0,0,0,0,0,0,0,0,0,0,0,0,0,0,1,0,0
0,0,0,1,0,0,0,0,0,0,0,0,0,0,0,0,0,1,0,0,0
0,0,0,1,0,0,0,0,0,0,0,0,0,0,0,0,0,1,0,0,0
0,0,0,0,1,1,0,0,0,0,0,0,0,0,0,1,1,0,0,0,0
0,0,0,0,0,0,1,1,0,0,0,0,0,1,1,0,0,0,0,0,0
0,0,0,0,0,0,0,0,1,1,1,1,1,0,0,0,0,0,0,0,0
0,0,0,0,0,0,0,0,0,0,0,0,0,0,0,0,0,0,0,0,0
endlayer

layer
0,0,0,0,0,0,0,0,0,0,0,0,0,0,0,0,0,0,0,0,0
0,0,0,0,0,0,0,0,1,1,1,1,1,0,0,0,0,0,0,0,0
0,0,0,0,0,0,1,1,0,0,0,0,0,1,1,0,0,0,0,0,0
0,0,0,0,1,1,0,0,0,0,0,0,0,0,0,1,1,0,0,0,0
0,0,0,1,0,0,0,0,0,0,0,0,0,0,0,0,0,1,0,0,0
0,0,0,1,0,0,0,0,0,0,0,0,0,0,0,0,0,1,0,0,0
0,0,1,0,0,0,0,0,0,0,0,0,0,0,0,0,0,0,1,0,0
0,0,1,0,0,0,0,0,0,0,0,0,0,0,0,0,0,0,1,0,0
0,1,0,0,0,0,0,0,0,0,0,0,0,0,0,0,0,0,0,1,0
0,1,0,0,0,0,0,0,0,0,0,0,0,0,0,0,0,0,0,1,0
0,1,0,0,0,0,0,0,0,0,0,0,0,0,0,0,0,0,0,1,0
0,1,0,0,0,0,0,0,0,0,0,0,0,0,0,0,0,0,0,1,0
0,1,0,0,0,0,0,0,0,0,0,0,0,0,0,0,0,0,0,1,0
0,0,1,0,0,0,0,0,0,0,0,0,0,0,0,0,0,0,1,0,0
0,0,1,0,0,0,0,0,0,0,0,0,0,0,0,0,0,0,1,0,0
0,0,0,1,0,0,0,0,0,0,0,0,0,0,0,0,0,1,0,0,0
0,0,0,1,0,0,0,0,0,0,0,0,0,0,0,0,0,1,0,0,0
0,0,0,0,1,1,0,0,0,0,0,0,0,0,0,1,1,0,0,0,0
0,0,0,0,0,0,1,1,0,0,0,0,0,1,1,0,0,0,0,0,0
0,0,0,0,0,0,0,0,1,1,1,1,1,0,0,0,0,0,0,0,0
0,0,0,0,0,0,0,0,0,0,0,0,0,0,0,0,0,0,0,0,0
endlayer

layer
0,0,0,0,0,0,0,0,0,0,0,0,0,0,0,0,0,0,0,0,0
0,0,0,0,0,0,0,0,1,1,1,1,1,0,0,0,0,0,0,0,0
0,0,0,0,0,0,1,1,0,0,0,0,0,1,1,0,0,0,0,0,0
0,0,0,0,1,1,0,0,0,0,0,0,0,0,0,1,1,0,0,0,0
0,0,0,1,0,0,0,0,0,0,0,0,0,0,0,0,0,1,0,0,0
0,0,0,1,0,0,0,0,0,0,0,0,0,0,0,0,0,1,0,0,0
0,0,1,0,0,0,0,0,0,0,0,0,0,0,0,0,0,0,1,0,0
0,0,1,0,0,0,0,0,0,0,0,0,0,0,0,0,0,0,1,0,0
0,1,0,0,0,0,0,0,0,0,0,0,0,0,0,0,0,0,0,1,0
0,1,0,0,0,0,0,0,0,0,0,0,0,0,0,0,0,0,0,1,0
0,1,0,0,0,0,0,0,0,0,0,0,0,0,0,0,0,0,0,1,0
0,1,0,0,0,0,0,0,0,0,0,0,0,0,0,0,0,0,0,1,0
0,1,0,0,0,0,0,0,0,0,0,0,0,0,0,0,0,0,0,1,0
0,0,1,0,0,0,0,0,0,0,0,0,0,0,0,0,0,0,1,0,0
0,0,1,0,0,0,0,0,0,0,0,0,0,0,0,0,0,0,1,0,0
0,0,0,1,0,0,0,0,0,0,0,0,0,0,0,0,0,1,0,0,0
0,0,0,1,0,0,0,0,0,0,0,0,0,0,0,0,0,1,0,0,0
0,0,0,0,1,1,0,0,0,0,0,0,0,0,0,1,1,0,0,0,0
0,0,0,0,0,0,1,1,0,0,0,0,0,1,1,0,0,0,0,0,0
0,0,0,0,0,0,0,0,1,1,1,1,1,0,0,0,0,0,0,0,0
0,0,0,0,0,0,0,0,0,0,0,0,0,0,0,0,0,0,0,0,0
endlayer

layer
0,0,0,0,0,0,0,0,2,2,2,2,2,0,0,0,0,0,0,0,0
0,0,0,0,0,0,2,2,1,1,1,1,1,2,2,0,0,0,0,0,0
0,0,0,0,2,2,1,1,2,2,2,2,2,1,1,2,2,0,0,0,0
0,0,0,2,1,1,2,2,0,0,0,0,0,2,2,1,1,2,0,0,0
0,0,2,1,2,2,0,0,0,0,0,0,0,0,0,2,2,1,2,0,0
0,0,2,1,2,0,0,0,0,0,0,0,0,0,0,0,2,1,2,0,0
0,2,1,2,0,0,0,0,0,0,0,0,0,0,0,0,0,2,1,2,0
0,2,1,2,0,0,0,0,0,0,0,0,0,0,0,0,0,2,1,2,0
2,1,2,0,0,0,0,0,0,0,0,0,0,0,0,0,0,0,2,1,2
2,1,2,0,0,0,0,0,0,0,0,0,0,0,0,0,0,0,2,1,2
2,1,2,0,0,0,0,0,0,0,0,0,0,0,0,0,0,0,2,1,2
2,1,2,0,0,0,0,0,0,0,0,0,0,0,0,0,0,0,2,1,2
2,1,2,0,0,0,0,0,0,0,0,0,0,0,0,0,0,0,2,1,2
0,2,1,2,0,0,0,0,0,0,0,0,0,0,0,0,0,2,1,2,0
0,2,1,2,0,0,0,0,0,0,0,0,0,0,0,0,0,2,1,2,0
0,0,2,1,2,0,0,0,0,0,0,0,0,0,0,0,2,1,2,0,0
0,0,2,1,2,2,0,0,0,0,0,0,0,0,0,2,2,1,2,0,0
0,0,0,2,1,1,2,2,0,0,0,0,0,2,2,1,1,2,0,0,0
0,0,0,0,2,2,1,1,2,2,2,2,2,1,1,2,2,0,0,0,0
0,0,0,0,0,0,2,2,1,1,1,1,1,2,2,0,0,0,0,0,0
0,0,0,0,0,0,0,0,2,2,2,2,2,0,0,0,0,0,0,0,0
endlayer

