
# Created by Ruins mod version 17.1 Ingame Parser
# authoring Player: ST753M

weight=1
uniqueMinDistance=1000
embed_into_distance=2
acceptable_target_blocks=grass,dirt,coarse_dirt,podzol,biomesoplenty:grass,biomesoplenty:dirt
unacceptable_target_blocks=flowing_water,water,flowing_lava,lava
dimensions=19,16,16
allowable_overhang=2
max_leveling=0
leveling_buffer=-1
preserve_water=0
preserve_lava=0

adjoining_template=ST753M/753_SmallVillageHut1;20;20;10;30
adjoining_template=ST753M/753_SmallVillageHut1;20;20;-10;30
adjoining_template=ST753M/753_SmallVillageHut1;-20;20;10;30
adjoining_template=ST753M/753_SmallVillageHut1;-20;20;-10;30
adjoining_template=ST753M/753_SmallVillageHut2;10;20;20;30
adjoining_template=ST753M/753_SmallVillageHut2;10;20;-20;30
adjoining_template=ST753M/753_SmallVillageHut2;-10;20;20;30
adjoining_template=ST753M/753_SmallVillageHut2;-10;20;-20;30

biomesToSpawnIn=swampland,mutated_swampland,lush_swamp,bayou,bog,dead_swamp,coralium_infested_swamp,moor,forest,maple_woods,boreal_forest,forest_hills,woodland,seasonal_forest,temperate_rainforest,fen,grove,sacred_springs,land_of_lakes,forested_hills,lush_hills,thicket,birch_forest,birch_forest_hills,mutated_birch_forest,mutated_birch_forest_hills,birch_forested_hills,plains,prairie,shrubland,chaparral,grassland,meadow,orchard,rocky_plains,rocky_plateau,orchard

=0,100,air
rule1=0,100,preserveBlock
rule2=0,100,minecraft:log-0
rule3=0,100,minecraft:dirt-0
rule4=0,100,minecraft:wooden_slab-9
rule5=0,100,minecraft:wooden_slab-1
rule6=0,100,minecraft:planks-1
rule7=0,100,minecraft:spruce_stairs-2
rule8=0,100,minecraft:spruce_stairs-0
rule9=0,100,minecraft:spruce_stairs-1
rule10=0,100,minecraft:spruce_stairs-3
rule11=0,100,minecraft:spruce_stairs-6
rule12=0,100,minecraft:spruce_stairs-4
rule13=0,100,minecraft:spruce_stairs-5
rule14=0,100,minecraft:spruce_stairs-7
rule15=0,100,minecraft:grass-0
rule16=0,100,minecraft:water-0
rule17=0,100,animania:block_mud-0
rule18=0,100,minecraft:log-8
rule19=0,100,minecraft:spruce_fence-0
rule20=0,100,minecraft:log-4
rule21=0,100,animania:invisiblock-0
rule22=0,100,teBlock;animania:block_trough;{Rot:2b,fluid:{FluidName:"slop",Amount:1000},id:"minecraft:tileentitytrough",items:{Size:1,Items:[]}}-4

rule23=0,100,CommandBlock:RUINSTRIGGER /summon animania:sow_yorkshire ~ ~1 ~ {PersistenceRequired:1}:@-1
^0,100,CommandBlock:RUINSTRIGGER /summon animania:sow_old_spot ~ ~1 ~ {PersistenceRequired:1}:@-1
^0,100,CommandBlock:RUINSTRIGGER /summon animania:sow_large_black ~ ~1 ~ {PersistenceRequired:1}:@-1
^0,100,CommandBlock:RUINSTRIGGER /summon animania:sow_large_white ~ ~1 ~ {PersistenceRequired:1}:@-1
^0,100,CommandBlock:RUINSTRIGGER /summon animania:sow_hampshire ~ ~1 ~ {PersistenceRequired:1}:@-1
^0,100,CommandBlock:RUINSTRIGGER /summon animania:sow_duroc ~ ~1 ~ {PersistenceRequired:1}:@-1

rule24^0,100,CommandBlock:RUINSTRIGGER /summon animania:hog_yorkshire ~ ~1 ~ {PersistenceRequired:1}:@-1
^0,100,CommandBlock:RUINSTRIGGER /summon animania:hog_old_spot ~ ~1 ~ {PersistenceRequired:1}:@-1
^0,100,CommandBlock:RUINSTRIGGER /summon animania:hog_large_black ~ ~1 ~ {PersistenceRequired:1}:@-1
^0,100,CommandBlock:RUINSTRIGGER /summon animania:hog_large_white ~ ~1 ~ {PersistenceRequired:1}:@-1
^0,100,CommandBlock:RUINSTRIGGER /summon animania:hog_hampshire ~ ~1 ~ {PersistenceRequired:1}:@-1
^0,100,CommandBlock:RUINSTRIGGER /summon animania:hog_duroc ~ ~1 ~ {PersistenceRequired:1}:@-1


rule25=0,100,CommandBlock:RUINSTRIGGER /summon villager ~ ~1 ~ {Profession:0,Career:3,Offers:{Recipes:[{rewardExp:0b,maxUses:2147483647,uses:0,buy:{id:"animania:truffle",Count:1b},sell:{id:"minecraft:emerald",Count:1b}},{rewardExp:0b,maxUses:2147483647,uses:0,buy:{id:"minecraft:emerald",Count:8b},sell:{id:"minecraft:carrot_on_a_stick",Count:1b,tag:{Unbreakable:1}}},{rewardExp:0b,maxUses:2147483647,uses:0,buy:{id:"minecraft:emerald",Count:21b},sell:{id:"animania:entity_egg_pig_random",Count:1b}}]}}:@-1


rule26=0,100,minecraft:spruce_fence_gate-1
rule27=0,100,minecraft:planks-0
rule28=0,100,minecraft:crafting_table-0
rule29=0,100,minecraft:oak_stairs-1
rule30=0,100,minecraft:trapdoor-11
rule31=0,100,minecraft:furnace-2
rule32=0,100,minecraft:oak_stairs-0
rule33=0,100,minecraft:wooden_door-2
rule34=0,100,minecraft:melon_block-0
rule35=0,100,minecraft:wooden_door-3
rule36=0,100,minecraft:glass_pane-0
rule37=0,100,minecraft:cake-0
rule38=0,100,teBlock;minecraft:flower_pot;{Item:"minecraft:air",Data:0,id:"minecraft:flower_pot"}-0
rule39=0,100,minecraft:cobblestone_wall-0
rule40=0,100,minecraft:wooden_door-9
rule41=0,100,minecraft:wooden_door-8
rule42=0,100,teBlock;minecraft:bed;{color:14,x:-800168,y:115,z:-200334,id:"minecraft:bed"}-9
rule43=0,100,teBlock;minecraft:bed;{color:14,x:-800168,y:115,z:-200333,id:"minecraft:bed"}-9
rule44=0,100,teBlock;minecraft:bed;{color:14,x:-800167,y:115,z:-200334,id:"minecraft:bed"}-1
rule45=0,100,teBlock;minecraft:bed;{color:14,x:-800167,y:115,z:-200333,id:"minecraft:bed"}-1
rule46=0,100,minecraft:oak_stairs-2
rule47=0,100,teBlock;minecraft:flower_pot;{Item:"minecraft:air",x:-800168,y:116,z:-200335,Data:0,id:"minecraft:flower_pot"}-0
rule48=0,100,minecraft:trapdoor-1
rule49=0,100,minecraft:stone_slab-3

layer
1,1,1,1,1,1,1,1,1,1,1,1,1,1,1,1
1,1,2,1,1,2,1,1,2,1,1,1,1,1,1,1
1,1,1,3,3,3,3,3,3,3,3,3,3,3,3,1
1,1,1,3,3,3,3,3,3,3,3,3,3,3,3,3
1,1,2,3,3,3,3,3,2,3,3,3,3,3,3,3
1,1,1,3,3,5,4,3,3,3,3,3,3,3,3,3
1,1,1,3,3,6,3,3,3,3,3,3,3,3,3,3
1,1,2,3,3,8,7,3,2,3,3,3,3,3,3,3
1,1,1,3,3,10,9,3,3,3,3,3,3,3,3,3
1,1,1,3,3,12,11,3,3,3,3,3,3,3,3,3
1,1,2,3,3,14,13,3,2,3,3,2,3,3,3,3
1,1,1,3,3,3,3,3,3,3,3,3,3,3,3,3
1,1,1,3,3,3,3,3,3,3,3,3,3,3,3,1
1,1,2,1,1,2,1,1,2,1,1,2,1,1,1,1
1,1,1,1,1,1,1,1,1,1,1,1,1,1,1,1
1,1,1,1,1,1,1,1,1,1,1,1,1,1,1,1
endlayer

layer
1,1,1,1,1,1,1,1,1,1,1,1,1,1,1,1
1,1,2,1,1,2,1,1,2,1,1,1,1,1,1,1
1,1,1,3,3,3,3,3,3,15,15,15,15,15,15,1
1,1,1,3,3,3,3,3,3,15,15,16,16,15,15,15
1,1,2,3,3,3,3,3,2,17,16,16,16,15,15,15
1,1,1,3,3,3,3,3,3,17,16,16,17,17,15,15
1,1,1,3,3,3,3,3,3,17,17,17,17,17,15,15
1,1,2,3,3,3,3,3,2,17,17,17,17,17,15,15
1,1,1,3,3,3,3,3,3,17,17,17,17,3,15,15
1,1,1,3,3,3,3,3,3,17,17,17,15,15,15,15
1,1,2,3,3,3,3,3,2,3,3,2,15,15,15,15
1,1,1,3,3,3,3,3,3,3,3,6,6,15,15,15
1,1,1,3,3,3,3,3,3,3,3,6,6,15,15,1
1,1,2,1,1,2,1,1,2,1,1,2,1,1,1,1
1,1,1,1,1,1,1,1,1,1,1,1,1,1,1,1
1,1,1,1,1,1,1,1,1,1,1,1,1,1,1,1
endlayer

layer
1,1,1,1,1,1,1,1,1,1,1,1,1,1,1,1
1,1,2,18,18,2,18,18,2,1,1,1,1,1,1,1
1,1,20,6,6,6,6,6,20,19,19,19,19,19,19,19
1,1,20,6,6,6,6,6,20,0,0,0,0,0,0,19
1,1,2,6,6,6,6,6,2,0,0,0,0,0,0,19
1,1,20,6,6,6,6,6,20,0,0,0,0,22,21,19
1,1,20,6,6,6,6,6,20,0,0,0,23,0,0,19
1,1,2,6,6,6,6,6,2,0,0,0,24,0,0,19
1,1,20,6,6,6,6,6,20,0,0,0,0,25,0,19
1,1,20,6,6,6,6,6,20,0,0,0,0,0,0,19
1,1,2,6,6,6,6,6,2,18,18,2,19,19,26,19
1,1,20,6,6,6,6,6,6,6,6,20,7,0,0,0
1,1,20,6,6,6,6,6,6,6,6,20,7,0,0,0
1,1,2,18,18,2,18,18,2,18,18,2,1,1,1,1
1,1,1,1,1,1,1,1,1,1,1,1,1,1,1,1
1,1,1,1,1,1,1,1,1,1,1,1,1,1,1,1
endlayer

layer
1,1,1,1,1,1,1,1,1,1,1,1,1,1,1,1
1,1,2,27,27,2,27,27,2,1,0,0,0,0,0,1
1,1,27,28,0,0,0,0,27,0,0,0,0,0,0,1
1,1,27,28,0,0,29,0,27,0,0,23,23,0,0,0
1,1,2,31,0,0,30,0,2,0,0,0,24,24,0,0
1,1,27,28,0,0,32,0,27,0,0,0,0,0,0,0
1,1,27,28,0,0,0,0,27,0,0,0,0,0,0,0
1,1,2,2,27,33,33,27,2,0,0,0,0,0,0,0
1,1,27,34,0,0,0,0,27,0,0,0,0,0,0,0
1,1,27,0,34,0,0,0,27,0,0,0,0,0,0,0
1,1,2,12,0,0,0,0,2,27,27,2,0,0,0,0
1,1,27,9,0,0,0,0,0,0,0,35,0,0,0,0
1,1,27,0,0,0,0,0,0,0,0,35,0,0,0,0
1,1,2,27,27,2,27,27,2,27,27,2,1,1,1,1
1,1,1,1,1,1,1,1,1,1,1,1,1,1,1,1
1,1,1,1,1,1,1,1,1,1,1,1,1,1,1,1
endlayer

layer
1,1,1,1,1,1,1,1,1,1,1,1,1,1,1,1
1,1,2,36,36,2,36,36,2,1,0,0,0,0,1,1
1,1,36,37,0,0,0,0,36,0,0,0,0,0,0,1
1,1,36,0,0,0,0,0,36,0,0,0,0,0,0,0
1,1,2,39,0,0,38,0,2,0,0,0,0,0,0,0
1,1,36,0,0,0,0,0,36,0,0,0,0,0,0,0
1,1,36,0,0,0,0,0,36,0,0,0,0,0,0,0
1,1,2,2,27,41,40,27,2,0,0,0,0,0,0,0
1,1,36,0,0,0,0,0,36,0,0,0,0,0,0,0
1,1,36,12,0,0,0,0,36,0,0,0,0,0,0,0
1,1,2,9,0,0,0,0,2,36,36,2,0,0,0,0
1,1,36,0,0,0,0,0,0,0,0,41,0,0,0,1
1,1,36,0,0,0,0,0,0,0,0,40,0,0,0,1
1,1,2,36,36,2,36,36,2,36,36,2,1,1,1,1
1,1,1,1,1,1,1,1,1,1,1,1,1,1,1,1
1,1,1,1,1,1,1,1,1,1,1,1,1,1,1,1
endlayer

layer
1,1,1,1,1,1,1,1,1,1,1,1,1,1,1,1
1,1,2,36,36,2,36,36,2,1,0,0,0,0,1,1
1,1,36,0,0,0,0,0,36,0,0,0,0,0,0,1
1,1,36,0,0,0,0,0,36,0,0,0,0,0,0,0
1,1,2,39,0,0,0,0,2,0,0,0,0,0,0,0
1,1,36,0,0,0,0,0,36,0,0,0,0,0,0,0
1,1,36,0,0,0,0,0,36,0,0,0,0,0,0,0
1,1,2,2,18,18,18,18,2,0,0,0,0,0,0,0
1,1,36,12,0,0,0,0,36,0,0,0,0,0,0,0
1,1,36,9,0,0,0,0,36,0,0,0,0,0,0,0
1,1,2,0,0,0,0,0,2,36,36,2,0,0,0,0
1,1,36,0,0,0,0,0,0,0,0,20,0,0,1,1
1,1,36,0,0,0,0,0,0,0,0,20,0,0,1,1
1,1,2,36,36,2,36,36,2,36,36,2,1,1,1,1
1,1,1,1,1,1,1,1,1,1,1,1,1,1,1,1
1,1,1,1,1,1,1,1,1,1,1,1,1,1,1,1
endlayer

layer
1,1,1,1,1,1,1,1,1,1,1,1,1,1,1,1
1,1,2,27,27,2,27,27,2,1,0,0,0,0,1,1
1,1,27,0,0,0,0,0,27,0,0,0,0,0,0,1
1,1,27,0,0,0,0,0,27,0,0,0,0,0,0,0
1,1,2,39,0,0,0,0,2,0,0,0,0,0,0,0
1,1,27,0,0,0,0,0,27,0,0,0,0,0,0,0
1,1,27,0,0,0,0,0,27,0,0,0,0,0,0,0
1,1,2,2,27,27,27,27,2,0,0,0,0,0,0,0
1,1,27,9,0,0,0,0,27,0,0,0,0,0,0,0
1,1,27,0,0,0,0,0,27,0,0,0,0,0,0,0
1,1,2,0,0,0,0,0,2,27,27,2,0,0,0,0
1,1,27,0,0,0,0,0,0,0,0,27,1,1,1,1
1,1,27,0,0,0,0,0,0,0,0,27,1,1,1,1
1,1,2,27,27,2,27,27,2,27,27,2,1,1,1,1
1,1,1,1,1,1,1,1,1,1,1,1,1,1,1,1
1,1,1,1,1,1,1,1,1,1,1,1,1,1,1,1
endlayer

layer
1,10,20,1,1,1,1,1,20,7,1,1,1,1,1,1
1,10,2,18,18,2,18,18,2,7,0,0,0,0,1,1
1,10,20,0,0,0,0,0,20,7,0,0,0,0,0,1
1,10,20,0,0,0,0,0,20,7,0,0,0,0,0,0
1,10,20,39,0,0,0,0,2,7,0,0,0,0,0,0
1,10,20,0,0,0,0,0,20,7,0,20,0,0,0,0
1,6,20,0,0,0,0,0,20,12,12,20,6,0,0,0
18,18,2,2,18,18,18,18,2,18,18,18,18,18,0,0
1,14,7,0,0,0,0,0,20,0,0,20,11,0,0,0
1,14,6,0,0,0,0,0,20,0,0,20,11,0,0,0
18,18,2,0,0,0,0,0,2,18,18,2,18,18,0,0
1,14,20,0,0,0,0,0,0,0,0,20,11,1,1,1
1,14,20,0,0,0,0,0,0,0,0,20,11,1,1,1
18,18,2,18,18,2,18,18,2,18,18,2,18,18,1,1
1,6,20,13,13,20,13,13,20,13,13,20,6,1,1,1
1,1,20,1,1,20,1,1,20,1,1,20,1,1,1,1
endlayer

layer
1,1,10,11,1,1,1,14,7,1,1,1,1,1,1,1
1,1,10,6,11,0,14,6,7,1,0,0,0,0,1,1
1,1,10,11,0,0,0,14,7,1,0,0,0,0,0,1
1,1,10,11,0,0,0,14,7,1,0,0,0,0,0,0
1,1,10,6,0,0,0,14,7,1,0,0,0,0,0,0
1,1,10,11,0,0,0,14,7,1,0,0,0,0,0,0
1,2,18,18,18,18,18,18,2,18,18,18,2,0,0,0
1,20,6,6,6,6,6,6,6,6,6,6,20,0,0,0
1,20,0,0,6,6,6,6,6,6,6,6,20,0,0,0
1,20,8,0,6,6,6,6,6,6,6,6,20,1,1,1
1,2,6,6,6,6,6,6,6,6,6,6,2,1,1,1
1,20,6,6,6,6,6,6,6,6,6,6,20,1,1,1
1,20,6,6,6,6,6,6,6,6,6,6,20,1,1,1
1,20,6,6,6,6,6,6,6,6,6,6,20,1,1,1
1,2,18,18,18,2,18,18,2,18,18,18,2,1,1,1
1,1,0,1,1,0,1,1,0,1,1,0,1,1,1,1
endlayer

layer
1,1,1,10,11,1,14,7,1,1,1,1,1,1,1,1
1,1,1,10,6,6,6,7,1,1,0,0,0,0,1,1
1,1,1,10,11,0,14,7,1,1,0,0,0,0,0,1
1,1,1,10,11,0,14,7,1,1,0,0,0,0,0,0
1,1,1,39,11,0,14,7,1,1,0,0,0,0,0,0
1,1,1,10,11,0,14,7,1,1,0,0,0,0,0,0
1,2,27,27,27,2,27,27,2,27,27,27,2,0,0,0
1,27,19,19,19,30,43,42,30,0,0,0,27,0,0,1
1,27,0,0,19,0,45,44,0,0,0,0,27,1,1,1
1,27,0,0,19,0,0,0,0,0,0,0,27,1,1,1
1,2,0,19,19,0,0,0,0,0,0,0,2,1,1,1
1,27,0,0,0,0,0,0,0,0,19,0,27,1,1,1
1,27,0,0,0,0,0,0,0,46,19,0,27,1,1,1
1,27,0,0,0,0,0,0,0,0,0,0,27,1,1,1
1,2,27,27,27,2,27,27,2,27,27,27,2,1,1,1
1,1,0,1,1,0,1,1,0,1,1,0,1,1,1,1
endlayer

layer
1,1,1,1,10,6,7,1,1,1,1,1,1,1,1,1
1,1,1,1,10,6,7,1,1,1,1,0,0,0,1,1
1,1,1,1,10,6,7,1,1,1,0,0,0,0,1,1
1,1,1,1,10,6,7,1,1,1,0,0,0,0,0,0
1,1,1,39,10,6,7,1,1,1,0,0,0,0,0,0
1,1,1,1,10,6,7,1,1,1,1,0,0,0,0,0
1,2,27,36,27,2,27,27,2,27,36,27,2,0,0,1
1,27,0,0,0,0,0,0,47,0,0,0,27,1,1,1
1,36,0,0,0,0,0,0,0,0,0,0,36,1,1,1
1,27,0,0,0,0,0,0,0,0,0,0,27,1,1,1
1,2,0,0,0,0,0,0,0,0,0,0,2,1,1,1
1,27,0,0,0,0,0,0,0,0,48,0,27,1,1,1
1,36,0,0,0,0,0,0,0,0,48,0,36,1,1,1
1,27,0,0,0,0,0,0,0,0,0,0,27,1,1,1
1,2,27,36,27,2,36,36,2,27,36,27,2,1,1,1
1,1,0,1,1,0,1,1,0,1,1,0,1,1,1,1
endlayer

layer
1,1,1,1,1,9,1,1,1,1,1,1,1,1,1,1
1,1,1,1,1,5,1,1,1,1,1,1,0,1,1,1
1,1,1,1,1,5,1,1,1,1,1,0,0,0,1,1
1,1,1,1,1,5,1,1,1,1,0,0,0,0,0,1
1,1,1,39,1,5,1,1,1,1,1,0,0,0,0,0
1,1,1,1,1,5,1,1,1,1,1,1,0,0,0,1
1,2,27,36,27,2,27,27,2,27,36,27,2,1,1,1
1,27,0,0,0,0,0,0,0,0,0,0,27,1,1,1
1,36,0,0,0,0,0,0,0,0,0,0,36,1,1,1
1,27,0,0,0,0,0,0,0,0,0,0,27,1,1,1
1,2,0,0,0,0,0,0,0,0,0,0,2,1,1,1
1,27,0,0,0,0,0,0,0,0,0,0,27,1,1,1
1,36,0,0,0,0,0,0,0,0,0,0,36,1,1,1
1,27,0,0,0,0,0,0,0,0,0,0,27,1,1,1
1,2,27,36,27,2,36,36,2,27,36,27,2,1,1,1
1,1,0,1,1,0,1,1,0,1,1,0,1,1,1,1
endlayer

layer
1,1,1,1,1,1,1,1,1,1,1,1,1,1,1,1
1,1,1,1,1,1,1,1,1,1,1,1,1,1,1,1
1,1,1,1,1,1,1,1,1,1,1,1,0,1,1,1
1,1,1,39,1,1,1,1,1,1,1,0,0,0,1,1
1,1,1,39,1,1,1,1,1,1,1,1,0,0,0,1
1,1,1,1,1,1,1,1,1,1,1,1,1,1,1,1
1,2,27,27,27,2,27,27,2,27,27,27,2,1,1,1
1,27,0,0,0,0,0,0,0,0,0,0,27,1,1,1
1,27,0,0,0,0,0,0,0,0,0,0,27,1,1,1
1,27,0,0,0,0,0,0,0,0,0,0,27,1,1,1
1,2,0,0,0,0,0,0,0,0,0,0,2,1,1,1
1,27,0,0,0,0,0,0,0,0,0,0,27,1,1,1
1,27,0,0,0,0,0,0,0,0,0,0,27,1,1,1
1,27,0,0,0,0,0,0,0,0,0,0,27,1,1,1
1,2,27,27,27,2,27,27,2,27,27,27,2,1,1,1
1,1,0,1,1,0,1,1,0,1,1,0,1,1,1,1
endlayer

layer
1,1,1,1,1,1,1,1,1,1,1,1,1,1,1,1
1,1,1,1,1,1,1,1,1,1,1,1,1,1,1,1
1,1,1,1,1,1,1,1,1,1,1,1,1,1,1,1
1,1,1,39,1,1,1,1,1,1,1,1,1,1,1,1
1,1,1,1,1,1,1,1,1,1,1,1,1,1,1,1
8,8,8,8,8,8,8,8,8,8,8,8,8,8,1,1
13,2,18,18,18,2,18,18,2,18,18,18,2,13,1,1
1,20,0,0,0,20,0,0,20,0,0,0,20,1,1,1
1,20,0,0,0,20,0,0,20,0,0,0,20,1,1,1
1,20,0,0,0,20,0,0,20,0,0,0,20,1,1,1
1,2,18,18,18,20,18,18,20,18,18,18,2,1,1,1
1,20,0,0,0,20,0,0,20,0,0,0,20,1,1,1
1,20,0,0,0,20,0,0,20,0,0,0,20,1,1,1
1,20,0,0,0,20,0,0,20,0,0,0,20,1,1,1
12,2,18,18,18,2,18,18,2,18,18,18,2,12,1,1
9,9,9,9,9,9,9,9,9,9,9,9,9,9,1,1
endlayer

layer
1,1,1,1,1,1,1,1,1,1,1,1,1,1,1,1
1,1,1,1,1,1,1,1,1,1,1,1,1,1,1,1
1,1,1,1,1,1,1,1,1,1,1,1,1,1,1,1
1,1,1,39,1,1,1,1,1,1,1,1,1,1,1,1
1,1,1,1,1,1,1,1,1,1,1,1,1,1,1,1
1,1,1,1,1,1,1,1,1,1,1,1,1,1,1,1
8,8,8,8,8,8,8,8,8,8,8,8,8,8,1,1
13,27,13,13,13,13,13,13,13,13,13,13,27,13,1,1
1,27,0,0,0,0,0,0,0,0,0,0,27,1,1,1
1,27,0,0,0,0,0,0,0,0,0,0,27,1,1,1
1,27,0,0,0,0,0,0,0,0,0,0,27,1,1,1
1,27,0,0,0,0,0,0,0,0,0,0,27,1,1,1
1,27,0,0,0,0,0,0,0,0,0,0,27,1,1,1
12,27,12,12,12,12,12,12,12,12,12,12,27,12,1,1
9,9,9,9,9,9,9,9,9,9,9,9,9,9,1,1
1,1,1,1,1,1,1,1,1,1,1,1,1,1,1,1
endlayer

layer
1,1,1,1,1,1,1,1,1,1,1,1,1,1,1,1
1,1,1,1,1,1,1,1,1,1,1,1,1,1,1,1
1,1,1,1,1,1,1,1,1,1,1,1,1,1,1,1
1,1,1,49,1,1,1,1,1,1,1,1,1,1,1,1
1,1,1,1,1,1,1,1,1,1,1,1,1,1,1,1
1,1,1,1,1,1,1,1,1,1,1,1,1,1,1,1
1,1,1,1,1,1,1,1,1,1,1,1,1,1,1,1
8,8,8,8,8,8,8,8,8,8,8,8,8,8,1,1
13,27,13,13,13,13,13,13,13,13,13,13,27,13,1,1
1,27,0,0,0,0,0,0,0,0,0,0,27,1,1,1
1,36,0,0,0,0,0,0,0,0,0,0,36,1,1,1
1,27,0,0,0,0,0,0,0,0,0,0,27,1,1,1
12,27,12,12,12,12,12,12,12,12,12,12,27,12,1,1
9,9,9,9,9,9,9,9,9,9,9,9,9,9,1,1
1,1,1,1,1,1,1,1,1,1,1,1,1,1,1,1
1,1,1,1,1,1,1,1,1,1,1,1,1,1,1,1
endlayer

layer
1,1,1,1,1,1,1,1,1,1,1,1,1,1,1,1
1,1,1,1,1,1,1,1,1,1,1,1,1,1,1,1
1,1,1,1,1,1,1,1,1,1,1,1,1,1,1,1
1,1,1,1,1,1,1,1,1,1,1,1,1,1,1,1
1,1,1,1,1,1,1,1,1,1,1,1,1,1,1,1
1,1,1,1,1,1,1,1,1,1,1,1,1,1,1,1
1,1,1,1,1,1,1,1,1,1,1,1,1,1,1,1
1,1,1,1,1,1,1,1,1,1,1,1,1,1,1,1
8,8,8,8,8,8,8,8,8,8,8,8,8,8,1,1
13,27,13,13,13,13,13,13,13,13,13,13,27,13,1,1
1,27,0,0,0,0,0,0,0,0,0,0,27,1,1,1
12,27,12,12,12,12,12,12,12,12,12,12,27,12,1,1
9,9,9,9,9,9,9,9,9,9,9,9,9,9,1,1
1,1,1,1,1,1,1,1,1,1,1,1,1,1,1,1
1,1,1,1,1,1,1,1,1,1,1,1,1,1,1,1
1,1,1,1,1,1,1,1,1,1,1,1,1,1,1,1
endlayer

layer
1,1,1,1,1,1,1,1,1,1,1,1,1,1,1,1
1,1,1,1,1,1,1,1,1,1,1,1,1,1,1,1
1,1,1,1,1,1,1,1,1,1,1,1,1,1,1,1
1,1,1,1,1,1,1,1,1,1,1,1,1,1,1,1
1,1,1,1,1,1,1,1,1,1,1,1,1,1,1,1
1,1,1,1,1,1,1,1,1,1,1,1,1,1,1,1
1,1,1,1,1,1,1,1,1,1,1,1,1,1,1,1
1,1,1,1,1,1,1,1,1,1,1,1,1,1,1,1
1,1,1,1,1,1,1,1,1,1,1,1,1,1,1,1
8,8,8,8,8,8,8,8,8,8,8,8,8,8,1,1
6,6,6,6,6,6,6,6,6,6,6,6,27,6,1,1
9,9,9,9,9,9,9,9,9,9,9,9,9,9,1,1
1,1,1,1,1,1,1,1,1,1,1,1,1,1,1,1
1,1,1,1,1,1,1,1,1,1,1,1,1,1,1,1
1,1,1,1,1,1,1,1,1,1,1,1,1,1,1,1
1,1,1,1,1,1,1,1,1,1,1,1,1,1,1,1
endlayer

layer
1,1,1,1,1,1,1,1,1,1,1,1,1,1,1,1
1,1,1,1,1,1,1,1,1,1,1,1,1,1,1,1
1,1,1,1,1,1,1,1,1,1,1,1,1,1,1,1
1,1,1,1,1,1,1,1,1,1,1,1,1,1,1,1
1,1,1,1,1,1,1,1,1,1,1,1,1,1,1,1
1,1,1,1,1,1,1,1,1,1,1,1,1,1,1,1
1,1,1,1,1,1,1,1,1,1,1,1,1,1,1,1
1,1,1,1,1,1,1,1,1,1,1,1,1,1,1,1
1,1,1,1,1,1,1,1,1,1,1,1,1,1,1,1
1,1,1,1,1,1,1,1,1,1,1,1,1,1,1,1
7,5,5,5,5,5,5,5,5,5,5,5,5,10,1,1
1,1,1,1,1,1,1,1,1,1,1,1,1,1,1,1
1,1,1,1,1,1,1,1,1,1,1,1,1,1,1,1
1,1,1,1,1,1,1,1,1,1,1,1,1,1,1,1
1,1,1,1,1,1,1,1,1,1,1,1,1,1,1,1
1,1,1,1,1,1,1,1,1,1,1,1,1,1,1,1
endlayer

