
# Created by Ruins mod version 17.1 Ingame Parser
# authoring Player: ST753M

weight=1
uniqueMinDistance=1000
embed_into_distance=4
acceptable_target_blocks=grass,dirt,coarse_dirt,podzol,stone,biomesoplenty:grass,biomesoplenty:dirt
unacceptable_target_blocks=flowing_water,water,flowing_lava,lava
dimensions=15,19,15
allowable_overhang=4
max_leveling=2
leveling_buffer=-1
preserve_water=0
preserve_lava=0

biomesToSpawnIn=forest,maple_woods,seasonal_forest,grove,shield,smaller_extreme_hills,plains,prairie,shrubland,chaparral,grassland,meadow,orchard,rocky_plains,rocky_plateau,mutated_plains,mystic_grove,savanna,savanna_rock,mutated_savanna,mutated_savanna_rock,brushland,steppe,tundra

=0,100,air
rule1=0,100,preserveBlock
rule2=0,100,minecraft:log-0
rule3=0,100,minecraft:dirt-1
rule4=0,100,minecraft:log-8
rule5=0,100,minecraft:log-4
rule6=0,100,minecraft:planks-4
^0,100,minecraft:planks-4
^0,100,minecraft:planks-4
^0,100,minecraft:planks-4
^0,100,minecraft:hardened_clay-0
^0,100,minecraft:hardened_clay-0
^0,100,minecraft:planks-3
^0,100,minecraft:planks-0

rule7=0,100,air
rule8=0,100,air
rule9=0,100,air
rule10=0,100,air

rule11=0,100,CommandBlock:RUINSTRIGGER /summon animania:cow_angus ~ ~ ~:@-1,CommandBlock:RUINSTRIGGER /summon animania:bull_angus ~ ~ ~:@-1,CommandBlock:RUINSTRIGGER /summon animania:calf_angus ~ ~ ~:@-1
^0,100,CommandBlock:RUINSTRIGGER /summon animania:cow_friesan ~ ~ ~:@-1,CommandBlock:RUINSTRIGGER /summon animania:bull_friesan ~ ~ ~:@-1,CommandBlock:RUINSTRIGGER /summon animania:calf_friesan ~ ~ ~:@-1
^0,100,CommandBlock:RUINSTRIGGER /summon animania:cow_hereford ~ ~ ~:@-1,CommandBlock:RUINSTRIGGER /summon animania:bull_hereford ~ ~ ~:@-1,CommandBlock:RUINSTRIGGER /summon animania:calf_hereford ~ ~ ~:@-1
^0,100,CommandBlock:RUINSTRIGGER /summon animania:cow_holsteain ~ ~ ~:@-1,CommandBlock:RUINSTRIGGER /summon animania:bull_holsteain ~ ~ ~:@-1,CommandBlock:RUINSTRIGGER /summon animania:calf_holsteain ~ ~ ~:@-1
^0,100,CommandBlock:RUINSTRIGGER /summon animania:cow_longhorn ~ ~ ~:@-1,CommandBlock:RUINSTRIGGER /summon animania:bull_longhorn ~ ~ ~:@-1,CommandBlock:RUINSTRIGGER /summon animania:calf_longhorn ~ ~ ~:@-1
^0,100,CommandBlock:RUINSTRIGGER /summon animania:cow_highland ~ ~ ~:@-1,CommandBlock:RUINSTRIGGER /summon animania:bull_highland ~ ~ ~:@-1,CommandBlock:RUINSTRIGGER /summon animania:calf_highland ~ ~ ~:@-1
^0,100,CommandBlock:RUINSTRIGGER /summon animania:cow_jersey ~ ~ ~:@-1,CommandBlock:RUINSTRIGGER /summon animania:bull_jersey ~ ~ ~:@-1,CommandBlock:RUINSTRIGGER /summon animania:calf_jersey ~ ~ ~:@-1
^0,100,CommandBlock:RUINSTRIGGER /summon animania:buck_fainting ~ ~ ~:@-1,CommandBlock:RUINSTRIGGER /summon animania:doe_fainting ~ ~ ~:@-1,CommandBlock:RUINSTRIGGER /summon animania:kid_fainting ~ ~ ~:@-1
^0,100,CommandBlock:RUINSTRIGGER /summon animania:buck_angora ~ ~ ~:@-1,CommandBlock:RUINSTRIGGER /summon animania:doe_angora ~ ~ ~:@-1,CommandBlock:RUINSTRIGGER /summon animania:kid_angora ~ ~ ~:@-1
^0,100,CommandBlock:RUINSTRIGGER /summon animania:stallion_draft ~ ~ ~:@-1,CommandBlock:RUINSTRIGGER /summon animania:mare_draft ~ ~ ~:@-1,CommandBlock:RUINSTRIGGER /summon animania:foal_draft ~ ~ ~:@-1
^0,100,CommandBlock:RUINSTRIGGER /summon animania:hog_yorkshire ~ ~ ~:@-1,CommandBlock:RUINSTRIGGER /summon animania:sow_yorkshire ~ ~ ~:@-1,CommandBlock:RUINSTRIGGER /summon animania:piglet_yorkshire ~ ~ ~:@-1
^0,100,CommandBlock:RUINSTRIGGER /summon animania:hog_large_black ~ ~ ~:@-1,CommandBlock:RUINSTRIGGER /summon animania:sow_large_black ~ ~ ~:@-1,CommandBlock:RUINSTRIGGER /summon animania:piglet_large_black ~ ~ ~:@-1
^0,100,CommandBlock:RUINSTRIGGER /summon animania:hog_large_white ~ ~ ~:@-1,CommandBlock:RUINSTRIGGER /summon animania:sow_large_white ~ ~ ~:@-1,CommandBlock:RUINSTRIGGER /summon animania:piglet_large_white ~ ~ ~:@-1
^0,100,CommandBlock:RUINSTRIGGER /summon animania:hog_old_spot ~ ~ ~:@-1,CommandBlock:RUINSTRIGGER /summon animania:sow_old_spot ~ ~ ~:@-1,CommandBlock:RUINSTRIGGER /summon animania:piglet_old_spot ~ ~ ~:@-1
^0,100,CommandBlock:RUINSTRIGGER /summon animania:hog_hampshire ~ ~ ~:@-1,CommandBlock:RUINSTRIGGER /summon animania:sow_hampshire ~ ~ ~:@-1,CommandBlock:RUINSTRIGGER /summon animania:piglet_hampshire ~ ~ ~:@-1
^0,100,CommandBlock:RUINSTRIGGER /summon animania:ewe_friesian ~ ~ ~:@-1,CommandBlock:RUINSTRIGGER /summon animania:ram_friesian ~ ~ ~:@-1,CommandBlock:RUINSTRIGGER /summon animania:lamb_friesian ~ ~ ~:@-1
^0,100,CommandBlock:RUINSTRIGGER /summon animania:ewe_suffolk ~ ~ ~:@-1,CommandBlock:RUINSTRIGGER /summon animania:ram_suffolk ~ ~ ~:@-1,CommandBlock:RUINSTRIGGER /summon animania:lamb_suffolk ~ ~ ~:@-1
^0,100,CommandBlock:RUINSTRIGGER /summon animania:ewe_dorper ~ ~ ~:@-1,CommandBlock:RUINSTRIGGER /summon animania:ram_dorper ~ ~ ~:@-1,CommandBlock:RUINSTRIGGER /summon animania:lamb_dorper ~ ~ ~:@-1
^0,100,CommandBlock:RUINSTRIGGER /summon animania:ewe_merino ~ ~ ~:@-1,CommandBlock:RUINSTRIGGER /summon animania:ram_merino ~ ~ ~:@-1,CommandBlock:RUINSTRIGGER /summon animania:lamb_merino ~ ~ ~:@-1
^0,100,CommandBlock:RUINSTRIGGER /summon animania:ewe_jacob ~ ~ ~:@-1,CommandBlock:RUINSTRIGGER /summon animania:ram_jacob ~ ~ ~:@-1,CommandBlock:RUINSTRIGGER /summon animania:lamb_jacob ~ ~ ~:@-1
^0,100,CommandBlock:RUINSTRIGGER /summon animania:ewe_dorset ~ ~ ~:@-1,CommandBlock:RUINSTRIGGER /summon animania:ram_dorset ~ ~ ~:@-1,CommandBlock:RUINSTRIGGER /summon animania:lamb_dorset ~ ~ ~:@-1
^0,100,CommandBlock:RUINSTRIGGER /summon horse ~ ~ ~:@-1

rule12=0,100,minecraft:spruce_fence-0
rule13=0,100,minecraft:spruce_fence_gate-1
rule14=0,100,minecraft:ladder-2
rule15=0,100,minecraft:spruce_fence_gate-3

rule16=0,100,air
rule17=0,100,air
rule18=0,100,air

rule19=0,100,minecraft:stained_glass_pane-8
rule20=0,100,minecraft:spruce_stairs-0
rule21=0,100,minecraft:spruce_stairs-5
rule22=0,100,minecraft:wooden_slab-9
rule23=0,100,minecraft:spruce_stairs-4
rule24=0,100,minecraft:spruce_stairs-1
rule25=0,100,minecraft:planks-1
rule26=0,100,minecraft:hay_block-0
rule27=0,100,minecraft:web-0

rule28=0,100,CommandBlock:RUINSTRIGGER /summon villager ~ ~1 ~ {Profession:0,Career:3,Offers:{Recipes:[{rewardExp:0b,maxUses:2147483647,uses:0,buy:{id:"animania:milk_bottle",Count:8b},sell:{id:"minecraft:emerald",Count:1b}},{rewardExp:0b,maxUses:2147483647,uses:0,buy:{id:"animania:blue_peacock_feather",Count:8b},sell:{id:"minecraft:emerald",Count:1b}},{rewardExp:0b,maxUses:2147483647,uses:0,buy:{id:"minecraft:emerald",Count:1b},sell:{id:"animania:carving_knife",Count:1b}},{rewardExp:0b,maxUses:2147483647,uses:0,buy:{id:"minecraft:emerald",Count:2b},sell:{id:"animania:truffle",Count:1b}},{rewardExp:0b,maxUses:2147483647,uses:0,buy:{id:"minecraft:emerald",Count:21b},sell:{id:"animania:entity_egg_random",Count:1b}}]}}:@-1

rule29=0,100,minecraft:wooden_slab-1

layer
1,1,1,1,1,1,1,1,1,1,1,1,1,1,1
1,2,1,1,1,2,1,1,1,2,1,1,1,2,1
1,1,2,2,2,2,2,2,2,2,2,2,2,1,1
1,1,2,3,3,3,3,3,3,3,3,3,2,1,1
1,1,2,3,3,3,3,3,3,3,3,3,2,1,1
1,2,2,3,3,3,3,3,3,3,3,3,2,2,1
1,1,2,3,3,3,3,3,3,3,3,3,2,1,1
1,1,2,3,3,3,3,3,3,3,3,3,2,1,1
1,1,2,3,3,3,3,3,3,3,3,3,2,1,1
1,1,2,3,3,3,3,3,3,3,3,3,2,1,1
1,1,2,3,3,3,3,3,3,3,3,3,2,1,1
1,1,2,3,3,3,3,3,3,3,3,3,2,1,1
1,1,2,3,3,3,3,3,3,3,3,3,2,1,1
1,2,2,3,3,3,3,3,3,3,3,3,2,2,1
1,1,2,3,3,3,3,3,3,3,3,3,2,1,1
1,1,2,3,3,3,3,3,3,3,3,3,2,1,1
1,1,2,2,2,2,2,2,2,2,2,2,2,1,1
1,2,1,1,1,2,1,1,1,2,1,1,1,2,1
1,1,1,1,1,1,1,1,1,1,1,1,1,1,1
endlayer

layer
1,1,1,1,1,1,1,1,1,1,1,1,1,1,1
1,2,1,1,1,2,1,1,1,2,1,1,1,2,1
1,1,2,2,2,2,2,2,2,2,2,2,2,1,1
1,1,2,3,3,3,3,3,3,3,3,3,2,1,1
1,1,2,3,3,3,3,3,3,3,3,3,2,1,1
1,2,2,3,3,3,3,3,3,3,3,3,2,2,1
1,1,2,3,3,3,3,3,3,3,3,3,2,1,1
1,1,2,3,3,3,3,3,3,3,3,3,2,1,1
1,1,2,3,3,3,3,3,3,3,3,3,2,1,1
1,1,2,3,3,3,3,3,3,3,3,3,2,1,1
1,1,2,3,3,3,3,3,3,3,3,3,2,1,1
1,1,2,3,3,3,3,3,3,3,3,3,2,1,1
1,1,2,3,3,3,3,3,3,3,3,3,2,1,1
1,2,2,3,3,3,3,3,3,3,3,3,2,2,1
1,1,2,3,3,3,3,3,3,3,3,3,2,1,1
1,1,2,3,3,3,3,3,3,3,3,3,2,1,1
1,1,2,2,2,2,2,2,2,2,2,2,2,1,1
1,2,1,1,1,2,1,1,1,2,1,1,1,2,1
1,1,1,1,1,1,1,1,1,1,1,1,1,1,1
endlayer

layer
1,1,1,1,1,1,1,1,1,1,1,1,1,1,1
1,2,1,1,1,2,1,1,1,2,1,1,1,2,1
1,1,3,3,3,3,3,3,3,3,3,3,3,1,1
1,1,3,3,3,3,3,3,3,3,3,3,3,1,1
1,1,3,3,3,3,3,3,3,3,3,3,3,1,1
1,2,3,3,3,3,3,3,3,3,3,3,3,2,1
1,1,3,3,3,3,3,3,3,3,3,3,3,1,1
1,1,3,3,3,3,3,3,3,3,3,3,3,1,1
1,1,3,3,3,3,3,3,3,3,3,3,3,1,1
1,1,3,3,3,3,3,3,3,3,3,3,3,1,1
1,1,3,3,3,3,3,3,3,3,3,3,3,1,1
1,1,3,3,3,3,3,3,3,3,3,3,3,1,1
1,1,3,3,3,3,3,3,3,3,3,3,3,1,1
1,2,3,3,3,3,3,3,3,3,3,3,3,2,1
1,1,3,3,3,3,3,3,3,3,3,3,3,1,1
1,1,3,3,3,3,3,3,3,3,3,3,3,1,1
1,1,3,3,3,3,3,3,3,3,3,3,3,1,1
1,2,1,1,1,2,1,1,1,2,1,1,1,2,1
1,1,1,1,1,1,1,1,1,1,1,1,1,1,1
endlayer

layer
1,1,1,1,1,1,1,1,1,1,1,1,1,1,1
1,2,4,4,4,2,4,4,4,2,4,4,4,2,1
1,5,3,3,3,3,3,3,3,3,3,3,3,5,1
1,5,3,3,3,3,3,3,3,3,3,3,3,5,1
1,5,3,3,3,3,3,3,3,3,3,3,3,5,1
1,2,3,3,3,3,3,3,3,3,3,3,3,2,1
1,5,3,3,3,3,3,3,3,3,3,3,3,5,1
1,5,3,3,3,3,3,3,3,3,3,3,3,5,1
1,5,3,3,3,3,3,3,3,3,3,3,3,5,1
1,5,3,3,3,3,3,3,3,3,3,3,3,5,1
1,5,3,3,3,3,3,3,3,3,3,3,3,5,1
1,5,3,3,3,3,3,3,3,3,3,3,3,5,1
1,5,3,3,3,3,3,3,3,3,3,3,3,5,1
1,2,3,3,3,3,3,3,3,3,3,3,3,2,1
1,5,3,3,3,3,3,3,3,3,3,3,3,5,1
1,5,3,3,3,3,3,3,3,3,3,3,3,5,1
1,5,3,3,3,3,3,3,3,3,3,3,3,5,1
1,2,4,4,4,2,4,4,4,2,4,4,4,2,1
1,1,1,1,1,1,1,1,1,1,1,1,1,1,1
endlayer

layer
1,1,1,1,1,1,1,1,1,1,1,1,1,1,1
1,2,6,6,6,2,6,6,6,2,6,6,6,2,1
1,6,0,8,10,6,0,8,9,6,0,8,7,6,1
1,6,0,11,0,6,0,11,0,6,0,11,0,6,1
1,6,0,0,0,6,0,0,0,6,0,0,0,6,1
1,2,12,13,12,2,12,13,12,2,12,13,12,2,1
1,6,14,0,0,0,0,0,0,0,0,0,0,6,1
0,12,0,0,0,0,0,0,0,0,0,0,0,12,0
0,0,0,0,0,0,0,0,0,0,0,0,0,0,0
0,0,0,0,0,0,0,0,0,0,0,0,0,0,0
0,0,0,0,0,0,0,0,0,0,0,0,0,0,0
0,12,0,0,0,0,0,0,0,0,0,0,0,12,0
1,6,0,0,0,0,0,0,0,0,0,0,0,6,1
1,2,12,15,12,2,12,15,12,2,12,15,12,2,1
1,6,0,0,0,6,0,0,0,6,0,0,0,6,1
1,6,0,11,0,6,0,11,0,6,0,11,0,6,1
1,6,0,18,8,6,0,17,8,6,0,16,8,6,1
1,2,6,6,6,2,6,6,6,2,6,6,6,2,1
1,1,1,1,1,1,1,1,1,1,1,1,1,1,1
endlayer

layer
1,1,1,1,1,1,1,1,1,1,1,1,1,1,1
1,2,6,19,6,2,6,19,6,2,6,19,6,2,1
1,6,0,0,0,6,0,0,0,6,0,0,0,6,1
1,19,0,0,0,6,0,0,0,6,0,0,0,19,1
1,6,0,0,0,6,0,0,0,6,0,0,0,6,1
1,2,0,0,0,2,0,0,0,2,0,0,0,2,1
1,6,14,0,0,0,0,0,0,0,0,0,0,6,1
0,12,0,0,0,0,0,0,0,0,0,0,0,12,0
0,0,0,0,0,0,0,0,0,0,0,0,0,0,0
0,0,0,0,0,0,0,0,0,0,0,0,0,0,0
0,0,0,0,0,0,0,0,0,0,0,0,0,0,0
0,12,0,0,0,0,0,0,0,0,0,0,0,12,0
1,6,0,0,0,0,0,0,0,0,0,0,0,6,1
1,2,0,0,0,2,0,0,0,2,0,0,0,2,1
1,6,0,0,0,6,0,0,0,6,0,0,0,6,1
1,19,0,0,0,6,0,0,0,6,0,0,0,19,1
1,6,0,0,0,6,0,0,0,6,0,0,0,6,1
1,2,6,19,6,2,6,19,6,2,6,19,6,2,1
1,1,1,1,1,1,1,1,1,1,1,1,1,1,1
endlayer

layer
1,1,1,1,1,1,1,1,1,1,1,1,1,1,1
1,2,6,19,6,2,6,19,6,2,6,19,6,2,1
1,6,0,0,0,12,0,0,0,12,0,0,0,6,1
1,19,0,0,0,12,0,0,0,12,0,0,0,19,1
1,6,0,0,0,12,0,0,0,12,0,0,0,6,1
1,2,0,0,0,2,0,0,0,2,0,0,0,2,1
1,6,14,0,0,0,0,0,0,0,0,0,0,6,1
0,12,0,0,0,0,0,0,0,0,0,0,0,12,0
0,0,0,0,0,0,0,0,0,0,0,0,0,0,0
0,0,0,0,0,0,0,0,0,0,0,0,0,0,0
0,0,0,0,0,0,0,0,0,0,0,0,0,0,0
0,12,0,0,0,0,0,0,0,0,0,0,0,12,0
1,6,0,0,0,0,0,0,0,0,0,0,0,6,1
1,2,0,0,0,2,0,0,0,2,0,0,0,2,1
1,6,0,0,0,12,0,0,0,12,0,0,0,6,1
1,19,0,0,0,12,0,0,0,12,0,0,0,19,1
1,6,0,0,0,12,0,0,0,12,0,0,0,6,1
1,2,6,19,6,2,6,19,6,2,6,19,6,2,1
1,1,1,1,1,1,1,1,1,1,1,1,1,1,1
endlayer

layer
20,20,20,20,20,20,20,20,20,20,20,20,20,20,20
21,2,4,4,4,2,4,4,4,2,4,4,4,2,21
1,5,22,22,22,5,22,22,22,5,22,22,22,5,1
1,5,22,22,22,5,22,22,22,5,22,22,22,5,1
1,5,22,22,22,5,22,22,22,5,22,22,22,5,1
1,2,4,4,4,2,4,4,4,2,4,4,4,2,1
1,5,14,22,22,5,0,0,0,5,22,22,22,5,1
1,5,22,22,22,5,0,0,0,5,22,22,22,5,1
0,5,22,22,22,5,0,0,0,5,22,22,22,5,0
0,5,22,22,22,5,0,0,0,5,22,22,22,5,0
0,5,22,22,22,5,0,0,0,5,22,22,22,5,0
1,5,22,22,22,5,0,0,0,5,22,22,22,5,1
1,5,22,22,22,5,0,0,0,5,22,22,22,5,1
1,2,4,4,4,2,4,4,4,2,4,4,4,2,1
1,5,22,22,22,5,22,22,22,5,22,22,22,5,1
1,5,22,22,22,5,22,22,22,5,22,22,22,5,1
1,5,22,22,22,5,22,22,22,5,22,22,22,5,1
23,2,4,4,4,2,4,4,4,2,4,4,4,2,23
24,24,24,24,24,24,24,24,24,24,24,24,24,24,24
endlayer

layer
1,1,1,1,1,1,1,1,1,1,1,1,1,1,1
20,20,20,20,20,20,20,20,20,20,20,20,20,20,20
21,6,25,25,25,25,25,25,25,25,25,25,25,6,21
1,6,0,0,0,0,0,26,26,0,0,0,0,6,1
1,6,0,0,0,0,0,0,0,0,0,0,0,6,1
1,2,0,0,0,2,12,12,12,2,0,0,27,2,1
1,6,14,0,0,12,0,0,0,12,0,0,0,6,1
1,6,0,0,0,12,0,0,0,12,0,0,0,6,1
1,6,0,0,28,12,0,0,0,12,0,0,0,6,1
1,2,0,0,0,2,0,0,0,2,0,0,0,2,1
1,6,26,26,0,12,0,0,0,12,0,0,0,6,1
1,6,0,0,0,12,0,0,0,12,0,0,0,6,1
1,6,0,0,26,12,0,0,0,12,0,0,0,6,1
1,2,0,0,26,2,12,12,12,2,0,0,0,2,1
1,6,0,0,0,0,0,0,0,0,0,0,26,6,1
1,6,0,0,0,0,0,0,0,0,0,0,0,6,1
23,6,25,25,25,25,25,25,25,25,25,25,25,6,23
24,24,24,24,24,24,24,24,24,24,24,24,24,24,24
1,1,1,1,1,1,1,1,1,1,1,1,1,1,1
endlayer

layer
1,1,1,1,1,1,1,1,1,1,1,1,1,1,1
1,1,1,1,1,1,1,1,1,1,1,1,1,1,1
20,20,20,20,20,20,20,20,20,20,20,20,20,20,20
21,6,0,0,0,0,0,0,0,0,0,0,0,6,21
1,6,0,0,0,0,0,0,0,0,0,0,0,6,1
1,2,0,0,0,2,0,0,0,2,0,0,0,2,1
1,6,14,0,0,0,0,0,0,0,0,0,0,6,1
1,19,0,0,0,0,0,0,0,0,0,0,0,19,1
1,6,0,0,0,0,0,0,0,0,0,0,0,6,1
1,2,27,0,0,2,0,0,0,2,0,0,0,2,1
1,6,0,0,0,0,0,0,0,0,0,0,0,6,1
1,19,0,0,0,0,0,0,0,0,0,0,0,19,1
1,6,0,0,26,0,0,0,0,0,0,0,0,6,1
1,2,0,0,0,2,0,0,0,2,0,0,0,2,1
1,6,0,0,0,0,0,0,0,0,0,0,0,6,1
23,6,0,0,0,0,0,0,0,0,0,0,0,6,23
24,24,24,24,24,24,24,24,24,24,24,24,24,24,24
1,1,1,1,1,1,1,1,1,1,1,1,1,1,1
1,1,1,1,1,1,1,1,1,1,1,1,1,1,1
endlayer

layer
1,1,1,1,1,1,1,1,1,1,1,1,1,1,1
1,1,1,1,1,1,1,1,1,1,1,1,1,1,1
1,1,1,1,1,1,1,1,1,1,1,1,1,1,1
20,20,20,20,20,20,20,20,20,20,20,20,20,20,20
21,6,0,0,0,0,0,0,0,0,0,0,27,6,21
1,2,0,0,0,2,0,0,0,2,0,0,0,2,1
1,6,14,0,0,0,0,0,0,0,0,0,0,6,1
1,19,0,0,0,0,0,0,0,0,0,0,0,19,1
1,6,0,0,0,0,0,0,0,0,0,0,0,6,1
1,2,0,0,0,2,0,0,0,2,0,0,0,2,1
1,6,0,0,0,0,0,0,0,0,0,0,0,6,1
1,19,0,0,0,0,0,0,0,0,0,0,0,19,1
1,6,0,0,0,0,0,0,0,0,0,0,0,6,1
1,2,0,0,0,2,0,0,0,2,0,0,0,2,1
23,6,0,0,0,0,0,0,0,0,0,0,0,6,23
24,24,24,24,24,24,24,24,24,24,24,24,24,24,24
1,1,1,1,1,1,1,1,1,1,1,1,1,1,1
1,1,1,1,1,1,1,1,1,1,1,1,1,1,1
1,1,1,1,1,1,1,1,1,1,1,1,1,1,1
endlayer

layer
1,1,1,1,1,1,1,1,1,1,1,1,1,1,1
1,1,1,1,1,1,1,1,1,1,1,1,1,1,1
1,1,1,1,1,1,1,1,1,1,1,1,1,1,1
1,1,1,1,1,1,1,1,1,1,1,1,1,1,1
20,20,20,20,20,20,20,20,20,20,20,20,20,20,20
21,2,0,0,0,2,0,0,27,2,0,0,0,2,21
1,5,0,0,0,0,0,0,0,0,0,0,0,5,1
1,5,0,0,0,27,0,0,0,0,0,0,0,5,1
1,5,0,0,0,0,27,0,0,0,0,0,0,5,1
1,2,4,4,4,2,4,4,4,2,4,4,4,2,1
1,5,0,0,0,0,0,0,0,0,0,0,0,5,1
1,5,0,0,0,0,0,0,0,0,0,0,0,5,1
1,5,0,0,0,0,0,0,0,0,0,0,0,5,1
23,2,0,0,0,2,0,0,0,2,0,0,0,2,23
24,24,24,24,24,24,24,24,24,24,24,24,24,24,24
1,1,1,1,1,1,1,1,1,1,1,1,1,1,1
1,1,1,1,1,1,1,1,1,1,1,1,1,1,1
1,1,1,1,1,1,1,1,1,1,1,1,1,1,1
1,1,1,1,1,1,1,1,1,1,1,1,1,1,1
endlayer

layer
1,1,1,1,1,1,1,1,1,1,1,1,1,1,1
1,1,1,1,1,1,1,1,1,1,1,1,1,1,1
1,1,1,1,1,1,1,1,1,1,1,1,1,1,1
1,1,1,1,1,1,1,1,1,1,1,1,1,1,1
1,1,1,1,1,1,1,1,1,1,1,1,1,1,1
29,29,29,29,29,29,29,29,29,29,29,29,29,29,29
25,25,25,25,25,25,25,25,25,25,25,25,25,25,25
22,6,22,22,22,22,22,22,22,22,22,22,22,6,22
1,6,0,0,27,0,0,0,0,0,0,0,27,6,1
1,6,27,0,0,2,0,27,0,2,0,0,0,6,1
1,6,0,0,0,0,0,0,0,0,0,0,0,6,1
22,6,22,22,22,22,22,22,22,22,22,22,22,6,22
25,25,25,25,25,25,25,25,25,25,25,25,25,25,25
29,29,29,29,29,29,29,29,29,29,29,29,29,29,29
1,1,1,1,1,1,1,1,1,1,1,1,1,1,1
1,1,1,1,1,1,1,1,1,1,1,1,1,1,1
1,1,1,1,1,1,1,1,1,1,1,1,1,1,1
1,1,1,1,1,1,1,1,1,1,1,1,1,1,1
1,1,1,1,1,1,1,1,1,1,1,1,1,1,1
endlayer

layer
1,1,1,1,1,1,1,1,1,1,1,1,1,1,1
1,1,1,1,1,1,1,1,1,1,1,1,1,1,1
1,1,1,1,1,1,1,1,1,1,1,1,1,1,1
1,1,1,1,1,1,1,1,1,1,1,1,1,1,1
1,1,1,1,1,1,1,1,1,1,1,1,1,1,1
1,1,1,1,1,1,1,1,1,1,1,1,1,1,1
1,1,1,1,1,1,1,1,1,1,1,1,1,1,1
29,29,29,29,29,29,29,29,29,29,29,29,29,29,29
25,25,25,25,25,25,25,25,25,25,25,25,25,25,25
25,25,25,25,25,25,25,25,25,25,25,25,25,25,25
25,25,25,25,25,25,25,25,25,25,25,25,25,25,25
29,29,29,29,29,29,29,29,29,29,29,29,29,29,29
1,1,1,1,1,1,1,1,1,1,1,1,1,1,1
1,1,1,1,1,1,1,1,1,1,1,1,1,1,1
1,1,1,1,1,1,1,1,1,1,1,1,1,1,1
1,1,1,1,1,1,1,1,1,1,1,1,1,1,1
1,1,1,1,1,1,1,1,1,1,1,1,1,1,1
1,1,1,1,1,1,1,1,1,1,1,1,1,1,1
1,1,1,1,1,1,1,1,1,1,1,1,1,1,1
endlayer

layer
1,1,1,1,1,1,1,1,1,1,1,1,1,1,1
1,1,1,1,1,1,1,1,1,1,1,1,1,1,1
1,1,1,1,1,1,1,1,1,1,1,1,1,1,1
1,1,1,1,1,1,1,1,1,1,1,1,1,1,1
1,1,1,1,1,1,1,1,1,1,1,1,1,1,1
1,1,1,1,1,1,1,1,1,1,1,1,1,1,1
1,1,1,1,1,1,1,1,1,1,1,1,1,1,1
1,1,1,1,1,1,1,1,1,1,1,1,1,1,1
1,1,1,1,1,1,1,1,1,1,1,1,1,1,1
29,29,29,29,29,29,29,29,29,29,29,29,29,29,29
1,1,1,1,1,1,1,1,1,1,1,1,1,1,1
1,1,1,1,1,1,1,1,1,1,1,1,1,1,1
1,1,1,1,1,1,1,1,1,1,1,1,1,1,1
1,1,1,1,1,1,1,1,1,1,1,1,1,1,1
1,1,1,1,1,1,1,1,1,1,1,1,1,1,1
1,1,1,1,1,1,1,1,1,1,1,1,1,1,1
1,1,1,1,1,1,1,1,1,1,1,1,1,1,1
1,1,1,1,1,1,1,1,1,1,1,1,1,1,1
1,1,1,1,1,1,1,1,1,1,1,1,1,1,1
endlayer

