
# Created by Ruins mod version 17.0 Ingame Parser
# authoring Player: ST753M

weight=1
uniqueMinDistance=2000
spawnMinDistance=500
embed_into_distance=-60
random_height_offset=-30,30
acceptable_target_blocks=
unacceptable_target_blocks=cloud
dimensions=35,16,18
allowable_overhang=999
max_leveling=0
leveling_buffer=-1
preserve_water=0
preserve_lava=0

biomesToSpawnIn=river,crystal_forest,origin_island,enchanted_forest,mystic_grove,magical_forest,void,omothol

rule1=0,100,minecraft:stone-0
rule2=0,100,minecraft:iron_ore-0
rule3=0,100,botania:biomestonea-14
rule4=0,100,botania:biomestoneb-6
rule5=0,100,minecraft:dirt-0
rule6=0,100,botania:biomestonea14stairs-1
rule7=0,100,IInventory;minecraft:chest;minecraft:vine#3#0#2+minecraft:vine#1#0#4+minecraft:feather#2#0#7+minecraft:feather#3#0#10+minecraft:enchanted_book#{StoredEnchantments:[{lvl:2s,id:2s}]}#0#13+minecraft:string#1#0#14+minecraft:string#2#0#16+minecraft:string#1#0#19+minecraft:feather#1#0#22+minecraft:vine#2#0#24+minecraft:feather#1#0#25-4,MobSpawner:skeleton,MobSpawner:zombie,MobSpawner:silverfish,MobSpawner:spider,MobSpawner:cave_spider,ChestGenHook:chests/spawn_bonus_chest:7-4
rule8=0,100,botania:altgrass-2
rule9=0,100,botania:biomestonea14stairs-4
rule10=0,100,botania:flower-3
rule11=0,100,teBlock;botania:specialflower;{x:5149,subTileCmp:{poolZ:0,windTicks:0,poolX:0,orientation:2,poolY:-1,mana:0,ticksExisted:13570},y:127,subTileName:"daffomill",z:-2771,id:"botania:specialflower"}-0
rule12=0,100,minecraft:cobblestone-0
rule13=0,100,botania:biomestonea14stairs-3
rule14=0,100,minecraft:log-0
rule15=0,100,botania:flower-4
rule16=0,100,teBlock;botania:specialflower;{x:5136,subTileCmp:{poolZ:0,windTicks:0,poolX:0,orientation:2,poolY:-1,mana:0,ticksExisted:14845},y:129,subTileName:"daffomill",z:-2769,id:"botania:specialflower"}-0
rule17=0,100,teBlock;botania:specialflower;{x:5137,subTileCmp:{poolZ:0,windTicks:0,poolX:0,orientation:3,poolY:-1,mana:0,ticksExisted:14758},y:129,subTileName:"daffomill",z:-2780,id:"botania:specialflower"}-0
rule18=0,100,minecraft:spruce_stairs-3
rule19=0,100,teBlock;botania:specialflower;{x:5134,subTileCmp:{poolZ:0,windTicks:0,poolX:0,orientation:0,poolY:-1,mana:0,ticksExisted:14813},y:130,subTileName:"daffomill",z:-2774,id:"botania:specialflower"}-0
rule20=0,100,minecraft:spruce_fence-0
rule21=0,100,teBlock;botania:specialflower;{x:5141,subTileCmp:{poolZ:0,windTicks:0,poolX:0,orientation:2,poolY:-1,mana:0,ticksExisted:14927},y:130,subTileName:"daffomill",z:-2781,id:"botania:specialflower"}-0
rule22=0,100,teBlock;botania:specialflower;{x:5145,subTileCmp:{poolZ:0,windTicks:0,poolX:0,orientation:2,poolY:-1,mana:0,ticksExisted:14989},y:130,subTileName:"daffomill",z:-2769,id:"botania:specialflower"}-0
rule23=0,100,teBlock;botania:specialflower;{x:5147,subTileCmp:{poolZ:0,windTicks:0,poolX:0,orientation:2,poolY:-1,mana:0,ticksExisted:14952},y:130,subTileName:"daffomill",z:-2778,id:"botania:specialflower"}-0
rule24=0,100,minecraft:log-4
rule25=0,100,IInventory;minecraft:chest;minecraft:wheat#3#0#0+minecraft:wheat#7#0#6+minecraft:wheat#3#0#12+minecraft:wheat#1#0#13+minecraft:wheat#4#0#17+minecraft:wheat#6#0#20+minecraft:wheat#3#0#24-2
rule26=0,100,minecraft:spruce_stairs-2
rule27=0,100,minecraft:log-8
rule28=0,100,minecraft:stained_glass-8
rule29=0,100,botania:livingrock0wall-0
rule30=0,100,botania:livingwood0wall-0
rule31=0,100,minecraft:web-0

layer
0,0,0,0,0,0,0,0,0,0,0,0,0,0,0,0,0,0
0,0,0,0,0,0,0,0,0,0,0,0,0,0,0,0,0,0
0,0,0,0,0,0,0,0,1,0,0,0,0,0,0,0,0,0
0,0,0,0,0,0,0,0,0,0,0,0,0,0,0,0,0,0
0,0,0,0,0,0,0,0,0,0,0,0,0,0,0,0,0,0
0,0,0,0,0,0,0,0,0,0,0,0,0,0,0,0,0,0
0,0,0,0,0,0,0,0,0,0,1,0,0,0,0,0,0,0
0,0,0,0,0,0,0,0,0,0,1,0,0,0,0,0,0,0
0,0,0,0,1,0,0,1,0,0,0,0,0,0,0,0,0,0
0,0,0,0,0,0,0,0,0,0,0,1,0,0,0,0,0,0
0,0,0,0,0,1,0,0,0,0,0,0,0,0,0,0,0,0
0,0,0,0,0,0,0,1,0,0,0,0,0,0,0,0,0,0
0,0,0,0,0,0,0,0,0,0,0,0,0,0,0,0,0,0
0,0,0,0,0,0,0,0,1,0,0,0,0,0,0,0,0,0
0,0,0,0,0,0,0,0,0,0,0,0,0,0,0,0,0,0
0,0,0,0,0,0,0,0,0,0,0,0,0,0,0,0,0,0
endlayer

layer
0,0,0,0,0,0,0,0,0,0,0,0,0,0,0,0,0,0
0,0,0,0,0,0,0,0,0,0,0,0,0,0,0,0,0,0
0,0,0,0,0,0,0,0,1,0,0,1,0,0,0,0,0,0
0,0,0,0,0,0,0,0,0,0,0,0,0,0,0,0,0,0
0,0,0,0,0,0,0,1,0,1,0,0,0,0,0,0,0,0
0,0,0,0,0,0,0,0,0,0,0,0,1,0,0,0,0,0
0,0,0,0,0,0,0,0,1,0,1,0,0,0,0,0,0,0
0,0,0,0,0,0,1,0,0,0,1,0,0,0,0,0,0,0
0,0,0,0,1,0,0,1,0,0,0,0,0,0,0,0,0,0
0,0,0,0,0,0,0,0,0,0,0,1,0,0,0,0,0,0
0,0,0,0,0,1,0,0,0,0,0,2,0,0,0,0,0,0
0,0,0,0,0,0,0,1,0,0,0,0,0,1,0,0,0,0
0,0,0,1,0,0,0,0,0,0,0,0,0,0,0,0,0,0
0,0,0,0,0,1,0,0,1,0,1,0,0,0,0,0,0,0
0,0,0,0,0,0,0,0,0,0,0,0,0,0,0,0,0,0
0,0,0,0,0,0,0,0,0,0,0,0,0,0,0,0,0,0
endlayer

layer
0,0,0,0,0,0,0,0,0,0,0,0,0,0,0,0,0,0
0,0,0,0,0,0,0,0,0,0,1,0,0,0,0,0,0,0
0,0,0,0,0,0,0,0,1,0,0,1,0,0,0,0,0,0
0,0,0,0,0,0,0,0,0,1,0,0,0,0,0,0,0,0
0,0,0,0,0,0,0,1,1,1,0,1,1,0,0,0,0,0
0,0,0,0,0,1,0,0,0,0,0,0,1,0,0,0,0,0
0,0,0,0,0,0,0,0,1,0,1,0,0,0,0,0,0,0
0,0,0,0,0,0,1,0,1,0,1,0,1,0,0,0,0,0
0,0,0,0,1,0,0,1,1,0,0,0,0,0,0,0,0,0
0,0,0,0,0,0,0,0,0,1,2,1,0,0,0,0,0,0
0,0,0,1,0,1,0,0,0,0,0,2,0,0,0,0,0,0
0,0,0,0,0,1,0,1,1,0,1,2,0,1,0,0,0,0
0,0,0,1,0,0,1,1,0,0,0,0,0,0,0,0,0,0
0,0,0,0,0,1,0,0,1,1,1,0,0,0,0,0,0,0
0,0,0,0,0,0,0,1,0,0,0,0,1,0,0,0,0,0
0,0,0,0,0,0,0,0,0,0,0,0,0,0,0,0,0,0
endlayer

layer
0,0,0,0,0,0,0,0,0,1,0,0,0,0,0,0,0,0
0,0,0,0,0,0,0,1,0,0,1,0,1,0,0,0,0,0
0,0,0,0,0,0,0,0,1,0,0,1,0,0,0,0,0,0
0,0,0,0,0,0,0,0,0,1,0,0,0,0,0,0,0,0
0,0,0,0,0,0,0,1,1,1,1,1,1,0,1,0,0,0
0,0,0,0,0,1,0,0,1,1,1,1,1,0,0,0,0,0
0,0,0,0,0,0,0,0,1,1,1,1,1,1,0,0,0,0
0,0,0,0,1,0,1,1,2,2,1,1,1,0,0,0,0,0
0,0,1,0,1,0,0,1,1,2,2,1,1,0,0,0,1,0
0,0,0,1,0,0,1,1,1,1,2,1,1,0,1,0,0,0
0,0,0,1,1,1,1,1,1,1,2,1,1,0,0,0,0,0
0,0,0,0,1,1,1,1,1,1,1,2,2,1,0,0,1,0
0,0,0,1,0,1,1,1,1,1,1,1,2,0,1,0,0,0
0,0,0,0,0,1,1,1,1,1,1,1,1,0,0,0,0,0
0,0,0,0,0,0,0,1,0,0,1,0,1,0,0,0,0,0
0,0,0,0,0,0,0,0,1,0,0,0,0,0,0,0,0,0
endlayer

layer
0,0,0,0,0,0,0,0,0,1,0,0,0,0,0,0,0,0
0,0,0,0,0,0,0,1,0,0,1,1,1,0,0,0,0,0
0,0,0,0,0,1,0,0,1,1,1,1,1,0,1,0,0,0
0,0,0,0,0,0,0,0,1,1,1,1,1,0,0,0,0,0
0,0,0,0,0,0,0,1,3,3,3,3,3,1,1,0,0,0
0,0,0,0,0,1,0,1,3,3,3,3,3,1,0,0,0,0
0,0,0,0,1,1,1,1,3,3,3,3,3,1,0,1,0,0
0,0,0,0,1,1,1,1,3,3,3,3,3,1,0,0,0,0
0,0,1,0,1,1,1,1,3,3,3,3,3,1,0,0,1,0
0,0,0,1,1,1,1,1,3,3,3,3,3,1,1,0,0,0
0,0,0,1,1,3,3,3,3,3,3,3,3,1,0,0,0,0
0,0,0,1,1,3,3,3,3,3,3,3,3,1,0,1,1,0
0,0,0,1,1,1,1,1,1,1,1,1,2,2,1,0,0,0
0,0,0,0,1,1,1,1,1,1,1,1,1,2,0,0,0,0
0,0,0,0,0,0,1,1,1,1,1,1,1,0,0,0,0,0
0,0,0,0,0,1,0,0,1,0,0,0,0,0,0,0,0,0
endlayer

layer
0,0,0,0,0,0,1,0,1,1,1,1,0,0,0,0,0,0
0,0,0,0,0,0,0,1,1,1,1,1,1,0,0,0,0,0
0,0,0,0,0,1,0,1,1,1,1,1,1,1,1,0,0,0
0,0,0,0,0,0,1,1,4,4,4,4,4,1,0,0,0,0
0,0,0,0,0,1,1,4,0,0,0,0,0,4,1,0,0,0
0,0,0,0,0,1,1,4,0,0,0,0,0,4,1,0,0,0
0,0,0,0,1,1,1,4,0,0,0,0,0,4,1,1,0,0
0,0,0,1,1,1,1,4,0,0,0,0,0,4,1,1,1,0
0,0,5,1,1,1,1,4,4,4,0,0,0,4,1,1,1,1
0,0,1,1,4,6,6,4,4,4,0,0,0,4,1,1,1,0
0,5,1,1,4,0,0,0,0,0,0,0,0,4,1,1,1,0
0,0,1,1,4,0,0,0,0,0,0,0,0,4,1,1,1,0
0,0,0,1,1,4,4,4,4,4,4,4,4,1,1,0,0,0
0,0,0,1,1,1,1,1,1,1,1,1,1,2,1,0,0,0
0,0,0,0,1,1,1,1,1,1,1,1,1,2,0,0,0,0
0,0,0,0,0,1,0,1,1,1,1,0,0,0,0,0,0,0
endlayer

layer
0,0,0,0,0,0,1,0,1,1,1,1,1,0,0,0,0,0
0,0,0,0,1,0,1,1,1,1,1,1,1,1,0,0,0,0
0,0,0,0,0,1,1,1,1,1,1,1,1,1,1,0,0,0
0,0,0,0,0,0,1,1,3,3,3,3,3,1,1,0,0,0
0,0,0,0,0,1,1,3,0,0,0,0,0,3,1,0,0,0
0,0,0,0,1,1,1,3,0,0,0,0,0,3,1,1,0,0
0,0,0,0,1,1,1,3,0,0,0,0,0,3,1,1,1,0
0,0,0,1,1,1,1,3,0,0,0,0,0,3,1,1,1,0
0,5,1,1,3,6,6,3,7,3,0,0,0,3,1,1,1,1
0,0,1,1,3,0,0,3,3,3,0,0,0,3,1,1,1,0
0,5,1,1,3,0,0,0,0,0,0,0,0,3,1,1,1,0
0,5,1,1,3,0,0,0,0,0,0,0,0,3,1,1,1,0
0,0,1,1,1,3,3,3,3,3,3,3,3,1,1,1,1,0
0,0,0,1,1,1,1,1,1,1,1,1,1,1,1,0,0,0
0,0,0,1,1,1,1,1,1,1,1,1,1,1,0,0,0,0
0,0,0,0,0,1,1,1,1,1,1,1,0,0,0,0,0,0
endlayer

layer
0,0,0,0,0,0,1,1,1,1,1,1,5,0,0,0,0,0
0,0,0,0,1,0,1,1,1,1,1,1,1,1,0,0,0,0
0,0,0,0,0,1,1,1,1,1,1,1,1,1,1,0,0,0
0,0,0,0,0,1,1,1,3,3,3,3,3,1,5,0,0,0
0,0,0,0,5,1,1,3,0,0,0,0,0,3,1,1,0,0
0,0,0,0,1,1,1,3,0,0,0,0,0,3,1,1,0,0
0,0,0,5,1,1,1,3,0,0,0,0,0,3,1,1,1,0
0,0,1,1,3,6,6,3,0,0,0,0,0,3,1,1,1,1
0,5,1,1,3,0,0,3,0,3,0,0,0,3,1,1,1,1
0,5,1,1,3,0,0,3,3,3,0,0,0,3,1,1,1,1
0,5,1,1,3,0,0,0,0,0,0,0,0,3,1,1,5,5
0,5,5,1,3,0,0,0,0,0,0,0,0,3,1,1,1,0
0,5,1,1,1,3,3,3,3,3,3,3,3,1,1,1,1,0
0,0,1,1,1,1,1,1,1,1,1,1,1,1,1,1,0,0
0,0,0,1,5,1,1,1,1,1,1,1,5,1,0,0,0,0
0,0,0,0,0,1,1,5,1,1,5,1,0,0,0,0,0,0
endlayer

layer
0,0,0,0,0,5,1,1,1,5,1,5,5,0,0,0,0,0
0,0,0,0,1,1,1,1,1,1,1,1,1,1,0,0,0,0
0,0,0,0,1,1,1,1,1,1,1,1,1,1,5,0,0,0
0,0,0,5,1,1,1,1,4,4,4,4,4,1,5,0,0,0
0,0,0,0,5,1,1,4,0,0,0,0,0,4,1,1,0,0
0,0,0,5,1,1,1,4,0,0,0,0,0,4,1,5,0,0
0,0,5,1,4,6,6,4,0,0,0,0,0,4,1,1,1,0
0,5,5,1,4,0,0,4,0,0,0,0,0,4,1,1,5,8
0,5,5,1,4,0,0,4,4,4,0,0,0,4,1,1,1,5
0,5,1,1,4,0,0,4,4,4,0,0,0,4,1,1,1,1
0,5,1,1,4,0,0,0,0,0,0,0,0,4,1,1,5,5
0,5,5,1,4,0,0,0,0,0,0,0,0,4,1,1,1,8
0,5,5,1,1,4,4,4,4,4,4,4,4,1,1,1,5,0
0,0,1,1,1,1,1,1,1,1,1,1,1,1,1,1,0,0
0,0,0,5,5,1,1,1,1,1,1,1,5,1,0,0,0,0
0,0,0,0,0,8,1,5,5,1,5,8,0,0,0,0,0,0
endlayer

layer
0,0,0,0,5,5,1,5,1,5,5,5,5,0,0,0,0,0
0,0,0,0,5,1,1,1,1,1,1,1,1,5,0,0,0,0
0,0,0,5,1,1,1,1,1,1,1,1,1,1,8,0,0,0
0,0,0,5,1,3,3,3,3,3,3,3,3,1,5,0,0,0
0,0,0,5,1,3,3,3,0,0,0,0,0,3,1,8,0,0
0,0,5,1,3,6,6,3,0,0,0,0,0,3,1,5,0,0
0,0,5,1,3,0,0,3,0,0,0,0,0,3,1,1,5,0
0,8,5,1,3,0,0,3,0,0,0,0,0,3,1,1,5,0
0,5,5,1,3,0,0,3,3,3,0,0,0,3,1,1,5,8
0,5,1,1,3,9,9,3,3,3,0,0,0,3,1,1,1,8
0,5,5,1,3,3,3,3,0,0,0,0,0,3,1,1,5,8
0,5,5,1,3,3,3,3,0,0,0,0,0,3,1,1,5,0
0,8,5,1,1,3,3,3,3,3,3,3,3,1,1,1,8,0
0,0,5,1,1,1,1,1,1,1,1,1,1,1,1,8,0,0
0,0,0,8,5,5,1,1,1,1,1,5,5,5,0,0,0,0
0,0,0,0,0,11,8,5,5,5,8,10,0,0,0,0,0,0
endlayer

layer
0,0,0,0,8,8,8,5,5,5,5,8,8,0,0,0,0,0
0,0,0,0,8,8,1,1,1,5,1,1,1,8,0,0,0,0
0,0,0,8,8,12,12,12,1,1,1,1,1,8,10,0,0,0
0,0,0,8,12,14,0,13,1,1,1,1,1,12,8,0,0,0
0,0,0,8,12,0,0,13,3,3,3,3,3,1,8,15,0,0
0,0,8,1,12,0,0,12,3,3,3,3,3,1,1,8,0,0
0,0,8,1,12,0,0,12,3,3,3,3,3,1,1,1,8,0
0,0,5,1,12,0,0,12,3,3,3,3,3,1,1,1,8,0
0,8,5,1,12,9,9,12,3,3,3,3,3,1,1,1,8,0
0,8,5,1,1,3,3,3,3,3,3,3,3,1,1,1,8,15
0,8,5,1,1,3,3,3,3,3,3,3,3,1,1,1,8,0
0,8,5,1,1,3,3,3,3,3,3,3,3,1,1,1,8,0
0,0,8,1,1,1,1,1,1,1,1,1,1,1,1,8,0,0
0,0,8,5,1,1,1,1,1,1,1,1,1,1,8,0,0,0
0,0,0,0,8,5,5,1,1,1,5,5,5,8,0,0,0,0
0,0,0,0,0,0,0,8,8,8,0,0,0,0,0,0,0,0
endlayer

layer
0,0,0,0,0,10,0,8,8,8,8,15,0,0,0,0,0,0
0,0,0,0,0,15,8,8,8,8,8,8,8,10,0,0,0,0
0,0,0,16,0,12,12,12,12,12,12,12,12,15,0,0,0,0
0,0,0,0,12,14,0,0,18,12,12,12,12,12,17,0,0,0
0,0,0,10,12,0,0,0,18,12,12,12,12,12,10,0,0,0
0,0,10,8,12,0,0,12,12,12,12,12,12,12,8,0,0,0
0,0,0,8,12,0,0,12,12,12,12,12,12,12,8,8,15,0
0,0,8,8,12,12,12,12,12,12,12,12,12,12,8,8,10,0
0,0,8,8,12,12,12,12,12,12,12,12,12,12,8,8,0,0
0,10,8,8,12,12,12,12,12,12,12,12,12,12,8,8,10,0
0,0,8,8,12,12,12,12,12,12,12,12,12,12,8,8,0,0
0,0,8,8,8,12,12,14,12,12,14,12,12,8,8,8,15,0
0,0,15,8,8,8,8,8,8,8,8,8,8,8,8,0,0,0
0,0,0,8,8,8,8,8,8,8,8,8,8,8,0,0,0,0
0,0,0,0,10,8,8,8,8,8,8,8,8,10,0,0,0,0
0,0,0,0,0,0,0,10,0,0,0,0,0,0,0,0,0,0
endlayer

layer
0,0,0,0,0,0,0,0,19,0,0,0,0,0,0,0,0,0
0,0,0,0,0,0,10,20,0,10,20,0,0,0,0,0,0,0
0,0,0,0,0,12,12,12,12,12,12,12,12,0,0,0,0,0
0,0,0,0,12,14,0,0,0,0,0,0,14,12,0,0,0,0
0,0,0,0,12,0,0,0,0,0,0,0,0,12,0,0,0,0
0,0,0,20,12,0,0,1,1,1,1,0,0,12,20,0,0,0
0,0,0,15,12,0,0,1,12,12,1,0,0,12,10,0,0,0
0,0,0,0,12,0,0,1,12,12,1,0,0,12,0,21,0,0
0,0,0,20,12,0,0,1,1,1,1,0,0,12,20,0,0,0
0,0,15,0,12,0,0,0,0,0,0,0,0,12,0,0,0,0
0,0,0,10,12,14,0,0,0,0,0,0,14,12,0,0,0,0
0,0,0,22,0,12,12,14,0,0,14,12,12,10,15,0,0,0
0,0,0,0,15,0,0,20,0,0,20,0,0,0,0,0,0,0
0,0,0,0,0,0,0,0,0,0,10,0,23,0,0,0,0,0
0,0,0,0,0,0,0,10,0,0,0,0,0,0,0,0,0,0
0,0,0,0,0,0,0,0,0,0,0,0,0,0,0,0,0,0
endlayer

layer
0,0,0,0,0,0,0,0,0,0,0,0,0,0,0,0,0,0
0,0,0,0,0,0,0,20,0,0,20,0,0,0,0,0,0,0
0,0,0,0,0,12,12,12,12,12,12,12,12,0,0,0,0,0
0,0,0,0,12,14,0,0,0,0,0,0,14,12,0,0,0,0
0,0,0,0,12,24,0,0,0,0,0,0,24,12,0,0,0,0
0,0,0,20,12,24,0,0,0,0,0,0,24,12,20,0,0,0
0,0,0,0,12,24,0,0,14,14,0,0,24,12,0,0,0,0
0,0,0,0,12,24,0,0,14,14,0,0,24,12,0,0,0,0
0,0,0,20,12,24,0,0,0,0,0,0,24,12,20,0,0,0
0,0,0,0,12,24,0,0,0,0,0,0,24,12,0,0,0,0
0,0,0,0,12,14,0,0,0,0,0,0,14,12,0,0,0,0
0,0,0,0,0,12,12,14,0,0,14,12,12,0,0,0,0,0
0,0,0,0,0,0,0,20,0,0,20,0,0,0,0,0,0,0
0,0,0,0,0,0,0,0,0,0,0,0,0,0,0,0,0,0
0,0,0,0,0,0,0,0,0,0,0,0,0,0,0,0,0,0
0,0,0,0,0,0,0,0,0,0,0,0,0,0,0,0,0,0
endlayer

layer
0,0,0,0,0,0,0,0,0,0,0,0,0,0,0,0,0,0
0,0,0,0,0,0,0,20,20,20,20,0,0,0,0,0,0,0
0,0,0,0,0,12,12,12,12,12,12,12,12,0,0,0,0,0
0,0,0,0,12,14,0,0,0,0,0,0,14,12,0,0,0,0
0,0,0,0,12,0,0,0,0,0,0,0,0,12,0,0,0,0
0,0,0,20,12,0,0,0,0,0,0,0,0,12,20,0,0,0
0,0,0,20,12,0,0,0,14,14,0,0,0,12,20,0,0,0
0,0,0,20,12,0,0,0,14,14,0,0,0,12,20,0,0,0
0,0,0,20,12,25,0,0,0,0,0,0,0,12,20,0,0,0
0,0,0,0,12,0,0,0,0,0,0,0,0,12,0,0,0,0
0,0,0,0,12,14,0,0,0,0,0,0,14,12,0,0,0,0
0,0,0,0,0,12,12,14,0,0,14,12,12,0,0,0,0,0
0,0,0,0,0,0,0,20,0,0,20,0,0,0,0,0,0,0
0,0,0,0,0,0,0,0,0,0,0,0,0,0,0,0,0,0
0,0,0,0,0,0,0,0,0,0,0,0,0,0,0,0,0,0
0,0,0,0,0,0,0,0,0,0,0,0,0,0,0,0,0,0
endlayer

layer
0,0,0,0,0,0,0,0,0,0,0,0,0,0,0,0,0,0
0,0,0,0,0,20,20,12,12,12,12,20,20,0,0,0,0,0
0,0,0,0,20,12,12,12,12,12,12,12,12,20,0,0,0,0
0,0,0,20,12,14,0,0,0,0,0,0,14,12,20,0,0,0
0,0,0,20,12,0,0,0,0,0,0,0,0,12,20,0,0,0
0,0,0,12,12,0,0,0,0,0,0,0,0,12,12,0,0,0
0,0,0,12,12,0,0,0,14,14,0,0,0,12,12,0,0,0
0,0,0,12,12,0,0,0,14,14,0,0,0,12,12,0,0,0
0,0,0,12,12,0,0,0,0,0,0,0,0,12,12,0,0,0
0,0,0,20,12,0,0,0,0,0,0,0,0,12,20,0,0,0
0,0,0,20,12,14,0,0,0,0,0,0,14,12,20,0,0,0
0,0,0,0,20,12,12,12,12,12,12,12,12,20,0,0,0,0
0,0,0,0,0,0,0,18,27,27,26,0,0,0,0,0,0,0
0,0,0,0,0,0,0,0,0,0,0,0,0,0,0,0,0,0
0,0,0,0,0,0,0,0,0,0,0,0,0,0,0,0,0,0
0,0,0,0,0,0,0,0,0,0,0,0,0,0,0,0,0,0
endlayer

layer
0,0,0,0,0,0,0,0,0,0,0,0,0,0,0,0,0,0
0,0,0,0,0,0,0,20,20,20,20,0,0,0,0,0,0,0
0,0,0,0,0,0,0,12,12,12,12,0,0,0,0,0,0,0
0,0,0,0,0,12,12,27,27,27,27,12,12,0,0,0,0,0
0,0,0,0,0,12,0,0,0,0,0,0,12,0,0,0,0,0
0,0,0,20,12,24,0,0,0,0,0,0,24,12,20,0,0,0
0,0,0,20,12,24,0,0,14,14,0,0,24,12,20,0,0,0
0,0,0,20,12,24,0,0,14,14,0,0,24,12,20,0,0,0
0,0,0,20,12,24,0,0,0,0,0,0,24,12,20,0,0,0
0,0,0,0,0,12,0,0,0,0,0,0,12,0,0,0,0,0
0,0,0,0,0,12,12,12,12,12,12,12,12,0,0,0,0,0
0,0,0,0,0,0,0,0,0,0,0,0,0,0,0,0,0,0
0,0,0,0,0,0,0,0,0,0,0,0,0,0,0,0,0,0
0,0,0,0,0,0,0,0,0,0,0,0,0,0,0,0,0,0
0,0,0,0,0,0,0,0,0,0,0,0,0,0,0,0,0,0
0,0,0,0,0,0,0,0,0,0,0,0,0,0,0,0,0,0
endlayer

layer
0,0,0,0,0,0,0,0,0,0,0,0,0,0,0,0,0,0
0,0,0,0,0,0,0,0,0,0,0,0,0,0,0,0,0,0
0,0,0,0,0,0,0,12,28,28,12,0,0,0,0,0,0,0
0,0,0,0,0,12,12,14,0,0,14,12,12,0,0,0,0,0
0,0,0,0,0,12,0,0,0,0,0,0,12,0,0,0,0,0
0,0,0,0,12,14,0,0,0,0,0,0,14,12,0,0,0,0
0,0,0,0,28,0,0,0,14,14,0,0,0,28,0,0,0,0
0,0,0,0,28,0,0,0,14,14,0,0,0,28,0,0,0,0
0,0,0,0,12,14,0,0,0,0,0,0,14,12,0,0,0,0
0,0,0,0,0,12,0,0,0,0,0,0,12,0,0,0,0,0
0,0,0,0,0,12,12,12,12,12,12,12,12,0,0,0,0,0
0,0,0,0,0,0,0,0,0,0,0,0,0,0,0,0,0,0
0,0,0,0,0,0,0,0,30,29,29,29,0,0,0,0,0,0
0,0,0,0,0,0,0,0,0,0,0,0,0,0,0,0,0,0
0,0,0,0,0,0,0,0,0,0,0,0,0,0,0,0,0,0
0,0,0,0,0,0,0,0,0,0,0,0,0,0,0,0,0,0
endlayer

layer
0,0,0,0,0,0,0,0,0,0,0,0,0,0,0,0,0,0
0,0,0,0,0,0,0,0,0,0,0,0,0,0,0,0,0,0
0,0,0,0,0,0,0,12,28,28,12,0,0,0,0,0,0,0
0,0,0,0,0,0,12,14,0,0,14,12,0,0,0,0,0,0
0,0,0,0,0,12,0,0,0,0,0,0,12,0,0,0,0,0
0,0,0,0,12,14,0,0,0,0,0,0,14,12,0,0,0,0
0,0,0,0,28,0,0,0,14,14,0,0,0,28,0,0,0,0
0,0,0,0,28,0,0,0,14,14,0,0,0,28,0,0,0,0
0,0,0,0,12,14,0,0,0,0,0,0,14,12,0,0,0,0
0,0,0,0,0,12,0,0,0,0,0,0,12,0,0,0,0,0
0,0,0,0,0,0,12,12,12,12,12,12,0,0,0,0,0,0
0,0,0,0,0,0,0,0,0,0,0,0,0,0,0,0,0,0
0,0,0,0,0,0,0,0,30,29,29,29,0,0,0,0,0,0
0,0,0,0,0,0,0,0,0,0,0,0,0,0,0,0,0,0
0,0,0,0,0,0,0,0,0,0,0,0,0,0,0,0,0,0
0,0,0,0,0,0,0,0,0,0,0,0,0,0,0,0,0,0
endlayer

layer
0,0,0,0,0,0,0,0,0,0,0,0,0,0,0,0,0,0
0,0,0,0,0,0,0,0,0,0,0,0,0,0,0,0,0,0
0,0,0,0,0,0,0,12,12,12,12,0,0,0,0,0,0,0
0,0,0,0,0,0,12,14,0,0,14,12,0,0,0,0,0,0
0,0,0,0,0,12,0,0,0,0,0,0,12,0,0,0,0,0
0,0,0,0,12,14,0,0,0,0,0,0,14,12,0,0,0,0
0,0,0,0,12,0,0,0,14,14,0,0,0,12,0,0,0,0
0,0,0,0,12,0,0,0,14,14,0,0,0,12,0,0,0,0
0,0,0,0,12,14,0,0,0,0,0,0,14,12,0,0,0,0
0,0,0,0,0,12,0,0,0,0,0,0,12,0,0,0,0,0
0,0,0,0,0,0,12,12,12,12,12,12,0,0,0,0,0,0
0,0,0,0,0,0,0,0,0,0,0,0,0,0,0,0,0,0
0,0,0,0,0,0,0,0,30,29,29,29,0,0,0,0,0,0
0,0,0,0,0,0,0,0,0,0,0,0,0,0,0,0,0,0
0,0,0,0,0,0,0,0,0,0,0,0,0,0,0,0,0,0
0,0,0,0,0,0,0,0,0,0,0,0,0,0,0,0,0,0
endlayer

layer
0,0,0,0,0,0,0,0,0,0,0,0,0,0,0,0,0,0
0,0,0,0,0,0,0,0,0,0,0,0,0,0,0,0,0,0
0,0,0,0,0,0,0,0,0,0,0,0,0,0,0,0,0,0
0,0,0,0,0,0,0,12,12,12,12,0,0,0,0,0,0,0
0,0,0,0,0,0,12,27,27,27,27,12,0,0,0,0,0,0
0,0,0,0,0,12,24,0,0,0,0,24,12,0,0,0,0,0
0,0,0,0,0,12,24,0,14,14,0,24,12,0,0,0,0,0
0,0,0,0,0,12,24,0,14,14,0,24,12,0,0,0,0,0
0,0,0,0,0,12,24,0,0,0,0,24,12,0,0,0,0,0
0,0,0,0,0,0,12,27,27,27,27,12,0,0,0,0,0,0
0,0,0,0,0,0,0,12,12,12,12,0,0,0,0,0,0,0
0,0,0,0,0,0,0,0,0,0,0,0,0,0,0,0,0,0
0,0,0,0,0,0,0,0,30,29,29,29,0,0,0,0,0,0
0,0,0,0,0,0,0,0,0,0,0,0,0,0,0,0,0,0
0,0,0,0,0,0,0,0,0,0,0,0,0,0,0,0,0,0
0,0,0,0,0,0,0,0,0,0,0,0,0,0,0,0,0,0
endlayer

layer
0,0,0,0,0,0,0,0,0,0,0,0,0,0,0,0,0,0
0,0,0,0,0,0,0,0,0,0,0,0,0,0,0,0,0,0
0,0,0,0,0,0,0,0,0,0,0,0,0,0,0,0,0,0
0,0,0,0,0,0,0,12,12,12,12,0,0,0,0,0,0,0
0,0,0,0,0,0,12,0,0,0,0,12,0,0,0,0,0,0
0,0,0,0,0,12,0,0,0,0,0,0,12,0,0,0,0,0
0,0,0,0,0,12,0,0,14,14,0,0,12,0,0,0,0,0
0,0,0,0,0,12,0,0,14,14,0,0,12,0,0,0,0,0
0,0,0,0,0,12,0,0,0,0,0,0,12,0,0,0,0,0
0,0,0,0,0,0,12,0,0,0,0,12,0,0,0,0,0,0
0,0,0,0,0,0,0,12,28,28,12,0,0,0,0,0,0,0
0,0,0,0,0,0,0,0,0,0,0,0,0,0,0,0,0,0
0,0,0,0,0,0,0,0,30,29,29,29,0,0,0,0,0,0
0,0,0,0,0,0,0,0,0,0,0,0,0,0,0,0,0,0
0,0,0,0,0,0,0,0,0,0,0,0,0,0,0,0,0,0
0,0,0,0,0,0,0,0,0,0,0,0,0,0,0,0,0,0
endlayer

layer
0,0,0,0,0,0,0,0,0,0,0,0,0,0,0,0,0,0
0,0,0,0,0,0,0,0,0,0,0,0,0,0,0,0,0,0
0,0,0,0,0,0,0,0,0,0,0,0,0,0,0,0,0,0
0,0,0,0,0,0,0,12,28,28,12,0,0,0,0,0,0,0
0,0,0,0,0,0,12,0,0,0,0,12,0,0,0,0,0,0
0,0,0,0,0,12,0,0,0,0,0,0,12,0,0,0,0,0
0,0,0,0,0,28,0,0,14,14,0,0,28,0,0,0,0,0
0,0,0,0,0,28,0,0,14,14,0,0,28,0,0,0,0,0
0,0,0,0,0,12,0,0,0,0,0,0,12,0,0,0,0,0
0,0,0,0,0,0,12,0,0,0,0,12,0,0,0,0,0,0
0,0,0,0,0,0,0,12,28,28,12,0,0,0,0,0,0,0
0,0,0,0,0,0,0,0,0,0,0,0,0,0,0,0,0,0
0,0,0,0,0,0,0,0,30,29,29,29,0,0,0,0,0,0
0,0,0,0,0,0,0,0,0,0,0,0,0,0,0,0,0,0
0,0,0,0,0,0,0,0,0,0,0,0,0,0,0,0,0,0
0,0,0,0,0,0,0,0,0,0,0,0,0,0,0,0,0,0
endlayer

layer
0,0,0,0,0,0,0,0,0,0,0,0,0,0,0,0,0,0
0,0,0,0,0,0,0,0,0,0,0,0,0,0,0,0,0,0
0,0,0,0,0,0,0,0,0,0,0,0,0,0,0,0,0,0
0,0,0,0,0,0,0,12,12,12,12,0,0,0,0,0,0,0
0,0,0,0,0,0,12,0,0,0,0,12,0,0,0,0,0,0
0,0,0,0,0,12,0,0,0,0,0,0,12,0,0,0,0,0
0,0,0,0,0,12,0,0,14,14,0,0,12,0,0,0,0,0
0,0,0,0,0,12,0,0,14,14,0,0,12,0,0,0,0,0
0,0,0,0,0,12,0,0,0,0,0,0,12,0,0,0,0,0
0,0,0,0,0,0,12,0,0,0,0,12,0,0,0,0,0,0
0,0,0,0,0,0,0,12,12,12,12,0,0,0,0,0,0,0
0,0,0,0,0,0,0,0,0,0,0,0,0,0,0,0,0,0
29,29,29,29,29,29,29,0,30,29,29,29,0,0,0,0,0,0
0,0,0,0,0,0,0,0,0,0,0,0,0,0,0,0,0,0
0,0,0,0,0,0,0,0,0,0,0,0,0,0,0,0,0,0
0,0,0,0,0,0,0,0,0,0,0,0,0,0,0,0,0,0
endlayer

layer
0,0,0,0,0,0,0,0,0,0,0,0,0,0,0,0,0,0
0,0,0,0,0,0,0,0,0,0,0,0,0,0,0,0,0,0
0,0,0,0,0,0,0,0,0,0,0,0,0,0,0,0,0,0
0,0,0,0,0,0,0,0,0,0,0,0,0,0,0,0,0,0
0,0,0,0,0,0,0,12,12,12,12,0,0,0,0,0,0,0
0,0,0,0,0,0,12,0,31,0,0,12,0,0,0,0,0,0
0,0,0,0,0,0,12,0,14,14,0,12,0,0,0,0,0,0
0,0,0,0,0,0,12,0,14,14,0,12,0,0,0,0,0,0
0,0,0,0,0,0,12,0,0,0,0,12,0,0,0,0,0,0
0,0,0,0,0,0,0,12,12,12,12,0,0,0,0,0,0,0
0,0,0,0,0,0,0,0,0,0,0,0,0,0,0,0,0,0
0,0,0,0,0,0,0,0,0,0,0,0,0,0,0,0,0,0
29,29,29,29,29,29,29,0,30,0,0,0,0,0,0,0,0,0
0,0,0,0,0,0,0,0,0,0,0,0,0,0,0,0,0,0
0,0,0,0,0,0,0,0,0,0,0,0,0,0,0,0,0,0
0,0,0,0,0,0,0,0,0,0,0,0,0,0,0,0,0,0
endlayer

layer
0,0,0,0,0,0,0,0,0,0,0,0,0,0,0,0,0,0
0,0,0,0,0,0,0,0,0,0,0,0,0,0,0,0,0,0
0,0,0,0,0,0,0,0,0,0,0,0,0,0,0,0,0,0
0,0,0,0,0,0,0,0,0,0,0,0,0,0,0,0,0,0
0,0,0,0,0,0,0,12,12,12,12,0,0,0,0,0,0,0
0,0,0,0,0,0,12,0,24,24,0,12,0,0,0,0,0,0
0,0,0,0,0,0,12,0,24,24,0,12,0,0,0,0,0,0
0,0,0,0,0,0,12,0,24,24,0,12,0,0,0,0,0,0
0,0,0,0,0,0,12,0,24,24,0,12,0,0,0,0,0,0
0,0,0,0,0,0,0,12,24,24,12,0,0,0,0,0,0,0
0,0,0,0,0,0,0,0,24,24,0,0,0,0,0,0,0,0
0,0,0,0,0,0,0,0,24,24,0,0,0,0,0,0,0,0
29,29,29,29,29,29,29,0,24,24,30,30,30,30,30,30,30,30
0,0,0,0,0,0,0,0,0,0,0,0,0,0,0,0,0,0
0,0,0,0,0,0,0,0,0,0,0,0,0,0,0,0,0,0
0,0,0,0,0,0,0,0,0,0,0,0,0,0,0,0,0,0
endlayer

layer
0,0,0,0,0,0,0,0,0,0,0,0,0,0,0,0,0,0
0,0,0,0,0,0,0,0,0,0,0,0,0,0,0,0,0,0
0,0,0,0,0,0,0,0,0,0,0,0,0,0,0,0,0,0
0,0,0,0,0,0,0,0,0,0,0,0,0,0,0,0,0,0
0,0,0,0,0,0,0,12,12,12,12,0,0,0,0,0,0,0
0,0,0,0,0,0,12,0,24,24,0,12,0,0,0,0,0,0
0,0,0,0,0,0,12,0,24,24,0,12,0,0,0,0,0,0
0,0,0,0,0,0,12,0,24,24,0,12,0,0,0,0,0,0
0,0,0,0,0,0,12,0,24,24,0,12,0,0,0,0,0,0
0,0,0,0,0,0,0,12,24,24,12,0,0,0,0,0,0,0
0,0,0,0,0,0,0,0,24,24,0,0,0,0,0,0,0,0
0,0,0,0,0,0,0,0,24,24,0,0,0,0,0,0,0,0
30,30,30,30,30,30,30,30,24,24,0,29,29,29,29,29,29,29
0,0,0,0,0,0,0,0,0,0,0,0,0,0,0,0,0,0
0,0,0,0,0,0,0,0,0,0,0,0,0,0,0,0,0,0
0,0,0,0,0,0,0,0,0,0,0,0,0,0,0,0,0,0
endlayer

layer
0,0,0,0,0,0,0,0,0,0,0,0,0,0,0,0,0,0
0,0,0,0,0,0,0,0,0,0,0,0,0,0,0,0,0,0
0,0,0,0,0,0,0,0,0,0,0,0,0,0,0,0,0,0
0,0,0,0,0,0,0,0,0,0,0,0,0,0,0,0,0,0
0,0,0,0,0,0,0,12,12,12,12,0,0,0,0,0,0,0
0,0,0,0,0,0,12,31,0,0,31,12,0,0,0,0,0,0
0,0,0,0,0,0,12,0,0,0,0,12,0,0,0,0,0,0
0,0,0,0,0,0,12,0,0,0,0,12,0,0,0,0,0,0
0,0,0,0,0,0,12,0,0,0,0,12,0,0,0,0,0,0
0,0,0,0,0,0,0,12,12,12,12,0,0,0,0,0,0,0
0,0,0,0,0,0,0,0,0,0,0,0,0,0,0,0,0,0
0,0,0,0,0,0,0,0,0,0,0,0,0,0,0,0,0,0
0,0,0,0,0,0,0,0,0,30,0,29,29,29,29,29,29,29
0,0,0,0,0,0,0,0,0,0,0,0,0,0,0,0,0,0
0,0,0,0,0,0,0,0,0,0,0,0,0,0,0,0,0,0
0,0,0,0,0,0,0,0,0,0,0,0,0,0,0,0,0,0
endlayer

layer
0,0,0,0,0,0,0,0,0,0,0,0,0,0,0,0,0,0
0,0,0,0,0,0,0,0,0,0,0,0,0,0,0,0,0,0
0,0,0,0,0,0,0,0,0,0,0,0,0,0,0,0,0,0
0,0,0,0,0,0,0,3,3,3,3,0,0,0,0,0,0,0
0,0,0,0,0,0,3,3,3,3,3,3,0,0,0,0,0,0
0,0,0,0,0,3,3,3,0,0,3,3,3,0,0,0,0,0
0,0,0,0,0,3,3,0,0,0,0,3,3,0,0,0,0,0
0,0,0,0,0,3,3,0,0,0,0,3,3,0,0,0,0,0
0,0,0,0,0,3,3,3,31,0,3,3,3,0,0,0,0,0
0,0,0,0,0,0,3,3,3,3,3,3,0,0,0,0,0,0
0,0,0,0,0,0,0,3,3,3,3,0,0,0,0,0,0,0
0,0,0,0,0,0,0,0,0,0,0,0,0,0,0,0,0,0
0,0,0,0,0,0,29,29,29,30,0,29,29,29,29,29,29,29
0,0,0,0,0,0,0,0,0,0,0,0,0,0,0,0,0,0
0,0,0,0,0,0,0,0,0,0,0,0,0,0,0,0,0,0
0,0,0,0,0,0,0,0,0,0,0,0,0,0,0,0,0,0
endlayer

layer
0,0,0,0,0,0,0,0,0,0,0,0,0,0,0,0,0,0
0,0,0,0,0,0,0,0,0,0,0,0,0,0,0,0,0,0
0,0,0,0,0,0,0,0,0,0,0,0,0,0,0,0,0,0
0,0,0,0,0,0,0,0,0,0,0,0,0,0,0,0,0,0
0,0,0,0,0,0,0,3,3,3,3,0,0,0,0,0,0,0
0,0,0,0,0,0,3,3,3,3,3,3,0,0,0,0,0,0
0,0,0,0,0,0,3,3,0,0,3,3,0,0,0,0,0,0
0,0,0,0,0,0,3,3,0,31,3,3,0,0,0,0,0,0
0,0,0,0,0,0,3,3,3,3,3,3,0,0,0,0,0,0
0,0,0,0,0,0,0,3,3,3,3,0,0,0,0,0,0,0
0,0,0,0,0,0,0,0,0,0,0,0,0,0,0,0,0,0
0,0,0,0,0,0,0,0,0,0,0,0,0,0,0,0,0,0
0,0,0,0,0,0,29,29,29,30,0,0,0,0,0,0,0,0
0,0,0,0,0,0,0,0,0,0,0,0,0,0,0,0,0,0
0,0,0,0,0,0,0,0,0,0,0,0,0,0,0,0,0,0
0,0,0,0,0,0,0,0,0,0,0,0,0,0,0,0,0,0
endlayer

layer
0,0,0,0,0,0,0,0,0,0,0,0,0,0,0,0,0,0
0,0,0,0,0,0,0,0,0,0,0,0,0,0,0,0,0,0
0,0,0,0,0,0,0,0,0,0,0,0,0,0,0,0,0,0
0,0,0,0,0,0,0,0,0,0,0,0,0,0,0,0,0,0
0,0,0,0,0,0,0,0,0,0,0,0,0,0,0,0,0,0
0,0,0,0,0,0,0,0,3,3,0,0,0,0,0,0,0,0
0,0,0,0,0,0,0,3,3,3,3,0,0,0,0,0,0,0
0,0,0,0,0,0,0,3,3,3,3,0,0,0,0,0,0,0
0,0,0,0,0,0,0,0,3,3,0,0,0,0,0,0,0,0
0,0,0,0,0,0,0,0,0,0,0,0,0,0,0,0,0,0
0,0,0,0,0,0,0,0,0,0,0,0,0,0,0,0,0,0
0,0,0,0,0,0,0,0,0,0,0,0,0,0,0,0,0,0
0,0,0,0,0,0,29,29,29,30,0,0,0,0,0,0,0,0
0,0,0,0,0,0,0,0,0,0,0,0,0,0,0,0,0,0
0,0,0,0,0,0,0,0,0,0,0,0,0,0,0,0,0,0
0,0,0,0,0,0,0,0,0,0,0,0,0,0,0,0,0,0
endlayer

layer
0,0,0,0,0,0,0,0,0,0,0,0,0,0,0,0,0,0
0,0,0,0,0,0,0,0,0,0,0,0,0,0,0,0,0,0
0,0,0,0,0,0,0,0,0,0,0,0,0,0,0,0,0,0
0,0,0,0,0,0,0,0,0,0,0,0,0,0,0,0,0,0
0,0,0,0,0,0,0,0,0,0,0,0,0,0,0,0,0,0
0,0,0,0,0,0,0,0,0,0,0,0,0,0,0,0,0,0
0,0,0,0,0,0,0,0,0,0,0,0,0,0,0,0,0,0
0,0,0,0,0,0,0,0,0,0,0,0,0,0,0,0,0,0
0,0,0,0,0,0,0,0,0,0,0,0,0,0,0,0,0,0
0,0,0,0,0,0,0,0,0,0,0,0,0,0,0,0,0,0
0,0,0,0,0,0,0,0,0,0,0,0,0,0,0,0,0,0
0,0,0,0,0,0,0,0,0,0,0,0,0,0,0,0,0,0
0,0,0,0,0,0,29,29,29,30,0,0,0,0,0,0,0,0
0,0,0,0,0,0,0,0,0,0,0,0,0,0,0,0,0,0
0,0,0,0,0,0,0,0,0,0,0,0,0,0,0,0,0,0
0,0,0,0,0,0,0,0,0,0,0,0,0,0,0,0,0,0
endlayer

layer
0,0,0,0,0,0,0,0,0,0,0,0,0,0,0,0,0,0
0,0,0,0,0,0,0,0,0,0,0,0,0,0,0,0,0,0
0,0,0,0,0,0,0,0,0,0,0,0,0,0,0,0,0,0
0,0,0,0,0,0,0,0,0,0,0,0,0,0,0,0,0,0
0,0,0,0,0,0,0,0,0,0,0,0,0,0,0,0,0,0
0,0,0,0,0,0,0,0,0,0,0,0,0,0,0,0,0,0
0,0,0,0,0,0,0,0,0,0,0,0,0,0,0,0,0,0
0,0,0,0,0,0,0,0,0,0,0,0,0,0,0,0,0,0
0,0,0,0,0,0,0,0,0,0,0,0,0,0,0,0,0,0
0,0,0,0,0,0,0,0,0,0,0,0,0,0,0,0,0,0
0,0,0,0,0,0,0,0,0,0,0,0,0,0,0,0,0,0
0,0,0,0,0,0,0,0,0,0,0,0,0,0,0,0,0,0
0,0,0,0,0,0,29,29,29,30,0,0,0,0,0,0,0,0
0,0,0,0,0,0,0,0,0,0,0,0,0,0,0,0,0,0
0,0,0,0,0,0,0,0,0,0,0,0,0,0,0,0,0,0
0,0,0,0,0,0,0,0,0,0,0,0,0,0,0,0,0,0
endlayer

layer
0,0,0,0,0,0,0,0,0,0,0,0,0,0,0,0,0,0
0,0,0,0,0,0,0,0,0,0,0,0,0,0,0,0,0,0
0,0,0,0,0,0,0,0,0,0,0,0,0,0,0,0,0,0
0,0,0,0,0,0,0,0,0,0,0,0,0,0,0,0,0,0
0,0,0,0,0,0,0,0,0,0,0,0,0,0,0,0,0,0
0,0,0,0,0,0,0,0,0,0,0,0,0,0,0,0,0,0
0,0,0,0,0,0,0,0,0,0,0,0,0,0,0,0,0,0
0,0,0,0,0,0,0,0,0,0,0,0,0,0,0,0,0,0
0,0,0,0,0,0,0,0,0,0,0,0,0,0,0,0,0,0
0,0,0,0,0,0,0,0,0,0,0,0,0,0,0,0,0,0
0,0,0,0,0,0,0,0,0,0,0,0,0,0,0,0,0,0
0,0,0,0,0,0,0,0,0,0,0,0,0,0,0,0,0,0
0,0,0,0,0,0,29,29,29,30,0,0,0,0,0,0,0,0
0,0,0,0,0,0,0,0,0,0,0,0,0,0,0,0,0,0
0,0,0,0,0,0,0,0,0,0,0,0,0,0,0,0,0,0
0,0,0,0,0,0,0,0,0,0,0,0,0,0,0,0,0,0
endlayer

layer
0,0,0,0,0,0,0,0,0,0,0,0,0,0,0,0,0,0
0,0,0,0,0,0,0,0,0,0,0,0,0,0,0,0,0,0
0,0,0,0,0,0,0,0,0,0,0,0,0,0,0,0,0,0
0,0,0,0,0,0,0,0,0,0,0,0,0,0,0,0,0,0
0,0,0,0,0,0,0,0,0,0,0,0,0,0,0,0,0,0
0,0,0,0,0,0,0,0,0,0,0,0,0,0,0,0,0,0
0,0,0,0,0,0,0,0,0,0,0,0,0,0,0,0,0,0
0,0,0,0,0,0,0,0,0,0,0,0,0,0,0,0,0,0
0,0,0,0,0,0,0,0,0,0,0,0,0,0,0,0,0,0
0,0,0,0,0,0,0,0,0,0,0,0,0,0,0,0,0,0
0,0,0,0,0,0,0,0,0,0,0,0,0,0,0,0,0,0
0,0,0,0,0,0,0,0,0,0,0,0,0,0,0,0,0,0
0,0,0,0,0,0,29,29,29,30,0,0,0,0,0,0,0,0
0,0,0,0,0,0,0,0,0,0,0,0,0,0,0,0,0,0
0,0,0,0,0,0,0,0,0,0,0,0,0,0,0,0,0,0
0,0,0,0,0,0,0,0,0,0,0,0,0,0,0,0,0,0
endlayer

