
# Created by Ruins mod version 17.1 Ingame Parser
# authoring Player: ST753M

weight=1
uniqueMinDistance=2000
embed_into_distance=-128
acceptable_target_blocks=
unacceptable_target_blocks=glass
dimensions=18,15,15
allowable_overhang=999
max_leveling=0
leveling_buffer=-1
preserve_water=0
preserve_lava=0

biomesToSpawnIn=river,crystal_forest,origin_island,enchanted_forest,mystic_grove,magical_forest,mutated_plains,mutated_forest

rule1=0,100,minecraft:stone-0
^0,100,botania:livingrock-0
rule2=0,100,minecraft:vine-8
rule3=0,100,minecraft:vine-2
rule4=0,100,minecraft:vine-4
rule5=0,100,minecraft:vine-1
rule6=0,100,minecraft:dirt-0

rule7=0,100,botania:quartzslabredhalf-0
^0,100,botania:quartzslabmanahalf-0
^0,100,botania:quartzslabblazehalf-0
^0,100,botania:quartzslablavenderhalf-0
^0,100,botania:quartzslabelfhalf-0
^0,100,botania:quartzslabsunnyhalf-0

rule8^0,100,botania:quartzslabredhalf-8
^0,100,botania:quartzslabmanahalf-8
^0,100,botania:quartzslabblazehalf-8
^0,100,botania:quartzslablavenderhalf-8
^0,100,botania:quartzslabelfhalf-8
^0,100,botania:quartzslabsunnyhalf-8

rule9^0,100,botania:quartztypered-3
^0,100,botania:quartztypemana-3
^0,100,botania:quartztypeblaze-3
^0,100,botania:quartztypelavender-3
^0,100,botania:quartztypeelf-3
^0,100,botania:quartztypesunny-3

rule10^0,100,botania:quartztypered-2
^0,100,botania:quartztypemana-2
^0,100,botania:quartztypeblaze-2
^0,100,botania:quartztypelavender-2
^0,100,botania:quartztypeelf-2
^0,100,botania:quartztypesunny-2

rule11^0,100,botania:quartzstairsred-7
^0,100,botania:quartzstairsmana-7
^0,100,botania:quartzstairsblaze-7
^0,100,botania:quartzstairslavender-7
^0,100,botania:quartzstairself-7
^0,100,botania:quartzstairssunny-7

rule12^0,100,botania:quartztypered-0
^0,100,botania:quartztypemana-0
^0,100,botania:quartztypeblaze-0
^0,100,botania:quartztypelavender-0
^0,100,botania:quartztypeelf-0
^0,100,botania:quartztypesunny-0

rule13^0,100,botania:quartzstairsred-5
^0,100,botania:quartzstairsmana-5
^0,100,botania:quartzstairsblaze-5
^0,100,botania:quartzstairslavender-5
^0,100,botania:quartzstairself-5
^0,100,botania:quartzstairssunny-5

rule14^0,100,botania:quartzstairsred-3
^0,100,botania:quartzstairsmana-3
^0,100,botania:quartzstairsblaze-3
^0,100,botania:quartzstairslavender-3
^0,100,botania:quartzstairself-3
^0,100,botania:quartzstairssunny-3

rule15^0,100,botania:quartzstairsred-4
^0,100,botania:quartzstairsmana-4
^0,100,botania:quartzstairsblaze-4
^0,100,botania:quartzstairslavender-4
^0,100,botania:quartzstairself-4
^0,100,botania:quartzstairssunny-4

rule16^0,100,botania:quartzstairsred-6
^0,100,botania:quartzstairsmana-6
^0,100,botania:quartzstairsblaze-6
^0,100,botania:quartzstairslavender-6
^0,100,botania:quartzstairself-6
^0,100,botania:quartzstairssunny-6

rule17^0,100,botania:quartzstairsred-0
^0,100,botania:quartzstairsmana-0
^0,100,botania:quartzstairsblaze-0
^0,100,botania:quartzstairslavender-0
^0,100,botania:quartzstairself-0
^0,100,botania:quartzstairssunny-0

rule18^0,100,botania:quartzstairsred-2
^0,100,botania:quartzstairsmana-2
^0,100,botania:quartzstairsblaze-2
^0,100,botania:quartzstairslavender-2
^0,100,botania:quartzstairself-2
^0,100,botania:quartzstairssunny-2

rule19^0,100,botania:quartzstairsred-1
^0,100,botania:quartzstairsmana-1
^0,100,botania:quartzstairsblaze-1
^0,100,botania:quartzstairslavender-1
^0,100,botania:quartzstairself-1
^0,100,botania:quartzstairssunny-1

rule20^0,100,botania:quartztypered-1
^0,100,botania:quartztypemana-1
^0,100,botania:quartztypeblaze-1
^0,100,botania:quartztypelavender-1
^0,100,botania:quartztypeelf-1
^0,100,botania:quartztypesunny-1

rule21^0,100,botania:quartztypered-4
^0,100,botania:quartztypemana-4
^0,100,botania:quartztypeblaze-4
^0,100,botania:quartztypelavender-4
^0,100,botania:quartztypeelf-4
^0,100,botania:quartztypesunny-4

rule22=0,100,minecraft:ladder-2

rule23=0,100,minecraft:grass-0
^0,100,botania:altgrass-4
^0,100,botania:altgrass-2

rule24=0,100,botania:starfield-0

rule25=0,90,botania:flower-0,botania:flower-1,botania:flower-2,botania:flower-3,botania:flower-4,botania:flower-5,botania:flower-6,botania:flower-7,botania:flower-8,botania:flower-9,botania:flower-10,botania:flower-11,botania:flower-12,botania:flower-13,botania:flower-14,botania:flower-15

rule26=0,100,MobSpawner:witch
rule27=0,100,stone
rule28=0,100,botania:elfglasspane-0

rule29=0,100,air

layer
0,0,0,0,0,0,0,0,0,0,0,0,0,0,0
0,0,0,0,0,0,0,0,0,0,0,0,0,0,0
0,0,0,0,0,0,0,0,0,0,1,0,0,0,0
0,0,0,0,0,0,0,0,0,0,0,0,0,0,0
0,0,0,0,1,0,0,0,0,0,0,0,0,0,0
0,0,0,0,0,0,0,0,0,0,0,0,0,0,0
0,0,0,0,0,1,0,0,0,0,0,0,0,0,0
0,0,0,1,0,0,0,0,0,0,0,0,0,0,0
0,0,0,0,0,0,2,0,0,1,0,0,0,0,0
0,0,0,0,0,0,1,0,0,0,0,1,0,0,0
0,0,0,0,1,0,0,0,0,2,0,0,0,0,0
0,0,0,0,0,0,0,0,0,1,0,0,0,0,0
0,0,0,0,0,0,0,0,0,0,0,0,0,0,0
0,0,0,0,0,0,0,0,0,0,0,0,0,0,0
0,0,0,0,0,0,0,0,0,0,0,0,0,0,0
endlayer

layer
0,0,0,0,0,0,0,0,0,0,0,0,0,0,0
0,0,0,0,0,0,0,0,0,0,0,0,0,0,0
0,0,0,0,0,0,1,0,0,0,1,0,0,0,0
0,0,0,0,0,0,0,0,0,1,0,0,0,0,0
0,0,1,0,1,0,0,0,0,0,0,0,0,0,0
0,0,0,0,0,0,1,1,1,0,0,0,1,0,0
0,0,0,0,0,1,1,3,1,1,0,0,0,0,0
6,0,0,1,0,1,5,0,4,1,0,1,0,0,0
0,0,0,0,0,1,1,2,1,1,0,0,1,0,0
0,0,1,0,1,3,1,1,1,0,0,1,0,0,0
0,0,0,0,1,1,0,0,0,1,0,1,0,0,0
0,0,0,0,0,0,0,0,1,1,0,0,0,0,0
0,0,0,0,0,1,0,0,0,0,0,0,0,0,0
0,0,0,0,0,0,0,0,0,0,0,0,0,0,0
0,0,0,0,0,0,0,0,0,0,0,0,0,0,0
endlayer

layer
0,0,0,0,0,0,0,0,0,0,0,0,0,0,0
0,0,0,0,1,0,0,0,1,0,0,0,0,0,0
0,0,0,0,0,0,1,0,0,0,1,0,1,0,0
0,0,0,1,0,1,1,1,1,1,0,0,0,0,0
6,0,1,0,1,1,1,1,1,1,1,0,0,1,0
0,0,0,1,1,1,8,7,1,1,1,1,1,0,0
0,1,0,1,1,11,9,10,9,1,1,1,0,0,0
6,0,0,1,1,13,10,0,10,12,1,1,1,0,0
0,0,0,1,1,16,15,10,14,1,1,1,1,0,0
0,0,1,1,1,1,19,18,17,1,1,1,0,0,0
0,0,1,0,1,1,1,1,1,1,1,1,0,1,0
0,0,0,0,0,1,1,1,1,1,0,0,0,0,0
0,0,0,0,0,1,0,0,0,0,1,0,6,0,0
0,0,0,6,0,0,1,0,0,0,0,0,0,0,0
0,0,0,0,0,0,0,0,0,0,0,0,0,0,0
endlayer

layer
0,0,0,0,0,0,6,0,2,0,0,0,0,0,0
0,0,4,6,1,0,0,1,1,0,0,0,0,0,0
0,0,0,0,1,1,1,1,1,1,1,0,1,0,0
0,0,0,1,1,1,1,1,1,1,1,1,0,6,0
6,0,1,1,1,1,20,20,20,1,1,1,1,1,0
3,0,1,1,1,20,20,20,20,20,1,1,1,0,6
6,1,1,1,20,20,20,10,20,20,20,1,1,0,0
6,1,1,1,20,20,10,0,10,20,20,1,1,1,5
0,0,1,1,20,20,20,10,20,20,20,1,1,0,6
0,0,1,1,1,20,20,20,20,20,1,1,1,0,0
6,0,1,1,1,1,20,20,20,1,1,1,1,1,0
0,0,0,1,1,1,1,1,1,1,1,1,3,0,0
0,0,0,0,1,1,1,1,1,1,1,0,6,0,0
0,0,0,6,0,0,1,0,6,0,0,0,0,0,0
0,0,0,0,0,0,0,0,0,0,0,0,0,0,0
endlayer

layer
0,0,0,0,0,4,6,6,0,6,0,0,0,0,0
0,0,0,6,1,1,6,1,1,1,1,6,2,0,0
0,0,6,6,1,1,1,1,1,1,1,1,1,6,0
0,6,6,1,1,1,21,21,21,1,1,1,1,6,0
6,1,1,1,1,10,0,0,0,10,1,1,1,1,5
6,1,1,1,10,0,0,0,0,10,10,1,1,1,6
6,6,1,9,0,0,0,10,0,0,0,9,1,1,6
6,6,1,9,0,0,10,0,10,0,0,9,1,1,0
4,6,1,9,0,0,0,10,0,0,0,9,1,1,6
6,1,1,1,10,22,0,0,0,0,10,1,1,1,3
6,1,1,1,1,10,0,0,0,10,1,1,1,1,6
4,6,1,1,1,1,21,21,21,1,1,1,1,6,0
0,3,1,1,1,1,1,1,1,1,1,1,6,0,0
0,0,6,6,6,6,6,6,6,6,6,6,0,0,0
0,0,0,0,6,0,0,6,0,0,0,0,0,0,0
endlayer

layer
0,0,0,0,0,6,6,6,6,6,23,0,0,0,0
0,0,6,6,6,1,1,1,1,1,1,6,6,0,0
0,6,1,1,1,1,1,1,1,1,1,1,1,6,0
0,6,1,1,1,1,12,20,12,1,1,1,1,6,0
23,1,1,1,1,10,0,0,0,10,1,1,1,1,6
6,1,1,1,10,0,0,0,0,24,10,1,1,1,6
6,1,1,12,0,0,0,10,0,0,0,12,1,1,6
6,1,1,20,0,0,10,0,10,0,0,20,1,1,6
6,1,1,12,0,0,0,10,0,0,0,12,1,1,6
6,1,1,1,10,22,0,0,0,0,10,1,1,1,6
6,1,1,1,1,10,0,0,0,10,1,1,1,1,23
0,6,1,1,1,1,12,20,12,1,1,1,1,6,0
0,6,1,1,1,1,1,1,1,1,1,1,1,6,0
0,0,6,6,1,1,1,1,1,1,1,6,6,3,0
0,0,0,0,23,6,6,6,6,6,6,0,0,0,0
endlayer

layer
0,0,0,0,23,6,23,23,23,6,25,0,0,0,0
0,0,23,6,1,1,1,1,1,1,6,6,23,0,0
0,23,6,1,1,1,1,1,1,1,1,1,6,23,5
0,6,1,1,1,1,12,20,12,1,1,1,1,6,0
25,6,1,1,1,10,0,0,0,10,26,1,1,1,23
6,1,1,1,10,0,0,0,0,0,10,1,1,1,6
23,1,1,12,0,0,0,10,0,0,0,12,1,1,23
23,1,1,20,0,0,10,0,10,0,0,20,1,1,23
23,1,1,12,0,0,0,10,0,0,0,12,1,1,23
6,1,1,1,10,22,0,0,0,0,10,1,1,1,6
23,1,1,1,1,10,0,0,0,10,1,1,1,6,25
0,6,1,1,1,1,12,20,12,1,1,1,1,6,0
0,23,6,1,1,1,1,1,1,1,1,1,6,23,0
0,0,23,6,6,1,1,1,1,1,1,6,23,0,0
0,0,0,0,25,6,23,23,23,6,23,0,0,0,0
endlayer

layer
0,0,0,0,0,17,25,25,0,17,2,0,0,0,0
0,0,0,23,23,23,23,23,23,23,23,23,25,0,0
0,25,23,10,6,6,23,23,23,6,6,10,23,25,0
0,23,10,6,6,6,12,20,12,6,6,6,10,23,0
0,23,6,6,1,10,0,0,0,10,1,6,6,23,25
14,23,6,6,10,0,0,0,0,0,10,1,6,23,18
0,23,23,12,0,0,0,10,0,0,0,12,23,23,0
25,23,23,20,0,0,10,0,10,0,0,20,23,23,25
0,23,23,12,0,0,0,10,0,0,0,12,23,23,0
14,23,6,6,10,22,0,0,0,0,10,6,6,23,18
25,23,6,6,1,10,0,0,0,10,1,6,6,23,0
0,23,10,6,6,6,12,20,12,6,6,6,10,23,0
0,25,23,10,6,6,23,23,23,6,6,10,23,25,0
0,0,25,23,23,23,23,23,23,23,23,23,25,0,0
0,0,0,0,0,19,25,0,25,19,0,0,0,0,0
endlayer

layer
0,0,0,0,0,0,0,0,0,0,0,0,0,0,0
0,0,0,0,25,17,0,25,25,17,25,0,0,0,0
0,0,25,10,23,12,17,17,17,12,23,10,25,0,0
0,25,10,12,15,12,21,21,21,12,15,12,10,25,0
0,0,23,11,1,10,0,0,0,10,1,16,23,25,0
0,14,12,12,10,0,0,0,0,0,10,12,12,18,0
0,25,14,9,0,0,0,10,0,0,0,9,18,25,0
0,0,14,9,0,0,10,0,10,0,0,9,18,0,0
0,25,14,9,0,0,0,10,0,0,0,9,18,0,0
0,14,12,12,10,22,0,0,0,0,10,12,12,18,0
0,25,23,11,1,10,0,0,0,10,1,16,23,25,0
0,25,10,12,13,12,21,21,21,12,13,12,10,0,0
0,0,25,10,23,12,19,19,19,12,23,10,25,0,0
0,0,0,0,25,19,0,25,0,19,25,25,0,0,0
0,0,0,0,0,0,0,0,0,0,0,0,0,0,0
endlayer

layer
0,0,0,0,0,0,0,0,0,0,0,0,0,0,0
0,0,0,0,0,0,0,0,0,0,0,0,0,0,0
0,0,0,10,25,17,0,0,0,17,25,10,0,0,0
0,0,10,12,17,12,17,17,17,12,17,12,10,0,0
0,0,25,14,8,20,20,20,20,9,27,18,25,0,0
0,0,14,12,20,20,20,20,20,20,21,12,18,0,0
0,0,0,14,20,20,20,20,20,20,20,18,0,0,0
0,0,0,14,20,20,20,28,20,20,20,18,0,0,0
0,0,0,14,20,20,20,20,20,20,20,18,0,0,0
0,0,14,12,10,20,20,20,20,20,20,12,18,0,0
0,0,25,14,7,10,20,20,20,20,10,18,25,0,0
0,0,10,12,19,12,19,19,19,12,19,12,10,0,0
0,0,0,10,0,19,0,0,0,19,25,10,0,0,0
0,0,0,0,0,0,0,0,0,0,0,0,0,0,0
0,0,0,0,0,0,0,0,0,0,0,0,0,0,0
endlayer

layer
0,0,0,0,0,0,0,0,0,0,0,0,0,0,0
0,0,0,0,0,0,0,0,0,0,0,0,0,0,0
0,0,0,17,0,0,0,0,0,0,0,17,0,0,0
0,0,14,12,0,17,0,0,0,17,0,12,18,0,0
0,0,0,0,10,12,0,0,0,12,10,0,0,0,0
0,0,0,14,12,0,0,0,0,0,12,18,0,0,0
0,0,0,0,0,0,0,0,0,0,0,0,0,0,0
0,0,0,0,0,0,0,0,0,0,0,0,0,0,0
0,0,0,0,0,0,0,0,0,0,0,0,0,0,0
0,0,0,14,12,0,0,0,0,0,12,18,0,0,0
0,0,0,0,10,12,0,0,0,12,10,0,0,0,0
0,0,14,12,0,19,0,0,0,19,0,12,18,0,0
0,0,0,19,0,0,0,0,0,0,0,19,0,0,0
0,0,0,0,0,0,0,0,0,0,0,0,0,0,0
0,0,0,0,0,0,0,0,0,0,0,0,0,0,0
endlayer

layer
0,0,0,0,0,0,0,0,0,0,0,0,0,0,0
0,0,0,0,0,0,0,0,0,0,0,0,0,0,0
0,0,0,0,0,0,0,0,0,0,0,0,0,0,0
0,0,0,28,0,0,0,0,0,0,0,28,0,0,0
0,0,0,0,10,12,0,0,0,12,10,0,0,0,0
0,0,0,0,12,0,0,0,0,0,12,0,0,0,0
0,0,0,0,0,0,0,0,0,0,0,0,0,0,0
0,0,0,0,0,0,0,0,0,0,0,0,0,0,0
0,0,0,0,0,0,0,0,0,0,0,0,0,0,0
0,0,0,0,12,0,0,0,0,0,12,0,0,0,0
0,0,0,0,10,12,0,0,0,12,10,0,0,0,0
0,0,0,28,0,0,0,0,0,0,0,28,0,0,0
0,0,0,0,0,0,0,0,0,0,0,0,0,0,0
0,0,0,0,0,0,0,0,0,0,0,0,0,0,0
0,0,0,0,0,0,0,0,0,0,0,0,0,0,0
endlayer

layer
0,0,0,0,0,0,0,0,0,0,0,0,0,0,0
0,0,0,0,0,0,0,0,0,0,0,0,0,0,0
0,0,0,0,0,0,0,0,0,0,0,0,0,0,0
0,0,0,0,0,0,0,0,0,0,0,0,0,0,0
0,0,0,0,10,12,0,0,0,12,10,0,0,0,0
0,0,0,0,12,0,0,0,0,0,12,0,0,0,0
0,0,0,0,0,0,0,0,0,0,0,0,0,0,0
0,0,0,0,0,0,0,29,0,0,0,0,0,0,0
0,0,0,0,0,0,0,0,0,0,0,0,0,0,0
0,0,0,0,12,0,0,0,0,0,12,0,0,0,0
0,0,0,0,10,12,0,0,0,12,10,0,0,0,0
0,0,0,0,0,0,0,0,0,0,0,0,0,0,0
0,0,0,0,0,0,0,0,0,0,0,0,0,0,0
0,0,0,0,0,0,0,0,0,0,0,0,0,0,0
0,0,0,0,0,0,0,0,0,0,0,0,0,0,0
endlayer

layer
0,0,0,0,0,0,0,0,0,0,0,0,0,0,0
0,0,0,0,0,0,0,0,0,0,0,0,0,0,0
0,0,0,0,0,0,0,0,0,0,0,0,0,0,0
0,0,0,0,0,0,0,0,0,0,0,0,0,0,0
0,0,0,0,10,12,16,0,11,12,10,0,0,0,0
0,0,0,0,12,28,0,0,0,28,12,0,0,0,0
0,0,0,0,13,0,0,0,0,0,13,0,0,0,0
0,0,0,0,0,0,0,0,0,0,0,0,0,0,0
0,0,0,0,15,0,0,0,0,0,15,0,0,0,0
0,0,0,0,12,28,0,0,0,28,12,0,0,0,0
0,0,0,0,10,12,16,0,11,12,10,0,0,0,0
0,0,0,0,0,0,0,0,0,0,0,0,0,0,0
0,0,0,0,0,0,0,0,0,0,0,0,0,0,0
0,0,0,0,0,0,0,0,0,0,0,0,0,0,0
0,0,0,0,0,0,0,0,0,0,0,0,0,0,0
endlayer

layer
0,0,0,0,0,0,0,0,0,0,0,0,0,0,0
0,0,0,0,0,0,0,0,0,0,0,0,0,0,0
0,0,0,0,0,0,0,0,0,0,0,0,0,0,0
0,0,0,8,15,8,15,8,15,8,15,8,0,0,0
0,0,0,11,12,12,12,12,12,12,12,16,0,0,0
0,0,0,8,12,20,0,0,0,20,12,8,0,0,0
0,0,0,11,12,0,0,0,0,0,12,16,0,0,0
0,0,0,8,12,0,0,0,0,0,12,8,0,0,0
0,0,0,11,12,0,0,0,0,0,12,16,0,0,0
0,0,0,8,12,20,0,0,0,20,12,8,0,0,0
0,0,0,11,12,12,12,12,12,12,12,16,0,0,0
0,0,0,8,13,8,13,8,13,8,13,8,0,0,0
0,0,0,0,0,0,0,0,0,0,0,0,0,0,0
0,0,0,0,0,0,0,0,0,0,0,0,0,0,0
0,0,0,0,0,0,0,0,0,0,0,0,0,0,0
endlayer

layer
0,0,0,0,0,0,0,0,0,0,0,0,0,0,0
0,0,0,0,0,0,0,0,0,0,0,0,0,0,0
0,0,0,0,0,0,0,15,0,0,0,0,0,0,0
0,0,0,15,15,15,15,12,15,15,15,15,0,0,0
0,0,0,11,12,21,21,9,21,21,12,16,0,0,0
0,0,0,11,9,10,0,0,0,10,9,16,0,0,0
0,0,0,11,9,0,0,0,0,0,9,16,0,0,0
0,0,11,12,21,0,0,0,0,0,21,12,16,0,0
0,0,0,11,9,0,0,0,0,0,9,16,0,0,0
0,0,0,11,9,10,0,0,0,10,9,16,0,0,0
0,0,0,11,12,21,21,9,21,21,12,16,0,0,0
0,0,0,11,13,13,13,12,13,13,13,13,0,0,0
0,0,0,0,0,0,0,13,0,0,0,0,0,0,0
0,0,0,0,0,0,0,0,0,0,0,0,0,0,0
0,0,0,0,0,0,0,0,0,0,0,0,0,0,0
endlayer

layer
0,0,0,0,0,0,0,0,0,0,0,0,0,0,0
0,0,0,0,0,0,0,0,0,0,0,0,0,0,0
0,0,0,0,0,0,0,19,0,0,0,0,0,0,0
0,0,0,12,18,0,0,0,0,0,14,12,0,0,0
0,0,0,19,17,17,7,17,7,17,17,19,0,0,0
0,0,0,0,14,10,13,13,13,10,18,0,0,0,0
0,0,0,0,7,16,0,0,0,11,7,0,0,0,0
0,0,18,0,14,16,0,0,0,11,18,0,14,0,0
0,0,0,0,7,16,0,0,0,11,7,0,0,0,0
0,0,0,0,14,10,15,15,15,10,18,0,0,0,0
0,0,0,17,19,19,7,19,7,19,19,17,0,0,0
0,0,0,12,18,0,0,0,0,0,14,12,0,0,0
0,0,0,0,0,0,0,17,0,0,0,0,0,0,0
0,0,0,0,0,0,0,0,0,0,0,0,0,0,0
0,0,0,0,0,0,0,0,0,0,0,0,0,0,0
endlayer

layer
0,0,0,0,0,0,0,0,0,0,0,0,0,0,0
0,0,0,0,0,0,0,0,0,0,0,0,0,0,0
0,0,0,0,0,0,0,0,0,0,0,0,0,0,0
0,0,0,7,0,0,0,0,0,0,0,7,0,0,0
0,0,0,0,0,0,0,0,0,0,0,0,0,0,0
0,0,0,0,0,28,0,17,0,28,0,0,0,0,0
0,0,0,0,0,0,7,13,7,0,0,0,0,0,0
0,0,0,0,0,14,16,0,11,18,0,0,0,0,0
0,0,0,0,0,0,7,15,7,0,0,0,0,0,0
0,0,0,0,0,28,0,19,0,28,0,0,0,0,0
0,0,0,0,0,0,0,0,0,0,0,0,0,0,0
0,0,0,7,0,0,0,0,0,0,0,7,0,0,0
0,0,0,0,0,0,0,0,0,0,0,0,0,0,0
0,0,0,0,0,0,0,0,0,0,0,0,0,0,0
0,0,0,0,0,0,0,0,0,0,0,0,0,0,0
endlayer

