# Castle Greywolf (NO CB)
# Created by Ruins mod version 16.4 Ingame Parser
# authoring Player: Jordan_Greywolf
# Created for MC 1.11: 23 Apr 2017
# Updated to MC 1.12: 23 Jun 2017
# Updated to MC 1.12.1: 12 Sep 2017

biomesToSpawnIn=autumn hills,autumn woods,bamboo forest,birch forest,extreme hills,extreme hills edge,fen,field,flower field,flower forest,forest,forested field,forested hills,forested island,foresthills,fungi forest,garden,grassland,green hills,grove,heathland,highland,hot springs,jade cliffs,lavender fields,lush redwoods,lush swamp,magical forest,majestic meadow,mangrove,maplewoods,meadow,meadow forest,mystic grove,ominous woods,orchard,origin island,origin valley,overgrown greens,pasture,pasture meadow,pine forest,plains,prairie,rwg_coldforest,rwg_snowforest,rwg_temperateforest,sacred springs,silkglades,sunflower plains,taiga,taigahills,thick ominous woods,thinned mystic grove,thinned pasture,wonderous woods,woodland,woodlands,wyvern biome,mining biome,birch_forest,extreme_hills,smaller_extreme_hills,mutated_forest,forest_hills,mutated_plains

uniqueMinDistance=4000

weight=1
embed_into_distance=9
acceptable_target_blocks=

unacceptable_target_blocks=flowing_water,water,flowing_lava,lava,cloud,Natura:Cloud,slime_congealed,slime_dirt,slime_grass,command_block

dimensions=45,35,29
allowable_overhang=0
max_leveling=9
leveling_buffer=-1
preserve_water=0
preserve_lava=0
preserve_plants=1

rule1=0,100,preserveBlock
rule2=0,100,minecraft:stone-6

# Castle Walls (randomized stonebrick)
rule3=0,100,minecraft:stonebrick-0,minecraft:stonebrick-0,minecraft:stonebrick-0,minecraft:stonebrick-1,minecraft:stonebrick-2

rule4=0,100,minecraft:stone-4
rule5=0,100,minecraft:stone_slab-8
rule6=0,100,minecraft:stone-0
rule7=0,100,minecraft:water-0
rule8=0,100,minecraft:stone-2
rule9=0,100,minecraft:obsidian-0

rule10=0,100,minecraft:flowing_lava

rule11=0,100,minecraft:stone_brick_stairs-6
rule12=0,100,minecraft:stone_brick_stairs-3
rule13=0,100,minecraft:stone_brick_stairs-2
rule14=0,100,minecraft:stone_brick_stairs-7
rule15=0,100,ChestGenHook:chests/simple_dungeon:5-3

rule16=0,100,MobSpawner:Skeleton,MobSpawner:Zombie,MobSpawner:Spider

rule17=0,100,minecraft:double_stone_slab-0
rule18=0,100,minecraft:cobblestone_wall-0
rule19=0,100,minecraft:water-8
rule20=0,100,minecraft:stone_stairs-2
rule21=0,100,minecraft:stone_stairs-1
rule22=0,100,minecraft:stone_stairs-3
rule23=0,100,minecraft:wooden_door-2
rule24=0,100,minecraft:water-9

rule25=0,100,minecraft:skull

rule26=0,100,ChestGenHook:chests/simple_dungeon:5-2
rule27=0,100,ChestGenHook:chests/simple_dungeon:5-4
rule28=0,100,minecraft:stone_slab-0
rule29=0,100,minecraft:wooden_door-1
rule30=0,100,minecraft:stone_stairs-0
rule31=0,100,minecraft:wooden_door-9
rule32=0,100,minecraft:water-1
rule33=0,100,minecraft:stone_brick_stairs-4
rule34=1,100,minecraft:torch-5
rule35=0,100,minecraft:stonebrick-3
rule36=0,100,minecraft:red_sandstone-1
rule37=0,100,minecraft:stone_brick_stairs-1
rule38=0,100,minecraft:grass-0

rule39=0,100,minecraft:tallgrass-2,minecraft:tallgrass-0,minecraft:tallgrass-1

rule40=0,100,minecraft:stone_brick_stairs-0
rule41=0,100,minecraft:stone_brick_stairs-5

rule42=0,100,minecraft:flowing_water

rule43=0,100,minecraft:dirt-0
rule44=0,100,minecraft:log-8
rule45=0,100,minecraft:log-0
rule46=0,100,minecraft:log-4
rule47=0,100,minecraft:clay-0
rule48=0,100,minecraft:stone_slab-13
rule49=0,100,minecraft:double_stone_slab-5

rule50=0,100,minecraft:red_flower-0,minecraft:red_flower-1,minecraft:red_flower-2,minecraft:red_flower-3,minecraft:tallgrass-2

rule51=0,100,IInventory;minecraft:chest;minecraft:stone#32#0#0+minecraft:stone#32#0#13-3,ChestGenHook:chests/spawn_bonus_chest:5-3

rule52=0,100,minecraft:oak_stairs-0
rule53=0,100,IInventory;minecraft:lit_furnace;minecraft:coal#32#0#1-2
rule54=0,100,minecraft:glass-0

rule55=0,100,minecraft:sapling-1

rule56=0,100,IInventory;minecraft:chest;minecraft:stone#16#0#0+minecraft:stone#16#0#13-3,ChestGenHook:chests/spawn_bonus_chest:5-3

rule57=0,100,minecraft:wooden_door-8
rule58=0,100,IInventory;minecraft:lit_furnace;minecraft:coal#32#1#1-2
rule59=0,100,minecraft:wooden_slab-8
rule60=0,100,minecraft:wooden_slab-10
rule61=0,100,minecraft:stone_slab-9
rule62=0,100,minecraft:stonebrick-2

rule63=0,100,teBlock;minecraft:flower_pot;{Item:"minecraft:sapling",x:0,y:0,z:0,Data:0,id:"flower_pot"}-0,teBlock;minecraft:flower_pot;{Item:"minecraft:sapling",x:0,y:0,z:0,Data:1,id:"flower_pot"}-0,teBlock;minecraft:flower_pot;{Item:"minecraft:sapling",x:0,y:0,z:0,Data:2,id:"flower_pot"}-0,teBlock;minecraft:flower_pot;{Item:"minecraft:sapling",x:0,y:0,z:0,Data:3,id:"flower_pot"}-0

rule64=0,100,minecraft:skull

rule65=0,100,minecraft:dark_oak_stairs-1
rule66=0,100,minecraft:dark_oak_stairs-3
rule67=0,100,minecraft:dark_oak_stairs-2
rule68=0,100,minecraft:oak_stairs-1
rule69=0,100,minecraft:bookshelf-0
rule70=0,100,minecraft:trapdoor-14
rule71=0,100,minecraft:stained_hardened_clay-0
rule72=0,100,minecraft:trapdoor-12
rule73=0,100,minecraft:trapdoor-13
rule74=0,100,minecraft:oak_stairs-4
rule75=0,100,minecraft:oak_stairs-6
rule76=0,100,minecraft:oak_stairs-7
rule77=0,100,minecraft:fence-0
rule78=0,100,minecraft:oak_stairs-3
rule79=0,100,minecraft:oak_stairs-2
rule80=0,100,minecraft:wooden_slab-9
rule81=0,100,minecraft:log-12
rule82=0,100,minecraft:log-1
rule83=0,100,minecraft:log-9
rule84=0,100,minecraft:log-5
rule85=0,100,minecraft:log-3
rule86=0,100,minecraft:log-7
rule87=0,100,minecraft:log-11
rule88=0,100,minecraft:planks-0
rule89=0,100,minecraft:trapdoor-15
rule90=0,100,minecraft:nether_brick_stairs-4
rule91=0,100,minecraft:stone_slab-14
rule92=0,100,minecraft:nether_brick_stairs-5
rule93=0,100,minecraft:double_plant-4
rule94=0,100,minecraft:carpet-14
rule95=0,100,minecraft:wooden_door-0

rule96=0,100,MobSpawner:Silverfish

rule97=0,100,minecraft:nether_brick_stairs-7
rule98=0,100,minecraft:nether_brick_stairs-6
rule99=0,100,minecraft:double_plant-10
rule100=0,100,minecraft:wooden_slab-12
rule101=0,100,ChestGenHook:chests/simple_dungeon:5-5
rule102=0,100,IInventory;minecraft:chest;minecraft:red_nether_brick#8#0#0+minecraft:red_nether_brick#8#0#3+minecraft:red_nether_brick#16#0#5+minecraft:red_nether_brick#8#0#6+minecraft:red_nether_brick#8#0#8+minecraft:red_nether_brick#16#0#10+minecraft:red_nether_brick#8#0#13+minecraft:red_nether_brick#16#0#16+minecraft:red_nether_brick#8#0#18+minecraft:red_nether_brick#16#0#20+minecraft:red_nether_brick#8#0#23+minecraft:red_nether_brick#8#0#26-3
rule103=0,100,IInventory;minecraft:chest;minecraft:stone#16#2#0+minecraft:stone#16#2#6+minecraft:stone#16#4#8+minecraft:stone#16#4#13+minecraft:stone#16#4#18+minecraft:stone#16#2#20+minecraft:stone#16#2#24+minecraft:stone#16#4#26-2
rule104=0,100,minecraft:ladder-4
rule105=0,100,minecraft:nether_brick_stairs-2
rule106=0,100,minecraft:nether_brick-0
rule107=0,100,minecraft:nether_brick_stairs-3
rule108=0,100,minecraft:nether_brick_stairs-0
rule109=0,100,minecraft:nether_brick_stairs-1
rule110=0,100,minecraft:stone_slab-6


rule111=0,100,MobSpawner:Spider

rule112=0,100,minecraft:stone_slab-5
rule113=0,100,minecraft:nether_brick_fence-0



layer
1,1,1,1,1,1,1,1,1,1,1,1,1,1,1,1,1,1,1,1,1,1,1,1,1,1,1,1,1
1,1,1,1,1,1,1,1,1,1,1,1,1,1,1,1,1,1,1,1,1,1,1,1,1,1,1,1,1
1,1,1,1,1,1,1,1,1,1,1,1,1,1,1,1,1,1,1,1,1,1,1,1,1,1,1,1,1
1,1,1,1,1,1,1,1,1,1,1,1,1,1,1,1,1,1,1,1,1,1,1,1,1,1,1,1,1
1,1,1,1,1,1,1,1,1,1,1,1,1,1,1,1,1,1,1,1,1,1,1,1,1,1,1,1,1
1,1,1,1,1,1,1,3,3,3,3,3,3,3,3,3,3,3,3,3,3,3,3,2,1,1,1,2,1
1,1,1,1,1,1,3,6,6,6,6,6,5,3,4,4,4,4,4,4,4,4,4,3,1,1,1,1,1
1,3,3,3,3,3,6,6,6,6,6,6,3,3,4,4,4,4,4,4,4,4,4,3,1,1,1,1,1
3,3,3,6,6,6,6,6,6,6,6,6,6,3,4,4,4,4,4,4,4,7,7,3,1,1,1,1,1
3,3,3,6,6,6,6,6,6,6,6,6,6,3,4,4,4,4,4,4,4,7,7,3,1,1,1,1,1
3,3,3,6,6,3,6,6,6,6,6,6,6,3,4,4,4,4,4,4,4,7,7,3,1,1,1,1,1
1,3,3,3,3,3,6,6,6,6,6,6,6,3,4,4,4,4,4,4,4,4,4,3,1,1,1,1,1
1,1,1,1,1,1,3,3,3,3,3,3,6,3,4,4,4,4,4,4,4,4,4,3,1,1,1,1,1
1,1,1,1,1,1,2,3,3,3,3,3,3,6,3,3,3,3,3,3,3,3,3,2,1,1,1,2,1
1,1,1,1,1,3,3,3,3,8,3,3,3,3,1,1,1,1,1,1,1,1,1,1,1,1,1,1,1
1,1,1,1,1,3,3,8,8,8,8,8,3,3,1,1,1,1,1,1,1,1,1,1,1,1,1,1,1
1,1,1,1,1,1,3,2,7,8,7,2,3,1,1,1,1,1,1,1,1,1,1,1,1,1,1,1,1
1,1,1,1,1,3,3,7,7,8,7,7,3,3,1,1,1,1,1,1,1,1,1,1,1,1,1,1,1
1,1,1,1,1,3,3,7,7,8,7,7,3,3,1,1,1,1,1,1,1,1,1,1,1,1,1,1,1
1,1,1,1,1,1,2,2,7,8,7,2,2,1,1,1,1,1,1,1,1,1,1,1,1,1,1,1,1
1,1,1,1,1,1,3,8,8,8,8,8,3,1,1,1,1,1,1,1,1,1,1,1,1,1,1,1,1
1,1,1,2,3,3,3,3,3,3,3,3,3,3,3,2,1,1,1,1,1,1,1,1,1,1,1,1,1
1,1,1,3,8,8,8,8,8,9,8,8,8,8,8,3,1,1,1,1,1,1,1,1,1,1,1,1,1
1,1,3,3,8,2,8,8,9,9,9,8,8,2,8,3,3,1,1,1,1,1,1,1,1,1,1,1,1
1,1,3,3,8,8,8,9,9,10,9,9,8,8,8,3,3,1,1,1,1,1,1,1,1,1,1,1,1
1,1,1,3,8,9,9,9,10,10,10,9,9,9,8,3,1,1,1,1,1,1,1,1,1,1,1,1,1
1,1,1,3,9,9,10,10,10,9,10,10,10,9,9,3,1,1,1,1,1,1,1,1,1,1,1,1,1
1,1,1,3,8,9,9,9,10,10,10,9,9,9,8,3,1,1,1,1,1,1,1,1,1,1,1,1,1
1,1,3,3,8,8,8,9,9,10,9,9,8,8,8,3,3,1,1,1,1,1,1,1,1,1,1,1,1
1,1,3,3,8,2,8,8,9,9,9,8,8,2,8,3,3,1,1,1,1,1,1,1,1,1,1,1,1
1,1,1,3,8,8,8,8,8,9,8,8,8,8,8,3,1,1,1,1,1,1,1,1,1,1,1,1,1
1,1,1,2,3,3,3,3,3,3,3,3,3,3,3,2,1,1,1,1,1,1,1,1,1,1,1,1,1
1,1,1,3,3,3,3,3,3,1,3,3,3,3,3,3,1,1,1,1,1,1,1,1,1,1,1,1,1
1,1,1,2,1,1,1,14,13,1,12,11,1,1,1,2,1,1,1,1,1,1,1,1,1,1,1,1,1
1,1,1,1,1,1,1,1,1,1,1,1,1,1,1,1,1,1,1,1,1,1,1,1,1,1,1,1,1
endlayer

layer
1,1,1,1,1,1,1,1,1,1,1,1,1,1,1,1,1,1,1,1,1,1,1,1,1,1,1,1,1
1,1,1,1,1,1,1,1,1,1,1,1,1,1,1,1,1,1,1,1,1,1,1,1,1,1,1,1,1
1,1,1,1,1,1,1,1,1,1,1,1,1,1,1,1,1,1,1,1,1,1,1,1,1,1,1,1,1
1,1,1,1,1,1,1,1,1,1,1,1,1,1,1,1,1,1,1,1,1,1,1,1,1,1,1,1,1
1,1,1,1,1,1,1,1,1,1,1,1,1,1,1,1,1,1,1,1,1,1,1,1,1,1,1,1,1
1,1,1,1,1,1,1,3,3,3,3,3,3,3,3,3,3,3,3,3,3,3,3,2,1,1,1,2,1
1,1,1,1,1,1,3,17,7,7,7,17,6,3,16,0,0,0,0,0,0,0,15,3,1,1,1,1,1
1,3,3,3,3,3,17,17,7,7,7,17,17,3,0,18,0,0,0,0,18,18,18,3,1,1,1,1,1
3,17,17,17,17,3,17,17,17,17,17,17,17,3,0,0,0,0,0,0,18,0,16,3,1,1,1,1,1
3,17,17,17,17,17,17,17,17,17,17,17,17,20,0,0,0,0,0,0,0,0,19,3,1,1,1,1,1
3,17,17,17,17,3,17,17,17,17,17,17,17,3,0,0,0,0,0,0,18,0,16,3,1,1,1,1,1
1,3,3,3,3,3,17,17,17,17,17,17,17,3,0,18,0,0,0,0,18,18,18,3,1,1,1,1,1
1,1,1,1,1,1,3,3,3,3,21,3,6,3,16,0,0,0,0,0,0,0,15,3,1,1,1,1,1
1,1,1,1,1,1,2,3,3,0,22,3,3,6,3,3,3,3,3,3,3,3,3,2,1,1,1,2,1
1,1,1,1,1,3,3,3,3,23,3,3,3,3,1,1,1,1,1,1,1,1,1,1,1,1,1,1,1
1,1,1,1,1,3,3,16,0,0,0,16,3,3,1,1,1,1,1,1,1,1,1,1,1,1,1,1,1
1,1,1,1,1,1,3,2,0,0,0,2,3,1,1,1,1,1,1,1,1,1,1,1,1,1,1,1,1
1,1,1,1,1,3,3,24,0,0,0,24,3,3,1,1,1,1,1,1,1,1,1,1,1,1,1,1,1
1,1,1,1,1,3,3,24,0,0,0,24,3,3,1,1,1,1,1,1,1,1,1,1,1,1,1,1,1
1,1,1,1,1,1,2,2,0,0,0,2,2,1,1,1,1,1,1,1,1,1,1,1,1,1,1,1,1
1,1,1,1,1,1,3,16,0,0,0,16,3,1,1,1,1,1,1,1,1,1,1,1,1,1,1,1,1
1,1,1,2,3,3,3,3,0,0,0,3,3,3,3,2,1,1,1,1,1,1,1,1,1,1,1,1,1
1,1,1,3,25,0,0,0,0,0,0,0,0,0,25,3,1,1,1,1,1,1,1,1,1,1,1,1,1
1,1,3,3,0,2,0,0,0,0,0,0,0,2,0,3,3,1,1,1,1,1,1,1,1,1,1,1,1
1,1,3,3,0,0,0,0,0,0,0,0,0,0,0,3,3,1,1,1,1,1,1,1,1,1,1,1,1
1,1,1,3,0,0,0,0,0,0,0,0,0,0,0,3,1,1,1,1,1,1,1,1,1,1,1,1,1
1,1,1,3,26,0,0,0,0,9,0,0,0,0,15,3,1,1,1,1,1,1,1,1,1,1,1,1,1
1,1,1,3,0,0,0,0,0,0,0,0,0,0,0,3,1,1,1,1,1,1,1,1,1,1,1,1,1
1,1,3,3,0,0,0,0,0,0,0,0,0,0,0,3,3,1,1,1,1,1,1,1,1,1,1,1,1
1,1,3,3,0,2,0,0,0,0,0,0,0,2,0,3,3,1,1,1,1,1,1,1,1,1,1,1,1
1,1,1,3,25,0,0,0,0,27,0,0,0,0,25,3,1,1,1,1,1,1,1,1,1,1,1,1,1
1,1,1,2,3,3,3,3,3,3,3,3,3,3,3,2,1,1,1,1,1,1,1,1,1,1,1,1,1
1,1,1,3,3,3,3,3,3,1,3,3,3,3,3,3,1,1,1,1,1,1,1,1,1,1,1,1,1
1,1,1,2,1,1,14,13,1,1,1,12,11,1,1,2,1,1,1,1,1,1,1,1,1,1,1,1,1
1,1,1,1,1,1,1,1,1,1,1,1,1,1,1,1,1,1,1,1,1,1,1,1,1,1,1,1,1
endlayer

layer
1,1,1,1,1,1,1,1,1,1,1,1,1,1,1,1,1,1,1,1,1,1,1,1,1,1,1,1,1
1,1,1,1,1,1,1,1,1,1,1,1,1,1,1,1,1,1,1,1,1,1,1,1,1,1,1,1,1
1,1,1,1,1,1,1,1,1,1,1,1,1,1,1,1,1,1,1,1,1,1,1,1,1,1,1,1,1
1,1,1,1,1,1,1,1,1,1,1,1,1,1,1,1,1,1,1,1,1,1,1,1,1,1,1,1,1
1,1,1,1,1,1,1,1,1,1,1,1,1,1,1,1,1,1,1,1,1,1,1,1,1,1,1,1,1
1,1,1,1,1,1,1,3,3,3,3,3,3,3,3,3,3,3,3,3,3,3,3,2,1,1,1,2,1
1,1,1,1,1,1,3,0,0,19,0,0,3,3,0,0,0,0,0,0,0,0,0,3,1,1,1,1,1
1,3,3,3,3,3,1,0,0,0,0,0,0,3,0,18,0,0,0,0,18,0,18,3,1,1,1,1,1
3,28,28,28,28,3,0,0,0,0,0,0,0,3,0,0,0,0,0,0,0,0,0,3,1,1,1,1,1
3,28,28,28,28,0,0,0,0,0,0,0,29,0,0,0,0,0,0,0,0,0,19,3,1,1,1,1,1
3,28,28,28,28,3,0,0,0,0,0,0,0,3,0,0,0,0,0,0,0,0,0,3,1,1,1,1,1
1,3,3,3,3,3,0,0,0,0,23,0,0,3,0,18,0,0,0,0,18,0,18,3,1,1,1,1,1
1,1,1,1,1,1,3,30,3,3,0,3,3,3,0,0,0,0,0,0,0,0,0,3,1,1,1,1,1
1,1,1,1,1,1,2,3,3,0,0,3,3,3,3,3,3,3,3,3,3,3,3,2,1,1,1,2,1
1,1,1,1,1,3,3,3,3,31,3,3,3,3,1,1,1,1,1,1,1,1,1,1,1,1,1,1,1
1,1,1,1,1,3,3,0,0,0,0,0,3,3,1,1,1,1,1,1,1,1,1,1,1,1,1,1,1
1,1,1,1,1,1,3,2,0,0,0,2,3,1,1,1,1,1,1,1,1,1,1,1,1,1,1,1,1
1,1,1,1,1,3,7,32,0,0,0,32,7,3,1,1,1,1,1,1,1,1,1,1,1,1,1,1,1
1,1,1,1,1,3,7,32,0,0,0,32,7,3,1,1,1,1,1,1,1,1,1,1,1,1,1,1,1
1,1,1,1,1,1,2,2,0,0,0,2,2,1,1,1,1,1,1,1,1,1,1,1,1,1,1,1,1
1,1,1,1,1,1,3,0,0,0,0,0,3,1,1,1,1,1,1,1,1,1,1,1,1,1,1,1,1
1,1,1,2,3,3,3,3,0,0,0,3,3,3,3,2,1,1,1,1,1,1,1,1,1,1,1,1,1
1,1,1,3,0,0,0,0,0,0,0,0,0,0,0,3,1,1,1,1,1,1,1,1,1,1,1,1,1
1,1,3,3,0,2,0,0,0,0,0,0,0,2,0,3,3,1,1,1,1,1,1,1,1,1,1,1,1
1,1,3,3,0,0,0,0,0,0,0,0,0,0,0,3,3,1,1,1,1,1,1,1,1,1,1,1,1
1,1,1,3,0,0,0,0,0,0,0,0,0,0,0,3,1,1,1,1,1,1,1,1,1,1,1,1,1
1,1,1,3,0,0,0,0,0,9,0,0,0,0,0,3,1,1,1,1,1,1,1,1,1,1,1,1,1
1,1,1,3,0,0,0,0,0,0,0,0,0,0,0,3,1,1,1,1,1,1,1,1,1,1,1,1,1
1,1,3,3,0,0,0,0,0,0,0,0,0,0,0,3,3,1,1,1,1,1,1,1,1,1,1,1,1
1,1,3,3,0,2,0,0,0,0,0,0,0,2,0,3,3,1,1,1,1,1,1,1,1,1,1,1,1
1,1,1,3,0,0,0,0,0,0,0,0,0,0,0,3,1,1,1,1,1,1,1,1,1,1,1,1,1
1,1,1,2,3,3,3,3,3,3,3,3,3,3,3,2,1,1,1,1,1,1,1,1,1,1,1,1,1
1,1,1,3,3,3,3,3,3,1,3,3,3,3,3,3,1,1,1,1,1,1,1,1,1,1,1,1,1
1,1,1,2,1,14,13,1,1,1,1,1,12,11,1,2,1,1,1,1,1,1,1,1,1,1,1,1,1
1,1,1,1,1,1,1,1,1,1,1,1,1,1,1,1,1,1,1,1,1,1,1,1,1,1,1,1,1
endlayer

layer
1,1,1,1,1,1,1,1,1,1,1,1,1,1,1,1,1,1,1,1,1,1,1,1,1,1,1,1,1
1,1,1,1,1,1,1,1,1,1,1,1,1,1,1,1,1,1,1,1,1,1,1,1,1,1,1,1,1
1,1,1,1,1,1,1,1,1,1,1,1,1,1,1,1,1,1,1,1,1,1,1,1,1,1,1,1,1
1,1,1,1,1,1,1,1,1,1,1,1,1,1,1,1,1,1,1,1,1,1,1,1,1,1,1,1,1
1,1,1,1,1,1,1,1,1,1,1,1,1,1,1,1,1,1,1,1,1,1,1,1,1,1,1,1,1
1,1,1,1,1,1,1,3,3,3,3,3,3,3,3,3,3,3,3,3,3,3,3,2,1,1,1,2,1
1,1,1,1,1,1,3,0,0,19,0,0,3,3,0,0,0,0,0,0,0,0,0,3,1,1,1,1,1
1,3,3,3,3,3,18,0,0,0,0,0,18,3,0,18,0,0,0,0,18,0,18,3,1,1,1,1,1
3,16,0,0,0,3,0,0,0,0,0,0,0,3,0,0,0,0,0,0,0,0,0,3,1,1,1,1,1
3,26,0,0,0,0,0,0,0,0,0,0,31,0,0,0,0,0,0,0,0,0,19,3,1,1,1,1,1
3,16,0,0,0,3,0,0,0,0,0,0,0,3,0,0,0,0,0,0,0,0,0,3,1,1,1,1,1
1,3,3,3,3,3,18,0,0,0,31,0,18,3,0,18,0,0,0,0,18,0,18,3,1,1,1,1,1
1,1,1,1,1,1,3,0,22,3,0,3,3,3,0,0,0,0,0,0,0,0,0,3,1,1,1,1,1
1,1,1,1,1,1,2,3,3,0,0,3,3,3,3,3,3,3,3,3,3,3,3,2,1,1,1,2,1
1,1,1,1,1,12,3,3,3,33,3,3,3,13,1,1,1,1,1,1,1,1,1,1,1,1,1,1,1
1,1,1,1,1,12,3,0,0,0,0,0,3,13,1,1,1,1,1,1,1,1,1,1,1,1,1,1,1
1,1,1,1,1,1,3,2,0,0,0,2,3,1,1,1,1,1,1,1,1,1,1,1,1,1,1,1,1
1,1,1,1,1,12,3,13,0,0,0,12,3,13,1,1,1,1,1,1,1,1,1,1,1,1,1,1,1
1,1,1,1,1,12,3,13,0,0,0,12,3,13,1,1,1,1,1,1,1,1,1,1,1,1,1,1,1
1,1,1,1,1,1,2,2,0,0,0,2,2,1,1,1,1,1,1,1,1,1,1,1,1,1,1,1,1
1,1,1,1,1,1,3,0,0,0,0,0,3,1,1,1,1,1,1,1,1,1,1,1,1,1,1,1,1
1,1,1,2,3,3,3,3,0,0,0,3,3,3,3,2,1,1,1,1,1,1,1,1,1,1,1,1,1
1,1,1,3,16,0,0,0,0,0,0,0,0,0,16,3,1,1,1,1,1,1,1,1,1,1,1,1,1
1,1,3,3,0,2,0,0,0,0,0,0,0,2,0,3,3,1,1,1,1,1,1,1,1,1,1,1,1
1,1,3,3,0,0,0,0,0,0,0,0,0,0,0,3,3,1,1,1,1,1,1,1,1,1,1,1,1
1,1,1,3,0,0,0,0,0,0,0,0,0,0,0,3,1,1,1,1,1,1,1,1,1,1,1,1,1
1,1,1,3,0,0,0,0,0,10,0,0,0,0,0,3,1,1,1,1,1,1,1,1,1,1,1,1,1
1,1,1,3,0,0,0,0,0,0,0,0,0,0,0,3,1,1,1,1,1,1,1,1,1,1,1,1,1
1,1,3,3,0,0,0,0,0,0,0,0,0,0,0,3,3,1,1,1,1,1,1,1,1,1,1,1,1
1,1,3,3,0,2,0,0,0,0,0,0,0,2,0,3,3,1,1,1,1,1,1,1,1,1,1,1,1
1,1,1,3,16,0,0,0,0,0,0,0,0,0,16,3,1,1,1,1,1,1,1,1,1,1,1,1,1
1,1,1,2,3,3,3,3,3,3,3,3,3,3,3,2,1,1,1,1,1,1,1,1,1,1,1,1,1
1,1,1,3,3,3,3,3,3,1,3,3,3,3,3,3,1,1,1,1,1,1,1,1,1,1,1,1,1
1,1,1,2,14,13,1,1,1,1,1,1,1,12,11,2,1,1,1,1,1,1,1,1,1,1,1,1,1
1,1,1,1,1,1,1,1,1,1,1,1,1,1,1,1,1,1,1,1,1,1,1,1,1,1,1,1,1
endlayer

layer
1,1,1,1,1,1,1,1,1,1,1,1,1,1,1,1,1,1,1,1,1,1,1,1,1,1,1,1,1
1,1,1,1,1,1,1,1,1,1,1,1,1,1,1,1,1,1,1,1,1,1,1,1,1,1,1,1,1
1,1,1,1,1,1,1,1,1,1,1,1,1,1,1,1,1,1,1,1,1,1,1,1,1,1,1,1,1
1,1,1,1,1,1,1,1,1,1,1,1,1,1,1,1,1,1,1,1,1,1,1,1,1,1,1,1,1
1,1,1,1,1,1,1,1,1,1,1,1,1,1,1,1,1,1,1,1,1,1,1,1,1,1,1,1,1
1,1,1,1,1,1,1,3,3,3,3,3,3,3,3,3,3,3,3,3,3,3,3,2,1,1,1,2,1
1,1,1,1,1,1,3,0,0,19,0,0,3,3,0,0,0,0,0,0,0,0,0,3,1,1,1,1,1
1,3,3,3,3,3,34,0,0,0,0,0,34,3,0,18,0,0,0,0,18,18,18,3,1,1,1,1,1
3,0,0,0,0,3,0,0,0,0,0,0,0,3,0,0,0,0,0,0,18,0,0,3,1,1,1,1,1
3,0,0,0,0,0,0,0,0,0,0,0,0,3,0,0,0,0,0,0,18,0,19,3,1,1,1,1,0
3,0,0,0,0,3,0,0,0,0,0,0,0,3,0,0,0,0,0,0,18,0,0,3,1,1,1,1,1
1,3,3,3,3,3,34,0,0,0,0,0,34,3,0,18,0,0,0,0,18,18,18,3,1,1,1,1,1
1,1,1,1,1,1,3,0,0,22,3,3,3,3,0,0,0,0,0,0,0,0,0,3,1,1,1,1,1
1,1,1,1,1,1,2,3,3,3,3,3,6,3,3,3,3,3,3,3,3,3,3,2,1,1,1,2,1
1,1,1,1,1,1,3,3,3,3,3,3,3,1,1,1,1,1,1,1,1,1,1,1,1,1,1,1,1
1,1,1,1,1,1,3,0,0,0,0,0,3,1,1,1,1,1,1,1,1,1,1,1,1,1,1,1,1
1,1,1,1,1,1,3,2,0,0,0,2,3,1,1,1,1,1,1,1,1,1,1,1,1,1,1,1,1
1,1,1,1,1,1,3,0,0,0,0,0,3,1,1,1,1,1,1,1,1,1,1,1,1,1,1,1,1
1,1,1,1,1,1,3,0,0,0,0,0,3,1,1,1,1,1,1,1,1,1,1,1,1,1,1,1,1
1,1,1,1,1,1,2,2,0,0,0,2,2,1,1,1,1,1,1,1,1,1,1,1,1,1,1,1,1
1,1,1,1,1,1,3,0,0,0,0,0,3,1,1,1,1,1,1,1,1,1,1,1,1,1,1,1,1
1,1,1,2,3,3,3,3,11,0,14,3,3,3,3,2,1,1,1,1,1,1,1,1,1,1,1,1,1
1,1,1,3,0,0,0,0,0,0,0,0,0,0,0,3,1,1,1,1,1,1,1,1,1,1,1,1,1
1,1,3,3,0,2,0,0,0,0,0,0,0,2,0,3,3,1,1,1,1,1,1,1,1,1,1,1,1
1,1,3,3,0,0,0,0,0,0,0,0,0,0,0,3,3,1,1,1,1,1,1,1,1,1,1,1,1
1,1,1,3,0,0,0,0,0,0,0,0,0,0,0,3,1,1,1,1,1,1,1,1,1,1,1,1,1
1,1,1,3,0,0,0,0,0,0,0,0,0,0,0,3,1,1,1,1,1,1,1,1,1,1,1,1,1
1,1,1,3,0,0,0,0,0,0,0,0,0,0,0,3,1,1,1,1,1,1,1,1,1,1,1,1,1
1,1,3,3,0,0,0,0,0,0,0,0,0,0,0,3,3,1,1,1,1,1,1,1,1,1,1,1,1
1,1,3,3,0,2,0,0,0,0,0,0,0,2,0,3,3,1,1,1,1,1,1,1,1,1,1,1,1
1,1,1,3,0,0,0,0,0,0,0,0,0,0,0,3,1,1,1,1,1,1,1,1,1,1,1,1,1
1,1,1,2,3,3,3,3,3,3,3,3,3,3,3,2,1,1,1,1,1,1,1,1,1,1,1,1,1
1,1,1,3,3,3,3,3,3,1,3,3,3,3,3,3,1,1,1,1,1,1,1,1,1,1,1,1,1
1,1,1,2,13,1,1,1,1,1,1,1,1,1,12,2,1,1,1,1,1,1,1,1,1,1,1,1,1
1,1,1,1,1,1,1,1,1,1,1,1,1,1,1,1,1,1,1,1,1,1,1,1,1,1,1,1,1
endlayer

layer
1,1,1,1,1,1,1,1,1,1,1,1,1,1,1,1,1,1,1,1,1,1,1,1,1,1,1,1,1
1,1,1,1,1,1,1,1,1,1,1,1,1,1,1,1,1,1,1,1,1,1,1,1,1,1,1,1,1
1,1,1,1,1,1,1,1,1,1,1,1,1,1,1,1,1,1,1,1,1,1,1,1,1,1,1,1,1
1,1,1,1,1,1,1,1,1,1,1,1,1,1,1,1,1,1,1,1,1,1,1,1,1,1,1,1,1
1,1,1,1,1,1,1,1,1,1,1,1,1,1,1,1,1,1,1,1,1,1,1,1,1,1,1,1,1
1,1,1,1,1,1,1,3,3,3,3,3,3,3,3,3,3,3,3,3,3,3,3,2,1,1,1,2,1
1,1,1,1,1,1,3,5,5,19,5,5,3,6,6,6,6,6,6,6,6,6,6,3,1,1,1,1,1
1,3,3,3,3,3,5,5,5,5,5,5,5,3,6,6,6,6,6,6,6,6,6,3,1,1,1,1,1
3,5,5,5,5,3,5,5,5,5,5,5,5,3,6,6,6,6,6,6,6,6,6,3,1,1,1,1,1
3,5,5,5,5,3,5,5,5,5,5,5,5,3,6,6,6,6,6,6,6,6,19,3,1,1,1,0,0
3,5,5,5,5,3,5,5,5,5,5,5,5,3,6,6,6,6,6,6,6,6,6,3,1,1,1,1,1
1,3,3,3,3,3,5,5,5,5,5,5,5,3,6,6,6,6,6,6,6,6,6,3,1,1,1,1,1
1,1,1,1,1,1,3,0,0,0,22,3,3,6,6,6,6,6,6,6,6,6,6,3,1,1,1,1,1
1,1,1,1,1,1,2,3,3,3,3,3,3,3,3,3,3,3,3,3,3,3,3,2,1,1,1,2,1
1,1,1,1,1,1,3,35,36,35,36,35,3,1,1,1,1,1,1,1,1,1,1,1,1,1,1,1,1
1,1,1,1,1,1,3,36,35,36,35,36,3,1,1,1,1,1,1,1,1,1,1,1,1,1,1,1,1
1,1,1,1,1,1,3,35,36,35,36,35,3,1,1,1,1,1,1,1,1,1,1,1,1,1,1,1,1
1,1,1,1,1,1,3,36,35,36,35,36,3,1,1,1,1,1,1,1,1,1,1,1,1,1,1,1,1
1,1,1,1,1,1,3,35,36,35,36,35,3,1,1,1,1,1,1,1,1,1,1,1,1,1,1,1,1
1,1,1,1,1,1,2,36,35,36,35,36,2,1,1,1,1,1,1,1,1,1,1,1,1,1,1,1,1
1,1,1,1,1,1,3,35,36,35,36,35,3,1,1,1,1,1,1,1,1,1,1,1,1,1,1,1,1
1,1,1,2,3,3,3,3,3,3,3,3,3,3,3,2,1,1,1,1,1,1,1,1,1,1,1,1,1
1,1,1,3,0,0,0,0,0,0,0,0,0,0,0,3,1,1,1,1,1,1,1,1,1,1,1,1,1
1,1,3,3,0,2,0,0,0,0,0,0,0,2,0,3,3,1,1,1,1,1,1,1,1,1,1,1,1
1,1,3,3,0,0,0,0,0,0,0,0,0,0,0,3,3,1,1,1,1,1,1,1,1,1,1,1,1
1,1,1,3,0,0,0,0,0,0,0,0,0,0,0,3,1,1,1,1,1,1,1,1,1,1,1,1,1
1,1,1,3,0,0,0,0,0,0,0,0,0,0,0,3,1,1,1,1,1,1,1,1,1,1,1,1,1
1,1,1,3,0,0,0,0,0,0,0,0,0,0,0,3,1,1,1,1,1,1,1,1,1,1,1,1,1
1,1,3,3,0,0,0,0,0,0,0,0,0,0,0,3,3,1,1,1,1,1,1,1,1,1,1,1,1
1,1,3,3,0,2,0,0,0,0,0,0,0,2,0,3,3,1,1,1,1,1,1,1,1,1,1,1,1
1,1,1,3,0,0,0,0,0,0,0,0,0,0,0,3,1,1,1,1,1,1,1,1,1,1,1,1,1
1,1,1,2,3,3,3,3,3,3,3,3,3,3,3,2,1,1,1,1,1,1,1,1,1,1,1,1,1
1,1,1,37,3,13,37,12,3,1,3,13,37,12,3,37,1,1,1,1,1,1,1,1,1,1,1,1,1
1,1,1,1,1,1,1,1,1,1,1,1,1,1,1,1,1,1,1,1,1,1,1,1,1,1,1,1,1
1,1,1,1,1,1,1,1,1,1,1,1,1,1,1,1,1,1,1,1,1,1,1,1,1,1,1,1,1
endlayer

layer
1,1,1,1,1,1,1,1,1,1,1,1,1,1,1,1,1,1,1,1,1,1,1,1,1,1,1,1,1
1,1,1,1,1,1,1,1,1,1,1,1,1,1,1,1,1,1,1,1,1,1,1,1,1,1,1,1,1
1,1,1,1,1,1,1,1,1,1,1,1,1,1,1,1,1,1,1,1,1,1,1,1,1,1,1,1,1
1,1,1,1,1,1,1,1,1,1,1,1,1,1,1,1,1,1,1,1,1,1,1,1,1,1,1,1,1
1,1,1,1,1,1,1,1,1,1,1,1,1,1,1,1,1,1,1,1,1,1,1,1,1,1,1,1,1
1,1,1,1,1,1,1,3,3,3,3,3,3,3,3,3,3,3,3,3,3,3,3,2,1,1,1,2,1
1,1,1,1,1,1,3,38,4,7,6,3,3,4,38,38,38,38,38,38,38,38,38,3,1,1,1,1,1
1,3,3,3,3,3,4,4,4,4,4,4,4,7,38,38,38,38,38,38,38,38,38,3,1,1,1,1,1
3,17,17,17,17,7,38,38,38,38,38,38,38,4,38,38,38,38,38,38,38,7,7,3,1,1,0,0,0
3,17,17,17,17,17,38,38,38,38,38,38,38,4,38,38,38,38,38,38,38,7,7,3,0,0,0,0,0
3,17,17,17,17,7,38,38,38,38,38,38,38,4,38,38,38,38,38,38,38,7,7,3,1,1,0,0,0
1,3,3,3,3,3,4,4,4,4,4,4,4,7,38,38,38,38,38,38,38,38,38,3,1,1,1,1,1
1,1,1,1,1,1,3,4,0,0,0,22,3,4,38,38,38,38,38,38,38,38,38,3,1,1,1,1,1
1,1,1,1,1,1,2,3,3,3,3,21,3,3,3,3,3,3,3,3,3,3,3,2,1,1,1,2,1
1,1,1,1,1,1,3,0,0,0,0,0,3,1,1,1,1,1,1,1,1,1,1,1,1,1,1,1,1
1,1,1,1,1,1,3,0,0,0,0,0,3,1,1,1,1,1,1,1,1,1,1,1,1,1,1,1,1
1,1,1,1,1,1,3,0,0,0,0,0,3,1,1,1,1,1,1,1,1,1,1,1,1,1,1,1,1
1,1,1,1,1,1,3,0,0,0,0,0,3,1,1,1,1,1,1,1,1,1,1,1,1,1,1,1,1
1,1,1,1,1,1,3,0,0,0,0,0,3,1,1,1,1,1,1,1,1,1,1,1,1,1,1,1,1
1,1,1,1,1,1,2,0,0,0,0,0,2,1,1,1,1,1,1,1,1,1,1,1,1,1,1,1,1
1,1,1,1,1,1,3,25,0,27,0,25,3,1,1,1,1,1,1,1,1,1,1,1,1,1,1,1,1
1,1,1,2,3,3,3,18,18,18,18,18,3,3,3,2,1,1,1,1,1,1,1,1,1,1,1,1,1
1,1,1,3,0,0,0,0,0,0,0,0,0,0,0,3,1,1,1,1,1,1,1,1,1,1,1,1,1
1,1,3,3,0,2,0,0,0,0,0,0,0,2,0,3,3,1,1,1,1,1,1,1,1,1,1,1,1
1,1,3,3,0,0,0,0,0,0,0,0,0,0,0,3,3,1,1,1,1,1,1,1,1,1,1,1,1
1,1,1,3,0,0,0,0,0,0,0,0,0,0,0,3,1,1,1,1,1,1,1,1,1,1,1,1,1
1,1,1,3,0,0,0,0,0,0,0,0,0,0,0,3,1,1,1,1,1,1,1,1,1,1,1,1,1
1,1,1,3,0,0,0,0,0,0,0,0,0,0,0,3,1,1,1,1,1,1,1,1,1,1,1,1,1
1,1,3,3,0,0,0,0,0,0,0,0,0,0,0,3,3,1,1,1,1,1,1,1,1,1,1,1,1
1,1,3,3,0,2,0,0,0,0,0,0,0,2,0,3,3,1,1,1,1,1,1,1,1,1,1,1,1
1,1,1,3,0,0,0,0,0,0,0,0,0,0,0,3,1,1,1,1,1,1,1,1,1,1,1,1,1
1,1,1,2,3,3,3,3,3,3,3,3,3,3,3,2,1,1,1,1,1,1,1,1,1,1,1,1,1
1,1,1,1,12,11,1,1,3,1,3,1,1,14,13,1,1,1,1,1,1,1,1,1,1,1,1,1,1
1,1,1,1,1,1,1,1,1,1,1,1,1,1,1,1,1,1,1,1,1,1,1,1,1,1,1,1,1
1,1,1,1,1,1,1,1,1,1,1,1,1,1,1,1,1,1,1,1,1,1,1,1,1,1,1,1,1
endlayer

layer
1,1,1,1,1,1,1,1,1,1,1,1,1,1,1,1,1,1,1,1,1,1,1,1,1,1,1,1,1
1,1,1,1,1,1,1,1,1,1,1,1,1,1,1,1,1,1,1,1,1,1,1,1,1,1,1,1,1
1,1,1,1,1,1,1,1,1,1,1,1,1,1,1,1,1,1,1,1,1,1,1,1,1,1,1,1,1
1,1,1,1,1,1,1,1,1,1,1,1,1,1,1,1,1,1,1,1,1,1,1,1,1,1,1,1,1
1,1,1,1,1,1,1,14,33,33,33,33,33,33,33,33,33,33,33,33,33,33,33,11,1,1,1,1,1
1,1,1,1,1,1,1,3,3,3,3,3,3,3,3,3,3,3,18,3,3,3,3,2,1,0,1,2,1
1,1,1,1,1,1,3,39,0,0,20,0,3,18,39,39,39,39,39,39,39,39,39,18,11,0,0,0,1
1,13,13,13,13,3,1,0,0,0,0,0,0,3,39,39,39,39,39,39,39,39,39,3,0,0,0,0,0
37,0,0,0,0,3,39,39,39,39,39,39,39,0,39,39,39,39,39,39,39,0,0,3,11,0,0,0,0
3,0,0,0,0,29,39,39,39,39,39,39,39,18,39,39,39,39,39,39,39,0,0,3,0,0,0,0,0
40,0,0,0,0,3,39,39,39,39,39,39,39,0,39,39,0,39,39,39,39,0,0,3,11,0,0,0,0
1,13,13,13,13,3,0,0,0,0,0,0,0,3,39,39,39,39,39,39,39,39,39,3,0,0,0,0,0
1,1,1,1,1,1,3,0,0,0,0,0,3,18,39,39,39,39,39,39,39,39,39,18,11,0,0,0,1
1,1,1,1,1,1,2,3,3,3,3,0,3,3,3,3,3,3,18,3,3,3,3,2,1,0,1,2,1
1,1,1,1,1,1,3,0,0,0,0,0,3,41,41,41,41,41,41,41,41,41,41,11,1,1,1,1,1
1,1,1,1,1,1,3,0,0,0,0,0,3,1,1,1,1,1,1,1,1,1,1,1,1,1,1,1,1
1,1,1,1,1,1,3,0,0,0,0,0,3,1,1,1,1,1,1,1,1,1,1,1,1,1,1,1,1
1,1,1,1,1,1,3,0,0,0,0,0,3,1,1,1,1,1,1,1,1,1,1,1,1,1,1,1,1
1,1,1,1,1,1,3,0,0,0,0,0,3,1,1,1,1,1,1,1,1,1,1,1,1,1,1,1,1
1,1,1,1,1,1,2,0,0,0,0,0,2,1,1,1,1,1,1,1,1,1,1,1,1,1,1,1,1
1,1,1,1,1,1,3,0,0,0,0,0,3,1,1,1,1,1,1,1,1,1,1,1,1,1,1,1,1
1,1,1,2,3,3,3,34,0,0,0,34,3,3,3,2,1,1,1,1,1,1,1,1,1,1,1,1,1
1,1,1,3,0,0,0,0,0,0,0,0,0,0,0,3,1,1,1,1,1,1,1,1,1,1,1,1,1
1,1,3,3,0,2,0,0,0,0,0,0,0,2,0,3,3,1,1,1,1,1,1,1,1,1,1,1,1
1,1,3,3,0,0,0,0,0,0,0,0,0,0,0,3,3,1,1,1,1,1,1,1,1,1,1,1,1
1,1,1,3,0,0,0,0,0,0,0,0,0,0,0,3,1,1,1,1,1,1,1,1,1,1,1,1,1
1,1,1,3,0,0,0,0,0,0,0,0,0,0,0,3,1,1,1,1,1,1,1,1,1,1,1,1,1
1,1,1,3,0,0,0,0,0,0,0,0,0,0,0,3,1,1,1,1,1,1,1,1,1,1,1,1,1
1,1,3,3,0,0,0,0,0,0,0,0,0,0,0,3,3,1,1,1,1,1,1,1,1,1,1,1,1
1,1,3,3,0,2,0,0,0,0,0,0,0,2,0,3,3,1,1,1,1,1,1,1,1,1,1,1,1
1,1,1,3,0,0,0,0,0,0,0,0,0,0,0,3,1,1,1,1,1,1,1,1,1,1,1,1,1
1,1,1,2,3,3,3,3,3,3,3,3,3,3,3,2,1,1,1,1,1,1,1,1,1,1,1,1,1
1,1,1,1,1,12,11,1,3,1,3,1,14,13,1,1,1,1,1,1,1,1,1,1,1,1,1,1,1
1,1,1,1,1,1,1,1,1,1,1,1,1,1,1,1,1,1,1,1,1,1,1,1,1,1,1,1,1
1,1,1,1,1,1,1,1,1,1,1,1,1,1,1,1,1,1,1,1,1,1,1,1,1,1,1,1,1
endlayer

layer
1,1,1,1,1,1,1,1,1,1,1,1,1,1,1,1,1,1,1,1,1,1,1,1,1,1,1,1,1
1,1,1,1,1,1,1,1,1,1,1,1,1,1,1,1,1,1,1,1,1,1,1,1,1,1,1,1,1
1,1,1,1,1,1,1,1,1,1,1,1,1,1,1,1,1,1,1,1,1,1,1,1,1,1,1,1,1
1,1,1,1,1,1,1,1,1,1,1,1,1,1,1,1,1,1,1,1,1,1,1,1,1,1,1,1,1
1,1,1,1,1,1,1,12,40,40,40,40,40,40,40,40,40,40,40,40,40,40,40,13,1,1,1,1,1
1,1,1,1,1,1,1,3,3,3,3,3,3,3,3,3,3,3,34,3,3,3,3,2,0,0,0,2,1
1,1,1,1,1,1,3,0,0,20,0,0,3,34,0,0,0,0,0,0,0,0,0,34,13,0,0,0,0
1,1,1,1,1,3,18,0,0,0,0,0,18,3,0,0,0,0,0,0,0,0,0,3,0,0,0,0,0
1,0,0,0,0,3,0,0,0,0,0,0,0,0,0,0,0,0,0,0,0,14,33,3,13,0,0,0,0
1,0,0,0,0,31,0,0,0,0,0,0,0,34,0,0,0,0,0,0,0,14,42,42,0,0,0,0,0
1,0,0,0,0,3,0,0,0,0,0,0,0,0,0,0,0,0,0,0,0,14,41,3,13,0,0,0,0
1,1,1,1,1,3,18,0,0,0,0,0,18,3,0,0,0,0,0,0,0,0,0,3,0,0,0,0,0
1,1,1,1,1,1,3,0,0,0,0,0,3,34,0,0,0,0,0,0,0,0,0,34,13,0,0,0,0
1,1,1,1,1,1,2,3,3,3,3,0,3,3,3,3,3,3,34,3,3,3,3,2,0,0,0,2,1
1,1,1,1,1,1,3,0,0,18,0,0,3,37,37,37,37,37,37,37,37,37,37,13,1,1,1,1,1
1,1,1,1,1,1,3,0,0,0,0,0,3,1,1,1,1,1,1,1,1,1,1,1,1,1,1,1,1
1,1,1,1,1,1,3,0,0,0,0,0,3,1,1,1,1,1,1,1,1,1,1,1,1,1,1,1,1
1,1,1,1,1,1,3,0,0,0,0,0,3,1,1,1,1,1,1,1,1,1,1,1,1,1,1,1,1
1,1,1,1,1,1,3,0,0,0,0,0,3,1,1,1,1,1,1,1,1,1,1,1,1,1,1,1,1
1,1,1,1,1,1,2,0,0,0,0,0,2,1,1,1,1,1,1,1,1,1,1,1,1,1,1,1,1
1,1,1,1,1,1,3,0,0,0,0,0,3,1,1,1,1,1,1,1,1,1,1,1,1,1,1,1,1
1,1,1,2,3,3,3,0,0,0,0,0,3,3,3,2,1,1,1,1,1,1,1,1,1,1,1,1,1
1,1,1,3,28,2,5,2,5,2,5,2,5,2,5,3,1,1,1,1,1,1,1,1,1,1,1,1,1
1,1,3,3,2,2,2,5,2,5,2,5,2,2,2,3,3,1,1,1,1,1,1,1,1,1,1,1,1
1,1,3,3,5,2,5,2,5,2,5,2,5,2,5,3,3,1,1,1,1,1,1,1,1,1,1,1,1
1,1,1,3,2,5,2,5,2,5,2,5,2,5,2,3,1,1,1,1,1,1,1,1,1,1,1,1,1
1,1,1,3,5,2,5,2,5,2,5,2,5,2,5,3,1,1,1,1,1,1,1,1,1,1,1,1,1
1,1,1,3,2,5,2,5,2,5,2,5,2,5,2,3,1,1,1,1,1,1,1,1,1,1,1,1,1
1,1,3,3,5,2,5,2,5,2,5,2,5,2,5,3,3,1,1,1,1,1,1,1,1,1,1,1,1
1,1,3,3,2,2,2,5,2,5,2,5,2,2,2,3,3,1,1,1,1,1,1,1,1,1,1,1,1
1,1,1,3,5,2,5,2,5,2,5,2,5,2,5,3,1,1,1,1,1,1,1,1,1,1,1,1,1
1,1,1,2,3,3,3,3,3,3,3,3,3,3,3,2,1,1,1,1,1,1,1,1,1,1,1,1,1
1,1,1,1,1,1,12,11,3,1,3,14,13,1,1,1,1,1,1,1,1,1,1,1,1,1,1,1,1
1,1,1,1,1,1,1,1,1,1,1,1,1,1,1,1,1,1,1,1,1,1,1,1,1,1,1,1,1
1,1,1,1,1,1,1,1,1,1,1,1,1,1,1,1,1,1,1,1,1,1,1,1,1,1,1,1,1
endlayer

layer
1,1,1,1,1,1,1,1,1,1,1,1,1,1,1,1,1,1,1,1,1,1,1,1,1,1,1,1,1
1,1,1,1,1,1,1,1,1,1,1,1,1,1,1,1,1,1,1,1,1,1,1,1,1,1,1,1,1
1,1,1,1,1,1,1,1,1,1,1,1,1,1,1,1,1,1,1,1,1,1,1,1,1,1,1,1,1
1,1,1,1,1,1,1,1,1,1,1,1,1,1,1,1,1,1,1,1,1,1,1,1,1,1,1,1,1
1,1,1,1,1,1,1,1,1,1,1,1,1,1,1,1,1,1,1,1,1,1,1,1,1,1,1,1,1
1,1,1,1,1,1,1,3,3,3,3,3,3,3,3,3,3,3,3,3,3,3,3,2,0,0,0,2,0
1,1,1,1,1,1,3,0,20,0,0,0,3,43,43,43,43,43,43,43,43,38,38,3,0,0,0,0,0
1,1,1,1,1,3,34,0,0,0,0,0,34,3,43,43,43,43,43,43,43,43,38,3,0,0,0,0,0
1,1,1,1,1,3,0,0,0,0,0,0,0,3,43,43,43,43,43,43,43,43,38,3,11,0,0,0,0
1,1,1,1,1,3,0,0,0,0,0,0,0,3,43,43,43,38,43,43,43,43,42,42,0,0,0,0,0
1,1,1,1,1,3,0,0,0,0,0,0,0,3,43,43,43,43,43,43,43,43,38,3,11,0,0,0,0
1,1,1,1,1,3,34,0,0,0,0,0,34,3,43,43,43,43,43,43,43,43,38,3,0,0,0,0,0
1,1,1,1,1,1,3,0,0,0,0,0,3,43,43,38,38,38,43,38,38,38,38,3,0,0,0,0,0
1,1,1,1,1,1,2,3,3,3,3,3,3,3,3,3,3,3,3,3,3,3,3,2,0,0,0,2,0
1,1,1,1,1,1,3,0,0,34,0,0,3,1,1,1,1,1,1,1,1,1,1,1,1,1,1,1,1
1,1,1,1,1,1,3,0,0,0,0,0,3,1,1,1,1,1,1,1,1,1,1,1,1,1,1,1,1
1,1,1,1,1,1,3,0,0,0,0,0,3,1,1,1,1,1,1,1,1,1,1,1,1,1,1,1,1
1,1,1,1,1,1,3,0,0,0,0,0,3,1,1,1,1,1,1,1,1,1,1,1,1,1,1,1,1
1,1,1,1,1,1,3,0,0,0,0,0,3,1,1,1,1,1,1,1,1,1,1,1,1,1,1,1,1
1,1,1,1,1,1,2,0,0,0,0,0,2,1,1,1,1,1,1,1,1,1,1,1,1,1,1,1,1
1,1,1,1,1,1,3,0,0,0,0,0,3,1,1,1,1,1,1,1,1,1,1,1,1,1,1,1,1
1,1,1,2,3,3,3,0,0,0,0,0,3,3,3,2,1,1,1,1,1,1,1,1,1,1,1,1,1
1,1,1,3,44,45,44,45,44,45,44,45,44,45,44,3,1,1,1,1,1,1,1,1,1,1,1,1,1
1,1,3,3,45,2,45,46,45,46,45,46,45,2,45,3,3,1,1,1,1,1,1,1,1,1,1,1,1
1,1,3,3,44,45,44,45,44,45,44,45,44,45,44,3,3,1,1,1,1,1,1,1,1,1,1,1,1
1,1,1,3,45,46,45,46,45,46,45,46,45,46,45,3,1,1,1,1,1,1,1,1,1,1,1,1,1
1,1,1,3,44,45,44,45,44,45,44,45,44,45,44,3,1,1,1,1,1,1,1,1,1,1,1,1,1
1,1,1,3,45,46,45,46,45,46,45,46,45,46,45,3,1,1,1,1,1,1,1,1,1,1,1,1,1
1,1,3,3,44,45,44,45,44,45,44,45,44,45,44,3,3,1,1,1,1,1,1,1,1,1,1,1,1
1,1,3,3,45,2,45,46,45,46,45,46,45,2,45,3,3,1,1,1,1,1,1,1,1,1,1,1,1
1,1,1,3,44,45,44,45,44,45,44,45,44,45,44,3,1,1,1,1,1,1,1,1,1,1,1,1,1
1,1,1,2,3,3,3,3,3,3,3,3,3,3,3,2,1,1,1,1,1,1,1,1,1,1,1,1,1
1,1,1,1,1,1,1,12,2,2,2,13,1,1,1,1,1,1,1,1,1,1,1,1,1,1,1,1,1
1,1,1,1,1,1,1,1,1,1,1,1,1,1,1,1,1,1,1,1,1,1,1,1,1,1,1,1,1
1,1,1,1,1,1,1,1,1,1,1,1,1,1,1,1,1,1,1,1,1,1,1,1,1,1,1,1,1
endlayer

layer
1,1,1,1,1,1,1,1,1,1,1,1,1,1,1,1,1,1,1,1,1,1,1,1,1,1,1,1,1
1,1,1,1,1,1,1,1,1,1,1,1,1,1,1,1,1,1,1,1,1,1,1,1,1,1,1,1,1
1,1,1,1,1,1,1,1,1,1,1,1,1,1,1,1,1,1,1,1,1,1,1,1,1,1,1,1,1
1,1,1,1,1,1,1,1,1,1,1,1,1,1,1,1,1,1,1,1,1,1,1,1,1,1,1,1,1
1,1,1,1,1,1,1,1,1,1,1,1,1,1,1,1,1,1,1,1,1,1,1,1,1,1,1,1,1
1,1,1,1,1,1,1,3,3,3,3,3,3,3,3,3,3,3,3,3,3,3,3,2,0,0,0,2,0
1,1,1,1,1,1,3,20,0,0,0,41,3,43,43,0,0,0,0,0,0,0,0,3,0,0,0,0,0
1,1,1,1,1,3,11,5,5,5,5,5,14,3,43,47,47,47,47,47,47,47,0,3,0,0,0,0,0
1,1,1,1,1,3,11,5,5,5,5,5,14,43,43,47,47,47,47,47,47,47,0,3,0,0,0,0,0
1,1,1,1,1,3,11,5,5,5,5,5,14,43,43,43,43,0,0,0,47,47,0,3,13,0,0,0,0
1,1,1,1,1,3,11,5,5,5,5,5,14,43,43,47,47,47,47,47,47,47,0,3,0,0,0,0,0
1,1,1,1,1,3,11,5,5,5,5,5,14,3,43,47,47,47,47,47,47,47,0,3,0,0,0,0,0
1,1,1,1,1,1,3,33,33,33,33,33,3,43,43,0,0,0,3,0,0,0,0,3,0,0,0,0,0
1,1,1,1,1,1,2,3,3,3,3,3,3,3,3,3,3,3,3,3,3,3,3,2,0,0,0,2,0
1,1,1,1,1,1,3,0,0,0,0,0,3,1,1,1,1,1,1,1,1,1,1,1,1,1,1,1,1
1,1,1,1,1,1,3,0,0,0,0,0,3,1,1,1,1,1,1,1,1,1,1,1,1,1,1,1,1
1,1,1,1,1,1,3,0,0,0,0,0,3,1,1,1,1,1,1,1,1,1,1,1,1,1,1,1,1
1,1,1,1,1,1,3,0,0,0,0,0,3,1,1,1,1,1,1,1,1,1,1,1,1,1,1,1,1
1,1,1,1,1,1,3,0,0,0,0,0,3,1,1,1,1,1,1,1,1,1,1,1,1,1,1,1,1
1,1,1,1,1,1,2,0,0,0,0,0,2,1,1,1,1,1,1,1,1,1,1,1,1,1,1,1,1
1,1,1,1,1,1,3,0,0,0,0,0,3,1,1,1,1,1,1,1,1,1,1,1,1,1,1,1,1
1,1,1,2,3,3,3,17,17,17,17,17,3,3,3,2,1,1,1,1,1,1,1,1,1,1,1,1,1
1,1,1,3,25,0,0,0,28,28,28,0,0,0,25,3,1,1,1,1,1,1,1,1,1,1,1,1,1
1,1,3,3,0,2,0,0,0,0,0,0,0,2,0,3,3,1,1,1,1,1,1,1,1,1,1,1,1
1,1,3,3,0,0,0,0,0,0,0,0,0,0,0,3,3,1,1,1,1,1,1,1,1,1,1,1,1
1,1,1,3,0,0,0,0,0,0,0,0,0,0,0,3,1,1,1,1,1,1,1,1,1,1,1,1,1
1,1,1,3,0,0,0,0,0,0,0,0,0,0,0,3,1,1,1,1,1,1,1,1,1,1,1,1,1
1,1,1,3,0,0,0,0,0,0,0,0,0,0,0,3,1,1,1,1,1,1,1,1,1,1,1,1,1
1,1,3,3,0,0,0,0,0,0,0,0,0,0,0,3,3,1,1,1,1,1,1,1,1,1,1,1,1
1,1,3,3,0,2,0,0,0,0,0,0,0,2,0,3,3,1,1,1,1,1,1,1,1,1,1,1,1
1,1,1,3,25,0,0,0,0,0,0,0,0,0,25,3,1,1,1,1,1,1,1,1,1,1,1,1,1
1,1,1,2,3,3,3,3,2,23,2,3,3,3,3,2,1,1,1,1,1,1,1,1,1,1,1,1,1
1,1,1,1,1,1,1,1,0,0,0,1,1,1,1,1,1,1,1,1,1,1,1,1,1,1,1,1,1
1,1,1,1,1,1,1,1,1,0,1,1,1,1,1,1,1,1,1,1,1,1,1,1,1,1,1,1,1
1,1,1,1,1,1,1,1,1,0,1,1,1,1,1,1,1,1,1,1,1,1,1,1,1,1,1,1,1
endlayer

layer
1,1,1,1,1,1,1,1,1,1,1,1,1,1,1,1,1,1,1,1,1,1,1,1,1,1,1,1,1
1,1,1,1,1,1,1,1,1,1,1,1,1,1,1,1,1,1,1,1,1,1,1,1,1,1,1,1,1
1,1,1,1,1,1,1,1,1,1,1,1,1,1,1,1,1,1,1,1,1,1,1,1,1,1,1,1,1
1,1,1,1,1,1,1,1,1,1,1,1,1,1,1,1,1,1,1,1,1,1,1,1,1,1,1,1,1
1,1,1,1,1,1,1,1,1,1,1,1,1,1,1,1,1,1,1,1,1,1,1,1,1,1,1,1,1
1,1,1,1,1,1,1,3,3,3,3,3,3,3,3,3,3,3,3,3,3,3,3,2,48,48,48,2,0
1,1,1,1,1,1,3,0,0,0,38,38,3,38,38,38,38,38,38,38,38,38,38,2,8,48,48,48,0
1,1,1,1,1,3,38,30,38,38,38,38,38,3,38,42,42,42,42,42,42,42,38,8,2,48,48,48,0
1,1,1,1,1,3,38,38,38,38,38,38,38,3,38,42,42,42,42,42,42,42,38,3,8,48,48,48,0
1,1,1,1,1,3,38,38,38,38,38,38,38,3,38,38,38,38,38,38,42,42,38,3,2,48,48,48,0
1,1,1,1,1,3,38,38,38,38,38,38,38,3,38,42,42,42,42,42,42,42,38,3,8,48,48,48,0
1,1,1,1,1,3,43,38,38,38,38,38,38,3,38,42,42,42,42,42,42,42,38,8,2,48,48,48,0
1,1,1,1,1,1,3,38,38,38,38,38,3,38,38,38,38,38,38,38,38,38,38,2,8,48,48,48,0
1,1,1,1,1,1,2,3,3,3,3,3,3,3,3,3,3,3,3,3,3,3,3,2,48,48,48,2,0
1,1,1,1,1,1,3,2,4,2,4,2,3,1,1,1,1,1,1,1,1,1,1,1,1,1,1,1,1
1,1,1,1,1,1,3,4,2,4,2,4,3,1,1,1,1,1,1,1,1,1,1,1,1,1,1,1,1
1,1,1,1,1,1,3,2,4,2,4,2,3,1,1,1,1,1,1,1,1,1,1,1,1,1,1,1,1
1,1,1,1,1,1,3,4,2,4,2,4,3,1,1,1,1,1,1,1,1,1,1,1,1,1,1,1,1
1,1,1,1,1,1,3,2,4,2,4,2,3,1,1,1,1,1,1,1,1,1,1,1,1,1,1,1,1
1,1,1,1,1,1,2,3,3,3,3,3,2,1,1,1,1,1,1,1,1,1,1,1,1,1,1,1,1
1,1,1,1,1,1,3,5,5,28,5,5,3,1,1,1,1,1,1,1,1,1,1,1,1,1,1,1,1
1,1,1,2,3,3,3,17,17,0,17,17,3,3,3,2,1,1,1,1,1,1,1,1,1,1,1,1,1
1,1,1,3,0,0,0,0,0,0,0,0,0,0,0,3,1,1,1,1,1,1,1,1,1,1,1,1,1
1,1,3,3,0,2,0,0,0,0,0,0,0,2,0,3,3,1,1,1,1,1,1,1,1,1,1,1,1
1,1,3,3,0,0,0,0,0,0,0,0,0,0,0,3,3,1,1,1,1,1,1,1,1,1,1,1,1
1,1,1,3,0,0,0,0,0,0,0,0,0,0,0,3,1,1,1,1,1,1,1,1,1,1,1,1,1
1,1,1,3,0,0,0,0,0,0,0,0,0,0,0,3,1,1,1,1,1,1,1,1,1,1,1,1,1
1,1,1,3,0,0,0,0,0,0,0,0,0,0,0,3,1,1,1,1,1,1,1,1,1,1,1,1,1
1,1,3,3,0,0,0,0,0,0,0,0,0,0,0,3,3,1,1,1,1,1,1,1,1,1,1,1,1
1,1,3,3,0,2,0,0,0,0,0,0,0,2,0,3,3,1,1,1,1,1,1,1,1,1,1,1,1
1,1,1,3,0,0,0,0,0,0,0,0,0,0,0,3,1,1,1,1,1,1,1,1,1,1,1,1,1
1,1,1,2,3,3,3,3,2,31,2,3,3,3,3,2,1,1,1,1,1,1,1,1,1,1,1,1,1
1,1,1,1,1,1,1,1,0,0,0,1,1,1,1,1,1,1,1,1,1,1,1,1,1,1,1,1,1
1,1,1,1,1,1,1,1,0,0,0,1,1,1,1,1,1,1,1,1,1,1,1,1,1,1,1,1,1
1,1,1,1,1,1,1,1,0,0,0,1,1,1,1,1,1,1,1,1,1,1,1,1,1,1,1,1,1
endlayer

layer
1,1,1,1,1,1,1,1,1,1,1,1,1,1,1,1,1,1,1,1,1,1,1,1,1,1,1,1,1
1,1,1,1,1,1,1,1,1,1,1,1,1,1,1,1,1,1,1,1,1,1,1,1,1,1,1,1,1
1,1,1,1,1,1,1,1,1,1,1,1,1,1,1,1,1,1,1,1,1,1,1,1,1,1,1,1,1
1,1,1,1,1,1,1,1,1,1,1,1,1,1,1,1,1,1,1,1,1,1,1,1,1,1,1,1,1
1,1,1,1,1,1,1,1,1,1,1,1,14,33,33,33,33,33,33,33,33,33,33,33,33,33,33,33,33
1,1,1,1,1,1,1,3,3,3,3,3,3,37,37,37,37,37,37,37,37,37,37,37,37,37,3,49,11
1,1,1,1,1,1,3,0,0,0,39,39,3,50,50,50,50,50,50,50,50,50,50,0,25,12,43,3,11
1,1,1,1,1,3,39,0,39,39,50,39,51,3,50,0,0,0,0,0,0,0,50,0,0,12,3,3,11
1,1,1,1,1,3,52,39,50,39,39,39,39,2,50,0,0,0,0,0,0,0,12,3,0,12,3,3,11
1,1,1,1,1,3,39,39,39,39,39,39,39,29,50,50,50,50,50,50,0,42,0,3,0,12,43,3,11
1,1,1,1,1,3,39,39,39,39,39,39,39,2,50,0,0,0,0,0,0,0,12,3,0,12,3,3,11
1,1,1,1,1,3,53,39,39,39,39,39,51,3,50,0,0,0,0,0,0,0,50,0,0,12,3,3,11
1,1,1,1,1,1,3,39,39,39,39,39,3,50,50,50,50,50,50,50,50,50,50,0,25,12,43,3,11
1,1,1,1,1,1,2,3,2,23,2,3,2,40,40,40,40,40,40,40,40,40,40,40,40,40,3,49,11
1,1,1,1,1,1,3,0,0,0,0,0,3,41,41,41,41,41,41,41,41,41,41,41,41,41,41,41,11
1,1,1,1,1,1,3,0,0,0,0,0,3,1,1,1,1,1,1,1,1,1,1,1,1,1,1,1,1
1,1,1,1,1,1,3,25,0,0,0,25,3,1,1,1,1,1,1,1,1,1,1,1,1,1,1,1,1
1,1,1,1,1,1,3,0,0,0,0,0,3,1,1,1,1,1,1,1,1,1,1,1,1,1,1,1,1
1,1,1,1,1,1,3,0,0,0,0,0,3,1,1,1,1,1,1,1,1,1,1,1,1,1,1,1,1
1,1,1,1,1,1,2,3,2,23,2,3,2,1,1,1,1,1,1,1,1,1,1,1,1,1,1,1,1
1,1,1,1,1,1,3,26,0,0,0,15,3,1,1,1,1,1,1,1,1,1,1,1,1,1,1,1,1
1,1,1,2,3,3,3,28,0,0,0,28,3,3,3,2,1,1,1,1,1,1,1,1,1,1,1,1,1
1,1,1,3,0,0,5,28,0,0,0,28,5,0,0,3,1,1,1,1,1,1,1,1,1,1,1,1,1
1,1,12,3,0,2,18,0,0,0,0,0,18,2,0,3,13,1,1,1,1,1,1,1,1,1,1,1,1
1,1,12,3,0,18,0,0,0,0,0,0,0,18,0,3,13,1,1,1,1,1,1,1,1,1,1,1,1
1,1,1,3,0,0,0,0,0,0,0,0,0,0,0,3,1,1,1,1,1,1,1,1,1,1,1,1,1
1,1,1,3,0,0,0,0,0,0,0,0,0,0,0,3,1,1,1,1,1,1,1,1,1,1,1,1,1
1,1,1,3,0,0,0,0,0,0,0,0,0,0,0,3,1,1,1,1,1,1,1,1,1,1,1,1,1
1,1,12,3,0,18,0,0,0,0,0,0,0,18,0,3,13,1,1,1,1,1,1,1,1,1,1,1,1
1,1,12,3,0,2,18,0,0,0,0,0,18,2,0,3,13,1,1,1,1,1,1,1,1,1,1,1,1
1,1,1,3,0,0,0,0,0,0,0,0,0,0,0,3,1,1,1,1,1,1,1,1,1,1,1,1,1
1,1,1,2,3,3,3,3,2,2,2,3,3,3,3,2,1,1,1,1,1,1,1,1,1,1,1,1,1
1,1,1,1,1,1,1,1,0,0,0,1,1,1,1,1,1,1,1,1,1,1,1,1,1,1,1,1,1
1,1,1,1,1,1,1,1,0,0,0,1,1,1,1,1,1,1,1,1,1,1,1,1,1,1,1,1,1
1,1,1,1,1,1,1,1,0,0,0,1,1,1,1,1,1,1,1,1,1,1,1,1,1,1,1,1,1
endlayer

layer
1,1,1,1,1,1,1,1,1,1,1,1,1,1,1,1,1,1,1,1,1,1,1,1,1,1,1,1,1
1,1,1,1,1,1,1,1,1,1,1,1,1,1,1,1,1,1,1,1,1,1,1,1,1,1,1,1,1
1,1,1,1,1,1,1,1,1,1,1,1,1,1,1,1,1,1,1,1,1,1,1,1,1,1,1,1,1
1,1,1,1,1,1,1,1,1,1,1,1,1,1,1,1,1,1,1,1,1,1,1,1,1,1,1,1,1
1,1,1,1,1,1,1,1,1,1,1,1,18,18,18,18,18,18,18,18,18,18,18,18,18,18,18,18,18
1,1,1,1,1,1,1,3,54,3,54,3,18,0,0,0,0,0,0,0,0,0,0,0,0,0,0,0,18
1,1,1,1,1,1,3,0,0,25,0,18,3,0,0,0,0,0,0,0,0,0,0,0,0,0,55,0,18
1,1,1,1,1,3,1,0,0,0,0,0,56,3,0,0,0,0,0,0,0,0,0,0,0,0,0,0,18
1,1,1,0,0,54,0,0,0,0,0,0,25,2,0,0,0,0,0,0,0,0,0,41,0,0,0,0,18
1,1,0,0,0,3,52,0,0,0,0,0,0,57,0,0,0,0,0,0,0,0,42,3,0,0,55,0,18
1,1,1,0,0,54,0,0,0,0,0,0,25,2,0,0,0,0,0,0,0,0,0,33,0,0,0,0,18
1,1,1,1,1,3,58,0,0,0,0,0,51,3,0,0,0,0,0,0,0,0,0,0,0,0,0,0,18
1,1,1,1,1,1,3,18,0,0,0,18,3,0,0,0,0,0,0,0,0,0,0,0,0,0,55,0,18
1,1,1,1,1,1,2,3,2,31,2,3,2,0,0,0,0,0,0,0,0,0,0,0,0,0,0,0,18
1,1,1,1,1,1,3,18,0,0,0,18,3,18,18,18,18,18,18,18,18,18,18,18,18,18,18,18,18
1,1,1,1,1,1,54,0,0,0,0,0,54,1,1,1,1,1,1,1,1,1,1,1,1,1,1,1,1
1,1,1,1,1,1,3,0,0,0,0,0,3,1,1,1,1,1,1,1,1,1,1,1,1,1,1,1,1
1,1,1,1,1,1,54,0,0,0,0,0,54,1,1,1,1,1,1,1,1,1,1,1,1,1,1,1,1
1,1,1,1,1,1,3,18,0,0,0,18,3,1,1,1,1,1,1,1,1,1,1,1,1,1,1,1,1
1,1,1,1,1,1,2,3,2,57,2,3,2,1,1,1,1,1,1,1,1,1,1,1,1,1,1,1,1
1,1,1,1,1,1,3,0,0,0,0,0,3,1,1,1,1,1,1,1,1,1,1,1,1,1,1,1,1
1,1,1,2,3,3,3,0,0,0,0,0,3,3,3,2,1,1,1,1,1,1,1,1,1,1,1,1,1
1,1,1,3,5,28,0,0,0,0,0,0,0,28,5,3,1,1,1,1,1,1,1,1,1,1,1,1,1
1,1,1,3,0,2,34,0,0,0,0,0,34,2,0,3,1,1,1,1,1,1,1,1,1,1,1,1,1
1,1,1,3,0,34,0,0,0,0,0,0,0,34,0,3,1,1,1,1,1,1,1,1,1,1,1,1,1
1,1,1,3,0,0,0,0,0,0,0,0,0,0,0,3,1,1,1,1,1,1,1,1,1,1,1,1,1
1,1,1,3,0,0,0,0,0,0,0,0,0,0,0,3,1,1,1,1,1,1,1,1,1,1,1,1,1
1,1,1,3,0,0,0,0,0,0,0,0,0,0,0,3,1,1,1,1,1,1,1,1,1,1,1,1,1
1,1,1,3,0,34,0,0,0,0,0,0,0,34,0,3,1,1,1,1,1,1,1,1,1,1,1,1,1
1,1,1,3,0,2,34,0,0,0,0,0,34,2,0,3,1,1,1,1,1,1,1,1,1,1,1,1,1
1,1,1,3,0,0,0,0,0,0,0,0,0,0,0,3,1,1,1,1,1,1,1,1,1,1,1,1,1
1,1,1,2,3,3,3,3,3,3,3,3,3,3,3,2,1,1,1,1,1,1,1,1,1,1,1,1,1
1,1,1,1,1,1,1,1,1,0,1,1,1,1,1,1,1,1,1,1,1,1,1,1,1,1,1,1,1
1,1,1,1,1,1,1,1,0,0,0,1,1,1,1,1,1,1,1,1,1,1,1,1,1,1,1,1,1
1,1,1,1,1,1,1,1,0,0,0,1,1,1,1,1,1,1,1,1,1,1,1,1,1,1,1,1,1
endlayer

layer
1,1,1,1,1,1,1,1,1,1,1,1,1,1,1,1,1,1,1,1,1,1,1,1,1,1,1,1,1
1,1,1,1,1,1,1,1,1,1,1,1,1,1,1,1,1,1,1,1,1,1,1,1,1,1,1,1,1
1,1,1,1,1,1,1,1,1,1,1,1,1,1,1,1,1,1,1,1,1,1,1,1,1,1,1,1,1
1,1,1,1,1,1,1,1,1,1,1,1,1,1,1,1,1,1,1,1,1,1,1,1,1,1,1,1,1
1,1,1,1,1,1,1,1,1,1,1,1,1,34,1,1,1,1,1,1,1,1,1,1,1,1,1,1,34
1,1,1,1,1,1,1,3,54,3,54,3,0,0,0,0,0,0,0,0,0,0,0,0,0,0,0,0,0
1,1,1,1,1,1,3,0,0,0,0,34,3,0,0,0,0,0,0,0,0,0,0,0,0,0,0,0,0
1,1,1,1,1,3,1,0,0,0,0,0,56,3,0,0,0,0,0,0,0,0,0,0,0,0,0,0,0
1,1,0,0,0,54,0,0,0,0,0,0,0,2,0,0,0,0,0,0,0,0,0,40,0,0,0,0,0
1,0,0,0,0,3,0,0,0,0,0,0,0,2,0,0,0,0,0,0,0,42,14,3,0,0,0,0,0
1,1,0,0,0,54,52,0,0,0,0,0,0,2,0,0,0,0,0,0,0,0,0,37,0,0,0,0,0
1,1,1,1,1,3,58,0,0,0,0,0,51,3,0,0,0,0,0,0,0,0,0,0,0,0,0,0,0
1,1,1,1,1,1,3,34,0,0,0,34,3,0,0,0,0,0,0,0,0,0,0,0,0,0,0,0,0
1,1,1,1,1,1,2,3,2,2,2,3,2,0,0,0,0,0,0,0,0,0,0,0,0,0,0,0,0
1,1,1,1,1,1,3,34,0,0,0,34,3,34,1,1,1,1,1,1,1,1,1,1,1,1,1,1,34
1,1,1,1,1,1,54,0,0,0,0,0,54,1,1,1,1,1,1,1,1,1,1,1,1,1,1,1,1
1,1,1,1,1,1,3,0,0,0,0,0,3,1,1,1,1,1,1,1,1,1,1,1,1,1,1,1,1
1,1,1,1,1,1,54,0,0,0,0,0,54,1,1,1,1,1,1,1,1,1,1,1,1,1,1,1,1
1,1,1,1,1,1,3,34,0,0,0,34,3,1,1,1,1,1,1,1,1,1,1,1,1,1,1,1,1
1,1,1,1,1,1,2,3,2,2,2,3,2,1,1,1,1,1,1,1,1,1,1,1,1,1,1,1,1
1,1,1,1,1,1,3,0,0,0,0,0,3,1,1,1,1,1,1,1,1,1,1,1,1,1,1,1,1
1,1,1,2,3,3,3,0,0,0,0,0,3,3,3,2,1,1,1,1,1,1,1,1,1,1,1,1,1
1,1,1,3,0,0,0,0,0,0,0,0,0,0,0,3,1,1,1,1,1,1,1,1,1,1,1,1,1
1,1,1,3,28,2,11,0,0,0,0,0,14,2,28,3,1,1,1,1,1,1,1,1,1,1,1,1,1
1,1,1,3,5,41,0,0,0,0,0,0,0,41,5,3,1,1,1,1,1,1,1,1,1,1,1,1,1
1,1,1,3,0,0,0,0,0,0,0,0,0,0,0,3,1,1,1,1,1,1,1,1,1,1,1,1,1
1,1,1,3,0,0,0,0,0,0,0,0,0,0,0,3,1,1,1,1,1,1,1,1,1,1,1,1,1
1,1,1,3,0,0,0,0,0,0,0,0,0,0,0,3,1,1,1,1,1,1,1,1,1,1,1,1,1
1,1,1,3,0,33,0,0,0,0,0,0,0,33,0,3,1,1,1,1,1,1,1,1,1,1,1,1,1
1,1,1,3,0,2,11,0,0,0,0,0,14,2,0,3,1,1,1,1,1,1,1,1,1,1,1,1,1
1,1,1,3,0,0,0,0,0,0,0,0,0,0,0,3,1,1,1,1,1,1,1,1,1,1,1,1,1
1,1,1,2,3,3,3,3,3,3,3,3,3,3,3,2,1,1,1,1,1,1,1,1,1,1,1,1,1
1,1,1,1,1,1,1,1,1,0,1,1,1,1,1,1,1,1,1,1,1,1,1,1,1,1,1,1,1
1,1,1,1,1,1,1,1,1,0,1,1,1,1,1,1,1,1,1,1,1,1,1,1,1,1,1,1,1
1,1,1,1,1,1,1,1,0,0,0,1,1,1,1,1,1,1,1,1,1,1,1,1,1,1,1,1,1
endlayer

layer
1,1,1,1,1,1,1,1,1,1,1,1,1,1,1,1,1,1,1,1,1,1,1,1,1,1,1,1,1
1,1,1,1,1,1,1,1,1,1,1,1,1,1,1,1,1,1,1,1,1,1,1,1,1,1,1,1,1
1,1,1,1,1,1,1,1,1,1,1,1,1,1,1,1,1,1,1,1,1,1,1,1,1,1,1,1,1
1,1,1,1,1,1,1,46,1,1,1,46,1,1,1,1,1,1,1,1,1,1,1,1,1,1,1,1,1
1,1,1,1,1,1,1,3,3,3,3,3,1,1,1,1,1,1,1,1,1,1,1,1,1,1,1,1,1
1,1,1,1,1,1,3,3,3,3,3,3,3,0,0,0,0,0,0,0,0,0,0,0,0,0,0,0,0
1,1,1,1,1,3,3,59,60,59,60,59,3,3,0,0,0,0,0,0,0,0,0,0,0,0,0,0,0
1,1,1,44,3,3,59,60,59,5,59,60,59,3,3,44,0,0,0,0,0,0,0,0,0,0,0,0,0
1,0,0,0,3,3,0,59,61,59,61,59,60,3,3,0,0,0,0,0,0,0,0,0,0,0,0,0,0
0,0,0,0,3,3,0,5,59,17,59,5,59,3,3,0,0,0,0,0,0,42,14,3,0,0,0,0,0
1,0,0,0,3,3,0,59,61,59,61,59,60,3,3,0,0,0,0,0,0,0,0,0,0,0,0,0,0
1,1,1,44,3,3,52,60,59,5,59,60,59,3,3,44,0,0,0,0,0,0,0,0,0,0,0,0,0
1,1,1,1,1,3,3,59,60,59,60,59,3,3,0,0,0,0,0,0,0,0,0,0,0,0,0,0,0
1,1,1,1,1,44,3,3,3,3,3,3,3,44,0,0,0,0,0,0,0,0,0,0,0,0,0,0,0
1,1,1,1,1,1,3,3,3,3,3,62,3,1,1,1,1,1,1,1,1,1,1,1,1,1,1,1,1
1,1,1,1,1,1,3,5,61,5,61,5,3,1,1,1,1,1,1,1,1,1,1,1,1,1,1,1,1
1,1,1,1,1,44,3,61,5,61,5,61,3,44,1,1,1,1,1,1,1,1,1,1,1,1,1,1,1
1,1,1,1,1,1,3,5,61,5,61,5,3,1,1,1,1,1,1,1,1,1,1,1,1,1,1,1,1
1,1,1,1,1,1,3,61,5,61,5,61,3,1,1,1,1,1,1,1,1,1,1,1,1,1,1,1,1
1,1,1,1,1,44,3,3,3,3,3,3,3,44,1,1,1,1,1,1,1,1,1,1,1,1,1,1,1
1,1,5,1,33,1,3,0,0,46,0,0,3,1,33,1,5,1,1,1,1,1,1,1,1,1,1,1,1
1,1,1,2,3,3,3,3,3,3,3,3,3,3,3,2,1,1,1,1,1,1,1,1,1,1,1,1,1
1,1,14,3,0,0,5,5,5,5,5,5,5,0,0,3,11,1,1,1,1,1,1,1,1,1,1,1,1
1,1,1,3,0,2,3,3,3,3,3,3,3,2,0,3,1,1,1,1,1,1,1,1,1,1,1,1,1
1,1,14,3,0,3,0,0,0,0,0,0,0,3,0,3,11,1,1,1,1,1,1,1,1,1,1,1,1
1,1,1,3,28,3,0,0,0,0,0,0,0,3,28,3,1,1,1,1,1,1,1,1,1,1,1,1,1
1,1,14,3,5,3,0,0,0,0,0,0,0,3,5,3,11,1,1,1,1,1,1,1,1,1,1,1,1
1,1,1,3,5,3,0,0,0,0,0,0,0,3,5,3,1,1,1,1,1,1,1,1,1,1,1,1,1
1,1,14,3,5,3,0,0,0,0,0,0,0,3,5,3,11,1,1,1,1,1,1,1,1,1,1,1,1
1,1,1,3,5,2,3,3,3,3,3,3,3,2,5,3,1,1,1,1,1,1,1,1,1,1,1,1,1
1,1,14,3,5,5,5,5,5,5,5,5,5,5,5,3,11,1,1,1,1,1,1,1,1,1,1,1,1
1,1,1,2,3,3,3,3,3,3,3,3,3,3,3,2,1,1,1,1,1,1,1,1,1,1,1,1,1
1,1,5,1,41,1,41,1,41,1,41,1,41,1,41,1,5,1,1,1,1,1,1,1,1,1,1,1,1
1,1,1,1,1,1,1,1,1,0,1,1,1,1,1,1,1,1,1,1,1,1,1,1,1,1,1,1,1
1,1,1,1,1,1,1,1,1,0,1,1,1,1,1,1,1,1,1,1,1,1,1,1,1,1,1,1,1
endlayer

layer
1,1,1,1,1,1,1,1,1,1,1,1,1,1,1,1,1,1,1,1,1,1,1,1,1,1,1,1,1
1,1,1,1,1,1,1,1,1,1,1,1,1,1,1,1,1,1,1,1,1,1,1,1,1,1,1,1,1
1,1,1,1,1,1,1,1,1,1,1,1,1,1,1,1,1,1,1,1,1,1,1,1,1,1,1,1,1
1,1,1,1,1,1,1,45,44,44,44,45,1,1,1,1,1,1,1,1,1,1,1,1,1,1,1,1,1
1,1,1,1,1,1,45,63,64,65,64,63,45,1,1,1,1,1,1,1,1,1,1,1,1,1,1,1,1
1,1,1,1,1,45,1,0,0,0,0,0,0,45,0,0,0,0,0,0,0,0,0,0,0,0,0,0,0
1,1,1,1,45,1,1,0,0,0,0,0,0,0,45,0,0,0,0,0,0,0,0,0,0,0,0,0,0
1,1,1,45,63,1,1,0,0,0,0,0,0,0,63,45,0,0,0,0,0,0,0,0,0,0,0,0,0
1,0,0,46,64,0,0,0,0,0,0,0,0,0,64,46,0,0,0,0,0,0,0,0,0,0,0,0,0
0,0,0,46,67,0,0,0,0,0,0,0,0,0,66,46,0,0,0,0,0,0,0,12,0,0,0,0,0
1,0,0,46,64,0,0,0,0,0,0,0,68,0,64,46,0,0,0,0,0,0,0,0,0,0,0,0,0
1,1,1,45,63,0,0,0,0,0,0,0,0,0,63,45,0,0,0,0,0,0,0,0,0,0,0,0,0
1,1,1,1,45,45,0,0,0,0,0,0,0,45,45,0,0,0,0,0,0,0,0,0,0,0,0,0,0
1,1,1,1,1,46,0,0,0,0,0,0,0,46,0,0,0,0,0,0,0,0,0,0,0,0,0,0,0
1,1,1,1,1,46,0,69,69,0,69,69,0,46,1,1,1,1,1,1,1,1,1,1,1,1,1,1,1
1,1,1,1,1,46,0,69,0,0,0,69,0,46,1,1,1,1,1,1,1,1,1,1,1,1,1,1,1
1,1,1,1,1,46,0,69,0,69,0,69,0,46,1,1,1,1,1,1,1,1,1,1,1,1,1,1,1
1,1,1,1,1,46,0,69,0,0,0,69,0,46,1,1,1,1,1,1,1,1,1,1,1,1,1,1,1
1,1,1,1,1,46,0,69,69,0,69,69,0,46,1,1,1,1,1,1,1,1,1,1,1,1,1,1,1
1,1,1,1,1,46,0,0,0,0,0,0,0,46,1,1,1,1,1,1,1,1,1,1,1,1,1,1,1
1,1,17,28,17,45,44,44,44,44,44,44,44,45,17,28,17,1,1,1,1,1,1,1,1,1,1,1,1
1,1,28,0,0,0,0,0,0,0,0,0,0,0,0,0,28,1,1,1,1,1,1,1,1,1,1,1,1
1,1,17,0,0,0,0,0,0,0,0,0,0,0,0,0,17,1,1,1,1,1,1,1,1,1,1,1,1
1,1,28,0,0,2,3,3,3,3,3,3,3,2,0,0,28,1,1,1,1,1,1,1,1,1,1,1,1
1,1,17,0,0,3,0,0,0,0,0,0,0,3,0,0,17,1,1,1,1,1,1,1,1,1,1,1,1
1,1,28,0,0,3,0,0,0,0,0,0,0,3,0,0,28,1,1,1,1,1,1,1,1,1,1,1,1
1,1,17,0,0,3,0,0,0,0,0,0,0,3,0,0,17,1,1,1,1,1,1,1,1,1,1,1,1
1,1,28,0,0,3,0,0,0,0,0,0,0,3,0,0,28,1,1,1,1,1,1,1,1,1,1,1,1
1,1,17,0,0,3,0,0,0,0,0,0,0,3,0,0,17,1,1,1,1,1,1,1,1,1,1,1,1
1,1,28,0,0,2,3,3,3,3,3,3,3,2,0,0,28,1,1,1,1,1,1,1,1,1,1,1,1
1,1,17,0,0,0,0,0,0,0,0,0,0,0,0,0,17,1,1,1,1,1,1,1,1,1,1,1,1
1,1,28,0,0,0,0,0,0,0,0,0,0,0,0,0,28,1,1,1,1,1,1,1,1,1,1,1,1
1,1,17,28,17,28,17,28,17,28,17,28,17,28,17,28,17,1,1,1,1,1,1,1,1,1,1,1,1
1,1,1,1,1,1,1,1,1,1,1,1,1,1,1,1,1,1,1,1,1,1,1,1,1,1,1,1,1
1,1,1,1,1,1,1,1,1,0,1,1,1,1,1,1,1,1,1,1,1,1,1,1,1,1,1,1,1
endlayer

layer
1,1,1,1,1,1,1,1,1,1,1,1,1,1,1,1,1,1,1,1,1,1,1,1,1,1,1,1,1
1,1,1,1,1,1,1,1,1,1,1,1,1,1,1,1,1,1,1,1,1,1,1,1,1,1,1,1,1
1,1,1,1,1,1,1,1,70,1,70,1,1,1,1,1,1,1,1,1,1,1,1,1,1,1,1,1,1
1,1,1,1,1,1,1,45,71,54,71,45,1,1,1,1,1,1,1,1,1,1,1,1,1,1,1,1,1
1,1,1,1,1,73,71,0,0,0,0,0,71,72,1,1,1,1,1,1,1,1,1,1,1,1,1,1,1
1,1,1,1,70,54,1,0,0,0,0,0,0,54,70,0,0,0,0,0,0,0,0,0,0,0,0,0,0
1,1,1,1,71,1,1,0,0,0,0,0,0,0,71,0,0,0,0,0,0,0,0,0,0,0,0,0,0
1,1,1,45,1,1,1,0,0,0,0,0,0,0,0,45,0,0,0,0,0,0,0,0,0,0,0,0,0
1,0,73,71,0,0,0,0,0,0,0,0,0,0,0,71,72,0,0,0,0,0,0,0,0,0,0,0,0
0,0,0,54,0,0,0,0,0,0,0,0,68,0,0,54,0,0,0,0,0,0,0,0,0,0,0,0,0
1,0,73,71,0,0,0,0,0,0,0,0,0,0,0,71,72,0,0,0,0,0,0,0,0,0,0,0,0
1,1,1,45,0,0,0,0,0,0,0,0,0,0,0,45,0,0,0,0,0,0,0,0,0,0,0,0,0
1,1,1,1,71,45,0,0,0,0,0,0,0,45,71,0,0,0,0,0,0,0,0,0,0,0,0,0,0
1,1,1,1,73,71,0,0,0,0,0,0,0,71,72,0,0,0,0,0,0,0,0,0,0,0,0,0,0
1,1,1,1,1,54,0,69,69,0,69,69,0,54,1,1,1,1,1,1,1,1,1,1,1,1,1,1,1
1,1,1,1,73,71,0,69,0,0,0,69,0,71,72,1,1,1,1,1,1,1,1,1,1,1,1,1,1
1,1,1,1,1,45,0,69,0,25,0,69,0,45,1,1,1,1,1,1,1,1,1,1,1,1,1,1,1
1,1,1,1,73,71,0,69,0,0,0,69,0,71,72,1,1,1,1,1,1,1,1,1,1,1,1,1,1
1,1,1,1,1,54,0,69,69,0,69,69,0,54,1,1,1,1,1,1,1,1,1,1,1,1,1,1,1
1,1,1,1,73,71,0,0,0,0,0,0,0,71,72,1,1,1,1,1,1,1,1,1,1,1,1,1,1
1,1,1,1,1,45,71,54,71,45,71,54,71,45,1,1,1,1,1,1,1,1,1,1,1,1,1,1,1
1,1,1,0,0,0,0,0,0,0,0,0,0,0,0,0,1,1,1,1,1,1,1,1,1,1,1,1,1
1,1,1,0,0,0,0,0,0,0,0,0,0,0,0,0,1,1,1,1,1,1,1,1,1,1,1,1,1
1,1,1,0,0,2,3,54,3,54,3,54,3,2,0,0,1,1,1,1,1,1,1,1,1,1,1,1,1
1,1,1,0,0,3,0,0,0,0,0,0,0,3,0,0,1,1,1,1,1,1,1,1,1,1,1,1,1
1,1,1,0,0,54,0,0,0,0,0,0,0,54,0,0,1,1,1,1,1,1,1,1,1,1,1,1,1
1,1,1,0,0,3,0,0,0,0,0,0,0,3,0,0,1,1,1,1,1,1,1,1,1,1,1,1,1
1,1,1,0,0,54,0,0,0,0,0,0,0,54,0,0,1,1,1,1,1,1,1,1,1,1,1,1,1
1,1,1,0,0,3,0,0,0,0,0,0,0,3,0,0,1,1,1,1,1,1,1,1,1,1,1,1,1
1,1,1,0,0,2,3,54,3,54,3,54,3,2,0,0,1,1,1,1,1,1,1,1,1,1,1,1,1
1,1,1,0,0,0,0,0,0,0,0,0,0,0,0,0,1,1,1,1,1,1,1,1,1,1,1,1,1
1,1,1,0,0,0,0,0,0,0,0,0,0,0,0,0,1,1,1,1,1,1,1,1,1,1,1,1,1
1,1,1,1,1,1,1,1,1,1,1,1,1,1,1,1,1,1,1,1,1,1,1,1,1,1,1,1,1
1,1,1,1,1,1,1,1,1,1,1,1,1,1,1,1,1,1,1,1,1,1,1,1,1,1,1,1,1
1,1,1,1,1,1,1,1,1,1,1,1,1,1,1,1,1,1,1,1,1,1,1,1,1,1,1,1,1
endlayer

layer
1,1,1,1,1,1,1,1,1,1,1,1,1,1,1,1,1,1,1,1,1,1,1,1,1,1,1,1,1
1,1,1,1,1,1,1,1,1,1,1,1,1,1,1,1,1,1,1,1,1,1,1,1,1,1,1,1,1
1,1,1,1,1,1,1,1,70,1,70,1,1,1,1,1,1,1,1,1,1,1,1,1,1,1,1,1,1
1,1,1,1,1,1,1,45,71,54,71,45,1,1,1,1,1,1,1,1,1,1,1,1,1,1,1,1,1
1,1,1,1,1,73,71,18,0,0,0,18,71,72,1,1,1,1,1,1,1,1,1,1,1,1,1,1,1
1,1,1,1,70,54,1,0,0,0,0,0,0,54,70,0,0,0,0,0,0,0,0,0,0,0,0,0,0
1,1,1,1,71,1,1,0,0,0,0,0,0,0,71,0,0,0,0,0,0,0,0,0,0,0,0,0,0
1,1,1,45,18,1,1,0,0,0,0,0,0,0,18,45,0,0,0,0,0,0,0,0,0,0,0,0,0
0,0,73,71,0,0,0,0,0,0,0,0,68,0,0,71,72,0,0,0,0,0,0,0,0,0,0,0,0
0,0,0,54,0,0,0,0,0,0,0,0,0,0,0,54,0,0,0,0,0,0,0,0,0,0,0,0,0
0,0,73,71,0,0,0,0,0,0,0,0,0,0,0,71,72,0,0,0,0,0,0,0,0,0,0,0,0
1,1,1,45,18,0,0,0,0,0,0,0,0,0,18,45,0,0,0,0,0,0,0,0,0,0,0,0,0
1,1,1,1,71,45,0,0,0,0,0,0,0,45,71,0,0,0,0,0,0,0,0,0,0,0,0,0,0
1,1,1,1,73,71,18,0,0,0,0,0,18,71,72,0,0,0,0,0,0,0,0,0,0,0,0,0,0
1,1,1,1,1,54,0,69,69,0,69,69,0,54,1,1,1,1,1,1,1,1,1,1,1,1,1,1,1
1,1,1,1,73,71,0,69,0,0,0,69,0,71,72,1,1,1,1,1,1,1,1,1,1,1,1,1,1
1,1,1,1,1,45,0,69,0,0,0,69,0,45,1,1,1,1,1,1,1,1,1,1,1,1,1,1,1
1,1,1,1,73,71,0,69,0,0,0,69,0,71,72,1,1,1,1,1,1,1,1,1,1,1,1,1,1
1,1,1,1,1,54,0,69,69,0,69,69,0,54,1,1,1,1,1,1,1,1,1,1,1,1,1,1,1
1,1,1,1,73,71,18,0,0,0,0,0,18,71,72,1,1,1,1,1,1,1,1,1,1,1,1,1,1
1,1,1,1,1,45,71,54,71,45,71,54,71,45,1,1,1,1,1,1,1,1,1,1,1,1,1,1,1
1,1,1,0,0,0,0,0,0,0,0,0,0,0,0,0,1,1,1,1,1,1,1,1,1,1,1,1,1
1,1,1,0,0,0,0,0,0,0,0,0,0,0,0,0,1,1,1,1,1,1,1,1,1,1,1,1,1
1,1,1,0,0,2,3,54,3,54,3,54,3,2,0,0,1,1,1,1,1,1,1,1,1,1,1,1,1
1,1,1,0,0,3,0,0,0,0,0,0,0,3,0,0,1,1,1,1,1,1,1,1,1,1,1,1,1
1,1,1,0,0,54,0,0,0,0,0,0,0,54,0,0,1,1,1,1,1,1,1,1,1,1,1,1,1
1,1,1,0,18,3,0,0,0,0,0,0,0,3,18,0,1,1,1,1,1,1,1,1,1,1,1,1,1
1,1,1,0,0,54,0,0,0,0,0,0,0,54,0,0,1,1,1,1,1,1,1,1,1,1,1,1,1
1,1,1,0,0,3,0,0,0,0,0,0,0,3,0,0,1,1,1,1,1,1,1,1,1,1,1,1,1
1,1,1,0,0,2,3,54,3,54,3,54,3,2,0,0,1,1,1,1,1,1,1,1,1,1,1,1,1
1,1,1,0,0,0,0,0,18,0,18,0,0,0,0,0,1,1,1,1,1,1,1,1,1,1,1,1,1
1,1,1,0,0,0,0,0,0,0,0,0,0,0,0,0,1,1,1,1,1,1,1,1,1,1,1,1,1
1,1,1,1,1,1,1,1,1,1,1,1,1,1,1,1,1,1,1,1,1,1,1,1,1,1,1,1,1
1,1,1,1,1,1,1,1,1,1,1,1,1,1,1,1,1,1,1,1,1,1,1,1,1,1,1,1,1
1,1,1,1,1,1,1,1,1,1,1,1,1,1,1,1,1,1,1,1,1,1,1,1,1,1,1,1,1
endlayer

layer
1,1,1,1,1,1,1,1,1,1,1,1,1,1,1,1,1,1,1,1,1,1,1,1,1,1,1,1,1
1,1,1,1,1,1,1,1,1,1,1,1,1,1,1,1,1,1,1,1,1,1,1,1,1,1,1,1,1
1,1,1,1,1,1,1,74,70,1,70,74,1,1,1,1,1,1,1,1,1,1,1,1,1,1,1,1,1
1,1,1,1,1,1,1,45,71,54,71,45,1,1,1,1,1,1,1,1,1,1,1,1,1,1,1,1,1
1,1,1,1,1,73,71,34,0,0,0,34,71,72,1,1,1,1,1,1,1,1,1,1,1,1,1,1,1
1,1,1,1,70,54,1,0,0,0,0,0,0,54,70,0,0,0,0,0,0,0,0,0,0,0,0,0,0
1,1,1,1,71,1,1,0,0,0,0,0,0,0,71,0,0,0,0,0,0,0,0,0,0,0,0,0,0
1,1,76,45,34,1,1,0,0,0,0,0,68,0,34,45,75,0,0,0,0,0,0,0,0,0,0,0,0
0,0,73,71,0,0,0,0,0,0,0,0,0,0,0,71,72,0,0,0,0,0,0,0,0,0,0,0,0
0,0,0,54,0,0,0,0,0,0,0,0,0,0,0,54,0,0,0,0,0,0,0,0,0,0,0,0,0
0,0,73,71,0,0,0,0,0,0,0,0,0,0,0,71,72,0,0,0,0,0,0,0,0,0,0,0,0
1,1,76,45,34,0,0,0,0,0,0,0,0,0,34,45,75,0,0,0,0,0,0,0,0,0,0,0,0
1,1,1,1,71,45,0,0,0,0,0,0,0,45,71,0,0,0,0,0,0,0,0,0,0,0,0,0,0
1,1,1,1,73,71,34,0,0,0,0,0,34,71,72,0,0,0,0,0,0,0,0,0,0,0,0,0,0
1,1,1,1,1,54,0,69,69,0,69,69,0,54,1,1,1,1,1,1,1,1,1,1,1,1,1,1,1
1,1,1,1,73,71,0,69,0,77,0,69,0,71,72,1,1,1,1,1,1,1,1,1,1,1,1,1,1
1,1,1,1,1,45,0,69,0,77,0,69,0,45,1,1,1,1,1,1,1,1,1,1,1,1,1,1,1
1,1,1,1,73,71,0,69,0,77,0,69,0,71,72,1,1,1,1,1,1,1,1,1,1,1,1,1,1
1,1,1,1,1,54,0,69,69,0,69,69,0,54,1,1,1,1,1,1,1,1,1,1,1,1,1,1,1
1,1,1,1,73,71,34,0,0,0,0,0,34,71,72,1,1,1,1,1,1,1,1,1,1,1,1,1,1
1,1,1,1,1,45,71,54,71,45,71,54,71,45,1,1,1,1,1,1,1,1,1,1,1,1,1,1,1
1,1,1,0,0,0,0,0,0,0,0,0,0,0,0,0,1,1,1,1,1,1,1,1,1,1,1,1,1
1,1,1,0,0,0,0,0,0,0,0,0,0,0,0,0,1,1,1,1,1,1,1,1,1,1,1,1,1
1,1,1,0,0,2,3,54,3,54,3,54,3,2,0,1,1,1,1,1,1,1,1,1,1,1,1,1,1
1,1,1,0,0,3,0,0,0,0,0,0,0,3,0,1,1,1,1,1,1,1,1,1,1,1,1,1,1
1,1,1,0,0,54,0,0,0,0,0,0,0,54,0,1,1,1,1,1,1,1,1,1,1,1,1,1,1
1,1,1,0,34,3,0,0,0,0,0,0,0,3,34,1,1,1,1,1,1,1,1,1,1,1,1,1,1
1,1,1,0,0,54,0,0,0,0,0,0,0,54,0,1,1,1,1,1,1,1,1,1,1,1,1,1,1
1,1,1,0,0,3,0,0,0,0,0,0,0,3,0,1,1,1,1,1,1,1,1,1,1,1,1,1,1
1,1,1,0,0,2,3,54,3,54,3,54,3,2,0,1,1,1,1,1,1,1,1,1,1,1,1,1,1
1,1,1,0,0,0,0,0,34,0,34,0,0,0,0,1,1,1,1,1,1,1,1,1,1,1,1,1,1
1,1,1,0,0,0,0,0,0,0,0,0,0,0,0,1,1,1,1,1,1,1,1,1,1,1,1,1,1
1,1,1,1,1,1,1,1,1,1,1,1,1,1,1,1,1,1,1,1,1,1,1,1,1,1,1,1,1
1,1,1,1,1,1,1,1,1,1,1,1,1,1,1,1,1,1,1,1,1,1,1,1,1,1,1,1,1
1,1,1,1,1,1,1,1,1,1,1,1,1,1,1,1,1,1,1,1,1,1,1,1,1,1,1,1,1
endlayer

layer
1,1,1,1,1,1,1,1,1,1,1,1,1,1,1,1,1,1,1,1,1,1,1,1,1,1,1,1,1
1,1,1,1,1,1,1,74,1,1,1,74,1,1,1,1,1,1,1,1,1,1,1,1,1,1,1,1,1
1,1,1,1,1,1,1,68,1,1,1,68,1,1,1,1,1,1,1,1,1,1,1,1,1,1,1,1,1
1,1,1,1,1,1,1,45,44,44,44,45,1,1,1,1,1,1,1,1,1,1,1,1,1,1,1,1,1
1,1,1,1,1,1,45,0,0,0,0,0,45,1,1,1,1,1,1,1,1,1,1,1,1,1,1,1,1
1,1,1,1,1,45,1,0,0,0,0,0,0,45,0,0,0,0,0,0,0,0,0,0,0,0,0,0,0
1,1,1,1,45,1,1,0,0,0,0,0,68,0,45,0,0,0,0,0,0,0,0,0,0,0,0,0,0
1,76,79,45,1,1,1,0,0,0,0,0,0,0,0,45,78,75,0,0,0,0,0,0,0,0,0,0,0
0,0,0,46,0,0,0,0,0,0,0,0,0,0,0,46,0,0,0,0,0,0,0,0,0,0,0,0,0
0,0,0,46,0,0,0,0,0,0,0,0,0,0,0,46,0,0,0,0,0,0,0,0,0,0,0,0,0
0,0,0,46,0,0,0,0,0,0,0,0,0,0,0,46,0,0,0,0,0,0,0,0,0,0,0,0,0
1,76,79,45,0,0,0,0,0,0,0,0,0,0,0,45,78,75,0,0,0,0,0,0,0,0,0,0,0
1,1,1,1,45,45,44,44,44,44,44,44,44,45,45,0,0,0,0,0,0,0,0,0,0,0,0,0,0
1,1,1,1,1,46,0,0,0,0,0,0,0,46,0,0,0,0,0,0,0,0,0,0,0,0,0,0,0
1,1,1,1,1,46,0,69,69,0,69,69,0,46,1,1,1,1,1,1,1,1,1,1,1,1,1,1,1
1,1,1,1,1,46,0,69,0,34,0,69,0,46,1,1,1,1,1,1,1,1,1,1,1,1,1,1,1
1,1,1,1,1,46,0,69,0,77,0,69,0,46,1,1,1,1,1,1,1,1,1,1,1,1,1,1,1
1,1,1,1,1,46,0,69,0,34,0,69,0,46,1,1,1,1,1,1,1,1,1,1,1,1,1,1,1
1,1,1,1,1,46,0,69,69,0,69,69,0,46,1,1,1,1,1,1,1,1,1,1,1,1,1,1,1
1,1,1,1,1,46,0,0,0,0,0,0,0,46,1,1,1,1,1,1,1,1,1,1,1,1,1,1,1
1,1,1,1,1,45,44,44,44,44,44,44,44,45,1,1,1,1,1,1,1,1,1,1,1,1,1,1,1
1,1,1,0,0,0,0,0,0,0,0,0,0,0,0,1,1,1,1,1,1,1,1,1,1,1,1,1,1
1,1,1,0,0,0,0,0,0,0,0,0,0,0,0,1,1,1,1,1,1,1,1,1,1,1,1,1,1
1,1,1,0,0,2,3,54,3,54,3,54,3,2,0,1,1,1,1,1,1,1,1,1,1,1,1,1,1
1,1,1,0,0,3,0,0,0,0,0,0,0,3,0,1,1,1,1,1,1,1,1,1,1,1,1,1,1
1,1,1,0,0,54,0,0,0,0,0,0,0,54,0,1,1,1,1,1,1,1,1,1,1,1,1,1,1
1,1,1,0,0,3,0,0,0,0,0,0,0,3,0,1,1,1,1,1,1,1,1,1,1,1,1,1,1
1,1,1,0,0,54,0,0,0,0,0,0,0,54,0,1,1,1,1,1,1,1,1,1,1,1,1,1,1
1,1,1,0,0,3,0,0,0,0,0,0,0,3,0,1,1,1,1,1,1,1,1,1,1,1,1,1,1
1,1,1,0,0,2,3,54,3,54,3,54,3,2,0,1,1,1,1,1,1,1,1,1,1,1,1,1,1
1,1,1,0,0,0,0,0,0,0,0,0,0,0,0,1,1,1,1,1,1,1,1,1,1,1,1,1,1
1,1,1,0,0,0,0,0,0,0,0,0,0,0,0,1,1,1,1,1,1,1,1,1,1,1,1,1,1
1,1,1,1,1,1,1,1,1,1,1,1,1,1,1,1,1,1,1,1,1,1,1,1,1,1,1,1,1
1,1,1,1,1,1,1,1,1,1,1,1,1,1,1,1,1,1,1,1,1,1,1,1,1,1,1,1,1
1,1,1,1,1,1,1,1,1,1,1,1,1,1,1,1,1,1,1,1,1,1,1,1,1,1,1,1,1
endlayer

layer
1,1,1,1,1,1,77,45,44,44,44,45,77,1,1,1,1,1,1,1,1,1,1,1,1,1,1,1,1
1,1,1,1,1,1,77,46,80,60,80,46,77,1,1,1,1,1,1,1,1,1,1,1,1,1,1,1,1
1,1,1,1,1,1,77,46,60,80,60,46,77,1,1,1,1,1,1,1,1,1,1,1,1,1,1,1,1
1,1,1,1,1,77,77,45,45,45,45,45,77,77,1,1,1,1,1,1,1,1,1,1,1,1,1,1,1
1,1,1,1,77,77,45,80,60,80,60,80,45,77,77,1,1,1,1,1,1,1,1,1,1,1,1,1,1
1,1,1,77,77,45,80,60,80,60,80,60,68,45,77,77,0,0,0,0,0,0,0,0,0,0,0,0,0
77,77,77,77,45,80,60,80,60,80,60,80,0,80,45,77,77,77,77,0,0,0,0,0,0,0,0,0,0
45,44,44,45,80,60,80,60,80,60,80,60,0,60,80,45,44,44,45,0,0,0,0,0,0,0,0,0,0
46,80,60,45,60,80,60,80,60,80,60,80,0,80,60,45,60,80,46,0,0,0,0,0,0,0,0,0,0
46,60,80,45,80,60,80,60,80,60,80,60,80,60,80,45,80,60,46,0,0,0,0,0,0,0,0,0,0
46,80,60,45,60,80,60,80,60,80,60,80,60,80,60,45,60,80,46,0,0,0,0,0,0,0,0,0,0
45,44,44,45,80,60,80,60,80,60,80,60,80,60,80,45,44,44,45,0,0,0,0,0,0,0,0,0,0
77,77,77,77,45,45,45,45,45,45,45,45,45,45,45,77,77,77,77,0,0,0,0,0,0,0,0,0,0
1,1,1,77,77,45,81,81,81,81,81,81,81,45,77,77,0,0,0,0,0,0,0,0,0,0,0,0,0
1,1,1,1,77,45,81,82,83,82,83,82,81,45,77,1,1,1,1,1,1,1,1,1,1,1,1,1,1
1,1,1,1,77,45,81,84,85,86,85,84,81,45,77,1,1,1,1,1,1,1,1,1,1,1,1,1,1
1,1,1,1,77,45,81,82,87,45,87,82,81,45,77,1,1,1,1,1,1,1,1,1,1,1,1,1,1
1,1,1,1,77,45,81,84,85,86,85,84,81,45,77,1,1,1,1,1,1,1,1,1,1,1,1,1,1
1,1,1,1,77,45,81,82,83,82,83,82,81,45,77,1,1,1,1,1,1,1,1,1,1,1,1,1,1
1,1,1,1,77,45,81,81,81,81,81,81,81,45,77,1,1,1,1,1,1,1,1,1,1,1,1,1,1
1,1,1,1,77,45,45,45,45,45,45,45,45,45,77,1,1,1,1,1,1,1,1,1,1,1,1,1,1
1,1,1,0,77,46,0,0,0,0,0,0,0,46,77,1,1,1,1,1,1,1,1,1,1,1,1,1,1
1,1,1,0,77,46,33,0,33,0,33,0,33,46,77,1,1,1,1,1,1,1,1,1,1,1,1,1,1
1,1,1,0,0,2,3,3,3,3,3,3,3,2,0,1,1,1,1,1,1,1,1,1,1,1,1,1,1
1,1,1,0,14,3,0,0,0,0,0,0,0,3,11,1,1,1,1,1,1,1,1,1,1,1,1,1,1
1,1,1,0,0,3,0,0,0,0,0,0,0,3,0,1,1,1,1,1,1,1,1,1,1,1,1,1,1
1,1,1,0,14,3,0,0,0,0,0,0,0,3,11,1,1,1,1,1,1,1,1,1,1,1,1,1,1
1,1,1,0,0,3,0,0,0,0,0,0,0,3,0,1,1,1,1,1,1,1,1,1,1,1,1,1,1
1,1,1,0,14,3,0,0,0,0,0,0,0,3,11,1,1,1,1,1,1,1,1,1,1,1,1,1,1
1,1,1,0,0,2,3,3,3,3,3,3,3,2,0,1,1,1,1,1,1,1,1,1,1,1,1,1,1
1,1,1,0,0,0,41,0,41,0,41,0,41,0,0,1,1,1,1,1,1,1,1,1,1,1,1,1,1
1,1,1,0,0,0,0,0,0,0,0,0,0,0,0,1,1,1,1,1,1,1,1,1,1,1,1,1,1
1,1,1,1,1,1,1,1,1,1,1,1,1,1,1,1,1,1,1,1,1,1,1,1,1,1,1,1,1
1,1,1,1,1,1,1,1,1,1,1,1,1,1,1,1,1,1,1,1,1,1,1,1,1,1,1,1,1
1,1,1,1,1,1,1,1,1,1,1,1,1,1,1,1,1,1,1,1,1,1,1,1,1,1,1,1,1
endlayer

layer
1,1,1,1,1,1,1,77,77,77,77,77,1,1,1,1,1,1,1,1,1,1,1,1,1,1,1,1,1
1,1,1,1,1,1,1,77,0,0,0,77,1,1,1,1,1,1,1,1,1,1,1,1,1,1,1,1,1
1,1,1,1,1,1,1,77,0,0,0,77,1,1,1,1,1,1,1,1,1,1,1,1,1,1,1,1,1
1,1,1,1,1,1,1,45,0,0,0,45,1,1,1,1,1,1,1,1,1,1,1,1,1,1,1,1,1
1,1,1,1,1,1,45,25,0,0,0,25,45,1,1,1,1,1,1,1,1,1,1,1,1,1,1,1,1
1,1,1,1,1,45,1,0,0,0,0,0,0,45,0,0,0,0,0,0,0,0,0,0,0,0,0,0,0
1,1,1,1,45,1,52,0,0,0,0,0,0,88,45,0,0,0,0,0,0,0,0,0,0,0,0,0,0
77,77,77,45,1,1,1,0,0,0,0,0,0,0,0,45,77,77,77,0,0,0,0,0,0,0,0,0,0
77,0,0,0,0,0,0,0,0,0,0,0,0,0,0,0,0,0,77,0,0,0,0,0,0,0,0,0,0
77,0,0,0,0,0,0,0,0,0,0,0,0,0,0,0,0,0,77,0,0,0,0,0,0,0,0,0,0
77,0,0,0,0,0,0,0,0,0,0,0,0,0,0,0,0,0,77,0,0,0,0,0,0,0,0,0,0
77,77,77,45,25,0,0,0,0,0,0,0,0,0,25,45,77,77,77,0,0,0,0,0,0,0,0,0,0
1,1,1,1,45,45,45,45,0,0,0,45,45,45,45,0,0,0,0,0,0,0,0,0,0,0,0,0,0
1,1,1,1,1,46,38,72,0,0,0,73,38,46,0,0,0,0,0,0,0,0,0,0,0,0,0,0,0
1,1,1,1,1,46,89,0,0,90,0,0,89,46,1,1,1,1,1,1,1,1,1,1,1,1,1,1,1
1,1,1,1,1,46,0,0,67,91,66,0,0,46,1,1,1,1,1,1,1,1,1,1,1,1,1,1,1
1,1,1,1,1,45,25,0,0,91,0,0,25,45,1,1,1,1,1,1,1,1,1,1,1,1,1,1,1
1,1,1,1,1,46,0,0,67,91,66,0,0,46,1,1,1,1,1,1,1,1,1,1,1,1,1,1,1
1,1,1,1,1,46,70,0,0,92,0,0,70,46,1,1,1,1,1,1,1,1,1,1,1,1,1,1,1
1,1,1,1,1,46,38,72,0,0,0,73,38,46,1,1,1,1,1,1,1,1,1,1,1,1,1,1,1
1,1,1,1,1,45,89,0,0,0,0,0,89,45,1,1,1,1,1,1,1,1,1,1,1,1,1,1,1
1,1,1,0,0,46,52,52,52,52,52,52,52,45,0,1,1,1,1,1,1,1,1,1,1,1,1,1,1
1,1,1,0,2,3,3,3,3,3,3,3,3,3,2,1,1,1,1,1,1,1,1,1,1,1,1,1,1
1,1,1,0,3,2,8,2,8,2,8,2,8,2,3,1,1,1,1,1,1,1,1,1,1,1,1,1,1
1,1,1,0,3,8,2,8,2,8,2,8,2,8,3,1,1,1,1,1,1,1,1,1,1,1,1,1,1
1,1,1,0,3,2,8,2,8,2,8,2,8,2,3,1,1,1,1,1,1,1,1,1,1,1,1,1,1
1,1,1,0,3,8,2,8,2,8,2,8,2,8,3,1,1,1,1,1,1,1,1,1,1,1,1,1,1
1,1,1,0,3,2,8,2,8,2,8,2,8,2,3,1,1,1,1,1,1,1,1,1,1,1,1,1,1
1,1,1,0,3,8,2,8,2,8,2,8,2,8,3,1,1,1,1,1,1,1,1,1,1,1,1,1,1
1,1,1,0,3,2,8,2,8,2,8,2,8,2,3,1,1,1,1,1,1,1,1,1,1,1,1,1,1
1,1,1,0,2,3,3,3,3,3,3,3,3,3,2,1,1,1,1,1,1,1,1,1,1,1,1,1,1
1,1,1,0,0,0,0,0,0,0,0,0,0,0,0,1,1,1,1,1,1,1,1,1,1,1,1,1,1
1,1,1,1,1,1,1,1,1,1,1,1,1,1,1,1,1,1,1,1,1,1,1,1,1,1,1,1,1
1,1,1,1,1,1,1,1,1,1,1,1,1,1,1,1,1,1,1,1,1,1,1,1,1,1,1,1,1
1,1,1,1,1,1,1,1,1,1,1,1,1,1,1,1,1,1,1,1,1,1,1,1,1,1,1,1,1
endlayer

layer
1,1,1,1,1,1,1,34,0,0,0,34,1,1,1,1,1,1,1,1,1,1,1,1,1,1,1,1,1
1,1,1,1,1,1,1,0,0,0,0,0,1,1,1,1,1,1,1,1,1,1,1,1,1,1,1,1,1
1,1,1,1,1,1,1,0,0,0,0,0,1,1,1,1,1,1,1,1,1,1,1,1,1,1,1,1,1
1,1,1,1,1,1,1,45,0,0,0,45,1,1,1,1,1,1,1,1,1,1,1,1,1,1,1,1,1
1,1,1,1,1,73,71,0,0,0,0,0,71,72,1,1,1,1,1,1,1,1,1,1,1,1,1,1,1
1,1,1,1,70,54,1,0,0,0,0,0,0,54,70,0,0,0,0,0,0,0,0,0,0,0,0,0,0
1,1,1,1,71,1,1,0,0,0,0,0,0,0,71,0,0,0,0,0,0,0,0,0,0,0,0,0,0
34,1,1,45,1,1,52,0,0,0,0,0,0,0,0,45,0,0,34,0,0,0,0,0,0,0,0,0,0
0,0,0,0,0,0,0,0,0,0,0,0,0,0,0,0,0,0,0,0,0,0,0,0,0,0,0,0,0
0,0,0,0,0,0,0,0,0,0,0,0,0,0,0,0,0,0,0,0,0,0,0,0,0,0,0,0,0
0,0,0,0,0,0,0,0,0,0,0,0,0,0,0,0,0,0,0,0,0,0,0,0,0,0,0,0,0
34,1,1,45,0,0,0,0,0,0,0,0,0,0,0,45,0,0,34,0,0,0,0,0,0,0,0,0,0
1,1,1,1,71,45,71,45,0,0,0,45,71,45,71,0,0,0,0,0,0,0,0,0,0,0,0,0,0
1,1,1,1,73,71,93,0,0,0,0,0,93,71,72,0,0,0,0,0,0,0,0,0,0,0,0,0,0
1,1,1,1,1,54,0,0,0,34,0,0,0,54,1,1,1,1,1,1,1,1,1,1,1,1,1,1,1
1,1,1,1,73,71,0,0,0,94,0,0,0,71,72,1,1,1,1,1,1,1,1,1,1,1,1,1,1
1,1,1,1,1,45,0,0,0,94,0,0,0,45,1,1,1,1,1,1,1,1,1,1,1,1,1,1,1
1,1,1,1,73,71,0,0,0,94,0,0,0,71,72,1,1,1,1,1,1,1,1,1,1,1,1,1,1
1,1,1,1,1,54,0,0,0,34,0,0,0,54,1,1,1,1,1,1,1,1,1,1,1,1,1,1,1
1,1,1,1,73,71,93,0,0,0,0,0,93,71,72,1,1,1,1,1,1,1,1,1,1,1,1,1,1
1,1,1,1,1,45,0,0,0,0,0,0,0,45,1,1,1,1,1,1,1,1,1,1,1,1,1,1,1
1,1,1,0,0,71,0,0,0,0,0,0,0,71,0,1,1,1,1,1,1,1,1,1,1,1,1,1,1
1,1,1,0,2,3,3,3,2,95,2,3,3,3,2,1,1,1,1,1,1,1,1,1,1,1,1,1,1
1,1,1,0,3,38,72,0,0,0,0,0,73,38,3,1,1,1,1,1,1,1,1,1,1,1,1,1,1
1,1,1,0,3,89,0,0,0,0,0,0,0,89,3,1,1,1,1,1,1,1,1,1,1,1,1,1,1
1,1,1,0,3,92,0,0,0,0,0,0,0,92,3,1,1,1,1,1,1,1,1,1,1,1,1,1,1
1,1,1,0,3,91,66,0,0,96,0,0,67,91,3,1,1,1,1,1,1,1,1,1,1,1,1,1,1
1,1,1,0,3,90,0,0,0,0,0,0,0,90,3,1,1,1,1,1,1,1,1,1,1,1,1,1,1
1,1,1,0,3,70,0,25,0,65,0,25,0,70,3,1,1,1,1,1,1,1,1,1,1,1,1,1,1
1,1,1,0,3,38,72,27,98,91,97,27,73,38,3,1,1,1,1,1,1,1,1,1,1,1,1,1,1
1,1,1,0,2,3,3,3,3,3,3,3,3,3,2,1,1,1,1,1,1,1,1,1,1,1,1,1,1
1,1,1,0,0,0,0,0,0,0,0,0,0,0,0,1,1,1,1,1,1,1,1,1,1,1,1,1,1
1,1,1,1,1,1,1,1,1,1,1,1,1,1,1,1,1,1,1,1,1,1,1,1,1,1,1,1,1
1,1,1,1,1,1,1,1,1,1,1,1,1,1,1,1,1,1,1,1,1,1,1,1,1,1,1,1,1
1,1,1,1,1,1,1,1,1,1,1,1,1,1,1,1,1,1,1,1,1,1,1,1,1,1,1,1,1
endlayer

layer
1,1,1,1,1,1,1,0,0,0,0,0,1,1,1,1,1,1,1,1,1,1,1,1,1,1,1,1,1
1,1,1,1,1,1,1,0,0,0,0,0,1,1,1,1,1,1,1,1,1,1,1,1,1,1,1,1,1
1,1,1,1,1,1,1,0,0,0,0,0,1,1,1,1,1,1,1,1,1,1,1,1,1,1,1,1,1
1,1,1,1,1,1,1,45,0,0,0,45,1,1,1,1,1,1,1,1,1,1,1,1,1,1,1,1,1
1,1,1,1,1,73,71,18,0,0,0,18,71,72,1,1,1,1,1,1,1,1,1,1,1,1,1,1,1
1,1,1,1,70,54,1,0,0,0,0,0,0,54,70,0,0,0,0,0,0,0,0,0,0,0,0,0,0
1,1,1,1,71,1,1,0,0,0,0,0,0,0,71,0,0,0,0,0,0,0,0,0,0,0,0,0,0
1,1,1,45,18,1,1,0,0,0,0,0,0,0,18,45,0,0,0,0,0,0,0,0,0,0,0,0,0
0,0,0,0,0,0,52,0,0,0,0,0,0,0,0,0,0,0,0,0,0,0,0,0,0,0,0,0,0
0,0,0,0,0,0,0,0,0,0,0,0,0,0,0,0,0,0,0,0,0,0,0,0,0,0,0,0,0
0,0,0,0,0,0,0,0,0,0,0,0,0,0,0,0,0,0,0,0,0,0,0,0,0,0,0,0,0
1,1,1,45,18,0,0,0,0,0,0,0,0,0,18,45,0,0,0,0,0,0,0,0,0,0,0,0,0
1,1,1,1,71,45,71,45,0,0,0,45,71,45,71,0,0,0,0,0,0,0,0,0,0,0,0,0,0
1,1,1,1,73,71,99,0,0,0,0,0,99,71,72,0,0,0,0,0,0,0,0,0,0,0,0,0,0
1,1,1,1,1,54,0,0,0,0,0,0,0,54,1,1,1,1,1,1,1,1,1,1,1,1,1,1,1
1,1,1,1,73,71,0,0,0,0,0,0,0,71,72,1,1,1,1,1,1,1,1,1,1,1,1,1,1
1,1,1,1,1,45,0,0,0,0,0,0,0,45,1,1,1,1,1,1,1,1,1,1,1,1,1,1,1
1,1,1,1,73,71,0,0,0,0,0,0,0,71,72,1,1,1,1,1,1,1,1,1,1,1,1,1,1
1,1,1,1,1,54,0,0,0,0,0,0,0,54,1,1,1,1,1,1,1,1,1,1,1,1,1,1,1
1,1,1,1,73,71,99,0,0,0,0,0,99,71,72,1,1,1,1,1,1,1,1,1,1,1,1,1,1
1,1,1,1,1,45,0,0,0,0,0,0,0,45,1,1,1,1,1,1,1,1,1,1,1,1,1,1,1
1,1,1,0,0,71,0,0,0,0,0,0,0,71,0,1,1,1,1,1,1,1,1,1,1,1,1,1,1
1,1,1,0,2,3,3,3,2,31,2,3,3,3,2,1,1,1,1,1,1,1,1,1,1,1,1,1,1
1,1,1,0,3,93,0,0,0,0,0,0,0,93,3,1,1,1,1,1,1,1,1,1,1,1,1,1,1
1,1,1,0,54,0,0,0,0,0,0,0,0,0,54,1,1,1,1,1,1,1,1,1,1,1,1,1,1
1,1,1,0,3,0,0,0,0,0,0,0,0,0,3,1,1,1,1,1,1,1,1,1,1,1,1,1,1
1,1,1,0,54,94,0,0,0,0,0,0,0,94,54,1,1,1,1,1,1,1,1,1,1,1,1,1,1
1,1,1,0,3,0,0,0,0,0,0,0,0,0,3,1,1,1,1,1,1,1,1,1,1,1,1,1,1
1,1,1,0,54,0,0,0,0,0,0,0,0,0,54,1,1,1,1,1,1,1,1,1,1,1,1,1,1
1,1,1,0,3,93,0,0,0,94,0,0,0,93,3,1,1,1,1,1,1,1,1,1,1,1,1,1,1
1,1,1,0,2,3,54,3,54,3,54,3,54,3,2,1,1,1,1,1,1,1,1,1,1,1,1,1,1
1,1,1,0,0,0,0,0,0,0,0,0,0,0,0,1,1,1,1,1,1,1,1,1,1,1,1,1,1
1,1,1,1,1,1,1,1,1,1,1,1,1,1,1,1,1,1,1,1,1,1,1,1,1,1,1,1,1
1,1,1,1,1,1,1,1,1,1,1,1,1,1,1,1,1,1,1,1,1,1,1,1,1,1,1,1,1
1,1,1,1,1,1,1,1,1,1,1,1,1,1,1,1,1,1,1,1,1,1,1,1,1,1,1,1,1
endlayer

layer
1,1,1,1,1,1,1,0,0,0,0,0,1,1,1,1,1,1,1,1,1,1,1,1,1,1,1,1,1
1,1,1,1,1,1,1,0,0,0,0,0,1,1,1,1,1,1,1,1,1,1,1,1,1,1,1,1,1
1,1,1,1,1,1,1,74,0,0,0,74,1,1,1,1,1,1,1,1,1,1,1,1,1,1,1,1,1
1,1,1,1,1,1,1,45,77,77,77,45,1,1,1,1,1,1,1,1,1,1,1,1,1,1,1,1,1
1,1,1,1,1,73,71,34,0,0,0,34,71,72,1,1,1,1,1,1,1,1,1,1,1,1,1,1,0
1,1,1,1,70,54,1,0,0,0,0,0,0,54,70,0,0,0,0,0,0,0,0,0,0,0,0,0,0
1,1,1,1,71,1,1,0,0,0,0,0,0,0,71,0,0,0,0,0,0,0,0,0,0,0,0,0,0
1,1,76,45,34,1,1,0,0,0,0,0,0,0,34,45,75,0,0,0,0,0,0,0,0,0,0,0,0
0,0,0,77,0,0,0,0,0,0,0,0,0,0,0,77,0,0,0,0,0,0,0,0,0,0,0,0,0
0,0,0,77,0,0,52,0,0,0,0,0,0,0,0,77,0,0,0,0,0,0,0,0,0,0,0,0,0
0,0,0,77,0,0,0,0,0,0,0,0,0,0,0,77,0,0,0,0,0,0,0,0,0,0,0,0,0
1,1,76,45,34,0,0,0,0,0,0,0,0,0,34,45,75,0,0,0,0,0,0,0,0,0,0,0,0
1,1,1,1,71,45,71,45,0,0,0,45,71,45,71,0,0,0,0,0,0,0,0,0,0,0,0,0,0
1,1,1,1,73,71,0,0,0,0,0,0,0,71,72,0,0,0,0,0,0,0,0,0,0,0,0,0,0
1,1,1,1,1,54,0,0,0,0,0,0,0,54,1,1,1,1,1,1,1,1,1,1,1,1,1,1,1
1,1,1,1,73,71,0,0,0,0,0,0,0,71,72,1,1,1,1,1,1,1,1,1,1,1,1,1,1
1,1,1,1,1,45,0,0,0,0,0,0,0,45,1,1,1,1,1,1,1,1,1,1,1,1,1,1,1
1,1,1,1,73,71,0,0,0,0,0,0,0,71,72,1,1,1,1,1,1,1,1,1,1,1,1,1,1
1,1,1,1,1,54,0,0,0,0,0,0,0,54,1,1,1,1,1,1,1,1,1,1,1,1,1,1,1
1,1,1,1,73,71,0,0,0,0,0,0,0,71,72,1,1,1,1,1,1,1,1,1,1,1,1,1,1
1,1,1,1,1,45,0,0,0,0,0,0,0,45,1,1,1,1,1,1,1,1,1,1,1,1,1,1,1
1,1,1,0,0,71,0,0,0,0,0,0,0,71,0,1,1,1,1,1,1,1,1,1,1,1,1,1,1
1,1,1,0,2,3,3,3,2,2,2,3,3,3,2,1,1,1,1,1,1,1,1,1,1,1,1,1,1
1,1,1,0,3,99,0,0,0,0,0,0,0,99,3,1,1,1,1,1,1,1,1,1,1,1,1,1,1
1,1,1,0,54,0,0,0,0,0,0,0,0,0,54,1,1,1,1,1,1,1,1,1,1,1,1,1,1
1,1,1,0,3,0,0,0,0,0,0,0,0,0,3,1,1,1,1,1,1,1,1,1,1,1,1,1,1
1,1,1,0,54,0,0,0,0,0,0,0,0,0,54,1,1,1,1,1,1,1,1,1,1,1,1,1,1
1,1,1,0,3,0,0,0,0,0,0,0,0,0,3,1,1,1,1,1,1,1,1,1,1,1,1,1,1
1,1,1,0,54,0,0,0,0,0,0,0,0,0,54,1,1,1,1,1,1,1,1,1,1,1,1,1,1
1,1,1,0,3,99,0,0,0,0,0,0,0,99,3,1,1,1,1,1,1,1,1,1,1,1,1,1,1
1,1,1,0,2,3,54,3,54,3,54,3,54,3,2,1,1,1,1,1,1,1,1,1,1,1,1,1,1
1,1,1,0,0,0,0,0,0,0,0,0,0,0,0,1,1,1,1,1,1,1,1,1,1,1,1,1,1
1,1,1,1,1,1,1,1,1,1,1,1,1,1,1,1,1,1,1,1,1,1,1,1,1,1,1,1,1
1,1,1,1,1,1,1,1,1,1,1,1,1,1,1,1,1,1,1,1,1,1,1,1,1,1,1,1,1
1,1,1,1,1,1,1,1,1,1,1,1,1,1,1,1,1,1,1,1,1,1,1,1,1,1,1,1,1
endlayer

layer
1,1,1,1,1,1,1,0,0,0,0,0,1,1,1,1,1,1,1,1,1,1,1,1,1,1,1,1,1
1,1,1,1,1,1,1,74,0,0,0,74,1,1,1,1,1,1,1,1,1,1,1,1,1,1,1,1,1
1,1,1,1,1,1,1,68,0,0,0,68,1,1,1,1,1,1,1,1,1,1,1,1,1,1,1,1,1
1,1,1,1,1,1,1,45,45,45,45,45,1,1,1,1,1,1,1,1,1,1,1,1,1,1,1,1,1
1,1,1,1,1,1,45,0,0,0,0,0,45,1,1,1,1,1,1,1,1,1,1,1,1,1,1,1,0
1,1,1,1,1,45,1,0,0,0,0,0,0,45,0,0,0,0,0,0,0,0,0,0,0,0,0,0,0
1,1,1,1,45,1,1,0,0,0,0,0,0,0,45,0,0,0,0,0,0,0,0,0,0,0,0,0,0
1,76,79,45,1,1,1,0,0,0,0,0,0,0,0,45,78,75,0,0,0,0,0,0,0,0,0,0,0
0,0,0,45,0,0,0,0,0,0,0,0,0,0,0,45,0,0,0,0,0,0,0,0,0,0,0,0,0
0,0,0,45,0,0,0,0,0,0,0,0,0,0,0,45,0,0,0,0,0,0,0,0,0,0,0,0,0
0,0,0,45,0,0,52,0,0,0,0,0,0,0,0,45,0,0,0,0,0,0,0,0,0,0,0,0,0
1,76,79,45,0,0,0,0,0,0,0,0,0,0,0,45,78,75,0,0,0,0,0,0,0,0,0,0,0
1,1,1,1,45,45,45,45,45,45,45,45,45,45,45,0,0,0,0,0,0,0,0,0,0,0,0,0,0
1,1,1,1,1,46,0,0,0,0,0,0,0,46,0,0,0,0,0,0,0,0,0,0,0,0,0,0,0
1,1,1,1,1,46,0,0,0,0,0,0,0,46,1,1,1,1,1,1,1,1,1,1,1,1,1,1,0
1,1,1,1,1,46,0,0,0,0,0,0,0,46,1,1,1,1,1,1,1,1,1,1,1,1,1,1,1
1,1,1,1,1,45,0,0,0,0,0,0,0,45,1,1,1,1,1,1,1,1,1,1,1,1,1,1,1
1,1,1,1,1,46,0,0,0,0,0,0,0,46,1,1,1,1,1,1,1,1,1,1,1,1,1,1,1
1,1,1,1,1,46,0,0,0,0,0,0,0,46,1,1,1,1,1,1,1,1,1,1,1,1,1,1,1
1,1,1,1,1,46,0,0,0,0,0,0,0,46,1,1,1,1,1,1,1,1,1,1,1,1,1,1,1
1,1,1,1,1,45,0,0,0,0,0,0,0,45,1,1,1,1,1,1,1,1,1,1,1,1,1,1,1
1,1,1,0,0,46,0,0,0,0,0,0,0,46,0,1,1,1,1,1,1,1,1,1,1,1,1,1,1
1,1,1,0,2,3,3,3,3,3,3,3,3,3,2,1,1,1,1,1,1,1,1,1,1,1,1,1,1
1,1,1,0,3,18,0,0,0,18,0,0,0,18,3,1,1,1,1,1,1,1,1,1,1,1,1,1,1
1,1,1,0,54,0,0,0,0,0,0,0,0,0,54,1,1,1,1,1,1,1,1,1,1,1,1,1,1
1,1,1,0,3,0,0,0,0,0,0,0,0,0,3,1,1,1,1,1,1,1,1,1,1,1,1,1,1
1,1,1,0,54,0,0,0,0,0,0,0,0,0,54,1,1,1,1,1,1,1,1,1,1,1,1,1,1
1,1,1,0,3,0,0,0,0,0,0,0,0,0,3,1,1,1,1,1,1,1,1,1,1,1,1,1,1
1,1,1,0,54,0,0,0,0,0,0,0,0,0,54,1,1,1,1,1,1,1,1,1,1,1,1,1,1
1,1,1,0,3,18,0,0,0,0,0,0,0,18,3,1,1,1,1,1,1,1,1,1,1,1,1,1,1
1,1,1,0,2,3,54,3,54,3,54,3,54,3,2,1,1,1,1,1,1,1,1,1,1,1,1,1,1
1,1,1,0,0,0,0,0,0,0,0,0,0,0,0,1,1,1,1,1,1,1,1,1,1,1,1,1,1
1,1,1,1,1,1,1,1,1,1,1,1,1,1,1,1,1,1,1,1,1,1,1,1,1,1,1,1,1
1,1,1,1,1,1,1,1,1,1,1,1,1,1,1,1,1,1,1,1,1,1,1,1,1,1,1,1,1
1,1,1,1,1,1,1,1,1,1,1,1,1,1,1,1,1,1,1,1,1,1,1,1,1,1,1,1,1
endlayer

layer
1,1,1,1,1,1,77,45,44,44,44,45,77,1,1,1,1,1,1,1,1,1,1,1,1,1,1,1,1
1,1,1,1,1,1,77,46,60,91,60,46,77,1,1,1,1,1,1,1,1,1,1,1,1,1,1,1,1
1,1,1,1,1,1,77,46,91,60,91,46,77,1,1,1,1,1,1,1,1,1,1,1,1,1,1,1,1
1,1,1,1,1,77,77,45,45,45,45,45,77,77,1,1,1,1,1,1,1,1,1,1,1,1,1,1,1
1,1,1,1,77,77,45,80,80,80,80,80,45,77,77,1,1,1,1,1,1,1,1,1,1,1,1,0,0
1,1,1,77,77,45,80,60,60,60,60,60,80,45,77,77,0,0,0,0,0,0,0,0,0,0,0,0,0
77,77,77,77,45,80,60,60,100,60,100,60,60,80,45,77,77,77,77,0,0,0,0,0,0,0,0,0,0
45,44,44,45,80,60,60,100,60,60,60,100,60,60,80,45,44,44,45,0,0,0,0,0,0,0,0,0,0
46,60,91,45,80,60,0,60,60,60,60,60,100,60,80,45,91,60,46,0,0,0,0,0,0,0,0,0,0
46,91,60,45,80,60,0,60,100,60,100,60,100,60,80,45,60,91,46,0,0,0,0,0,0,0,0,0,0
46,60,91,45,80,60,0,60,100,60,100,60,60,60,80,45,91,60,46,0,0,0,0,0,0,0,0,0,0
45,44,44,45,80,80,52,80,60,80,60,80,80,80,80,45,44,44,45,0,0,0,0,0,0,0,0,0,0
77,77,77,77,45,45,45,45,45,45,45,45,45,45,45,77,77,77,77,0,0,0,0,0,0,0,0,0,0
1,1,1,77,77,45,81,81,81,81,81,81,81,45,77,77,0,0,0,0,0,0,0,0,0,0,0,0,0
1,1,1,1,77,45,81,36,81,36,81,36,81,45,77,1,1,1,1,1,1,1,1,1,1,1,1,1,0
1,1,1,1,77,45,81,81,36,81,36,81,81,45,77,1,1,1,1,1,1,1,1,1,1,1,1,1,1
1,1,1,1,77,45,81,36,81,36,81,36,81,45,77,1,1,1,1,1,1,1,1,1,1,1,1,1,1
1,1,1,1,77,45,81,81,36,81,36,81,81,45,77,1,1,1,1,1,1,1,1,1,1,1,1,1,1
1,1,1,1,77,45,81,36,81,36,81,36,81,45,77,1,1,1,1,1,1,1,1,1,1,1,1,1,1
1,1,1,1,77,45,81,81,81,81,81,81,81,45,77,1,1,1,1,1,1,1,1,1,1,1,1,1,1
1,1,1,1,77,45,45,45,45,45,45,45,45,45,77,1,1,1,1,1,1,1,1,1,1,1,1,1,1
1,1,1,0,77,45,44,44,44,44,44,44,44,45,77,1,1,1,1,1,1,1,1,1,1,1,1,1,1
1,1,1,0,2,3,3,3,3,3,3,3,3,3,2,1,1,1,1,1,1,1,1,1,1,1,1,1,1
1,1,1,0,3,34,0,0,0,34,0,0,0,34,3,1,1,1,1,1,1,1,1,1,1,1,1,1,1
1,1,1,0,54,0,0,0,0,0,0,0,0,0,54,1,1,1,1,1,1,1,1,1,1,1,1,1,1
1,1,1,0,3,0,0,0,0,0,0,0,0,0,3,1,1,1,1,1,1,1,1,1,1,1,1,1,1
1,1,1,0,54,0,0,0,0,0,0,0,0,0,54,1,1,1,1,1,1,1,1,1,1,1,1,1,1
1,1,1,0,3,0,0,0,0,0,0,0,0,0,3,1,1,1,1,1,1,1,1,1,1,1,1,1,1
1,1,1,0,54,0,0,0,0,0,0,0,0,0,54,1,1,1,1,1,1,1,1,1,1,1,1,1,1
1,1,1,0,3,34,0,0,0,0,0,0,0,34,3,1,1,1,1,1,1,1,1,1,1,1,1,1,1
1,1,1,0,2,3,54,3,54,3,54,3,54,3,2,1,1,1,1,1,1,1,1,1,1,1,1,1,1
1,1,1,0,0,0,0,0,0,0,0,0,0,0,0,1,1,1,1,1,1,1,1,1,1,1,1,1,1
1,1,1,1,1,1,1,1,1,1,1,1,1,1,1,1,1,1,1,1,1,1,1,1,1,1,1,1,1
1,1,1,1,1,1,1,1,1,1,1,1,1,1,1,1,1,1,1,1,1,1,1,1,1,1,1,1,1
1,1,1,1,1,1,1,1,1,1,1,1,1,1,1,1,1,1,1,1,1,1,1,1,1,1,1,1,1
endlayer

layer
1,1,1,1,1,1,0,45,44,44,44,45,1,1,1,1,1,1,1,1,1,1,1,1,1,1,1,1,1
1,1,1,1,1,1,1,46,25,101,25,46,1,1,1,1,1,1,1,1,1,1,1,1,1,1,1,1,1
1,1,1,1,1,1,1,46,1,1,1,46,1,1,1,1,1,1,1,1,1,1,1,1,1,1,1,1,1
1,1,1,1,1,1,1,45,1,1,1,45,1,1,1,1,1,1,1,1,1,1,1,1,1,1,1,1,0
1,1,1,1,1,1,45,1,1,1,1,1,45,1,1,1,1,1,1,1,1,1,1,1,1,1,0,0,0
1,1,1,1,1,45,1,0,0,0,0,0,0,45,0,0,0,0,0,0,0,0,0,0,0,0,0,0,0
1,1,1,1,45,1,1,0,0,90,0,0,0,0,45,0,0,0,0,0,0,0,0,0,0,0,0,0,0
45,44,44,45,1,1,1,0,0,91,0,0,0,0,0,45,44,44,45,0,0,0,0,0,0,0,0,0,0
46,25,0,0,0,0,0,0,0,91,0,0,0,0,0,0,0,25,46,0,0,0,0,0,0,0,0,0,0
46,26,0,0,0,0,0,0,0,91,0,0,0,0,0,0,0,15,46,0,0,0,0,0,0,0,0,0,0
46,25,0,0,0,0,0,0,0,92,0,0,0,0,0,0,0,25,46,0,0,0,0,0,0,0,0,0,0
45,44,44,45,0,0,0,0,0,0,0,0,0,0,0,45,44,44,45,0,0,0,0,0,0,0,0,0,0
1,1,1,1,45,45,0,0,0,0,0,0,0,45,45,0,0,0,0,0,0,0,0,0,0,0,0,0,0
1,1,1,1,1,46,0,0,0,0,0,0,0,46,0,0,0,0,0,0,0,0,0,0,0,0,0,0,0
1,1,1,1,1,46,0,0,0,0,0,0,0,46,1,1,1,1,1,1,1,1,1,1,1,1,1,0,0
1,1,1,1,1,46,0,0,0,0,0,0,0,46,1,1,1,1,1,1,1,1,1,1,1,1,1,1,0
1,1,1,1,1,45,0,0,0,0,0,0,0,45,1,1,1,1,1,1,1,1,1,1,1,1,1,1,1
1,1,1,1,1,46,0,0,0,0,0,0,0,46,1,1,1,1,1,1,1,1,1,1,1,1,1,1,1
1,1,1,1,1,46,0,0,0,0,0,0,0,46,1,1,1,1,1,1,1,1,1,1,1,1,1,1,1
1,1,1,1,1,46,0,0,0,0,0,0,0,46,1,1,1,1,1,1,1,1,1,1,1,1,1,1,1
1,1,1,1,1,45,0,0,0,0,0,0,0,45,1,1,1,1,1,1,1,1,1,1,1,1,1,1,1
1,1,1,0,0,45,52,52,52,52,52,52,52,45,0,1,1,1,1,1,1,1,1,1,1,1,1,1,1
1,1,1,0,2,3,3,3,3,3,3,3,3,3,2,1,1,1,1,1,1,1,1,1,1,1,1,1,1
1,1,1,0,3,0,0,0,0,0,0,0,0,0,3,1,1,1,1,1,1,1,1,1,1,1,1,1,1
1,1,1,0,3,0,0,0,0,0,0,0,0,0,3,1,1,1,1,1,1,1,1,1,1,1,1,1,1
1,1,1,0,3,0,0,0,0,0,0,0,0,0,3,1,1,1,1,1,1,1,1,1,1,1,1,1,1
1,1,1,0,3,0,0,0,0,0,0,0,0,0,3,1,1,1,1,1,1,1,1,1,1,1,1,1,1
1,1,1,0,3,0,0,0,0,0,0,0,0,0,3,1,1,1,1,1,1,1,1,1,1,1,1,1,1
1,1,1,0,3,0,0,0,0,0,0,0,0,0,3,1,1,1,1,1,1,1,1,1,1,1,1,1,1
1,1,1,0,3,0,0,0,0,0,0,0,0,0,3,1,1,1,1,1,1,1,1,1,1,1,1,1,1
1,1,1,0,2,3,3,3,3,3,3,3,3,3,2,1,1,1,1,1,1,1,1,1,1,1,1,1,1
1,1,1,0,0,0,0,0,0,0,0,0,0,0,0,1,1,1,1,1,1,1,1,1,1,1,1,1,1
1,1,1,1,1,1,1,1,1,1,1,1,1,1,1,1,1,1,1,1,1,1,1,1,1,1,1,1,1
1,1,1,1,1,1,1,1,1,1,1,1,1,1,1,1,1,1,1,1,1,1,1,1,1,1,1,1,1
1,1,1,1,1,1,1,1,1,1,1,1,1,1,1,1,1,1,1,1,1,1,1,1,1,1,1,1,1
endlayer

layer
1,1,1,1,1,0,0,45,71,54,71,45,0,0,0,1,1,1,1,1,1,1,1,1,1,1,1,1,1
1,1,1,1,1,1,0,71,1,1,1,71,0,1,1,1,1,1,1,1,1,1,1,1,1,1,1,1,1
1,1,1,1,1,1,1,71,1,1,1,71,1,1,1,1,1,1,1,1,1,1,1,1,1,1,1,1,1
1,1,1,1,1,1,1,45,1,1,1,45,1,1,1,1,1,1,1,1,1,1,1,1,1,1,1,1,0
1,1,1,1,0,73,71,1,1,1,1,1,71,72,0,1,1,1,1,1,1,1,1,1,1,0,0,0,0
1,1,1,1,70,54,1,0,0,0,0,0,0,54,70,0,0,0,0,0,0,0,0,0,0,0,0,0,0
1,1,1,1,71,1,1,0,0,0,0,0,0,0,71,0,0,0,0,0,0,0,0,0,0,0,0,0,0
45,71,71,45,1,1,1,0,0,0,0,0,0,0,0,45,71,71,45,0,0,0,0,0,0,0,0,0,0
71,0,0,0,0,0,0,0,0,34,0,0,0,0,0,0,0,0,71,72,0,0,0,0,0,0,0,0,0
54,0,0,0,0,0,0,0,0,0,0,0,0,0,0,0,0,0,54,0,0,0,0,0,0,0,0,0,0
71,0,0,0,0,0,0,0,0,0,0,0,0,0,0,0,0,0,71,72,0,0,0,0,0,0,0,0,0
45,71,71,45,0,0,0,0,0,0,0,0,0,0,0,45,71,71,45,0,0,0,0,0,0,0,0,0,0
1,1,1,1,71,45,0,0,0,0,0,0,0,45,71,0,0,0,0,0,0,0,0,0,0,0,0,0,0
1,1,1,1,73,71,0,0,0,0,0,0,0,71,72,0,0,0,0,0,0,0,0,0,0,0,0,0,0
1,1,1,1,1,54,0,0,0,0,0,0,0,54,0,1,1,1,1,1,1,1,1,1,1,1,0,0,0
1,1,1,1,73,71,0,0,0,0,0,0,0,71,72,1,1,1,1,1,1,1,1,1,1,1,1,0,0
1,1,1,1,1,45,0,0,0,0,0,0,0,45,1,1,1,1,1,1,1,1,1,1,1,1,1,1,0
1,1,1,1,73,71,0,0,0,0,0,0,0,71,72,1,1,1,1,1,1,1,1,1,1,1,1,1,1
1,1,1,1,1,54,0,0,0,0,0,0,0,54,0,1,1,1,1,1,1,1,1,1,1,1,1,1,1
1,1,1,1,73,71,0,0,0,0,0,0,0,71,72,1,1,1,1,1,1,1,1,1,1,1,1,1,1
1,1,1,1,1,45,0,0,0,0,0,0,0,45,1,1,1,1,1,1,1,1,1,1,1,1,1,1,1
1,1,1,12,40,71,0,0,0,0,0,0,0,71,40,40,1,1,1,1,1,1,1,1,1,1,1,1,1
1,1,1,12,2,3,40,40,40,40,40,40,40,3,2,13,1,1,1,1,1,1,1,1,1,1,1,1,1
1,1,1,12,3,8,8,8,4,8,4,8,8,8,3,13,1,1,1,1,1,1,1,1,1,1,1,1,1
1,1,1,12,3,8,4,4,8,4,8,4,4,8,3,13,1,1,1,1,1,1,1,1,1,1,1,1,1
1,1,1,12,3,8,4,2,4,2,4,2,4,8,3,13,1,1,1,1,1,1,1,1,1,1,1,1,1
1,1,1,12,3,4,8,4,2,2,2,4,8,4,3,13,1,1,1,1,1,1,1,1,1,1,1,1,1
1,1,1,12,3,8,4,2,4,2,4,2,4,8,3,13,1,1,1,1,1,1,1,1,1,1,1,1,1
1,1,1,12,3,8,4,4,8,4,8,4,4,8,3,13,1,1,1,1,1,1,1,1,1,1,1,1,1
1,1,1,12,3,8,8,8,4,8,4,8,8,8,3,13,1,1,1,1,1,1,1,1,1,1,1,1,1
1,1,1,12,2,3,3,3,3,3,3,3,3,3,2,13,1,1,1,1,1,1,1,1,1,1,1,1,1
1,1,1,37,37,37,37,37,37,37,37,37,37,37,37,13,1,1,1,1,1,1,1,1,1,1,1,1,1
1,1,1,1,1,1,1,1,1,1,1,1,1,1,1,1,1,1,1,1,1,1,1,1,1,1,1,1,1
1,1,1,1,1,1,1,1,1,1,1,1,1,1,1,1,1,1,1,1,1,1,1,1,1,1,1,1,1
1,1,1,1,1,1,1,1,1,1,1,1,1,1,1,1,1,1,1,1,1,1,1,1,1,1,1,1,1
endlayer

layer
1,1,1,1,0,0,0,45,71,54,71,45,0,0,0,0,1,1,1,1,1,1,1,1,1,1,1,1,1
1,1,1,1,1,0,0,71,1,1,1,71,0,0,1,1,1,1,1,1,1,1,1,1,1,1,1,1,1
1,1,1,1,1,1,0,71,1,1,1,71,0,1,1,1,1,1,1,1,1,1,1,1,1,1,1,1,1
1,1,1,1,1,1,1,45,1,1,1,45,1,1,1,1,1,1,1,1,1,1,1,1,1,1,1,0,0
1,1,1,1,0,73,71,18,1,1,1,18,71,72,0,1,1,1,1,1,1,1,1,1,0,0,0,0,0
1,1,1,1,70,54,1,0,0,0,0,0,0,54,70,0,0,0,0,0,0,0,0,0,0,0,0,0,0
1,1,1,1,71,1,1,0,0,0,0,0,0,0,71,0,0,0,0,0,0,0,0,0,0,0,0,0,0
45,71,71,45,18,1,1,0,0,0,0,0,0,0,18,45,71,71,45,0,0,0,0,0,0,0,0,0,0
71,0,0,0,0,0,0,0,0,0,0,0,0,0,0,0,0,0,71,72,0,0,0,0,0,0,0,0,0
54,0,0,0,0,0,0,0,0,0,0,0,0,0,0,0,0,0,54,0,0,0,0,0,0,0,0,0,0
71,0,0,0,0,0,0,0,0,0,0,0,0,0,0,0,0,0,71,72,0,0,0,0,0,0,0,0,0
45,71,71,45,18,0,0,0,0,0,0,0,0,0,18,45,71,71,45,0,0,0,0,0,0,0,0,0,0
1,1,1,1,71,45,0,0,0,0,0,0,0,45,71,0,0,0,0,0,0,0,0,0,0,0,0,0,0
1,1,1,1,73,71,0,0,0,0,0,0,0,71,72,0,0,0,0,0,0,0,0,0,0,0,0,0,0
1,1,1,1,1,54,0,0,0,0,0,0,0,54,0,0,1,1,1,1,1,1,1,1,0,0,0,0,0
1,1,1,1,73,71,0,0,0,0,0,0,0,71,72,1,1,1,1,1,1,1,1,1,1,1,0,0,0
1,1,1,1,1,45,0,0,0,0,0,0,0,45,1,1,1,1,1,1,1,1,1,1,1,1,1,0,0
1,1,1,1,73,71,0,0,0,0,0,0,0,71,72,1,1,1,1,1,1,1,1,1,1,1,1,1,0
1,1,1,1,1,54,0,0,0,0,0,0,0,54,0,0,1,1,1,1,1,1,1,1,1,1,1,1,0
1,1,1,1,73,71,0,0,0,0,0,0,0,71,72,1,1,1,1,1,1,1,1,1,1,1,1,1,1
1,1,1,1,1,45,0,0,0,0,0,0,0,45,1,1,1,1,1,1,1,1,1,1,1,1,1,1,1
1,1,1,0,0,71,0,0,0,0,0,0,0,71,0,1,1,1,1,1,1,1,1,1,1,1,1,1,1
1,1,1,0,2,3,0,0,0,0,0,0,0,3,2,1,1,1,1,1,1,1,1,1,1,1,1,1,1
1,1,1,0,3,18,0,0,0,0,0,0,0,18,3,1,1,1,1,1,1,1,1,1,1,1,1,1,1
1,1,1,0,3,0,0,0,0,0,0,0,0,0,3,1,1,1,1,1,1,1,1,1,1,1,1,1,1
1,1,1,0,3,0,0,0,0,0,0,0,0,0,3,1,1,1,1,1,1,1,1,1,1,1,1,1,1
1,1,1,0,3,103,0,0,0,0,0,0,0,102,3,1,1,1,1,1,1,1,1,1,1,1,1,1,1
1,1,1,0,3,0,0,0,0,0,0,0,0,0,3,1,1,1,1,1,1,1,1,1,1,1,1,1,1
1,1,1,0,3,0,0,0,0,0,0,0,0,0,3,1,1,1,1,1,1,1,1,1,1,1,1,1,1
1,1,1,0,3,18,0,0,0,104,0,0,0,18,3,1,1,1,1,1,1,1,1,1,1,1,1,1,1
1,1,1,0,2,3,3,3,3,3,3,3,3,3,2,1,1,1,1,1,1,1,1,1,1,1,1,1,1
1,1,1,0,0,0,0,0,0,0,0,0,0,0,0,1,1,1,1,1,1,1,1,1,1,1,1,1,1
1,1,1,1,1,1,1,1,1,1,1,1,1,1,1,1,1,1,1,1,1,1,1,1,1,1,1,1,1
1,1,1,1,1,1,1,1,1,1,1,1,1,1,1,1,1,1,1,1,1,1,1,1,1,1,1,1,1
1,1,1,1,1,1,1,1,1,1,1,1,1,1,1,1,1,1,1,1,1,1,1,1,1,1,1,1,1
endlayer

layer
1,1,1,0,0,0,0,45,71,54,71,45,0,0,0,0,0,0,0,0,0,0,0,1,1,1,1,1,1
1,1,0,0,0,0,0,71,0,0,0,71,0,0,0,0,0,0,0,0,0,0,0,0,0,0,1,1,1
1,1,0,0,0,0,0,71,0,0,0,71,0,0,0,0,0,0,0,0,0,0,0,0,0,0,0,0,0
1,0,0,0,0,0,0,45,0,0,0,45,0,0,0,0,0,0,0,0,0,0,0,0,0,0,0,0,0
0,0,0,0,0,73,71,34,0,0,0,34,71,72,0,0,0,0,0,0,0,0,0,0,0,0,0,0,0
0,0,0,0,70,54,0,0,0,0,0,0,0,54,70,0,0,0,0,0,0,0,0,0,0,0,0,0,0
0,0,0,0,71,0,0,0,0,0,0,0,0,0,71,0,0,0,0,0,0,0,0,0,0,0,0,0,0
45,71,71,45,34,0,0,0,0,0,0,0,0,0,34,45,71,71,45,0,0,0,0,0,0,0,0,0,0
71,0,0,0,0,0,0,0,0,0,0,0,0,0,0,0,0,0,71,72,0,0,0,0,0,0,0,0,0
54,0,0,0,0,0,0,0,0,0,0,0,0,0,0,0,0,0,54,0,0,0,0,0,0,0,0,0,0
71,0,0,0,0,0,0,0,0,0,0,0,0,0,0,0,0,0,71,72,0,0,0,0,0,0,0,0,0
45,71,71,45,34,0,0,0,0,0,0,0,0,0,34,45,71,71,45,0,0,0,0,0,0,0,0,0,0
0,0,0,0,71,45,0,0,0,0,0,0,0,45,71,0,0,0,0,0,0,0,0,0,0,0,0,0,0
0,0,0,0,73,71,0,0,0,0,0,0,0,71,72,0,0,0,0,0,0,0,0,0,0,0,0,0,0
1,0,0,0,0,54,0,0,0,0,0,0,0,54,0,0,0,0,0,0,0,0,0,0,0,0,0,0,0
1,1,0,0,73,71,0,0,0,0,0,0,0,71,72,0,0,0,0,0,0,0,0,0,0,0,0,0,0
1,1,0,0,0,45,0,0,0,0,0,0,0,45,0,0,0,0,0,0,0,0,0,0,0,0,0,0,0
1,1,0,0,73,71,0,0,0,0,0,0,0,71,72,0,0,0,0,0,0,0,0,0,0,0,0,0,0
1,1,0,0,0,54,0,0,0,0,0,0,0,54,0,0,0,0,0,0,0,0,0,0,0,0,0,0,0
1,1,0,0,73,71,0,0,0,0,0,0,0,71,72,0,0,0,0,0,0,0,0,0,0,0,0,0,0
1,1,1,0,0,45,0,0,0,0,0,0,0,45,0,0,0,0,0,0,0,0,0,0,0,0,0,0,0
1,1,1,0,0,71,0,0,0,0,0,0,0,71,0,0,0,0,0,0,0,0,0,0,0,0,0,0,0
1,1,1,0,2,3,0,0,0,0,0,0,0,3,2,0,0,0,0,0,0,0,0,0,0,0,0,0,0
1,1,1,0,3,34,0,0,0,0,0,0,0,34,3,0,0,0,0,0,0,0,0,0,0,0,0,0,0
1,1,1,0,54,0,0,0,0,0,0,0,0,0,54,0,0,0,0,0,0,0,0,0,0,0,0,0,0
1,1,1,0,3,0,0,0,0,0,0,0,0,0,3,0,0,0,0,0,0,0,0,0,0,0,0,0,0
1,1,1,0,54,0,0,0,0,0,0,0,0,0,54,0,0,0,0,0,0,0,0,0,0,0,0,0,0
1,1,1,0,3,0,0,0,0,0,0,0,0,0,3,0,0,0,0,0,0,0,0,0,0,0,0,0,0
1,1,1,0,54,0,0,0,0,0,0,0,0,0,54,0,0,0,0,0,0,0,0,0,0,0,0,0,0
1,1,1,0,3,34,0,0,0,104,0,0,0,34,3,0,0,0,0,0,0,0,0,0,0,0,0,0,1
1,1,1,0,2,3,54,3,54,3,54,3,54,3,2,0,0,0,0,0,0,0,0,0,0,0,0,1,1
1,1,0,0,0,0,0,0,0,0,0,0,0,0,0,0,0,0,0,0,0,0,0,0,0,0,1,1,1
1,0,0,0,0,0,0,0,0,0,0,0,0,0,0,0,0,0,0,0,0,0,0,0,0,1,1,1,1
1,1,0,0,0,0,0,0,0,0,0,0,0,0,0,0,0,0,0,0,0,0,0,0,1,1,1,1,1
1,1,1,0,0,0,0,0,0,0,0,0,0,0,0,0,0,0,0,0,0,0,0,1,1,1,1,1,1
endlayer

layer
1,1,0,0,0,0,0,45,44,44,44,45,0,0,0,0,0,0,0,0,0,0,0,0,0,0,1,1,1
1,0,0,0,0,0,0,46,0,0,0,46,0,0,0,0,0,0,0,0,0,0,0,0,0,0,0,0,0
1,0,0,0,0,0,0,46,0,0,0,46,0,0,0,0,0,0,0,0,0,0,0,0,0,0,0,0,0
0,0,0,0,0,0,0,45,45,45,45,45,0,0,0,0,0,0,0,0,0,0,0,0,0,0,0,0,0
0,0,0,0,0,0,45,0,0,0,0,0,45,0,0,0,0,0,0,0,0,0,0,0,0,0,0,0,0
0,0,0,0,0,45,0,0,0,0,0,0,0,45,0,0,0,0,0,0,0,0,0,0,0,0,0,0,0
0,0,0,0,45,0,0,0,0,0,0,0,0,0,45,0,0,0,0,0,0,0,0,0,0,0,0,0,0
45,44,44,45,0,0,0,0,0,0,0,0,0,0,0,45,44,44,45,0,0,0,0,0,0,0,0,0,0
46,0,0,45,0,0,0,0,0,0,0,0,0,0,0,45,0,0,46,0,0,0,0,0,0,0,0,0,0
46,0,0,45,0,0,0,0,0,0,0,0,0,0,0,45,0,0,46,0,0,0,0,0,0,0,0,0,0
46,0,0,45,0,0,0,0,0,0,0,0,0,0,0,45,0,0,46,0,0,0,0,0,0,0,0,0,0
45,44,44,45,0,0,0,0,0,0,0,0,0,0,0,45,44,44,45,0,0,0,0,0,0,0,0,0,0
0,0,0,0,45,45,44,44,44,44,44,44,44,45,45,0,0,0,0,0,0,0,0,0,0,0,0,0,0
0,0,0,0,0,46,0,0,0,0,0,0,0,46,0,0,0,0,0,0,0,0,0,0,0,0,0,0,0
0,0,0,0,0,46,0,0,0,0,0,0,0,46,0,0,0,0,0,0,0,0,0,0,0,0,0,0,0
0,0,0,0,0,46,0,0,0,0,0,0,0,46,0,0,0,0,0,0,0,0,0,0,0,0,0,0,0
0,0,0,0,0,45,44,44,44,44,44,44,44,45,0,0,0,0,0,0,0,0,0,0,0,0,0,0,0
0,0,0,0,0,46,0,0,0,0,0,0,0,46,0,0,0,0,0,0,0,0,0,0,0,0,0,0,0
0,0,0,0,0,46,0,0,0,0,0,0,0,46,0,0,0,0,0,0,0,0,0,0,0,0,0,0,0
0,0,0,0,0,46,0,0,0,0,0,0,0,46,0,0,0,0,0,0,0,0,0,0,0,0,0,0,0
0,0,0,0,0,45,44,44,44,44,44,44,44,45,0,0,0,0,0,0,0,0,0,0,0,0,0,0,0
0,0,0,0,0,46,0,0,0,0,0,0,0,46,0,0,0,0,0,0,0,0,0,0,0,0,0,0,0
0,0,0,0,2,3,0,0,0,0,0,0,0,3,2,0,0,0,0,0,0,0,0,0,0,0,0,0,0
0,0,0,0,3,0,0,0,0,0,0,0,0,0,3,0,0,0,0,0,0,0,0,0,0,0,0,0,0
0,0,0,0,54,0,0,0,0,0,0,0,0,0,54,0,0,0,0,0,0,0,0,0,0,0,0,0,0
0,0,0,0,3,0,0,0,0,0,0,0,0,0,3,0,0,0,0,0,0,0,0,0,0,0,0,0,0
0,0,0,0,54,0,0,0,0,0,0,0,0,0,54,0,0,0,0,0,0,0,0,0,0,0,0,0,0
0,0,0,0,3,0,0,0,0,0,0,0,0,0,3,0,0,0,0,0,0,0,0,0,0,0,0,0,0
0,0,0,0,54,0,0,0,0,0,0,0,0,0,54,0,0,0,0,0,0,0,0,0,0,0,0,0,0
0,0,0,0,3,0,0,0,0,104,0,0,0,0,3,0,0,0,0,0,0,0,0,0,0,0,0,0,0
0,0,0,0,2,3,54,3,54,3,54,3,54,3,2,0,0,0,0,0,0,0,0,0,0,0,0,0,1
0,0,0,0,0,0,0,0,0,0,0,0,0,0,0,0,0,0,0,0,0,0,0,0,0,0,0,1,1
0,0,0,0,0,0,0,0,0,0,0,0,0,0,0,0,0,0,0,0,0,0,0,0,0,0,1,1,1
1,0,0,0,0,0,0,0,0,0,0,0,0,0,0,0,0,0,0,0,0,0,0,0,0,1,1,1,1
1,1,0,0,0,0,0,0,0,0,0,0,0,0,0,0,0,0,0,0,0,0,0,0,1,1,1,1,1
endlayer

layer
1,0,0,0,0,0,107,106,71,54,71,106,105,0,0,0,0,0,0,0,0,0,0,0,0,0,0,1,1
1,0,0,0,0,0,107,106,0,0,0,106,105,0,0,0,0,0,0,0,0,0,0,0,0,0,0,0,0
0,0,0,0,0,0,107,106,0,0,0,106,105,0,0,0,0,0,0,0,0,0,0,0,0,0,0,0,0
0,0,0,0,0,107,108,106,106,106,106,106,105,108,0,0,0,0,0,0,0,0,0,0,0,0,0,0,0
0,0,0,0,107,108,106,0,0,0,0,0,106,105,108,0,0,0,0,0,0,0,0,0,0,0,0,0,0
0,0,0,107,108,106,0,0,0,0,0,0,0,106,105,108,0,0,0,0,0,0,0,0,0,0,0,0,0
108,108,108,108,106,0,0,0,0,0,0,0,0,0,106,105,108,108,108,0,0,0,0,0,0,0,0,0,0
106,106,106,106,0,0,0,0,0,0,0,0,0,0,0,106,106,106,106,0,0,0,0,0,0,0,0,0,0
71,0,0,106,0,0,0,0,0,0,0,0,0,0,0,106,0,0,71,72,0,0,0,0,0,0,0,0,0
54,0,0,106,0,0,0,0,0,0,0,0,0,0,0,106,0,0,54,0,0,0,0,0,0,0,0,0,0
71,0,0,106,0,0,0,0,0,0,0,0,0,0,0,106,0,0,71,72,0,0,0,0,0,0,0,0,0
106,106,106,106,0,0,0,0,0,0,0,0,0,0,0,106,106,106,106,0,0,0,0,0,0,0,0,0,0
109,109,109,107,106,106,77,77,77,77,77,77,77,106,106,105,109,109,109,0,0,0,0,0,0,0,0,0,0
0,0,0,109,107,106,0,0,0,0,0,0,0,106,105,109,0,0,0,0,0,0,0,0,0,0,0,0,0
0,0,0,0,107,106,0,0,0,0,0,0,0,106,105,0,0,0,0,0,0,0,0,0,0,0,0,0,0
0,0,0,0,107,106,0,0,0,0,0,0,0,106,105,0,0,0,0,0,0,0,0,0,0,0,0,0,0
0,0,0,0,107,106,77,77,77,77,77,77,77,106,105,0,0,0,0,0,0,0,0,0,0,0,0,0,0
0,0,0,0,107,106,0,0,0,0,0,0,0,106,105,0,0,0,0,0,0,0,0,0,0,0,0,0,0
0,0,0,0,107,106,0,0,0,0,0,0,0,106,105,0,0,0,0,0,0,0,0,0,0,0,0,0,0
0,0,0,0,107,106,0,0,0,0,0,0,0,106,105,0,0,0,0,0,0,0,0,0,0,0,0,0,0
0,0,0,0,107,106,77,77,77,77,77,77,77,106,105,0,0,0,0,0,0,0,0,0,0,0,0,0,0
0,0,0,0,107,106,0,0,0,0,0,0,0,106,105,0,0,0,0,0,0,0,0,0,0,0,0,0,0
0,0,0,0,2,3,0,0,0,0,0,0,0,3,2,0,0,0,0,0,0,0,0,0,0,0,0,0,0
0,0,0,0,3,0,0,0,0,0,0,0,0,0,3,0,0,0,0,0,0,0,0,0,0,0,0,0,0
0,0,0,0,54,0,0,0,0,0,0,0,0,0,54,0,0,0,0,0,0,0,0,0,0,0,0,0,0
0,0,0,0,3,0,0,0,0,0,0,0,0,0,3,0,0,0,0,0,0,0,0,0,0,0,0,0,0
0,0,0,0,54,0,0,0,0,0,0,0,0,0,54,0,0,0,0,0,0,0,0,0,0,0,0,0,0
0,0,0,0,3,0,0,0,0,0,0,0,0,0,3,0,0,0,0,0,0,0,0,0,0,0,0,0,0
0,0,0,0,54,0,0,0,0,0,0,0,0,0,54,0,0,0,0,0,0,0,0,0,0,0,0,0,0
0,0,0,0,3,0,0,0,0,104,0,0,0,0,3,0,0,0,0,0,0,0,0,0,0,0,0,0,0
0,0,0,0,2,3,54,3,54,3,54,3,54,3,2,0,0,0,0,0,0,0,0,0,0,0,0,0,0
0,0,0,0,0,0,0,0,0,0,0,0,0,0,0,0,0,0,0,0,0,0,0,0,0,0,0,0,0
0,0,0,0,0,0,0,0,0,0,0,0,0,0,0,0,0,0,0,0,0,0,0,0,0,0,0,0,1
0,0,0,0,0,0,0,0,0,0,0,0,0,0,0,0,0,0,0,0,0,0,0,0,0,0,0,1,1
1,0,0,0,0,0,0,0,0,0,0,0,0,0,0,0,0,0,0,0,0,0,0,0,0,0,1,1,1
endlayer

layer
1,0,0,0,0,0,0,107,106,71,106,105,0,0,0,0,0,0,0,0,0,0,0,0,0,0,0,0,1
0,0,0,0,0,0,0,107,98,0,97,105,0,0,0,0,0,0,0,0,0,0,0,0,0,0,0,0,0
0,0,0,0,0,0,0,107,98,0,97,105,0,0,0,0,0,0,0,0,0,0,0,0,0,0,0,0,0
0,0,0,0,0,0,0,106,0,0,0,106,0,0,0,0,0,0,0,0,0,0,0,0,0,0,0,0,0
0,0,0,0,0,0,106,0,0,0,0,0,106,0,0,0,0,0,0,0,0,0,0,0,0,0,0,0,0
0,0,0,0,0,106,0,0,0,0,0,0,0,106,0,0,0,0,0,0,0,0,0,0,0,0,0,0,0
0,0,0,0,106,0,0,0,0,0,0,0,0,0,106,0,0,0,0,0,0,0,0,0,0,0,0,0,0
108,108,108,106,0,0,0,0,0,0,0,0,0,0,0,106,108,108,108,0,0,0,0,0,0,0,0,0,0
106,92,92,0,0,0,0,0,0,0,0,0,0,0,0,0,92,92,106,0,0,0,0,0,0,0,0,0,0
71,0,0,0,0,0,0,0,0,0,0,0,0,0,0,0,0,0,71,0,0,0,0,0,0,0,0,0,0
106,90,90,0,0,0,0,0,0,0,0,0,0,0,0,0,90,90,106,0,0,0,0,0,0,0,0,0,0
109,109,109,106,0,0,0,0,0,0,0,0,0,0,0,106,109,109,109,0,0,0,0,0,0,0,0,0,0
0,0,0,0,106,106,0,0,0,0,0,0,0,106,106,0,0,0,0,0,0,0,0,0,0,0,0,0,0
0,0,0,0,0,106,0,0,0,0,0,0,0,106,0,0,0,0,0,0,0,0,0,0,0,0,0,0,0
0,0,0,0,0,106,0,0,0,0,0,0,0,106,0,0,0,0,0,0,0,0,0,0,0,0,0,0,0
0,0,0,0,0,106,0,0,0,0,0,0,0,106,0,0,0,0,0,0,0,0,0,0,0,0,0,0,0
0,0,0,0,0,106,0,0,0,0,0,0,0,106,0,0,0,0,0,0,0,0,0,0,0,0,0,0,0
0,0,0,0,0,106,0,0,0,0,0,0,0,106,0,0,0,0,0,0,0,0,0,0,0,0,0,0,0
0,0,0,0,0,106,0,0,0,0,0,0,0,106,0,0,0,0,0,0,0,0,0,0,0,0,0,0,0
0,0,0,0,0,106,0,0,0,0,0,0,0,106,0,0,0,0,0,0,0,0,0,0,0,0,0,0,0
0,0,0,0,0,106,0,0,0,0,0,0,0,106,0,0,0,0,0,0,0,0,0,0,0,0,0,0,0
0,0,0,0,0,106,0,0,0,0,0,0,0,106,0,0,0,0,0,0,0,0,0,0,0,0,0,0,0
0,0,0,0,2,3,0,0,0,0,0,0,0,3,2,0,0,0,0,0,0,0,0,0,0,0,0,0,0
0,0,0,0,3,0,0,0,0,0,0,0,0,0,3,0,0,0,0,0,0,0,0,0,0,0,0,0,0
0,0,0,0,54,0,0,0,0,0,0,0,0,0,54,0,0,0,0,0,0,0,0,0,0,0,0,0,0
0,0,0,0,3,0,0,0,0,0,0,0,0,0,3,0,0,0,0,0,0,0,0,0,0,0,0,0,0
0,0,0,0,54,0,0,0,0,0,0,0,0,0,54,0,0,0,0,0,0,0,0,0,0,0,0,0,0
0,0,0,0,3,0,0,0,0,0,0,0,0,0,3,0,0,0,0,0,0,0,0,0,0,0,0,0,0
0,0,0,0,54,0,0,0,0,0,0,0,0,0,54,0,0,0,0,0,0,0,0,0,0,0,0,0,0
0,0,0,0,3,0,0,0,0,104,0,0,0,0,3,0,0,0,0,0,0,0,0,0,0,0,0,0,0
0,0,0,0,2,3,54,3,54,3,54,3,54,3,2,0,0,0,0,0,0,0,0,0,0,0,0,0,0
0,0,0,0,0,0,0,0,0,0,0,0,0,0,0,0,0,0,0,0,0,0,0,0,0,0,0,0,0
0,0,0,0,0,0,0,0,0,0,0,0,0,0,0,0,0,0,0,0,0,0,0,0,0,0,0,0,0
0,0,0,0,0,0,0,0,0,0,0,0,0,0,0,0,0,0,0,0,0,0,0,0,0,0,0,0,1
0,0,0,0,0,0,0,0,0,0,0,0,0,0,0,0,0,0,0,0,0,0,0,0,0,0,0,1,1
endlayer

layer
0,0,0,0,0,0,0,0,107,106,105,0,0,0,0,0,0,0,0,0,0,0,0,0,0,0,0,0,0
0,0,0,0,0,0,0,0,107,91,105,0,0,0,0,0,0,0,0,0,0,0,0,0,0,0,0,0,0
0,0,0,0,0,0,0,0,107,91,105,0,0,0,0,0,0,0,0,0,0,0,0,0,0,0,0,0,0
0,0,0,0,0,0,0,107,108,91,105,108,0,0,0,0,0,0,0,0,0,0,0,0,0,0,0,0,0
0,0,0,0,0,0,107,108,106,106,106,105,108,0,0,0,0,0,0,0,0,0,0,0,0,0,0,0,0
0,0,0,0,0,107,108,106,0,0,0,106,105,108,0,0,0,0,0,0,0,0,0,0,0,0,0,0,0
0,0,0,0,107,108,106,0,0,0,0,0,106,105,108,0,0,0,0,0,0,0,0,0,0,0,0,0,0
0,0,0,107,108,106,0,0,0,0,0,0,0,106,105,108,0,0,0,0,0,0,0,0,0,0,0,0,0
108,108,108,108,106,0,0,0,0,0,0,0,0,0,106,105,108,108,108,0,0,0,0,0,0,0,0,0,0
106,91,91,91,106,0,0,0,0,0,0,0,0,0,106,91,91,91,106,0,0,0,0,0,0,0,0,0,0
109,109,109,109,106,0,0,0,0,0,0,0,0,0,106,105,109,109,109,0,0,0,0,0,0,0,0,0,0
0,0,0,107,109,106,0,0,0,0,0,0,0,106,109,105,0,0,0,0,0,0,0,0,0,0,0,0,0
0,0,0,0,107,109,106,0,0,0,0,0,106,109,105,0,0,0,0,0,0,0,0,0,0,0,0,0,0
0,0,0,0,0,107,98,0,0,0,0,0,97,105,0,0,0,0,0,0,0,0,0,0,0,0,0,0,0
0,0,0,0,0,107,98,0,0,0,0,0,97,105,0,0,0,0,0,0,0,0,0,0,0,0,0,0,0
0,0,0,0,0,107,98,0,0,0,0,0,97,105,0,0,0,0,0,0,0,0,0,0,0,0,0,0,0
0,0,0,0,0,107,98,0,0,0,0,0,97,105,0,0,0,0,0,0,0,0,0,0,0,0,0,0,0
0,0,0,0,0,107,98,0,0,0,0,0,97,105,0,0,0,0,0,0,0,0,0,0,0,0,0,0,0
0,0,0,0,0,107,98,0,0,0,0,0,97,105,0,0,0,0,0,0,0,0,0,0,0,0,0,0,0
0,0,0,0,0,107,98,0,0,0,0,0,97,105,0,0,0,0,0,0,0,0,0,0,0,0,0,0,0
0,0,0,0,0,107,98,0,0,0,0,0,97,105,0,0,0,0,0,0,0,0,0,0,0,0,0,0,0
0,0,0,0,0,107,98,0,0,0,0,0,97,105,0,0,0,0,0,0,0,0,0,0,0,0,0,0,0
0,0,0,0,2,3,3,3,3,3,3,3,3,3,2,0,0,0,0,0,0,0,0,0,0,0,0,0,0
0,0,0,0,3,0,0,0,0,0,0,0,0,0,3,0,0,0,0,0,0,0,0,0,0,0,0,0,0
0,0,0,0,3,0,0,0,0,0,0,0,0,0,3,0,0,0,0,0,0,0,0,0,0,0,0,0,0
0,0,0,0,3,0,0,0,0,0,0,0,0,0,3,0,0,0,0,0,0,0,0,0,0,0,0,0,0
0,0,0,0,3,0,0,0,0,0,0,0,0,0,3,0,0,0,0,0,0,0,0,0,0,0,0,0,0
0,0,0,0,3,0,0,0,0,0,0,0,0,0,3,0,0,0,0,0,0,0,0,0,0,0,0,0,0
0,0,0,0,3,0,0,0,0,0,0,0,0,0,3,0,0,0,0,0,0,0,0,0,0,0,0,0,0
0,0,0,0,3,0,0,0,0,104,0,0,0,0,3,0,0,0,0,0,0,0,0,0,0,0,0,0,0
0,0,0,0,2,3,3,3,3,3,3,3,3,3,2,0,0,0,0,0,0,0,0,0,0,0,0,0,0
0,0,0,0,0,0,0,0,0,0,0,0,0,0,0,0,0,0,0,0,0,0,0,0,0,0,0,0,0
0,0,0,0,0,0,0,0,0,0,0,0,0,0,0,0,0,0,0,0,0,0,0,0,0,0,0,0,0
0,0,0,0,0,0,0,0,0,0,0,0,0,0,0,0,0,0,0,0,0,0,0,0,0,0,0,0,0
0,0,0,0,0,0,0,0,0,0,0,0,0,0,0,0,0,0,0,0,0,0,0,0,0,0,0,0,1
endlayer

layer
0,0,0,0,0,0,0,0,0,110,0,0,0,0,0,0,0,0,0,0,0,0,0,0,0,0,0,0,0
0,0,0,0,0,0,0,0,0,110,0,0,0,0,0,0,0,0,0,0,0,0,0,0,0,0,0,0,0
0,0,0,0,0,0,0,0,0,110,0,0,0,0,0,0,0,0,0,0,0,0,0,0,0,0,0,0,0
0,0,0,0,0,0,0,0,0,110,0,0,0,0,0,0,0,0,0,0,0,0,0,0,0,0,0,0,0
0,0,0,0,0,0,0,0,106,106,106,0,0,0,0,0,0,0,0,0,0,0,0,0,0,0,0,0,0
0,0,0,0,0,0,0,106,106,0,106,106,0,0,0,0,0,0,0,0,0,0,0,0,0,0,0,0,0
0,0,0,0,0,0,106,106,0,0,0,106,106,0,0,0,0,0,0,0,0,0,0,0,0,0,0,0,0
0,0,0,0,0,106,106,0,0,0,0,0,106,106,0,0,0,0,0,0,0,0,0,0,0,0,0,0,0
0,0,0,0,106,106,0,0,0,0,0,0,0,106,106,0,0,0,0,0,0,0,0,0,0,0,0,0,0
110,110,110,110,106,0,0,0,0,0,0,0,0,0,106,110,110,110,110,0,0,0,0,0,0,0,0,0,0
0,0,0,0,106,106,0,0,0,0,0,0,0,106,106,0,0,0,0,0,0,0,0,0,0,0,0,0,0
0,0,0,0,0,106,106,106,0,0,0,106,106,106,0,0,0,0,0,0,0,0,0,0,0,0,0,0,0
0,0,0,0,0,0,109,106,0,111,0,106,109,0,0,0,0,0,0,0,0,0,0,0,0,0,0,0,0
0,0,0,0,0,0,107,98,0,0,0,97,105,0,0,0,0,0,0,0,0,0,0,0,0,0,0,0,0
0,0,0,0,0,0,107,98,0,0,0,97,105,0,0,0,0,0,0,0,0,0,0,0,0,0,0,0,0
0,0,0,0,0,0,107,98,0,0,0,97,105,0,0,0,0,0,0,0,0,0,0,0,0,0,0,0,0
0,0,0,0,0,0,107,98,0,111,0,97,105,0,0,0,0,0,0,0,0,0,0,0,0,0,0,0,0
0,0,0,0,0,0,107,98,0,0,0,97,105,0,0,0,0,0,0,0,0,0,0,0,0,0,0,0,0
0,0,0,0,0,0,107,98,0,0,0,97,105,0,0,0,0,0,0,0,0,0,0,0,0,0,0,0,0
0,0,0,0,0,0,107,98,0,0,0,97,105,0,0,0,0,0,0,0,0,0,0,0,0,0,0,0,0
0,0,0,0,0,0,107,98,0,111,0,97,105,0,0,0,0,0,0,0,0,0,0,0,0,0,0,0,0
0,0,0,0,33,0,107,98,0,0,0,97,105,0,33,0,0,0,0,0,0,0,0,0,0,0,0,0,0
0,0,0,14,2,3,3,3,3,3,3,3,3,3,2,11,0,0,0,0,0,0,0,0,0,0,0,0,0
0,0,0,0,3,0,0,41,0,0,0,41,0,0,3,0,0,0,0,0,0,0,0,0,0,0,0,0,0
0,0,0,14,3,0,0,0,0,0,0,0,0,0,3,11,0,0,0,0,0,0,0,0,0,0,0,0,0
0,0,0,0,3,11,0,0,0,0,0,0,0,14,3,0,0,0,0,0,0,0,0,0,0,0,0,0,0
0,0,0,14,3,0,0,0,0,0,0,0,0,0,3,11,0,0,0,0,0,0,0,0,0,0,0,0,0
0,0,0,0,3,11,0,0,0,0,0,0,0,14,3,0,0,0,0,0,0,0,0,0,0,0,0,0,0
0,0,0,14,3,0,0,0,0,0,0,0,0,0,3,11,0,0,0,0,0,0,0,0,0,0,0,0,0
0,0,0,0,3,0,0,33,0,104,0,33,0,0,3,0,0,0,0,0,0,0,0,0,0,0,0,0,0
0,0,0,14,2,3,3,3,3,3,3,3,3,3,2,11,0,0,0,0,0,0,0,0,0,0,0,0,0
0,0,0,0,41,0,41,0,41,0,41,0,41,0,41,0,0,0,0,0,0,0,0,0,0,0,0,0,0
0,0,0,0,0,0,0,0,0,0,0,0,0,0,0,0,0,0,0,0,0,0,0,0,0,0,0,0,0
0,0,0,0,0,0,0,0,0,0,0,0,0,0,0,0,0,0,0,0,0,0,0,0,0,0,0,0,0
0,0,0,0,0,0,0,0,0,0,0,0,0,0,0,0,0,0,0,0,0,0,0,0,0,0,0,0,0
endlayer

layer
0,0,0,0,0,0,0,0,0,0,0,0,0,0,0,0,0,0,0,0,0,0,0,0,0,0,0,0,0
0,0,0,0,0,0,0,0,0,0,0,0,0,0,0,0,0,0,0,0,0,0,0,0,0,0,0,0,0
0,0,0,0,0,0,0,0,0,0,0,0,0,0,0,0,0,0,0,0,0,0,0,0,0,0,0,0,0
0,0,0,0,0,0,0,0,0,0,0,0,0,0,0,0,0,0,0,0,0,0,0,0,0,0,0,0,0
0,0,0,0,0,0,0,0,107,108,108,0,0,0,0,0,0,0,0,0,0,0,0,0,0,0,0,0,0
0,0,0,0,0,0,0,107,108,106,105,108,0,0,0,0,0,0,0,0,0,0,0,0,0,0,0,0,0
0,0,0,0,0,0,107,108,106,106,106,105,108,0,0,0,0,0,0,0,0,0,0,0,0,0,0,0,0
0,0,0,0,0,107,108,106,106,0,106,106,105,108,0,0,0,0,0,0,0,0,0,0,0,0,0,0,0
0,0,0,0,107,108,106,106,0,0,0,106,106,105,108,0,0,0,0,0,0,0,0,0,0,0,0,0,0
0,0,0,0,107,106,106,0,0,0,0,0,106,106,105,0,0,0,0,0,0,0,0,0,0,0,0,0,0
0,0,0,0,109,107,106,106,106,0,106,106,106,109,105,0,0,0,0,0,0,0,0,0,0,0,0,0,0
0,0,0,0,0,109,109,107,106,0,106,109,109,105,0,0,0,0,0,0,0,0,0,0,0,0,0,0,0
0,0,0,0,0,0,0,107,106,91,106,105,0,0,0,0,0,0,0,0,0,0,0,0,0,0,0,0,0
0,0,0,0,0,0,0,107,98,91,97,105,0,0,0,0,0,0,0,0,0,0,0,0,0,0,0,0,0
0,0,0,0,0,0,0,107,98,91,97,105,0,0,0,0,0,0,0,0,0,0,0,0,0,0,0,0,0
0,0,0,0,0,0,0,107,98,91,97,105,0,0,0,0,0,0,0,0,0,0,0,0,0,0,0,0,0
0,0,0,0,0,0,0,107,98,91,97,105,0,0,0,0,0,0,0,0,0,0,0,0,0,0,0,0,0
0,0,0,0,0,0,0,107,98,91,97,105,0,0,0,0,0,0,0,0,0,0,0,0,0,0,0,0,0
0,0,0,0,0,0,0,107,98,91,97,105,0,0,0,0,0,0,0,0,0,0,0,0,0,0,0,0,0
0,0,0,0,0,0,0,107,98,91,97,105,0,0,0,0,0,0,0,0,0,0,0,0,0,0,0,0,0
0,0,0,0,0,0,0,107,98,91,97,105,0,0,0,0,0,0,0,0,0,0,0,0,0,0,0,0,0
0,0,0,2,2,2,2,2,2,2,2,2,2,2,2,2,0,0,0,0,0,0,0,0,0,0,0,0,0
0,0,0,2,8,8,8,8,8,8,8,8,8,8,8,2,0,0,0,0,0,0,0,0,0,0,0,0,0
0,0,0,2,8,4,4,4,8,4,8,4,4,4,8,2,0,0,0,0,0,0,0,0,0,0,0,0,0
0,0,0,2,8,8,8,8,8,4,8,8,8,8,8,2,0,0,0,0,0,0,0,0,0,0,0,0,0
0,0,0,2,8,4,4,4,8,4,8,4,4,4,8,2,0,0,0,0,0,0,0,0,0,0,0,0,0
0,0,0,2,8,8,8,8,8,8,8,8,8,8,8,2,0,0,0,0,0,0,0,0,0,0,0,0,0
0,0,0,2,8,4,4,4,8,4,8,4,4,4,8,2,0,0,0,0,0,0,0,0,0,0,0,0,0
0,0,0,2,8,8,8,8,8,4,8,8,8,8,8,2,0,0,0,0,0,0,0,0,0,0,0,0,0
0,0,0,2,8,4,4,4,8,104,8,4,4,4,8,2,0,0,0,0,0,0,0,0,0,0,0,0,0
0,0,0,2,8,8,8,8,8,8,8,8,8,8,8,2,0,0,0,0,0,0,0,0,0,0,0,0,0
0,0,0,2,2,2,2,2,2,2,2,2,2,2,2,2,0,0,0,0,0,0,0,0,0,0,0,0,0
0,0,0,0,0,0,0,0,0,0,0,0,0,0,0,0,0,0,0,0,0,0,0,0,0,0,0,0,0
0,0,0,0,0,0,0,0,0,0,0,0,0,0,0,0,0,0,0,0,0,0,0,0,0,0,0,0,0
0,0,0,0,0,0,0,0,0,0,0,0,0,0,0,0,0,0,0,0,0,0,0,0,0,0,0,0,0
endlayer

layer
0,0,0,0,0,0,0,0,0,0,0,0,0,0,0,0,0,0,0,0,0,0,0,0,0,0,0,0,0
0,0,0,0,0,0,0,0,0,0,0,0,0,0,0,0,0,0,0,0,0,0,0,0,0,0,0,0,0
0,0,0,0,0,0,0,0,0,0,0,0,0,0,0,0,0,0,0,0,0,0,0,0,0,0,0,0,0
0,0,0,0,0,0,0,0,0,0,0,0,0,0,0,0,0,0,0,0,0,0,0,0,0,0,0,0,0
0,0,0,0,0,0,0,0,0,0,0,0,0,0,0,0,0,0,0,0,0,0,0,0,0,0,0,0,0
0,0,0,0,0,0,0,0,0,108,0,0,0,0,0,0,0,0,0,0,0,0,0,0,0,0,0,0,0
0,0,0,0,0,0,0,0,107,106,105,0,0,0,0,0,0,0,0,0,0,0,0,0,0,0,0,0,0
0,0,0,0,0,0,0,107,108,106,105,108,0,0,0,0,0,0,0,0,0,0,0,0,0,0,0,0,0
0,0,0,0,0,0,108,108,106,0,106,105,108,0,0,0,0,0,0,0,0,0,0,0,0,0,0,0,0
0,0,0,0,0,107,106,106,106,0,106,106,106,105,0,0,0,0,0,0,0,0,0,0,0,0,0,0,0
0,0,0,0,0,0,109,109,106,106,106,109,109,0,0,0,0,0,0,0,0,0,0,0,0,0,0,0,0
0,0,0,0,0,0,0,0,109,109,109,0,0,0,0,0,0,0,0,0,0,0,0,0,0,0,0,0,0
0,0,0,0,0,0,0,0,110,110,110,0,0,0,0,0,0,0,0,0,0,0,0,0,0,0,0,0,0
0,0,0,0,0,0,0,0,110,110,110,0,0,0,0,0,0,0,0,0,0,0,0,0,0,0,0,0,0
0,0,0,0,0,0,0,0,110,110,110,0,0,0,0,0,0,0,0,0,0,0,0,0,0,0,0,0,0
0,0,0,0,0,0,0,0,110,110,110,0,0,0,0,0,0,0,0,0,0,0,0,0,0,0,0,0,0
0,0,0,0,0,0,0,0,110,110,110,0,0,0,0,0,0,0,0,0,0,0,0,0,0,0,0,0,0
0,0,0,0,0,0,0,0,110,110,110,0,0,0,0,0,0,0,0,0,0,0,0,0,0,0,0,0,0
0,0,0,0,0,0,0,0,110,110,110,0,0,0,0,0,0,0,0,0,0,0,0,0,0,0,0,0,0
0,0,0,0,0,0,0,0,110,110,110,0,0,0,0,0,0,0,0,0,0,0,0,0,0,0,0,0,0
0,0,0,0,0,0,0,0,110,110,110,0,0,0,0,0,0,0,0,0,0,0,0,0,0,0,0,0,0
0,0,0,2,13,12,13,12,13,2,12,13,12,13,12,2,0,0,0,0,0,0,0,0,0,0,0,0,0
0,0,0,37,25,0,0,0,0,0,0,0,0,0,25,37,0,0,0,0,0,0,0,0,0,0,0,0,0
0,0,0,40,0,0,0,0,0,0,0,0,0,0,0,40,0,0,0,0,0,0,0,0,0,0,0,0,0
0,0,0,37,0,0,0,0,0,0,0,0,0,0,0,37,0,0,0,0,0,0,0,0,0,0,0,0,0
0,0,0,40,0,0,0,0,0,0,0,0,0,0,0,40,0,0,0,0,0,0,0,0,0,0,0,0,0
0,0,0,112,0,0,0,0,0,27,0,0,0,0,0,112,0,0,0,0,0,0,0,0,0,0,0,0,0
0,0,0,37,0,0,0,0,0,0,0,0,0,0,0,37,0,0,0,0,0,0,0,0,0,0,0,0,0
0,0,0,40,0,0,0,0,0,0,0,0,0,0,0,40,0,0,0,0,0,0,0,0,0,0,0,0,0
0,0,0,37,0,0,0,0,0,0,0,0,0,0,0,37,0,0,0,0,0,0,0,0,0,0,0,0,0
0,0,0,40,25,0,0,0,0,0,0,0,0,0,25,40,0,0,0,0,0,0,0,0,0,0,0,0,0
0,0,0,2,13,12,13,12,13,2,12,13,12,13,12,2,0,0,0,0,0,0,0,0,0,0,0,0,0
0,0,0,0,0,0,0,0,0,0,0,0,0,0,0,0,0,0,0,0,0,0,0,0,0,0,0,0,0
0,0,0,0,0,0,0,0,0,0,0,0,0,0,0,0,0,0,0,0,0,0,0,0,0,0,0,0,0
0,0,0,0,0,0,0,0,0,0,0,0,0,0,0,0,0,0,0,0,0,0,0,0,0,0,0,0,0
endlayer

layer
0,0,0,0,0,0,0,0,0,0,0,0,0,0,0,0,0,0,0,0,0,0,0,0,0,0,0,0,0
0,0,0,0,0,0,0,0,0,0,0,0,0,0,0,0,0,0,0,0,0,0,0,0,0,0,0,0,0
0,0,0,0,0,0,0,0,0,0,0,0,0,0,0,0,0,0,0,0,0,0,0,0,0,0,0,0,0
0,0,0,0,0,0,0,0,0,0,0,0,0,0,0,0,0,0,0,0,0,0,0,0,0,0,0,0,0
0,0,0,0,0,0,0,0,0,0,0,0,0,0,0,0,0,0,0,0,0,0,0,0,0,0,0,0,0
0,0,0,0,0,0,0,0,0,0,0,0,0,0,0,0,0,0,0,0,0,0,0,0,0,0,0,0,0
0,0,0,0,0,0,0,0,0,0,0,0,0,0,0,0,0,0,0,0,0,0,0,0,0,0,0,0,0
0,0,0,0,0,0,0,0,0,108,0,0,0,0,0,0,0,0,0,0,0,0,0,0,0,0,0,0,0
0,0,0,0,0,0,0,0,106,106,106,0,0,0,0,0,0,0,0,0,0,0,0,0,0,0,0,0,0
0,0,0,0,0,0,0,107,106,0,106,105,0,0,0,0,0,0,0,0,0,0,0,0,0,0,0,0,0
0,0,0,0,0,0,0,0,106,106,106,0,0,0,0,0,0,0,0,0,0,0,0,0,0,0,0,0,0
0,0,0,0,0,0,0,0,0,0,0,0,0,0,0,0,0,0,0,0,0,0,0,0,0,0,0,0,0
0,0,0,0,0,0,0,0,0,0,0,0,0,0,0,0,0,0,0,0,0,0,0,0,0,0,0,0,0
0,0,0,0,0,0,0,0,0,0,0,0,0,0,0,0,0,0,0,0,0,0,0,0,0,0,0,0,0
0,0,0,0,0,0,0,0,0,0,0,0,0,0,0,0,0,0,0,0,0,0,0,0,0,0,0,0,0
0,0,0,0,0,0,0,0,0,0,0,0,0,0,0,0,0,0,0,0,0,0,0,0,0,0,0,0,0
0,0,0,0,0,0,0,0,0,0,0,0,0,0,0,0,0,0,0,0,0,0,0,0,0,0,0,0,0
0,0,0,0,0,0,0,0,0,0,0,0,0,0,0,0,0,0,0,0,0,0,0,0,0,0,0,0,0
0,0,0,0,0,0,0,0,0,0,0,0,0,0,0,0,0,0,0,0,0,0,0,0,0,0,0,0,0
0,0,0,0,0,0,0,0,0,0,0,0,0,0,0,0,0,0,0,0,0,0,0,0,0,0,0,0,0
0,0,0,0,0,0,0,0,0,0,0,0,0,0,0,0,0,0,0,0,0,0,0,0,0,0,0,0,0
0,0,0,0,0,0,0,0,0,0,0,0,0,0,0,0,0,0,0,0,0,0,0,0,0,0,0,0,0
0,0,0,0,0,0,0,0,0,0,0,0,0,0,0,0,0,0,0,0,0,0,0,0,0,0,0,0,0
0,0,0,0,0,0,0,0,0,0,0,0,0,0,0,0,0,0,0,0,0,0,0,0,0,0,0,0,0
0,0,0,0,0,0,0,0,0,0,0,0,0,0,0,0,0,0,0,0,0,0,0,0,0,0,0,0,0
0,0,0,0,0,0,0,0,0,0,0,0,0,0,0,0,0,0,0,0,0,0,0,0,0,0,0,0,0
0,0,0,0,0,0,0,0,0,0,0,0,0,0,0,0,0,0,0,0,0,0,0,0,0,0,0,0,0
0,0,0,0,0,0,0,0,0,0,0,0,0,0,0,0,0,0,0,0,0,0,0,0,0,0,0,0,0
0,0,0,0,0,0,0,0,0,0,0,0,0,0,0,0,0,0,0,0,0,0,0,0,0,0,0,0,0
0,0,0,0,0,0,0,0,0,0,0,0,0,0,0,0,0,0,0,0,0,0,0,0,0,0,0,0,0
0,0,0,0,0,0,0,0,0,0,0,0,0,0,0,0,0,0,0,0,0,0,0,0,0,0,0,0,0
0,0,0,0,0,0,0,0,0,0,0,0,0,0,0,0,0,0,0,0,0,0,0,0,0,0,0,0,0
0,0,0,0,0,0,0,0,0,0,0,0,0,0,0,0,0,0,0,0,0,0,0,0,0,0,0,0,0
0,0,0,0,0,0,0,0,0,0,0,0,0,0,0,0,0,0,0,0,0,0,0,0,0,0,0,0,0
0,0,0,0,0,0,0,0,0,0,0,0,0,0,0,0,0,0,0,0,0,0,0,0,0,0,0,0,0
endlayer

layer
0,0,0,0,0,0,0,0,0,0,0,0,0,0,0,0,0,0,0,0,0,0,0,0,0,0,0,0,0
0,0,0,0,0,0,0,0,0,0,0,0,0,0,0,0,0,0,0,0,0,0,0,0,0,0,0,0,0
0,0,0,0,0,0,0,0,0,0,0,0,0,0,0,0,0,0,0,0,0,0,0,0,0,0,0,0,0
0,0,0,0,0,0,0,0,0,0,0,0,0,0,0,0,0,0,0,0,0,0,0,0,0,0,0,0,0
0,0,0,0,0,0,0,0,0,0,0,0,0,0,0,0,0,0,0,0,0,0,0,0,0,0,0,0,0
0,0,0,0,0,0,0,0,0,0,0,0,0,0,0,0,0,0,0,0,0,0,0,0,0,0,0,0,0
0,0,0,0,0,0,0,0,0,0,0,0,0,0,0,0,0,0,0,0,0,0,0,0,0,0,0,0,0
0,0,0,0,0,0,0,0,0,0,0,0,0,0,0,0,0,0,0,0,0,0,0,0,0,0,0,0,0
0,0,0,0,0,0,0,0,108,108,108,0,0,0,0,0,0,0,0,0,0,0,0,0,0,0,0,0,0
0,0,0,0,0,0,0,0,107,106,105,0,0,0,0,0,0,0,0,0,0,0,0,0,0,0,0,0,0
0,0,0,0,0,0,0,0,109,109,109,0,0,0,0,0,0,0,0,0,0,0,0,0,0,0,0,0,0
0,0,0,0,0,0,0,0,0,0,0,0,0,0,0,0,0,0,0,0,0,0,0,0,0,0,0,0,0
0,0,0,0,0,0,0,0,0,0,0,0,0,0,0,0,0,0,0,0,0,0,0,0,0,0,0,0,0
0,0,0,0,0,0,0,0,0,0,0,0,0,0,0,0,0,0,0,0,0,0,0,0,0,0,0,0,0
0,0,0,0,0,0,0,0,0,0,0,0,0,0,0,0,0,0,0,0,0,0,0,0,0,0,0,0,0
0,0,0,0,0,0,0,0,0,0,0,0,0,0,0,0,0,0,0,0,0,0,0,0,0,0,0,0,0
0,0,0,0,0,0,0,0,0,0,0,0,0,0,0,0,0,0,0,0,0,0,0,0,0,0,0,0,0
0,0,0,0,0,0,0,0,0,0,0,0,0,0,0,0,0,0,0,0,0,0,0,0,0,0,0,0,0
0,0,0,0,0,0,0,0,0,0,0,0,0,0,0,0,0,0,0,0,0,0,0,0,0,0,0,0,0
0,0,0,0,0,0,0,0,0,0,0,0,0,0,0,0,0,0,0,0,0,0,0,0,0,0,0,0,0
0,0,0,0,0,0,0,0,0,0,0,0,0,0,0,0,0,0,0,0,0,0,0,0,0,0,0,0,0
0,0,0,0,0,0,0,0,0,0,0,0,0,0,0,0,0,0,0,0,0,0,0,0,0,0,0,0,0
0,0,0,0,0,0,0,0,0,0,0,0,0,0,0,0,0,0,0,0,0,0,0,0,0,0,0,0,0
0,0,0,0,0,0,0,0,0,0,0,0,0,0,0,0,0,0,0,0,0,0,0,0,0,0,0,0,0
0,0,0,0,0,0,0,0,0,0,0,0,0,0,0,0,0,0,0,0,0,0,0,0,0,0,0,0,0
0,0,0,0,0,0,0,0,0,0,0,0,0,0,0,0,0,0,0,0,0,0,0,0,0,0,0,0,0
0,0,0,0,0,0,0,0,0,0,0,0,0,0,0,0,0,0,0,0,0,0,0,0,0,0,0,0,0
0,0,0,0,0,0,0,0,0,0,0,0,0,0,0,0,0,0,0,0,0,0,0,0,0,0,0,0,0
0,0,0,0,0,0,0,0,0,0,0,0,0,0,0,0,0,0,0,0,0,0,0,0,0,0,0,0,0
0,0,0,0,0,0,0,0,0,0,0,0,0,0,0,0,0,0,0,0,0,0,0,0,0,0,0,0,0
0,0,0,0,0,0,0,0,0,0,0,0,0,0,0,0,0,0,0,0,0,0,0,0,0,0,0,0,0
0,0,0,0,0,0,0,0,0,0,0,0,0,0,0,0,0,0,0,0,0,0,0,0,0,0,0,0,0
0,0,0,0,0,0,0,0,0,0,0,0,0,0,0,0,0,0,0,0,0,0,0,0,0,0,0,0,0
0,0,0,0,0,0,0,0,0,0,0,0,0,0,0,0,0,0,0,0,0,0,0,0,0,0,0,0,0
0,0,0,0,0,0,0,0,0,0,0,0,0,0,0,0,0,0,0,0,0,0,0,0,0,0,0,0,0
endlayer

layer
0,0,0,0,0,0,0,0,0,0,0,0,0,0,0,0,0,0,0,0,0,0,0,0,0,0,0,0,0
0,0,0,0,0,0,0,0,0,0,0,0,0,0,0,0,0,0,0,0,0,0,0,0,0,0,0,0,0
0,0,0,0,0,0,0,0,0,0,0,0,0,0,0,0,0,0,0,0,0,0,0,0,0,0,0,0,0
0,0,0,0,0,0,0,0,0,0,0,0,0,0,0,0,0,0,0,0,0,0,0,0,0,0,0,0,0
0,0,0,0,0,0,0,0,0,0,0,0,0,0,0,0,0,0,0,0,0,0,0,0,0,0,0,0,0
0,0,0,0,0,0,0,0,0,0,0,0,0,0,0,0,0,0,0,0,0,0,0,0,0,0,0,0,0
0,0,0,0,0,0,0,0,0,0,0,0,0,0,0,0,0,0,0,0,0,0,0,0,0,0,0,0,0
0,0,0,0,0,0,0,0,0,0,0,0,0,0,0,0,0,0,0,0,0,0,0,0,0,0,0,0,0
0,0,0,0,0,0,0,0,0,0,0,0,0,0,0,0,0,0,0,0,0,0,0,0,0,0,0,0,0
0,0,0,0,0,0,0,0,0,106,0,0,0,0,0,0,0,0,0,0,0,0,0,0,0,0,0,0,0
0,0,0,0,0,0,0,0,0,0,0,0,0,0,0,0,0,0,0,0,0,0,0,0,0,0,0,0,0
0,0,0,0,0,0,0,0,0,0,0,0,0,0,0,0,0,0,0,0,0,0,0,0,0,0,0,0,0
0,0,0,0,0,0,0,0,0,0,0,0,0,0,0,0,0,0,0,0,0,0,0,0,0,0,0,0,0
0,0,0,0,0,0,0,0,0,0,0,0,0,0,0,0,0,0,0,0,0,0,0,0,0,0,0,0,0
0,0,0,0,0,0,0,0,0,0,0,0,0,0,0,0,0,0,0,0,0,0,0,0,0,0,0,0,0
0,0,0,0,0,0,0,0,0,0,0,0,0,0,0,0,0,0,0,0,0,0,0,0,0,0,0,0,0
0,0,0,0,0,0,0,0,0,0,0,0,0,0,0,0,0,0,0,0,0,0,0,0,0,0,0,0,0
0,0,0,0,0,0,0,0,0,0,0,0,0,0,0,0,0,0,0,0,0,0,0,0,0,0,0,0,0
0,0,0,0,0,0,0,0,0,0,0,0,0,0,0,0,0,0,0,0,0,0,0,0,0,0,0,0,0
0,0,0,0,0,0,0,0,0,0,0,0,0,0,0,0,0,0,0,0,0,0,0,0,0,0,0,0,0
0,0,0,0,0,0,0,0,0,0,0,0,0,0,0,0,0,0,0,0,0,0,0,0,0,0,0,0,0
0,0,0,0,0,0,0,0,0,0,0,0,0,0,0,0,0,0,0,0,0,0,0,0,0,0,0,0,0
0,0,0,0,0,0,0,0,0,0,0,0,0,0,0,0,0,0,0,0,0,0,0,0,0,0,0,0,0
0,0,0,0,0,0,0,0,0,0,0,0,0,0,0,0,0,0,0,0,0,0,0,0,0,0,0,0,0
0,0,0,0,0,0,0,0,0,0,0,0,0,0,0,0,0,0,0,0,0,0,0,0,0,0,0,0,0
0,0,0,0,0,0,0,0,0,0,0,0,0,0,0,0,0,0,0,0,0,0,0,0,0,0,0,0,0
0,0,0,0,0,0,0,0,0,0,0,0,0,0,0,0,0,0,0,0,0,0,0,0,0,0,0,0,0
0,0,0,0,0,0,0,0,0,0,0,0,0,0,0,0,0,0,0,0,0,0,0,0,0,0,0,0,0
0,0,0,0,0,0,0,0,0,0,0,0,0,0,0,0,0,0,0,0,0,0,0,0,0,0,0,0,0
0,0,0,0,0,0,0,0,0,0,0,0,0,0,0,0,0,0,0,0,0,0,0,0,0,0,0,0,0
0,0,0,0,0,0,0,0,0,0,0,0,0,0,0,0,0,0,0,0,0,0,0,0,0,0,0,0,0
0,0,0,0,0,0,0,0,0,0,0,0,0,0,0,0,0,0,0,0,0,0,0,0,0,0,0,0,0
0,0,0,0,0,0,0,0,0,0,0,0,0,0,0,0,0,0,0,0,0,0,0,0,0,0,0,0,0
0,0,0,0,0,0,0,0,0,0,0,0,0,0,0,0,0,0,0,0,0,0,0,0,0,0,0,0,0
0,0,0,0,0,0,0,0,0,0,0,0,0,0,0,0,0,0,0,0,0,0,0,0,0,0,0,0,0
endlayer

layer
0,0,0,0,0,0,0,0,0,0,0,0,0,0,0,0,0,0,0,0,0,0,0,0,0,0,0,0,0
0,0,0,0,0,0,0,0,0,0,0,0,0,0,0,0,0,0,0,0,0,0,0,0,0,0,0,0,0
0,0,0,0,0,0,0,0,0,0,0,0,0,0,0,0,0,0,0,0,0,0,0,0,0,0,0,0,0
0,0,0,0,0,0,0,0,0,0,0,0,0,0,0,0,0,0,0,0,0,0,0,0,0,0,0,0,0
0,0,0,0,0,0,0,0,0,0,0,0,0,0,0,0,0,0,0,0,0,0,0,0,0,0,0,0,0
0,0,0,0,0,0,0,0,0,0,0,0,0,0,0,0,0,0,0,0,0,0,0,0,0,0,0,0,0
0,0,0,0,0,0,0,0,0,0,0,0,0,0,0,0,0,0,0,0,0,0,0,0,0,0,0,0,0
0,0,0,0,0,0,0,0,0,0,0,0,0,0,0,0,0,0,0,0,0,0,0,0,0,0,0,0,0
0,0,0,0,0,0,0,0,0,0,0,0,0,0,0,0,0,0,0,0,0,0,0,0,0,0,0,0,0
0,0,0,0,0,0,0,0,0,106,0,0,0,0,0,0,0,0,0,0,0,0,0,0,0,0,0,0,0
0,0,0,0,0,0,0,0,0,0,0,0,0,0,0,0,0,0,0,0,0,0,0,0,0,0,0,0,0
0,0,0,0,0,0,0,0,0,0,0,0,0,0,0,0,0,0,0,0,0,0,0,0,0,0,0,0,0
0,0,0,0,0,0,0,0,0,0,0,0,0,0,0,0,0,0,0,0,0,0,0,0,0,0,0,0,0
0,0,0,0,0,0,0,0,0,0,0,0,0,0,0,0,0,0,0,0,0,0,0,0,0,0,0,0,0
0,0,0,0,0,0,0,0,0,0,0,0,0,0,0,0,0,0,0,0,0,0,0,0,0,0,0,0,0
0,0,0,0,0,0,0,0,0,0,0,0,0,0,0,0,0,0,0,0,0,0,0,0,0,0,0,0,0
0,0,0,0,0,0,0,0,0,0,0,0,0,0,0,0,0,0,0,0,0,0,0,0,0,0,0,0,0
0,0,0,0,0,0,0,0,0,0,0,0,0,0,0,0,0,0,0,0,0,0,0,0,0,0,0,0,0
0,0,0,0,0,0,0,0,0,0,0,0,0,0,0,0,0,0,0,0,0,0,0,0,0,0,0,0,0
0,0,0,0,0,0,0,0,0,0,0,0,0,0,0,0,0,0,0,0,0,0,0,0,0,0,0,0,0
0,0,0,0,0,0,0,0,0,0,0,0,0,0,0,0,0,0,0,0,0,0,0,0,0,0,0,0,0
0,0,0,0,0,0,0,0,0,0,0,0,0,0,0,0,0,0,0,0,0,0,0,0,0,0,0,0,0
0,0,0,0,0,0,0,0,0,0,0,0,0,0,0,0,0,0,0,0,0,0,0,0,0,0,0,0,0
0,0,0,0,0,0,0,0,0,0,0,0,0,0,0,0,0,0,0,0,0,0,0,0,0,0,0,0,0
0,0,0,0,0,0,0,0,0,0,0,0,0,0,0,0,0,0,0,0,0,0,0,0,0,0,0,0,0
0,0,0,0,0,0,0,0,0,0,0,0,0,0,0,0,0,0,0,0,0,0,0,0,0,0,0,0,0
0,0,0,0,0,0,0,0,0,0,0,0,0,0,0,0,0,0,0,0,0,0,0,0,0,0,0,0,0
0,0,0,0,0,0,0,0,0,0,0,0,0,0,0,0,0,0,0,0,0,0,0,0,0,0,0,0,0
0,0,0,0,0,0,0,0,0,0,0,0,0,0,0,0,0,0,0,0,0,0,0,0,0,0,0,0,0
0,0,0,0,0,0,0,0,0,0,0,0,0,0,0,0,0,0,0,0,0,0,0,0,0,0,0,0,0
0,0,0,0,0,0,0,0,0,0,0,0,0,0,0,0,0,0,0,0,0,0,0,0,0,0,0,0,0
0,0,0,0,0,0,0,0,0,0,0,0,0,0,0,0,0,0,0,0,0,0,0,0,0,0,0,0,0
0,0,0,0,0,0,0,0,0,0,0,0,0,0,0,0,0,0,0,0,0,0,0,0,0,0,0,0,0
0,0,0,0,0,0,0,0,0,0,0,0,0,0,0,0,0,0,0,0,0,0,0,0,0,0,0,0,0
0,0,0,0,0,0,0,0,0,0,0,0,0,0,0,0,0,0,0,0,0,0,0,0,0,0,0,0,0
endlayer

layer
0,0,0,0,0,0,0,0,0,0,0,0,0,0,0,0,0,0,0,0,0,0,0,0,0,0,0,0,0
0,0,0,0,0,0,0,0,0,0,0,0,0,0,0,0,0,0,0,0,0,0,0,0,0,0,0,0,0
0,0,0,0,0,0,0,0,0,0,0,0,0,0,0,0,0,0,0,0,0,0,0,0,0,0,0,0,0
0,0,0,0,0,0,0,0,0,0,0,0,0,0,0,0,0,0,0,0,0,0,0,0,0,0,0,0,0
0,0,0,0,0,0,0,0,0,0,0,0,0,0,0,0,0,0,0,0,0,0,0,0,0,0,0,0,0
