# Dungeon Spiral (NO CB)
# Created by Ruins mod version 15.6 Ingame Parser
# authoring Player: Jordan_Greywolf
# Created for MC 1.8: 31 May 2016
# Updated for MC 1.9: 31 May 2016
# Updated for MC 1.11: 13 Jan 2017
# Verified for MC 1.12: 23 Jun 2017
# Updated to MC 1.12.1: 12 Sep 2017

biomesToSpawnIn=bamboo forest,birch forest,bog,brushland,chaparral,dead forest,dead swamp,eerie,eldritch,extreme hills edge,fen,flower field,forest,grassland,grove,heathland,ice plains,land of lakes,lavender fields,lush swamp,maple woods,marsh,meadow,mountain foothills,mystic grove,outback,prairie,seasonal forest,shield,shrubland,sunflower plains,tainted land,wasteland,wetland,woodland,xeric shrubland,mining biome,birch_forest,smaller_extreme_hills,ice_flats,mutated_plains

preventRotation=1

uniqueMinDistance=1000

weight=1
embed_into_distance=57
acceptable_target_blocks=

unacceptable_target_blocks=flowing_water,water,cloud,Natura:Cloud,lava,flowing_lava,slime_congealed,slime_dirt,slime_grass,command_block

dimensions=57,7,7
allowable_overhang=0
max_leveling=20
leveling_buffer=-1
preserve_water=0
preserve_lava=0
preserve_plants=1

rule1=0,100,preserveBlock

rule2=0,100,minecraft:stonebrick,minecraft:stonebrick,minecraft:stonebrick-1,minecraft:stonebrick-1,minecraft:stonebrick-2

rule3=0,100,minecraft:stone-6
rule4=0,100,minecraft:stone_slab-0
rule5=0,100,minecraft:stone_brick_stairs-2
rule6=0,100,ChestGenHook:chests/simple_dungeon:5-5
rule7=0,100,ChestGenHook:chests/simple_dungeon:5-3
rule8=0,100,minecraft:stone_brick_stairs-4

rule9=0,100,minecraft:air

rule10=0,100,minecraft:dark_oak_door-0
rule11=0,100,minecraft:stone_brick_stairs-1
rule12=0,100,minecraft:dark_oak_door-8
rule13=0,100,minecraft:stone_brick_stairs-6

rule14=0,100,minecraft:air

rule15=0,100,minecraft:dark_oak_door-1
rule16=0,100,minecraft:stone_brick_stairs-3
rule17=0,100,minecraft:dark_oak_door-2

rule18=0,100,minecraft:air

rule19=0,100,minecraft:stone_brick_stairs-5
rule20=0,100,minecraft:stone_brick_stairs-0
rule21=0,100,minecraft:dark_oak_door-3

rule22=0,100,minecraft:air

rule23=0,100,minecraft:stone_brick_stairs-7

# Bottom Floor
layer
1,1,2,3,2,1,1
1,3,2,3,2,3,1
2,2,4,4,4,2,2
3,3,3,3,4,3,3
2,2,3,5,4,2,2
1,3,2,4,2,3,1
1,1,2,3,2,1,1
endlayer

# Repeating 1
layer
1,1,2,3,2,1,1
1,3,2,6,2,3,1
2,2,0,0,0,2,2
3,0,8,3,0,7,3
2,2,5,0,0,2,2
1,3,2,9,2,3,1
1,1,2,10,2,1,1
endlayer

# Repeating 2
layer
1,1,2,3,2,1,1
1,3,2,0,2,3,1
2,2,8,0,0,2,2
3,4,11,3,0,0,3
2,2,0,0,0,2,2
1,3,2,0,2,3,1
1,1,2,12,2,1,1
endlayer

# Repeating 3
layer
1,1,2,3,2,1,1
1,3,2,0,2,3,1
2,2,11,13,0,2,2
15,14,0,3,0,0,3
2,2,0,0,0,2,2
1,3,2,0,2,3,1
1,1,2,3,2,1,1
endlayer

# Repeating 4
layer
1,1,2,3,2,1,1
1,3,2,4,2,3,1
2,2,0,16,13,2,2
12,0,0,3,0,0,3
2,2,0,0,0,2,2
1,3,2,0,2,3,1
1,1,2,3,2,1,1
endlayer

# Repeating 5
layer
1,1,2,17,2,1,1
1,3,2,18,2,3,1
2,2,0,0,16,2,2
3,0,0,3,19,0,3
2,2,0,0,0,2,2
1,3,2,0,2,3,1
1,1,2,3,2,1,1
endlayer

# Repeating 6
layer
1,1,2,12,2,1,1
1,3,2,0,2,3,1
2,2,0,0,0,2,2
3,0,0,3,20,4,3
2,2,0,0,19,2,2
1,3,2,0,2,3,1
1,1,2,3,2,1,1
endlayer

# Repeating 7
layer
1,1,2,3,2,1,1
1,3,2,0,2,3,1
2,2,0,0,0,2,2
3,0,0,3,0,22,21
2,2,0,23,20,2,2
1,3,2,0,2,3,1
1,1,2,3,2,1,1
endlayer

# Repeating 8
layer
1,1,2,3,2,1,1
1,3,2,0,2,3,1
2,2,0,0,0,2,2
3,0,0,3,0,0,12
2,2,23,5,0,2,2
1,3,2,4,2,3,1
1,1,2,3,2,1,1
endlayer

# Repeating 1
layer
1,1,2,3,2,1,1
1,3,2,0,2,3,1
2,2,0,0,0,2,2
3,0,8,3,0,0,3
2,2,5,0,0,2,2
1,3,2,9,2,3,1
1,1,2,10,2,1,1
endlayer

# Repeating 2
layer
1,1,2,3,2,1,1
1,3,2,0,2,3,1
2,2,8,0,0,2,2
3,4,11,3,0,0,3
2,2,0,0,0,2,2
1,3,2,0,2,3,1
1,1,2,12,2,1,1
endlayer

# Repeating 3
layer
1,1,2,3,2,1,1
1,3,2,0,2,3,1
2,2,11,13,0,2,2
15,14,0,3,0,0,3
2,2,0,0,0,2,2
1,3,2,0,2,3,1
1,1,2,3,2,1,1
endlayer

# Repeating 4
layer
1,1,2,3,2,1,1
1,3,2,4,2,3,1
2,2,0,16,13,2,2
12,0,0,3,0,0,3
2,2,0,0,0,2,2
1,3,2,0,2,3,1
1,1,2,3,2,1,1
endlayer

# Repeating 5
layer
1,1,2,17,2,1,1
1,3,2,18,2,3,1
2,2,0,0,16,2,2
3,0,0,3,19,0,3
2,2,0,0,0,2,2
1,3,2,0,2,3,1
1,1,2,3,2,1,1
endlayer

# Repeating 6
layer
1,1,2,12,2,1,1
1,3,2,0,2,3,1
2,2,0,0,0,2,2
3,0,0,3,20,4,3
2,2,0,0,19,2,2
1,3,2,0,2,3,1
1,1,2,3,2,1,1
endlayer

# Repeating 7
layer
1,1,2,3,2,1,1
1,3,2,0,2,3,1
2,2,0,0,0,2,2
3,0,0,3,0,22,21
2,2,0,23,20,2,2
1,3,2,0,2,3,1
1,1,2,3,2,1,1
endlayer

# Repeating 8
layer
1,1,2,3,2,1,1
1,3,2,0,2,3,1
2,2,0,0,0,2,2
3,0,0,3,0,0,12
2,2,23,5,0,2,2
1,3,2,4,2,3,1
1,1,2,3,2,1,1
endlayer

# Repeating 1
layer
1,1,2,3,2,1,1
1,3,2,0,2,3,1
2,2,0,0,0,2,2
3,0,8,3,0,0,3
2,2,5,0,0,2,2
1,3,2,9,2,3,1
1,1,2,10,2,1,1
endlayer

# Repeating 2
layer
1,1,2,3,2,1,1
1,3,2,0,2,3,1
2,2,8,0,0,2,2
3,4,11,3,0,0,3
2,2,0,0,0,2,2
1,3,2,0,2,3,1
1,1,2,12,2,1,1
endlayer

# Repeating 3
layer
1,1,2,3,2,1,1
1,3,2,0,2,3,1
2,2,11,13,0,2,2
15,14,0,3,0,0,3
2,2,0,0,0,2,2
1,3,2,0,2,3,1
1,1,2,3,2,1,1
endlayer

# Repeating 4
layer
1,1,2,3,2,1,1
1,3,2,4,2,3,1
2,2,0,16,13,2,2
12,0,0,3,0,0,3
2,2,0,0,0,2,2
1,3,2,0,2,3,1
1,1,2,3,2,1,1
endlayer

# Repeating 5
layer
1,1,2,17,2,1,1
1,3,2,18,2,3,1
2,2,0,0,16,2,2
3,0,0,3,19,0,3
2,2,0,0,0,2,2
1,3,2,0,2,3,1
1,1,2,3,2,1,1
endlayer

# Repeating 6
layer
1,1,2,12,2,1,1
1,3,2,0,2,3,1
2,2,0,0,0,2,2
3,0,0,3,20,4,3
2,2,0,0,19,2,2
1,3,2,0,2,3,1
1,1,2,3,2,1,1
endlayer

# Repeating 7
layer
1,1,2,3,2,1,1
1,3,2,0,2,3,1
2,2,0,0,0,2,2
3,0,0,3,0,22,21
2,2,0,23,20,2,2
1,3,2,0,2,3,1
1,1,2,3,2,1,1
endlayer

# Repeating 8
layer
1,1,2,3,2,1,1
1,3,2,0,2,3,1
2,2,0,0,0,2,2
3,0,0,3,0,0,12
2,2,23,5,0,2,2
1,3,2,4,2,3,1
1,1,2,3,2,1,1
endlayer

# Repeating 1
layer
1,1,2,3,2,1,1
1,3,2,0,2,3,1
2,2,0,0,0,2,2
3,0,8,3,0,0,3
2,2,5,0,0,2,2
1,3,2,9,2,3,1
1,1,2,10,2,1,1
endlayer

# Repeating 2
layer
1,1,2,3,2,1,1
1,3,2,0,2,3,1
2,2,8,0,0,2,2
3,4,11,3,0,0,3
2,2,0,0,0,2,2
1,3,2,0,2,3,1
1,1,2,12,2,1,1
endlayer

# Repeating 3
layer
1,1,2,3,2,1,1
1,3,2,0,2,3,1
2,2,11,13,0,2,2
15,14,0,3,0,0,3
2,2,0,0,0,2,2
1,3,2,0,2,3,1
1,1,2,3,2,1,1
endlayer

# Repeating 4
layer
1,1,2,3,2,1,1
1,3,2,4,2,3,1
2,2,0,16,13,2,2
12,0,0,3,0,0,3
2,2,0,0,0,2,2
1,3,2,0,2,3,1
1,1,2,3,2,1,1
endlayer

# Repeating 5
layer
1,1,2,17,2,1,1
1,3,2,18,2,3,1
2,2,0,0,16,2,2
3,0,0,3,19,0,3
2,2,0,0,0,2,2
1,3,2,0,2,3,1
1,1,2,3,2,1,1
endlayer

# Repeating 6
layer
1,1,2,12,2,1,1
1,3,2,0,2,3,1
2,2,0,0,0,2,2
3,0,0,3,20,4,3
2,2,0,0,19,2,2
1,3,2,0,2,3,1
1,1,2,3,2,1,1
endlayer

# Repeating 7
layer
1,1,2,3,2,1,1
1,3,2,0,2,3,1
2,2,0,0,0,2,2
3,0,0,3,0,22,21
2,2,0,23,20,2,2
1,3,2,0,2,3,1
1,1,2,3,2,1,1
endlayer

# Repeating 8
layer
1,1,2,3,2,1,1
1,3,2,0,2,3,1
2,2,0,0,0,2,2
3,0,0,3,0,0,12
2,2,23,5,0,2,2
1,3,2,4,2,3,1
1,1,2,3,2,1,1
endlayer

# Repeating 1
layer
1,1,2,3,2,1,1
1,3,2,0,2,3,1
2,2,0,0,0,2,2
3,0,8,3,0,0,3
2,2,5,0,0,2,2
1,3,2,9,2,3,1
1,1,2,10,2,1,1
endlayer

# Repeating 2
layer
1,1,2,3,2,1,1
1,3,2,0,2,3,1
2,2,8,0,0,2,2
3,4,11,3,0,0,3
2,2,0,0,0,2,2
1,3,2,0,2,3,1
1,1,2,12,2,1,1
endlayer

# Repeating 3
layer
1,1,2,3,2,1,1
1,3,2,0,2,3,1
2,2,11,13,0,2,2
15,14,0,3,0,0,3
2,2,0,0,0,2,2
1,3,2,0,2,3,1
1,1,2,3,2,1,1
endlayer

# Repeating 4
layer
1,1,2,3,2,1,1
1,3,2,4,2,3,1
2,2,0,16,13,2,2
12,0,0,3,0,0,3
2,2,0,0,0,2,2
1,3,2,0,2,3,1
1,1,2,3,2,1,1
endlayer

# Repeating 5
layer
1,1,2,17,2,1,1
1,3,2,18,2,3,1
2,2,0,0,16,2,2
3,0,0,3,19,0,3
2,2,0,0,0,2,2
1,3,2,0,2,3,1
1,1,2,3,2,1,1
endlayer

# Repeating 6
layer
1,1,2,12,2,1,1
1,3,2,0,2,3,1
2,2,0,0,0,2,2
3,0,0,3,20,4,3
2,2,0,0,19,2,2
1,3,2,0,2,3,1
1,1,2,3,2,1,1
endlayer

# Repeating 7
layer
1,1,2,3,2,1,1
1,3,2,0,2,3,1
2,2,0,0,0,2,2
3,0,0,3,0,22,21
2,2,0,23,20,2,2
1,3,2,0,2,3,1
1,1,2,3,2,1,1
endlayer

# Repeating 8
layer
1,1,2,3,2,1,1
1,3,2,0,2,3,1
2,2,0,0,0,2,2
3,0,0,3,0,0,12
2,2,23,5,0,2,2
1,3,2,4,2,3,1
1,1,2,3,2,1,1
endlayer

# Repeating 1
layer
1,1,2,3,2,1,1
1,3,2,0,2,3,1
2,2,0,0,0,2,2
3,0,8,3,0,0,3
2,2,5,0,0,2,2
1,3,2,9,2,3,1
1,1,2,10,2,1,1
endlayer

# Repeating 2
layer
1,1,2,3,2,1,1
1,3,2,0,2,3,1
2,2,8,0,0,2,2
3,4,11,3,0,0,3
2,2,0,0,0,2,2
1,3,2,0,2,3,1
1,1,2,12,2,1,1
endlayer

# Repeating 3
layer
1,1,2,3,2,1,1
1,3,2,0,2,3,1
2,2,11,13,0,2,2
15,14,0,3,0,0,3
2,2,0,0,0,2,2
1,3,2,0,2,3,1
1,1,2,3,2,1,1
endlayer

# Repeating 4
layer
1,1,2,3,2,1,1
1,3,2,4,2,3,1
2,2,0,16,13,2,2
12,0,0,3,0,0,3
2,2,0,0,0,2,2
1,3,2,0,2,3,1
1,1,2,3,2,1,1
endlayer

# Repeating 5
layer
1,1,2,17,2,1,1
1,3,2,18,2,3,1
2,2,0,0,16,2,2
3,0,0,3,19,0,3
2,2,0,0,0,2,2
1,3,2,0,2,3,1
1,1,2,3,2,1,1
endlayer

# Repeating 6
layer
1,1,2,12,2,1,1
1,3,2,0,2,3,1
2,2,0,0,0,2,2
3,0,0,3,20,4,3
2,2,0,0,19,2,2
1,3,2,0,2,3,1
1,1,2,3,2,1,1
endlayer

# Repeating 7
layer
1,1,2,3,2,1,1
1,3,2,0,2,3,1
2,2,0,0,0,2,2
3,0,0,3,0,22,21
2,2,0,23,20,2,2
1,3,2,0,2,3,1
1,1,2,3,2,1,1
endlayer

# Repeating 8
layer
1,1,2,3,2,1,1
1,3,2,0,2,3,1
2,2,0,0,0,2,2
3,0,0,3,0,0,12
2,2,23,5,0,2,2
1,3,2,4,2,3,1
1,1,2,3,2,1,1
endlayer

# Top Repeating 1
layer
1,1,2,3,2,1,1
1,3,2,0,2,3,1
2,2,0,0,0,2,2
3,0,8,3,0,0,3
2,2,5,0,0,2,2
1,3,2,0,2,3,1
1,1,2,3,2,1,1
endlayer

# Top Repeating 2
layer
1,1,2,3,2,1,1
1,3,2,0,2,3,1
2,2,8,0,0,2,2
3,4,11,3,0,0,3
2,2,0,0,0,2,2
1,3,2,0,2,3,1
1,1,2,3,2,1,1
endlayer

# Top Repeating 3
layer
1,1,2,3,2,1,1
1,3,2,0,2,3,1
2,2,11,13,0,2,2
3,0,0,3,0,0,3
2,2,0,0,0,2,2
1,3,2,0,2,3,1
1,1,2,3,2,1,1
endlayer

# Top Repeating 4
layer
1,1,2,3,2,1,1
1,3,2,4,2,3,1
2,2,0,16,13,2,2
3,0,0,3,0,0,3
2,2,0,0,0,2,2
1,3,2,0,2,3,1
1,1,2,3,2,1,1
endlayer

# Top Repeating 5
layer
1,1,2,3,2,1,1
1,3,2,0,2,3,1
2,2,0,0,16,2,2
3,0,0,3,19,0,3
2,2,0,0,0,2,2
1,3,2,0,2,3,1
1,1,2,3,2,1,1
endlayer

# Top Repeating 6
layer
1,1,2,3,2,1,1
1,3,2,0,2,3,1
2,2,0,0,0,2,2
3,0,0,3,20,4,3
2,2,0,0,19,2,2
1,3,2,0,2,3,1
1,1,2,3,2,1,1
endlayer

# Top Repeating 7
layer
1,1,2,3,2,1,1
1,3,2,0,2,3,1
2,2,0,0,0,2,2
3,0,0,3,0,0,3
2,2,0,23,20,2,2
1,3,2,0,2,3,1
1,1,2,3,2,1,1
endlayer

# Top Repeating 8
layer
1,1,2,3,2,1,1
1,3,2,0,2,3,1
2,2,0,0,0,2,2
3,0,0,3,0,0,3
2,2,23,5,0,2,2
1,3,2,4,2,3,1
1,1,2,3,2,1,1
endlayer


