
# Created by Ruins mod version 17.0 Ingame Parser
# authoring Player: ST753M

weight=1
embed_into_distance=13
acceptable_target_blocks=
unacceptable_target_blocks=flowing_water,water,flowing_lava,lava,ice,bedrock,netherrack,nether_brick,nether_brick_fence,soul_sand,quartz_ore,end_stone,obsidian,iron_bars,Natura:Cloud,slime_grass,slime_congealed,slime_dirt,clouds,natura:clouds
dimensions=13,11,16
allowable_overhang=8
max_leveling=0
leveling_buffer=-1
preserve_water=0
preserve_lava=0

biomesToSpawnIn=dead_swamp,coralium_infested_swamp,forest,maple_woods,boreal_forest,forest_hills,woodland,seasonal_forest,temperate_rainforest,fen,grove,sacred_springs,land_of_lakes,forested_hills,lush_hills,thicket,birch_forest,birch_forest_hills,mutated_birch_forest,mutated_birch_forest_hills,birch_forested_hills,taiga,taiga_hills,mutated_redwood_taiga,mutated_redwood_taiga_hills,redwood_taiga,mutated_taiga,redwood_taiga_hills,redwood_forest,coniferous_forest,shield,dead_forest,autumnal_wooded_hills,autumnal_woods,extreme_hills,smaller_extreme_hills,mutated_extreme_hills,mutated_extreme_hills_with_trees,extreme_hills_with_trees,highland,alps,alps_foothills,mountain,mountain_foothills,crag,cliffs,savanna,savanna_rock,mutated_savanna,mutated_savanna_rock,brushland,steppe,wasteland,tundra,outback,badlands,desert_shrubland,arid_highland,mesa,mesa_clear_rock,mesa_rock,mutated_mesa,mutated_mesa_clear_rock,mutated_mesa_rock,lush_desert,darklands,darklands_forest,darklands_hills,darklands_mountains,darklands_plains,ominous_woods,eerie

rule1=0,100,minecraft:concrete-7
rule2=0,100,minecraft:stonebrick-0
rule3=0,100,minecraft:stone_brick_stairs-2
rule4=0,100,minecraft:bed-9
rule5=0,100,minecraft:iron_bars-0
rule6=0,100,minecraft:bed-1
rule7=0,100,minecraft:wooden_slab-8
rule8=0,100,minecraft:iron_trapdoor-3
rule9=0,100,IInventory;minecraft:chest;minecraft:rotten_flesh#3#0#0+minecraft:air#0#0#1+harvestcraft:zombiejerkyitem#5#0#4+minecraft:air#0#0#8+harvestcraft:freshwateritem#9#0#11+minecraft:rotten_flesh#2#0#16+minecraft:rotten_flesh#4#0#24-5
rule10=0,100,IInventory;minecraft:trapped_chest;harvestcraft:beefjerkyitem#1#0#0+harvestcraft:beefjerkyitem#3#0#11+harvestcraft:flouritem#2#0#16+minecraft:water_bucket#1#0#22-5
rule11=0,100,IInventory;minecraft:chest;minecraft:bowl#2#0#3+minecraft:air#0#0#5+minecraft:bowl#2#0#9+minecraft:air#0#0#12+minecraft:bowl#1#0#13+minecraft:air#0#0#14+harvestcraft:driedsoupitem#3#0#16+harvestcraft:beefjerkyitem#4#0#19+minecraft:air#0#0#26-5
rule12=0,100,minecraft:stone_brick_stairs-1
rule13=0,100,minecraft:stone_brick_stairs-0
rule14=0,100,minecraft:quartz_stairs-6
rule15=0,100,minecraft:quartz_block-2
rule16=0,100,minecraft:quartz_stairs-7
rule17=0,100,IInventory;minecraft:trapped_chest;harvestcraft:flouritem#3#0#3+harvestcraft:zombiejerkyitem#4#0#13+minecraft:beetroot#5#0#15+harvestcraft:flouritem#2#0#19-5
rule18=0,100,IInventory;minecraft:chest;harvestcraft:zombiejerkyitem#3#0#1+minecraft:air#0#24#3+harvestcraft:zombiejerkyitem#2#0#11+harvestcraft:grapejellyitem#5#0#13+minecraft:air#0#0#14+harvestcraft:honeyitem#5#0#15+harvestcraft:honeyitem#4#0#20+minecraft:air#0#0#21+minecraft:air#0#24#24+harvestcraft:zombiejerkyitem#2#0#25-5
rule19=0,100,IInventory;minecraft:trapped_chest;harvestcraft:garlicitem#3#0#4+harvestcraft:vinegaritem#4#0#8+minecraft:potion#{Potion:"minecraft:healing"}#0#20+harvestcraft:vinegaritem#3#0#24-5
rule20=0,100,minecraft:lever-10
rule21=0,100,minecraft:quartz_block-4
rule22=0,100,minecraft:quartz_block-3
rule23=0,100,minecraft:lever-9
rule24=0,100,minecraft:bookshelf-0
rule25=0,100,minecraft:stone_brick_stairs-5
rule26=0,100,minecraft:stone_brick_stairs-4
rule27=0,100,minecraft:quartz_stairs-2
rule28=0,100,minecraft:quartz_stairs-3
rule29=0,100,preserveBlock
rule30=0,100,?minecraft:stone_brick_stairs-3

layer
1,1,1,1,1,1,1,1,1,1,1,1,1,1,1,1
1,2,2,2,2,2,1,2,2,2,2,2,2,2,2,1
1,2,2,2,2,2,1,2,2,2,2,2,2,2,2,1
1,2,2,2,2,2,1,1,1,1,1,2,2,2,2,1
1,2,2,2,2,2,2,2,2,2,1,2,2,2,2,1
1,2,2,2,2,2,2,2,2,2,1,2,2,2,2,1
1,2,2,2,2,2,2,2,2,2,1,2,2,2,2,1
1,2,2,2,2,2,2,2,2,2,1,2,2,2,2,1
1,2,2,2,2,2,2,2,2,2,1,2,2,2,2,1
1,2,2,2,2,2,2,2,2,1,1,2,2,2,2,1
1,1,1,1,1,1,1,1,1,1,1,1,1,1,1,1
endlayer

layer
1,2,2,2,2,2,2,2,2,2,1,2,2,2,2,1
2,4,5,5,4,2,2,2,2,2,3,0,0,0,0,2
2,6,0,0,6,2,2,2,2,2,3,0,0,0,0,2
1,0,0,0,0,1,2,2,2,2,1,5,5,0,5,2
2,0,0,0,0,0,7,7,7,0,2,0,0,0,0,2
2,1,0,0,0,0,0,0,0,0,2,0,0,0,0,2
2,7,0,0,0,0,0,0,0,0,2,0,0,0,0,2
2,7,0,0,0,0,0,0,0,0,2,0,0,0,0,2
2,7,0,0,0,0,0,0,0,0,2,0,0,0,0,2
2,1,7,7,7,1,7,7,7,1,2,0,0,0,0,2
1,2,2,2,2,2,2,2,2,2,1,2,2,2,2,1
endlayer

layer
1,2,2,2,2,2,2,2,2,2,1,2,2,2,2,1
2,0,8,8,0,2,2,2,2,3,0,0,0,0,0,2
2,0,0,0,0,2,2,2,2,3,0,0,0,0,0,2
1,0,0,0,0,1,2,2,2,2,1,5,5,0,5,2
2,0,0,0,0,0,11,10,9,0,2,0,0,0,0,2
2,1,0,0,0,0,0,0,0,0,12,0,0,0,0,2
2,7,0,0,0,0,0,0,0,0,0,0,0,0,0,2
2,7,0,0,0,0,0,0,0,0,13,0,0,0,0,2
2,7,0,0,0,0,0,0,0,0,2,16,15,14,0,2
2,1,7,7,7,1,7,7,7,1,2,0,0,0,0,2
1,2,2,2,2,2,2,2,2,2,1,2,2,2,2,1
endlayer

layer
1,2,2,2,2,2,2,2,2,2,1,2,2,2,2,1
2,0,0,0,0,2,2,2,3,0,0,0,0,0,0,2
2,0,0,0,0,2,2,2,3,0,0,0,0,0,0,2
1,0,0,0,0,1,2,2,2,2,1,5,5,0,5,2
2,0,0,0,0,0,19,18,17,0,2,0,0,0,0,2
2,1,0,0,0,0,0,0,0,0,0,0,0,0,0,2
2,7,0,0,0,0,0,0,0,0,0,0,0,0,0,2
2,7,0,0,0,0,0,0,0,0,0,0,0,20,0,2
2,7,0,0,0,0,0,0,0,0,2,21,22,21,0,2
2,1,7,7,7,1,7,7,7,1,2,0,0,23,0,2
1,2,2,2,2,2,2,2,2,2,1,2,2,2,2,1
endlayer

layer
1,2,2,2,2,2,2,2,2,2,1,2,2,2,2,1
2,24,24,24,24,2,2,3,0,0,0,0,0,0,0,2
2,0,0,0,0,2,2,3,0,0,0,0,0,0,0,2
1,0,0,0,0,1,2,2,2,2,1,5,5,5,5,2
2,0,0,0,0,0,0,0,0,0,2,0,0,0,0,2
2,1,0,0,0,0,0,0,0,0,25,0,0,0,0,2
2,7,0,0,0,0,0,0,0,0,0,0,0,0,0,2
2,7,0,0,0,0,0,0,0,0,26,0,0,0,0,2
2,7,0,0,0,0,0,0,0,0,2,28,15,27,0,2
2,1,7,7,7,1,7,7,7,1,2,0,0,0,0,2
1,2,2,2,2,2,2,2,2,2,1,2,2,2,2,1
endlayer

layer
1,2,2,2,2,2,2,2,2,2,1,2,2,2,2,1
2,2,2,2,2,2,3,0,0,0,5,0,0,0,0,2
2,2,2,2,2,2,3,0,0,0,5,0,0,0,0,2
1,1,1,1,1,1,2,2,2,2,1,5,5,5,5,2
2,0,0,0,0,0,0,0,0,0,2,0,0,0,0,2
2,1,0,0,0,0,0,0,0,0,2,0,0,0,0,2
2,0,0,0,0,0,0,0,0,0,2,0,0,0,0,2
2,0,0,0,0,0,0,0,0,0,2,0,0,0,0,2
2,0,0,0,0,0,0,0,0,0,2,0,0,0,0,2
2,1,0,0,0,1,0,0,0,1,2,0,0,0,0,2
1,2,2,2,2,2,2,2,2,2,1,2,2,2,2,1
endlayer

layer
1,1,1,1,1,1,1,1,1,1,1,1,1,1,1,1
1,2,2,2,2,3,0,0,0,0,2,2,2,2,2,1
1,2,2,2,2,3,0,0,0,0,2,2,2,2,2,1
1,2,2,2,2,1,1,1,1,1,1,1,1,1,1,1
1,2,2,2,2,2,2,2,2,2,1,2,2,2,2,1
1,2,2,2,2,2,2,2,2,2,1,2,2,2,2,1
1,2,2,2,2,2,2,2,2,2,1,2,2,2,2,1
1,2,2,2,2,2,2,2,2,2,1,2,2,2,2,1
1,2,2,2,2,2,2,2,2,2,1,2,2,2,2,1
1,2,2,2,2,2,2,2,2,2,1,2,2,2,2,1
1,1,1,1,1,1,1,1,1,1,1,1,1,1,1,1
endlayer

layer
29,29,29,29,29,29,29,29,29,29,29,29,29,29,29,29
29,29,29,0,0,0,0,0,29,29,29,29,29,29,29,29
29,29,29,0,0,0,0,0,29,29,29,29,29,29,29,29
29,29,29,0,0,29,29,29,29,29,29,29,29,29,29,29
29,29,29,0,0,30,2,2,29,29,29,29,29,29,29,29
29,29,29,0,0,30,2,2,29,29,29,29,29,29,29,29
29,29,29,29,29,29,29,29,29,29,29,29,29,29,29,29
29,29,29,29,29,29,29,29,29,29,29,29,29,29,29,29
29,29,29,29,29,29,29,29,29,29,29,29,29,29,29,29
29,29,29,29,29,29,29,29,29,29,29,29,29,29,29,29
29,29,29,29,29,29,29,29,29,29,29,29,29,29,29,29
endlayer

layer
29,29,29,29,29,29,29,29,29,29,29,29,29,29,29,29
29,29,29,0,0,0,0,29,29,29,29,29,29,29,29,29
29,29,29,0,0,0,0,29,29,29,29,29,29,29,29,29
29,29,29,0,0,29,29,29,29,29,29,29,29,29,29,29
29,29,29,0,0,0,30,2,2,29,29,29,29,29,29,29
29,29,29,0,0,0,30,2,2,29,29,29,29,29,29,29
29,29,29,29,29,29,29,29,29,29,29,29,29,29,29,29
29,29,29,29,29,29,29,29,29,29,29,29,29,29,29,29
29,29,29,29,29,29,29,29,29,29,29,29,29,29,29,29
29,29,29,29,29,29,29,29,29,29,29,29,29,29,29,29
29,29,29,29,29,29,29,29,29,29,29,29,29,29,29,29
endlayer

layer
29,29,29,29,29,29,29,29,29,29,29,29,29,29,29,29
29,29,29,29,29,29,29,29,29,29,29,29,29,29,29,29
29,29,29,29,29,29,29,29,29,29,29,29,29,29,29,29
29,29,29,29,29,29,29,29,29,29,29,29,29,29,29,29
29,29,29,29,0,0,0,30,2,2,29,29,29,29,29,29
29,29,29,29,0,0,0,30,2,2,29,29,29,29,29,29
29,29,29,29,29,29,29,29,29,29,29,29,29,29,29,29
29,29,29,29,29,29,29,29,29,29,29,29,29,29,29,29
29,29,29,29,29,29,29,29,29,29,29,29,29,29,29,29
29,29,29,29,29,29,29,29,29,29,29,29,29,29,29,29
29,29,29,29,29,29,29,29,29,29,29,29,29,29,29,29
endlayer

layer
29,29,29,29,29,29,29,29,29,29,29,29,29,29,29,29
29,29,29,29,29,29,29,29,29,29,29,29,29,29,29,29
29,29,29,29,29,29,29,29,29,29,29,29,29,29,29,29
29,29,29,29,29,29,29,29,29,29,29,29,29,29,29,29
29,29,29,29,29,0,0,0,30,2,2,29,29,29,29,29
29,29,29,29,29,0,0,0,30,2,2,29,29,29,29,29
29,29,29,29,29,29,29,29,29,29,29,29,29,29,29,29
29,29,29,29,29,29,29,29,29,29,29,29,29,29,29,29
29,29,29,29,29,29,29,29,29,29,29,29,29,29,29,29
29,29,29,29,29,29,29,29,29,29,29,29,29,29,29,29
29,29,29,29,29,29,29,29,29,29,29,29,29,29,29,29
endlayer

layer
29,29,29,29,29,29,29,29,29,29,29,29,29,29,29,29
29,29,29,29,29,29,29,29,29,29,29,29,29,29,29,29
29,29,29,29,29,29,29,29,29,29,29,29,29,29,29,29
29,29,29,29,29,29,29,29,29,29,29,29,29,29,29,29
29,29,29,29,29,29,0,0,0,30,2,29,29,29,29,29
29,29,29,29,29,29,0,0,0,30,2,29,29,29,29,29
29,29,29,29,29,29,29,29,29,29,29,29,29,29,29,29
29,29,29,29,29,29,29,29,29,29,29,29,29,29,29,29
29,29,29,29,29,29,29,29,29,29,29,29,29,29,29,29
29,29,29,29,29,29,29,29,29,29,29,29,29,29,29,29
29,29,29,29,29,29,29,29,29,29,29,29,29,29,29,29
endlayer

layer
29,29,29,29,29,29,29,29,29,29,29,29,29,29,29,29
29,29,29,29,29,29,29,29,29,29,29,29,29,29,29,29
29,29,29,29,29,29,29,29,29,29,29,29,29,29,29,29
29,29,29,29,29,29,29,29,29,29,29,29,29,29,29,29
29,29,29,29,29,29,29,0,0,0,30,29,29,29,29,29
29,29,29,29,29,29,29,0,0,0,30,29,29,29,29,29
29,29,29,29,29,29,29,29,29,29,29,29,29,29,29,29
29,29,29,29,29,29,29,29,29,29,29,29,29,29,29,29
29,29,29,29,29,29,29,29,29,29,29,29,29,29,29,29
29,29,29,29,29,29,29,29,29,29,29,29,29,29,29,29
29,29,29,29,29,29,29,29,29,29,29,29,29,29,29,29
endlayer

