# Ice Guard Tower #2 (tall version) (NO CB)
# MC 1.7.10; 26 Oct 2014

# Created by Ruins mod version 13.8 Ingame Parser
# authoring Player: Jordan_Greywolf

# Updated to MC 1.8: 27 Jul 2015
# Updated to MC 1.9: 30 Apr 2016
# Updated to MC 1.11: 13 Jan 2017
# Updated to MC 1.12: 23 Jun 2017

biomesToSpawnIn=arctic,cold beach,glacier,iceika,ice mountains,ice plains,ice plains spikes,icy hills,ice wasteland,polar,polar chasm,rwg_coldplains,twilight glacier,taiga_cold,taiga_cold_hills,mutated_taiga,mutated_taiga_cold,ice_mountains,ice_flats,mutated_ice_flats,frozen_beach,cold_beach

uniqueMinDistance=1000

weight=1
embed_into_distance=7
acceptable_target_blocks=snow,snow_layer,ice,packed_ice

preventRotation=1



dimensions=34,9,9
allowable_overhang=5
max_leveling=5
leveling_buffer=-1
preserve_water=0
preserve_lava=0
preserve_plants=1

rule1=0,100,minecraft:snow-0
rule2=0,100,minecraft:packed_ice-0

rule3=0,100,MobSpawner:Skeleton

rule4=0,100,minecraft:ice-0
rule5=0,100,IInventory;minecraft:trapped_chest;minecraft:ice#16#0#0+minecraft:packed_ice#16#0#1+minecraft:lit_pumpkin#4#0#2+minecraft:painting#1#0#3-5
rule6=0,100,minecraft:snow_layer-5
rule7=0,100,minecraft:snow_layer-2
rule8=0,100,IInventory;minecraft:dispenser;minecraft:snowball#16#0#0+minecraft:snowball#16#0#1+minecraft:snowball#16#0#2+minecraft:snowball#16#0#3+minecraft:snowball#16#0#4+minecraft:snowball#16#0#5+minecraft:snowball#16#0#6+minecraft:snowball#16#0#7+minecraft:snowball#16#0#8-4
rule9=0,100,IInventory;minecraft:dispenser;minecraft:snowball#16#0#0+minecraft:snowball#16#0#1+minecraft:snowball#16#0#2+minecraft:snowball#16#0#3+minecraft:snowball#16#0#4+minecraft:snowball#16#0#5+minecraft:snowball#16#0#6+minecraft:snowball#16#0#7+minecraft:snowball#16#0#8-2
rule10=0,100,IInventory;minecraft:dispenser;minecraft:snowball#16#0#0+minecraft:snowball#16#0#1+minecraft:snowball#16#0#2+minecraft:snowball#16#0#3+minecraft:snowball#16#0#4+minecraft:snowball#16#0#5+minecraft:snowball#16#0#6+minecraft:snowball#16#0#7+minecraft:snowball#16#0#8-3
rule11=0,100,IInventory;minecraft:dispenser;minecraft:snowball#16#0#0+minecraft:snowball#16#0#1+minecraft:snowball#16#0#2+minecraft:snowball#16#0#3+minecraft:snowball#16#0#4+minecraft:snowball#16#0#5+minecraft:snowball#16#0#6+minecraft:snowball#16#0#7+minecraft:snowball#16#0#8-5
rule12=2,100,minecraft:stone_button-1
rule13=2,100,minecraft:stone_button-3
rule14=2,100,minecraft:stone_button-4
rule15=2,100,minecraft:stone_button-2
rule16=0,100,preserveBlock
rule17=0,100,ChestGenHook:chests/simple_dungeon:4
rule18=0,100,minecraft:birch_door-3
rule19=0,100,minecraft:birch_door-8

layer
16,16,16,1,1,1,16,16,16
16,16,1,2,2,2,1,16,16
16,1,2,2,2,2,2,1,16
1,2,2,2,2,2,2,2,1
1,2,2,2,2,2,2,2,1
1,2,2,2,2,2,2,2,1
16,1,2,2,2,2,2,1,16
16,16,1,1,1,1,1,16,16
16,16,16,1,1,1,16,16,16
endlayer

layer
16,16,16,1,1,1,16,16,16
16,16,1,2,2,2,1,16,16
16,1,2,2,2,2,2,1,16
1,2,2,2,2,2,2,2,1
1,2,2,2,2,2,2,2,1
1,2,2,2,2,2,2,2,1
16,1,2,2,2,2,2,1,16
16,16,1,1,1,1,1,16,16
16,16,16,1,1,1,16,16,16
endlayer

layer
16,16,16,1,1,1,16,16,16
16,16,1,2,2,2,1,16,16
16,1,2,2,2,2,2,1,16
1,2,2,2,2,2,2,2,1
1,2,2,2,2,2,2,2,1
1,2,2,2,2,2,2,2,1
16,1,2,2,2,2,2,1,16
16,16,1,1,1,1,1,16,16
16,16,16,1,1,1,16,16,16
endlayer

layer
16,16,16,1,1,1,16,16,16
16,16,1,2,2,2,1,16,16
16,1,2,2,2,2,2,1,16
1,2,2,2,2,2,2,2,1
1,2,2,2,2,2,2,2,1
1,2,2,2,2,2,2,2,1
16,1,2,2,2,2,2,1,16
16,16,1,1,1,1,1,16,16
16,16,16,1,1,1,16,16,16
endlayer

layer
16,16,16,1,1,1,16,16,16
16,16,1,2,2,2,1,16,16
16,1,2,2,2,2,2,1,16
1,2,2,2,2,2,2,2,1
1,2,2,2,2,2,2,2,1
1,2,2,2,2,2,2,2,1
16,1,2,2,2,2,2,1,16
16,16,1,1,1,1,1,16,16
16,16,16,1,1,1,16,16,16
endlayer



layer
16,16,1,1,1,1,1,16,16
16,1,1,2,2,2,1,1,16
1,2,2,2,2,2,2,2,1
1,2,2,2,2,2,2,2,1
1,2,2,2,2,2,2,2,1
1,2,2,2,2,2,2,2,1
1,2,2,2,2,2,2,2,1
16,1,1,1,1,1,1,1,16
16,16,1,1,1,1,1,16,16
endlayer

# Base Floor
layer
16,16,1,1,1,1,1,1,16
16,1,2,2,2,2,2,1,1
1,2,2,4,2,4,2,2,1
1,2,4,2,4,2,4,2,1
1,4,2,4,2,4,2,2,1
1,2,4,2,4,2,4,2,1
1,2,1,1,2,4,4,2,1
16,1,2,2,2,2,2,1,1
16,16,1,1,1,1,1,1,16
endlayer

layer
16,16,1,1,1,1,1,16,16
16,1,2,2,2,2,2,1,1
1,2,0,0,5,0,0,2,1
16,2,0,0,0,0,0,2,1
0,18,0,0,3,0,0,2,16
16,2,0,0,0,0,0,2,16
16,2,7,6,1,1,1,2,1
16,1,2,2,2,2,2,1,1
16,16,1,1,1,1,1,1,16
endlayer

layer
16,16,16,1,1,1,16,16,16
16,16,2,2,2,2,2,16,16
16,2,0,0,0,0,0,2,1
16,2,0,0,0,0,1,2,16
0,19,0,0,0,0,1,2,16
16,2,0,0,0,0,1,2,16
16,2,0,0,0,7,6,2,16
16,16,2,2,4,2,2,1,16
16,16,16,1,16,1,16,16,16
endlayer

layer
16,16,16,16,16,16,16,16,16
16,16,2,2,2,2,2,16,16
16,2,0,0,1,1,1,2,16
16,2,0,0,0,0,6,2,16
16,4,0,0,0,0,7,2,16
16,2,0,0,0,0,0,2,16
16,2,0,0,0,0,0,2,16
16,16,2,2,4,2,2,16,16
16,16,16,16,16,16,16,16,16
endlayer

layer
16,16,16,16,16,16,16,16,16
16,16,2,2,2,2,2,16,16
16,2,1,1,6,7,0,2,16
16,2,1,0,0,0,0,2,16
16,2,0,0,0,0,0,4,16
16,2,0,0,0,0,0,2,16
16,2,0,0,0,0,0,2,16
16,16,2,2,2,2,2,16,16
16,16,16,16,16,16,16,16,16
endlayer

layer
16,16,16,16,16,16,16,16,16
16,16,2,2,4,2,2,16,16
16,2,7,0,0,0,0,2,16
16,2,6,0,0,0,0,2,16
16,2,1,0,0,0,0,4,16
16,2,1,0,0,0,0,2,16
16,2,1,0,0,0,0,2,16
16,16,2,2,2,2,2,16,16
16,16,16,16,16,16,16,16,16
endlayer

layer
16,16,0,0,0,0,0,16,16
16,0,2,2,4,2,2,0,16
0,2,0,0,0,0,0,2,0
0,2,0,0,0,0,0,2,0
0,2,0,0,0,0,0,4,0
0,2,7,0,0,0,0,2,0
0,2,6,1,1,1,0,2,0
16,0,2,2,2,2,2,0,16
16,16,0,0,0,0,0,16,16
endlayer

# 2nd Floor
layer
16,0,0,0,0,0,0,0,16
0,2,2,2,4,2,2,2,0
0,2,0,0,2,4,2,2,0
0,2,0,2,4,2,4,2,0
0,4,0,4,2,4,2,2,0
0,2,0,2,4,2,4,2,0
0,2,0,0,7,6,1,2,0
0,2,2,2,4,2,2,2,0
16,0,0,0,0,0,0,0,16
endlayer

layer
0,0,0,0,0,0,0,0,0
0,0,2,2,2,2,2,0,0
0,2,0,0,0,0,0,2,0
0,2,0,0,0,0,1,2,0
0,4,0,0,3,0,1,2,0
0,2,0,0,0,0,1,2,0
0,2,0,0,0,0,7,2,0
0,0,2,2,4,2,2,0,0
0,0,0,0,0,0,0,0,0
endlayer

layer
0,0,0,0,0,0,0,0,0
0,0,2,2,2,2,2,0,0
0,2,0,0,1,1,1,2,0
0,2,0,0,0,0,6,2,0
0,4,0,0,0,0,7,2,0
0,2,0,0,0,0,0,2,0
0,2,0,0,0,0,0,2,0
0,0,2,2,4,2,2,0,0
0,0,0,0,0,0,0,0,0
endlayer

layer
0,0,0,0,0,0,0,0,0
0,0,2,2,2,2,2,0,0
0,2,1,1,6,7,0,2,0
0,2,1,0,0,0,0,2,0
0,2,0,0,0,0,0,4,0
0,2,0,0,0,0,0,2,0
0,2,0,0,0,0,0,2,0
0,0,2,2,2,2,2,0,0
0,0,0,0,0,0,0,0,0
endlayer

layer
0,0,0,0,0,0,0,0,0
0,0,2,2,4,2,2,0,0
0,2,7,0,0,0,0,2,0
0,2,6,0,0,0,0,2,0
0,2,1,0,0,0,0,4,0
0,2,1,0,0,0,0,2,0
0,2,1,0,0,0,0,2,0
0,0,2,2,2,2,2,0,0
0,0,0,0,0,0,0,0,0
endlayer

layer
0,0,0,0,0,0,0,0,0
0,0,2,2,4,2,2,0,0
0,2,0,0,0,0,0,2,0
0,2,0,0,0,0,0,2,0
0,2,0,0,0,0,0,4,0
0,2,7,0,0,0,0,2,0
0,2,6,1,1,1,0,2,0
0,0,2,2,2,2,2,0,0
0,0,0,0,0,0,0,0,0
endlayer

# 3rd Floor
layer
0,0,0,0,0,0,0,0,0
0,2,2,2,4,2,2,2,0
0,2,0,0,2,4,2,2,0
0,2,0,2,4,2,4,2,0
0,4,0,4,2,4,2,2,0
0,2,0,2,4,2,4,2,0
0,2,0,0,7,6,1,2,0
0,2,2,2,4,2,2,2,0
0,0,0,0,0,0,0,0,0
endlayer

layer
0,0,0,0,0,0,0,0,0
0,0,2,2,2,2,2,0,0
0,2,0,0,0,0,0,2,0
0,2,0,0,0,0,1,2,0
0,4,0,0,3,0,1,2,0
0,2,0,0,0,0,1,2,0
0,2,0,0,0,0,7,2,0
0,0,2,2,4,2,2,0,0
0,0,0,0,0,0,0,0,0
endlayer

layer
0,0,0,0,0,0,0,0,0
0,0,2,2,2,2,2,0,0
0,2,0,0,1,1,1,2,0
0,2,0,0,0,0,6,2,0
0,4,0,0,0,0,7,2,0
0,2,0,0,0,0,0,2,0
0,2,0,0,0,0,0,2,0
0,0,2,2,4,2,2,0,0
0,0,0,0,0,0,0,0,0
endlayer

layer
0,0,0,0,0,0,0,0,0
0,0,2,2,2,2,2,0,0
0,2,1,1,6,7,0,2,0
0,2,1,0,0,0,0,2,0
0,2,0,0,0,0,0,4,0
0,2,0,0,0,0,0,2,0
0,2,0,0,0,0,0,2,0
0,0,2,2,2,2,2,0,0
0,0,0,0,0,0,0,0,0
endlayer

layer
0,0,0,0,0,0,0,0,0
0,0,2,2,4,2,2,0,0
0,2,7,0,0,0,0,2,0
0,2,6,0,0,0,0,2,0
0,2,1,0,0,0,0,4,0
0,2,1,0,0,0,0,2,0
0,2,1,0,0,0,0,2,0
0,0,2,2,2,2,2,0,0
0,0,0,0,0,0,0,0,0
endlayer

layer
0,0,0,0,0,0,0,0,0
0,0,2,2,4,2,2,0,0
0,2,0,0,0,0,0,2,0
0,2,0,0,0,0,0,2,0
0,2,0,0,0,0,0,4,0
0,2,7,0,0,0,0,2,0
0,2,6,1,1,1,0,2,0
0,0,2,2,2,2,2,0,0
0,0,0,0,0,0,0,0,0
endlayer

# 4th Floor
layer
0,0,0,0,0,0,0,0,0
0,2,2,2,4,2,2,2,0
0,2,0,0,2,4,2,2,0
0,2,0,2,4,2,4,2,0
0,4,0,4,2,4,2,2,0
0,2,0,2,4,2,4,2,0
0,2,0,0,7,6,1,2,0
0,2,2,2,4,2,2,2,0
0,0,0,0,0,0,0,0,0
endlayer

layer
0,0,0,0,0,0,0,0,0
0,0,2,2,2,2,2,0,0
0,2,0,0,0,0,0,2,0
0,2,0,0,0,0,1,2,0
0,4,0,0,3,0,1,2,0
0,2,0,0,0,0,1,2,0
0,2,0,0,0,0,7,2,0
0,0,2,2,4,2,2,0,0
0,0,0,0,0,0,0,0,0
endlayer

layer
0,0,0,0,0,0,0,0,0
0,0,2,2,2,2,2,0,0
0,2,0,0,1,1,1,2,0
0,2,0,0,0,0,6,2,0
0,4,0,0,0,0,7,2,0
0,2,0,0,0,0,0,2,0
0,2,0,0,0,0,0,2,0
0,0,2,2,4,2,2,0,0
0,0,0,0,0,0,0,0,0
endlayer

layer
0,0,0,0,0,0,0,0,0
0,0,2,2,2,2,2,0,0
0,2,1,1,6,7,0,2,0
0,2,1,0,0,0,0,2,0
0,2,0,0,0,0,0,4,0
0,2,0,0,0,0,0,2,0
0,2,0,0,0,0,0,2,0
0,0,2,2,2,2,2,0,0
0,0,0,0,0,0,0,0,0
endlayer

layer
0,0,0,0,0,0,0,0,0
0,0,2,2,4,2,2,0,0
0,2,7,0,0,0,0,2,0
0,2,6,0,0,0,0,2,0
0,2,1,0,0,0,0,4,0
0,2,1,0,0,0,0,2,0
0,2,1,0,0,0,0,2,0
0,0,2,2,2,2,2,0,0
0,0,0,0,0,0,0,0,0
endlayer

layer
16,16,0,2,0,2,0,16,16
16,0,2,2,4,2,2,0,16
0,2,0,0,0,0,0,2,0
2,2,0,0,0,0,0,2,2
0,2,0,0,0,0,0,2,0
2,2,7,0,0,0,0,2,2
0,2,6,1,1,1,0,2,0
16,0,2,2,2,2,2,0,16
16,16,0,2,0,2,0,16,16
endlayer

# Top Floor
layer
16,0,0,2,2,2,0,0,16
0,2,2,2,4,2,2,2,0
0,2,0,0,2,4,2,2,0
2,2,0,2,4,2,4,2,2
2,4,0,4,2,4,2,4,2
2,2,0,2,4,2,4,2,2
0,2,0,0,7,6,1,2,0
0,2,2,2,4,2,2,2,0
16,0,0,2,2,2,0,0,16
endlayer


layer
0,0,2,2,8,2,2,0,0
0,2,2,0,0,0,2,2,0
2,2,0,0,0,0,0,2,2
2,0,0,0,0,0,0,0,2
10,0,0,0,17,0,0,0,9
2,0,0,0,0,0,0,0,2
2,2,0,0,0,0,0,2,2
0,2,2,0,0,0,2,2,0
0,0,2,2,11,2,2,0,0
endlayer

layer
0,0,2,0,2,0,2,0,0
0,0,0,0,12,0,0,0,0
2,0,0,0,0,0,0,0,2
0,0,0,0,0,0,0,0,0
2,14,0,0,0,0,0,13,2
0,0,0,0,0,0,0,0,0
2,0,0,0,0,0,0,0,2
0,0,0,0,15,0,0,0,0
0,0,2,0,2,0,2,0,0
endlayer



