
# Created by Ruins mod version 17.0 Ingame Parser
# authoring Player: ST753M

weight=1
embed_into_distance=2
acceptable_target_blocks=grass,sand,dirt,white_sand
unacceptable_target_blocks=flowing_water,water,flowing_lava,lava
dimensions=14,11,11
allowable_overhang=3
max_leveling=0
leveling_buffer=-1
preserve_water=0
preserve_lava=0

biomesToSpawnIn=beaches,white_beach,ocean,jungle_edge,mutated_desert,oasis

=0,100,preserveBlock
rule1=0,100,minecraft:grass-0
rule2=0,100,minecraft:dirt-0
rule3=0,100,harvestcraft:tropicalgarden-0
rule4=0,100,minecraft:log-3
rule5=0,100,minecraft:leaves-7
rule6=0,50,harvestcraft:pamcoconut-0
rule7=0,100,minecraft:leaves-15

layer
0,0,0,0,0,0,0,0,0,0,0
0,0,0,0,0,0,0,0,0,0,0
0,0,0,0,1,2,1,0,0,0,0
0,0,0,2,2,2,1,2,0,0,0
0,0,2,2,2,1,2,2,2,0,0
0,0,1,2,1,2,2,2,2,0,0
0,0,2,2,2,2,2,2,2,0,0
0,0,0,2,2,2,2,2,0,0,0
0,0,0,0,2,1,1,0,0,0,0
0,0,0,0,0,0,0,0,0,0,0
0,0,0,0,0,0,0,0,0,0,0
endlayer

layer
0,0,0,0,0,0,0,0,0,0,0
0,0,0,0,0,0,0,0,0,0,0
0,0,0,0,1,1,1,0,0,0,0
0,0,0,1,2,2,1,1,0,0,0
0,0,1,2,2,2,1,2,1,0,0
0,0,1,2,1,2,1,2,1,0,0
0,0,1,1,1,1,2,2,1,0,0
0,0,0,1,1,2,2,1,0,0,0
0,0,0,0,1,1,1,0,0,0,0
0,0,0,0,0,0,0,0,0,0,0
0,0,0,0,0,0,0,0,0,0,0
endlayer

layer
0,0,0,0,0,0,0,0,0,0,0
0,0,0,0,0,0,0,0,0,0,0
0,0,0,0,0,0,0,0,0,0,0
0,0,0,3,1,1,1,0,0,0,0
0,0,0,1,1,1,1,1,0,0,0
0,0,0,1,1,4,1,1,0,0,0
0,0,0,1,1,1,1,1,0,0,0
0,0,0,0,1,1,1,0,0,0,0
0,0,0,0,0,0,0,0,0,0,0
0,0,0,0,0,0,0,0,0,0,0
0,0,0,0,0,0,0,0,0,0,0
endlayer

layer
0,0,0,0,0,0,0,0,0,0,0
0,0,0,0,0,0,0,0,0,0,0
0,0,0,0,0,0,0,0,0,0,0
0,0,0,0,0,0,0,0,0,0,0
0,0,0,0,0,0,0,3,0,0,0
0,0,0,0,0,4,0,0,0,0,0
0,0,0,0,3,0,0,0,0,0,0
0,0,0,0,0,0,0,0,0,0,0
0,0,0,0,0,0,0,0,0,0,0
0,0,0,0,0,0,0,0,0,0,0
0,0,0,0,0,0,0,0,0,0,0
endlayer

layer
0,0,0,0,0,0,0,0,0,0,0
0,0,0,0,0,0,0,0,0,0,0
0,0,0,0,0,0,0,0,0,0,0
0,0,0,0,0,0,0,0,0,0,0
0,0,0,0,0,0,0,0,0,0,0
0,0,0,0,0,4,0,0,0,0,0
0,0,0,0,0,0,0,0,0,0,0
0,0,0,0,0,0,0,0,0,0,0
0,0,0,0,0,0,0,0,0,0,0
0,0,0,0,0,0,0,0,0,0,0
0,0,0,0,0,0,0,0,0,0,0
endlayer

layer
0,0,0,0,0,0,0,0,0,0,0
0,0,0,0,0,0,0,0,0,0,0
0,0,0,0,0,0,0,0,0,0,0
0,0,0,0,0,0,0,0,0,0,0
0,0,0,0,0,0,0,0,0,0,0
0,0,0,0,0,4,0,0,0,0,0
0,0,0,0,0,0,0,0,0,0,0
0,0,0,0,0,0,0,0,0,0,0
0,0,0,0,0,0,0,0,0,0,0
0,0,0,0,0,0,0,0,0,0,0
0,0,0,0,0,0,0,0,0,0,0
endlayer

layer
0,0,0,0,0,0,0,0,0,0,0
0,0,0,0,0,0,0,0,0,0,0
0,0,0,0,0,0,0,0,0,0,0
0,0,0,0,0,0,0,0,0,0,0
0,0,0,0,0,0,0,0,0,0,0
0,0,0,0,0,4,0,0,0,0,0
0,0,0,0,0,0,0,0,0,0,0
0,0,0,0,0,0,0,0,0,0,0
0,0,0,0,0,0,0,0,0,0,0
0,0,0,0,0,0,0,0,0,0,0
0,0,0,0,0,0,0,0,0,0,0
endlayer

layer
0,0,0,0,0,0,0,0,0,0,0
0,0,0,0,0,0,0,0,0,0,0
0,0,0,0,0,0,0,0,0,0,0
0,0,0,0,0,0,0,0,0,0,0
0,0,0,0,0,0,0,0,0,0,0
0,0,0,0,0,4,0,0,0,0,0
0,0,0,0,0,0,0,0,0,0,0
0,0,0,0,0,0,0,0,0,0,0
0,0,0,0,0,0,0,0,0,0,0
0,0,0,0,0,0,0,0,0,0,0
0,0,0,0,0,0,0,0,0,0,0
endlayer

layer
0,0,0,0,5,0,0,0,0,0,0
0,0,0,0,5,0,0,0,0,0,0
0,0,0,0,0,0,0,0,0,0,0
0,0,0,0,0,0,0,0,0,0,0
0,0,0,0,0,6,0,0,0,5,5
0,0,0,0,6,4,6,0,0,0,0
5,5,0,0,0,6,0,0,0,0,0
0,0,0,0,0,0,0,0,0,0,0
0,0,0,0,0,0,0,0,0,0,0
0,0,0,0,0,0,5,0,0,0,0
0,0,0,0,0,0,5,0,0,0,0
endlayer

layer
0,0,0,0,0,0,5,0,0,0,0
0,0,0,0,5,0,5,0,0,0,0
0,0,0,0,5,0,0,0,0,0,0
0,0,0,0,5,0,0,0,0,0,0
5,5,0,0,7,5,5,5,5,5,0
0,0,0,0,7,4,5,0,0,0,0
0,5,5,5,7,7,7,0,0,7,7
0,0,0,0,0,0,5,0,0,0,0
0,0,0,0,0,0,5,0,0,0,0
0,0,0,0,5,0,5,0,0,0,0
0,0,0,0,5,0,0,0,0,0,0
endlayer

layer
0,0,0,0,0,0,0,0,0,0,0
0,0,0,0,0,0,5,0,0,0,0
0,0,0,0,0,0,7,0,0,0,0
0,0,0,0,0,0,7,0,0,0,0
0,5,5,5,7,7,7,0,0,0,0
0,0,0,0,7,4,5,0,0,0,0
0,0,0,0,7,5,5,5,7,7,0
0,0,0,0,5,0,0,0,0,0,0
0,0,0,0,5,0,0,0,0,0,0
0,0,0,0,5,0,0,0,0,0,0
0,0,0,0,0,0,0,0,0,0,0
endlayer

layer
0,0,0,0,0,0,0,0,0,0,0
0,0,7,0,0,0,0,0,0,0,0
0,0,7,5,0,0,0,0,7,7,0
0,0,0,5,7,0,0,5,7,0,0
0,0,0,0,7,7,7,5,0,0,0
0,0,0,0,7,5,5,0,0,0,0
0,0,0,7,7,5,5,0,0,0,0
0,0,5,7,0,0,5,5,0,0,0
0,7,7,0,0,0,0,7,7,0,0
0,0,0,0,0,0,0,0,7,0,0
0,0,0,0,0,0,0,0,0,0,0
endlayer

layer
0,0,0,0,0,0,0,0,0,0,0
0,0,0,0,0,7,0,0,0,0,0
0,0,0,0,0,5,0,0,0,0,0
0,0,0,0,0,7,0,0,0,0,0
0,0,0,0,0,7,0,0,0,0,0
0,5,5,5,5,5,5,5,5,5,0
0,0,0,0,0,5,0,0,0,0,0
0,0,0,0,0,5,0,0,0,0,0
0,0,0,0,0,5,0,0,0,0,0
0,0,0,0,0,5,0,0,0,0,0
0,0,0,0,0,0,0,0,0,0,0
endlayer

layer
0,0,0,0,0,0,0,0,0,0,0
0,0,0,0,0,0,0,0,0,0,0
0,0,0,0,0,0,0,0,0,0,0
0,0,0,0,0,5,0,0,0,0,0
0,0,0,0,0,0,0,0,0,0,0
0,0,0,5,0,0,0,5,0,0,0
0,0,0,0,0,0,0,0,0,0,0
0,0,0,0,0,5,0,0,0,0,0
0,0,0,0,0,0,0,0,0,0,0
0,0,0,0,0,0,0,0,0,0,0
0,0,0,0,0,0,0,0,0,0,0
endlayer

