
# Created by Ruins mod version 17.0 Ingame Parser
# authoring Player: ST753M

weight=1
uniqueMinDistance=1000
embed_into_distance=3
acceptable_target_blocks=
unacceptable_target_blocks=flowing_water,water,flowing_lava,lava,ice,bedrock,netherrack,nether_brick,nether_brick_fence,soul_sand,quartz_ore,end_stone,obsidian,iron_bars,Natura:Cloud,slime_grass,slime_congealed,slime_dirt,clouds,natura:clouds
dimensions=9,17,17
allowable_overhang=3
max_leveling=0
leveling_buffer=-1
preserve_water=0
preserve_lava=0

biomesToSpawnIn=dense_twilight_forest,enchanted_forest,firefly_forest,mushroom_forest,oak_savannah,twilight_clearing,twilight_forest,twilight_swamp

rule1=0,100,preserveBlock
rule2=0,100,botania:livingrock-1
rule3=0,100,botania:livingrock-4
rule4=0,100,minecraft:grass-0
rule5=0,100,botania:livingrock1stairs-2
rule6=0,100,botania:livingrock1stairs-0
rule7=0,100,botania:livingrock1stairs-3
rule8=0,100,botania:livingrock1stairs-1
rule9=0,100,minecraft:sapling-2,minecraft:sapling-3,minecraft:sapling-4,twilightforest:twilight_sapling-6,twilightforest:twilight_sapling-5,twilightforest:twilight_sapling-7,twilightforest:twilight_sapling-8,twilightforest:twilight_sapling-9
rule10=0,100,botania:livingrock1slab-0

layer
1,1,1,1,1,2,2,2,2,2,2,2,1,1,1,1,1
1,1,1,2,2,2,2,2,2,2,2,2,2,2,1,1,1
1,1,2,2,2,2,2,2,2,2,2,2,2,2,2,1,1
1,2,2,2,2,2,2,2,2,2,2,2,2,2,2,2,1
1,2,2,2,2,2,2,2,2,2,2,2,2,2,2,2,1
2,2,2,2,2,2,2,2,2,2,2,2,2,2,2,2,2
2,2,2,2,2,2,2,2,2,2,2,2,2,2,2,2,2
2,2,2,2,2,2,2,2,2,2,2,2,2,2,2,2,2
2,2,2,2,2,2,2,2,2,2,2,2,2,2,2,2,2
2,2,2,2,2,2,2,2,2,2,2,2,2,2,2,2,2
2,2,2,2,2,2,2,2,2,2,2,2,2,2,2,2,2
2,2,2,2,2,2,2,2,2,2,2,2,2,2,2,2,2
1,2,2,2,2,2,2,2,2,2,2,2,2,2,2,2,1
1,2,2,2,2,2,2,2,2,2,2,2,2,2,2,2,1
1,1,2,2,2,2,2,2,2,2,2,2,2,2,2,1,1
1,1,1,2,2,2,2,2,2,2,2,2,2,2,1,1,1
1,1,1,1,1,2,2,2,2,2,2,2,1,1,1,1,1
endlayer

layer
1,1,1,1,1,3,2,3,2,3,2,3,1,1,1,1,1
1,1,1,3,2,2,2,2,2,2,2,2,2,3,1,1,1
1,1,2,2,2,2,2,2,2,2,2,2,2,2,2,1,1
1,3,2,2,2,2,2,2,2,2,2,2,2,2,2,3,1
1,2,2,2,2,2,2,2,2,2,2,2,2,2,2,2,1
3,2,2,2,2,2,2,2,2,2,2,2,2,2,2,2,3
2,2,2,2,2,2,2,2,2,2,2,2,2,2,2,2,2
3,2,2,2,2,2,2,2,2,2,2,2,2,2,2,2,3
2,2,2,2,2,2,2,2,2,2,2,2,2,2,2,2,2
3,2,2,2,2,2,2,2,2,2,2,2,2,2,2,2,3
2,2,2,2,2,2,2,2,2,2,2,2,2,2,2,2,2
3,2,2,2,2,2,2,2,2,2,2,2,2,2,2,2,3
1,2,2,2,2,2,2,2,2,2,2,2,2,2,2,2,1
1,3,2,2,2,2,2,2,2,2,2,2,2,2,2,3,1
1,1,2,2,2,2,2,2,2,2,2,2,2,2,2,1,1
1,1,1,3,2,2,2,2,2,2,2,2,2,3,1,1,1
1,1,1,1,1,3,2,3,2,3,2,3,1,1,1,1,1
endlayer

layer
1,1,1,1,1,2,3,2,3,2,3,2,1,1,1,1,1
1,1,1,2,3,2,2,2,2,2,2,2,3,2,1,1,1
1,1,3,2,2,2,2,2,2,2,2,2,2,2,3,1,1
1,2,2,2,2,2,4,4,4,4,4,2,2,2,2,2,1
1,3,2,2,4,4,4,4,4,4,4,4,4,2,2,3,1
2,2,2,2,4,4,4,4,4,4,4,4,4,2,2,2,2
3,2,2,4,4,4,4,4,4,4,4,4,4,4,2,2,3
2,2,2,4,4,4,4,4,4,4,4,4,4,4,2,2,2
3,2,2,4,4,4,4,4,4,4,4,4,4,4,2,2,3
2,2,2,4,4,4,4,4,4,4,4,4,4,4,2,2,2
3,2,2,4,4,4,4,4,4,4,4,4,4,4,2,2,3
2,2,2,2,4,4,4,4,4,4,4,4,4,2,2,2,2
1,3,2,2,4,4,4,4,4,4,4,4,4,2,2,3,1
1,2,2,2,2,2,4,4,4,4,4,2,2,2,2,2,1
1,1,3,2,2,2,2,2,2,2,2,2,2,2,3,1,1
1,1,1,2,3,2,2,2,2,2,2,2,3,2,1,1,1
1,1,1,1,1,2,3,2,3,2,3,2,1,1,1,1,1
endlayer

layer
1,1,1,1,1,6,6,6,6,6,6,5,1,1,1,1,1
1,1,1,6,6,7,2,2,2,2,2,6,6,5,1,1,1
1,1,6,7,2,2,8,8,8,8,7,2,2,6,5,1,1
1,6,7,2,8,8,5,0,0,0,8,8,7,2,6,5,1
1,7,2,8,5,0,0,0,0,0,0,0,8,7,2,5,1
6,7,2,5,0,0,0,0,0,0,0,0,0,7,2,6,5
7,2,8,5,0,0,0,0,0,0,0,0,0,8,7,2,5
7,2,5,0,0,0,0,0,0,0,0,0,0,0,7,2,5
7,2,5,0,0,0,0,0,9,0,0,0,0,0,7,2,5
7,2,5,0,0,0,0,0,0,0,0,0,0,0,7,2,5
7,2,5,6,0,0,0,0,0,0,0,0,0,6,7,2,5
8,7,2,5,0,0,0,0,0,0,0,0,0,7,2,5,8
1,7,2,5,6,0,0,0,0,0,0,0,6,7,2,5,1
1,8,7,2,5,6,6,0,0,0,6,6,7,2,5,8,1
1,1,8,7,2,2,5,6,6,6,7,2,2,5,8,1,1
1,1,1,8,8,7,2,2,2,2,2,5,8,8,1,1,1
1,1,1,1,1,8,8,8,8,8,8,8,1,1,1,1,1
endlayer

layer
1,1,1,1,1,0,0,0,0,0,0,0,1,1,1,1,1
1,1,1,0,0,0,2,0,0,0,2,0,0,0,1,1,1
1,1,0,0,0,0,0,0,0,0,0,0,0,0,0,1,1
1,0,0,2,0,0,0,0,0,0,0,0,0,2,0,0,1
1,0,0,0,0,0,0,0,0,0,0,0,0,0,0,0,1
0,0,0,0,0,0,0,0,0,0,0,0,0,0,0,0,0
0,2,0,0,0,0,0,0,0,0,0,0,0,0,0,2,0
0,0,0,0,0,0,0,0,0,0,0,0,0,0,0,0,0
0,0,0,0,0,0,0,0,0,0,0,0,0,0,0,0,0
0,0,0,0,0,0,0,0,0,0,0,0,0,0,0,0,0
0,2,0,0,0,0,0,0,0,0,0,0,0,0,0,2,0
0,0,0,0,0,0,0,0,0,0,0,0,0,0,0,0,0
1,0,0,0,0,0,0,0,0,0,0,0,0,0,0,0,1
1,0,0,2,0,0,0,0,0,0,0,0,0,2,0,0,1
1,1,0,0,0,0,0,0,0,0,0,0,0,0,0,1,1
1,1,1,0,0,0,2,0,0,0,2,0,0,0,1,1,1
1,1,1,1,1,0,0,0,0,0,0,0,1,1,1,1,1
endlayer

layer
1,1,1,1,1,0,0,0,0,0,0,0,1,1,1,1,1
1,1,1,0,0,0,2,0,0,0,2,0,0,0,1,1,1
1,1,0,0,0,0,0,0,0,0,0,0,0,0,0,1,1
1,0,0,2,0,0,0,0,0,0,0,0,0,2,0,0,1
1,0,0,0,0,0,0,0,0,0,0,0,0,0,0,0,1
0,0,0,0,0,0,0,0,0,0,0,0,0,0,0,0,0
0,2,0,0,0,0,0,0,0,0,0,0,0,0,0,2,0
0,0,0,0,0,0,0,0,0,0,0,0,0,0,0,0,0
0,0,0,0,0,0,0,0,0,0,0,0,0,0,0,0,0
0,0,0,0,0,0,0,0,0,0,0,0,0,0,0,0,0
0,2,0,0,0,0,0,0,0,0,0,0,0,0,0,2,0
0,0,0,0,0,0,0,0,0,0,0,0,0,0,0,0,0
1,0,0,0,0,0,0,0,0,0,0,0,0,0,0,0,1
1,0,0,2,0,0,0,0,0,0,0,0,0,2,0,0,1
1,1,0,0,0,0,0,0,0,0,0,0,0,0,0,1,1
1,1,1,0,0,0,2,0,0,0,2,0,0,0,1,1,1
1,1,1,1,1,0,0,0,0,0,0,0,1,1,1,1,1
endlayer

layer
1,1,1,1,1,0,0,0,0,0,0,0,1,1,1,1,1
1,1,1,0,0,0,2,0,0,0,2,0,0,0,1,1,1
1,1,0,0,0,0,0,0,0,0,0,0,0,0,0,1,1
1,0,0,2,0,0,0,0,0,0,0,0,0,2,0,0,1
1,0,0,0,0,0,0,0,0,0,0,0,0,0,0,0,1
0,0,0,0,0,0,0,0,0,0,0,0,0,0,0,0,0
0,2,0,0,0,0,0,0,0,0,0,0,0,0,0,2,0
0,0,0,0,0,0,0,0,0,0,0,0,0,0,0,0,0
0,0,0,0,0,0,0,0,0,0,0,0,0,0,0,0,0
0,0,0,0,0,0,0,0,0,0,0,0,0,0,0,0,0
0,2,0,0,0,0,0,0,0,0,0,0,0,0,0,2,0
0,0,0,0,0,0,0,0,0,0,0,0,0,0,0,0,0
1,0,0,0,0,0,0,0,0,0,0,0,0,0,0,0,1
1,0,0,2,0,0,0,0,0,0,0,0,0,2,0,0,1
1,1,0,0,0,0,0,0,0,0,0,0,0,0,0,1,1
1,1,1,0,0,0,2,0,0,0,2,0,0,0,1,1,1
1,1,1,1,1,0,0,0,0,0,0,0,1,1,1,1,1
endlayer

layer
1,1,1,1,1,7,6,6,6,6,6,6,1,1,1,1,1
1,1,1,7,6,6,2,2,2,2,2,5,6,6,1,1,1
1,1,7,6,2,2,8,8,8,8,7,2,2,5,6,1,1
1,7,6,2,8,8,5,0,0,0,8,8,7,2,5,6,1
1,7,2,8,5,0,0,0,0,0,0,0,8,7,2,5,1
7,6,2,5,0,0,0,0,0,0,0,0,0,7,2,5,6
7,2,8,5,0,0,0,0,0,0,0,0,0,8,7,2,5
7,2,5,0,0,0,0,0,0,0,0,0,0,0,7,2,5
7,2,5,0,0,0,0,0,0,0,0,0,0,0,7,2,5
7,2,5,0,0,0,0,0,0,0,0,0,0,0,7,2,5
7,2,6,5,0,0,0,0,0,0,0,0,0,7,6,2,5
7,8,2,5,0,0,0,0,0,0,0,0,0,7,2,8,5
1,7,2,6,5,0,0,0,0,0,0,0,7,6,2,5,1
1,7,8,2,6,6,5,0,0,0,7,6,6,2,8,5,1
1,1,7,8,2,2,6,6,6,6,6,2,2,8,5,1,1
1,1,1,7,8,8,2,2,2,2,2,8,8,5,1,1,1
1,1,1,1,1,7,8,8,8,8,8,5,1,1,1,1,1
endlayer

layer
1,1,1,1,1,1,1,1,1,1,1,1,1,1,1,1,1
1,1,1,1,1,1,3,10,10,10,3,1,1,1,1,1,1
1,1,1,1,10,10,0,0,0,0,0,10,10,1,1,1,1
1,1,1,3,0,0,0,0,0,0,0,0,0,3,1,1,1
1,1,10,0,0,0,0,0,0,0,0,0,0,0,10,1,1
1,1,10,0,0,0,0,0,0,0,0,0,0,0,10,1,1
1,3,0,0,0,0,0,0,0,0,0,0,0,0,0,3,1
1,10,0,0,0,0,0,0,0,0,0,0,0,0,0,10,1
1,10,0,0,0,0,0,0,0,0,0,0,0,0,0,10,1
1,10,0,0,0,0,0,0,0,0,0,0,0,0,0,10,1
1,3,0,0,0,0,0,0,0,0,0,0,0,0,0,3,1
1,1,10,0,0,0,0,0,0,0,0,0,0,0,10,1,1
1,1,10,0,0,0,0,0,0,0,0,0,0,0,10,1,1
1,1,1,3,0,0,0,0,0,0,0,0,0,3,1,1,1
1,1,1,1,10,10,0,0,0,0,0,10,10,1,1,1,1
1,1,1,1,1,1,3,10,10,10,3,1,1,1,1,1,1
1,1,1,1,1,1,1,1,1,1,1,1,1,1,1,1,1
endlayer

