
# Created by Ruins mod version 17.0 Ingame Parser
# authoring Player: ST753M

weight=1
embed_into_distance=256
acceptable_target_blocks=grass,dirt,coarse_dirt,podzol,stone,gravel,mycelium,clay,mud,sand,sandstone,red_sand,terracotta,dried_clay,ice,snow,water,stained_hardened_clay,hardened_clay,biomesoplenty:grass,biomesoplenty:dirt
unacceptable_target_blocks=end_stone
dimensions=11,21,21
allowable_overhang=9999
max_leveling=0
leveling_buffer=-1
preserve_water=0
preserve_lava=0

=0,100,air
rule1=0,100,preserveBlock
rule2=0,100,minecraft:stonebrick-0
rule3=0,100,minecraft:glowstone-0
rule4=0,100,minecraft:spruce_stairs-1
rule5=0,100,minecraft:carpet-7
rule6=0,100,minecraft:spruce_stairs-3
rule7=0,100,minecraft:spruce_fence-0
rule8=0,100,minecraft:spruce_stairs-2
rule9=0,100,minecraft:spruce_stairs-0
rule10=0,100,minecraft:carpet-8
rule11=0,100,minecraft:stone_brick_stairs-0
rule12=0,100,minecraft:stone_brick_stairs-3
rule13=0,100,minecraft:stone_brick_stairs-2
rule14=0,100,minecraft:stone_brick_stairs-1
rule15=0,100,minecraft:spruce_fence_gate-3
rule16=0,100,minecraft:stonebrick-3
rule17=0,100,minecraft:trapdoor-1
rule18=0,100,CommandBlock:RUINSTRIGGER /summon villager ~ ~1 ~:@-1
rule19=0,100,minecraft:stone_slab-5

# Sells a number of "dwarven" harvestcraft foods like iron brew
rule20=0,100,CommandBlock:RUINSTRIGGER /summon villager ~ ~1 ~ {Profession:4,Offers:{Recipes:[{rewardExp:0b,maxUses:2147483647,uses:0,buy:{id:"minecraft:wheat",Count:20b},sell:{id:"minecraft:emerald",Count:1b}},{rewardExp:0b,maxUses:2147483647,uses:0,buy:{id:"minecraft:nether_wart",Count:20b},sell:{id:"minecraft:emerald",Count:1b}},{rewardExp:0b,maxUses:2147483647,uses:0,buy:{id:"minecraft:golden_apple",Count:1b},sell:{id:"minecraft:emerald",Count:1b}},{rewardExp:0b,maxUses:2147483647,uses:0,buy:{id:"minecraft:emerald",Count:1b},sell:{id:"harvestcraft:grilledmushroomitem",Count:2b}},{rewardExp:0b,maxUses:2147483647,uses:0,buy:{id:"minecraft:emerald",Count:1b},sell:{id:"harvestcraft:roastedrootveggiemedleyitem",Count:1b}},{rewardExp:0b,maxUses:2147483647,uses:0,buy:{id:"minecraft:emerald",Count:2b},sell:{id:"harvestcraft:ironbrewitem",Count:1b}}]},PersistenceRequired:1}:@-1

rule21=0,100,minecraft:stone_brick_stairs-7
rule22=0,100,minecraft:stone_brick_stairs-6
rule23=0,100,minecraft:stone_brick_stairs-5
rule24=0,100,minecraft:stone_brick_stairs-4
rule25=0,100,minecraft:stone_slab-13

layer
1,1,1,1,1,1,2,2,2,2,2,2,2,2,2,1,1,1,1,1,1
1,1,1,1,1,2,2,2,2,2,2,2,2,2,2,2,1,1,1,1,1
1,1,1,1,1,2,2,2,2,2,2,2,2,2,2,2,1,1,1,1,1
1,1,1,1,1,2,2,2,2,2,3,2,2,2,2,2,1,1,1,1,1
1,1,1,1,2,2,2,2,2,2,2,2,2,2,2,2,2,1,1,1,1
1,2,2,2,2,2,2,2,2,2,2,2,2,2,2,2,2,2,2,2,1
2,2,2,2,2,2,2,2,2,2,2,2,2,2,2,2,2,2,2,2,2
2,2,2,2,2,2,2,2,2,2,3,2,2,2,2,2,2,2,2,2,2
2,2,2,2,2,2,2,2,2,2,2,2,2,2,2,2,2,2,2,2,2
2,2,2,2,2,2,2,2,2,2,2,2,2,2,2,2,2,2,2,2,2
2,2,2,3,2,2,2,3,2,2,3,2,2,3,2,2,2,3,2,2,2
2,2,2,2,2,2,2,2,2,2,2,2,2,2,2,2,2,2,2,2,2
2,2,2,2,2,2,2,2,2,2,2,2,2,2,2,2,2,2,2,2,2
2,2,2,2,2,2,2,2,2,2,3,2,2,2,2,2,2,2,2,2,2
2,2,2,2,2,2,2,2,2,2,2,2,2,2,2,2,2,2,2,2,2
1,2,2,2,2,2,2,2,2,2,2,2,2,2,2,2,2,2,2,2,1
1,1,1,1,2,2,2,2,2,2,2,2,2,2,2,2,2,1,1,1,1
1,1,1,1,1,2,2,2,2,2,2,2,2,2,2,2,1,1,1,1,1
1,1,1,1,1,2,2,2,3,2,2,2,2,3,2,2,1,1,1,1,1
1,1,1,1,1,2,2,2,2,2,2,2,2,2,2,2,1,1,1,1,1
1,1,1,1,1,1,2,2,2,2,2,2,2,2,2,1,1,1,1,1,1
endlayer

layer
1,1,1,1,1,2,2,2,2,2,2,2,2,2,2,2,1,1,1,1,1
1,1,1,1,1,2,2,0,0,0,0,0,0,0,2,2,1,1,1,1,1
1,1,1,1,1,2,0,0,4,5,5,5,4,0,0,2,1,1,1,1,1
1,1,1,1,2,2,0,8,7,6,5,8,7,6,0,2,2,1,1,1,1
1,1,1,2,2,2,0,0,9,5,5,5,9,0,0,2,2,2,1,1,1
2,2,2,2,2,2,0,0,5,5,10,5,5,0,0,2,2,2,2,2,2
2,2,0,0,0,0,12,11,11,5,10,5,11,11,11,0,0,0,0,2,2
2,0,0,4,0,0,12,2,13,5,10,5,12,2,13,0,0,4,0,0,2
2,0,8,7,6,5,12,14,14,5,10,5,14,14,13,5,8,7,6,0,2
2,0,5,9,5,5,5,5,5,5,5,5,5,5,5,5,5,9,5,0,2
2,0,5,5,5,10,10,10,10,5,5,5,10,10,10,10,5,5,5,0,2
2,0,5,4,5,5,5,5,5,5,5,5,5,5,5,5,5,4,5,0,2
2,0,8,7,6,5,12,11,13,5,10,5,11,11,13,5,8,7,6,0,2
2,0,0,9,0,0,12,2,13,5,10,5,12,2,13,0,0,9,0,0,2
2,2,0,0,0,0,12,14,13,5,10,5,14,14,13,0,0,0,0,2,2
2,2,2,2,2,2,0,0,5,5,10,5,5,0,0,2,2,2,2,2,2
1,1,1,2,2,2,0,0,0,5,5,5,0,0,0,2,2,2,1,1,1
1,1,1,1,2,2,15,13,13,13,13,13,13,13,13,2,2,1,1,1,1
1,1,1,1,1,2,5,5,5,5,5,5,5,5,5,2,1,1,1,1,1
1,1,1,1,1,2,2,5,5,5,5,5,5,5,2,2,1,1,1,1,1
1,1,1,1,1,2,2,2,2,2,2,2,2,2,2,2,1,1,1,1,1
endlayer

layer
1,1,1,1,1,1,2,2,2,2,16,2,2,2,2,1,1,1,1,1,1
1,1,1,1,1,2,13,0,0,0,0,0,0,0,12,2,1,1,1,1,1
1,1,1,1,1,2,0,0,0,0,0,0,0,0,0,2,1,1,1,1,1
1,1,1,1,2,0,0,0,17,0,0,0,17,0,0,0,2,1,1,1,1
1,1,1,2,2,2,0,0,0,0,0,0,0,0,0,2,2,2,1,1,1
1,2,2,0,2,16,0,0,0,0,0,0,0,0,0,16,2,0,2,2,1
2,14,0,0,0,0,0,0,0,0,0,0,0,0,0,0,0,0,0,14,2
2,0,0,0,0,0,0,2,0,0,0,0,0,2,0,0,0,0,0,0,2
2,0,0,17,0,0,0,0,0,0,0,0,0,0,0,0,0,17,0,0,2
2,0,0,0,0,0,0,0,0,0,0,0,0,0,0,0,0,0,0,0,2
16,0,0,0,0,0,0,18,0,0,0,0,0,18,0,0,0,0,0,0,16
2,0,0,0,0,0,0,0,0,0,0,0,0,0,0,0,0,0,0,0,2
2,0,0,17,0,0,0,0,0,0,0,0,0,0,0,0,0,17,0,0,2
2,0,0,0,0,0,0,2,0,0,0,0,0,2,0,0,0,0,0,0,2
2,11,0,0,0,0,0,0,0,0,0,0,0,0,0,0,0,0,0,11,2
1,2,2,0,2,16,0,0,0,0,0,0,0,0,0,16,2,0,2,2,1
1,1,1,2,2,2,0,0,0,0,0,0,0,0,0,2,2,2,1,1,1
1,1,1,1,2,0,0,19,19,19,19,19,19,19,12,0,2,1,1,1,1
1,1,1,1,1,2,0,0,0,20,0,0,0,0,0,2,1,1,1,1,1
1,1,1,1,1,2,13,0,0,0,0,0,0,0,12,2,1,1,1,1,1
1,1,1,1,1,1,2,2,2,2,16,2,2,2,2,1,1,1,1,1,1
endlayer

layer
1,1,1,1,1,1,2,2,2,2,2,2,2,2,2,1,1,1,1,1,1
1,1,1,1,1,2,13,0,0,0,0,0,0,0,12,2,1,1,1,1,1
1,1,1,1,1,2,0,0,0,0,0,0,0,0,0,2,1,1,1,1,1
1,1,1,1,2,0,0,0,0,0,0,0,0,0,0,0,2,1,1,1,1
1,1,1,2,2,2,0,0,0,0,0,0,0,0,0,2,2,2,1,1,1
1,2,2,0,2,2,22,0,0,0,0,0,0,0,21,2,2,0,2,2,1
2,14,0,0,0,23,0,0,0,0,0,0,0,0,0,23,0,0,0,14,2
2,0,0,0,0,0,0,2,0,0,0,0,0,2,0,0,0,0,0,0,2
2,0,0,0,0,0,0,0,0,0,0,0,0,0,0,0,0,0,0,0,2
2,0,0,0,0,0,0,0,0,0,0,0,0,0,0,0,0,0,0,0,2
2,0,0,0,0,0,0,0,0,0,0,0,0,0,0,0,0,0,0,0,2
2,0,0,0,0,0,0,0,0,0,0,0,0,0,0,0,0,0,0,0,2
2,0,0,0,0,0,0,0,0,0,0,0,0,0,0,0,0,0,0,0,2
2,0,0,0,0,0,0,2,0,0,0,0,0,2,0,0,0,0,0,0,2
2,11,0,0,0,24,0,0,0,0,0,0,0,0,0,24,0,0,0,11,2
1,2,2,0,2,2,22,0,0,0,0,0,0,0,21,2,2,0,2,2,1
1,1,1,2,2,2,0,0,0,0,0,0,0,0,0,2,2,2,1,1,1
1,1,1,1,2,0,0,0,0,0,0,0,0,0,0,0,2,1,1,1,1
1,1,1,1,1,2,0,0,0,0,0,0,0,0,0,2,1,1,1,1,1
1,1,1,1,1,2,13,0,0,0,0,0,0,0,12,2,1,1,1,1,1
1,1,1,1,1,1,2,2,2,2,2,2,2,2,2,1,1,1,1,1,1
endlayer

layer
1,1,1,1,1,2,2,2,16,2,2,2,16,2,2,2,1,1,1,1,1
1,1,1,1,1,2,13,0,0,0,0,0,0,0,12,2,1,1,1,1,1
1,1,1,1,1,2,0,0,0,0,0,0,0,0,0,2,1,1,1,1,1
1,1,1,1,2,0,0,0,0,0,0,0,0,0,0,0,2,1,1,1,1
1,1,1,2,2,2,0,0,0,0,0,0,0,0,0,2,2,2,1,1,1
2,2,2,0,2,2,2,22,0,0,0,0,0,21,2,2,2,0,2,2,2
2,14,0,0,0,2,0,0,0,0,0,0,0,0,0,2,0,0,0,14,2
2,0,0,0,0,23,0,16,0,0,0,0,0,16,0,23,0,0,0,0,2
16,0,0,0,0,0,0,0,0,0,0,0,0,0,0,0,0,0,0,0,16
2,0,0,0,0,0,0,0,0,0,0,0,0,0,0,0,0,0,0,0,2
2,0,0,0,0,0,0,0,0,0,0,0,0,0,0,0,0,0,0,0,2
2,0,0,0,0,0,0,0,0,0,0,0,0,0,0,0,0,0,0,0,2
16,0,0,0,0,0,0,0,0,0,0,0,0,0,0,0,0,0,0,0,16
2,0,0,0,0,24,0,16,0,0,0,0,0,16,0,24,0,0,0,0,2
2,11,0,0,0,2,0,0,0,0,0,0,0,0,0,2,0,0,0,11,2
2,2,2,0,2,2,2,22,0,0,0,0,0,21,2,2,2,0,2,2,2
1,1,1,2,2,2,0,0,0,0,0,0,0,0,0,2,2,2,1,1,1
1,1,1,1,2,0,0,0,0,0,0,0,0,0,0,0,2,1,1,1,1
1,1,1,1,1,2,0,0,0,0,0,0,0,0,0,2,1,1,1,1,1
1,1,1,1,1,2,13,0,0,0,0,0,0,0,12,2,1,1,1,1,1
1,1,1,1,1,2,2,2,16,2,2,2,16,2,2,2,1,1,1,1,1
endlayer

layer
1,1,1,1,1,2,12,2,2,2,16,2,2,2,13,2,1,1,1,1,1
1,1,1,1,1,2,2,0,0,0,0,0,0,0,2,2,1,1,1,1,1
1,1,1,1,1,2,0,0,0,0,0,0,0,0,0,2,1,1,1,1,1
1,1,1,1,2,2,0,0,0,0,0,0,0,0,0,2,2,1,1,1,1
1,1,1,2,2,2,0,0,0,0,0,0,0,0,0,2,2,2,1,1,1
2,2,2,2,2,2,2,16,22,0,0,0,21,16,2,2,2,2,2,2,2
11,2,0,0,0,2,0,0,0,0,0,0,0,0,0,2,0,0,0,2,11
2,0,0,0,0,16,0,2,0,0,0,0,0,2,0,16,0,0,0,0,2
2,0,0,0,0,23,0,0,0,0,0,0,0,0,0,23,0,0,0,0,2
2,0,0,0,0,0,0,0,0,0,0,0,0,0,0,0,0,0,0,0,2
16,0,0,0,0,0,0,0,0,0,0,0,0,0,0,0,0,0,0,0,16
2,0,0,0,0,0,0,0,0,0,0,0,0,0,0,0,0,0,0,0,2
2,0,0,0,0,24,0,0,0,0,0,0,0,0,0,24,0,0,0,0,2
2,0,0,0,0,16,0,2,0,0,0,0,0,2,0,16,0,0,0,0,2
14,2,0,0,0,2,0,0,0,0,0,0,0,0,0,2,0,0,0,2,14
2,2,2,2,2,2,2,16,22,0,0,0,21,16,2,2,2,2,2,2,2
1,1,1,2,2,2,0,0,0,0,0,0,0,0,0,2,2,2,1,1,1
1,1,1,1,2,2,0,0,0,0,0,0,0,0,0,2,2,1,1,1,1
1,1,1,1,1,2,0,0,0,0,0,0,0,0,0,2,1,1,1,1,1
1,1,1,1,1,2,2,0,0,0,0,0,0,0,2,2,1,1,1,1,1
1,1,1,1,1,2,12,2,2,2,16,2,2,2,13,2,1,1,1,1,1
endlayer

layer
1,1,1,1,1,2,1,12,2,2,2,2,2,13,1,2,1,1,1,1,1
1,1,1,1,1,2,2,22,0,0,0,0,0,21,2,2,1,1,1,1,1
1,1,1,1,1,2,0,0,0,0,0,0,0,0,0,2,1,1,1,1,1
1,1,1,1,1,2,22,0,0,0,0,0,0,0,21,2,1,1,1,1,1
1,1,1,1,2,2,0,0,0,0,0,0,0,0,0,2,2,1,1,1,1
2,2,2,2,2,2,2,2,2,2,2,2,2,2,2,2,2,2,2,2,2
1,2,0,23,0,2,0,0,0,0,0,0,0,0,0,2,0,23,0,2,1
11,23,0,0,0,2,0,2,0,0,0,0,0,2,0,2,0,0,0,23,11
2,0,0,0,0,2,0,0,0,0,0,0,0,0,0,2,0,0,0,0,2
2,0,0,0,0,2,0,0,0,0,0,0,0,0,0,2,0,0,0,0,2
2,0,0,0,0,2,0,0,0,0,0,0,0,0,0,2,0,0,0,0,2
2,0,0,0,0,2,0,0,0,0,0,0,0,0,0,2,0,0,0,0,2
2,0,0,0,0,2,0,0,0,0,0,0,0,0,0,2,0,0,0,0,2
14,24,0,0,0,2,0,2,0,0,0,0,0,2,0,2,0,0,0,24,14
1,2,0,24,0,2,0,0,0,0,0,0,0,0,0,2,0,24,0,2,1
2,2,2,2,2,2,2,2,2,2,2,2,2,2,2,2,2,2,2,2,2
1,1,1,1,2,2,0,0,0,0,0,0,0,0,0,2,2,1,1,1,1
1,1,1,1,1,2,22,0,0,0,0,0,0,0,21,2,1,1,1,1,1
1,1,1,1,1,2,0,0,0,0,0,0,0,0,0,2,1,1,1,1,1
1,1,1,1,1,2,2,22,0,0,0,0,0,21,2,2,1,1,1,1,1
1,1,1,1,1,2,1,12,2,2,2,2,2,13,1,2,1,1,1,1,1
endlayer

layer
1,1,1,1,1,12,22,1,1,12,2,13,1,1,21,13,1,1,1,1,1
1,1,1,1,1,1,2,2,2,22,0,21,2,2,2,1,1,1,1,1,1
1,1,1,1,1,1,2,0,0,0,0,0,0,0,2,1,1,1,1,1,1
1,1,1,1,1,1,2,22,0,0,0,0,0,21,2,1,1,1,1,1,1
1,1,1,1,1,1,2,0,0,0,0,0,0,0,2,1,1,1,1,1,1
11,1,1,1,1,16,2,2,2,2,16,2,2,2,2,16,1,1,1,1,11
23,2,2,2,2,2,2,24,22,0,0,0,24,24,2,2,2,2,2,2,23
1,2,0,23,0,2,21,2,22,0,0,0,21,2,22,2,0,23,0,2,1
1,2,0,0,0,2,21,23,23,0,0,0,21,23,22,2,0,0,0,2,1
11,23,0,0,0,2,0,0,0,0,0,0,0,0,0,2,0,0,0,23,11
2,0,0,0,0,16,0,0,0,0,0,0,0,0,0,16,0,0,0,0,2
14,24,0,0,0,2,0,0,0,0,0,0,0,0,0,2,0,0,0,24,14
1,2,0,0,0,2,21,24,22,0,0,0,24,24,22,2,0,0,0,2,1
1,2,0,24,0,2,21,2,22,0,0,0,21,2,22,2,0,24,0,2,1
24,2,2,2,2,2,2,23,23,0,0,0,23,23,2,2,2,2,2,2,24
14,1,1,1,1,16,2,2,2,2,16,2,2,2,2,16,1,1,1,1,14
1,1,1,1,1,1,2,0,0,0,0,0,0,0,2,1,1,1,1,1,1
1,1,1,1,1,1,2,22,0,0,0,0,0,21,2,1,1,1,1,1,1
1,1,1,1,1,1,2,0,0,0,0,0,0,0,2,1,1,1,1,1,1
1,1,1,1,1,1,2,2,2,22,0,21,2,2,2,1,1,1,1,1,1
1,1,1,1,1,12,22,1,1,12,2,13,1,1,21,13,1,1,1,1,1
endlayer

layer
1,1,1,1,1,1,12,2,22,1,1,1,21,2,13,1,1,1,1,1,1
1,1,1,1,1,1,1,2,2,2,2,2,2,2,1,1,1,1,1,1,1
1,1,1,1,1,1,1,2,2,0,0,0,2,2,1,1,1,1,1,1,1
1,1,1,1,1,1,1,2,2,22,0,21,2,2,1,1,1,1,1,1,1
1,1,1,1,1,1,1,2,2,0,0,0,2,2,1,1,1,1,1,1,1
1,1,1,1,1,1,12,2,2,2,2,2,2,2,13,1,1,1,1,1,1
11,1,1,1,1,11,1,2,2,22,25,21,2,2,1,11,1,1,1,1,11
2,2,2,2,2,2,2,2,2,0,0,0,2,2,2,2,2,2,2,2,2
23,2,2,2,2,2,2,2,2,22,0,21,2,2,2,2,2,2,2,2,23
1,2,0,23,0,2,23,0,23,0,0,0,23,0,23,2,0,23,0,2,1
1,2,0,0,0,2,25,0,0,0,0,0,0,0,25,2,0,0,0,2,1
1,2,0,24,0,2,24,0,24,0,0,0,24,0,24,2,0,24,0,2,1
24,2,2,2,2,2,2,2,2,22,0,21,2,2,2,2,2,2,2,2,24
2,2,2,2,2,2,2,2,2,0,0,0,2,2,2,2,2,2,2,2,2
14,1,1,1,1,14,1,2,2,22,25,21,2,2,1,14,1,1,1,1,14
1,1,1,1,1,1,12,2,2,2,2,2,2,2,13,1,1,1,1,1,1
1,1,1,1,1,1,1,2,2,0,0,0,2,2,1,1,1,1,1,1,1
1,1,1,1,1,1,1,2,2,22,0,21,2,2,1,1,1,1,1,1,1
1,1,1,1,1,1,1,2,2,0,0,0,2,2,1,1,1,1,1,1,1
1,1,1,1,1,1,1,2,2,2,2,2,2,2,1,1,1,1,1,1,1
1,1,1,1,1,1,12,2,22,1,1,1,21,2,13,1,1,1,1,1,1
endlayer

layer
1,1,1,1,1,1,1,12,2,2,2,2,2,13,1,1,1,1,1,1,1
1,1,1,1,1,1,1,1,2,2,2,2,2,1,1,1,1,1,1,1,1
1,1,1,1,1,1,1,1,19,2,2,2,19,1,1,1,1,1,1,1,1
1,1,1,1,1,1,1,1,1,2,2,2,1,1,1,1,1,1,1,1,1
1,1,1,1,1,1,1,1,1,2,2,2,1,1,1,1,1,1,1,1,1
1,1,1,1,1,1,1,1,12,2,2,2,13,1,1,1,1,1,1,1,1
1,1,1,1,1,1,1,1,1,2,2,2,1,1,1,1,1,1,1,1,1
11,1,1,1,1,1,1,1,1,2,2,2,1,1,1,1,1,1,1,1,11
2,2,19,1,1,11,1,1,1,2,2,2,1,1,1,11,1,1,19,2,2
2,2,2,2,2,2,2,2,2,2,25,2,2,2,2,2,2,2,2,2,2
2,2,2,2,2,2,2,2,2,25,0,25,2,2,2,2,2,2,2,2,2
2,2,2,2,2,2,2,2,2,2,25,2,2,2,2,2,2,2,2,2,2
2,2,19,1,1,14,1,1,1,2,2,2,1,1,1,14,1,1,19,2,2
14,1,1,1,1,1,1,1,1,2,2,2,1,1,1,1,1,1,1,1,14
1,1,1,1,1,1,1,1,1,2,2,2,1,1,1,1,1,1,1,1,1
1,1,1,1,1,1,1,1,12,2,2,2,13,1,1,1,1,1,1,1,1
1,1,1,1,1,1,1,1,1,2,2,2,1,1,1,1,1,1,1,1,1
1,1,1,1,1,1,1,1,1,2,2,2,1,1,1,1,1,1,1,1,1
1,1,1,1,1,1,1,1,19,2,2,2,19,1,1,1,1,1,1,1,1
1,1,1,1,1,1,1,1,2,2,2,2,2,1,1,1,1,1,1,1,1
1,1,1,1,1,1,1,12,2,2,2,2,2,13,1,1,1,1,1,1,1
endlayer

layer
1,1,1,1,1,1,1,1,19,19,2,19,19,1,1,1,1,1,1,1,1
1,1,1,1,1,1,1,1,1,19,2,19,1,1,1,1,1,1,1,1,1
1,1,1,1,1,1,1,1,1,1,2,1,1,1,1,1,1,1,1,1,1
1,1,1,1,1,1,1,1,1,1,19,1,1,1,1,1,1,1,1,1,1
1,1,1,1,1,1,1,1,1,1,1,1,1,1,1,1,1,1,1,1,1
1,1,1,1,1,1,1,1,1,1,1,1,1,1,1,1,1,1,1,1,1
1,1,1,1,1,1,1,1,1,1,1,1,1,1,1,1,1,1,1,1,1
1,1,1,1,1,1,1,1,1,1,19,1,1,1,1,1,1,1,1,1,1
19,1,1,1,1,1,1,1,1,11,11,11,1,1,1,1,1,1,1,1,19
19,19,1,1,1,1,1,1,12,2,2,2,13,1,1,1,1,1,1,19,19
2,2,2,19,1,1,1,19,12,2,16,2,13,19,1,1,1,19,2,2,2
19,19,1,1,1,1,1,1,12,2,2,2,13,1,1,1,1,1,1,19,19
19,1,1,1,1,1,1,1,1,14,14,14,1,1,1,1,1,1,1,1,19
1,1,1,1,1,1,1,1,1,1,19,1,1,1,1,1,1,1,1,1,1
1,1,1,1,1,1,1,1,1,1,1,1,1,1,1,1,1,1,1,1,1
1,1,1,1,1,1,1,1,1,1,1,1,1,1,1,1,1,1,1,1,1
1,1,1,1,1,1,1,1,1,1,1,1,1,1,1,1,1,1,1,1,1
1,1,1,1,1,1,1,1,1,1,19,1,1,1,1,1,1,1,1,1,1
1,1,1,1,1,1,1,1,1,1,2,1,1,1,1,1,1,1,1,1,1
1,1,1,1,1,1,1,1,1,19,2,19,1,1,1,1,1,1,1,1,1
1,1,1,1,1,1,1,1,19,19,2,19,19,1,1,1,1,1,1,1,1
endlayer

