
# Created by Ruins mod version 17.0 Ingame Parser
# authoring Player: ST753M

weight=1
embed_into_distance=1
uniqueMinDistance=2000
acceptable_target_blocks=
unacceptable_target_blocks=flowing_water,water,flowing_lava,lava,ice,bedrock,netherrack,nether_brick,nether_brick_fence,soul_sand,quartz_ore,end_stone,obsidian,iron_bars,Natura:Cloud,slime_grass,slime_congealed,slime_dirt,clouds,natura:clouds
dimensions=14,20,15
allowable_overhang=1
max_leveling=1
leveling_buffer=0
preserve_water=0
preserve_lava=0

adjoining_template=ST753M/753_SmallVillageHut1;20;20;10;90
adjoining_template=plains/753_House_Orchard;25;20;-15;90
adjoining_template=ST753M/753_SmallVillageHut1;-20;20;10;90
adjoining_template=ST753M/753_SmallVillageHut1;-20;20;-10;90
adjoining_template=ST753M/753_SmallVillageHut2;10;20;20;90
adjoining_template=ST753M/753_SmallVillageHut2;10;20;-20;90
adjoining_template=plains/753_House_Orchard;-15;20;25;90
adjoining_template=ST753M/753_SmallVillageHut2;-10;20;-20;90

biomesToSpawnIn=plains,chaparral,grassland,orchard

=0,100,air
rule1=0,100,minecraft:log-0
rule2=0,100,preserveBlock
rule3=0,100,minecraft:brick_block-0
rule4=0,100,minecraft:log-4
rule5=0,100,minecraft:oak_stairs-3
rule6=0,100,minecraft:oak_stairs-1
rule7=0,100,minecraft:planks-0
rule8=0,100,minecraft:log-8
rule9=0,100,minecraft:netherrack-0
rule10=0,100,minecraft:spruce_fence-0
rule11=0,100,minecraft:leaves-4
rule12=0,100,minecraft:spruce_stairs-3
rule13=0,100,minecraft:spruce_stairs-2
rule14=0,100,minecraft:spruce_stairs-1
rule15=0,100,minecraft:spruce_stairs-0
rule16=0,100,minecraft:wooden_door-3

rule17=0,100,CommandBlock:RUINSTRIGGER /summon villager ~ ~1 ~:@-1

rule18=0,100,minecraft:fence_gate-3

rule19=0,100,CommandBlock:RUINSTRIGGER /summon villager ~ ~1 ~ {CustomName:"Barista",CustomNameVisible:1,Profession:0,Offers:{Recipes:[{rewardExp:0b,maxUses:2147483647,uses:0,buy:{id:"minecraft:emerald",Count:1b},sell:{id:"harvestcraft:coffeeitem",Count:1b}},{rewardExp:0b,maxUses:2147483647,uses:0,buy:{id:"minecraft:emerald",Count:1b},sell:{id:"harvestcraft:teaitem",Count:1b}},{rewardExp:0b,maxUses:2147483647,uses:0,buy:{id:"minecraft:emerald",Count:1b},sell:{id:"harvestcraft:greenteaitem",Count:1b}},{rewardExp:0b,maxUses:2147483647,uses:0,buy:{id:"minecraft:emerald",Count:1b},sell:{id:"harvestcraft:rosepetalteaitem",Count:1b}},{rewardExp:0b,maxUses:2147483647,uses:0,buy:{id:"minecraft:emerald",Count:1b},sell:{id:"harvestcraft:earlgreyteaitem",Count:1b}},{rewardExp:0b,maxUses:2147483647,uses:0,buy:{id:"minecraft:emerald",Count:1b},sell:{id:"harvestcraft:chaiteaitem",Count:1b}},{rewardExp:0b,maxUses:2147483647,uses:0,buy:{id:"minecraft:emerald",Count:1b},sell:{id:"harvestcraft:raspberryicedteaitem",Count:1b}},{rewardExp:0b,maxUses:2147483647,uses:0,buy:{id:"minecraft:emerald",Count:2b},sell:{id:"harvestcraft:espressoitem",Count:1b}},{rewardExp:0b,maxUses:2147483647,uses:0,buy:{id:"minecraft:emerald",Count:2b},sell:{id:"harvestcraft:coffeeconlecheitem",Count:1b}},{rewardExp:0b,maxUses:2147483647,uses:0,buy:{id:"minecraft:emerald",Count:2b},sell:{id:"harvestcraft:sweetteaitem",Count:1b}},{rewardExp:0b,maxUses:2147483647,uses:0,buy:{id:"minecraft:emerald",Count:2b},sell:{id:"harvestcraft:bubbleteaitem",Count:1b}},{rewardExp:0b,maxUses:2147483647,uses:0,buy:{id:"minecraft:emerald",Count:2b},sell:{id:"harvestcraft:lemonaideitem",Count:1b}},{rewardExp:0b,maxUses:2147483647,uses:0,buy:{id:"minecraft:emerald",Count:1b},sell:{id:"harvestcraft:pumpkinmuffinitem",Count:1b}},{rewardExp:0b,maxUses:2147483647,uses:0,buy:{id:"minecraft:emerald",Count:1b},sell:{id:"harvestcraft:durianmuffinitem",Count:1b}},{rewardExp:0b,maxUses:2147483647,uses:0,buy:{id:"minecraft:emerald",Count:1b},sell:{id:"harvestcraft:blueberrymuffinitem",Count:1b}},{rewardExp:0b,maxUses:2147483647,uses:0,buy:{id:"minecraft:emerald",Count:2b},sell:{id:"harvestcraft:honeybreaditem",Count:1b}},{rewardExp:0b,maxUses:2147483647,uses:0,buy:{id:"minecraft:emerald",Count:2b},sell:{id:"harvestcraft:mochaicecreamitem",Count:1b}},{rewardExp:0b,maxUses:2147483647,uses:0,buy:{id:"minecraft:emerald",Count:2b},sell:{id:"harvestcraft:raspberrytrifleitem",Count:1b}},{rewardExp:0b,maxUses:2147483647,uses:0,buy:{id:"minecraft:emerald",Count:2b},sell:{id:"harvestcraft:softpretzelitem",Count:1b}},{rewardExp:0b,maxUses:2147483647,uses:0,buy:{id:"minecraft:emerald",Count:3b},sell:{id:"harvestcraft:honeybunitem",Count:1b}},{rewardExp:0b,maxUses:2147483647,uses:0,buy:{id:"minecraft:emerald",Count:1b},sell:{id:"harvestcraft:donutitem",Count:1b}},{rewardExp:0b,maxUses:2147483647,uses:0,buy:{id:"minecraft:emerald",Count:2b},sell:{id:"harvestcraft:powdereddonutitem",Count:1b}},{rewardExp:0b,maxUses:2147483647,uses:0,buy:{id:"minecraft:emerald",Count:2b},sell:{id:"harvestcraft:chocolatedonutitem",Count:1b}},{rewardExp:0b,maxUses:2147483647,uses:0,buy:{id:"minecraft:emerald",Count:2b},sell:{id:"harvestcraft:jellydonutitem",Count:1b}},{rewardExp:0b,maxUses:2147483647,uses:0,buy:{id:"minecraft:emerald",Count:3b},sell:{id:"harvestcraft:cinnamonsugardonutitem",Count:1b}},{rewardExp:0b,maxUses:2147483647,uses:0,buy:{id:"minecraft:emerald",Count:3b},sell:{id:"harvestcraft:frosteddonutitem",Count:1b}},{rewardExp:0b,maxUses:2147483647,uses:0,buy:{id:"minecraft:emerald",Count:3b},sell:{id:"harvestcraft:sugarcookieitem",Count:1b}},{rewardExp:0b,maxUses:2147483647,uses:0,buy:{id:"minecraft:emerald",Count:10b},sell:{id:"harvestcraft:weekendpicnicitem",Count:1b}},{rewardExp:0b,maxUses:2147483647,uses:0,buy:{id:"harvestcraft:honeyitem",Count:16b},sell:{id:"minecraft:emerald",Count:1b}},{rewardExp:0b,maxUses:2147483647,uses:0,buy:{id:"minecraft:sugar",Count:16b},sell:{id:"minecraft:emerald",Count:1b}},{rewardExp:0b,maxUses:2147483647,uses:0,buy:{id:"harvestcraft:heavycreamitem",Count:16b},sell:{id:"minecraft:emerald",Count:1b}},{rewardExp:0b,maxUses:2147483647,uses:0,buy:{id:"harvestcraft:gingeritem",Count:16b},sell:{id:"minecraft:emerald",Count:1b}},{rewardExp:0b,maxUses:2147483647,uses:0,buy:{id:"harvestcraft:spiceleafitem",Count:16b},sell:{id:"minecraft:emerald",Count:1b}},{rewardExp:0b,maxUses:2147483647,uses:0,buy:{id:"harvestcraft:tealeafitem",Count:16b},sell:{id:"minecraft:emerald",Count:1b}},{rewardExp:0b,maxUses:2147483647,uses:0,buy:{id:"harvestcraft:groundcinnamonitem",Count:16b},sell:{id:"minecraft:emerald",Count:1b}},{rewardExp:0b,maxUses:2147483647,uses:0,buy:{id:"harvestcraft:coffeebeanitem",Count:16b},sell:{id:"minecraft:emerald",Count:1b}}]}}:@-1

rule20=0,100,minecraft:crafting_table-0
rule21=0,100,minecraft:iron_bars-0
rule22=0,100,minecraft:furnace-4
rule23=0,100,minecraft:fire-15
rule24=0,100,minecraft:carpet-12
rule25=0,100,minecraft:stained_glass_pane-8
rule26=0,100,minecraft:wooden_door-8
rule27=0,100,minecraft:stone_slab-0
rule28=2,100,minecraft:torch-2
rule29=2,100,minecraft:torch-4
rule30=0,100,minecraft:double_stone_slab-0
rule31=2,100,WallSign:null:null:null:null-4
rule32=0,100,minecraft:double_stone_slab-1
rule33=0,100,minecraft:stone_slab-8
rule34=0,100,minecraft:stone_slab-9
rule35=2,100,minecraft:torch-1
rule36=2,100,minecraft:torch-3
rule37=0,100,minecraft:brick_stairs-7
rule38=0,100,minecraft:brick_stairs-6
rule39=0,100,minecraft:brick_stairs-1
rule40=0,100,minecraft:stone_slab-1
rule41=0,100,minecraft:spruce_stairs-7
rule42=0,100,minecraft:spruce_stairs-5
rule43=0,100,minecraft:spruce_stairs-6
rule44=0,100,minecraft:spruce_stairs-4
rule45=0,100,minecraft:wooden_slab-9
rule46=0,100,minecraft:brick_stairs-2
rule47=0,100,minecraft:brick_stairs-3
rule48=0,100,minecraft:wooden_slab-1
rule49=0,100,minecraft:planks-1

layer
2,1,2,2,2,1,2,2,2,1,2,2,2,2,1
5,4,3,3,3,3,3,3,3,3,3,3,3,3,2
5,4,3,3,3,3,3,3,3,3,3,3,3,3,2
5,4,3,3,3,3,3,3,3,3,3,3,3,3,2
5,4,3,3,3,3,3,3,3,3,3,3,3,3,2
2,1,3,3,3,3,3,3,3,3,3,3,3,3,1
2,2,3,3,3,3,3,3,3,3,3,3,3,3,2
2,2,3,3,3,3,3,3,3,3,3,3,3,3,2
2,2,3,3,3,3,3,3,3,3,3,3,3,3,2
2,1,3,3,3,3,3,3,3,3,3,3,3,3,1
2,2,3,3,3,3,3,3,3,3,3,3,3,3,2
2,2,3,3,3,3,3,3,3,3,3,3,3,3,2
2,2,3,3,3,3,3,3,3,3,3,3,3,3,2
2,1,3,3,3,3,3,3,3,3,3,3,3,3,1
2,2,3,3,3,3,3,3,3,3,3,3,3,3,2
2,2,3,3,3,3,3,3,3,3,3,3,3,3,2
2,2,3,3,3,3,3,3,3,3,3,3,3,3,2
2,1,2,3,3,3,3,3,2,1,3,3,3,3,1
2,2,2,3,3,3,3,3,2,2,6,6,6,6,2
2,2,2,2,3,3,3,2,2,2,2,2,2,2,2
endlayer

layer
2,1,7,7,7,1,7,7,7,1,7,7,7,7,1
2,5,7,1,7,7,7,1,7,7,7,7,7,1,7
2,5,7,7,7,7,7,7,7,7,7,7,7,7,7
2,5,7,7,7,7,7,7,7,7,7,7,7,7,7
2,5,7,1,7,7,7,1,7,7,7,7,7,7,7
2,1,8,8,8,1,8,8,8,1,7,7,7,7,1
2,4,7,7,7,7,7,7,7,4,7,7,7,7,7
2,4,7,7,7,7,7,7,7,4,7,7,7,1,7
2,4,7,7,7,7,7,7,7,4,7,7,7,7,7
2,1,7,7,7,7,7,7,7,1,7,7,7,7,1
2,4,7,7,7,7,7,7,7,4,7,7,7,7,7
2,4,7,7,7,7,7,7,7,4,1,7,7,1,7
2,4,7,7,7,7,7,7,7,4,7,7,7,7,7
2,1,7,7,7,7,7,7,7,1,7,7,7,7,1
2,4,7,7,7,7,7,7,7,4,7,7,7,7,7
2,4,7,7,7,7,7,7,7,4,1,7,7,1,7
2,4,7,3,3,3,3,3,7,4,7,7,7,7,7
2,1,8,3,3,3,3,3,8,1,6,6,6,6,1
2,2,2,3,3,9,3,3,2,2,2,2,2,2,2
2,2,2,3,3,3,3,3,2,2,2,2,2,2,2
endlayer

layer
2,1,10,10,10,1,10,10,10,1,10,10,10,10,1
2,0,0,11,13,10,12,11,0,0,0,0,0,11,10
2,0,0,0,0,0,0,0,0,0,0,14,0,0,10
2,0,0,0,0,0,0,0,0,0,13,10,12,0,10
2,0,0,11,13,10,12,11,0,0,0,15,0,0,10
2,1,3,3,3,1,3,3,3,1,0,0,0,0,1
2,3,0,0,0,14,0,0,0,3,0,0,0,0,10
2,3,0,0,13,10,12,0,0,16,0,0,0,11,10
2,3,14,0,0,15,0,0,14,3,14,0,0,14,10
2,1,10,0,0,0,0,0,10,1,10,0,0,10,1
2,3,15,0,0,0,0,0,15,3,15,0,0,15,10
2,3,0,0,0,0,0,0,0,3,11,0,0,11,10
2,3,0,0,0,17,17,0,0,3,14,0,0,14,10
2,1,18,13,13,13,13,13,13,1,10,0,0,10,1
2,3,0,0,0,0,0,0,0,3,15,0,0,15,10
2,3,0,0,0,19,0,0,0,3,11,0,0,11,10
2,3,20,20,21,21,21,20,20,3,0,0,0,0,10
2,1,3,3,0,0,0,3,3,1,0,0,0,0,1
2,2,2,3,22,23,22,3,2,2,2,2,2,2,2
2,2,2,3,3,3,3,3,2,2,2,2,2,2,2
endlayer

layer
2,10,0,0,0,10,0,0,0,10,0,0,0,0,10
2,0,0,0,0,24,0,0,0,0,0,0,0,0,0
2,0,0,0,0,0,0,0,0,0,0,0,0,0,0
2,0,0,0,0,0,0,0,0,0,0,24,0,0,0
2,0,0,0,0,24,0,0,0,0,0,0,0,0,0
2,1,3,25,3,1,3,25,3,1,0,0,0,0,10
2,3,0,0,0,0,0,0,0,3,0,0,0,0,0
2,25,0,0,0,24,0,0,0,26,0,0,0,0,0
2,3,0,0,0,0,0,0,0,3,0,0,0,0,0
2,1,24,0,0,0,0,0,24,1,24,0,0,24,10
2,3,0,0,0,0,0,0,0,3,0,0,0,0,0
2,25,0,0,0,0,0,0,0,25,0,0,0,0,0
2,3,0,0,0,0,0,0,0,3,0,0,0,0,0
2,1,0,27,27,27,27,27,27,1,24,0,0,24,10
2,3,0,0,0,0,0,0,0,3,0,0,0,0,0
2,25,0,0,0,0,0,0,0,25,0,0,0,0,0
2,3,27,27,0,0,0,27,27,3,0,0,0,0,0
2,1,3,3,0,0,0,3,3,1,0,0,0,0,10
2,2,2,3,22,21,22,3,2,2,2,2,2,2,2
2,2,2,3,3,3,3,3,2,2,2,2,2,2,2
endlayer

layer
2,10,0,0,0,10,0,0,0,10,0,0,0,0,10
2,0,0,0,0,0,0,0,0,0,0,0,0,0,0
2,0,0,0,0,0,0,0,0,0,0,0,0,0,0
2,0,0,0,0,0,0,0,0,0,0,0,0,0,0
2,28,0,0,0,28,0,0,0,28,0,0,0,0,0
2,1,3,25,3,1,3,25,3,1,29,0,0,0,10
2,3,0,0,0,0,0,0,0,3,0,0,0,0,0
2,25,0,0,0,0,0,0,0,30,0,0,0,0,0
2,3,0,0,0,0,0,0,0,3,0,0,0,0,0
2,1,0,0,0,0,0,0,0,1,29,0,0,0,10
2,3,0,0,0,0,0,0,0,3,0,0,0,0,0
2,25,0,0,0,0,0,0,0,25,0,0,0,0,0
2,3,0,0,0,0,0,0,0,3,0,0,0,0,0
2,1,0,0,0,0,0,0,0,1,29,0,0,0,10
2,3,0,0,0,0,0,0,0,3,0,0,0,0,0
2,25,0,0,0,0,0,0,0,25,0,0,0,0,0
2,3,31,31,0,0,0,31,31,3,0,0,0,0,0
2,1,3,3,0,0,0,3,3,1,29,0,0,0,10
2,2,2,3,27,27,27,3,2,2,2,2,2,2,2
2,2,2,3,3,3,3,3,2,2,2,2,2,2,2
endlayer

layer
2,30,34,33,34,30,34,33,34,30,34,33,34,33,32
2,33,34,33,34,33,34,33,34,33,34,33,34,33,33
2,33,34,33,34,33,34,33,34,33,34,33,34,34,34
2,0,0,0,0,0,0,0,0,0,0,0,33,33,33
2,0,0,0,0,0,0,0,0,0,0,0,34,34,34
2,1,3,3,3,1,3,3,3,1,0,0,33,33,30
2,3,0,0,0,35,0,0,0,3,0,0,34,34,34
2,3,0,0,0,0,0,0,0,3,0,0,33,33,33
2,3,0,0,0,0,0,0,0,3,0,0,34,34,34
2,1,29,0,0,0,0,0,36,1,0,0,33,33,30
2,3,0,0,0,0,0,0,0,3,0,0,34,34,34
2,3,0,0,0,0,0,0,0,3,0,0,33,33,33
2,3,0,0,0,0,0,0,0,3,0,0,34,34,34
2,1,29,0,0,0,0,0,36,1,0,0,33,33,30
2,3,0,0,0,0,0,0,0,3,0,0,34,34,34
2,3,0,0,0,0,0,0,0,3,0,0,33,33,33
2,3,0,31,31,0,31,31,0,3,0,0,34,34,34
2,1,3,3,38,0,37,3,3,1,0,0,33,33,30
2,2,2,3,0,0,0,3,2,2,2,2,2,2,2
2,2,2,39,3,3,3,39,2,2,2,2,2,2,2
endlayer

layer
2,2,2,2,2,2,2,2,2,2,2,2,2,2,2
2,2,2,2,2,2,2,2,2,2,2,2,2,2,2
2,27,40,27,40,27,40,27,40,27,40,27,2,2,2
2,30,32,30,32,30,32,30,32,30,32,27,27,2,2
15,30,32,30,32,30,32,30,32,30,32,32,40,2,2
12,1,8,8,8,1,8,8,8,1,30,30,27,2,2
12,4,0,0,0,0,0,0,0,4,32,32,40,2,2
12,4,0,0,0,0,0,0,0,4,30,30,27,2,2
12,4,0,0,0,0,0,0,0,4,32,32,40,2,2
12,1,0,0,0,0,0,0,0,1,30,30,27,2,2
12,4,0,0,0,0,0,0,0,4,32,32,40,2,2
12,4,0,0,0,0,0,0,0,4,30,30,27,2,2
12,4,0,0,0,0,0,0,0,4,32,32,40,2,2
12,1,0,0,0,0,0,0,0,1,30,30,27,2,2
12,4,0,0,0,0,0,0,0,4,32,32,40,2,2
12,4,0,0,0,0,0,0,0,4,30,30,27,2,2
12,4,31,31,0,0,0,31,31,4,32,32,40,2,2
12,1,3,3,3,3,3,3,3,1,30,30,27,2,2
12,14,14,3,0,0,0,3,2,2,2,2,2,2,2
2,2,2,2,3,3,3,2,2,2,2,2,2,2,2
endlayer

layer
2,2,2,2,2,2,2,2,2,2,2,2,2,2,2
2,2,2,2,2,2,2,2,2,2,2,2,2,2,2
2,2,2,2,2,2,2,2,2,2,2,2,2,2,2
2,2,2,2,2,2,2,2,2,2,2,2,2,2,2
2,27,40,27,40,27,40,27,40,27,40,2,2,2,2
2,15,15,15,15,15,15,15,15,15,27,2,2,2,2
2,12,42,42,42,42,42,42,41,13,40,2,2,2,2
2,12,43,0,0,0,0,0,41,13,27,2,2,2,2
2,12,43,0,0,0,0,0,41,13,40,2,2,2,2
2,12,43,0,0,0,0,0,41,13,27,2,2,2,2
2,12,43,0,0,0,0,0,41,13,40,2,2,2,2
2,12,43,0,0,0,0,0,41,13,27,2,2,2,2
2,12,43,0,0,0,0,0,41,13,40,2,2,2,2
2,12,43,0,0,0,0,0,41,13,27,2,2,2,2
2,12,43,0,0,0,0,0,41,13,40,2,2,2,2
2,12,43,0,0,0,0,0,41,13,27,2,2,2,2
2,12,43,44,44,44,44,44,41,13,40,2,2,2,2
2,14,14,3,3,3,3,3,14,14,27,2,2,2,2
2,2,2,3,0,0,0,3,2,2,2,2,2,2,2
2,2,2,2,39,3,39,2,2,2,2,2,2,2,2
endlayer

layer
2,2,2,2,2,2,2,2,2,2,2,2,2,2,2
2,2,2,2,2,2,2,2,2,2,2,2,2,2,2
2,2,2,2,2,2,2,2,2,2,2,2,2,2,2
2,2,2,2,2,2,2,2,2,2,2,2,2,2,2
2,2,2,2,2,2,2,2,2,2,2,2,2,2,2
2,2,12,45,0,0,0,45,13,2,2,2,2,2,2
2,2,12,3,3,25,3,3,13,2,2,2,2,2,2
2,2,12,45,0,0,0,45,13,2,2,2,2,2,2
2,2,12,45,0,0,0,45,13,2,2,2,2,2,2
2,2,12,45,0,0,0,45,13,2,2,2,2,2,2
2,2,12,45,0,0,0,45,13,2,2,2,2,2,2
2,2,12,45,0,0,0,45,13,2,2,2,2,2,2
2,2,12,45,0,0,0,45,13,2,2,2,2,2,2
2,2,12,45,0,0,0,45,13,2,2,2,2,2,2
2,2,12,45,0,0,0,45,13,2,2,2,2,2,2
2,2,12,45,0,0,0,45,13,2,2,2,2,2,2
2,2,12,3,3,3,3,3,13,2,2,2,2,2,2
2,2,2,3,3,3,3,3,2,2,2,2,2,2,2
2,2,2,47,3,0,3,46,2,2,2,2,2,2,2
2,2,2,2,2,3,2,2,2,2,2,2,2,2,2
endlayer

layer
2,2,2,2,2,2,2,2,2,2,2,2,2,2,2
2,2,2,2,2,2,2,2,2,2,2,2,2,2,2
2,2,2,2,2,2,2,2,2,2,2,2,2,2,2
2,2,2,2,2,2,2,2,2,2,2,2,2,2,2
2,2,2,2,2,2,2,2,2,2,2,2,2,2,2
2,2,2,48,49,45,49,48,2,2,2,2,2,2,2
2,2,2,48,49,3,49,48,2,2,2,2,2,2,2
2,2,2,48,49,4,49,48,2,2,2,2,2,2,2
2,2,2,48,49,4,49,48,2,2,2,2,2,2,2
2,2,2,48,49,4,49,48,2,2,2,2,2,2,2
2,2,2,48,49,4,49,48,2,2,2,2,2,2,2
2,2,2,48,49,4,49,48,2,2,2,2,2,2,2
2,2,2,48,49,4,49,48,2,2,2,2,2,2,2
2,2,2,48,49,4,49,48,2,2,2,2,2,2,2
2,2,2,48,49,4,49,48,2,2,2,2,2,2,2
2,2,2,48,49,4,49,48,2,2,2,2,2,2,2
2,2,2,48,49,3,49,48,2,2,2,2,2,2,2
2,2,2,47,3,3,3,46,2,2,2,2,2,2,2
2,2,2,2,3,0,3,2,2,2,2,2,2,2,2
2,2,2,2,2,39,2,2,2,2,2,2,2,2,2
endlayer

layer
2,2,2,2,2,2,2,2,2,2,2,2,2,2,2
2,2,2,2,2,2,2,2,2,2,2,2,2,2,2
2,2,2,2,2,2,2,2,2,2,2,2,2,2,2
2,2,2,2,2,2,2,2,2,2,2,2,2,2,2
2,2,2,2,2,2,2,2,2,2,2,2,2,2,2
2,2,2,2,2,49,2,2,2,2,2,2,2,2,2
2,2,2,2,2,48,2,2,2,2,2,2,2,2,2
2,2,2,2,2,48,2,2,2,2,2,2,2,2,2
2,2,2,2,2,48,2,2,2,2,2,2,2,2,2
2,2,2,2,2,48,2,2,2,2,2,2,2,2,2
2,2,2,2,2,48,2,2,2,2,2,2,2,2,2
2,2,2,2,2,48,2,2,2,2,2,2,2,2,2
2,2,2,2,2,48,2,2,2,2,2,2,2,2,2
2,2,2,2,2,48,2,2,2,2,2,2,2,2,2
2,2,2,2,2,48,2,2,2,2,2,2,2,2,2
2,2,2,2,2,48,2,2,2,2,2,2,2,2,2
2,2,2,2,2,48,2,2,2,2,2,2,2,2,2
2,2,2,2,3,3,3,2,2,2,2,2,2,2,2
2,2,2,2,3,3,3,2,2,2,2,2,2,2,2
2,2,2,2,2,2,2,2,2,2,2,2,2,2,2
endlayer

layer
2,2,2,2,2,2,2,2,2,2,2,2,2,2,2
2,2,2,2,2,2,2,2,2,2,2,2,2,2,2
2,2,2,2,2,2,2,2,2,2,2,2,2,2,2
2,2,2,2,2,2,2,2,2,2,2,2,2,2,2
2,2,2,2,2,2,2,2,2,2,2,2,2,2,2
2,2,2,2,2,2,2,2,2,2,2,2,2,2,2
2,2,2,2,2,2,2,2,2,2,2,2,2,2,2
2,2,2,2,2,2,2,2,2,2,2,2,2,2,2
2,2,2,2,2,2,2,2,2,2,2,2,2,2,2
2,2,2,2,2,2,2,2,2,2,2,2,2,2,2
2,2,2,2,2,2,2,2,2,2,2,2,2,2,2
2,2,2,2,2,2,2,2,2,2,2,2,2,2,2
2,2,2,2,2,2,2,2,2,2,2,2,2,2,2
2,2,2,2,2,2,2,2,2,2,2,2,2,2,2
2,2,2,2,2,2,2,2,2,2,2,2,2,2,2
2,2,2,2,2,2,2,2,2,2,2,2,2,2,2
2,2,2,2,2,2,2,2,2,2,2,2,2,2,2
2,2,2,2,3,3,3,2,2,2,2,2,2,2,2
2,2,2,2,3,3,3,2,2,2,2,2,2,2,2
2,2,2,2,2,2,2,2,2,2,2,2,2,2,2
endlayer

layer
2,2,2,2,2,2,2,2,2,2,2,2,2,2,2
2,2,2,2,2,2,2,2,2,2,2,2,2,2,2
2,2,2,2,2,2,2,2,2,2,2,2,2,2,2
2,2,2,2,2,2,2,2,2,2,2,2,2,2,2
2,2,2,2,2,2,2,2,2,2,2,2,2,2,2
2,2,2,2,2,2,2,2,2,2,2,2,2,2,2
2,2,2,2,2,2,2,2,2,2,2,2,2,2,2
2,2,2,2,2,2,2,2,2,2,2,2,2,2,2
2,2,2,2,2,2,2,2,2,2,2,2,2,2,2
2,2,2,2,2,2,2,2,2,2,2,2,2,2,2
2,2,2,2,2,2,2,2,2,2,2,2,2,2,2
2,2,2,2,2,2,2,2,2,2,2,2,2,2,2
2,2,2,2,2,2,2,2,2,2,2,2,2,2,2
2,2,2,2,2,2,2,2,2,2,2,2,2,2,2
2,2,2,2,2,2,2,2,2,2,2,2,2,2,2
2,2,2,2,2,2,2,2,2,2,2,2,2,2,2
2,2,2,2,2,2,2,2,2,2,2,2,2,2,2
2,2,2,2,3,3,3,2,2,2,2,2,2,2,2
2,2,2,2,3,3,3,2,2,2,2,2,2,2,2
2,2,2,2,2,2,2,2,2,2,2,2,2,2,2
endlayer

layer
2,2,2,2,2,2,2,2,2,2,2,2,2,2,2
2,2,2,2,2,2,2,2,2,2,2,2,2,2,2
2,2,2,2,2,2,2,2,2,2,2,2,2,2,2
2,2,2,2,2,2,2,2,2,2,2,2,2,2,2
2,2,2,2,2,2,2,2,2,2,2,2,2,2,2
2,2,2,2,2,2,2,2,2,2,2,2,2,2,2
2,2,2,2,2,2,2,2,2,2,2,2,2,2,2
2,2,2,2,2,2,2,2,2,2,2,2,2,2,2
2,2,2,2,2,2,2,2,2,2,2,2,2,2,2
2,2,2,2,2,2,2,2,2,2,2,2,2,2,2
2,2,2,2,2,2,2,2,2,2,2,2,2,2,2
2,2,2,2,2,2,2,2,2,2,2,2,2,2,2
2,2,2,2,2,2,2,2,2,2,2,2,2,2,2
2,2,2,2,2,2,2,2,2,2,2,2,2,2,2
2,2,2,2,2,2,2,2,2,2,2,2,2,2,2
2,2,2,2,2,2,2,2,2,2,2,2,2,2,2
2,2,2,2,2,2,2,2,2,2,2,2,2,2,2
2,2,2,2,27,27,27,2,2,2,2,2,2,2,2
2,2,2,2,27,27,27,2,2,2,2,2,2,2,2
2,2,2,2,2,2,2,2,2,2,2,2,2,2,2
endlayer

