
# Created by Ruins mod version 16.7 Ingame Parser
# authoring Player: ST753M

weight=1
uniqueMinDistance=2000
embed_into_distance=3
acceptable_target_blocks=
unacceptable_target_blocks=flowing_water,water,flowing_lava,lava,ice,bedrock,netherrack,nether_brick,nether_brick_fence,soul_sand,quartz_ore,end_stone,obsidian,iron_bars,Natura:Cloud,slime_grass,slime_congealed,slime_dirt
dimensions=11,19,19
allowable_overhang=3
max_leveling=2
leveling_buffer=-1
preserve_water=0
preserve_lava=0

adjoining_template=ST753M/753_SmallVillageHut1;20;20;10;90
adjoining_template=ST753M/753_SmallVillageHut1;20;20;-10;90
adjoining_template=forest/753_House_Oak;-20;20;10;90
adjoining_template=plains/753_Store_Icecream_CB;-25;20;-15;90
adjoining_template=plains/753_Store_Coffeeshop_CB;15;20;25;100
adjoining_template=ST753M/753_SmallVillageHut2;10;20;-20;80
adjoining_template=ST753M/753_SmallVillageHut2;-10;20;20;80
adjoining_template=ST753M/753_SmallVillageHut2;-10;20;-20;80

biomesToSpawnIn=plains,chaparral,grassland,orchard

=0,100,air
rule1=0,100,preserveBlock
rule2=0,100,minecraft:stonebrick-0
rule3=0,100,minecraft:double_stone_slab-0
rule4=0,100,minecraft:cobblestone-0
rule5=0,100,minecraft:grass-0
rule6=0,100,minecraft:stone_slab-8
rule7=0,100,minecraft:brick_block-0
rule8=0,100,minecraft:wooden_door-2
rule9=0,100,minecraft:cobblestone_wall-0
rule10=0,100,minecraft:oak_stairs-1
rule11=0,100,minecraft:fence_gate-0
rule12=0,100,minecraft:oak_stairs-3
rule13=0,100,minecraft:oak_stairs-2
rule14=0,100,minecraft:oak_stairs-0
rule15=0,100,minecraft:crafting_table-0
rule16=0,100,minecraft:hopper-5

rule17=0,100,CommandBlock:RUINSTRIGGER /summon villager ~ ~1 ~ {Profession:4,Offers:{Recipes:[{rewardExp:0b,maxUses:2147483647,uses:0,buy:{id:"minecraft:emerald",Count:1},sell:{id:"harvestcraft:friesitem",Count:1b}},{rewardExp:0b,maxUses:2147483647,uses:0,buy:{id:"minecraft:emerald",Count:2},sell:{id:"harvestcraft:zucchinifriesitem",Count:1b}},{rewardExp:0b,maxUses:2147483647,uses:0,buy:{id:"minecraft:emerald",Count:1},sell:{id:"harvestcraft:potatochipsitem",Count:1b}},{rewardExp:0b,maxUses:2147483647,uses:0,buy:{id:"minecraft:emerald",Count:1},sell:{id:"harvestcraft:bbqpotatochipsitem",Count:1b}},{rewardExp:0b,maxUses:2147483647,uses:0,buy:{id:"minecraft:emerald",Count:2},sell:{id:"harvestcraft:ceasarsaladitem",Count:1b}},{rewardExp:0b,maxUses:2147483647,uses:0,buy:{id:"minecraft:emerald",Count:1},sell:{id:"harvestcraft:coleslawitem",Count:1b}},{rewardExp:0b,maxUses:2147483647,uses:0,buy:{id:"minecraft:emerald",Count:1},sell:{id:"harvestcraft:colasodaitem",Count:1b}},{rewardExp:0b,maxUses:2147483647,uses:0,buy:{id:"minecraft:emerald",Count:1},sell:{id:"harvestcraft:lemonlimesodaitem",Count:1b}},{rewardExp:0b,maxUses:2147483647,uses:0,buy:{id:"minecraft:emerald",Count:1},sell:{id:"harvestcraft:rootbeersodaitem",Count:1b}},{rewardExp:0b,maxUses:2147483647,uses:0,buy:{id:"minecraft:emerald",Count:1},sell:{id:"harvestcraft:strawberrymilkshakeitem",Count:1b}},{rewardExp:0b,maxUses:2147483647,uses:0,buy:{id:"minecraft:emerald",Count:1},sell:{id:"harvestcraft:bananamilkshakeitem",Count:1b}},{rewardExp:0b,maxUses:2147483647,uses:0,buy:{id:"minecraft:emerald",Count:1},sell:{id:"harvestcraft:chocolatemilkshakeitem",Count:1b}},{rewardExp:0b,maxUses:2147483647,uses:0,buy:{id:"minecraft:emerald",Count:2},sell:{id:"harvestcraft:hamburgeritem",Count:1b}},{rewardExp:0b,maxUses:2147483647,uses:0,buy:{id:"minecraft:emerald",Count:3},sell:{id:"harvestcraft:cheeseburgeritem",Count:1b}},{rewardExp:0b,maxUses:2147483647,uses:0,buy:{id:"minecraft:emerald",Count:3},sell:{id:"harvestcraft:onionhamburgeritem",Count:1b}},{rewardExp:0b,maxUses:2147483647,uses:0,buy:{id:"minecraft:emerald",Count:3},sell:{id:"harvestcraft:deluxecheeseburgeritem",Count:1b}},{rewardExp:0b,maxUses:2147483647,uses:0,buy:{id:"minecraft:emerald",Count:3},sell:{id:"harvestcraft:baconcheeseburgeritem",Count:1b}},{rewardExp:0b,maxUses:2147483647,uses:0,buy:{id:"minecraft:emerald",Count:2},sell:{id:"harvestcraft:fishsandwichitem",Count:1b}},{rewardExp:0b,maxUses:2147483647,uses:0,buy:{id:"minecraft:emerald",Count:2},sell:{id:"harvestcraft:chickensandwichitem",Count:1b}},{rewardExp:0b,maxUses:2147483647,uses:0,buy:{id:"minecraft:emerald",Count:5},sell:{id:"harvestcraft:delightedmealitem",Count:1b}},{rewardExp:0b,maxUses:2147483647,uses:0,buy:{id:"minecraft:emerald",Count:6},sell:{id:"harvestcraft:gourmetbeefburgeritem",Count:1b}},{rewardExp:0b,maxUses:2147483647,uses:0,buy:{id:"minecraft:emerald",Count:6},sell:{id:"harvestcraft:paradiseburgeritem",Count:1b}},{rewardExp:0b,maxUses:2147483647,uses:0,buy:{id:"minecraft:emerald",Count:2},sell:{id:"harvestcraft:applepieitem",Count:1b}},{rewardExp:0b,maxUses:2147483647,uses:0,buy:{id:"minecraft:emerald",Count:2},sell:{id:"harvestcraft:cherrypieitem",Count:1b}},{rewardExp:0b,maxUses:2147483647,uses:0,buy:{id:"minecraft:emerald",Count:2},sell:{id:"harvestcraft:icecreamitem",Count:1b}}]}}:@-1

rule18=0,100,minecraft:cauldron-0
rule19=0,100,IInventory;minecraft:hopper;minecraft:carpet#1#12#0-4
rule20=0,100,minecraft:stone_stairs-6
rule21=0,100,IInventory;minecraft:chest;harvestcraft:skilletitem#1#0#2+minecraft:baked_potato#2#0#4+minecraft:bucket#1#0#7+harvestcraft:lettuceitem#1#0#10+minecraft:egg#3#0#14+minecraft:water_bucket#1#0#20+harvestcraft:cuttingboarditem#1#0#25-3
rule22=0,100,minecraft:wooden_door-0
rule23=0,100,minecraft:wooden_door-9
rule24=0,100,minecraft:glass_pane-0
rule25=0,100,minecraft:carpet-12
rule26=0,100,harvestcraft:cherrycheesecake-0
rule27=0,100,minecraft:lever-12
rule28=0,100,minecraft:furnace-2
rule29=0,100,minecraft:wooden_door-8
rule30=0,100,minecraft:wooden_slab-12
rule31=0,100,minecraft:stone_stairs-1
rule32=0,100,minecraft:stone_stairs-2
rule33=0,100,minecraft:stone_stairs-0
rule34=0,100,minecraft:oak_stairs-6
rule35=0,100,minecraft:planks-0
rule36=0,100,minecraft:oak_stairs-7
rule37=0,100,minecraft:planks-2
rule38=0,100,minecraft:planks-4
rule39=0,100,minecraft:planks-1
rule40=0,100,minecraft:wooden_slab-8
rule41=0,100,minecraft:glowstone-0
rule42=0,100,minecraft:stone_slab-0

layer
1,1,1,1,1,1,1,1,1,1,1,1,1,1,1,1,1,1,1
1,1,2,2,2,2,2,2,2,2,2,2,2,2,2,2,1,1,1
1,1,2,2,2,2,2,2,2,2,2,2,2,2,2,2,1,1,1
1,3,2,2,2,2,2,2,2,2,2,2,2,2,2,2,2,2,1
1,2,2,2,2,2,2,2,2,2,2,2,2,2,2,2,2,2,1
1,2,2,2,2,2,2,2,2,2,2,2,2,2,2,2,2,2,1
1,2,2,2,2,2,2,2,2,2,2,2,2,2,2,2,2,2,1
1,2,2,2,2,2,2,2,2,2,2,2,2,2,2,2,2,2,1
1,3,2,2,2,2,2,2,2,2,2,2,2,2,2,2,2,2,1
1,2,2,2,2,2,2,2,2,2,2,2,2,2,2,2,2,2,1
1,2,2,2,2,2,2,2,2,2,2,2,2,2,2,2,2,2,1
1,2,2,2,2,2,2,2,2,2,2,2,2,2,2,2,2,2,1
4,2,2,2,2,2,2,2,2,2,2,2,2,2,2,2,2,2,1
4,2,2,2,2,2,2,2,2,2,2,2,2,2,2,2,2,2,1
4,2,2,2,2,2,2,2,2,2,2,2,2,2,2,2,2,2,1
4,2,2,2,2,2,2,2,2,2,2,2,2,2,2,2,2,2,1
1,2,2,2,2,2,2,2,2,2,2,2,2,2,2,2,2,2,1
1,3,2,2,2,2,2,3,2,2,2,2,2,2,2,2,2,3,1
1,1,1,1,1,1,1,1,1,1,1,1,1,1,1,1,1,1,1
endlayer

layer
1,1,2,2,2,2,2,2,2,2,2,2,2,2,2,2,1,1,1
1,1,2,2,2,2,2,2,2,2,2,2,2,2,2,2,1,1,1
1,1,2,2,2,2,2,2,2,2,2,2,2,2,2,2,1,1,1
1,3,2,2,2,2,2,2,2,2,2,2,2,2,2,2,2,2,1
1,2,2,2,2,2,2,2,2,2,2,2,2,2,2,2,2,2,1
1,2,2,2,2,2,2,2,2,2,2,2,2,2,2,2,2,2,1
1,2,2,2,2,2,2,2,2,2,2,2,2,2,2,2,2,2,1
1,2,2,2,2,2,2,2,2,2,2,2,2,2,2,2,2,2,1
1,3,2,2,2,2,2,2,2,2,2,2,2,2,2,2,2,2,1
1,2,2,2,2,2,2,2,2,2,2,2,2,2,2,2,2,2,1
1,2,2,2,2,2,2,2,2,2,2,2,2,2,2,2,2,2,1
1,2,2,2,2,2,2,2,2,2,2,2,2,2,2,2,2,2,1
4,2,2,2,2,2,2,2,2,2,2,2,2,2,2,2,2,2,1
4,2,2,2,2,2,2,2,2,2,2,2,2,2,2,2,2,2,1
4,2,2,2,2,2,2,2,2,2,2,2,2,2,2,2,2,2,1
4,2,2,2,2,2,2,2,2,2,2,2,2,2,2,2,2,2,1
1,2,2,2,2,2,2,2,2,2,2,2,2,2,2,2,2,2,1
1,3,2,2,2,2,2,3,2,2,2,2,2,2,2,2,2,3,1
1,1,1,1,1,1,1,1,1,1,1,1,1,1,1,1,1,1,1
endlayer

layer
1,2,2,2,2,2,2,2,2,2,2,2,2,2,2,2,1,1,1
1,2,5,5,5,5,5,2,2,2,2,2,2,2,2,2,1,1,1
1,2,5,5,5,5,5,2,2,2,2,2,2,2,2,2,1,1,1
1,3,2,2,2,2,2,2,2,2,2,2,2,2,2,2,2,2,1
1,2,6,6,6,6,6,6,6,6,6,6,6,6,6,6,6,2,1
1,2,6,6,6,6,6,6,6,6,6,6,6,6,6,6,6,2,1
1,2,6,6,6,6,6,6,6,6,6,6,6,6,6,6,6,2,1
1,2,6,6,6,6,6,6,6,6,6,6,6,6,6,6,6,2,1
1,3,6,6,6,6,6,6,6,6,6,6,6,6,6,6,6,2,1
1,2,6,6,6,6,6,6,6,6,6,6,6,6,6,6,6,2,1
1,2,6,6,6,6,6,6,6,6,6,6,6,6,6,6,6,2,1
1,2,6,6,6,6,6,6,6,6,6,6,6,6,6,6,6,2,1
4,2,6,6,6,6,6,6,6,6,6,6,6,6,6,6,6,2,1
4,2,6,6,6,6,6,6,6,6,6,6,6,6,6,6,6,2,1
4,2,6,6,6,6,6,6,6,6,6,6,6,6,6,6,6,2,1
4,2,6,6,6,6,6,6,6,6,6,6,6,6,6,6,6,2,1
1,2,6,6,6,6,6,6,6,6,6,6,6,6,6,6,6,2,1
1,3,2,2,2,2,2,3,2,2,2,2,2,2,2,2,2,3,1
1,1,1,1,1,1,1,1,1,1,1,1,1,1,1,1,1,1,1
endlayer

layer
1,1,0,0,0,0,0,0,0,3,3,3,0,0,0,0,1,1,1
1,1,0,0,0,0,0,0,0,0,0,0,0,0,0,0,1,1,1
1,1,0,0,0,0,0,0,0,0,0,0,0,0,0,0,1,1,1
1,3,3,3,3,3,3,3,7,7,7,7,7,7,7,8,7,3,1
1,7,0,9,0,9,0,3,0,0,0,0,0,0,0,0,0,7,1
1,7,0,9,0,9,0,11,0,0,10,0,0,0,10,0,0,7,1
1,7,0,9,0,9,0,7,0,13,9,12,0,13,9,12,0,7,1
1,7,0,0,0,0,0,7,0,0,14,0,0,0,14,0,0,7,1
1,3,3,7,0,0,7,3,3,0,0,0,0,0,0,0,0,7,1
1,7,16,0,0,0,0,0,9,0,15,9,0,0,10,0,0,7,1
1,7,18,0,0,0,17,0,9,0,0,9,0,13,9,12,0,7,1
1,7,19,0,0,0,0,0,9,0,0,9,0,0,14,0,0,7,1
4,4,4,20,0,0,0,3,3,0,0,0,0,0,0,0,0,7,1
4,4,4,0,0,0,21,7,0,0,10,0,0,0,10,0,0,7,1
4,4,4,0,0,0,9,7,0,13,9,12,0,13,9,12,0,7,1
4,4,4,20,0,0,0,11,0,0,14,0,0,0,14,0,0,7,1
1,7,9,0,0,0,0,3,0,0,0,0,0,0,0,0,0,7,1
1,3,3,7,7,7,7,3,7,22,7,7,7,7,7,7,7,3,1
1,1,1,1,1,1,1,1,1,1,1,1,1,1,1,1,1,1,1
endlayer

layer
1,1,0,0,0,0,0,0,0,9,0,9,0,0,0,0,1,1,1
1,1,0,0,0,0,0,0,0,0,0,0,0,0,0,0,1,1,1
1,1,0,0,0,0,0,0,0,0,0,0,0,0,0,0,1,1,1
1,3,7,7,7,7,7,3,7,24,24,7,24,24,7,23,7,3,1
1,7,0,25,0,25,0,3,0,0,0,0,0,0,0,0,0,7,1
1,24,0,26,0,25,0,0,0,0,0,0,0,0,0,0,0,24,1
1,24,0,25,0,25,0,7,0,0,25,0,0,0,25,0,0,24,1
1,7,0,0,0,0,0,7,0,0,0,0,0,0,0,0,0,7,1
1,3,3,7,0,0,7,3,3,0,0,0,0,0,0,0,0,24,1
1,7,25,0,0,0,0,0,0,0,25,25,0,0,0,0,0,24,1
1,7,27,0,0,0,0,0,0,0,0,25,0,0,25,0,0,7,1
1,7,25,0,0,0,0,0,0,0,0,25,0,0,0,0,0,24,1
4,4,4,9,0,0,0,3,3,0,0,0,0,0,0,0,0,24,1
4,4,28,0,0,0,25,7,0,0,0,0,0,0,0,0,0,7,1
4,4,28,0,0,0,25,7,0,0,25,0,0,0,25,0,0,24,1
4,4,4,9,0,0,0,0,0,0,0,0,0,0,0,0,0,24,1
1,7,25,0,0,0,0,3,0,0,0,0,0,0,0,0,0,7,1
1,3,3,7,24,24,7,3,7,29,7,24,24,7,24,24,7,3,1
1,1,1,1,1,1,1,1,1,1,1,1,1,1,1,1,1,1,1
endlayer

layer
1,1,0,0,0,0,0,0,0,9,0,9,0,0,0,0,1,1,1
1,1,0,0,0,0,0,0,0,0,0,0,0,0,0,0,1,1,1
1,1,0,0,0,0,0,0,0,0,0,0,0,0,0,0,1,1,1
1,3,7,24,7,24,7,3,7,24,24,7,24,24,7,7,7,3,1
1,7,0,0,0,0,0,3,0,0,0,0,0,0,0,0,0,7,1
1,24,0,0,0,0,0,0,30,0,0,0,0,0,0,0,0,24,1
1,24,0,0,0,0,0,0,30,0,0,0,0,0,0,0,0,24,1
1,7,0,0,0,0,0,0,30,0,0,0,0,0,0,0,0,7,1
1,3,3,7,0,0,7,3,3,0,0,0,0,0,0,0,0,24,1
1,7,0,0,0,0,0,0,0,0,0,0,0,0,0,0,0,24,1
1,24,0,0,30,0,0,0,0,0,0,0,0,0,0,0,0,7,1
1,7,0,0,30,0,0,0,0,0,0,0,0,0,0,0,0,24,1
4,4,31,0,30,0,0,3,3,0,0,0,0,0,0,0,0,24,1
4,4,32,0,0,0,0,0,0,0,0,0,0,0,0,0,0,7,1
4,4,32,0,0,0,0,0,0,0,0,0,0,0,0,0,0,24,1
4,4,33,0,0,0,0,0,0,0,0,0,0,0,0,0,0,24,1
1,7,0,0,0,0,0,3,0,0,0,0,0,0,0,0,0,7,1
1,3,3,7,24,24,7,3,7,7,7,24,24,7,24,24,7,3,1
1,1,1,1,1,1,1,1,1,1,1,1,1,1,1,1,1,1,1
endlayer

layer
1,1,1,1,1,1,1,1,36,35,35,35,34,1,1,1,1,1,1
1,1,1,1,1,1,1,1,1,1,1,1,1,1,1,1,1,1,1
1,1,1,1,1,1,1,1,1,1,1,1,1,1,1,1,1,1,1
1,3,7,24,7,24,7,3,7,7,7,7,7,7,7,7,7,3,1
1,7,0,0,0,0,0,3,0,0,0,0,0,0,0,0,0,7,1
1,7,0,0,0,0,0,6,37,0,0,0,0,0,0,0,0,7,1
1,7,0,0,0,0,0,6,37,0,0,0,0,0,0,0,0,7,1
1,7,0,0,0,0,0,6,37,0,0,0,0,0,0,0,0,7,1
1,3,3,7,6,6,7,3,3,0,0,0,0,0,0,0,0,7,1
1,7,0,0,0,0,0,6,0,0,0,0,0,0,0,0,0,7,1
1,24,0,0,37,0,0,6,0,0,0,0,0,0,0,0,0,7,1
1,7,0,0,37,0,0,6,0,0,0,0,0,0,0,0,0,7,1
33,7,33,0,37,0,0,3,3,0,0,0,0,0,0,0,0,7,1
4,4,20,0,0,0,0,6,0,0,0,0,0,0,0,0,0,7,1
4,4,20,0,0,0,0,6,0,0,0,0,0,0,0,0,0,7,1
31,7,31,0,0,0,0,6,0,0,0,0,0,0,0,0,0,7,1
1,7,0,0,0,0,0,3,0,0,0,0,0,0,0,0,0,7,1
1,3,3,7,7,7,7,3,7,7,7,7,7,7,7,7,7,3,1
1,1,1,1,1,1,1,1,1,1,1,1,1,1,1,1,1,1,1
endlayer

layer
1,1,1,1,1,1,1,36,38,39,37,39,38,34,1,1,1,1,1
1,1,1,1,1,1,1,1,1,1,1,1,1,1,1,1,1,1,1
40,40,40,40,40,40,40,40,40,40,40,40,40,40,40,40,40,40,40
40,3,7,7,7,7,7,3,7,7,7,7,7,7,7,7,7,3,40
40,7,6,6,6,6,6,7,6,6,6,6,6,6,6,6,6,7,40
40,7,6,6,6,6,6,7,38,6,6,6,6,6,6,6,6,7,40
40,7,6,6,41,6,6,7,38,6,41,6,6,6,41,6,6,7,40
40,7,6,6,6,6,6,7,38,6,41,6,6,6,41,6,6,7,40
40,3,3,7,7,7,7,7,3,6,41,6,6,6,41,6,6,7,40
40,7,6,6,6,6,6,7,6,6,6,6,6,6,6,6,6,7,40
40,7,6,6,38,6,6,7,6,6,6,6,6,6,6,6,6,7,40
40,7,6,6,38,6,6,7,6,6,6,6,6,6,6,6,6,7,40
40,7,4,6,38,6,6,7,3,6,41,6,6,6,41,6,6,7,40
4,4,4,6,6,6,6,7,6,6,41,6,6,6,41,6,6,7,40
4,4,4,6,41,6,6,7,6,6,41,6,6,6,41,6,6,7,40
40,7,4,6,6,6,6,7,6,6,6,6,6,6,6,6,6,7,40
40,7,6,6,6,6,6,7,6,6,6,6,6,6,6,6,6,7,40
40,3,3,7,7,7,7,3,7,7,7,7,7,7,7,7,7,3,40
40,40,40,40,40,40,40,40,40,40,40,40,40,40,40,40,40,40,40
endlayer

layer
1,1,1,1,1,1,1,39,38,37,38,37,38,39,1,1,1,1,1
1,1,1,1,1,1,1,1,1,1,1,1,1,1,1,1,1,1,1
1,1,1,1,1,1,1,1,1,1,1,1,1,1,1,1,1,1,1
1,12,14,14,14,14,14,14,14,14,14,14,14,14,14,14,14,13,1
1,12,35,35,35,35,35,35,35,35,35,35,35,35,35,35,35,13,1
1,12,35,42,42,42,42,42,42,42,42,42,42,42,42,42,35,13,1
1,12,35,42,42,42,42,42,42,42,42,42,42,42,42,42,35,13,1
1,12,35,42,42,42,42,42,42,2,2,2,42,42,42,42,35,13,1
1,12,35,42,42,42,42,42,42,2,2,2,42,42,42,42,35,13,1
1,12,35,42,42,42,42,42,42,42,42,42,42,42,42,42,35,13,1
1,12,35,42,42,42,42,42,42,42,42,42,42,42,42,42,35,13,1
1,12,35,42,42,42,42,42,42,42,42,42,42,42,42,42,35,13,1
1,12,35,42,42,42,42,42,42,42,42,42,42,42,42,42,35,13,1
4,4,35,42,42,42,42,42,42,42,42,42,2,42,2,42,35,13,1
4,4,35,42,42,42,42,42,42,42,42,42,2,42,2,42,35,13,1
1,12,35,42,42,42,42,42,42,42,42,42,42,42,42,42,35,13,1
1,12,35,35,35,35,35,35,35,35,35,35,35,35,35,35,35,13,1
1,10,10,10,10,10,10,10,10,10,10,10,10,10,10,10,10,13,1
1,1,1,1,1,1,1,1,1,1,1,1,1,1,1,1,1,1,1
endlayer

layer
1,1,1,1,1,1,1,12,37,38,39,38,37,13,1,1,1,1,1
1,1,1,1,1,1,1,1,1,1,1,1,1,1,1,1,1,1,1
1,1,1,1,1,1,1,1,1,1,1,1,1,1,1,1,1,1,1
1,1,1,1,1,1,1,1,1,1,1,1,1,1,1,1,1,1,1
1,1,1,1,1,1,1,1,1,1,1,1,1,1,1,1,1,1,1
1,1,1,1,1,1,1,1,1,1,1,1,1,1,1,1,1,1,1
1,1,1,1,1,1,1,1,1,1,1,1,1,1,1,1,1,1,1
1,1,1,1,1,1,1,1,1,2,2,2,1,1,1,1,1,1,1
1,1,1,1,1,1,1,1,1,2,2,2,1,1,1,1,1,1,1
1,1,1,1,1,1,1,1,1,1,1,1,1,1,1,1,1,1,1
1,1,1,1,1,1,1,1,1,1,1,1,1,1,1,1,1,1,1
1,1,1,1,1,1,1,1,1,1,1,1,1,1,1,1,1,1,1
1,1,1,1,1,1,1,1,1,1,1,1,1,1,1,1,1,1,1
4,4,1,1,1,1,1,1,1,1,1,1,1,1,1,1,1,1,1
4,4,1,1,1,1,1,1,1,1,1,1,1,1,1,1,1,1,1
1,1,1,1,1,1,1,1,1,1,1,1,1,1,1,1,1,1,1
1,1,1,1,1,1,1,1,1,1,1,1,1,1,1,1,1,1,1
1,1,1,1,1,1,1,1,1,1,1,1,1,1,1,1,1,1,1
1,1,1,1,1,1,1,1,1,1,1,1,1,1,1,1,1,1,1
endlayer

layer
1,1,1,1,1,1,1,1,12,35,35,35,13,1,1,1,1,1,1
1,1,1,1,1,1,1,1,1,1,1,1,1,1,1,1,1,1,1
1,1,1,1,1,1,1,1,1,1,1,1,1,1,1,1,1,1,1
1,1,1,1,1,1,1,1,1,1,1,1,1,1,1,1,1,1,1
1,1,1,1,1,1,1,1,1,1,1,1,1,1,1,1,1,1,1
1,1,1,1,1,1,1,1,1,1,1,1,1,1,1,1,1,1,1
1,1,1,1,1,1,1,1,1,1,1,1,1,1,1,1,1,1,1
1,1,1,1,1,1,1,1,1,1,1,1,1,1,1,1,1,1,1
1,1,1,1,1,1,1,1,1,1,1,1,1,1,1,1,1,1,1
1,1,1,1,1,1,1,1,1,1,1,1,1,1,1,1,1,1,1
1,1,1,1,1,1,1,1,1,1,1,1,1,1,1,1,1,1,1
1,1,1,1,1,1,1,1,1,1,1,1,1,1,1,1,1,1,1
1,1,1,1,1,1,1,1,1,1,1,1,1,1,1,1,1,1,1
4,4,1,1,1,1,1,1,1,1,1,1,1,1,1,1,1,1,1
4,4,1,1,1,1,1,1,1,1,1,1,1,1,1,1,1,1,1
1,1,1,1,1,1,1,1,1,1,1,1,1,1,1,1,1,1,1
1,1,1,1,1,1,1,1,1,1,1,1,1,1,1,1,1,1,1
1,1,1,1,1,1,1,1,1,1,1,1,1,1,1,1,1,1,1
1,1,1,1,1,1,1,1,1,1,1,1,1,1,1,1,1,1,1
endlayer

