
# Created by Ruins mod version 17.0 Ingame Parser
# authoring Player: ST753M

weight=1
embed_into_distance=2
acceptable_target_blocks=grass,dirt,podzol,biomesoplenty:grass,biomesoplenty:dirt
unacceptable_target_blocks=flowing_water,water,flowing_lava,lava
dimensions=20,11,15
allowable_overhang=2
max_leveling=0
leveling_buffer=-1
preserve_water=0
preserve_lava=0

adjoining_template=ST753M/753_SmallVillageHut1;20;20;10;30
adjoining_template=ST753M/753_SmallVillageHut1;20;20;-10;30
adjoining_template=ST753M/753_SmallVillageHut1;-20;20;10;30
adjoining_template=ST753M/753_SmallVillageHut1;-20;20;-10;30
adjoining_template=ST753M/753_SmallVillageHut2;10;20;20;30
adjoining_template=ST753M/753_SmallVillageHut2;10;20;-20;30
adjoining_template=ST753M/753_SmallVillageHut2;-10;20;20;30
adjoining_template=ST753M/753_SmallVillageHut2;-10;20;-20;30

biomesToSpawnIn=plains,prairie,shrubland,chaparral,grassland,meadow,orchard,rocky_plains,rocky_plateau

=0,100,air
rule1=0,100,preserveBlock
rule2=0,100,minecraft:dirt-0
rule3=0,100,minecraft:cobblestone-0
rule4=0,100,minecraft:grass-0
rule5=0,100,minecraft:water-0
rule6=0,100,minecraft:farmland-7
rule7=0,100,minecraft:stone_stairs-2
rule8=0,100,minecraft:stone_stairs-3
rule9=0,100,minecraft:fence-0

rule10=0,100,minecraft:wheat-3
^0,100,harvestcraft:pamcorncrop-0
^0,100,harvestcraft:pamryecrop-1
^0,100,harvestcraft:pamoatscrop-1
^0,100,harvestcraft:pambarleycrop-2
^0,100,harvestcraft:pamricecrop-2

rule11=0,100,minecraft:wooden_slab-8
rule12=0,100,minecraft:stone-0

rule13=0,100,minecraft:wheat-3
^0,100,harvestcraft:pamcorncrop-0
^0,100,harvestcraft:pamryecrop-1
^0,100,harvestcraft:pamoatscrop-1
^0,100,harvestcraft:pambarleycrop-2
^0,100,harvestcraft:pamricecrop-2

rule14=0,100,minecraft:log-0
rule15=0,100,minecraft:hay_block-0
rule16=0,100,minecraft:ladder-4
rule17=0,100,minecraft:spruce_door-0
rule18=0,100,IInventory;minecraft:chest;harvestcraft:barleyitem#3#0#2+harvestcraft:ryeitem#3#0#4+harvestcraft:barleyitem#5#0#6+harvestcraft:oatsitem#4#0#10+minecraft:wheat#6#0#14+harvestcraft:ryeitem#4#0#17+harvestcraft:ryeitem#6#0#18+harvestcraft:barleyitem#2#0#21+minecraft:wheat#5#0#25-2
rule19=0,100,IInventory;minecraft:trapped_chest;harvestcraft:flouritem#3#0#5+harvestcraft:cornmealitem#5#0#7+harvestcraft:flouritem#4#0#11+harvestcraft:flouritem#5#0#19+harvestcraft:mortarandpestleitem#1#0#22+harvestcraft:flouritem#4#0#25-2
rule20=0,100,minecraft:spruce_door-8
rule21=0,100,minecraft:stained_glass_pane-8
rule22=2,50,minecraft:torch-2
rule23=0,100,minecraft:oak_stairs-4
rule24=0,100,minecraft:planks-0
rule25=0,100,minecraft:oak_stairs-5
rule26=0,100,minecraft:log-8
rule27=0,100,minecraft:stone_stairs-0
rule28=0,100,minecraft:oak_stairs-0
rule29=0,100,minecraft:web-0
rule30=0,100,minecraft:oak_stairs-1
rule31=0,100,minecraft:stone_stairs-1
rule32=0,100,minecraft:oak_stairs-6
rule33=0,100,minecraft:oak_stairs-7
rule34=0,100,minecraft:log-4
rule35=0,100,minecraft:oak_stairs-2
rule36=0,100,minecraft:oak_stairs-3
rule37=0,100,minecraft:stone_slab-3

layer
1,1,2,2,3,3,3,3,3,3,3,2,2,1,1
2,2,2,3,3,3,3,3,3,3,3,3,2,2,2
2,2,2,3,3,3,3,3,3,3,3,3,2,2,2
2,2,2,3,3,3,3,3,3,3,3,3,2,2,2
2,2,2,3,3,3,3,3,3,3,3,3,2,2,2
2,2,2,3,3,3,3,3,3,3,3,3,2,2,2
2,2,2,3,3,3,3,3,3,3,3,3,2,2,2
2,2,2,3,3,3,3,3,3,3,3,3,2,2,2
1,2,2,2,3,3,3,3,3,3,3,2,2,2,1
1,1,1,2,2,3,3,3,3,3,2,2,1,1,1
1,1,1,1,2,3,3,3,3,3,2,1,1,1,1
endlayer

layer
1,1,4,2,3,3,3,3,3,3,3,2,4,1,1
2,2,2,3,3,3,3,3,3,3,3,3,2,2,2
4,2,2,3,3,3,3,3,3,3,3,3,2,4,2
4,2,2,3,3,3,3,3,3,3,3,3,4,2,2
4,4,4,3,3,3,3,3,3,3,3,3,2,2,2
4,4,2,3,3,3,3,3,3,3,3,3,2,2,2
4,2,4,3,3,3,3,3,3,3,3,3,2,2,2
2,2,2,3,3,3,3,3,3,3,3,3,2,2,2
1,4,2,2,3,3,3,3,3,3,3,2,2,4,1
1,1,1,4,4,3,3,3,3,3,4,4,1,1,1
1,1,1,1,4,3,3,3,3,3,4,1,1,1,1
endlayer

layer
1,1,1,4,4,3,3,3,3,3,4,4,1,1,1
4,2,4,4,5,3,3,3,3,3,5,4,4,4,2
6,6,6,3,3,3,3,3,3,3,3,3,6,6,6
6,6,6,3,3,3,3,3,3,3,3,3,6,6,6
6,6,6,3,3,3,3,3,3,3,3,3,6,6,6
6,6,6,3,3,3,3,3,3,3,3,3,6,6,6
6,6,6,3,3,3,3,3,3,3,3,3,6,6,6
4,4,4,4,5,3,3,3,3,3,5,4,4,4,4
1,1,4,4,4,3,3,3,3,3,4,4,4,1,1
1,1,1,1,1,8,3,3,3,7,1,1,1,1,1
1,1,1,1,1,8,3,3,3,7,1,1,1,1,1
endlayer

layer
1,1,1,1,9,3,3,3,3,3,9,1,1,1,1
1,9,9,9,3,0,0,0,0,0,3,9,9,9,1
13,13,13,3,11,0,12,12,12,0,11,3,10,10,10
13,13,13,3,11,0,12,14,12,0,11,3,10,10,10
13,13,13,3,11,0,12,12,12,0,11,3,10,10,10
13,13,13,3,11,0,0,0,0,0,11,3,10,10,10
13,13,13,3,11,0,0,0,0,15,11,3,10,10,10
1,9,9,9,3,0,0,0,0,16,3,9,9,9,1
1,1,1,1,9,3,3,17,3,3,9,1,1,1,1
1,1,1,1,1,1,1,1,1,1,1,1,1,1,1
1,1,1,1,1,1,1,1,1,1,1,1,1,1,1
endlayer

layer
1,1,1,1,9,3,3,3,3,3,9,1,1,1,1
1,1,1,9,3,0,0,0,0,0,3,9,1,1,1
0,0,0,3,18,0,0,0,0,0,0,3,0,0,0
0,0,0,3,19,0,0,14,0,0,0,3,0,0,0
0,0,0,3,0,0,0,0,0,0,0,3,0,0,0
0,0,0,3,0,0,0,0,0,0,15,3,0,0,0
0,0,0,3,0,0,0,0,0,0,0,3,0,0,0
1,1,1,9,3,0,0,0,0,16,3,9,1,1,1
1,1,1,1,9,3,3,20,3,3,9,1,1,1,1
1,1,1,1,1,1,1,1,1,1,1,1,1,1,1
1,1,1,1,1,1,1,1,1,1,1,1,1,1,1
endlayer

layer
1,1,1,1,1,3,21,21,21,3,1,1,1,1,1
1,1,1,1,3,0,0,0,0,0,3,1,1,1,1
1,1,1,3,0,0,0,0,0,0,0,3,1,1,1
1,1,1,21,0,0,0,14,0,0,0,21,1,1,1
1,1,1,21,0,0,0,0,0,0,0,21,1,1,1
1,1,1,21,0,0,0,0,0,0,0,21,1,1,1
1,1,1,3,0,0,0,0,0,0,0,3,1,1,1
1,1,1,1,3,0,0,22,0,16,3,1,1,1,1
1,1,1,1,1,3,3,3,3,3,1,1,1,1,1
1,1,1,1,1,1,1,1,1,1,1,1,1,1,1
1,1,1,1,1,1,1,9,9,9,1,1,1,1,1
endlayer

layer
1,1,1,1,1,3,3,3,3,3,1,1,1,1,1
1,1,1,1,3,11,11,11,11,11,3,1,1,1,1
1,1,1,3,11,11,0,0,0,11,11,3,1,1,1
1,1,1,3,11,11,0,14,0,11,11,3,1,1,1
1,1,1,3,11,11,0,0,0,11,11,3,1,1,1
1,1,1,3,11,11,11,11,11,11,11,3,1,1,1
1,1,1,3,11,11,11,11,11,11,11,3,1,1,1
1,1,1,1,3,11,11,11,11,16,3,1,1,1,1
1,1,1,1,1,3,3,3,3,3,1,1,1,1,1
1,1,1,1,1,1,1,1,1,1,1,1,1,1,1
1,1,1,1,1,1,1,9,9,9,1,1,1,1,1
endlayer

layer
1,1,1,1,1,3,3,3,3,3,1,1,1,1,1
1,1,1,1,3,0,0,0,0,0,3,1,1,1,1
1,1,1,3,0,0,0,0,0,0,0,3,1,1,1
1,1,1,3,0,0,0,14,0,0,0,3,1,1,1
1,1,1,3,0,0,0,0,0,0,0,3,1,1,1
1,1,1,3,0,0,0,0,0,0,0,3,1,1,1
1,1,1,3,0,0,0,0,0,0,0,3,1,1,1
1,1,1,1,3,0,0,0,0,16,3,1,1,1,1
1,1,1,1,1,3,3,3,3,3,1,1,1,1,1
1,1,1,1,1,1,1,1,1,1,1,1,1,1,1
1,1,1,1,1,1,1,9,9,9,1,1,1,1,1
endlayer

layer
1,1,1,1,1,3,3,3,3,3,1,1,1,1,1
1,1,1,1,3,0,0,0,0,0,3,1,1,1,1
1,1,1,3,0,0,0,23,0,0,0,3,1,1,1
1,1,1,3,0,0,0,24,0,0,0,3,1,1,1
1,1,1,3,0,0,0,25,0,0,0,3,1,1,1
1,1,1,3,0,0,0,0,0,0,0,3,1,1,1
1,1,1,3,0,0,0,0,0,0,0,3,1,1,1
1,1,1,1,3,0,0,0,0,16,3,1,1,1,1
1,1,1,1,1,3,3,3,3,3,1,1,1,1,1
1,1,1,1,1,1,1,1,1,1,1,1,1,1,1
1,1,1,1,1,1,1,9,9,9,1,1,1,1,1
endlayer

layer
1,1,1,1,1,1,3,3,3,1,1,1,1,1,1
1,1,1,1,3,3,0,0,0,3,3,1,1,1,1
1,1,1,1,3,0,0,24,0,0,3,1,1,1,1
1,1,1,3,26,26,26,26,26,26,26,3,1,1,1
1,1,1,3,0,0,0,24,0,0,0,3,1,1,1
1,1,1,3,0,0,0,0,0,0,0,3,1,1,1
1,1,1,1,3,0,0,0,0,0,3,1,1,1,1
1,1,1,1,3,3,0,0,0,3,3,1,1,1,1
1,1,1,1,1,1,3,3,3,1,1,1,1,1,1
1,1,1,1,1,1,1,1,1,1,1,1,1,1,1
1,1,1,1,1,1,1,9,9,9,1,1,1,1,1
endlayer

layer
1,1,1,1,1,1,27,3,27,1,1,1,1,1,1
1,1,1,1,1,3,0,0,0,3,1,1,1,1,1
1,1,1,1,3,0,0,28,0,0,3,1,1,1,1
1,1,1,8,29,0,0,24,0,0,0,7,1,1,1
1,1,1,3,0,0,0,30,0,0,0,3,1,1,1
1,1,1,8,0,0,0,0,0,0,0,7,1,1,1
1,1,1,1,3,0,0,0,0,0,3,1,1,1,1
1,1,1,1,1,3,0,0,29,3,1,1,1,1,1
1,1,1,1,1,1,31,3,31,1,1,1,1,1,1
1,1,1,1,1,1,1,1,1,1,1,1,1,1,1
9,9,9,9,9,9,1,9,9,9,1,1,1,1,1
endlayer

layer
1,1,1,1,1,1,1,1,1,1,1,1,1,1,1
1,1,1,1,1,3,3,3,3,3,1,1,1,1,1
1,1,1,1,3,0,0,0,0,0,3,1,1,1,1
1,1,1,1,3,0,0,0,0,0,3,1,1,1,1
1,1,1,1,3,0,33,24,32,0,3,1,1,1,1
1,1,1,1,3,0,0,0,0,0,3,1,1,1,1
1,1,1,1,3,0,0,0,0,0,3,1,1,1,1
1,1,1,1,1,3,3,3,3,3,1,1,1,1,1
1,1,1,1,1,1,1,1,1,1,1,1,1,1,1
1,1,1,1,1,1,1,1,1,1,1,1,1,1,1
9,9,9,9,9,9,1,9,0,0,1,1,1,1,1
endlayer

layer
1,1,1,1,1,1,1,1,1,1,1,1,1,1,1
1,1,1,1,1,1,3,3,3,1,1,1,1,1,1
1,1,1,1,1,3,0,34,0,3,1,1,1,1,1
1,1,1,1,3,0,0,34,0,0,3,1,1,1,1
1,1,1,1,21,0,24,34,24,0,21,1,1,1,1
1,1,1,1,3,0,0,34,0,0,3,1,1,1,1
1,1,1,1,1,3,0,34,0,3,1,1,1,1,1
1,1,1,1,1,1,3,34,3,1,1,1,1,1,1
1,1,1,1,1,1,1,34,1,1,1,1,1,1,1
1,1,1,1,1,1,1,34,1,1,1,1,1,1,1
9,9,9,9,9,9,9,34,9,9,9,9,9,9,9
endlayer

layer
1,1,1,1,1,1,1,1,1,1,1,1,1,1,1
1,1,1,1,1,1,27,3,27,1,1,1,1,1,1
1,1,1,1,1,3,0,0,0,3,1,1,1,1,1
1,1,1,1,8,0,0,0,0,29,7,1,1,1,1
1,1,1,1,3,0,36,24,35,0,3,1,1,1,1
1,1,1,1,8,0,0,0,0,0,7,1,1,1,1
1,1,1,1,1,3,0,0,0,3,1,1,1,1,1
1,1,1,1,1,1,31,3,31,1,1,1,1,1,1
1,1,1,1,1,1,1,1,1,1,1,1,1,1,1
1,1,1,1,1,1,1,1,1,1,1,1,1,1,1
1,1,1,1,1,1,1,9,1,9,9,9,9,9,9
endlayer

layer
1,1,1,1,1,1,1,1,1,1,1,1,1,1,1
1,1,1,1,1,1,1,1,1,1,1,1,1,1,1
1,1,1,1,1,1,27,3,27,1,1,1,1,1,1
1,1,1,1,1,8,3,3,3,7,1,1,1,1,1
1,1,1,1,1,3,3,3,3,3,1,1,1,1,1
1,1,1,1,1,8,3,3,3,7,1,1,1,1,1
1,1,1,1,1,1,31,3,31,1,1,1,1,1,1
1,1,1,1,1,1,1,1,1,1,1,1,1,1,1
1,1,1,1,1,1,1,1,1,1,1,1,1,1,1
1,1,1,1,1,1,1,1,1,1,1,1,1,1,1
1,1,1,1,1,9,9,9,1,9,9,9,9,9,9
endlayer

layer
1,1,1,1,1,1,1,1,1,1,1,1,1,1,1
1,1,1,1,1,1,1,1,1,1,1,1,1,1,1
1,1,1,1,1,1,1,1,1,1,1,1,1,1,1
1,1,1,1,1,1,37,37,37,1,1,1,1,1,1
1,1,1,1,1,1,37,37,37,1,1,1,1,1,1
1,1,1,1,1,1,37,37,37,1,1,1,1,1,1
1,1,1,1,1,1,1,1,1,1,1,1,1,1,1
1,1,1,1,1,1,1,1,1,1,1,1,1,1,1
1,1,1,1,1,1,1,1,1,1,1,1,1,1,1
1,1,1,1,1,1,1,1,1,1,1,1,1,1,1
1,1,1,1,1,9,9,9,1,1,1,1,1,1,1
endlayer

layer
1,1,1,1,1,1,1,1,1,1,1,1,1,1,1
1,1,1,1,1,1,1,1,1,1,1,1,1,1,1
1,1,1,1,1,1,1,1,1,1,1,1,1,1,1
1,1,1,1,1,1,1,1,1,1,1,1,1,1,1
1,1,1,1,1,1,1,1,1,1,1,1,1,1,1
1,1,1,1,1,1,1,1,1,1,1,1,1,1,1
1,1,1,1,1,1,1,1,1,1,1,1,1,1,1
1,1,1,1,1,1,1,1,1,1,1,1,1,1,1
1,1,1,1,1,1,1,1,1,1,1,1,1,1,1
1,1,1,1,1,1,1,1,1,1,1,1,1,1,1
1,1,1,1,1,9,9,9,1,1,1,1,1,1,1
endlayer

layer
1,1,1,1,1,1,1,1,1,1,1,1,1,1,1
1,1,1,1,1,1,1,1,1,1,1,1,1,1,1
1,1,1,1,1,1,1,1,1,1,1,1,1,1,1
1,1,1,1,1,1,1,1,1,1,1,1,1,1,1
1,1,1,1,1,1,1,1,1,1,1,1,1,1,1
1,1,1,1,1,1,1,1,1,1,1,1,1,1,1
1,1,1,1,1,1,1,1,1,1,1,1,1,1,1
1,1,1,1,1,1,1,1,1,1,1,1,1,1,1
1,1,1,1,1,1,1,1,1,1,1,1,1,1,1
1,1,1,1,1,1,1,1,1,1,1,1,1,1,1
1,1,1,1,1,9,9,9,1,1,1,1,1,1,1
endlayer

layer
1,1,1,1,1,1,1,1,1,1,1,1,1,1,1
1,1,1,1,1,1,1,1,1,1,1,1,1,1,1
1,1,1,1,1,1,1,1,1,1,1,1,1,1,1
1,1,1,1,1,1,1,1,1,1,1,1,1,1,1
1,1,1,1,1,1,1,1,1,1,1,1,1,1,1
1,1,1,1,1,1,1,1,1,1,1,1,1,1,1
1,1,1,1,1,1,1,1,1,1,1,1,1,1,1
1,1,1,1,1,1,1,1,1,1,1,1,1,1,1
1,1,1,1,1,1,1,1,1,1,1,1,1,1,1
1,1,1,1,1,1,1,1,1,1,1,1,1,1,1
1,1,1,1,1,9,9,9,1,1,1,1,1,1,1
endlayer

layer
1,1,1,1,1,1,1,1,1,1,1,1,1,1,1
1,1,1,1,1,1,1,1,1,1,1,1,1,1,1
1,1,1,1,1,1,1,1,1,1,1,1,1,1,1
1,1,1,1,1,1,1,1,1,1,1,1,1,1,1
1,1,1,1,1,1,1,1,1,1,1,1,1,1,1
1,1,1,1,1,1,1,1,1,1,1,1,1,1,1
1,1,1,1,1,1,1,1,1,1,1,1,1,1,1
1,1,1,1,1,1,1,1,1,1,1,1,1,1,1
1,1,1,1,1,1,1,1,1,1,1,1,1,1,1
1,1,1,1,1,1,1,1,1,1,1,1,1,1,1
1,1,1,1,1,9,9,9,1,1,1,1,1,1,1
endlayer

