
# Created by Ruins mod version 16.7 Ingame Parser
# authoring Player: lafuller

weight=1
embed_into_distance=4
acceptable_target_blocks=
unacceptable_target_blocks=flowing_water,water,flowing_lava,lava,ice,bedrock,netherrack,nether_brick,nether_brick_fence,soul_sand,quartz_ore,end_stone,obsidian,iron_bars,cloud,flesh,ash_block,slime_grass,slime_congealed,slime_dirt
biomesToSpawnIn=plains,mutated_plains,forest,birch forest,taiga,woodland,woodlands,prarie,meadow,badlands,lavender fields,flower field,sunflower plains
dimensions=19,14,17
allowable_overhang=0
max_leveling=4
leveling_buffer=-1
preserve_water=0
preserve_lava=0

rule1=0,100,preserveBlock
rule2=0,100,minecraft:stone-6
rule3=0,100,stonebrick-0,stonebrick-0,stonebrick-0,stonebrick-0,stonebrick-1,stonebrick-2,stonebrick-2,stone-5,stone-6,cobblestone
rule4=0,100,stonebrick-0,stonebrick-2,stonebrick-2,stonebrick-1,stonebrick-1,cobblestone
rule5=0,100,stonebrick-0,stonebrick-1,stonebrick-2,stone-5,stone-5,stone-6,mycelium-0,mycelium
rule6=0,100,stonebrick-0,stonebrick-0,stonebrick-2,mycelium-0,mycelium-0,mycelium-0,mycelium
rule7=0,100,stonebrick-0,stonebrick-0,stonebrick-0,stonebrick-0,stonebrick-1,stonebrick-2,stonebrick-2,stone-5,stone-6,cobblestone,gravel
rule8=0,100,minecraft:stone_brick_stairs-3
rule9=0,100,minecraft:stone-5
rule10=0,100,minecraft:cobblestone_wall-0
rule11=0,100,minecraft:log-0
rule12=0,100,minecraft:oak_stairs-0,air
rule13=0,100,minecraft:planks-0,oak_stairs-0,oak_stairs-1,oak_stairs-4,oak_stairs-5,air
rule14=0,100,minecraft:oak_stairs-7,air
rule15=0,100,minecraft:oak_stairs-2,air
rule16=0,100,minecraft:planks-1,spruce_stairs-0,spruce_stairs-1,spruce_stairs-4,spruce_stairs-5,air,air,air
rule17=0,100,minecraft:mycelium-0
rule18=2,100,minecraft:planks-5,dark_oak_stairs-0,dark_oak_stairs-1,dark_oak_stairs-4,dark_oak_stairs-5,air,air,air,air,air,air
rule19=0,100,minecraft:spruce_stairs-5,air
rule20=0,100,minecraft:log2-1
rule21=0,100,minecraft:spruce_stairs-2,air
rule22=0,100,minecraft:stone_brick_stairs-1
rule23=0,100,minecraft:stone_brick_stairs-5
rule24=0,100,minecraft:stone_brick_stairs-7
rule25=0,100,minecraft:stone_slab-13
rule26=0,100,minecraft:stone_brick_stairs-4
rule27=0,100,minecraft:stone_brick_stairs-6
rule28=0,100,minecraft:log2-9
rule29=0,100,minecraft:log2-5
rule30=0,100,minecraft:stone_brick_stairs-0
rule31=0,100,ChestGenHook:chests/stronghold_corridor:5-3
rule32=0,100,minecraft:wooden_slab-9

layer
1,1,1,1,2,3,3,3,3,3,3,2,1,1,1,1,1
1,3,3,3,3,3,4,4,4,4,4,3,1,1,1,1,1
1,3,3,3,2,4,4,5,5,5,4,2,3,3,3,3,2
2,3,3,2,4,4,5,6,6,5,4,4,4,4,4,4,3
3,3,2,4,4,5,5,6,6,5,5,4,5,5,5,4,3
3,4,4,5,5,6,5,6,5,6,6,5,6,6,5,4,3
3,4,5,6,6,6,6,6,6,6,6,6,5,5,5,4,3
3,4,5,5,5,6,6,6,6,6,6,6,5,4,4,4,3
3,4,4,4,4,5,6,6,5,5,6,5,5,4,2,3,2
2,3,3,2,4,5,5,5,5,6,6,6,5,4,3,1,1
1,1,1,3,4,4,4,4,4,5,6,5,5,4,3,1,1
1,1,1,2,3,3,3,2,4,5,5,5,4,4,3,1,1
8,7,7,7,7,7,7,3,4,4,4,4,4,4,3,1,1
8,7,7,7,7,7,7,2,3,3,3,3,3,3,2,1,1
endlayer

layer
1,1,1,1,9,7,7,10,7,10,7,9,1,1,1,1,1
1,7,7,7,7,7,11,32,32,32,11,7,1,1,1,1,1
1,7,7,7,9,0,0,0,0,0,0,9,10,7,10,7,9
9,7,7,9,0,0,0,0,0,0,0,0,0,0,0,11,7
7,7,9,0,0,0,0,0,0,0,0,0,0,0,0,32,7
7,11,0,0,0,0,0,0,0,0,0,0,0,0,0,32,10
10,32,0,0,0,0,0,0,0,0,0,0,0,0,0,32,7
7,32,0,0,0,0,0,0,0,0,0,0,0,0,0,11,7
7,11,0,0,0,0,0,0,0,0,0,0,0,0,9,7,9
9,7,10,9,0,0,0,0,0,0,0,0,12,12,10,1,1
1,1,1,7,11,0,0,0,0,0,0,11,13,13,7,1,1
1,1,1,9,7,7,7,9,0,0,0,0,13,13,10,1,1
1,8,7,7,7,7,7,7,11,0,0,31,13,13,7,1,1
1,8,7,7,7,7,7,9,7,10,7,7,10,7,7,1,1
endlayer

layer
1,1,1,1,2,7,7,10,7,10,7,2,1,1,1,1,1
1,7,7,7,7,7,11,0,0,0,11,7,1,1,1,1,1
1,7,7,7,2,0,0,0,0,0,0,2,10,7,10,7,2
2,7,7,2,0,0,0,0,0,0,0,0,0,0,0,11,7
7,7,2,0,0,0,0,0,0,0,0,0,0,0,0,0,7
7,11,0,0,0,0,0,0,0,0,0,0,0,0,0,0,10
10,0,0,0,0,0,0,0,0,0,0,0,0,0,0,0,7
7,0,0,0,0,0,0,0,0,0,0,0,0,0,0,11,7
7,11,0,0,0,0,0,0,0,0,0,0,0,0,2,7,2
2,7,10,2,0,0,0,0,0,0,0,0,0,0,10,1,1
1,1,1,7,11,0,0,0,0,0,0,11,12,12,7,1,1
1,1,1,2,7,7,7,2,0,0,0,14,13,13,10,1,1
1,1,8,7,7,7,7,7,11,0,0,14,13,13,7,1,1
1,1,8,7,7,7,7,2,7,10,7,7,10,7,2,1,1
endlayer

layer
1,1,1,1,9,7,7,10,7,10,7,9,1,1,1,1,1
1,7,7,7,7,7,11,0,0,0,11,7,1,1,1,1,1
1,7,7,7,9,0,0,0,0,0,0,9,10,7,10,7,9
9,7,7,9,0,0,0,0,0,0,0,0,0,0,0,11,7
7,7,9,0,0,0,0,0,0,0,0,0,0,0,0,0,7
7,11,0,0,0,0,0,0,0,0,0,0,0,0,0,0,10
10,0,0,0,0,0,0,0,0,0,0,0,0,0,0,0,7
7,0,0,0,0,0,0,0,0,0,0,0,0,0,0,11,7
7,11,0,0,0,0,0,0,0,0,0,0,0,0,9,7,9
9,7,10,9,0,0,0,0,0,0,0,0,0,0,10,1,1
1,1,1,7,11,0,0,0,0,0,0,11,0,0,7,1,1
1,1,1,9,7,7,7,9,0,0,14,15,0,0,10,1,1
1,1,1,8,7,7,7,7,11,0,14,15,0,0,7,1,1
1,1,1,8,7,7,7,9,7,10,7,7,10,7,7,1,1
endlayer

layer
1,1,1,1,2,7,7,7,7,7,7,2,1,1,1,1,1
1,7,7,7,7,7,13,13,13,13,13,7,1,1,1,1,1
1,7,17,17,2,13,13,16,16,16,16,2,7,7,7,7,2
2,7,17,17,2,16,16,18,18,18,18,16,16,13,13,13,7
7,7,2,2,2,18,18,18,18,18,18,18,16,16,16,13,7
7,13,13,16,18,18,18,18,0,0,18,18,18,18,16,13,7
7,13,16,16,18,18,18,0,0,0,0,18,18,18,16,13,7
7,13,16,16,18,18,18,0,0,0,0,0,19,19,13,13,7
7,13,13,13,16,18,18,18,18,0,0,0,0,0,2,7,2
2,7,7,2,13,16,16,18,18,18,18,0,0,0,7,1,1
1,1,1,7,13,13,13,13,13,16,16,20,0,0,7,1,1
1,1,1,2,7,13,13,2,13,13,21,0,0,0,7,1,1
1,1,1,1,8,3,3,7,13,13,15,0,0,0,7,1,1
1,1,1,1,8,22,22,2,7,7,7,7,7,7,2,1,1
endlayer

layer
1,1,1,1,20,1,1,0,0,0,1,20,1,1,1,1,1
1,7,7,7,7,1,0,0,0,0,0,0,1,1,1,1,1
1,7,0,0,10,0,0,0,0,0,0,20,0,1,1,1,20
20,7,0,0,0,0,0,0,0,0,0,0,0,0,0,1,1
1,7,10,0,0,0,0,0,0,0,0,0,0,0,0,0,1
1,0,0,0,0,0,0,0,0,0,0,0,0,0,0,0,1
0,0,0,0,0,0,0,0,0,0,0,0,0,0,0,0,0
0,0,0,0,0,0,0,0,0,0,0,0,0,0,0,0,0
1,0,0,0,0,0,0,0,0,0,0,0,0,0,20,0,20
20,0,0,20,0,0,0,0,0,0,0,0,0,0,0,0,1
1,1,0,0,0,0,0,0,0,0,0,20,0,0,0,1,1
1,1,1,20,0,0,0,20,0,0,0,0,0,0,1,1,1
1,1,1,1,0,0,0,0,0,0,0,0,0,0,1,1,1
1,1,1,1,1,1,1,20,0,0,0,1,1,1,20,1,1
endlayer

layer
1,1,1,1,20,1,0,0,0,0,0,20,1,1,1,1,1
1,7,7,7,7,0,0,0,0,0,0,0,0,1,1,1,1
1,7,0,0,10,0,0,0,0,0,0,20,0,0,0,1,20
20,7,0,0,0,0,0,0,0,0,0,0,0,0,0,0,1
1,7,10,0,0,0,0,0,0,0,0,0,0,0,0,0,0
0,0,0,0,0,0,0,0,0,0,0,0,0,0,0,0,0
0,0,0,0,0,0,0,0,0,0,0,0,0,0,0,0,0
0,0,0,0,0,0,0,0,0,0,0,0,0,0,0,0,0
0,0,0,0,0,0,0,0,0,0,0,0,0,0,20,0,20
20,0,0,20,0,0,0,0,0,0,0,0,0,0,0,0,0
1,0,0,0,0,0,0,0,0,0,0,20,0,0,0,0,1
1,1,0,20,0,0,0,20,0,0,0,0,0,0,0,1,1
1,1,1,0,0,0,0,0,0,0,0,0,0,0,1,1,1
1,1,1,1,1,0,0,20,0,0,0,0,1,1,20,1,1
endlayer

layer
1,1,1,1,20,0,0,0,0,0,0,20,0,1,1,1,1
1,7,7,7,7,0,0,0,0,0,0,0,0,0,0,1,1
1,7,0,0,10,0,0,0,0,0,0,20,0,0,0,0,20
20,7,0,0,0,0,0,0,0,0,0,0,0,0,0,0,0
0,7,10,0,0,0,0,0,0,0,0,0,0,0,0,0,0
0,0,0,0,0,0,0,0,0,0,0,0,0,0,0,0,0
0,0,0,0,0,0,0,0,0,0,0,0,0,0,0,0,0
0,0,0,0,0,0,0,0,0,0,0,0,0,0,0,0,0
0,0,0,0,0,0,0,0,0,0,0,0,0,0,20,0,20
20,0,0,20,0,0,0,0,0,0,0,0,0,0,0,0,0
0,0,0,0,0,0,0,0,0,0,0,20,0,0,0,0,0
1,0,0,20,0,0,0,20,0,0,0,0,0,0,0,0,1
1,1,0,0,0,0,0,0,0,0,0,0,0,0,0,1,1
1,1,1,1,0,0,0,20,0,0,0,0,0,0,20,1,1
endlayer

layer
1,1,0,0,20,0,0,0,0,0,0,20,0,0,0,1,1
1,7,7,7,7,0,0,0,0,0,0,0,0,0,0,0,1
0,7,0,24,23,0,0,0,0,0,0,20,0,0,0,0,20
20,7,26,25,0,0,0,0,0,0,0,0,0,0,0,0,0
0,7,27,0,0,0,0,0,0,0,0,0,0,0,0,0,0
0,0,0,0,0,0,0,0,0,0,0,0,0,0,0,0,0
0,0,0,0,0,0,0,0,0,0,0,0,0,0,0,0,0
0,0,0,0,0,0,0,0,0,0,0,0,0,0,0,0,0
0,0,0,0,0,0,0,0,0,0,0,0,0,0,20,0,20
20,0,0,20,0,0,0,0,0,0,0,0,0,0,0,0,0
0,0,0,0,0,0,0,0,0,0,0,20,0,0,0,0,0
0,0,0,20,0,0,0,20,0,0,0,0,0,0,0,0,0
1,0,0,0,0,0,0,0,0,0,0,0,0,0,0,0,1
1,1,0,0,0,0,0,20,0,0,0,0,0,0,20,1,1
endlayer

layer
1,0,0,0,20,28,28,28,28,28,28,20,0,0,0,0,1
0,7,7,7,29,0,0,0,0,0,0,29,0,0,0,0,0
0,7,0,7,29,0,0,0,0,0,0,20,28,28,28,28,20
20,7,7,3,29,0,0,0,0,0,0,29,0,0,0,0,29
29,28,28,28,28,28,0,0,0,0,0,29,0,0,0,0,29
29,0,0,29,0,0,0,0,0,0,0,0,0,0,0,0,29
29,0,0,29,0,0,0,0,0,0,0,0,0,0,0,0,29
29,0,0,29,0,0,0,0,0,0,0,0,0,0,0,0,29
29,0,0,29,0,0,0,0,0,0,0,0,28,28,20,28,20
20,28,28,20,0,0,0,0,0,0,0,29,0,0,29,0,0
0,0,0,29,0,0,0,29,0,0,0,20,0,0,29,0,0
0,0,0,20,28,28,28,20,0,0,0,0,0,0,29,0,0
0,0,0,0,0,0,0,29,0,0,0,0,0,0,29,0,0
1,0,0,0,0,0,0,20,28,28,28,28,28,28,20,0,1
endlayer

layer
0,0,0,0,0,0,0,0,0,0,0,0,0,0,0,0,0
0,8,7,7,0,0,0,0,0,0,0,0,0,0,0,0,0
0,7,0,7,20,0,0,0,0,0,0,20,0,0,0,0,0
0,7,7,0,0,0,0,0,0,0,0,0,0,0,0,0,0
0,0,0,0,0,0,0,0,0,0,0,0,0,0,0,0,0
0,0,0,0,0,0,0,0,0,0,0,0,0,0,0,0,0
0,0,0,0,0,0,0,0,0,0,0,0,0,0,0,0,0
0,0,0,0,0,0,0,0,0,0,0,0,0,0,0,0,0
0,0,0,0,0,0,0,0,0,0,0,0,0,0,0,0,0
0,0,0,20,0,0,0,0,0,0,0,0,0,0,0,0,0
0,0,0,0,0,0,0,0,0,0,0,20,0,0,0,0,0
0,0,0,0,0,0,0,20,0,0,0,0,0,0,0,0,0
0,0,0,0,0,0,0,0,0,0,0,0,0,0,0,0,0
0,0,0,0,0,0,0,0,0,0,0,0,0,0,0,0,0
endlayer

layer
0,0,0,0,0,0,0,0,0,0,0,0,0,0,0,0,0
0,0,7,7,0,0,0,0,0,0,0,0,0,0,0,0,0
0,7,0,7,20,0,0,0,0,0,0,20,0,0,0,0,0
0,7,7,0,0,0,0,0,0,0,0,0,0,0,0,0,0
0,0,0,0,0,0,0,0,0,0,0,0,0,0,0,0,0
0,0,0,0,0,0,0,0,0,0,0,0,0,0,0,0,0
0,0,0,0,0,0,0,0,0,0,0,0,0,0,0,0,0
0,0,0,0,0,0,0,0,0,0,0,0,0,0,0,0,0
0,0,0,0,0,0,0,0,0,0,0,0,0,0,0,0,0
0,0,0,20,0,0,0,0,0,0,0,0,0,0,0,0,0
0,0,0,0,0,0,0,0,0,0,0,20,0,0,0,0,0
0,0,0,0,0,0,0,20,0,0,0,0,0,0,0,0,0
0,0,0,0,0,0,0,0,0,0,0,0,0,0,0,0,0
0,0,0,0,0,0,0,0,0,0,0,0,0,0,0,0,0
endlayer

layer
0,0,0,0,0,0,0,0,0,0,0,0,0,0,0,0,0
0,0,7,7,0,0,0,0,0,0,0,0,0,0,0,0,0
0,7,0,7,20,0,0,0,0,0,0,20,0,0,0,0,0
0,7,7,0,0,0,0,0,0,0,0,0,0,0,0,0,0
0,0,0,0,0,0,0,0,0,0,0,0,0,0,0,0,0
0,0,0,0,0,0,0,0,0,0,0,0,0,0,0,0,0
0,0,0,0,0,0,0,0,0,0,0,0,0,0,0,0,0
0,0,0,0,0,0,0,0,0,0,0,0,0,0,0,0,0
0,0,0,0,0,0,0,0,0,0,0,0,0,0,0,0,0
0,0,0,20,0,0,0,0,0,0,0,0,0,0,0,0,0
0,0,0,0,0,0,0,0,0,0,0,20,0,0,0,0,0
0,0,0,0,0,0,0,0,0,0,0,0,0,0,0,0,0
0,0,0,0,0,0,0,0,0,0,0,0,0,0,0,0,0
0,0,0,0,0,0,0,0,0,0,0,0,0,0,0,0,0
endlayer

layer
0,0,0,0,0,0,0,0,0,0,0,0,0,0,0,0,0
0,0,7,30,0,0,0,0,0,0,0,0,0,0,0,0,0
0,7,0,7,20,0,0,0,0,0,0,0,0,0,0,0,0
0,7,7,0,0,0,0,0,0,0,0,0,0,0,0,0,0
0,0,0,0,0,0,0,0,0,0,0,0,0,0,0,0,0
0,0,0,0,0,0,0,0,0,0,0,0,0,0,0,0,0
0,0,0,0,0,0,0,0,0,0,0,0,0,0,0,0,0
0,0,0,0,0,0,0,0,0,0,0,0,0,0,0,0,0
0,0,0,0,0,0,0,0,0,0,0,0,0,0,0,0,0
0,0,0,0,0,0,0,0,0,0,0,0,0,0,0,0,0
0,0,0,0,0,0,0,0,0,0,0,20,0,0,0,0,0
0,0,0,0,0,0,0,0,0,0,0,0,0,0,0,0,0
0,0,0,0,0,0,0,0,0,0,0,0,0,0,0,0,0
0,0,0,0,0,0,0,0,0,0,0,0,0,0,0,0,0
endlayer

layer
0,0,0,0,0,0,0,0,0,0,0,0,0,0,0,0,0
0,0,7,0,0,0,0,0,0,0,0,0,0,0,0,0,0
0,7,0,7,0,0,0,0,0,0,0,0,0,0,0,0,0
0,8,7,0,0,0,0,0,0,0,0,0,0,0,0,0,0
0,0,0,0,0,0,0,0,0,0,0,0,0,0,0,0,0
0,0,0,0,0,0,0,0,0,0,0,0,0,0,0,0,0
0,0,0,0,0,0,0,0,0,0,0,0,0,0,0,0,0
0,0,0,0,0,0,0,0,0,0,0,0,0,0,0,0,0
0,0,0,0,0,0,0,0,0,0,0,0,0,0,0,0,0
0,0,0,0,0,0,0,0,0,0,0,0,0,0,0,0,0
0,0,0,0,0,0,0,0,0,0,0,0,0,0,0,0,0
0,0,0,0,0,0,0,0,0,0,0,0,0,0,0,0,0
0,0,0,0,0,0,0,0,0,0,0,0,0,0,0,0,0
0,0,0,0,0,0,0,0,0,0,0,0,0,0,0,0,0
endlayer

layer
0,0,0,0,0,0,0,0,0,0,0,0,0,0,0,0,0
0,0,7,0,0,0,0,0,0,0,0,0,0,0,0,0,0
0,7,0,7,0,0,0,0,0,0,0,0,0,0,0,0,0
0,0,7,0,0,0,0,0,0,0,0,0,0,0,0,0,0
0,0,0,0,0,0,0,0,0,0,0,0,0,0,0,0,0
0,0,0,0,0,0,0,0,0,0,0,0,0,0,0,0,0
0,0,0,0,0,0,0,0,0,0,0,0,0,0,0,0,0
0,0,0,0,0,0,0,0,0,0,0,0,0,0,0,0,0
0,0,0,0,0,0,0,0,0,0,0,0,0,0,0,0,0
0,0,0,0,0,0,0,0,0,0,0,0,0,0,0,0,0
0,0,0,0,0,0,0,0,0,0,0,0,0,0,0,0,0
0,0,0,0,0,0,0,0,0,0,0,0,0,0,0,0,0
0,0,0,0,0,0,0,0,0,0,0,0,0,0,0,0,0
0,0,0,0,0,0,0,0,0,0,0,0,0,0,0,0,0
endlayer

layer
0,0,0,0,0,0,0,0,0,0,0,0,0,0,0,0,0
0,0,7,0,0,0,0,0,0,0,0,0,0,0,0,0,0
0,7,0,7,0,0,0,0,0,0,0,0,0,0,0,0,0
0,0,0,0,0,0,0,0,0,0,0,0,0,0,0,0,0
0,0,0,0,0,0,0,0,0,0,0,0,0,0,0,0,0
0,0,0,0,0,0,0,0,0,0,0,0,0,0,0,0,0
0,0,0,0,0,0,0,0,0,0,0,0,0,0,0,0,0
0,0,0,0,0,0,0,0,0,0,0,0,0,0,0,0,0
0,0,0,0,0,0,0,0,0,0,0,0,0,0,0,0,0
0,0,0,0,0,0,0,0,0,0,0,0,0,0,0,0,0
0,0,0,0,0,0,0,0,0,0,0,0,0,0,0,0,0
0,0,0,0,0,0,0,0,0,0,0,0,0,0,0,0,0
0,0,0,0,0,0,0,0,0,0,0,0,0,0,0,0,0
0,0,0,0,0,0,0,0,0,0,0,0,0,0,0,0,0
endlayer

layer
0,0,0,0,0,0,0,0,0,0,0,0,0,0,0,0,0
0,0,7,0,0,0,0,0,0,0,0,0,0,0,0,0,0
0,0,0,7,0,0,0,0,0,0,0,0,0,0,0,0,0
0,0,0,0,0,0,0,0,0,0,0,0,0,0,0,0,0
0,0,0,0,0,0,0,0,0,0,0,0,0,0,0,0,0
0,0,0,0,0,0,0,0,0,0,0,0,0,0,0,0,0
0,0,0,0,0,0,0,0,0,0,0,0,0,0,0,0,0
0,0,0,0,0,0,0,0,0,0,0,0,0,0,0,0,0
0,0,0,0,0,0,0,0,0,0,0,0,0,0,0,0,0
0,0,0,0,0,0,0,0,0,0,0,0,0,0,0,0,0
0,0,0,0,0,0,0,0,0,0,0,0,0,0,0,0,0
0,0,0,0,0,0,0,0,0,0,0,0,0,0,0,0,0
0,0,0,0,0,0,0,0,0,0,0,0,0,0,0,0,0
0,0,0,0,0,0,0,0,0,0,0,0,0,0,0,0,0
endlayer

layer
0,0,0,0,0,0,0,0,0,0,0,0,0,0,0,0,0
0,0,7,0,0,0,0,0,0,0,0,0,0,0,0,0,0
0,0,0,0,0,0,0,0,0,0,0,0,0,0,0,0,0
0,0,0,0,0,0,0,0,0,0,0,0,0,0,0,0,0
0,0,0,0,0,0,0,0,0,0,0,0,0,0,0,0,0
0,0,0,0,0,0,0,0,0,0,0,0,0,0,0,0,0
0,0,0,0,0,0,0,0,0,0,0,0,0,0,0,0,0
0,0,0,0,0,0,0,0,0,0,0,0,0,0,0,0,0
0,0,0,0,0,0,0,0,0,0,0,0,0,0,0,0,0
0,0,0,0,0,0,0,0,0,0,0,0,0,0,0,0,0
0,0,0,0,0,0,0,0,0,0,0,0,0,0,0,0,0
0,0,0,0,0,0,0,0,0,0,0,0,0,0,0,0,0
0,0,0,0,0,0,0,0,0,0,0,0,0,0,0,0,0
0,0,0,0,0,0,0,0,0,0,0,0,0,0,0,0,0
endlayer

