
# Created by Ruins mod version 17.1 Ingame Parser
# authoring Player: ST753M

weight=2
embed_into_distance=128
acceptable_target_blocks=
unacceptable_target_blocks=end_stone
dimensions=10,74,13
allowable_overhang=999
max_leveling=0
leveling_buffer=-1
preserve_water=0
preserve_lava=0

biomesToSpawnIn=river,ocean,deep_ocean,coral_reef,kelp_forest,coralium_infested_ocean,rocky_plains,rocky_plateau,hell,undergarden,visceral_heap,phantasmagoric_inferno,corrupted_sands,fungi_forest,ruthless_sands,torrid_wasteland,arctic_abyss,polar_chasm

=0,100,air
rule1=0,100,preserveBlock

rule2=0,100,bloodmagic:demon_brick_2-2
^0,100,bloodmagic:demon_brick_2-3
^0,100,bloodmagic:demon_brick_2-4
^0,100,bloodmagic:demon_brick_2-1
^0,100,bloodmagic:demon_brick_2-2
^0,100,bloodmagic:demon_brick_2-0

rule3^0,100,bloodmagic:demon_brick_2-7
^0,100,bloodmagic:demon_brick_2-8
^0,100,bloodmagic:demon_brick_2-9
^0,100,bloodmagic:demon_brick_2-6
^0,100,bloodmagic:demon_brick_2-7
^0,100,bloodmagic:demon_brick_2-5

rule4^0,100,bloodmagic:demon_light-2
^0,100,bloodmagic:demon_light-3
^0,100,bloodmagic:demon_light-4
^0,100,bloodmagic:demon_light-1
^0,100,bloodmagic:demon_light-2
^0,100,bloodmagic:demon_light-0

rule5^0,100,bloodmagic:demon_brick_2-12
^0,100,bloodmagic:demon_brick_2-13
^0,100,bloodmagic:demon_brick_2-14
^0,100,bloodmagic:demon_brick_2-11
^0,100,bloodmagic:demon_brick_2-12
^0,100,bloodmagic:demon_brick_2-10

rule6^0,100,bloodmagic:demon_pillar_cap_2-0
^0,100,bloodmagic:demon_pillar_cap_2-1
^0,100,bloodmagic:demon_pillar_cap_3-0
^0,100,bloodmagic:demon_pillar_cap_1-1
^0,100,bloodmagic:demon_pillar_cap_2-0
^0,100,bloodmagic:demon_pillar_cap_1-0

rule7^0,100,minecraft:lava-0
^0,100,minecraft:lava-0
^0,100,minecraft:lava-0
^0,100,minecraft:lava-0
^0,100,minecraft:lava-0
^0,100,minecraft:lava-0

rule8^0,100,bloodmagic:demon_pillar_2-2
^0,100,bloodmagic:demon_pillar_2-3
^0,100,bloodmagic:demon_pillar_2-4
^0,100,bloodmagic:demon_pillar_2-1
^0,100,bloodmagic:demon_pillar_2-2
^0,100,bloodmagic:demon_pillar_2-0

rule9^0,100,bloodmagic:demon_extras-7
^0,100,bloodmagic:demon_extras-8
^0,100,bloodmagic:demon_extras-9
^0,100,bloodmagic:demon_extras-6
^0,100,bloodmagic:demon_extras-7
^0,100,bloodmagic:demon_extras-5

rule10^0,100,bloodmagic:demon_pillar_cap_2-2
^0,100,bloodmagic:demon_pillar_cap_2-3
^0,100,bloodmagic:demon_pillar_cap_3-2
^0,100,bloodmagic:demon_pillar_cap_1-3
^0,100,bloodmagic:demon_pillar_cap_2-2
^0,100,bloodmagic:demon_pillar_cap_1-2

rule11^0,100,bloodmagic:demon_pillar_cap_2-4
^0,100,bloodmagic:demon_pillar_cap_2-5
^0,100,bloodmagic:demon_pillar_cap_3-4
^0,100,bloodmagic:demon_pillar_cap_1-5
^0,100,bloodmagic:demon_pillar_cap_2-4
^0,100,bloodmagic:demon_pillar_cap_1-4

rule12^0,100,bloodmagic:demon_pillar_2-12
^0,100,bloodmagic:demon_pillar_2-13
^0,100,bloodmagic:demon_pillar_2-14
^0,100,bloodmagic:demon_pillar_2-11
^0,100,bloodmagic:demon_pillar_2-12
^0,100,bloodmagic:demon_pillar_2-10

rule13^0,100,bloodmagic:demon_pillar_cap_2-6
^0,100,bloodmagic:demon_pillar_cap_2-7
^0,100,bloodmagic:demon_pillar_cap_3-6
^0,100,bloodmagic:demon_pillar_cap_1-7
^0,100,bloodmagic:demon_pillar_cap_2-6
^0,100,bloodmagic:demon_pillar_cap_1-6

rule14^0,100,bloodmagic:demon_wall_1-12
^0,100,bloodmagic:demon_wall_1-3
^0,100,bloodmagic:demon_wall_1-14
^0,100,bloodmagic:demon_wall_1-1
^0,100,bloodmagic:demon_wall_1-12
^0,100,bloodmagic:demon_wall_1-0

layer
1,1,1,1,2,2,2,2,2,1,1,1,1
1,1,2,3,3,3,3,3,3,3,2,1,1
1,1,2,3,3,3,4,3,3,3,2,1,1
1,1,2,3,3,3,3,3,3,3,2,1,1
1,1,2,3,3,3,3,3,3,3,2,1,1
1,1,2,3,3,3,4,3,3,3,2,1,1
1,1,2,3,3,3,3,3,3,3,2,1,1
1,1,2,3,3,3,3,3,3,3,2,1,1
1,1,2,3,3,3,4,3,3,3,2,1,1
1,1,2,3,3,3,3,3,3,3,2,1,1
1,1,2,3,3,3,3,3,3,3,2,1,1
1,1,2,3,3,3,4,3,3,3,2,1,1
1,1,2,3,3,3,3,3,3,3,2,1,1
1,1,2,3,3,3,3,3,3,3,2,1,1
1,1,2,3,3,3,4,3,3,3,2,1,1
1,1,2,3,3,3,3,3,3,3,2,1,1
1,1,2,3,3,3,3,3,3,3,2,1,1
1,1,2,3,3,3,4,3,3,3,2,1,1
1,1,2,3,3,3,3,3,3,3,2,1,1
1,1,2,3,3,3,3,3,3,3,2,1,1
1,1,2,3,3,3,4,3,3,3,2,1,1
1,1,2,3,3,3,3,3,3,3,2,1,1
1,1,2,3,3,3,3,3,3,3,2,1,1
1,1,2,3,3,3,4,3,3,3,2,1,1
1,1,2,3,3,3,3,3,3,3,2,1,1
1,1,2,3,3,3,3,3,3,3,2,1,1
1,1,2,3,3,3,4,3,3,3,2,1,1
1,1,2,3,3,3,3,3,3,3,2,1,1
1,1,2,3,3,3,3,3,3,3,2,1,1
1,1,2,3,3,3,4,3,3,3,2,1,1
1,1,2,3,3,3,3,3,3,3,2,1,1
1,1,2,3,3,3,3,3,3,3,2,1,1
1,1,2,3,3,3,4,3,3,3,2,1,1
1,1,2,3,3,3,3,3,3,3,2,1,1
1,1,2,3,3,3,3,3,3,3,2,1,1
1,1,2,3,3,3,4,3,3,3,2,1,1
1,1,2,3,3,3,3,3,3,3,2,1,1
1,1,2,3,3,3,3,3,3,3,2,1,1
1,1,2,3,3,3,4,3,3,3,2,1,1
1,1,2,3,3,3,3,3,3,3,2,1,1
1,1,2,3,3,3,3,3,3,3,2,1,1
1,1,2,3,3,3,4,3,3,3,2,1,1
1,1,2,3,3,3,3,3,3,3,2,1,1
1,1,2,3,3,3,3,3,3,3,2,1,1
1,1,2,3,3,3,4,3,3,3,2,1,1
1,1,2,3,3,3,3,3,3,3,2,1,1
1,1,2,3,3,3,3,3,3,3,2,1,1
1,1,2,3,3,3,4,3,3,3,2,1,1
1,1,2,3,3,3,3,3,3,3,2,1,1
1,1,2,3,3,3,3,3,3,3,2,1,1
1,1,2,3,3,3,4,3,3,3,2,1,1
1,1,2,3,3,3,3,3,3,3,2,1,1
1,1,2,3,3,3,3,3,3,3,2,1,1
1,1,2,3,3,3,4,3,3,3,2,1,1
1,1,2,3,3,3,3,3,3,3,2,1,1
1,1,2,3,3,3,3,3,3,3,2,1,1
1,1,2,3,3,3,4,3,3,3,2,1,1
1,1,2,3,3,3,3,3,3,3,2,1,1
1,1,2,3,3,3,3,3,3,3,2,1,1
1,1,2,3,3,3,4,3,3,3,2,1,1
1,1,2,3,3,3,3,3,3,3,2,1,1
1,1,2,3,3,3,3,3,3,3,2,1,1
1,1,2,3,3,3,4,3,3,3,2,1,1
1,1,2,3,3,3,3,3,3,3,2,1,1
1,1,2,3,3,3,3,3,3,3,2,1,1
1,1,2,3,3,3,4,3,3,3,2,1,1
1,1,2,3,3,3,3,3,3,3,2,1,1
1,1,2,3,3,3,3,3,3,3,2,1,1
1,1,2,3,3,3,4,3,3,3,2,1,1
1,1,2,3,3,3,3,3,3,3,2,1,1
1,1,2,3,3,3,3,3,3,3,2,1,1
1,1,2,3,3,3,4,3,3,3,2,1,1
1,1,2,3,3,3,3,3,3,3,2,1,1
1,1,1,1,2,2,2,2,2,1,1,1,1
endlayer

layer
1,1,2,2,2,5,6,5,2,2,2,1,1
1,2,7,7,7,7,7,7,7,7,7,2,1
1,2,7,8,7,7,7,7,7,8,7,2,1
1,2,7,7,7,7,7,7,7,7,7,2,1
1,2,7,7,7,7,7,7,7,7,7,2,1
1,2,7,8,7,7,7,7,7,8,7,2,1
1,2,7,7,7,7,7,7,7,7,7,2,1
1,2,7,7,7,7,7,7,7,7,7,2,1
1,2,7,8,7,7,7,7,7,8,7,2,1
1,2,7,7,7,7,7,7,7,7,7,2,1
1,2,7,7,7,7,7,7,7,7,7,2,1
1,2,7,8,7,7,7,7,7,8,7,2,1
1,2,7,7,7,7,7,7,7,7,7,2,1
1,2,7,7,7,7,7,7,7,7,7,2,1
1,2,7,8,7,7,7,7,7,8,7,2,1
1,2,7,7,7,7,7,7,7,7,7,2,1
1,2,7,7,7,7,7,7,7,7,7,2,1
1,2,7,8,7,7,7,7,7,8,7,2,1
1,2,7,7,7,7,7,7,7,7,7,2,1
1,2,7,7,7,7,7,7,7,7,7,2,1
1,2,7,8,7,7,7,7,7,8,7,2,1
1,2,7,7,7,7,7,7,7,7,7,2,1
1,2,7,7,7,7,7,7,7,7,7,2,1
1,2,7,8,7,7,7,7,7,8,7,2,1
1,2,7,7,7,7,7,7,7,7,7,2,1
1,2,7,7,7,7,7,7,7,7,7,2,1
1,2,7,8,7,7,7,7,7,8,7,2,1
1,2,7,7,7,7,7,7,7,7,7,2,1
1,2,7,7,7,7,7,7,7,7,7,2,1
1,2,7,8,7,7,7,7,7,8,7,2,1
1,2,7,7,7,7,7,7,7,7,7,2,1
1,2,7,7,7,7,7,7,7,7,7,2,1
1,2,7,8,7,7,7,7,7,8,7,2,1
1,2,7,7,7,7,7,7,7,7,7,2,1
1,2,7,7,7,7,7,7,7,7,7,2,1
1,2,7,8,7,7,7,7,7,8,7,2,1
1,2,7,7,7,7,7,7,7,7,7,2,1
1,2,7,7,7,7,7,7,7,7,7,2,1
1,2,7,8,7,7,7,7,7,8,7,2,1
1,2,7,7,7,7,7,7,7,7,7,2,1
1,2,7,7,7,7,7,7,7,7,7,2,1
1,2,7,8,7,7,7,7,7,8,7,2,1
1,2,7,7,7,7,7,7,7,7,7,2,1
1,2,7,7,7,7,7,7,7,7,7,2,1
1,2,7,8,7,7,7,7,7,8,7,2,1
1,2,7,7,7,7,7,7,7,7,7,2,1
1,2,7,7,7,7,7,7,7,7,7,2,1
1,2,7,8,7,7,7,7,7,8,7,2,1
1,2,7,7,7,7,7,7,7,7,7,2,1
1,2,7,7,7,7,7,7,7,7,7,2,1
1,2,7,8,7,7,7,7,7,8,7,2,1
1,2,7,7,7,7,7,7,7,7,7,2,1
1,2,7,7,7,7,7,7,7,7,7,2,1
1,2,7,8,7,7,7,7,7,8,7,2,1
1,2,7,7,7,7,7,7,7,7,7,2,1
1,2,7,7,7,7,7,7,7,7,7,2,1
1,2,7,8,7,7,7,7,7,8,7,2,1
1,2,7,7,7,7,7,7,7,7,7,2,1
1,2,7,7,7,7,7,7,7,7,7,2,1
1,2,7,8,7,7,7,7,7,8,7,2,1
1,2,7,7,7,7,7,7,7,7,7,2,1
1,2,7,7,7,7,7,7,7,7,7,2,1
1,2,7,8,7,7,7,7,7,8,7,2,1
1,2,7,7,7,7,7,7,7,7,7,2,1
1,2,7,7,7,7,7,7,7,7,7,2,1
1,2,7,8,7,7,7,7,7,8,7,2,1
1,2,7,7,7,7,7,7,7,7,7,2,1
1,2,7,7,7,7,7,7,7,7,7,2,1
1,2,7,8,7,7,7,7,7,8,7,2,1
1,2,7,7,7,7,7,7,7,7,7,2,1
1,2,7,7,7,7,7,7,7,7,7,2,1
1,2,7,8,7,7,7,7,7,8,7,2,1
1,2,7,7,7,7,7,7,7,7,7,2,1
1,1,2,2,2,5,6,5,2,2,2,1,1
endlayer

layer
1,1,2,2,4,3,8,3,4,2,2,1,1
1,3,3,0,0,0,0,0,0,0,3,3,1
6,3,3,8,0,0,0,0,0,8,3,3,6
1,3,3,0,0,0,0,0,0,0,3,3,1
1,3,3,0,0,0,0,0,0,0,3,3,1
6,3,3,8,0,0,0,0,0,8,3,3,6
1,3,3,0,0,0,0,0,0,0,3,3,1
1,3,3,0,0,0,0,0,0,0,3,3,1
6,3,3,8,0,0,0,0,0,8,3,3,6
1,3,3,0,0,0,0,0,0,0,3,3,1
1,3,3,0,0,0,0,0,0,0,3,3,1
6,3,3,8,0,0,0,0,0,8,3,3,6
1,3,3,0,0,0,0,0,0,0,3,3,1
1,3,3,0,0,0,0,0,0,0,3,3,1
6,3,3,8,0,0,0,0,0,8,3,3,6
1,3,3,0,0,0,0,0,0,0,3,3,1
1,3,3,0,0,0,0,0,0,0,3,3,1
6,3,3,8,0,0,0,0,0,8,3,3,6
1,3,3,0,0,0,0,0,0,0,3,3,1
1,3,3,0,0,0,0,0,0,0,3,3,1
6,3,3,8,0,0,0,0,0,8,3,3,6
1,3,3,0,0,0,0,0,0,0,3,3,1
1,3,3,0,0,0,0,0,0,0,3,3,1
6,3,3,8,0,0,0,0,0,8,3,3,6
1,3,3,0,0,0,0,0,0,0,3,3,1
1,3,3,0,0,0,0,0,0,0,3,3,1
6,3,3,8,0,0,0,0,0,8,3,3,6
1,3,3,0,0,0,0,0,0,0,3,3,1
1,3,3,0,0,0,0,0,0,0,3,3,1
6,3,3,8,0,0,0,0,0,8,3,3,6
1,3,3,0,0,0,0,0,0,0,3,3,1
1,3,3,0,0,0,0,0,0,0,3,3,1
6,3,3,8,0,0,0,0,0,8,3,3,6
1,3,3,0,0,0,0,0,0,0,3,3,1
1,3,3,0,0,0,0,0,0,0,3,3,1
6,3,3,8,0,0,0,0,0,8,3,3,6
1,3,3,0,0,0,0,0,0,0,3,3,1
1,3,3,0,0,0,0,0,0,0,3,3,1
6,3,3,8,0,0,0,0,0,8,3,3,6
1,3,3,0,0,0,0,0,0,0,3,3,1
1,3,3,0,0,0,0,0,0,0,3,3,1
6,3,3,8,0,0,0,0,0,8,3,3,6
1,3,3,0,0,0,0,0,0,0,3,3,1
1,3,3,0,0,0,0,0,0,0,3,3,1
6,3,3,8,0,0,0,0,0,8,3,3,6
1,3,3,0,0,0,0,0,0,0,3,3,1
1,3,3,0,0,0,0,0,0,0,3,3,1
6,3,3,8,0,0,0,0,0,8,3,3,6
1,3,3,0,0,0,0,0,0,0,3,3,1
1,3,3,0,0,0,0,0,0,0,3,3,1
6,3,3,8,0,0,0,0,0,8,3,3,6
1,3,3,0,0,0,0,0,0,0,3,3,1
1,3,3,0,0,0,0,0,0,0,3,3,1
6,3,3,8,0,0,0,0,0,8,3,3,6
1,3,3,0,0,0,0,0,0,0,3,3,1
1,3,3,0,0,0,0,0,0,0,3,3,1
6,3,3,8,0,0,0,0,0,8,3,3,6
1,3,3,0,0,0,0,0,0,0,3,3,1
1,3,3,0,0,0,0,0,0,0,3,3,1
6,3,3,8,0,0,0,0,0,8,3,3,6
1,3,3,0,0,0,0,0,0,0,3,3,1
1,3,3,0,0,0,0,0,0,0,3,3,1
6,3,3,8,0,0,0,0,0,8,3,3,6
1,3,3,0,0,0,0,0,0,0,3,3,1
1,3,3,0,0,0,0,0,0,0,3,3,1
6,3,3,8,0,0,0,0,0,8,3,3,6
1,3,3,0,0,0,0,0,0,0,3,3,1
1,3,3,0,0,0,0,0,0,0,3,3,1
6,3,3,8,0,0,0,0,0,8,3,3,6
1,3,3,0,0,0,0,0,0,0,3,3,1
1,3,3,0,0,0,0,0,0,0,3,3,1
6,3,3,8,0,0,0,0,0,8,3,3,6
1,3,3,0,0,0,0,0,0,0,3,3,1
1,1,2,2,4,3,8,3,4,2,2,1,1
endlayer

layer
1,9,2,5,3,3,8,3,3,5,2,9,1
9,0,0,0,0,0,0,0,0,0,0,0,9
8,0,0,10,0,0,0,0,0,10,0,0,8
9,0,0,0,0,0,0,0,0,0,0,0,9
9,0,0,0,0,0,0,0,0,0,0,0,9
8,0,0,10,0,0,0,0,0,10,0,0,8
9,0,0,0,0,0,0,0,0,0,0,0,9
9,0,0,0,0,0,0,0,0,0,0,0,9
8,0,0,10,0,0,0,0,0,10,0,0,8
9,0,0,0,0,0,0,0,0,0,0,0,9
9,0,0,0,0,0,0,0,0,0,0,0,9
8,0,0,10,0,0,0,0,0,10,0,0,8
9,0,0,0,0,0,0,0,0,0,0,0,9
9,0,0,0,0,0,0,0,0,0,0,0,9
8,0,0,10,0,0,0,0,0,10,0,0,8
9,0,0,0,0,0,0,0,0,0,0,0,9
9,0,0,0,0,0,0,0,0,0,0,0,9
8,0,0,10,0,0,0,0,0,10,0,0,8
9,0,0,0,0,0,0,0,0,0,0,0,9
9,0,0,0,0,0,0,0,0,0,0,0,9
8,0,0,10,0,0,0,0,0,10,0,0,8
9,0,0,0,0,0,0,0,0,0,0,0,9
9,0,0,0,0,0,0,0,0,0,0,0,9
8,0,0,10,0,0,0,0,0,10,0,0,8
9,0,0,0,0,0,0,0,0,0,0,0,9
9,0,0,0,0,0,0,0,0,0,0,0,9
8,0,0,10,0,0,0,0,0,10,0,0,8
9,0,0,0,0,0,0,0,0,0,0,0,9
9,0,0,0,0,0,0,0,0,0,0,0,9
8,0,0,10,0,0,0,0,0,10,0,0,8
9,0,0,0,0,0,0,0,0,0,0,0,9
9,0,0,0,0,0,0,0,0,0,0,0,9
8,0,0,10,0,0,0,0,0,10,0,0,8
9,0,0,0,0,0,0,0,0,0,0,0,9
9,0,0,0,0,0,0,0,0,0,0,0,9
8,0,0,10,0,0,0,0,0,10,0,0,8
9,0,0,0,0,0,0,0,0,0,0,0,9
9,0,0,0,0,0,0,0,0,0,0,0,9
8,0,0,10,0,0,0,0,0,10,0,0,8
9,0,0,0,0,0,0,0,0,0,0,0,9
9,0,0,0,0,0,0,0,0,0,0,0,9
8,0,0,10,0,0,0,0,0,10,0,0,8
9,0,0,0,0,0,0,0,0,0,0,0,9
9,0,0,0,0,0,0,0,0,0,0,0,9
8,0,0,10,0,0,0,0,0,10,0,0,8
9,0,0,0,0,0,0,0,0,0,0,0,9
9,0,0,0,0,0,0,0,0,0,0,0,9
8,0,0,10,0,0,0,0,0,10,0,0,8
9,0,0,0,0,0,0,0,0,0,0,0,9
9,0,0,0,0,0,0,0,0,0,0,0,9
8,0,0,10,0,0,0,0,0,10,0,0,8
9,0,0,0,0,0,0,0,0,0,0,0,9
9,0,0,0,0,0,0,0,0,0,0,0,9
8,0,0,10,0,0,0,0,0,10,0,0,8
9,0,0,0,0,0,0,0,0,0,0,0,9
9,0,0,0,0,0,0,0,0,0,0,0,9
8,0,0,10,0,0,0,0,0,10,0,0,8
9,0,0,0,0,0,0,0,0,0,0,0,9
9,0,0,0,0,0,0,0,0,0,0,0,9
8,0,0,10,0,0,0,0,0,10,0,0,8
9,0,0,0,0,0,0,0,0,0,0,0,9
9,0,0,0,0,0,0,0,0,0,0,0,9
8,0,0,10,0,0,0,0,0,10,0,0,8
9,0,0,0,0,0,0,0,0,0,0,0,9
9,0,0,0,0,0,0,0,0,0,0,0,9
8,0,0,10,0,0,0,0,0,10,0,0,8
9,0,0,0,0,0,0,0,0,0,0,0,9
9,0,0,0,0,0,0,0,0,0,0,0,9
8,0,0,10,0,0,0,0,0,10,0,0,8
9,0,0,0,0,0,0,0,0,0,0,0,9
9,0,0,0,0,0,0,0,0,0,0,0,9
8,0,0,10,0,0,0,0,0,10,0,0,8
9,0,0,0,0,0,0,0,0,0,0,0,9
1,9,2,5,3,3,8,3,3,5,2,9,1
endlayer

layer
1,9,2,13,12,12,5,12,12,11,2,9,1
2,0,0,0,0,0,0,0,0,0,0,0,2
8,0,0,14,0,0,0,0,0,14,0,0,8
2,0,0,0,0,0,0,0,0,0,0,0,2
2,0,0,0,0,0,0,0,0,0,0,0,2
8,0,0,14,0,0,0,0,0,14,0,0,8
2,0,0,0,0,0,0,0,0,0,0,0,2
2,0,0,0,0,0,0,0,0,0,0,0,2
8,0,0,14,0,0,0,0,0,14,0,0,8
2,0,0,0,0,0,0,0,0,0,0,0,2
2,0,0,0,0,0,0,0,0,0,0,0,2
8,0,0,14,0,0,0,0,0,14,0,0,8
2,0,0,0,0,0,0,0,0,0,0,0,2
2,0,0,0,0,0,0,0,0,0,0,0,2
8,0,0,14,0,0,0,0,0,14,0,0,8
2,0,0,0,0,0,0,0,0,0,0,0,2
2,0,0,0,0,0,0,0,0,0,0,0,2
8,0,0,14,0,0,0,0,0,14,0,0,8
2,0,0,0,0,0,0,0,0,0,0,0,2
2,0,0,0,0,0,0,0,0,0,0,0,2
8,0,0,14,0,0,0,0,0,14,0,0,8
2,0,0,0,0,0,0,0,0,0,0,0,2
2,0,0,0,0,0,0,0,0,0,0,0,2
8,0,0,14,0,0,0,0,0,14,0,0,8
2,0,0,0,0,0,0,0,0,0,0,0,2
2,0,0,0,0,0,0,0,0,0,0,0,2
8,0,0,14,0,0,0,0,0,14,0,0,8
2,0,0,0,0,0,0,0,0,0,0,0,2
2,0,0,0,0,0,0,0,0,0,0,0,2
8,0,0,14,0,0,0,0,0,14,0,0,8
2,0,0,0,0,0,0,0,0,0,0,0,2
2,0,0,0,0,0,0,0,0,0,0,0,2
8,0,0,14,0,0,0,0,0,14,0,0,8
2,0,0,0,0,0,0,0,0,0,0,0,2
2,0,0,0,0,0,0,0,0,0,0,0,2
8,0,0,14,0,0,0,0,0,14,0,0,8
2,0,0,0,0,0,0,0,0,0,0,0,2
2,0,0,0,0,0,0,0,0,0,0,0,2
8,0,0,14,0,0,0,0,0,14,0,0,8
2,0,0,0,0,0,0,0,0,0,0,0,2
2,0,0,0,0,0,0,0,0,0,0,0,2
8,0,0,14,0,0,0,0,0,14,0,0,8
2,0,0,0,0,0,0,0,0,0,0,0,2
2,0,0,0,0,0,0,0,0,0,0,0,2
8,0,0,14,0,0,0,0,0,14,0,0,8
2,0,0,0,0,0,0,0,0,0,0,0,2
2,0,0,0,0,0,0,0,0,0,0,0,2
8,0,0,14,0,0,0,0,0,14,0,0,8
2,0,0,0,0,0,0,0,0,0,0,0,2
2,0,0,0,0,0,0,0,0,0,0,0,2
8,0,0,14,0,0,0,0,0,14,0,0,8
2,0,0,0,0,0,0,0,0,0,0,0,2
2,0,0,0,0,0,0,0,0,0,0,0,2
8,0,0,14,0,0,0,0,0,14,0,0,8
2,0,0,0,0,0,0,0,0,0,0,0,2
2,0,0,0,0,0,0,0,0,0,0,0,2
8,0,0,14,0,0,0,0,0,14,0,0,8
2,0,0,0,0,0,0,0,0,0,0,0,2
2,0,0,0,0,0,0,0,0,0,0,0,2
8,0,0,14,0,0,0,0,0,14,0,0,8
2,0,0,0,0,0,0,0,0,0,0,0,2
2,0,0,0,0,0,0,0,0,0,0,0,2
8,0,0,14,0,0,0,0,0,14,0,0,8
2,0,0,0,0,0,0,0,0,0,0,0,2
2,0,0,0,0,0,0,0,0,0,0,0,2
8,0,0,14,0,0,0,0,0,14,0,0,8
2,0,0,0,0,0,0,0,0,0,0,0,2
2,0,0,0,0,0,0,0,0,0,0,0,2
8,0,0,14,0,0,0,0,0,14,0,0,8
2,0,0,0,0,0,0,0,0,0,0,0,2
2,0,0,0,0,0,0,0,0,0,0,0,2
8,0,0,14,0,0,0,0,0,14,0,0,8
2,0,0,0,0,0,0,0,0,0,0,0,2
1,9,2,13,12,12,5,12,12,11,2,9,1
endlayer

layer
1,9,2,5,3,3,8,3,3,5,2,9,1
9,0,0,0,0,0,0,0,0,0,0,0,9
8,0,0,6,0,0,0,0,0,6,0,0,8
9,0,0,0,0,0,0,0,0,0,0,0,9
9,0,0,0,0,0,0,0,0,0,0,0,9
8,0,0,6,0,0,0,0,0,6,0,0,8
9,0,0,0,0,0,0,0,0,0,0,0,9
9,0,0,0,0,0,0,0,0,0,0,0,9
8,0,0,6,0,0,0,0,0,6,0,0,8
9,0,0,0,0,0,0,0,0,0,0,0,9
9,0,0,0,0,0,0,0,0,0,0,0,9
8,0,0,6,0,0,0,0,0,6,0,0,8
9,0,0,0,0,0,0,0,0,0,0,0,9
9,0,0,0,0,0,0,0,0,0,0,0,9
8,0,0,6,0,0,0,0,0,6,0,0,8
9,0,0,0,0,0,0,0,0,0,0,0,9
9,0,0,0,0,0,0,0,0,0,0,0,9
8,0,0,6,0,0,0,0,0,6,0,0,8
9,0,0,0,0,0,0,0,0,0,0,0,9
9,0,0,0,0,0,0,0,0,0,0,0,9
8,0,0,6,0,0,0,0,0,6,0,0,8
9,0,0,0,0,0,0,0,0,0,0,0,9
9,0,0,0,0,0,0,0,0,0,0,0,9
8,0,0,6,0,0,0,0,0,6,0,0,8
9,0,0,0,0,0,0,0,0,0,0,0,9
9,0,0,0,0,0,0,0,0,0,0,0,9
8,0,0,6,0,0,0,0,0,6,0,0,8
9,0,0,0,0,0,0,0,0,0,0,0,9
9,0,0,0,0,0,0,0,0,0,0,0,9
8,0,0,6,0,0,0,0,0,6,0,0,8
9,0,0,0,0,0,0,0,0,0,0,0,9
9,0,0,0,0,0,0,0,0,0,0,0,9
8,0,0,6,0,0,0,0,0,6,0,0,8
9,0,0,0,0,0,0,0,0,0,0,0,9
9,0,0,0,0,0,0,0,0,0,0,0,9
8,0,0,6,0,0,0,0,0,6,0,0,8
9,0,0,0,0,0,0,0,0,0,0,0,9
9,0,0,0,0,0,0,0,0,0,0,0,9
8,0,0,6,0,0,0,0,0,6,0,0,8
9,0,0,0,0,0,0,0,0,0,0,0,9
9,0,0,0,0,0,0,0,0,0,0,0,9
8,0,0,6,0,0,0,0,0,6,0,0,8
9,0,0,0,0,0,0,0,0,0,0,0,9
9,0,0,0,0,0,0,0,0,0,0,0,9
8,0,0,6,0,0,0,0,0,6,0,0,8
9,0,0,0,0,0,0,0,0,0,0,0,9
9,0,0,0,0,0,0,0,0,0,0,0,9
8,0,0,6,0,0,0,0,0,6,0,0,8
9,0,0,0,0,0,0,0,0,0,0,0,9
9,0,0,0,0,0,0,0,0,0,0,0,9
8,0,0,6,0,0,0,0,0,6,0,0,8
9,0,0,0,0,0,0,0,0,0,0,0,9
9,0,0,0,0,0,0,0,0,0,0,0,9
8,0,0,6,0,0,0,0,0,6,0,0,8
9,0,0,0,0,0,0,0,0,0,0,0,9
9,0,0,0,0,0,0,0,0,0,0,0,9
8,0,0,6,0,0,0,0,0,6,0,0,8
9,0,0,0,0,0,0,0,0,0,0,0,9
9,0,0,0,0,0,0,0,0,0,0,0,9
8,0,0,6,0,0,0,0,0,6,0,0,8
9,0,0,0,0,0,0,0,0,0,0,0,9
9,0,0,0,0,0,0,0,0,0,0,0,9
8,0,0,6,0,0,0,0,0,6,0,0,8
9,0,0,0,0,0,0,0,0,0,0,0,9
9,0,0,0,0,0,0,0,0,0,0,0,9
8,0,0,6,0,0,0,0,0,6,0,0,8
9,0,0,0,0,0,0,0,0,0,0,0,9
9,0,0,0,0,0,0,0,0,0,0,0,9
8,0,0,6,0,0,0,0,0,6,0,0,8
9,0,0,0,0,0,0,0,0,0,0,0,9
9,0,0,0,0,0,0,0,0,0,0,0,9
8,0,0,6,0,0,0,0,0,6,0,0,8
9,0,0,0,0,0,0,0,0,0,0,0,9
1,9,2,5,3,3,8,3,3,5,2,9,1
endlayer

layer
1,1,2,2,4,3,8,3,4,2,2,1,1
1,3,3,0,0,0,0,0,0,0,3,3,1
10,3,3,8,0,0,0,0,0,8,3,3,10
1,3,3,0,0,0,0,0,0,0,3,3,1
1,3,3,0,0,0,0,0,0,0,3,3,1
10,3,3,8,0,0,0,0,0,8,3,3,10
1,3,3,0,0,0,0,0,0,0,3,3,1
1,3,3,0,0,0,0,0,0,0,3,3,1
10,3,3,8,0,0,0,0,0,8,3,3,10
1,3,3,0,0,0,0,0,0,0,3,3,1
1,3,3,0,0,0,0,0,0,0,3,3,1
10,3,3,8,0,0,0,0,0,8,3,3,10
1,3,3,0,0,0,0,0,0,0,3,3,1
1,3,3,0,0,0,0,0,0,0,3,3,1
10,3,3,8,0,0,0,0,0,8,3,3,10
1,3,3,0,0,0,0,0,0,0,3,3,1
1,3,3,0,0,0,0,0,0,0,3,3,1
10,3,3,8,0,0,0,0,0,8,3,3,10
1,3,3,0,0,0,0,0,0,0,3,3,1
1,3,3,0,0,0,0,0,0,0,3,3,1
10,3,3,8,0,0,0,0,0,8,3,3,10
1,3,3,0,0,0,0,0,0,0,3,3,1
1,3,3,0,0,0,0,0,0,0,3,3,1
10,3,3,8,0,0,0,0,0,8,3,3,10
1,3,3,0,0,0,0,0,0,0,3,3,1
1,3,3,0,0,0,0,0,0,0,3,3,1
10,3,3,8,0,0,0,0,0,8,3,3,10
1,3,3,0,0,0,0,0,0,0,3,3,1
1,3,3,0,0,0,0,0,0,0,3,3,1
10,3,3,8,0,0,0,0,0,8,3,3,10
1,3,3,0,0,0,0,0,0,0,3,3,1
1,3,3,0,0,0,0,0,0,0,3,3,1
10,3,3,8,0,0,0,0,0,8,3,3,10
1,3,3,0,0,0,0,0,0,0,3,3,1
1,3,3,0,0,0,0,0,0,0,3,3,1
10,3,3,8,0,0,0,0,0,8,3,3,10
1,3,3,0,0,0,0,0,0,0,3,3,1
1,3,3,0,0,0,0,0,0,0,3,3,1
10,3,3,8,0,0,0,0,0,8,3,3,10
1,3,3,0,0,0,0,0,0,0,3,3,1
1,3,3,0,0,0,0,0,0,0,3,3,1
10,3,3,8,0,0,0,0,0,8,3,3,10
1,3,3,0,0,0,0,0,0,0,3,3,1
1,3,3,0,0,0,0,0,0,0,3,3,1
10,3,3,8,0,0,0,0,0,8,3,3,10
1,3,3,0,0,0,0,0,0,0,3,3,1
1,3,3,0,0,0,0,0,0,0,3,3,1
10,3,3,8,0,0,0,0,0,8,3,3,10
1,3,3,0,0,0,0,0,0,0,3,3,1
1,3,3,0,0,0,0,0,0,0,3,3,1
10,3,3,8,0,0,0,0,0,8,3,3,10
1,3,3,0,0,0,0,0,0,0,3,3,1
1,3,3,0,0,0,0,0,0,0,3,3,1
10,3,3,8,0,0,0,0,0,8,3,3,10
1,3,3,0,0,0,0,0,0,0,3,3,1
1,3,3,0,0,0,0,0,0,0,3,3,1
10,3,3,8,0,0,0,0,0,8,3,3,10
1,3,3,0,0,0,0,0,0,0,3,3,1
1,3,3,0,0,0,0,0,0,0,3,3,1
10,3,3,8,0,0,0,0,0,8,3,3,10
1,3,3,0,0,0,0,0,0,0,3,3,1
1,3,3,0,0,0,0,0,0,0,3,3,1
10,3,3,8,0,0,0,0,0,8,3,3,10
1,3,3,0,0,0,0,0,0,0,3,3,1
1,3,3,0,0,0,0,0,0,0,3,3,1
10,3,3,8,0,0,0,0,0,8,3,3,10
1,3,3,0,0,0,0,0,0,0,3,3,1
1,3,3,0,0,0,0,0,0,0,3,3,1
10,3,3,8,0,0,0,0,0,8,3,3,10
1,3,3,0,0,0,0,0,0,0,3,3,1
1,3,3,0,0,0,0,0,0,0,3,3,1
10,3,3,8,0,0,0,0,0,8,3,3,10
1,3,3,0,0,0,0,0,0,0,3,3,1
1,1,2,2,4,3,8,3,4,2,2,1,1
endlayer

layer
1,1,2,2,2,5,10,5,2,2,2,1,1
1,2,0,0,0,0,0,0,0,0,0,2,1
9,2,0,8,0,0,0,0,0,8,0,2,9
1,2,0,0,0,0,0,0,0,0,0,2,1
1,2,0,0,0,0,0,0,0,0,0,2,1
9,2,0,8,0,0,0,0,0,8,0,2,9
1,2,0,0,0,0,0,0,0,0,0,2,1
1,2,0,0,0,0,0,0,0,0,0,2,1
9,2,0,8,0,0,0,0,0,8,0,2,9
1,2,0,0,0,0,0,0,0,0,0,2,1
1,2,0,0,0,0,0,0,0,0,0,2,1
9,2,0,8,0,0,0,0,0,8,0,2,9
1,2,0,0,0,0,0,0,0,0,0,2,1
1,2,0,0,0,0,0,0,0,0,0,2,1
9,2,0,8,0,0,0,0,0,8,0,2,9
1,2,0,0,0,0,0,0,0,0,0,2,1
1,2,0,0,0,0,0,0,0,0,0,2,1
9,2,0,8,0,0,0,0,0,8,0,2,9
1,2,0,0,0,0,0,0,0,0,0,2,1
1,2,0,0,0,0,0,0,0,0,0,2,1
9,2,0,8,0,0,0,0,0,8,0,2,9
1,2,0,0,0,0,0,0,0,0,0,2,1
1,2,0,0,0,0,0,0,0,0,0,2,1
9,2,0,8,0,0,0,0,0,8,0,2,9
1,2,0,0,0,0,0,0,0,0,0,2,1
1,2,0,0,0,0,0,0,0,0,0,2,1
9,2,0,8,0,0,0,0,0,8,0,2,9
1,2,0,0,0,0,0,0,0,0,0,2,1
1,2,0,0,0,0,0,0,0,0,0,2,1
9,2,0,8,0,0,0,0,0,8,0,2,9
1,2,0,0,0,0,0,0,0,0,0,2,1
1,2,0,0,0,0,0,0,0,0,0,2,1
9,2,0,8,0,0,0,0,0,8,0,2,9
1,2,0,0,0,0,0,0,0,0,0,2,1
1,2,0,0,0,0,0,0,0,0,0,2,1
9,2,0,8,0,0,0,0,0,8,0,2,9
1,2,0,0,0,0,0,0,0,0,0,2,1
1,2,0,0,0,0,0,0,0,0,0,2,1
9,2,0,8,0,0,0,0,0,8,0,2,9
1,2,0,0,0,0,0,0,0,0,0,2,1
1,2,0,0,0,0,0,0,0,0,0,2,1
9,2,0,8,0,0,0,0,0,8,0,2,9
1,2,0,0,0,0,0,0,0,0,0,2,1
1,2,0,0,0,0,0,0,0,0,0,2,1
9,2,0,8,0,0,0,0,0,8,0,2,9
1,2,0,0,0,0,0,0,0,0,0,2,1
1,2,0,0,0,0,0,0,0,0,0,2,1
9,2,0,8,0,0,0,0,0,8,0,2,9
1,2,0,0,0,0,0,0,0,0,0,2,1
1,2,0,0,0,0,0,0,0,0,0,2,1
9,2,0,8,0,0,0,0,0,8,0,2,9
1,2,0,0,0,0,0,0,0,0,0,2,1
1,2,0,0,0,0,0,0,0,0,0,2,1
9,2,0,8,0,0,0,0,0,8,0,2,9
1,2,0,0,0,0,0,0,0,0,0,2,1
1,2,0,0,0,0,0,0,0,0,0,2,1
9,2,0,8,0,0,0,0,0,8,0,2,9
1,2,0,0,0,0,0,0,0,0,0,2,1
1,2,0,0,0,0,0,0,0,0,0,2,1
9,2,0,8,0,0,0,0,0,8,0,2,9
1,2,0,0,0,0,0,0,0,0,0,2,1
1,2,0,0,0,0,0,0,0,0,0,2,1
9,2,0,8,0,0,0,0,0,8,0,2,9
1,2,0,0,0,0,0,0,0,0,0,2,1
1,2,0,0,0,0,0,0,0,0,0,2,1
9,2,0,8,0,0,0,0,0,8,0,2,9
1,2,0,0,0,0,0,0,0,0,0,2,1
1,2,0,0,0,0,0,0,0,0,0,2,1
9,2,0,8,0,0,0,0,0,8,0,2,9
1,2,0,0,0,0,0,0,0,0,0,2,1
1,2,0,0,0,0,0,0,0,0,0,2,1
9,2,0,8,0,0,0,0,0,8,0,2,9
1,2,0,0,0,0,0,0,0,0,0,2,1
1,1,2,2,2,5,10,5,2,2,2,1,1
endlayer

layer
1,1,1,1,2,2,2,2,2,1,1,1,1
1,1,2,2,2,0,0,0,2,2,2,1,1
1,9,2,8,2,0,0,0,2,8,2,9,1
1,1,2,2,2,0,0,0,2,2,2,1,1
1,1,2,2,2,0,0,0,2,2,2,1,1
1,9,2,8,2,0,0,0,2,8,2,9,1
1,1,2,2,2,0,0,0,2,2,2,1,1
1,1,2,2,2,0,0,0,2,2,2,1,1
1,9,2,8,2,0,0,0,2,8,2,9,1
1,1,2,2,2,0,0,0,2,2,2,1,1
1,1,2,2,2,0,0,0,2,2,2,1,1
1,9,2,8,2,0,0,0,2,8,2,9,1
1,1,2,2,2,0,0,0,2,2,2,1,1
1,1,2,2,2,0,0,0,2,2,2,1,1
1,9,2,8,2,0,0,0,2,8,2,9,1
1,1,2,2,2,0,0,0,2,2,2,1,1
1,1,2,2,2,0,0,0,2,2,2,1,1
1,9,2,8,2,0,0,0,2,8,2,9,1
1,1,2,2,2,0,0,0,2,2,2,1,1
1,1,2,2,2,0,0,0,2,2,2,1,1
1,9,2,8,2,0,0,0,2,8,2,9,1
1,1,2,2,2,0,0,0,2,2,2,1,1
1,1,2,2,2,0,0,0,2,2,2,1,1
1,9,2,8,2,0,0,0,2,8,2,9,1
1,1,2,2,2,0,0,0,2,2,2,1,1
1,1,2,2,2,0,0,0,2,2,2,1,1
1,9,2,8,2,0,0,0,2,8,2,9,1
1,1,2,2,2,0,0,0,2,2,2,1,1
1,1,2,2,2,0,0,0,2,2,2,1,1
1,9,2,8,2,0,0,0,2,8,2,9,1
1,1,2,2,2,0,0,0,2,2,2,1,1
1,1,2,2,2,0,0,0,2,2,2,1,1
1,9,2,8,2,0,0,0,2,8,2,9,1
1,1,2,2,2,0,0,0,2,2,2,1,1
1,1,2,2,2,0,0,0,2,2,2,1,1
1,9,2,8,2,0,0,0,2,8,2,9,1
1,1,2,2,2,0,0,0,2,2,2,1,1
1,1,2,2,2,0,0,0,2,2,2,1,1
1,9,2,8,2,0,0,0,2,8,2,9,1
1,1,2,2,2,0,0,0,2,2,2,1,1
1,1,2,2,2,0,0,0,2,2,2,1,1
1,9,2,8,2,0,0,0,2,8,2,9,1
1,1,2,2,2,0,0,0,2,2,2,1,1
1,1,2,2,2,0,0,0,2,2,2,1,1
1,9,2,8,2,0,0,0,2,8,2,9,1
1,1,2,2,2,0,0,0,2,2,2,1,1
1,1,2,2,2,0,0,0,2,2,2,1,1
1,9,2,8,2,0,0,0,2,8,2,9,1
1,1,2,2,2,0,0,0,2,2,2,1,1
1,1,2,2,2,0,0,0,2,2,2,1,1
1,9,2,8,2,0,0,0,2,8,2,9,1
1,1,2,2,2,0,0,0,2,2,2,1,1
1,1,2,2,2,0,0,0,2,2,2,1,1
1,9,2,8,2,0,0,0,2,8,2,9,1
1,1,2,2,2,0,0,0,2,2,2,1,1
1,1,2,2,2,0,0,0,2,2,2,1,1
1,9,2,8,2,0,0,0,2,8,2,9,1
1,1,2,2,2,0,0,0,2,2,2,1,1
1,1,2,2,2,0,0,0,2,2,2,1,1
1,9,2,8,2,0,0,0,2,8,2,9,1
1,1,2,2,2,0,0,0,2,2,2,1,1
1,1,2,2,2,0,0,0,2,2,2,1,1
1,9,2,8,2,0,0,0,2,8,2,9,1
1,1,2,2,2,0,0,0,2,2,2,1,1
1,1,2,2,2,0,0,0,2,2,2,1,1
1,9,2,8,2,0,0,0,2,8,2,9,1
1,1,2,2,2,0,0,0,2,2,2,1,1
1,1,2,2,2,0,0,0,2,2,2,1,1
1,9,2,8,2,0,0,0,2,8,2,9,1
1,1,2,2,2,0,0,0,2,2,2,1,1
1,1,2,2,2,0,0,0,2,2,2,1,1
1,9,2,8,2,0,0,0,2,8,2,9,1
1,1,2,2,2,0,0,0,2,2,2,1,1
1,1,1,1,2,2,2,2,2,1,1,1,1
endlayer

layer
1,1,1,1,1,1,1,1,1,1,1,1,1
1,1,1,1,3,9,8,9,3,1,1,1,1
1,1,9,12,12,8,5,8,12,12,9,1,1
1,1,1,1,3,9,8,9,3,1,1,1,1
1,1,1,1,3,8,9,8,3,1,1,1,1
1,1,9,12,12,9,5,9,12,12,9,1,1
1,1,1,1,3,8,9,8,3,1,1,1,1
1,1,1,1,3,9,8,9,3,1,1,1,1
1,1,9,12,12,8,5,8,12,12,9,1,1
1,1,1,1,3,9,8,9,3,1,1,1,1
1,1,1,1,3,8,9,8,3,1,1,1,1
1,1,9,12,12,9,5,9,12,12,9,1,1
1,1,1,1,3,8,9,8,3,1,1,1,1
1,1,1,1,3,9,8,9,3,1,1,1,1
1,1,9,12,12,8,5,8,12,12,9,1,1
1,1,1,1,3,9,8,9,3,1,1,1,1
1,1,1,1,3,8,9,8,3,1,1,1,1
1,1,9,12,12,9,5,9,12,12,9,1,1
1,1,1,1,3,8,9,8,3,1,1,1,1
1,1,1,1,3,9,8,9,3,1,1,1,1
1,1,9,12,12,8,5,8,12,12,9,1,1
1,1,1,1,3,9,8,9,3,1,1,1,1
1,1,1,1,3,8,9,8,3,1,1,1,1
1,1,9,12,12,9,5,9,12,12,9,1,1
1,1,1,1,3,8,9,8,3,1,1,1,1
1,1,1,1,3,9,8,9,3,1,1,1,1
1,1,9,12,12,8,5,8,12,12,9,1,1
1,1,1,1,3,9,8,9,3,1,1,1,1
1,1,1,1,3,8,9,8,3,1,1,1,1
1,1,9,12,12,9,5,9,12,12,9,1,1
1,1,1,1,3,8,9,8,3,1,1,1,1
1,1,1,1,3,9,8,9,3,1,1,1,1
1,1,9,12,12,8,5,8,12,12,9,1,1
1,1,1,1,3,9,8,9,3,1,1,1,1
1,1,1,1,3,8,9,8,3,1,1,1,1
1,1,9,12,12,9,5,9,12,12,9,1,1
1,1,1,1,3,8,9,8,3,1,1,1,1
1,1,1,1,3,9,8,9,3,1,1,1,1
1,1,9,12,12,8,5,8,12,12,9,1,1
1,1,1,1,3,9,8,9,3,1,1,1,1
1,1,1,1,3,8,9,8,3,1,1,1,1
1,1,9,12,12,9,5,9,12,12,9,1,1
1,1,1,1,3,8,9,8,3,1,1,1,1
1,1,1,1,3,9,8,9,3,1,1,1,1
1,1,9,12,12,8,5,8,12,12,9,1,1
1,1,1,1,3,9,8,9,3,1,1,1,1
1,1,1,1,3,8,9,8,3,1,1,1,1
1,1,9,12,12,9,5,9,12,12,9,1,1
1,1,1,1,3,8,9,8,3,1,1,1,1
1,1,1,1,3,9,8,9,3,1,1,1,1
1,1,9,12,12,8,5,8,12,12,9,1,1
1,1,1,1,3,9,8,9,3,1,1,1,1
1,1,1,1,3,8,9,8,3,1,1,1,1
1,1,9,12,12,9,5,9,12,12,9,1,1
1,1,1,1,3,8,9,8,3,1,1,1,1
1,1,1,1,3,9,8,9,3,1,1,1,1
1,1,9,12,12,8,5,8,12,12,9,1,1
1,1,1,1,3,9,8,9,3,1,1,1,1
1,1,1,1,3,8,9,8,3,1,1,1,1
1,1,9,12,12,9,5,9,12,12,9,1,1
1,1,1,1,3,8,9,8,3,1,1,1,1
1,1,1,1,3,9,8,9,3,1,1,1,1
1,1,9,12,12,8,5,8,12,12,9,1,1
1,1,1,1,3,9,8,9,3,1,1,1,1
1,1,1,1,3,8,9,8,3,1,1,1,1
1,1,9,12,12,9,5,9,12,12,9,1,1
1,1,1,1,3,8,9,8,3,1,1,1,1
1,1,1,1,3,9,8,9,3,1,1,1,1
1,1,9,12,12,8,5,8,12,12,9,1,1
1,1,1,1,3,9,8,9,3,1,1,1,1
1,1,1,1,3,8,9,8,3,1,1,1,1
1,1,9,12,12,9,5,9,12,12,9,1,1
1,1,1,1,3,8,9,8,3,1,1,1,1
1,1,1,1,1,1,1,1,1,1,1,1,1
endlayer

